Workbook

Sheet TOTAL
A1: Site Name | B1: Day | C1: Month | D1: Year | E1: Total Electricity Kwh | F1: Electricity Tariff ($/Kwh) | G1: LPG (Kg) | H1: LPG $/Kg | I1: Water Utility Supply (m3) m3 | J1: Water Utility Supply (m3) $/m3 | K1: Irrigation Water (m3) m3 | L1: Irrigation water $/m3 | M1: Room Nights | N1: Total Guests
A2: Dubai at Jumeirah Beach | B2: 1 | C2: 2 | D2: 2023 | E2: =Submetering!M2+Submetering!N2+Submetering!O2+Submetering!P2+Submetering!Q2+Submetering!R2+Submetering!S2+Submetering!T2+Submetering!U2+Submetering!V2 -> 36734.88 | F2: 0.44448 | G2: =Submetering!Z2+Submetering!AA2+Submetering!AB2 -> 899.64 | H2: =1.62/0.52 -> 3.1153846 | I2: =Submetering!G2 -> 498 | J2: 13.83 | K2: =Submetering!BL2 -> 232 | L2: 1.2 | M2: =Submetering!E2 -> 165.9 | N2: =Submetering!F2 -> 311
A3: Dubai at Jumeirah Beach | B3: =B2+1 -> 2 | C3: 2 | D3: 2023 | E3: =Submetering!M3+Submetering!N3+Submetering!O3+Submetering!P3+Submetering!Q3+Submetering!R3+Submetering!S3+Submetering!T3+Submetering!U3+Submetering!V3 -> 34737.36 | F3: 0.44448 | G3: =Submetering!Z3+Submetering!AA3+Submetering!AB3 -> 814.59 | H3: =1.62/0.52 -> 3.1153846 | I3: =Submetering!G3 -> 587 | J3: 13.83 | K3: =Submetering!BL3 -> 225 | L3: 1.2 | M3: =Submetering!E3 -> 165.9 | N3: =Submetering!F3 -> 322
A4: Dubai at Jumeirah Beach | B4: =B3+1 -> 3 | C4: 2 | D4: 2023 | E4: =Submetering!M4+Submetering!N4+Submetering!O4+Submetering!P4+Submetering!Q4+Submetering!R4+Submetering!S4+Submetering!T4+Submetering!U4+Submetering!V4 -> 38050.32 | F4: 0.44448 | G4: =Submetering!Z4+Submetering!AA4+Submetering!AB4 -> 791.91 | H4: =1.62/0.52 -> 3.1153846 | I4: =Submetering!G4 -> 577 | J4: 13.83 | K4: =Submetering!BL4 -> 221 | L4: 1.2 | M4: =Submetering!E4 -> 170.64 | N4: =Submetering!F4 -> 302
A5: Dubai at Jumeirah Beach | B5: =B4+1 -> 4 | C5: 2 | D5: 2023 | E5: =Submetering!M5+Submetering!N5+Submetering!O5+Submetering!P5+Submetering!Q5+Submetering!R5+Submetering!S5+Submetering!T5+Submetering!U5+Submetering!V5 -> 37416.96 | F5: 0.44448 | G5: =Submetering!Z5+Submetering!AA5+Submetering!AB5 -> 871.29 | H5: =1.62/0.52 -> 3.1153846 | I5: =Submetering!G5 -> 620 | J5: 13.83 | K5: =Submetering!BL5 -> 208 | L5: 1.2 | M5: =Submetering!E5 -> 180.12 | N5: =Submetering!F5 -> 312
A6: Dubai at Jumeirah Beach | B6: =B5+1 -> 5 | C6: 2 | D6: 2023 | E6: =Submetering!M6+Submetering!N6+Submetering!O6+Submetering!P6+Submetering!Q6+Submetering!R6+Submetering!S6+Submetering!T6+Submetering!U6+Submetering!V6 -> 38196.48 | F6: 0.44448 | G6: =Submetering!Z6+Submetering!AA6+Submetering!AB6 -> 875.07 | H6: =1.62/0.52 -> 3.1153846 | I6: =Submetering!G6 -> 533 | J6: 13.83 | K6: =Submetering!BL6 -> 225 | L6: 1.2 | M6: =Submetering!E6 -> 163.53 | N6: =Submetering!F6 -> 286
A7: Dubai at Jumeirah Beach | B7: =B6+1 -> 6 | C7: 2 | D7: 2023 | E7: =Submetering!M7+Submetering!N7+Submetering!O7+Submetering!P7+Submetering!Q7+Submetering!R7+Submetering!S7+Submetering!T7+Submetering!U7+Submetering!V7 -> 37709.28 | F7: 0.44448 | G7: =Submetering!Z7+Submetering!AA7+Submetering!AB7 -> 782.46 | H7: =1.62/0.52 -> 3.1153846 | I7: =Submetering!G7 -> 518 | J7: 13.83 | K7: =Submetering!BL7 -> 183 | L7: 1.2 | M7: =Submetering!E7 -> 170.64 | N7: =Submetering!F7 -> 290
A8: Dubai at Jumeirah Beach | B8: =B7+1 -> 7 | C8: 2 | D8: 2023 | E8: =Submetering!M8+Submetering!N8+Submetering!O8+Submetering!P8+Submetering!Q8+Submetering!R8+Submetering!S8+Submetering!T8+Submetering!U8+Submetering!V8 -> 38829.84 | F8: 0.44448 | G8: =Submetering!Z8+Submetering!AA8+Submetering!AB8 -> 740.88 | H8: =1.62/0.52 -> 3.1153846 | I8: =Submetering!G8 -> 588 | J8: 13.83 | K8: =Submetering!BL8 -> 201 | L8: 1.2 | M8: =Submetering!E8 -> 137.46 | N8: =Submetering!F8 -> 241
A9: Dubai at Jumeirah Beach | B9: =B8+1 -> 8 | C9: 2 | D9: 2023 | E9: =Submetering!M9+Submetering!N9+Submetering!O9+Submetering!P9+Submetering!Q9+Submetering!R9+Submetering!S9+Submetering!T9+Submetering!U9+Submetering!V9 -> 38391.36 | F9: 0.44448 | G9: =Submetering!Z9+Submetering!AA9+Submetering!AB9 -> 852.39 | H9: =1.62/0.52 -> 3.1153846 | I9: =Submetering!G9 -> 629 | J9: 13.83 | K9: =Submetering!BL9 -> 198 | L9: 1.2 | M9: =Submetering!E9 -> 161.16 | N9: =Submetering!F9 -> 268
A10: Dubai at Jumeirah Beach | B10: =B9+1 -> 9 | C10: 2 | D10: 2023 | E10: =Submetering!M10+Submetering!N10+Submetering!O10+Submetering!P10+Submetering!Q10+Submetering!R10+Submetering!S10+Submetering!T10+Submetering!U10+Submetering!V10 -> 37124.64 | F10: 0.44448 | G10: =Submetering!Z10+Submetering!AA10+Submetering!AB10 -> 916.65 | H10: =1.62/0.52 -> 3.1153846 | I10: =Submetering!G10 -> 610 | J10: 13.83 | K10: =Submetering!BL10 -> 195 | L10: 1.2 | M10: =Submetering!E10 -> 165.9 | N10: =Submetering!F10 -> 300
A11: Dubai at Jumeirah Beach | B11: =B10+1 -> 10 | C11: 2 | D11: 2023 | E11: =Submetering!M11+Submetering!N11+Submetering!O11+Submetering!P11+Submetering!Q11+Submetering!R11+Submetering!S11+Submetering!T11+Submetering!U11+Submetering!V11 -> 37416.96 | F11: 0.44448 | G11: =Submetering!Z11+Submetering!AA11+Submetering!AB11 -> 939.33 | H11: =1.62/0.52 -> 3.1153846 | I11: =Submetering!G11 -> 678 | J11: 13.83 | K11: =Submetering!BL11 -> 207 | L11: 1.2 | M11: =Submetering!E11 -> 158.79 | N11: =Submetering!F11 -> 308
A12: Dubai at Jumeirah Beach | B12: =B11+1 -> 11 | C12: 2 | D12: 2023 | E12: =Submetering!M12+Submetering!N12+Submetering!O12+Submetering!P12+Submetering!Q12+Submetering!R12+Submetering!S12+Submetering!T12+Submetering!U12+Submetering!V12 -> 38050.32 | F12: 0.44448 | G12: =Submetering!Z12+Submetering!AA12+Submetering!AB12 -> 903.42 | H12: =1.62/0.52 -> 3.1153846 | I12: =Submetering!G12 -> 584 | J12: 13.83 | K12: =Submetering!BL12 -> 378 | L12: 1.2 | M12: =Submetering!E12 -> 215.67 | N12: =Submetering!F12 -> 399
A13: Dubai at Jumeirah Beach | B13: =B12+1 -> 12 | C13: 2 | D13: 2023 | E13: =Submetering!M13+Submetering!N13+Submetering!O13+Submetering!P13+Submetering!Q13+Submetering!R13+Submetering!S13+Submetering!T13+Submetering!U13+Submetering!V13 -> 38976 | F13: 0.44448 | G13: =Submetering!Z13+Submetering!AA13+Submetering!AB13 -> 922.32 | H13: =1.62/0.52 -> 3.1153846 | I13: =Submetering!G13 -> 576 | J13: 13.83 | K13: =Submetering!BL13 -> 269 | L13: 1.2 | M13: =Submetering!E13 -> 215.67 | N13: =Submetering!F13 -> 391
A14: Dubai at Jumeirah Beach | B14: =B13+1 -> 13 | C14: 2 | D14: 2023 | E14: =Submetering!M14+Submetering!N14+Submetering!O14+Submetering!P14+Submetering!Q14+Submetering!R14+Submetering!S14+Submetering!T14+Submetering!U14+Submetering!V14 -> 37904.16 | F14: 0.44448 | G14: =Submetering!Z14+Submetering!AA14+Submetering!AB14 -> 801.36 | H14: =1.62/0.52 -> 3.1153846 | I14: =Submetering!G14 -> 529 | J14: 13.83 | K14: =Submetering!BL14 -> 253 | L14: 1.2 | M14: =Submetering!E14 -> 210.93 | N14: =Submetering!F14 -> 377
... A29: Dubai at Jumeirah Beach | B29: =B28+1 -> 28 | C29: 2 | D29: 2023 | E29: =Submetering!M29+Submetering!N29+Submetering!O29+Submetering!P29+Submetering!Q29+Submetering!R29+Submetering!S29+Submetering!T29+Submetering!U29+Submetering!V29 -> 0 | F29: 0.44448 | G29: =Submetering!Z29+Submetering!AA29+Submetering!AB29 -> 0 | H29: =1.62/0.52 -> 3.1153846 | I29: =Submetering!G29 -> 0 | J29: 13.83 | K29: =Submetering!BL29 -> 0 | L29: 1.2 | M29: =Submetering!E29 -> 0 | N29: =Submetering!F29 -> 0

Sheet Submetering
A1: Site Name | B1: Day | C1: Month | D1: Year | E1: Room Nights | F1: Total Guests | G1: Potable Water -IG (m3) | H1: Resort Water (m3) | I1: Irrigation Water (m3) | J1: Domestic Water for Irrigation (m3) | K1: Cooling Tower Water (m3) | L1: Cooling Tower Blowdown (m3) | M1: EMDB-1 All Pumps (KWh) | N1: EMDB-2 Elevators (KWh) | O1: MDB-1 Chiller #1 (KWh) | P1: MDB-2 Chiller #2 (KWh) | Q1: MDB-3 Chiller #3(KWh) | R1: MDB-4 North Riser (KWh) | S1: MDB-5 North Riser (KWh) | T1: MDB-6 Main Kitchen (KWh) | U1: MDB-7 South Riser (KWh) | V1: MDB-8 F&B (KWh) | W1: Chiller 1 (Kwh cooling) | X1: Chiller 2 (Kwh cooling) | Y1: Chiller 3 (Kwh cooling) | Z1: Steam Boiler LPG (Kg) | AA1: Solar Hot Water Boiler LPG (Kg) | AB1: Low Temp Hot Water Boiler LPG (Kg) | AC1: Steam Boiler Steam (Kg) | AD1: Ird Kitchen (Kg) | AE1: Suq Kitchen (Kg) | AF1: Bakery Kitchen (Kg) | AG1: Shai Saloon Kitchen (kg) | AH1: Banquet Kitchen (Kg) | AI1: Sea Fu Kitchen (Kg) | AJ1: Jean George Cold Water (m³) | AK1: Jean George Hot Water (m³) | AL1: Coya Cold Water (m³) | AM1: Coya Hot Water (m³) | AN1: Nusrat Cold Water (m³) | AO1: Nusrat Hot Water (m³) | AP1: Provocateur Cold Water (m³) | AQ1: Provocateur Hot Water (m³) | AR1: Scalini Cold Water (m³) | AS1: Scalini Hot Water (m³) | AT1: F&B V Irrigation (m³) | AU1: MDB Coya (KWh) | AV1: MDB Jean Georges (KWh) | AW1: MDB Nusrat(KWh) | AX1: SMDB Provocateur (KWh) | AY1: SMDB Scalini (KWh) | AZ1: Common ESMDB (KWh) | BA1: Chilled Water Coya (Kwh) | BB1: Chilled Water Coya Cold Room (Kwh) | BC1: Chilled Water Jean Georges (Kwh) | BD1: Chilled Water Nusrat (Kwh) | BE1: Chilled Water Provocateur A (Kwh) | BF1: Chilled Water Provocateur B (Kwh) | BG1: Coya LPG (Kg) | BH1: Nusrat LPG (Kg) | BI1: Jean Georges LPG (Kg) | BJ1: Provocateur LPG (Kg) | BK1: Scalini LPG (Kg) | BL1: TSE Irrigation (m3)
A2: Dubai at Jumeirah Beach | B2: 1 | C2: 2 | D2: 2023 | E2: =237*0.7 -> 165.9 | F2: =278+33 -> 311 | G2: ='DJB Daily Readings'!C10-'DJB Daily Readings'!C9 -> 498 | H2: ='DJB Daily Readings'!F10-'DJB Daily Readings'!F9 -> 390 | I2: ='DJB Daily Readings'!L9 -> 249 | J2: ='DJB Daily Readings'!N9 -> 0 | K2: ='DJB Daily Readings'!O10-'DJB Daily Readings'!O9 -> 67 | L2: ='DJB Daily Readings'!R10-'DJB Daily Readings'!R9 -> 11 | M2: ='DJB Daily Readings'!U10-'DJB Daily Readings'!U9 -> 1997.52 | N2: ='DJB Daily Readings'!X10-'DJB Daily Readings'!X9 -> 4579.68 | O2: ='DJB Daily Readings'!AA10-'DJB Daily Readings'!AA9 -> 0 | P2: ='DJB Daily Readings'!AD10-'DJB Daily Readings'!AD9 -> 1364.16 | Q2: ='DJB Daily Readings'!AG10-'DJB Daily Readings'!AG9 -> 7405.44 | R2: ='DJB Daily Readings'!AJ10-'DJB Daily Readings'!AJ9 -> 4482.24 | S2: ='DJB Daily Readings'!AM10-'DJB Daily Readings'!AM9 -> 3751.44 | T2: ='DJB Daily Readings'!AP10-'DJB Daily Readings'!AP9 -> 4530.96 | U2: ='DJB Daily Readings'!AS10-'DJB Daily Readings'!AS9 -> 2923.2 | V2: ='DJB Daily Readings'!AV10-'DJB Daily Readings'!AV9 -> 5700.24 | W2: ='DJB Daily Readings'!AZ10-'DJB Daily Readings'!AZ9 -> 0 | X2: ='DJB Daily Readings'!BC10-'DJB Daily Readings'!BC9 -> 0 | Y2: ='DJB Daily Readings'!BF10-'DJB Daily Readings'!BF9 -> 35200 | Z2: =('DJB Daily Readings'!CK10-'DJB Daily Readings'!CK9)*1.89 -> 149.31 | AA2: =('DJB Daily Readings'!CN10-'DJB Daily Readings'!CN9)*1.89 -> 228.69 | AB2: =('DJB Daily Readings'!CQ10-'DJB Daily Readings'!CQ9)*1.89 -> 521.64 | AC2: ='DJB Daily Readings'!CT10-'DJB Daily Readings'!CT9 -> 183 | AD2: =('DJB Daily Readings'!BY10-'DJB Daily Readings'!BY9)*1.89 -> 32.13 | AE2: =('DJB Daily Readings'!CA10-'DJB Daily Readings'!CA9)*1.89 -> 37.8 | AF2: =('DJB Daily Readings'!CC10-'DJB Daily Readings'!CC9)*1.89 -> 15.12 | AG2: =('DJB Daily Readings'!CE10-'DJB Daily Readings'!CE9)*1.89 -> 18.9 | AH2: =('DJB Daily Readings'!CG10-'DJB Daily Readings'!CG9)*1.89 -> 26.46 | AI2: =('DJB Daily Readings'!CI10-'DJB Daily Readings'!CI9)*1.89 -> 66.15 | AJ2: ='DJB Daily Readings'!CY10-'DJB Daily Readings'!CY9 -> 8 | AK2: ='DJB Daily Readings'!CW10-'DJB Daily Readings'!CW9 -> 10 | AL2: ='DJB Daily Readings'!DC10-'DJB Daily Readings'!DC9 -> 12 | AM2: ='DJB Daily Readings'!DA10-'DJB Daily Readings'!DA9 -> 14 | AN2: ='DJB Daily Readings'!DG10-'DJB Daily Readings'!DG9 -> 4 | AO2: ='DJB Daily Readings'!DE10-'DJB Daily Readings'!DE9 -> 9 | AP2: ='DJB Daily Readings'!DK10-'DJB Daily Readings'!DK9 -> 8 | AQ2: ='DJB Daily Readings'!DI10-'DJB Daily Readings'!DI9 -> 8 | AR2: ='DJB Daily Readings'!DO10-'DJB Daily Readings'!DO9 -> 6 | AS2: ='DJB Daily Readings'!DM10-'DJB Daily Readings'!DM9 -> 4 | AT2: ='DJB Daily Readings'!DQ10-'DJB Daily Readings'!DQ9 -> 4 | AU2: ='DJB Daily Readings'!DT10-'DJB Daily Readings'!DT9 -> 11.2 | AW2: ='DJB Daily Readings'!DX10-'DJB Daily Readings'!DX9 -> 5.8 | AX2: ='DJB Daily Readings'!DZ10-'DJB Daily Readings'!DZ9 -> 6.3 | AY2: ='DJB Daily Readings'!EB10-'DJB Daily Readings'!EB9 -> 484 | AZ2: ='DJB Daily Readings'!ED10-'DJB Daily Readings'!ED9 -> 153.8 | BA2: ='DJB Daily Readings'!EG10-'DJB Daily Readings'!EG9 -> 2700 | BB2: ='DJB Daily Readings'!EI10-'DJB Daily Readings'!EI9 -> 220 | BC2: ='DJB Daily Readings'!EQ10-'DJB Daily Readings'!EQ9 -> 1600 | BD2: ='DJB Daily Readings'!EK10-'DJB Daily Readings'!EK9 -> 800 | BE2: ='DJB Daily Readings'!EM10-'DJB Daily Readings'!EM9 -> 200 | BF2: ='DJB Daily Readings'!EO10-'DJB Daily Readings'!EO9 -> 540 | BG2: =('DJB Daily Readings'!ET10-'DJB Daily Readings'!ET9)*1.89 -> 30.24 | BH2: =('DJB Daily Readings'!EV10-'DJB Daily Readings'!EV9)*1.89 -> 20.79 | BI2: =('DJB Daily Readings'!EZ10-'DJB Daily Readings'!EZ9)*1.89 -> 28.35 | BJ2: =('DJB Daily Readings'!EX10-'DJB Daily Readings'!EX9)*1.89 -> 15.12 | BK2: =('DJB Daily Readings'!FB10-'DJB Daily Readings'!FB9)*1.89 -> 51.03 | BL2: ='DJB Daily Readings'!J9 -> 232
A3: Dubai at Jumeirah Beach | B3: =B2+1 -> 2 | C3: 2 | D3: 2023 | E3: =237*0.7 -> 165.9 | F3: =286+36 -> 322 | G3: ='DJB Daily Readings'!C11-'DJB Daily Readings'!C10 -> 587 | H3: ='DJB Daily Readings'!F11-'DJB Daily Readings'!F10 -> 461 | I3: ='DJB Daily Readings'!L10 -> 0 | J3: ='DJB Daily Readings'!N10 -> 0 | K3: ='DJB Daily Readings'!O11-'DJB Daily Readings'!O10 -> 67 | L3: ='DJB Daily Readings'!R11-'DJB Daily Readings'!R10 -> 6 | M3: ='DJB Daily Readings'!U11-'DJB Daily Readings'!U10 -> 1802.64 | N3: ='DJB Daily Readings'!X11-'DJB Daily Readings'!X10 -> 4189.92 | O3: ='DJB Daily Readings'!AA11-'DJB Daily Readings'!AA10 -> 828.24 | P3: ='DJB Daily Readings'!AD11-'DJB Daily Readings'!AD10 -> 633.36 | Q3: ='DJB Daily Readings'!AG11-'DJB Daily Readings'!AG10 -> 7454.16 | R3: ='DJB Daily Readings'!AJ11-'DJB Daily Readings'!AJ10 -> 4238.64 | S3: ='DJB Daily Readings'!AM11-'DJB Daily Readings'!AM10 -> 3654 | T3: ='DJB Daily Readings'!AP11-'DJB Daily Readings'!AP10 -> 3995.04 | U3: ='DJB Daily Readings'!AS11-'DJB Daily Readings'!AS10 -> 2582.16 | V3: ='DJB Daily Readings'!AV11-'DJB Daily Readings'!AV10 -> 5359.2 | W3: ='DJB Daily Readings'!AZ11-'DJB Daily Readings'!AZ10 -> 0 | X3: ='DJB Daily Readings'!BC11-'DJB Daily Readings'!BC10 -> 0 | Y3: ='DJB Daily Readings'!BF11-'DJB Daily Readings'!BF10 -> 39700 | Z3: =('DJB Daily Readings'!CK11-'DJB Daily Readings'!CK10)*1.89 -> 132.3 | AA3: =('DJB Daily Readings'!CN11-'DJB Daily Readings'!CN10)*1.89 -> 219.24 | AB3: =('DJB Daily Readings'!CQ11-'DJB Daily Readings'!CQ10)*1.89 -> 463.05 | AC3: ='DJB Daily Readings'!CT11-'DJB Daily Readings'!CT10 -> 164 | AD3: =('DJB Daily Readings'!BY11-'DJB Daily Readings'!BY10)*1.89 -> 22.68 | AE3: =('DJB Daily Readings'!CA11-'DJB Daily Readings'!CA10)*1.89 -> 32.13 | AF3: =('DJB Daily Readings'!CC11-'DJB Daily Readings'!CC10)*1.89 -> 11.34 | AG3: =('DJB Daily Readings'!CE11-'DJB Daily Readings'!CE10)*1.89 -> 13.23 | AH3: =('DJB Daily Readings'!CG11-'DJB Daily Readings'!CG10)*1.89 -> 26.46 | AI3: =('DJB Daily Readings'!CI11-'DJB Daily Readings'!CI10)*1.89 -> 64.26 | AJ3: ='DJB Daily Readings'!CY11-'DJB Daily Readings'!CY10 -> 7 | AK3: ='DJB Daily Readings'!CW11-'DJB Daily Readings'!CW10 -> 9 | AL3: ='DJB Daily Readings'!DC11-'DJB Daily Readings'!DC10 -> 16 | AM3: ='DJB Daily Readings'!DA11-'DJB Daily Readings'!DA10 -> 14 | AN3: ='DJB Daily Readings'!DG11-'DJB Daily Readings'!DG10 -> 5 | AO3: ='DJB Daily Readings'!DE11-'DJB Daily Readings'!DE10 -> 8 | AP3: ='DJB Daily Readings'!DK11-'DJB Daily Readings'!DK10 -> 7 | AQ3: ='DJB Daily Readings'!DI11-'DJB Daily Readings'!DI10 -> 11 | AR3: ='DJB Daily Readings'!DO11-'DJB Daily Readings'!DO10 -> 6 | AS3: ='DJB Daily Readings'!DM11-'DJB Daily Readings'!DM10 -> 5 | AT3: ='DJB Daily Readings'!DQ11-'DJB Daily Readings'!DQ10 -> 6 | AU3: ='DJB Daily Readings'!DT11-'DJB Daily Readings'!DT10 -> 11 | AW3: ='DJB Daily Readings'!DX11-'DJB Daily Readings'!DX10 -> 5.8 | AX3: ='DJB Daily Readings'!DZ11-'DJB Daily Readings'!DZ10 -> 6.1 | AY3: ='DJB Daily Readings'!EB11-'DJB Daily Readings'!EB10 -> 532 | AZ3: ='DJB Daily Readings'!ED11-'DJB Daily Readings'!ED10 -> 148.2 | BA3: ='DJB Daily Readings'!EG11-'DJB Daily Readings'!EG10 -> 3200 | BB3: ='DJB Daily Readings'!EI11-'DJB Daily Readings'!EI10 -> 240 | BC3: ='DJB Daily Readings'!EQ11-'DJB Daily Readings'!EQ10 -> 2900 | BD3: ='DJB Daily Readings'!EK11-'DJB Daily Readings'!EK10 -> 900 | BE3: ='DJB Daily Readings'!EM11-'DJB Daily Readings'!EM10 -> 300 | BF3: ='DJB Daily Readings'!EO11-'DJB Daily Readings'!EO10 -> 670 | BG3: =('DJB Daily Readings'!ET11-'DJB Daily Readings'!ET10)*1.89 -> 26.46 | BH3: =('DJB Daily Readings'!EV11-'DJB Daily Readings'!EV10)*1.89 -> 20.79 | BI3: =('DJB Daily Readings'!EZ11-'DJB Daily Readings'!EZ10)*1.89 -> 30.24 | BJ3: =('DJB Daily Readings'!EX11-'DJB Daily Readings'!EX10)*1.89 -> 17.01 | BK3: =('DJB Daily Readings'!FB11-'DJB Daily Readings'!FB10)*1.89 -> 49.14 | BL3: ='DJB Daily Readings'!J11 -> 225
A4: Dubai at Jumeirah Beach | B4: =B3+1 -> 3 | C4: 2 | D4: 2023 | E4: =237*0.72 -> 170.64 | F4: =268+34 -> 302 | G4: ='DJB Daily Readings'!C12-'DJB Daily Readings'!C11 -> 577 | H4: ='DJB Daily Readings'!F12-'DJB Daily Readings'!F11 -> 430 | I4: ='DJB Daily Readings'!L11 -> 272 | J4: ='DJB Daily Readings'!N11 -> 0 | K4: ='DJB Daily Readings'!O12-'DJB Daily Readings'!O11 -> 81 | L4: ='DJB Daily Readings'!R12-'DJB Daily Readings'!R11 -> 7 | M4: ='DJB Daily Readings'!U12-'DJB Daily Readings'!U11 -> 1948.8 | N4: ='DJB Daily Readings'!X12-'DJB Daily Readings'!X11 -> 4725.84 | O4: ='DJB Daily Readings'!AA12-'DJB Daily Readings'!AA11 -> 8087.52 | P4: ='DJB Daily Readings'!AD12-'DJB Daily Readings'!AD11 -> 194.88 | Q4: ='DJB Daily Readings'!AG12-'DJB Daily Readings'!AG11 -> 1948.8 | R4: ='DJB Daily Readings'!AJ12-'DJB Daily Readings'!AJ11 -> 4823.28 | S4: ='DJB Daily Readings'!AM12-'DJB Daily Readings'!AM11 -> 3702.72 | T4: ='DJB Daily Readings'!AP12-'DJB Daily Readings'!AP11 -> 4238.64 | U4: ='DJB Daily Readings'!AS12-'DJB Daily Readings'!AS11 -> 2679.6 | V4: ='DJB Daily Readings'!AV12-'DJB Daily Readings'!AV11 -> 5700.24 | W4: ='DJB Daily Readings'!AZ12-'DJB Daily Readings'!AZ11 -> 34300 | X4: ='DJB Daily Readings'!BC12-'DJB Daily Readings'!BC11 -> 0 | Y4: ='DJB Daily Readings'!BF12-'DJB Daily Readings'!BF11 -> 10400 | Z4: =('DJB Daily Readings'!CK12-'DJB Daily Readings'!CK11)*1.89 -> 141.75 | AA4: =('DJB Daily Readings'!CN12-'DJB Daily Readings'!CN11)*1.89 -> 226.8 | AB4: =('DJB Daily Readings'!CQ12-'DJB Daily Readings'!CQ11)*1.89 -> 423.36 | AC4: ='DJB Daily Readings'!CT12-'DJB Daily Readings'!CT11 -> 174 | AD4: =('DJB Daily Readings'!BY12-'DJB Daily Readings'!BY11)*1.89 -> 32.13 | AE4: =('DJB Daily Readings'!CA12-'DJB Daily Readings'!CA11)*1.89 -> 39.69 | AF4: =('DJB Daily Readings'!CC12-'DJB Daily Readings'!CC11)*1.89 -> 13.23 | AG4: =('DJB Daily Readings'!CE12-'DJB Daily Readings'!CE11)*1.89 -> 17.01 | AH4: =('DJB Daily Readings'!CG12-'DJB Daily Readings'!CG11)*1.89 -> 24.57 | AI4: =('DJB Daily Readings'!CI12-'DJB Daily Readings'!CI11)*1.89 -> 68.04 | AJ4: ='DJB Daily Readings'!CY12-'DJB Daily Readings'!CY11 -> 5 | AK4: ='DJB Daily Readings'!CW12-'DJB Daily Readings'!CW11 -> 9 | AL4: ='DJB Daily Readings'!DC12-'DJB Daily Readings'!DC11 -> 15 | AM4: ='DJB Daily Readings'!DA12-'DJB Daily Readings'!DA11 -> 15 | AN4: ='DJB Daily Readings'!DG12-'DJB Daily Readings'!DG11 -> 5 | AO4: ='DJB Daily Readings'!DE12-'DJB Daily Readings'!DE11 -> 8 | AP4: ='DJB Daily Readings'!DK12-'DJB Daily Readings'!DK11 -> 11 | AQ4: ='DJB Daily Readings'!DI12-'DJB Daily Readings'!DI11 -> 12 | AR4: ='DJB Daily Readings'!DO12-'DJB Daily Readings'!DO11 -> 9 | AS4: ='DJB Daily Readings'!DM12-'DJB Daily Readings'!DM11 -> 6 | AT4: ='DJB Daily Readings'!DQ12-'DJB Daily Readings'!DQ11 -> 6 | AU4: ='DJB Daily Readings'!DT12-'DJB Daily Readings'!DT11 -> 11.3 | AW4: ='DJB Daily Readings'!DX12-'DJB Daily Readings'!DX11 -> 6 | AX4: ='DJB Daily Readings'!DZ12-'DJB Daily Readings'!DZ11 -> 7.6 | AY4: ='DJB Daily Readings'!EB12-'DJB Daily Readings'!EB11 -> 579 | AZ4: ='DJB Daily Readings'!ED12-'DJB Daily Readings'!ED11 -> 154.7 | BA4: ='DJB Daily Readings'!EG12-'DJB Daily Readings'!EG11 -> 3600 | BB4: ='DJB Daily Readings'!EI12-'DJB Daily Readings'!EI11 -> 280 | BC4: ='DJB Daily Readings'!EQ12-'DJB Daily Readings'!EQ11 -> 4900 | BD4: ='DJB Daily Readings'!EK12-'DJB Daily Readings'!EK11 -> 1100 | BE4: ='DJB Daily Readings'!EM12-'DJB Daily Readings'!EM11 -> 500 | BF4: ='DJB Daily Readings'!EO12-'DJB Daily Readings'!EO11 -> 690 | BG4: =('DJB Daily Readings'!ET12-'DJB Daily Readings'!ET11)*1.89 -> 30.24 | BH4: =('DJB Daily Readings'!EV12-'DJB Daily Readings'!EV11)*1.89 -> 20.79 | BI4: =('DJB Daily Readings'!EZ12-'DJB Daily Readings'!EZ11)*1.89 -> 28.35 | BJ4: =('DJB Daily Readings'!EX12-'DJB Daily Readings'!EX11)*1.89 -> 24.57 | BK4: =('DJB Daily Readings'!FB12-'DJB Daily Readings'!FB11)*1.89 -> 66.15 | BL4: ='DJB Daily Readings'!J12 -> 221
A5: Dubai at Jumeirah Beach | B5: =B4+1 -> 4 | C5: 2 | D5: 2023 | E5: =237*0.76 -> 180.12 | F5: =280+32 -> 312 | G5: ='DJB Daily Readings'!C13-'DJB Daily Readings'!C12 -> 620 | H5: ='DJB Daily Readings'!F13-'DJB Daily Readings'!F12 -> 457 | I5: ='DJB Daily Readings'!L12 -> 260 | J5: ='DJB Daily Readings'!N12 -> 14 | K5: ='DJB Daily Readings'!O13-'DJB Daily Readings'!O12 -> 70 | L5: ='DJB Daily Readings'!R13-'DJB Daily Readings'!R12 -> 5 | M5: ='DJB Daily Readings'!U13-'DJB Daily Readings'!U12 -> 1948.8 | N5: ='DJB Daily Readings'!X13-'DJB Daily Readings'!X12 -> 4677.12 | O5: ='DJB Daily Readings'!AA13-'DJB Daily Readings'!AA12 -> 0 | P5: ='DJB Daily Readings'!AD13-'DJB Daily Readings'!AD12 -> 8087.52 | Q5: ='DJB Daily Readings'!AG13-'DJB Daily Readings'!AG12 -> 535.92 | R5: ='DJB Daily Readings'!AJ13-'DJB Daily Readings'!AJ12 -> 5115.6 | S5: ='DJB Daily Readings'!AM13-'DJB Daily Readings'!AM12 -> 3800.16 | T5: ='DJB Daily Readings'!AP13-'DJB Daily Readings'!AP12 -> 4530.96 | U5: ='DJB Daily Readings'!AS13-'DJB Daily Readings'!AS12 -> 2971.92 | V5: ='DJB Daily Readings'!AV13-'DJB Daily Readings'!AV12 -> 5748.96 | W5: ='DJB Daily Readings'!AZ13-'DJB Daily Readings'!AZ12 -> 0 | X5: ='DJB Daily Readings'!BC13-'DJB Daily Readings'!BC12 -> 32600 | Y5: ='DJB Daily Readings'!BF13-'DJB Daily Readings'!BF12 -> 3000 | Z5: =('DJB Daily Readings'!CK13-'DJB Daily Readings'!CK12)*1.89 -> 137.97 | AA5: =('DJB Daily Readings'!CN13-'DJB Daily Readings'!CN12)*1.89 -> 238.14 | AB5: =('DJB Daily Readings'!CQ13-'DJB Daily Readings'!CQ12)*1.89 -> 495.18 | AC5: ='DJB Daily Readings'!CT13-'DJB Daily Readings'!CT12 -> 172 | AD5: =('DJB Daily Readings'!BY13-'DJB Daily Readings'!BY12)*1.89 -> 28.35 | AE5: =('DJB Daily Readings'!CA13-'DJB Daily Readings'!CA12)*1.89 -> 37.8 | AF5: =('DJB Daily Readings'!CC13-'DJB Daily Readings'!CC12)*1.89 -> 13.23 | AG5: =('DJB Daily Readings'!CE13-'DJB Daily Readings'!CE12)*1.89 -> 18.9 | AH5: =('DJB Daily Readings'!CG13-'DJB Daily Readings'!CG12)*1.89 -> 30.24 | AI5: =('DJB Daily Readings'!CI13-'DJB Daily Readings'!CI12)*1.89 -> 68.04 | AJ5: ='DJB Daily Readings'!CY13-'DJB Daily Readings'!CY12 -> 5 | AK5: ='DJB Daily Readings'!CW13-'DJB Daily Readings'!CW12 -> 7 | AL5: ='DJB Daily Readings'!DC13-'DJB Daily Readings'!DC12 -> 15 | AM5: ='DJB Daily Readings'!DA13-'DJB Daily Readings'!DA12 -> 15 | AN5: ='DJB Daily Readings'!DG13-'DJB Daily Readings'!DG12 -> 5 | AO5: ='DJB Daily Readings'!DE13-'DJB Daily Readings'!DE12 -> 8 | AP5: ='DJB Daily Readings'!DK13-'DJB Daily Readings'!DK12 -> 11 | AQ5: ='DJB Daily Readings'!DI13-'DJB Daily Readings'!DI12 -> 12 | AR5: ='DJB Daily Readings'!DO13-'DJB Daily Readings'!DO12 -> 9 | AS5: ='DJB Daily Readings'!DM13-'DJB Daily Readings'!DM12 -> 6 | AT5: ='DJB Daily Readings'!DQ13-'DJB Daily Readings'!DQ12 -> 0 | AU5: ='DJB Daily Readings'!DT13-'DJB Daily Readings'!DT12 -> 11.8 | AW5: ='DJB Daily Readings'!DX13-'DJB Daily Readings'!DX12 -> 6.1 | AX5: ='DJB Daily Readings'!DZ13-'DJB Daily Readings'!DZ12 -> 7.9 | AY5: ='DJB Daily Readings'!EB13-'DJB Daily Readings'!EB12 -> 602 | AZ5: ='DJB Daily Readings'!ED13-'DJB Daily Readings'!ED12 -> 155.7 | BA5: ='DJB Daily Readings'!EG13-'DJB Daily Readings'!EG12 -> 2600 | BB5: ='DJB Daily Readings'!EI13-'DJB Daily Readings'!EI12 -> 220 | BC5: ='DJB Daily Readings'!EQ13-'DJB Daily Readings'!EQ12 -> 700 | BD5: ='DJB Daily Readings'!EK13-'DJB Daily Readings'!EK12 -> 800 | BE5: ='DJB Daily Readings'!EM13-'DJB Daily Readings'!EM12 -> 400 | BF5: ='DJB Daily Readings'!EO13-'DJB Daily Readings'!EO12 -> 620 | BG5: =('DJB Daily Readings'!ET13-'DJB Daily Readings'!ET12)*1.89 -> 32.13 | BH5: =('DJB Daily Readings'!EV13-'DJB Daily Readings'!EV12)*1.89 -> 22.68 | BI5: =('DJB Daily Readings'!EZ13-'DJB Daily Readings'!EZ12)*1.89 -> 26.46 | BJ5: =('DJB Daily Readings'!EX13-'DJB Daily Readings'!EX12)*1.89 -> 22.68 | BK5: =('DJB Daily Readings'!FB13-'DJB Daily Readings'!FB12)*1.89 -> 71.82 | BL5: ='DJB Daily Readings'!J13 -> 208
A6: Dubai at Jumeirah Beach | B6: =B5+1 -> 5 | C6: 2 | D6: 2023 | E6: =237*0.69 -> 163.53 | F6: =267+19 -> 286 | G6: ='DJB Daily Readings'!C14-'DJB Daily Readings'!C13 -> 533 | H6: ='DJB Daily Readings'!F14-'DJB Daily Readings'!F13 -> 425 | I6: ='DJB Daily Readings'!L13 -> 120 | J6: ='DJB Daily Readings'!N13 -> 16 | K6: ='DJB Daily Readings'!O14-'DJB Daily Readings'!O13 -> 71 | L6: ='DJB Daily Readings'!R14-'DJB Daily Readings'!R13 -> 10 | M6: ='DJB Daily Readings'!U14-'DJB Daily Readings'!U13 -> 1997.52 | N6: ='DJB Daily Readings'!X14-'DJB Daily Readings'!X13 -> 4774.56 | O6: ='DJB Daily Readings'!AA14-'DJB Daily Readings'!AA13 -> 1023.12 | P6: ='DJB Daily Readings'!AD14-'DJB Daily Readings'!AD13 -> 7551.6 | Q6: ='DJB Daily Readings'!AG14-'DJB Daily Readings'!AG13 -> 48.72 | R6: ='DJB Daily Readings'!AJ14-'DJB Daily Readings'!AJ13 -> 6138.72 | S6: ='DJB Daily Readings'!AM14-'DJB Daily Readings'!AM13 -> 3702.72 | T6: ='DJB Daily Readings'!AP14-'DJB Daily Readings'!AP13 -> 4287.36 | U6: ='DJB Daily Readings'!AS14-'DJB Daily Readings'!AS13 -> 3069.36 | V6: ='DJB Daily Readings'!AV14-'DJB Daily Readings'!AV13 -> 5602.8 | W6: ='DJB Daily Readings'!AZ14-'DJB Daily Readings'!AZ13 -> 4300 | X6: ='DJB Daily Readings'!BC14-'DJB Daily Readings'!BC13 -> 33100 | Y6: ='DJB Daily Readings'!BF14-'DJB Daily Readings'!BF13 -> 0 | Z6: =('DJB Daily Readings'!CK14-'DJB Daily Readings'!CK13)*1.89 -> 141.75 | AA6: =('DJB Daily Readings'!CN14-'DJB Daily Readings'!CN13)*1.89 -> 236.25 | AB6: =('DJB Daily Readings'!CQ14-'DJB Daily Readings'!CQ13)*1.89 -> 497.07 | AC6: ='DJB Daily Readings'!CT14-'DJB Daily Readings'!CT13 -> 174 | AD6: =('DJB Daily Readings'!BY14-'DJB Daily Readings'!BY13)*1.89 -> 30.24 | AE6: =('DJB Daily Readings'!CA14-'DJB Daily Readings'!CA13)*1.89 -> 41.58 | AF6: =('DJB Daily Readings'!CC14-'DJB Daily Readings'!CC13)*1.89 -> 11.34 | AG6: =('DJB Daily Readings'!CE14-'DJB Daily Readings'!CE13)*1.89 -> 17.01 | AH6: =('DJB Daily Readings'!CG14-'DJB Daily Readings'!CG13)*1.89 -> 28.35 | AI6: =('DJB Daily Readings'!CI14-'DJB Daily Readings'!CI13)*1.89 -> 64.26 | AJ6: ='DJB Daily Readings'!CY14-'DJB Daily Readings'!CY13 -> 4 | AK6: ='DJB Daily Readings'!CW14-'DJB Daily Readings'!CW13 -> 7 | AL6: ='DJB Daily Readings'!DC14-'DJB Daily Readings'!DC13 -> 16 | AM6: ='DJB Daily Readings'!DA14-'DJB Daily Readings'!DA13 -> 16 | AN6: ='DJB Daily Readings'!DG14-'DJB Daily Readings'!DG13 -> 4 | AO6: ='DJB Daily Readings'!DE14-'DJB Daily Readings'!DE13 -> 9 | AP6: ='DJB Daily Readings'!DK14-'DJB Daily Readings'!DK13 -> 9 | AQ6: ='DJB Daily Readings'!DI14-'DJB Daily Readings'!DI13 -> 12 | AR6: ='DJB Daily Readings'!DO14-'DJB Daily Readings'!DO13 -> 7 | AS6: ='DJB Daily Readings'!DM14-'DJB Daily Readings'!DM13 -> 3 | AT6: ='DJB Daily Readings'!DQ14-'DJB Daily Readings'!DQ13 -> 4 | AU6: ='DJB Daily Readings'!DT14-'DJB Daily Readings'!DT13 -> 10.8 | AW6: ='DJB Daily Readings'!DX14-'DJB Daily Readings'!DX13 -> 5.8 | AX6: ='DJB Daily Readings'!DZ14-'DJB Daily Readings'!DZ13 -> 7.5 | AY6: ='DJB Daily Readings'!EB14-'DJB Daily Readings'!EB13 -> 530 | AZ6: ='DJB Daily Readings'!ED14-'DJB Daily Readings'!ED13 -> 150.7 | BA6: ='DJB Daily Readings'!EG14-'DJB Daily Readings'!EG13 -> 2600 | BB6: ='DJB Daily Readings'!EI14-'DJB Daily Readings'!EI13 -> 250 | BC6: ='DJB Daily Readings'!EQ14-'DJB Daily Readings'!EQ13 -> 1200 | BD6: ='DJB Daily Readings'!EK14-'DJB Daily Readings'!EK13 -> 800 | BE6: ='DJB Daily Readings'!EM14-'DJB Daily Readings'!EM13 -> 500 | BF6: ='DJB Daily Readings'!EO14-'DJB Daily Readings'!EO13 -> 640 | BG6: =('DJB Daily Readings'!ET14-'DJB Daily Readings'!ET13)*1.89 -> 32.13 | BH6: =('DJB Daily Readings'!EV14-'DJB Daily Readings'!EV13)*1.89 -> 18.9 | BI6: =('DJB Daily Readings'!EZ14-'DJB Daily Readings'!EZ13)*1.89 -> 22.68 | BJ6: =('DJB Daily Readings'!EX14-'DJB Daily Readings'!EX13)*1.89 -> 18.9 | BK6: =('DJB Daily Readings'!FB14-'DJB Daily Readings'!FB13)*1.89 -> 58.59 | BL6: ='DJB Daily Readings'!J14 -> 225
A7: Dubai at Jumeirah Beach | B7: =B6+1 -> 6 | C7: 2 | D7: 2023 | E7: =237*0.72 -> 170.64 | F7: =273+17 -> 290 | G7: ='DJB Daily Readings'!C15-'DJB Daily Readings'!C14 -> 518 | H7: ='DJB Daily Readings'!F15-'DJB Daily Readings'!F14 -> 385 | I7: ='DJB Daily Readings'!L14 -> 224 | J7: ='DJB Daily Readings'!N14 -> 5 | K7: ='DJB Daily Readings'!O15-'DJB Daily Readings'!O14 -> 68 | L7: ='DJB Daily Readings'!R15-'DJB Daily Readings'!R14 -> 7 | M7: ='DJB Daily Readings'!U15-'DJB Daily Readings'!U14 -> 1948.8 | N7: ='DJB Daily Readings'!X15-'DJB Daily Readings'!X14 -> 4628.4 | O7: ='DJB Daily Readings'!AA15-'DJB Daily Readings'!AA14 -> 6333.6 | P7: ='DJB Daily Readings'!AD15-'DJB Daily Readings'!AD14 -> 1218 | Q7: ='DJB Daily Readings'!AG15-'DJB Daily Readings'!AG14 -> 1218 | R7: ='DJB Daily Readings'!AJ15-'DJB Daily Readings'!AJ14 -> 5554.08 | S7: ='DJB Daily Readings'!AM15-'DJB Daily Readings'!AM14 -> 3654 | T7: ='DJB Daily Readings'!AP15-'DJB Daily Readings'!AP14 -> 4530.96 | U7: ='DJB Daily Readings'!AS15-'DJB Daily Readings'!AS14 -> 3118.08 | V7: ='DJB Daily Readings'!AV15-'DJB Daily Readings'!AV14 -> 5505.36 | W7: ='DJB Daily Readings'!AZ15-'DJB Daily Readings'!AZ14 -> 34600 | X7: ='DJB Daily Readings'!BC15-'DJB Daily Readings'!BC14 -> 0 | Y7: ='DJB Daily Readings'!BF15-'DJB Daily Readings'!BF14 -> 4000 | Z7: =('DJB Daily Readings'!CK15-'DJB Daily Readings'!CK14)*1.89 -> 139.86 | AA7: =('DJB Daily Readings'!CN15-'DJB Daily Readings'!CN14)*1.89 -> 226.8 | AB7: =('DJB Daily Readings'!CQ15-'DJB Daily Readings'!CQ14)*1.89 -> 415.8 | AC7: ='DJB Daily Readings'!CT15-'DJB Daily Readings'!CT14 -> 173 | AD7: =('DJB Daily Readings'!BY15-'DJB Daily Readings'!BY14)*1.89 -> 32.13 | AE7: =('DJB Daily Readings'!CA15-'DJB Daily Readings'!CA14)*1.89 -> 39.69 | AF7: =('DJB Daily Readings'!CC15-'DJB Daily Readings'!CC14)*1.89 -> 11.34 | AG7: =('DJB Daily Readings'!CE15-'DJB Daily Readings'!CE14)*1.89 -> 17.01 | AH7: =('DJB Daily Readings'!CG15-'DJB Daily Readings'!CG14)*1.89 -> 30.24 | AI7: =('DJB Daily Readings'!CI15-'DJB Daily Readings'!CI14)*1.89 -> 64.26 | AJ7: ='DJB Daily Readings'!CY15-'DJB Daily Readings'!CY14 -> 2 | AK7: ='DJB Daily Readings'!CW15-'DJB Daily Readings'!CW14 -> 4 | AL7: ='DJB Daily Readings'!DC15-'DJB Daily Readings'!DC14 -> 12 | AM7: ='DJB Daily Readings'!DA15-'DJB Daily Readings'!DA14 -> 14 | AN7: ='DJB Daily Readings'!DG15-'DJB Daily Readings'!DG14 -> 5 | AO7: ='DJB Daily Readings'!DE15-'DJB Daily Readings'!DE14 -> 7 | AP7: ='DJB Daily Readings'!DK15-'DJB Daily Readings'!DK14 -> 9 | AQ7: ='DJB Daily Readings'!DI15-'DJB Daily Readings'!DI14 -> 7 | AR7: ='DJB Daily Readings'!DO15-'DJB Daily Readings'!DO14 -> 4 | AS7: ='DJB Daily Readings'!DM15-'DJB Daily Readings'!DM14 -> 6 | AT7: ='DJB Daily Readings'!DQ15-'DJB Daily Readings'!DQ14 -> 7 | AU7: ='DJB Daily Readings'!DT15-'DJB Daily Readings'!DT14 -> 10.9 | AW7: ='DJB Daily Readings'!DX15-'DJB Daily Readings'!DX14 -> 5.7 | AX7: ='DJB Daily Readings'!DZ15-'DJB Daily Readings'!DZ14 -> 6.3 | AY7: ='DJB Daily Readings'!EB15-'DJB Daily Readings'!EB14 -> 537 | AZ7: ='DJB Daily Readings'!ED15-'DJB Daily Readings'!ED14 -> 152.4 | BA7: ='DJB Daily Readings'!EG15-'DJB Daily Readings'!EG14 -> 2700 | BB7: ='DJB Daily Readings'!EI15-'DJB Daily Readings'!EI14 -> 250 | BC7: ='DJB Daily Readings'!EQ15-'DJB Daily Readings'!EQ14 -> 1200 | BD7: ='DJB Daily Readings'!EK15-'DJB Daily Readings'!EK14 -> 900 | BE7: ='DJB Daily Readings'!EM15-'DJB Daily Readings'!EM14 -> 400 | BF7: ='DJB Daily Readings'!EO15-'DJB Daily Readings'!EO14 -> 690 | BG7: =('DJB Daily Readings'!ET15-'DJB Daily Readings'!ET14)*1.89 -> 28.35 | BH7: =('DJB Daily Readings'!EV15-'DJB Daily Readings'!EV14)*1.89 -> 20.79 | BI7: =('DJB Daily Readings'!EZ15-'DJB Daily Readings'!EZ14)*1.89 -> 24.57 | BJ7: =('DJB Daily Readings'!EX15-'DJB Daily Readings'!EX14)*1.89 -> 17.01 | BK7: =('DJB Daily Readings'!FB15-'DJB Daily Readings'!FB14)*1.89 -> 54.81 | BL7: ='DJB Daily Readings'!J15 -> 183
A8: Dubai at Jumeirah Beach | B8: =B7+1 -> 7 | C8: 2 | D8: 2023 | E8: =237*0.58 -> 137.46 | F8: =223+18 -> 241 | G8: ='DJB Daily Readings'!C16-'DJB Daily Readings'!C15 -> 588 | H8: ='DJB Daily Readings'!F16-'DJB Daily Readings'!F15 -> 381 | I8: ='DJB Daily Readings'!L15 -> 152 | J8: ='DJB Daily Readings'!N15 -> 16 | K8: ='DJB Daily Readings'!O16-'DJB Daily Readings'!O15 -> 89 | L8: ='DJB Daily Readings'!R16-'DJB Daily Readings'!R15 -> 7 | M8: ='DJB Daily Readings'!U16-'DJB Daily Readings'!U15 -> 1948.8 | N8: ='DJB Daily Readings'!X16-'DJB Daily Readings'!X15 -> 4677.12 | O8: ='DJB Daily Readings'!AA16-'DJB Daily Readings'!AA15 -> 48.72 | P8: ='DJB Daily Readings'!AD16-'DJB Daily Readings'!AD15 -> 1851.36 | Q8: ='DJB Daily Readings'!AG16-'DJB Daily Readings'!AG15 -> 7795.2 | R8: ='DJB Daily Readings'!AJ16-'DJB Daily Readings'!AJ15 -> 5554.08 | S8: ='DJB Daily Readings'!AM16-'DJB Daily Readings'!AM15 -> 3995.04 | T8: ='DJB Daily Readings'!AP16-'DJB Daily Readings'!AP15 -> 4189.92 | U8: ='DJB Daily Readings'!AS16-'DJB Daily Readings'!AS15 -> 3264.24 | V8: ='DJB Daily Readings'!AV16-'DJB Daily Readings'!AV15 -> 5505.36 | W8: ='DJB Daily Readings'!AZ16-'DJB Daily Readings'!AZ15 -> 0 | X8: ='DJB Daily Readings'!BC16-'DJB Daily Readings'!BC15 -> 4300 | Y8: ='DJB Daily Readings'!BF16-'DJB Daily Readings'!BF15 -> 39800 | Z8: =('DJB Daily Readings'!CK16-'DJB Daily Readings'!CK15)*1.89 -> 143.64 | AA8: =('DJB Daily Readings'!CN16-'DJB Daily Readings'!CN15)*1.89 -> 213.57 | AB8: =('DJB Daily Readings'!CQ16-'DJB Daily Readings'!CQ15)*1.89 -> 383.67 | AC8: ='DJB Daily Readings'!CT16-'DJB Daily Readings'!CT15 -> 177 | AD8: =('DJB Daily Readings'!BY16-'DJB Daily Readings'!BY15)*1.89 -> 28.35 | AE8: =('DJB Daily Readings'!CA16-'DJB Daily Readings'!CA15)*1.89 -> 35.91 | AF8: =('DJB Daily Readings'!CC16-'DJB Daily Readings'!CC15)*1.89 -> 9.45 | AG8: =('DJB Daily Readings'!CE16-'DJB Daily Readings'!CE15)*1.89 -> 17.01 | AH8: =('DJB Daily Readings'!CG16-'DJB Daily Readings'!CG15)*1.89 -> 28.35 | AI8: =('DJB Daily Readings'!CI16-'DJB Daily Readings'!CI15)*1.89 -> 62.37 | AJ8: ='DJB Daily Readings'!CY16-'DJB Daily Readings'!CY15 -> 3 | AK8: ='DJB Daily Readings'!CW16-'DJB Daily Readings'!CW15 -> 5 | AL8: ='DJB Daily Readings'!DC16-'DJB Daily Readings'!DC15 -> 14 | AM8: ='DJB Daily Readings'!DA16-'DJB Daily Readings'!DA15 -> 3 | AN8: ='DJB Daily Readings'!DG16-'DJB Daily Readings'!DG15 -> 4 | AO8: ='DJB Daily Readings'!DE16-'DJB Daily Readings'!DE15 -> 7 | AP8: ='DJB Daily Readings'!DK16-'DJB Daily Readings'!DK15 -> 10 | AQ8: ='DJB Daily Readings'!DI16-'DJB Daily Readings'!DI15 -> 7 | AR8: ='DJB Daily Readings'!DO16-'DJB Daily Readings'!DO15 -> 4 | AS8: ='DJB Daily Readings'!DM16-'DJB Daily Readings'!DM15 -> 6 | AT8: ='DJB Daily Readings'!DQ16-'DJB Daily Readings'!DQ15 -> 0 | AU8: ='DJB Daily Readings'!DT16-'DJB Daily Readings'!DT15 -> 10 | AW8: ='DJB Daily Readings'!DX16-'DJB Daily Readings'!DX15 -> 5.9 | AX8: ='DJB Daily Readings'!DZ16-'DJB Daily Readings'!DZ15 -> 6.6 | AY8: ='DJB Daily Readings'!EB16-'DJB Daily Readings'!EB15 -> 520 | AZ8: ='DJB Daily Readings'!ED16-'DJB Daily Readings'!ED15 -> 151.8 | BA8: ='DJB Daily Readings'!EG16-'DJB Daily Readings'!EG15 -> 3000 | BB8: ='DJB Daily Readings'!EI16-'DJB Daily Readings'!EI15 -> 250 | BC8: ='DJB Daily Readings'!EQ16-'DJB Daily Readings'!EQ15 -> 2000 | BD8: ='DJB Daily Readings'!EK16-'DJB Daily Readings'!EK15 -> 1000 | BE8: ='DJB Daily Readings'!EM16-'DJB Daily Readings'!EM15 -> 400 | BF8: ='DJB Daily Readings'!EO16-'DJB Daily Readings'!EO15 -> 670 | BG8: =('DJB Daily Readings'!ET16-'DJB Daily Readings'!ET15)*1.89 -> 30.24 | BH8: =('DJB Daily Readings'!EV16-'DJB Daily Readings'!EV15)*1.89 -> 18.9 | BI8: =('DJB Daily Readings'!EZ16-'DJB Daily Readings'!EZ15)*1.89 -> 22.68 | BJ8: =('DJB Daily Readings'!EX16-'DJB Daily Readings'!EX15)*1.89 -> 17.01 | BK8: =('DJB Daily Readings'!FB16-'DJB Daily Readings'!FB15)*1.89 -> 60.48 | BL8: ='DJB Daily Readings'!J16 -> 201
A9: Dubai at Jumeirah Beach | B9: =B8+1 -> 8 | C9: 2 | D9: 2023 | E9: =237*0.68 -> 161.16 | F9: =245+23 -> 268 | G9: ='DJB Daily Readings'!C17-'DJB Daily Readings'!C16 -> 629 | H9: ='DJB Daily Readings'!F17-'DJB Daily Readings'!F16 -> 404 | I9: ='DJB Daily Readings'!L16 -> 220 | J9: ='DJB Daily Readings'!N16 -> 73 | K9: ='DJB Daily Readings'!O17-'DJB Daily Readings'!O16 -> 85 | L9: ='DJB Daily Readings'!R17-'DJB Daily Readings'!R16 -> 6 | M9: ='DJB Daily Readings'!U17-'DJB Daily Readings'!U16 -> 1997.52 | N9: ='DJB Daily Readings'!X17-'DJB Daily Readings'!X16 -> 4530.96 | O9: ='DJB Daily Readings'!AA17-'DJB Daily Readings'!AA16 -> 0 | P9: ='DJB Daily Readings'!AD17-'DJB Daily Readings'!AD16 -> 8282.4 | Q9: ='DJB Daily Readings'!AG17-'DJB Daily Readings'!AG16 -> 1656.48 | R9: ='DJB Daily Readings'!AJ17-'DJB Daily Readings'!AJ16 -> 5700.24 | S9: ='DJB Daily Readings'!AM17-'DJB Daily Readings'!AM16 -> 3848.88 | T9: ='DJB Daily Readings'!AP17-'DJB Daily Readings'!AP16 -> 4092.48 | U9: ='DJB Daily Readings'!AS17-'DJB Daily Readings'!AS16 -> 2728.32 | V9: ='DJB Daily Readings'!AV17-'DJB Daily Readings'!AV16 -> 5554.08 | W9: ='DJB Daily Readings'!AZ17-'DJB Daily Readings'!AZ16 -> 0 | X9: ='DJB Daily Readings'!BC17-'DJB Daily Readings'!BC16 -> 42200 | Y9: ='DJB Daily Readings'!BF17-'DJB Daily Readings'!BF16 -> 4200 | Z9: =('DJB Daily Readings'!CK17-'DJB Daily Readings'!CK16)*1.89 -> 141.75 | AA9: =('DJB Daily Readings'!CN17-'DJB Daily Readings'!CN16)*1.89 -> 223.02 | AB9: =('DJB Daily Readings'!CQ17-'DJB Daily Readings'!CQ16)*1.89 -> 487.62 | AC9: ='DJB Daily Readings'!CT17-'DJB Daily Readings'!CT16 -> 175 | AD9: =('DJB Daily Readings'!BY17-'DJB Daily Readings'!BY16)*1.89 -> 32.13 | AE9: =('DJB Daily Readings'!CA17-'DJB Daily Readings'!CA16)*1.89 -> 37.8 | AF9: =('DJB Daily Readings'!CC17-'DJB Daily Readings'!CC16)*1.89 -> 17.01 | AG9: =('DJB Daily Readings'!CE17-'DJB Daily Readings'!CE16)*1.89 -> 17.01 | AH9: =('DJB Daily Readings'!CG17-'DJB Daily Readings'!CG16)*1.89 -> 28.35 | AI9: =('DJB Daily Readings'!CI17-'DJB Daily Readings'!CI16)*1.89 -> 68.04 | AJ9: ='DJB Daily Readings'!CY17-'DJB Daily Readings'!CY16 -> 7 | AK9: ='DJB Daily Readings'!CW17-'DJB Daily Readings'!CW16 -> 13 | AL9: ='DJB Daily Readings'!DC17-'DJB Daily Readings'!DC16 -> 13 | AM9: ='DJB Daily Readings'!DA17-'DJB Daily Readings'!DA16 -> 4 | AN9: ='DJB Daily Readings'!DG17-'DJB Daily Readings'!DG16 -> 4 | AO9: ='DJB Daily Readings'!DE17-'DJB Daily Readings'!DE16 -> 8 | AP9: ='DJB Daily Readings'!DK17-'DJB Daily Readings'!DK16 -> 9 | AQ9: ='DJB Daily Readings'!DI17-'DJB Daily Readings'!DI16 -> 9 | AR9: ='DJB Daily Readings'!DO17-'DJB Daily Readings'!DO16 -> 5 | AS9: ='DJB Daily Readings'!DM17-'DJB Daily Readings'!DM16 -> 5 | AT9: ='DJB Daily Readings'!DQ17-'DJB Daily Readings'!DQ16 -> 6 | AU9: ='DJB Daily Readings'!DT17-'DJB Daily Readings'!DT16 -> 11.3 | AW9: ='DJB Daily Readings'!DX17-'DJB Daily Readings'!DX16 -> 5.8 | AX9: ='DJB Daily Readings'!DZ17-'DJB Daily Readings'!DZ16 -> 6.5 | AY9: ='DJB Daily Readings'!EB17-'DJB Daily Readings'!EB16 -> 511 | AZ9: ='DJB Daily Readings'!ED17-'DJB Daily Readings'!ED16 -> 152.3 | BA9: ='DJB Daily Readings'!EG17-'DJB Daily Readings'!EG16 -> 3200 | BB9: ='DJB Daily Readings'!EI17-'DJB Daily Readings'!EI16 -> 260 | BC9: ='DJB Daily Readings'!EQ17-'DJB Daily Readings'!EQ16 -> 3000 | BD9: ='DJB Daily Readings'!EK17-'DJB Daily Readings'!EK16 -> 1000 | BE9: ='DJB Daily Readings'!EM17-'DJB Daily Readings'!EM16 -> 300 | BF9: ='DJB Daily Readings'!EO17-'DJB Daily Readings'!EO16 -> 680 | BG9: =('DJB Daily Readings'!ET17-'DJB Daily Readings'!ET16)*1.89 -> 28.35 | BH9: =('DJB Daily Readings'!EV17-'DJB Daily Readings'!EV16)*1.89 -> 20.79 | BI9: =('DJB Daily Readings'!EZ17-'DJB Daily Readings'!EZ16)*1.89 -> 32.13 | BJ9: =('DJB Daily Readings'!EX17-'DJB Daily Readings'!EX16)*1.89 -> 15.12 | BK9: =('DJB Daily Readings'!FB17-'DJB Daily Readings'!FB16)*1.89 -> 51.03 | BL9: ='DJB Daily Readings'!J17 -> 198
A10: Dubai at Jumeirah Beach | B10: =B9+1 -> 9 | C10: 2 | D10: 2023 | E10: =237*0.7 -> 165.9 | F10: =263+37 -> 300 | G10: ='DJB Daily Readings'!C18-'DJB Daily Readings'!C17 -> 610 | H10: ='DJB Daily Readings'!F18-'DJB Daily Readings'!F17 -> 416 | I10: ='DJB Daily Readings'!L17 -> 264 | J10: ='DJB Daily Readings'!N17 -> 90 | K10: ='DJB Daily Readings'!O18-'DJB Daily Readings'!O17 -> 67 | L10: ='DJB Daily Readings'!R18-'DJB Daily Readings'!R17 -> 4 | M10: ='DJB Daily Readings'!U18-'DJB Daily Readings'!U17 -> 1997.52 | N10: ='DJB Daily Readings'!X18-'DJB Daily Readings'!X17 -> 4725.84 | O10: ='DJB Daily Readings'!AA18-'DJB Daily Readings'!AA17 -> 1023.12 | P10: ='DJB Daily Readings'!AD18-'DJB Daily Readings'!AD17 -> 1120.56 | Q10: ='DJB Daily Readings'!AG18-'DJB Daily Readings'!AG17 -> 6382.32 | R10: ='DJB Daily Readings'!AJ18-'DJB Daily Readings'!AJ17 -> 5554.08 | S10: ='DJB Daily Readings'!AM18-'DJB Daily Readings'!AM17 -> 3654 | T10: ='DJB Daily Readings'!AP18-'DJB Daily Readings'!AP17 -> 4336.08 | U10: ='DJB Daily Readings'!AS18-'DJB Daily Readings'!AS17 -> 2825.76 | V10: ='DJB Daily Readings'!AV18-'DJB Daily Readings'!AV17 -> 5505.36 | W10: ='DJB Daily Readings'!AZ18-'DJB Daily Readings'!AZ17 -> 4000 | X10: ='DJB Daily Readings'!BC18-'DJB Daily Readings'!BC17 -> 0 | Y10: ='DJB Daily Readings'!BF18-'DJB Daily Readings'!BF17 -> 31700 | Z10: =('DJB Daily Readings'!CK18-'DJB Daily Readings'!CK17)*1.89 -> 147.42 | AA10: =('DJB Daily Readings'!CN18-'DJB Daily Readings'!CN17)*1.89 -> 226.8 | AB10: =('DJB Daily Readings'!CQ18-'DJB Daily Readings'!CQ17)*1.89 -> 542.43 | AC10: ='DJB Daily Readings'!CT18-'DJB Daily Readings'!CT17 -> 187 | AD10: =('DJB Daily Readings'!BY18-'DJB Daily Readings'!BY17)*1.89 -> 28.35 | AE10: =('DJB Daily Readings'!CA18-'DJB Daily Readings'!CA17)*1.89 -> 37.8 | AF10: =('DJB Daily Readings'!CC18-'DJB Daily Readings'!CC17)*1.89 -> 13.23 | AG10: =('DJB Daily Readings'!CE18-'DJB Daily Readings'!CE17)*1.89 -> 17.01 | AH10: =('DJB Daily Readings'!CG18-'DJB Daily Readings'!CG17)*1.89 -> 26.46 | AI10: =('DJB Daily Readings'!CI18-'DJB Daily Readings'!CI17)*1.89 -> 68.04 | AJ10: ='DJB Daily Readings'!CY18-'DJB Daily Readings'!CY17 -> 6 | AK10: ='DJB Daily Readings'!CW18-'DJB Daily Readings'!CW17 -> 10 | AL10: ='DJB Daily Readings'!DC18-'DJB Daily Readings'!DC17 -> 12 | AM10: ='DJB Daily Readings'!DA18-'DJB Daily Readings'!DA17 -> 34 | AN10: ='DJB Daily Readings'!DG18-'DJB Daily Readings'!DG17 -> 4 | AO10: ='DJB Daily Readings'!DE18-'DJB Daily Readings'!DE17 -> 7 | AP10: ='DJB Daily Readings'!DK18-'DJB Daily Readings'!DK17 -> 6 | AQ10: ='DJB Daily Readings'!DI18-'DJB Daily Readings'!DI17 -> 10 | AR10: ='DJB Daily Readings'!DO18-'DJB Daily Readings'!DO17 -> 8 | AS10: ='DJB Daily Readings'!DM18-'DJB Daily Readings'!DM17 -> 4 | AT10: ='DJB Daily Readings'!DQ18-'DJB Daily Readings'!DQ17 -> 7 | AU10: ='DJB Daily Readings'!DT18-'DJB Daily Readings'!DT17 -> 10.7 | AW10: ='DJB Daily Readings'!DX18-'DJB Daily Readings'!DX17 -> 5.8 | AX10: ='DJB Daily Readings'!DZ18-'DJB Daily Readings'!DZ17 -> 6.2 | AY10: ='DJB Daily Readings'!EB18-'DJB Daily Readings'!EB17 -> 502 | AZ10: ='DJB Daily Readings'!ED18-'DJB Daily Readings'!ED17 -> 150.4 | BA10: ='DJB Daily Readings'!EG18-'DJB Daily Readings'!EG17 -> 2200 | BB10: ='DJB Daily Readings'!EI18-'DJB Daily Readings'!EI17 -> 240 | BC10: ='DJB Daily Readings'!EQ18-'DJB Daily Readings'!EQ17 -> 2000 | BD10: ='DJB Daily Readings'!EK18-'DJB Daily Readings'!EK17 -> 700 | BE10: ='DJB Daily Readings'!EM18-'DJB Daily Readings'!EM17 -> 300 | BF10: ='DJB Daily Readings'!EO18-'DJB Daily Readings'!EO17 -> 630 | BG10: =('DJB Daily Readings'!ET18-'DJB Daily Readings'!ET17)*1.89 -> 28.35 | BH10: =('DJB Daily Readings'!EV18-'DJB Daily Readings'!EV17)*1.89 -> 20.79 | BI10: =('DJB Daily Readings'!EZ18-'DJB Daily Readings'!EZ17)*1.89 -> 26.46 | BJ10: =('DJB Daily Readings'!EX18-'DJB Daily Readings'!EX17)*1.89 -> 17.01 | BK10: =('DJB Daily Readings'!FB18-'DJB Daily Readings'!FB17)*1.89 -> 54.81 | BL10: ='DJB Daily Readings'!J18 -> 195
A11: Dubai at Jumeirah Beach | B11: =B10+1 -> 10 | C11: 2 | D11: 2023 | E11: =237*0.67 -> 158.79 | F11: =265+43 -> 308 | G11: ='DJB Daily Readings'!C19-'DJB Daily Readings'!C18 -> 678 | H11: ='DJB Daily Readings'!F19-'DJB Daily Readings'!F18 -> 481 | I11: ='DJB Daily Readings'!L18 -> 271 | J11: ='DJB Daily Readings'!N18 -> 88 | K11: ='DJB Daily Readings'!O19-'DJB Daily Readings'!O18 -> 58 | L11: ='DJB Daily Readings'!R19-'DJB Daily Readings'!R18 -> 6 | M11: ='DJB Daily Readings'!U19-'DJB Daily Readings'!U18 -> 2046.24 | N11: ='DJB Daily Readings'!X19-'DJB Daily Readings'!X18 -> 4677.12 | O11: ='DJB Daily Readings'!AA19-'DJB Daily Readings'!AA18 -> 5992.56 | P11: ='DJB Daily Readings'!AD19-'DJB Daily Readings'!AD18 -> 2046.24 | Q11: ='DJB Daily Readings'!AG19-'DJB Daily Readings'!AG18 -> 0 | R11: ='DJB Daily Readings'!AJ19-'DJB Daily Readings'!AJ18 -> 5554.08 | S11: ='DJB Daily Readings'!AM19-'DJB Daily Readings'!AM18 -> 3946.32 | T11: ='DJB Daily Readings'!AP19-'DJB Daily Readings'!AP18 -> 4433.52 | U11: ='DJB Daily Readings'!AS19-'DJB Daily Readings'!AS18 -> 3069.36 | V11: ='DJB Daily Readings'!AV19-'DJB Daily Readings'!AV18 -> 5651.52 | W11: ='DJB Daily Readings'!AZ19-'DJB Daily Readings'!AZ18 -> 30500 | X11: ='DJB Daily Readings'!BC19-'DJB Daily Readings'!BC18 -> 3800 | Y11: ='DJB Daily Readings'!BF19-'DJB Daily Readings'!BF18 -> 0 | Z11: =('DJB Daily Readings'!CK19-'DJB Daily Readings'!CK18)*1.89 -> 149.31 | AA11: =('DJB Daily Readings'!CN19-'DJB Daily Readings'!CN18)*1.89 -> 234.36 | AB11: =('DJB Daily Readings'!CQ19-'DJB Daily Readings'!CQ18)*1.89 -> 555.66 | AC11: ='DJB Daily Readings'!CT19-'DJB Daily Readings'!CT18 -> 189 | AD11: =('DJB Daily Readings'!BY19-'DJB Daily Readings'!BY18)*1.89 -> 28.35 | AE11: =('DJB Daily Readings'!CA19-'DJB Daily Readings'!CA18)*1.89 -> 35.91 | AF11: =('DJB Daily Readings'!CC19-'DJB Daily Readings'!CC18)*1.89 -> 13.23 | AG11: =('DJB Daily Readings'!CE19-'DJB Daily Readings'!CE18)*1.89 -> 17.01 | AH11: =('DJB Daily Readings'!CG19-'DJB Daily Readings'!CG18)*1.89 -> 26.46 | AI11: =('DJB Daily Readings'!CI19-'DJB Daily Readings'!CI18)*1.89 -> 66.15 | AJ11: ='DJB Daily Readings'!CY19-'DJB Daily Readings'!CY18 -> 9 | AK11: ='DJB Daily Readings'!CW19-'DJB Daily Readings'!CW18 -> 12 | AL11: ='DJB Daily Readings'!DC19-'DJB Daily Readings'!DC18 -> 18 | AM11: ='DJB Daily Readings'!DA19-'DJB Daily Readings'!DA18 -> 17 | AN11: ='DJB Daily Readings'!DG19-'DJB Daily Readings'!DG18 -> 5 | AO11: ='DJB Daily Readings'!DE19-'DJB Daily Readings'!DE18 -> 9 | AP11: ='DJB Daily Readings'!DK19-'DJB Daily Readings'!DK18 -> 8 | AQ11: ='DJB Daily Readings'!DI19-'DJB Daily Readings'!DI18 -> 13 | AR11: ='DJB Daily Readings'!DO19-'DJB Daily Readings'!DO18 -> 10 | AS11: ='DJB Daily Readings'!DM19-'DJB Daily Readings'!DM18 -> 4 | AT11: ='DJB Daily Readings'!DQ19-'DJB Daily Readings'!DQ18 -> 6 | AU11: ='DJB Daily Readings'!DT19-'DJB Daily Readings'!DT18 -> 11.4 | AW11: ='DJB Daily Readings'!DX19-'DJB Daily Readings'!DX18 -> 6 | AX11: ='DJB Daily Readings'!DZ19-'DJB Daily Readings'!DZ18 -> 7.4 | AY11: ='DJB Daily Readings'!EB19-'DJB Daily Readings'!EB18 -> 553 | AZ11: ='DJB Daily Readings'!ED19-'DJB Daily Readings'!ED18 -> 157.9 | BA11: ='DJB Daily Readings'!EG19-'DJB Daily Readings'!EG18 -> 2400 | BB11: ='DJB Daily Readings'!EI19-'DJB Daily Readings'!EI18 -> 250 | BC11: ='DJB Daily Readings'!EQ19-'DJB Daily Readings'!EQ18 -> 1300 | BD11: ='DJB Daily Readings'!EK19-'DJB Daily Readings'!EK18 -> 800 | BE11: ='DJB Daily Readings'!EM19-'DJB Daily Readings'!EM18 -> 200 | BF11: ='DJB Daily Readings'!EO19-'DJB Daily Readings'!EO18 -> 680 | BG11: =('DJB Daily Readings'!ET19-'DJB Daily Readings'!ET18)*1.89 -> 26.46 | BH11: =('DJB Daily Readings'!EV19-'DJB Daily Readings'!EV18)*1.89 -> 22.68 | BI11: =('DJB Daily Readings'!EZ19-'DJB Daily Readings'!EZ18)*1.89 -> 32.13 | BJ11: =('DJB Daily Readings'!EX19-'DJB Daily Readings'!EX18)*1.89 -> 24.57 | BK11: =('DJB Daily Readings'!FB19-'DJB Daily Readings'!FB18)*1.89 -> 66.15 | BL11: ='DJB Daily Readings'!J19 -> 207
A12: Dubai at Jumeirah Beach | B12: =B11+1 -> 11 | C12: 2 | D12: 2023 | E12: =237*0.91 -> 215.67 | F12: =320+79 -> 399 | G12: ='DJB Daily Readings'!C20-'DJB Daily Readings'!C19 -> 584 | H12: ='DJB Daily Readings'!F20-'DJB Daily Readings'!F19 -> 460 | I12: ='DJB Daily Readings'!L19 -> 266 | J12: ='DJB Daily Readings'!N19 -> 80 | K12: ='DJB Daily Readings'!O20-'DJB Daily Readings'!O19 -> 62 | L12: ='DJB Daily Readings'!R20-'DJB Daily Readings'!R19 -> 3 | M12: ='DJB Daily Readings'!U20-'DJB Daily Readings'!U19 -> 2046.24 | N12: ='DJB Daily Readings'!X20-'DJB Daily Readings'!X19 -> 4725.84 | O12: ='DJB Daily Readings'!AA20-'DJB Daily Readings'!AA19 -> 97.44 | P12: ='DJB Daily Readings'!AD20-'DJB Daily Readings'!AD19 -> 6674.64 | Q12: ='DJB Daily Readings'!AG20-'DJB Daily Readings'!AG19 -> 1997.52 | R12: ='DJB Daily Readings'!AJ20-'DJB Daily Readings'!AJ19 -> 5456.64 | S12: ='DJB Daily Readings'!AM20-'DJB Daily Readings'!AM19 -> 3751.44 | T12: ='DJB Daily Readings'!AP20-'DJB Daily Readings'!AP19 -> 4482.24 | U12: ='DJB Daily Readings'!AS20-'DJB Daily Readings'!AS19 -> 3166.8 | V12: ='DJB Daily Readings'!AV20-'DJB Daily Readings'!AV19 -> 5651.52 | W12: ='DJB Daily Readings'!AZ20-'DJB Daily Readings'!AZ19 -> 0 | X12: ='DJB Daily Readings'!BC20-'DJB Daily Readings'!BC19 -> 33700 | Y12: ='DJB Daily Readings'!BF20-'DJB Daily Readings'!BF19 -> 3900 | Z12: =('DJB Daily Readings'!CK20-'DJB Daily Readings'!CK19)*1.89 -> 145.53 | AA12: =('DJB Daily Readings'!CN20-'DJB Daily Readings'!CN19)*1.89 -> 224.91 | AB12: =('DJB Daily Readings'!CQ20-'DJB Daily Readings'!CQ19)*1.89 -> 532.98 | AC12: ='DJB Daily Readings'!CT20-'DJB Daily Readings'!CT19 -> 185 | AD12: =('DJB Daily Readings'!BY20-'DJB Daily Readings'!BY19)*1.89 -> 35.91 | AE12: =('DJB Daily Readings'!CA20-'DJB Daily Readings'!CA19)*1.89 -> 43.47 | AF12: =('DJB Daily Readings'!CC20-'DJB Daily Readings'!CC19)*1.89 -> 9.45 | AG12: =('DJB Daily Readings'!CE20-'DJB Daily Readings'!CE19)*1.89 -> 17.01 | AH12: =('DJB Daily Readings'!CG20-'DJB Daily Readings'!CG19)*1.89 -> 32.13 | AI12: =('DJB Daily Readings'!CI20-'DJB Daily Readings'!CI19)*1.89 -> 73.71 | AJ12: ='DJB Daily Readings'!CY20-'DJB Daily Readings'!CY19 -> 5 | AK12: ='DJB Daily Readings'!CW20-'DJB Daily Readings'!CW19 -> 11 | AL12: ='DJB Daily Readings'!DC20-'DJB Daily Readings'!DC19 -> 14 | AM12: ='DJB Daily Readings'!DA20-'DJB Daily Readings'!DA19 -> 14 | AN12: ='DJB Daily Readings'!DG20-'DJB Daily Readings'!DG19 -> 3 | AO12: ='DJB Daily Readings'!DE20-'DJB Daily Readings'!DE19 -> 8 | AP12: ='DJB Daily Readings'!DK20-'DJB Daily Readings'!DK19 -> 11 | AQ12: ='DJB Daily Readings'!DI20-'DJB Daily Readings'!DI19 -> 11 | AR12: ='DJB Daily Readings'!DO20-'DJB Daily Readings'!DO19 -> 9 | AS12: ='DJB Daily Readings'!DM20-'DJB Daily Readings'!DM19 -> 4 | AT12: ='DJB Daily Readings'!DQ20-'DJB Daily Readings'!DQ19 -> 1 | AU12: ='DJB Daily Readings'!DT20-'DJB Daily Readings'!DT19 -> 11.2 | AW12: ='DJB Daily Readings'!DX20-'DJB Daily Readings'!DX19 -> 5.9 | AX12: ='DJB Daily Readings'!DZ20-'DJB Daily Readings'!DZ19 -> 7.7 | AY12: ='DJB Daily Readings'!EB20-'DJB Daily Readings'!EB19 -> 580 | AZ12: ='DJB Daily Readings'!ED20-'DJB Daily Readings'!ED19 -> 152 | BA12: ='DJB Daily Readings'!EG20-'DJB Daily Readings'!EG19 -> 2500 | BB12: ='DJB Daily Readings'!EI20-'DJB Daily Readings'!EI19 -> 240 | BC12: ='DJB Daily Readings'!EQ20-'DJB Daily Readings'!EQ19 -> 1400 | BD12: ='DJB Daily Readings'!EK20-'DJB Daily Readings'!EK19 -> 800 | BE12: ='DJB Daily Readings'!EM20-'DJB Daily Readings'!EM19 -> 300 | BF12: ='DJB Daily Readings'!EO20-'DJB Daily Readings'!EO19 -> 620 | BG12: =('DJB Daily Readings'!ET20-'DJB Daily Readings'!ET19)*1.89 -> 28.35 | BH12: =('DJB Daily Readings'!EV20-'DJB Daily Readings'!EV19)*1.89 -> 18.9 | BI12: =('DJB Daily Readings'!EZ20-'DJB Daily Readings'!EZ19)*1.89 -> 30.24 | BJ12: =('DJB Daily Readings'!EX20-'DJB Daily Readings'!EX19)*1.89 -> 26.46 | BK12: =('DJB Daily Readings'!FB20-'DJB Daily Readings'!FB19)*1.89 -> 64.26 | BL12: ='DJB Daily Readings'!J20 -> 378
A13: Dubai at Jumeirah Beach | B13: =B12+1 -> 12 | C13: 2 | D13: 2023 | E13: =237*0.91 -> 215.67 | F13: =335+56 -> 391 | G13: ='DJB Daily Readings'!C21-'DJB Daily Readings'!C20 -> 576 | H13: ='DJB Daily Readings'!F21-'DJB Daily Readings'!F20 -> 462 | I13: ='DJB Daily Readings'!L20 -> 132 | J13: ='DJB Daily Readings'!N20 -> 13 | K13: ='DJB Daily Readings'!O21-'DJB Daily Readings'!O20 -> 78 | L13: ='DJB Daily Readings'!R21-'DJB Daily Readings'!R20 -> 3 | M13: ='DJB Daily Readings'!U21-'DJB Daily Readings'!U20 -> 1997.52 | N13: ='DJB Daily Readings'!X21-'DJB Daily Readings'!X20 -> 4628.4 | O13: ='DJB Daily Readings'!AA21-'DJB Daily Readings'!AA20 -> 1023.12 | P13: ='DJB Daily Readings'!AD21-'DJB Daily Readings'!AD20 -> 48.72 | Q13: ='DJB Daily Readings'!AG21-'DJB Daily Readings'!AG20 -> 8331.12 | R13: ='DJB Daily Readings'!AJ21-'DJB Daily Readings'!AJ20 -> 5748.96 | S13: ='DJB Daily Readings'!AM21-'DJB Daily Readings'!AM20 -> 3848.88 | T13: ='DJB Daily Readings'!AP21-'DJB Daily Readings'!AP20 -> 4482.24 | U13: ='DJB Daily Readings'!AS21-'DJB Daily Readings'!AS20 -> 3312.96 | V13: ='DJB Daily Readings'!AV21-'DJB Daily Readings'!AV20 -> 5554.08 | W13: ='DJB Daily Readings'!AZ21-'DJB Daily Readings'!AZ20 -> 4000 | X13: ='DJB Daily Readings'!BC21-'DJB Daily Readings'!BC20 -> 0 | Y13: ='DJB Daily Readings'!BF21-'DJB Daily Readings'!BF20 -> 36600 | Z13: =('DJB Daily Readings'!CK21-'DJB Daily Readings'!CK20)*1.89 -> 149.31 | AA13: =('DJB Daily Readings'!CN21-'DJB Daily Readings'!CN20)*1.89 -> 230.58 | AB13: =('DJB Daily Readings'!CQ21-'DJB Daily Readings'!CQ20)*1.89 -> 542.43 | AC13: ='DJB Daily Readings'!CT21-'DJB Daily Readings'!CT20 -> 189 | AD13: =('DJB Daily Readings'!BY21-'DJB Daily Readings'!BY20)*1.89 -> 32.13 | AE13: =('DJB Daily Readings'!CA21-'DJB Daily Readings'!CA20)*1.89 -> 39.69 | AF13: =('DJB Daily Readings'!CC21-'DJB Daily Readings'!CC20)*1.89 -> 15.12 | AG13: =('DJB Daily Readings'!CE21-'DJB Daily Readings'!CE20)*1.89 -> 18.9 | AH13: =('DJB Daily Readings'!CG21-'DJB Daily Readings'!CG20)*1.89 -> 28.35 | AI13: =('DJB Daily Readings'!CI21-'DJB Daily Readings'!CI20)*1.89 -> 66.15 | AJ13: ='DJB Daily Readings'!CY21-'DJB Daily Readings'!CY20 -> 3 | AK13: ='DJB Daily Readings'!CW21-'DJB Daily Readings'!CW20 -> 6 | AL13: ='DJB Daily Readings'!DC21-'DJB Daily Readings'!DC20 -> 15 | AM13: ='DJB Daily Readings'!DA21-'DJB Daily Readings'!DA20 -> 16 | AN13: ='DJB Daily Readings'!DG21-'DJB Daily Readings'!DG20 -> 6 | AO13: ='DJB Daily Readings'!DE21-'DJB Daily Readings'!DE20 -> 10 | AP13: ='DJB Daily Readings'!DK21-'DJB Daily Readings'!DK20 -> 8 | AQ13: ='DJB Daily Readings'!DI21-'DJB Daily Readings'!DI20 -> 12 | AR13: ='DJB Daily Readings'!DO21-'DJB Daily Readings'!DO20 -> 9 | AS13: ='DJB Daily Readings'!DM21-'DJB Daily Readings'!DM20 -> 4 | AT13: ='DJB Daily Readings'!DQ21-'DJB Daily Readings'!DQ20 -> 0 | AU13: ='DJB Daily Readings'!DT21-'DJB Daily Readings'!DT20 -> 3.8 | AW13: ='DJB Daily Readings'!DX21-'DJB Daily Readings'!DX20 -> 5.9 | AX13: ='DJB Daily Readings'!DZ21-'DJB Daily Readings'!DZ20 -> 6.9 | AY13: ='DJB Daily Readings'!EB21-'DJB Daily Readings'!EB20 -> 586 | AZ13: ='DJB Daily Readings'!ED21-'DJB Daily Readings'!ED20 -> 152.3 | BA13: ='DJB Daily Readings'!EG21-'DJB Daily Readings'!EG20 -> 3000 | BB13: ='DJB Daily Readings'!EI21-'DJB Daily Readings'!EI20 -> 260 | BC13: ='DJB Daily Readings'!EQ21-'DJB Daily Readings'!EQ20 -> 1800 | BD13: ='DJB Daily Readings'!EK21-'DJB Daily Readings'!EK20 -> 900 | BE13: ='DJB Daily Readings'!EM21-'DJB Daily Readings'!EM20 -> 200 | BF13: ='DJB Daily Readings'!EO21-'DJB Daily Readings'!EO20 -> 710 | BG13: =('DJB Daily Readings'!ET21-'DJB Daily Readings'!ET20)*1.89 -> 28.35 | BH13: =('DJB Daily Readings'!EV21-'DJB Daily Readings'!EV20)*1.89 -> 22.68 | BI13: =('DJB Daily Readings'!EZ21-'DJB Daily Readings'!EZ20)*1.89 -> 24.57 | BJ13: =('DJB Daily Readings'!EX21-'DJB Daily Readings'!EX20)*1.89 -> 20.79 | BK13: =('DJB Daily Readings'!FB21-'DJB Daily Readings'!FB20)*1.89 -> 58.59 | BL13: ='DJB Daily Readings'!J21 -> 269
