Workbook

Sheet Utility Consnsumption
E6: HL&P Utility Consumption | H6: =Elect!A1 -> 44896
B9: Electric Power Consumption
B11: Chiller Central Plant | D11: Guest Rooms | F11: Public areas / Utilities Power & Light | H11: Grumandize | J11: Total Consumption | L11: Total First Arabian bill
B12: KW.hr | C12: LE | D12: KW.hr | E12: LE | F12: KW.hr | G12: LE | H12: KW.hr | I12: LE | J12: KW.hr | K12: LE | L12: KW.hr | M12: LE
B13: =Elect!AN37 -> 172525.16 | C13: =(B13*1.15)+(2879*60*0.72) -> 322776.73 | D13: =Elect!J37 -> 195595.22 | E13: =(D13*1.15)+(573*60)+10000 -> 269314.51 | F13: =Elect!BI37 -> 382141.79 | G13: =(F13*1.15) -> 439463.06 | H13: =Elect!Q37 -> 14785 | I13: =H13*1.6+1500 -> 25156 | J13: =B13+D13+F13+H13 -> 765047.17 | K13: =G13+E13+C13+I13 -> 1056710.3 | L13: =B13+F13 -> 554666.95 | M13: =C13+G13 -> 762239.79
K16: =K18 -> 1389950.4
E17: Water Consumption / As per share ratio | J17: Average elec Tariff | K17: =K13/J13 -> 1.3812355
J18: Utilties total EGP | K18: =K13+F20+F27+G35 -> 1389950.4
E19: M3 | F19: LE
E20: =Water!H38 -> 10279.968 | F20: =E20*10 -> 102799.68
E24: Natural Gas Consumption
E26: M3 | F26: LE
E27: =Gas!C38 -> 47727.118 | F27: =E27*3.9 -> 186135.76
D31: Plant Room Gas Share ( STEAM)
D33: Last Reading | E33: Present Reading | F33: M 3 | G33: LE
D34: =Gas!D6 -> 598602.33 | E34: =Gas!D36 -> 614265.22 | F34: =Gas!E38 -> 11360.164 | G34: =F34*3.9 -> 44304.639
D35: Total Amount | G35: =G34 -> 44304.639
D38: Casino Electricity Charge
D40: Last Reading | E40: Present Reading | F40: KW.hr | G40: LE
C41: Casino 3rd floor EM | D41: =Elect!R5 -> 226100.67 | E41: =Elect!R36 -> 230535.33 | F41: =E41-D41 -> 4434.6667 | G41: =F41*1.15 -> 5099.8667
C42: Casino 3rd floor Normal | D42: =Elect!T5 -> 412645.67 | E42: =Elect!T36 -> 420593.17 | F42: =E42-D42 -> 7947.5 | G42: =F42*1.15 -> 9139.625
D43: Total Amount | G43: =G42+G41 -> 14239.492
D49: New Casino Water Charge
D51: Last Reading | E51: Present Reading | F51: M3 | G51: LE
C52: Hot Water | D52: 310 | E52: 322 | F52: 12 | G52: =F52*10 -> 120
C53: Cold Water | D53: 5476 | E53: 5583 | F53: 107 | G53: =F53*10 -> 1070
D54: Total Amount | G54: =G52+G53 -> 1190

Sheet Total
A1: Site Name | B1: Day | C1: Month | D1: Year | E1: Total Electricity Kwh | F1: Electricity Tariff ($/Kwh) | G1: Natual Gas (m3) | H1: Natural Gas $/m3 | I1: Water Utility Supply (m3) m3 | J1: Water Utility Supply (m3) $/m3 | K1: Room Nights
A2: Cairo at The First Residence | B2: 1 | C2: 12 | D2: 2022 | E2: =Elect!BS6+Submetering!AH2 -> 26916.463 | F2: ='Utility Consnsumption'!K13/'Utility Consnsumption'!J13 -> 1.3812355 | G2: =Gas!K7+Submetering!AR2 -> 1803.1867 | H2: 3.8 | I2: =Water!H7+Submetering!AM2 -> 819.15333 | J2: 10 | K2: =Elect!BT6 -> 210
A3: Cairo at The First Residence | B3: =B2+1 -> 2 | C3: 12 | D3: 2022 | E3: =Elect!BS7+Submetering!AH3 -> 24471.715 | F3: =F2 -> 1.3812355 | G3: =Gas!K8+Submetering!AR3 -> 1988.8 | H3: 3.8 | I3: =Water!H8+Submetering!AM3 -> 179.54222 | J3: 10 | K3: =Elect!BT7 -> 242
A4: Cairo at The First Residence | B4: =B3+1 -> 3 | C4: 12 | D4: 2022 | E4: =Elect!BS8+Submetering!AH4 -> 25340.555 | F4: =F3 -> 1.3812355 | G4: =Gas!K9+Submetering!AR4 -> 1988.8 | H4: 3.8 | I4: =Water!H9+Submetering!AM4 -> 239.41111 | J4: 10 | K4: =Elect!BT8 -> 225
A5: Cairo at The First Residence | B5: =B4+1 -> 4 | C5: 12 | D5: 2022 | E5: =Elect!BS9+Submetering!AH5 -> 25596.628 | F5: =F4 -> 1.3812355 | G5: =Gas!K10+Submetering!AR5 -> 1981.8 | H5: 3.8 | I5: =Water!H10+Submetering!AM5 -> 272.98667 | J5: 10 | K5: =Elect!BT9 -> 236
A6: Cairo at The First Residence | B6: =B5+1 -> 5 | C6: 12 | D6: 2022 | E6: =Elect!BS10+Submetering!AH6 -> 25205.725 | F6: =F5 -> 1.3812355 | G6: =Gas!K11+Submetering!AR6 -> 1981.8 | H6: 3.8 | I6: =Water!H11+Submetering!AM6 -> 325.38 | J6: 10 | K6: =Elect!BT10 -> 216
A7: Cairo at The First Residence | B7: =B6+1 -> 6 | C7: 12 | D7: 2022 | E7: =Elect!BS11+Submetering!AH7 -> 23281.213 | F7: =F6 -> 1.3812355 | G7: =Gas!K12+Submetering!AR7 -> 1960.1 | H7: 3.8 | I7: =Water!H12+Submetering!AM7 -> 314.94 | J7: 10 | K7: =Elect!BT11 -> 198
A8: Cairo at The First Residence | B8: =B7+1 -> 7 | C8: 12 | D8: 2022 | E8: =Elect!BS12+Submetering!AH8 -> 28001.118 | F8: =F7 -> 1.3812355 | G8: =Gas!K13+Submetering!AR8 -> 1974.5667 | H8: 3.8 | I8: =Water!H13+Submetering!AM8 -> 258.29333 | J8: 10 | K8: =Elect!BT12 -> 184
A9: Cairo at The First Residence | B9: =B8+1 -> 8 | C9: 12 | D9: 2022 | E9: =Elect!BS13+Submetering!AH9 -> 24074.52 | F9: =F8 -> 1.3812355 | G9: =Gas!K14+Submetering!AR9 -> 1970.95 | H9: 3.8 | I9: =Water!H14+Submetering!AM9 -> 307.4 | J9: 10 | K9: =Elect!BT13 -> 184
A10: Cairo at The First Residence | B10: =B9+1 -> 9 | C10: 12 | D10: 2022 | E10: =Elect!BS14+Submetering!AH10 -> 23862.13 | F10: =F9 -> 1.3812355 | G10: =Gas!K15+Submetering!AR10 -> 1258.6833 | H10: 3.8 | I10: =Water!H15+Submetering!AM10 -> 380.28667 | J10: 10 | K10: =Elect!BT14 -> 183
A11: Cairo at The First Residence | B11: =B10+1 -> 10 | C11: 12 | D11: 2022 | E11: =Elect!BS15+Submetering!AH11 -> 23009.75 | F11: =F10 -> 1.3812355 | G11: =Gas!K16+Submetering!AR11 -> 1777.88 | H11: 3.8 | I11: =Water!H16+Submetering!AM11 -> 290.58 | J11: 10 | K11: =Elect!BT15 -> 207
A12: Cairo at The First Residence | B12: =B11+1 -> 11 | C12: 12 | D12: 2022 | E12: =Elect!BS16+Submetering!AH12 -> 26167.805 | F12: =F11 -> 1.3812355 | G12: =Gas!K17+Submetering!AR12 -> 1747.92 | H12: 3.8 | I12: =Water!H17+Submetering!AM12 -> 309.14 | J12: 10 | K12: =Elect!BT16 -> 236
A13: Cairo at The First Residence | B13: =B12+1 -> 12 | C13: 12 | D13: 2022 | E13: =Elect!BS17+Submetering!AH13 -> 24475.062 | F13: =F12 -> 1.3812355 | G13: =Gas!K18+Submetering!AR13 -> 1865.68 | H13: 3.8 | I13: =Water!H18+Submetering!AM13 -> 311.46 | J13: 10 | K13: =Elect!BT17 -> 236
A14: Cairo at The First Residence | B14: =B13+1 -> 13 | C14: 12 | D14: 2022 | E14: =Elect!BS18+Submetering!AH14 -> 26495.435 | F14: =F13 -> 1.3812355 | G14: =Gas!K19+Submetering!AR14 -> 1566.7613 | H14: 3.8 | I14: =Water!H19+Submetering!AM14 -> 327.85467 | J14: 10 | K14: =Elect!BT18 -> 234
... A32: Cairo at The First Residence | B32: =B31+1 -> 31 | C32: 12 | D32: 2022 | E32: =Elect!BS36+Submetering!AH32 -> 22940.956 | F32: =F31 -> 1.3812355 | G32: =Gas!K37+Submetering!AR32 -> 1818.9267 | H32: 3.8 | I32: =Water!H37+Submetering!AM32 -> 327.555 | J32: 10 | K32: =Elect!BT36 -> 236.33333

Sheet Submetering
A1: Site Name | B1: Day | C1: Month | D1: Year | E1: Electricity | F1: Main Feeder -KWh | G1: T2+T8 -KWh | H1: La Gourmandize -KWh | I1: Casino 3rd floor EM -KWh | J1: Casino 3rd floor Normal -KWh | K1: Chiller 1 -KWh | L1: Chiller 2 -KWh | M1: Chiller 3 -KWh | N1: Chiller 4 -KWh | O1: Chiller 5 -KWh | P1: Chiller 6 -KWh | Q1: Cooling towers -KWh | R1: Chiller Pumps -KWh | S1: Cooling Tower Pumps -KWh | T1: Fiber Chiller -KWh | U1: Mall Ceiling light -KWh | V1: LG Bakery -KWh | W1: LG Bakery light ( Old lockers ) -KWh | X1: MCCR1 -KWh | Y1: Children Swimming Pool -KWh | Z1: DPH1 -KWh | AA1: Guest Rooms Emerg. -KWh | AB1: Hotel Hoods -KWh | AC1: Main G2 -KWh | AD1: Old Casino Emergency -KWh | AE1: L / A -KWh | AF1: L / B -KWh | AG1: L / C -KWh | AH1: Boat -KWh | AI1: Water | AJ1: Main water meter 1 -m3 | AK1: Main water meter 2 -m3 | AL1: Main water meter 3 -m3 | AM1: Boat -m3 | AN1: Gas | AO1: Main Gas Flow Meter -m3 | AP1: Laundry Gas Flow Meter -m3 | AQ1: Gourmandize Gas Flow Meter -m3 | AR1: Boat -m3 | AS1: Room Nights
A2: Cairo at The First Residence | B2: 1 | C2: 12 | D2: 2022 | F2: =Elect!J6 -> 5035.1667 | G2: =Elect!K6 -> 4149.3333 | H2: =Elect!Q6 -> 510 | I2: =Elect!S6 -> 138.33333 | J2: =Elect!U6 -> 224.33333 | K2: =Elect!W6 -> 3837.5533 | L2: =Elect!Y6 -> 0 | M2: =Elect!AA6 -> 2646.82 | N2: =Elect!AC6 -> 0 | O2: =Elect!AE6 -> 12.72 | P2: =Elect!AG6 -> 8.3033333 | Q2: =Elect!AI6 -> 368.085 | R2: =Elect!AK6 -> 2130.9533 | S2: =Elect!AM6 -> 126.67 | T2: =Elect!AP6 -> 173.325 | U2: =Elect!AR6 -> 187 | V2: =Elect!AT6 -> 117.33333 | W2: =Elect!AV6 -> 46.166667 | X2: =Elect!AX6 -> 1079.1667 | Y2: =Elect!AZ6 -> 10.333333 | Z2: =Elect!BB6 -> 4754.6667 | AA2: =Elect!BD6 -> 236 | AB2: =Elect!BF6 -> 0 | AC2: =Elect!BH6 -> 5636.2 | AD2: =Elect!BL6 -> 338 | AE2: =Elect!BN6 -> 967 | AF2: =Elect!BP6 -> 137 | AG2: =Elect!BR6 -> 136.33333 | AH2: =Boat!C4 -> 0 | AJ2: =Water!C7 -> 253.26667 | AK2: =Water!E7 -> 322.86667 | AL2: =Water!G7 -> 243.02 | AM2: =Boat!E4 -> 0 | AO2: =Gas!C7 -> 1396.02 | AP2: =Gas!E7 -> 407.16667 | AQ2: =Gas!G7 -> 65.444444 | AR2: =Boat!G4 -> 0 | AS2: =Elect!BT6 -> 210
A3: Cairo at The First Residence | B3: =B2+1 -> 2 | C3: 12 | D3: 2022 | F3: =Elect!J7 -> 6579 | G3: =Elect!K7 -> 3507 | H3: =Elect!Q7 -> 510 | I3: =Elect!S7 -> 137 | J3: =Elect!U7 -> 251 | K3: =Elect!W7 -> 988.98 | L3: =Elect!Y7 -> 0 | M3: =Elect!AA7 -> 2176.71 | N3: =Elect!AC7 -> 0 | O3: =Elect!AE7 -> 9.54 | P3: =Elect!AG7 -> 11.66 | Q3: =Elect!AI7 -> 328.6 | R3: =Elect!AK7 -> 2198.97 | S3: =Elect!AM7 -> 111.83 | T3: =Elect!AP7 -> 125.325 | U3: =Elect!AR7 -> 211 | V3: =Elect!AT7 -> 155 | W3: =Elect!AV7 -> 30 | X3: =Elect!AX7 -> 922 | Y3: =Elect!AZ7 -> 10 | Z3: =Elect!BB7 -> 4485 | AA3: =Elect!BD7 -> 201 | AB3: =Elect!BF7 -> 10 | AC3: =Elect!BH7 -> 5407.1 | AD3: =Elect!BL7 -> 263 | AE3: =Elect!BN7 -> 875 | AF3: =Elect!BP7 -> 127 | AG3: =Elect!BR7 -> 134 | AH3: =Boat!C5 -> 0 | AJ3: =Water!C8 -> 22.555556 | AK3: =Water!E8 -> 35.766667 | AL3: =Water!G8 -> 121.22 | AM3: =Boat!E5 -> 0 | AO3: =Gas!C8 -> 1643 | AP3: =Gas!E8 -> 345.8 | AQ3: =Gas!G8 -> 90.888889 | AR3: =Boat!G5 -> 0 | AS3: =Elect!BT7 -> 242
A4: Cairo at The First Residence | B4: =B3+1 -> 3 | C4: 12 | D4: 2022 | F4: =Elect!J8 -> 5998 | G4: =Elect!K8 -> 3618 | H4: =Elect!Q8 -> 480 | I4: =Elect!S8 -> 139 | J4: =Elect!U8 -> 257 | K4: =Elect!W8 -> 3490.05 | L4: =Elect!Y8 -> 0 | M4: =Elect!AA8 -> 0 | N4: =Elect!AC8 -> 0 | O4: =Elect!AE8 -> 13.25 | P4: =Elect!AG8 -> 12.19 | Q4: =Elect!AI8 -> 393.79 | R4: =Elect!AK8 -> 2473.51 | S4: =Elect!AM8 -> 115.54 | T4: =Elect!AP8 -> 147.375 | U4: =Elect!AR8 -> 183 | V4: =Elect!AT8 -> 144 | W4: =Elect!AV8 -> 32 | X4: =Elect!AX8 -> 976 | Y4: =Elect!AZ8 -> 11 | Z4: =Elect!BB8 -> 4908 | AA4: =Elect!BD8 -> 216 | AB4: =Elect!BF8 -> 100 | AC4: =Elect!BH8 -> 5646.85 | AD4: =Elect!BL8 -> 270 | AE4: =Elect!BN8 -> 1040 | AF4: =Elect!BP8 -> 107 | AG4: =Elect!BR8 -> 149 | AH4: =Boat!C6 -> 0 | AJ4: =Water!C9 -> 85.711111 | AK4: =Water!E9 -> 107.3 | AL4: =Water!G9 -> 46.4 | AM4: =Boat!E6 -> 0 | AO4: =Gas!C9 -> 1643 | AP4: =Gas!E9 -> 345.8 | AQ4: =Gas!G9 -> 81.333333 | AR4: =Boat!G6 -> 0 | AS4: =Elect!BT8 -> 225
A5: Cairo at The First Residence | B5: =B4+1 -> 4 | C5: 12 | D5: 2022 | F5: =Elect!J9 -> 6469 | G5: =Elect!K9 -> 3537 | H5: =Elect!Q9 -> 510 | I5: =Elect!S9 -> 143 | J5: =Elect!U9 -> 263 | K5: =Elect!W9 -> 448.38 | L5: =Elect!Y9 -> 0 | M5: =Elect!AA9 -> 2972.24 | N5: =Elect!AC9 -> 0 | O5: =Elect!AE9 -> 13.78 | P5: =Elect!AG9 -> 12.19 | Q5: =Elect!AI9 -> 204.05 | R5: =Elect!AK9 -> 2271.05 | S5: =Elect!AM9 -> 111.3 | T5: =Elect!AP9 -> 151.5375 | U5: =Elect!AR9 -> 191 | V5: =Elect!AT9 -> 160 | W5: =Elect!AV9 -> 32 | X5: =Elect!AX9 -> 924 | Y5: =Elect!AZ9 -> 10 | Z5: =Elect!BB9 -> 5200 | AA5: =Elect!BD9 -> 227 | AB5: =Elect!BF9 -> 0 | AC5: =Elect!BH9 -> 5689.1 | AD5: =Elect!BL9 -> 278 | AE5: =Elect!BN9 -> 1025 | AF5: =Elect!BP9 -> 137 | AG5: =Elect!BR9 -> 153 | AH5: =Boat!C7 -> 0 | AJ5: =Water!C10 -> 83.133333 | AK5: =Water!E10 -> 106.33333 | AL5: =Water!G10 -> 83.52 | AM5: =Boat!E7 -> 0 | AO5: =Gas!C10 -> 1643 | AP5: =Gas!E10 -> 338.8 | AQ5: =Gas!G10 -> 95.666667 | AR5: =Boat!G7 -> 0 | AS5: =Elect!BT9 -> 236
A6: Cairo at The First Residence | B6: =B5+1 -> 5 | C6: 12 | D6: 2022 | F6: =Elect!J10 -> 6327 | G6: =Elect!K10 -> 4093 | H6: =Elect!Q10 -> 450 | I6: =Elect!S10 -> 144 | J6: =Elect!U10 -> 257 | K6: =Elect!W10 -> 2495.24 | L6: =Elect!Y10 -> 0 | M6: =Elect!AA10 -> 958.24 | N6: =Elect!AC10 -> 0 | O6: =Elect!AE10 -> 13.25 | P6: =Elect!AG10 -> 12.19 | Q6: =Elect!AI10 -> 191.86 | R6: =Elect!AK10 -> 2385 | S6: =Elect!AM10 -> 118.72 | T6: =Elect!AP10 -> 131.625 | U6: =Elect!AR10 -> 203 | V6: =Elect!AT10 -> 150 | W6: =Elect!AV10 -> 34 | X6: =Elect!AX10 -> 951 | Y6: =Elect!AZ10 -> 11 | Z6: =Elect!BB10 -> 4895 | AA6: =Elect!BD10 -> 242 | AB6: =Elect!BF10 -> 5 | AC6: =Elect!BH10 -> 5631.6 | AD6: =Elect!BL10 -> 281 | AE6: =Elect!BN10 -> 986 | AF6: =Elect!BP10 -> 146 | AG6: =Elect!BR10 -> 157 | AH6: =Boat!C8 -> 0 | AJ6: =Water!C11 -> 87 | AK6: =Water!E11 -> 110.2 | AL6: =Water!G11 -> 128.18 | AM6: =Boat!E8 -> 0 | AO6: =Gas!C11 -> 1643 | AP6: =Gas!E11 -> 338.8 | AQ6: =Gas!G11 -> 97 | AR6: =Boat!G8 -> 0 | AS6: =Elect!BT10 -> 216
A7: Cairo at The First Residence | B7: =B6+1 -> 6 | C7: 12 | D7: 2022 | F7: =Elect!J11 -> 6729 | G7: =Elect!K11 -> 3438 | H7: =Elect!Q11 -> 450 | I7: =Elect!S11 -> 148 | J7: =Elect!U11 -> 268 | K7: =Elect!W11 -> 620.63 | L7: =Elect!Y11 -> 0 | M7: =Elect!AA11 -> 169.6 | N7: =Elect!AC11 -> 0 | O7: =Elect!AE11 -> 13.78 | P7: =Elect!AG11 -> 11.66 | Q7: =Elect!AI11 -> 160.59 | R7: =Elect!AK11 -> 2593.82 | S7: =Elect!AM11 -> 116.07 | T7: =Elect!AP11 -> 125.2125 | U7: =Elect!AR11 -> 200 | V7: =Elect!AT11 -> 131 | W7: =Elect!AV11 -> 33 | X7: =Elect!AX11 -> 1073 | Y7: =Elect!AZ11 -> 11 | Z7: =Elect!BB11 -> 4663 | AA7: =Elect!BD11 -> 233 | AB7: =Elect!BF11 -> 108 | AC7: =Elect!BH11 -> 5838.85 | AD7: =Elect!BL11 -> 286 | AE7: =Elect!BN11 -> 1042 | AF7: =Elect!BP11 -> 145 | AG7: =Elect!BR11 -> 158 | AH7: =Boat!C9 -> 0 | AJ7: =Water!C12 -> 81.2 | AK7: =Water!E12 -> 104.4 | AL7: =Water!G12 -> 129.34 | AM7: =Boat!E9 -> 0 | AO7: =Gas!C12 -> 1643 | AP7: =Gas!E12 -> 317.1 | AQ7: =Gas!G12 -> 95 | AR7: =Boat!G9 -> 0 | AS7: =Elect!BT11 -> 198
A8: Cairo at The First Residence | B8: =B7+1 -> 7 | C8: 12 | D8: 2022 | F8: =Elect!J12 -> 6469 | G8: =Elect!K12 -> 4925 | H8: =Elect!Q12 -> 480 | I8: =Elect!S12 -> 139 | J8: =Elect!U12 -> 254 | K8: =Elect!W12 -> 5764.81 | L8: =Elect!Y12 -> 0 | M8: =Elect!AA12 -> 43.46 | N8: =Elect!AC12 -> 0 | O8: =Elect!AE12 -> 13.25 | P8: =Elect!AG12 -> 12.19 | Q8: =Elect!AI12 -> 216.77 | R8: =Elect!AK12 -> 2291.19 | S8: =Elect!AM12 -> 117.66 | T8: =Elect!AP12 -> 157.3875 | U8: =Elect!AR12 -> 195 | V8: =Elect!AT12 -> 162 | W8: =Elect!AV12 -> 46 | X8: =Elect!AX12 -> 827 | Y8: =Elect!AZ12 -> 11 | Z8: =Elect!BB12 -> 5060 | AA8: =Elect!BD12 -> 246 | AB8: =Elect!BF12 -> 72 | AC8: =Elect!BH12 -> 5816.4 | AD8: =Elect!BL12 -> 275 | AE8: =Elect!BN12 -> 1145 | AF8: =Elect!BP12 -> 143 | AG8: =Elect!BR12 -> 153 | AH8: =Boat!C10 -> 0 | AJ8: =Water!C13 -> 85.066667 | AK8: =Water!E13 -> 108.26667 | AL8: =Water!G13 -> 64.96 | AM8: =Boat!E10 -> 0 | AO8: =Gas!C13 -> 1643 | AP8: =Gas!E13 -> 331.56667 | AQ8: =Gas!G13 -> 96.333333 | AR8: =Boat!G10 -> 0 | AS8: =Elect!BT12 -> 184
A9: Cairo at The First Residence | B9: =B8+1 -> 8 | C9: 12 | D9: 2022 | F9: =Elect!J13 -> 6399 | G9: =Elect!K13 -> 4015 | H9: =Elect!Q13 -> 510 | I9: =Elect!S13 -> 142 | J9: =Elect!U13 -> 256 | K9: =Elect!W13 -> 2300.73 | L9: =Elect!Y13 -> 0 | M9: =Elect!AA13 -> 37.1 | N9: =Elect!AC13 -> 1.59 | O9: =Elect!AE13 -> 13.25 | P9: =Elect!AG13 -> 12.19 | Q9: =Elect!AI13 -> 286.73 | R9: =Elect!AK13 -> 2312.39 | S9: =Elect!AM13 -> 112.89 | T9: =Elect!AP13 -> 70.65 | U9: =Elect!AR13 -> 197 | V9: =Elect!AT13 -> 201 | W9: =Elect!AV13 -> 41 | X9: =Elect!AX13 -> 923 | Y9: =Elect!AZ13 -> 124 | Z9: =Elect!BB13 -> 4707 | AA9: =Elect!BD13 -> 241 | AB9: =Elect!BF13 -> 70 | AC9: =Elect!BH13 -> 5514 | AD9: =Elect!BL13 -> 167 | AE9: =Elect!BN13 -> 1204 | AF9: =Elect!BP13 -> 136 | AG9: =Elect!BR13 -> 151 | AH9: =Boat!C11 -> 0 | AJ9: =Water!C14 -> 84.1 | AK9: =Water!E14 -> 107.3 | AL9: =Water!G14 -> 116 | AM9: =Boat!E11 -> 0 | AO9: =Gas!C14 -> 1643 | AP9: =Gas!E14 -> 327.95 | AQ9: =Gas!G14 -> 96 | AR9: =Boat!G11 -> 0 | AS9: =Elect!BT13 -> 184
A10: Cairo at The First Residence | B10: =B9+1 -> 9 | C10: 12 | D10: 2022 | F10: =Elect!J14 -> 6217 | G10: =Elect!K14 -> 4022 | H10: =Elect!Q14 -> 450 | I10: =Elect!S14 -> 141 | J10: =Elect!U14 -> 257 | K10: =Elect!W14 -> 2243.49 | L10: =Elect!Y14 -> 0 | M10: =Elect!AA14 -> 251.22 | N10: =Elect!AC14 -> 0 | O10: =Elect!AE14 -> 12.19 | P10: =Elect!AG14 -> 11.13 | Q10: =Elect!AI14 -> 311.11 | R10: =Elect!AK14 -> 2160.28 | S10: =Elect!AM14 -> 115.01 | T10: =Elect!AP14 -> 84.15 | U10: =Elect!AR14 -> 217 | V10: =Elect!AT14 -> 171 | W10: =Elect!AV14 -> 41 | X10: =Elect!AX14 -> 917 | Y10: =Elect!AZ14 -> 493 | Z10: =Elect!BB14 -> 4453 | AA10: =Elect!BD14 -> 228 | AB10: =Elect!BF14 -> 89 | AC10: =Elect!BH14 -> 5397.55 | AD10: =Elect!BL14 -> 75 | AE10: =Elect!BN14 -> 1147 | AF10: =Elect!BP14 -> 134 | AG10: =Elect!BR14 -> 152 | AH10: =Boat!C12 -> 0 | AJ10: =Water!C15 -> 80.233333 | AK10: =Water!E15 -> 103.43333 | AL10: =Water!G15 -> 196.62 | AM10: =Boat!E12 -> 0 | AO10: =Gas!C15 -> 874.5 | AP10: =Gas!E15 -> 384.18333 | AQ10: =Gas!G15 -> 90.666667 | AR10: =Boat!G12 -> 0 | AS10: =Elect!BT14 -> 183
A11: Cairo at The First Residence | B11: =B10+1 -> 10 | C11: 12 | D11: 2022 | F11: =Elect!J15 -> 6463 | G11: =Elect!K15 -> 4149 | H11: =Elect!Q15 -> 510 | I11: =Elect!S15 -> 142 | J11: =Elect!U15 -> 265 | K11: =Elect!W15 -> 2414.68 | L11: =Elect!Y15 -> 0 | M11: =Elect!AA15 -> 0 | N11: =Elect!AC15 -> 0 | O11: =Elect!AE15 -> 12.19 | P11: =Elect!AG15 -> 11.66 | Q11: =Elect!AI15 -> 236.91 | R11: =Elect!AK15 -> 1837.51 | S11: =Elect!AM15 -> 116.6 | T11: =Elect!AP15 -> 93.15 | U11: =Elect!AR15 -> 197 | V11: =Elect!AT15 -> 176 | W11: =Elect!AV15 -> 40 | X11: =Elect!AX15 -> 900 | Y11: =Elect!AZ15 -> 10 | Z11: =Elect!BB15 -> 4001 | AA11: =Elect!BD15 -> 213 | AB11: =Elect!BF15 -> 70 | AC11: =Elect!BH15 -> 5707.05 | AD11: =Elect!BL15 -> 189 | AE11: =Elect!BN15 -> 1182 | AF11: =Elect!BP15 -> 129 | AG11: =Elect!BR15 -> 135 | AH11: =Boat!C13 -> 0 | AJ11: =Water!C16 -> 75.4 | AK11: =Water!E16 -> 92.8 | AL11: =Water!G16 -> 122.38 | AM11: =Boat!E13 -> 0 | AO11: =Gas!C16 -> 1471.28 | AP11: =Gas!E16 -> 306.6 | AQ11: =Gas!G16 -> 90 | AR11: =Boat!G13 -> 0 | AS11: =Elect!BT15 -> 207
A12: Cairo at The First Residence | B12: =B11+1 -> 11 | C12: 12 | D12: 2022 | F12: =Elect!J16 -> 6856 | G12: =Elect!K16 -> 4055 | H12: =Elect!Q16 -> 450 | I12: =Elect!S16 -> 143 | J12: =Elect!U16 -> 267 | K12: =Elect!W16 -> 2371.22 | L12: =Elect!Y16 -> 0 | M12: =Elect!AA16 -> 132.5 | N12: =Elect!AC16 -> 0 | O12: =Elect!AE16 -> 12.72 | P12: =Elect!AG16 -> 11.66 | Q12: =Elect!AI16 -> 248.04 | R12: =Elect!AK16 -> 2050.04 | S12: =Elect!AM16 -> 116.6 | T12: =Elect!AP16 -> 76.725 | U12: =Elect!AR16 -> 198 | V12: =Elect!AT16 -> 184 | W12: =Elect!AV16 -> 42 | X12: =Elect!AX16 -> 933 | Y12: =Elect!AZ16 -> 477 | Z12: =Elect!BB16 -> 5759 | AA12: =Elect!BD16 -> 248 | AB12: =Elect!BF16 -> 50 | AC12: =Elect!BH16 -> 5951.3 | AD12: =Elect!BL16 -> 231 | AE12: =Elect!BN16 -> 1198 | AF12: =Elect!BP16 -> 148 | AG12: =Elect!BR16 -> 129 | AH12: =Boat!C14 -> 0 | AJ12: =Water!C17 -> 81.2 | AK12: =Water!E17 -> 104.4 | AL12: =Water!G17 -> 123.54 | AM12: =Boat!E14 -> 0 | AO12: =Gas!C17 -> 1411.92 | AP12: =Gas!E17 -> 336 | AQ12: =Gas!G17 -> 88 | AR12: =Boat!G14 -> 0 | AS12: =Elect!BT16 -> 236
A13: Cairo at The First Residence | B13: =B12+1 -> 12 | C13: 12 | D13: 2022 | F13: =Elect!J17 -> 6916 | G13: =Elect!K17 -> 3705 | H13: =Elect!Q17 -> 420 | I13: =Elect!S17 -> 142 | J13: =Elect!U17 -> 264 | K13: =Elect!W17 -> 2666.43 | L13: =Elect!Y17 -> 0 | M13: =Elect!AA17 -> 0 | N13: =Elect!AC17 -> 0 | O13: =Elect!AE17 -> 13.25 | P13: =Elect!AG17 -> 11.66 | Q13: =Elect!AI17 -> 278.25 | R13: =Elect!AK17 -> 2156.04 | S13: =Elect!AM17 -> 116.07 | T13: =Elect!AP17 -> 96.4125 | U13: =Elect!AR17 -> 208 | V13: =Elect!AT17 -> 194 | W13: =Elect!AV17 -> 43 | X13: =Elect!AX17 -> 899 | Y13: =Elect!AZ17 -> 10 | Z13: =Elect!BB17 -> 4536 | AA13: =Elect!BD17 -> 249 | AB13: =Elect!BF17 -> 15 | AC13: =Elect!BH17 -> 5646.95 | AD13: =Elect!BL17 -> 240 | AE13: =Elect!BN17 -> 1167 | AF13: =Elect!BP17 -> 162 | AG13: =Elect!BR17 -> 136 | AH13: =Boat!C15 -> 0 | AJ13: =Water!C18 -> 87 | AK13: =Water!E18 -> 104.4 | AL13: =Water!G18 -> 120.06 | AM13: =Boat!E15 -> 0 | AO13: =Gas!C18 -> 1503.08 | AP13: =Gas!E18 -> 362.6 | AQ13: =Gas!G18 -> 91 | AR13: =Boat!G15 -> 0 | AS13: =Elect!BT17 -> 236
A14: Cairo at The First Residence | B14: =B13+1 -> 13 | C14: 12 | D14: 2022 | F14: =Elect!J18 -> 8015 | G14: =Elect!K18 -> 3681 | H14: =Elect!Q18 -> 450 | I14: =Elect!S18 -> 144 | J14: =Elect!U18 -> 264 | K14: =Elect!W18 -> 3150.85 | L14: =Elect!Y18 -> 0 | M14: =Elect!AA18 -> 0 | N14: =Elect!AC18 -> 0 | O14: =Elect!AE18 -> 12.72 | P14: =Elect!AG18 -> 12.19 | Q14: =Elect!AI18 -> 307.4 | R14: =Elect!AK18 -> 2283.24 | S14: =Elect!AM18 -> 117.66 | T14: =Elect!AP18 -> 86.625 | U14: =Elect!AR18 -> 195 | V14: =Elect!AT18 -> 200 | W14: =Elect!AV18 -> 44 | X14: =Elect!AX18 -> 921 | Y14: =Elect!AZ18 -> 11 | Z14: =Elect!BB18 -> 4783 | AA14: =Elect!BD18 -> 253 | AB14: =Elect!BF18 -> 59 | AC14: =Elect!BH18 -> 5593.75 | AD14: =Elect!BL18 -> 245 | AE14: =Elect!BN18 -> 1176 | AF14: =Elect!BP18 -> 149 | AG14: =Elect!BR18 -> 146 | AH14: =Boat!C16 -> 0 | AJ14: =Water!C19 -> 76.753333 | AK14: =Water!E19 -> 98.213333 | AL14: =Water!G19 -> 152.888 | AM14: =Boat!E16 -> 0 | AO14: =Gas!C19 -> 1231.508 | AP14: =Gas!E19 -> 335.25333 | AQ14: =Gas!G19 -> 91.711111 | AR14: =Boat!G16 -> 0 | AS14: =Elect!BT18 -> 234
... A32: Cairo at The First Residence | B32: =B31+1 -> 31 | C32: 12 | D32: 2022 | F32: =Elect!J36 -> 5918.5 | G32: =Elect!K36 -> 4221 | H32: =Elect!Q36 -> 525 | I32: =Elect!S36 -> 146 | J32: =Elect!U36 -> 238.5 | K32: =Elect!W36 -> 2183.865 | L32: =Elect!Y36 -> 0 | M32: =Elect!AA36 -> 0 | N32: =Elect!AC36 -> 0 | O32: =Elect!AE36 -> 12.985 | P32: =Elect!AG36 -> 12.19 | Q32: =Elect!AI36 -> 272.685 | R32: =Elect!AK36 -> 1550.78 | S32: =Elect!AM36 -> 114.745 | T32: =Elect!AP36 -> 139.33125 | U32: =Elect!AR36 -> 216 | V32: =Elect!AT36 -> 107.5 | W32: =Elect!AV36 -> 43.5 | X32: =Elect!AX36 -> 927.5 | Y32: =Elect!AZ36 -> 11 | Z32: =Elect!BB36 -> 5346.5 | AA32: =Elect!BD36 -> 203.5 | AB32: =Elect!BF36 -> 40 | AC32: =Elect!BH36 -> 5315.375 | AD32: =Elect!BL36 -> 238.5 | AE32: =Elect!BN36 -> 1103.5 | AF32: =Elect!BP36 -> 129 | AG32: =Elect!BR36 -> 153 | AH32: =Boat!C34 -> 0 | AJ32: =Water!C37 -> 88.45 | AK32: =Water!E37 -> 124.12 | AL32: =Water!G37 -> 114.985 | AM32: =Boat!E34 -> 0 | AO32: =Gas!C37 -> 1422.785 | AP32: =Gas!E37 -> 396.14167 | AQ32: =Gas!G37 -> 84.361111 | AR32: =Boat!G34 -> 0 | AS32: =Elect!BT36 -> 236.33333

Sheet Boat
B1: Electricity | D1: Water | F1: Gas
B2: Read | C2: Cons | D2: Read | E2: Cons | F2: Read | G2: Cons
B3: 0 | D3: 0 | F3: 0
A4: 1 | B4: 0 | C4: =B4-B3 -> 0 | D4: 0 | E4: =D4-D3 -> 0 | F4: 0 | G4: =F4-F3 -> 0
A5: 2 | B5: 0 | C5: =B5-B4 -> 0 | D5: 0 | E5: =D5-D4 -> 0 | F5: 0 | G5: =F5-F4 -> 0
A6: 3 | B6: 0 | C6: =B6-B5 -> 0 | D6: 0 | E6: =D6-D5 -> 0 | F6: 0 | G6: =F6-F5 -> 0
A7: 4 | B7: 0 | C7: =B7-B6 -> 0 | D7: 0 | E7: =D7-D6 -> 0 | F7: 0 | G7: =F7-F6 -> 0
A8: 5 | B8: 0 | C8: =B8-B7 -> 0 | D8: 0 | E8: =D8-D7 -> 0 | F8: 0 | G8: =F8-F7 -> 0
A9: 6 | B9: 0 | C9: =B9-B8 -> 0 | D9: 0 | E9: =D9-D8 -> 0 | F9: 0 | G9: =F9-F8 -> 0
A10: 7 | B10: 0 | C10: =B10-B9 -> 0 | D10: 0 | E10: =D10-D9 -> 0 | F10: 0 | G10: =F10-F9 -> 0
A11: 8 | B11: 0 | C11: =B11-B10 -> 0 | D11: 0 | E11: =D11-D10 -> 0 | F11: 0 | G11: =F11-F10 -> 0
A12: 9 | B12: 0 | C12: =B12-B11 -> 0 | D12: 0 | E12: =D12-D11 -> 0 | F12: 0 | G12: =F12-F11 -> 0
A13: 10 | B13: 0 | C13: =B13-B12 -> 0 | D13: 0 | E13: =D13-D12 -> 0 | F13: 0 | G13: =F13-F12 -> 0
A14: 11 | B14: 0 | C14: =B14-B13 -> 0 | D14: 0 | E14: =D14-D13 -> 0 | F14: 0 | G14: =F14-F13 -> 0
A15: 12 | B15: 0 | C15: =B15-B14 -> 0 | D15: 0 | E15: =D15-D14 -> 0 | F15: 0 | G15: =F15-F14 -> 0
... A34: 31 | B34: 0 | C34: =B34-B33 -> 0 | D34: 0 | E34: =D34-D33 -> 0 | F34: 0 | G34: =F34-F33 -> 0
A35: Sum | C35: =SUM(C4:C34) -> 0 | E35: =SUM(E4:E34) -> 0 | G35: =SUM(G4:G34) -> 0

Sheet Water
A1: =Elect!A1 -> 44896 | T1: Main Water UP | V1: 4 | W1: Water Truck UP
A3: Day | E3: Water Incoming | I3: New casino | N3: Rooms Consumption | P3: Public Areas consumption | R3: Swimming pool | T3: No. of rooms | U3: Cons. Per occ. room | V3: No. of guest | W3: Cons. Per guest | X3: Total cost | Y3: L.E\ | Z3: L.E\
B4: Main water meter 1 | D4: Main water meter 2 | F4: Main water meter 3 | H4: Total Inc. | I4: Hot water | K4: Cold water | N4: Express Riser | O4: Consp. | P4: Read. | Q4: Cons. | R4: Read. | S4: Cons. | Y4: Room | Z4: Guest
B5: Counter | C5: Produc 58% | D5: Counter | E5: Produc 58% | F5: Counter | G5: Produc 58% | I5: Counter | K5: Counter
B6: 90135.333 | C6: =IF(B6>=B5,B6-B5,0)*10*0.58 -> 0 | D6: 13386.333 | E6: =IF(D6>=D5,D6-D5,0)*10*0.58 -> 0 | F6: 61792 | G6: =IF(F6>=F5,F6-F5,0)*0.58 -> 0 | I6: 310 | K6: 5476
A7: 1 | B7: 90179 | C7: =IF(B7>=B6,B7-B6,0)*10*0.58 -> 253.26667 | D7: 13442 | E7: =IF(D7>=D6,D7-D6,0)*10*0.58 -> 322.86667 | F7: 62211 | G7: =IF(F7>=F6,F7-F6,0)*0.58 -> 243.02 | H7: =C7+E7+G7 -> 819.15333 | O7: =IF(N7>=N6,N7-N6,0) -> 0 | Q7: =(H7-O7)*0.58 -> 475.10893 | S7: =IF(R7-R6>0,R7-R6,0) -> 0 | T7: =Elect!BT6 -> 210 | U7: =H7/T7 -> 3.9007302 | V7: =Elect!BV6 -> 0 | W7: =H7/V7 -> #DIV/0! | X7: =H7*V1 -> 3276.6133 | Y7: =IF(X7>0,X7/T7,0) -> 15.602921 | Z7: 0
A8: 2 | B8: 90182.889 | C8: =IF(B8>=B7,B8-B7,0)*10*0.58 -> 22.555556 | D8: 13448.167 | E8: =IF(D8>=D7,D8-D7,0)*10*0.58 -> 35.766667 | F8: 62420 | G8: =IF(F8>=F7,F8-F7,0)*0.58 -> 121.22 | H8: =C8+E8+G8 -> 179.54222 | O8: =IF(N8>=N7,N8-N7,0) -> 0 | Q8: =(H8-O8)*0.58 -> 104.13449 | S8: =IF(R8-R7>0,R8-R7,0) -> 0 | T8: =Elect!BT7 -> 242 | U8: =H8/T8 -> 0.74191001 | V8: =Elect!BV7 -> 0 | W8: =H8/V8 -> #DIV/0! | X8: =H8*V1 -> 718.16889 | Y8: =IF(X8>0,X8/T8,0) -> 2.96764 | Z8: =IF(X8>0,X8/V8,0) -> #DIV/0!
A9: 3 | B9: 90197.667 | C9: =IF(B9>=B8,B9-B8,0)*10*0.58 -> 85.711111 | D9: 13466.667 | E9: =IF(D9>=D8,D9-D8,0)*10*0.58 -> 107.3 | F9: 62500 | G9: =IF(F9>=F8,F9-F8,0)*0.58 -> 46.4 | H9: =C9+E9+G9 -> 239.41111 | O9: =IF(N9>=N8,N9-N8,0) -> 0 | Q9: =(H9-O9)*0.58 -> 138.85844 | S9: =IF(R9-R8>0,R9-R8,0) -> 0 | T9: =Elect!BT8 -> 225 | U9: =H9/T9 -> 1.0640494 | V9: =Elect!BV8 -> 0 | W9: =H9/V9 -> #DIV/0! | X9: =H9*V1 -> 957.64444 | Y9: =IF(X9>0,X9/T9,0) -> 4.2561975 | Z9: =IF(X9>0,X9/V9,0) -> #DIV/0!
A10: 4 | B10: 90212 | C10: =IF(B10>=B9,B10-B9,0)*10*0.58 -> 83.133333 | D10: 13485 | E10: =IF(D10>=D9,D10-D9,0)*10*0.58 -> 106.33333 | F10: 62644 | G10: =IF(F10>=F9,F10-F9,0)*0.58 -> 83.52 | H10: =C10+E10+G10 -> 272.98667 | O10: =IF(N10>=N9,N10-N9,0) -> 0 | Q10: =(H10-O10)*0.58 -> 158.33227 | S10: =IF(R10-R9>0,R10-R9,0) -> 0 | T10: =Elect!BT9 -> 236 | U10: =H10/T10 -> 1.1567232 | V10: =Elect!BV9 -> 0 | W10: =H10/V10 -> #DIV/0! | X10: =H10*V1 -> 1091.9467 | Y10: =IF(X10>0,X10/T10,0) -> 4.6268927 | Z10: =IF(X10>0,X10/V10,0) -> #DIV/0!
A11: 5 | B11: 90227 | C11: =IF(B11>=B10,B11-B10,0)*10*0.58 -> 87 | D11: 13504 | E11: =IF(D11>=D10,D11-D10,0)*10*0.58 -> 110.2 | F11: 62865 | G11: =IF(F11>=F10,F11-F10,0)*0.58 -> 128.18 | H11: =C11+E11+G11 -> 325.38 | O11: =IF(N11>=N10,N11-N10,0) -> 0 | Q11: =(H11-O11)*0.58 -> 188.7204 | S11: =IF(R11-R10>0,R11-R10,0) -> 0 | T11: =Elect!BT10 -> 216 | U11: =H11/T11 -> 1.5063889 | V11: =Elect!BV10 -> 0 | W11: =H11/V11 -> #DIV/0! | X11: =H11*V1 -> 1301.52 | Y11: =IF(X11>0,X11/T11,0) -> 6.0255556 | Z11: =IF(X11>0,X11/V11,0) -> #DIV/0!
A12: 6 | B12: 90241 | C12: =IF(B12>=B11,B12-B11,0)*10*0.58 -> 81.2 | D12: 13522 | E12: =IF(D12>=D11,D12-D11,0)*10*0.58 -> 104.4 | F12: 63088 | G12: =IF(F12>=F11,F12-F11,0)*0.58 -> 129.34 | H12: =C12+E12+G12 -> 314.94 | O12: =IF(N12>=N11,N12-N11,0) -> 0 | Q12: =(H12-O12)*0.58 -> 182.6652 | S12: =IF(R12-R11>0,R12-R11,0) -> 0 | T12: =Elect!BT11 -> 198 | U12: =H12/T12 -> 1.5906061 | V12: =Elect!BV11 -> 0 | W12: =H12/V12 -> #DIV/0! | X12: =H12*V1 -> 1259.76 | Y12: =IF(X12>0,X12/T12,0) -> 6.3624242 | Z12: =IF(X12>0,X12/V12,0) -> #DIV/0!
A13: 7 | B13: 90255.667 | C13: =IF(B13>=B12,B13-B12,0)*10*0.58 -> 85.066667 | D13: 13540.667 | E13: =IF(D13>=D12,D13-D12,0)*10*0.58 -> 108.26667 | F13: 63200 | G13: =IF(F13>=F12,F13-F12,0)*0.58 -> 64.96 | H13: =C13+E13+G13 -> 258.29333 | O13: =IF(N13>=N12,N13-N12,0) -> 0 | Q13: =(H13-O13)*0.58 -> 149.81013 | S13: =IF(R13-R12>0,R13-R12,0) -> 0 | T13: =Elect!BT12 -> 184 | U13: =H13/T13 -> 1.4037681 | V13: =Elect!BV12 -> 0 | W13: =H13/V13 -> #DIV/0! | X13: =H13*V1 -> 1033.1733 | Y13: =IF(X13>0,X13/T13,0) -> 5.6150725 | Z13: =IF(X13>0,X13/V13,0) -> #DIV/0!
A14: 8 | B14: 90270.167 | C14: =IF(B14>=B13,B14-B13,0)*10*0.58 -> 84.1 | D14: 13559.167 | E14: =IF(D14>=D13,D14-D13,0)*10*0.58 -> 107.3 | F14: 63400 | G14: =IF(F14>=F13,F14-F13,0)*0.58 -> 116 | H14: =C14+E14+G14 -> 307.4 | O14: =IF(N14>=N13,N14-N13,0) -> 0 | Q14: =(H14-O14)*0.58 -> 178.292 | S14: =IF(R14-R13>0,R14-R13,0) -> 0 | T14: =Elect!BT13 -> 184 | U14: =H14/T14 -> 1.6706522 | V14: =Elect!BV13 -> 0 | W14: =H14/V14 -> #DIV/0! | X14: =H14*V1 -> 1229.6 | Y14: =IF(X14>0,X14/T14,0) -> 6.6826087 | Z14: =IF(X14>0,X14/V14,0) -> #DIV/0!
A15: 9 | B15: 90284 | C15: =IF(B15>=B14,B15-B14,0)*10*0.58 -> 80.233333 | D15: 13577 | E15: =IF(D15>=D14,D15-D14,0)*10*0.58 -> 103.43333 | F15: 63739 | G15: =IF(F15>=F14,F15-F14,0)*0.58 -> 196.62 | H15: =C15+E15+G15 -> 380.28667 | O15: =IF(N15>=N14,N15-N14,0) -> 0 | Q15: =(H15-O15)*0.58 -> 220.56627 | S15: =IF(R15-R14>0,R15-R14,0) -> 0 | T15: =Elect!BT14 -> 183 | U15: =H15/T15 -> 2.0780692 | V15: =Elect!BV14 -> 0 | W15: =H15/V15 -> #DIV/0! | X15: =H15*V1 -> 1521.1467 | Y15: =IF(X15>0,X15/T15,0) -> 8.3122769 | Z15: =IF(X15>0,X15/V15,0) -> #DIV/0!
A16: 10 | B16: 90297 | C16: =IF(B16>=B15,B16-B15,0)*10*0.58 -> 75.4 | D16: 13593 | E16: =IF(D16>=D15,D16-D15,0)*10*0.58 -> 92.8 | F16: 63950 | G16: =IF(F16>=F15,F16-F15,0)*0.58 -> 122.38 | H16: =C16+E16+G16 -> 290.58 | O16: =IF(N16>=N15,N16-N15,0) -> 0 | Q16: =(H16-O16)*0.58 -> 168.5364 | S16: =IF(R16-R15>0,R16-R15,0) -> 0 | T16: =Elect!BT15 -> 207 | U16: =H16/T16 -> 1.4037681 | V16: =Elect!BV15 -> 0 | W16: =H16/V16 -> #DIV/0! | X16: =H16*V1 -> 1162.32 | Y16: =IF(X16>0,X16/T16,0) -> 5.6150725 | Z16: =IF(X16>0,X16/V16,0) -> #DIV/0!
A17: 11 | B17: 90311 | C17: =IF(B17>=B16,B17-B16,0)*10*0.58 -> 81.2 | D17: 13611 | E17: =IF(D17>=D16,D17-D16,0)*10*0.58 -> 104.4 | F17: 64163 | G17: =IF(F17>=F16,F17-F16,0)*0.58 -> 123.54 | H17: =C17+E17+G17 -> 309.14 | O17: =IF(N17>=N16,N17-N16,0) -> 0 | Q17: =(H17-O17)*0.58 -> 179.3012 | S17: =IF(R17-R16>0,R17-R16,0) -> 0 | T17: =Elect!BT16 -> 236 | U17: =H17/T17 -> 1.3099153 | V17: =Elect!BV16 -> 0 | W17: =H17/V17 -> #DIV/0! | X17: =H17*V1 -> 1236.56 | Y17: =IF(X17>0,X17/T17,0) -> 5.239661 | Z17: =IF(X17>0,X17/V17,0) -> #DIV/0!
A18: 12 | B18: 90326 | C18: =IF(B18>=B17,B18-B17,0)*10*0.58 -> 87 | D18: 13629 | E18: =IF(D18>=D17,D18-D17,0)*10*0.58 -> 104.4 | F18: 64370 | G18: =IF(F18>=F17,F18-F17,0)*0.58 -> 120.06 | H18: =C18+E18+G18 -> 311.46 | O18: =IF(N18>=N17,N18-N17,0) -> 0 | Q18: =(H18-O18)*0.58 -> 180.6468 | S18: =IF(R18-R17>0,R18-R17,0) -> 0 | T18: =Elect!BT17 -> 236 | U18: =H18/T18 -> 1.3197458 | V18: =Elect!BV17 -> 0 | W18: =H18/V18 -> #DIV/0! | X18: =H18*V1 -> 1245.84 | Y18: =IF(X18>0,X18/T18,0) -> 5.2789831 | Z18: =IF(X18>0,X18/V18,0) -> #DIV/0!
A19: 13 | B19: 90339.233 | C19: =IF(B19>=B18,B19-B18,0)*10*0.58 -> 76.753333 | D19: 13645.933 | E19: =IF(D19>=D18,D19-D18,0)*10*0.58 -> 98.213333 | F19: 64633.6 | G19: =IF(F19>=F18,F19-F18,0)*0.58 -> 152.888 | H19: =C19+E19+G19 -> 327.85467 | O19: =IF(N19>=N18,N19-N18,0) -> 0 | Q19: =(H19-O19)*0.58 -> 190.15571 | S19: =IF(R19-R18>0,R19-R18,0) -> 0 | T19: =Elect!BT18 -> 234 | U19: =H19/T19 -> 1.4010883 | V19: =Elect!BV18 -> 0 | W19: =H19/V19 -> #DIV/0! | X19: =H19*V1 -> 1311.4187 | Y19: =IF(X19>0,X19/T19,0) -> 5.6043533 | Z19: =IF(X19>0,X19/V19,0) -> #DIV/0!
A20: 14 | B20: 90353.1 | C20: =IF(B20>=B19,B20-B19,0)*10*0.58 -> 80.426667 | D20: 13663.3 | E20: =IF(D20>=D19,D20-D19,0)*10*0.58 -> 100.72667 | F20: 64870 | G20: =IF(F20>=F19,F20-F19,0)*0.58 -> 137.112 | H20: =C20+E20+G20 -> 318.26533 | O20: =IF(N20>=N19,N20-N19,0) -> 0 | Q20: =(H20-O20)*0.58 -> 184.59389 | S20: =IF(R20-R19>0,R20-R19,0) -> 0 | T20: =Elect!BT19 -> 234 | U20: =H20/T20 -> 1.3601083 | V20: =Elect!BV19 -> 0 | W20: =H20/V20 -> #DIV/0! | X20: =H20*V1 -> 1273.0613 | Y20: =IF(X20>0,X20/T20,0) -> 5.440433 | Z20: =IF(X20>0,X20/V20,0) -> #DIV/0!
A21: 15 | B21: 90366.967 | C21: =IF(B21>=B20,B21-B20,0)*10*0.58 -> 80.426667 | D21: 13680.667 | E21: =IF(D21>=D20,D21-D20,0)*10*0.58 -> 100.72667 | F21: 65106.4 | G21: =IF(F21>=F20,F21-F20,0)*0.58 -> 137.112 | H21: =C21+E21+G21 -> 318.26533 | O21: =IF(N21>=N20,N21-N20,0) -> 0 | Q21: =(H21-O21)*0.58 -> 184.59389 | S21: =IF(R21-R20>0,R21-R20,0) -> 0 | T21: =Elect!BT20 -> 234 | U21: =H21/T21 -> 1.3601083 | V21: =Elect!BV20 -> 0 | W21: =H21/V21 -> #DIV/0! | X21: =H21*V1 -> 1273.0613 | Y21: =IF(X21>0,X21/T21,0) -> 5.440433 | Z21: =IF(X21>0,X21/V21,0) -> #DIV/0!
A22: 16 | B22: 90380.833 | C22: =IF(B22>=B21,B22-B21,0)*10*0.58 -> 80.426667 | D22: 13698.033 | E22: =IF(D22>=D21,D22-D21,0)*10*0.58 -> 100.72667 | F22: 65342.8 | G22: =IF(F22>=F21,F22-F21,0)*0.58 -> 137.112 | H22: =C22+E22+G22 -> 318.26533 | O22: =IF(N22>=N21,N22-N21,0) -> 0 | Q22: =(H22-O22)*0.58 -> 184.59389 | S22: =IF(R22-R21>0,R22-R21,0) -> 0 | T22: =Elect!BT21 -> 232 | U22: =H22/T22 -> 1.3718333 | V22: =Elect!BV21 -> 0 | W22: =H22/V22 -> #DIV/0! | X22: =H22*V1 -> 1273.0613 | Y22: =IF(X22>0,X22/T22,0) -> 5.4873333 | Z22: =IF(X22>0,X22/V22,0) -> #DIV/0!
A23: 17 | B23: 90405 | C23: =IF(B23>=B22,B23-B22,0)*10*0.58 -> 140.16667 | D23: 13729 | E23: =IF(D23>=D22,D23-D22,0)*10*0.58 -> 179.60667 | F23: 65424 | G23: =IF(F23>=F22,F23-F22,0)*0.58 -> 47.096 | H23: =C23+E23+G23 -> 366.86933 | O23: =IF(N23>=N22,N23-N22,0) -> 0 | Q23: =(H23-O23)*0.58 -> 212.78421 | S23: =IF(R23-R22>0,R23-R22,0) -> 0 | T23: =Elect!BT22 -> 216 | U23: =H23/T23 -> 1.6984691 | V23: =Elect!BV22 -> 0 | W23: =H23/V23 -> #DIV/0! | X23: =H23*V1 -> 1467.4773 | Y23: =IF(X23>0,X23/T23,0) -> 6.7938765 | Z23: =IF(X23>0,X23/V23,0) -> #DIV/0!
A24: 18 | B24: 90419 | C24: =IF(B24>=B23,B24-B23,0)*10*0.58 -> 81.2 | D24: 13748 | E24: =IF(D24>=D23,D24-D23,0)*10*0.58 -> 110.2 | F24: 65633 | G24: =IF(F24>=F23,F24-F23,0)*0.58 -> 121.22 | H24: =C24+E24+G24 -> 312.62 | O24: =IF(N24>=N23,N24-N23,0) -> 0 | Q24: =(H24-O24)*0.58 -> 181.3196 | S24: =IF(R24-R23>0,R24-R23,0) -> 0 | T24: =Elect!BT23 -> 167 | U24: =H24/T24 -> 1.871976 | V24: =Elect!BV23 -> 0 | W24: =H24/V24 -> #DIV/0! | X24: =H24*V1 -> 1250.48 | Y24: =IF(X24>0,X24/T24,0) -> 7.4879042 | Z24: =IF(X24>0,X24/V24,0) -> #DIV/0!
A25: 19 | B25: 90433 | C25: =IF(B25>=B24,B25-B24,0)*10*0.58 -> 81.2 | D25: 13765 | E25: =IF(D25>=D24,D25-D24,0)*10*0.58 -> 98.6 | F25: 65844 | G25: =IF(F25>=F24,F25-F24,0)*0.58 -> 122.38 | H25: =C25+E25+G25 -> 302.18 | O25: =IF(N25>=N24,N25-N24,0) -> 0 | Q25: =(H25-O25)*0.58 -> 175.2644 | S25: =IF(R25-R24>0,R25-R24,0) -> 0 | T25: =Elect!BT24 -> 191 | U25: =H25/T25 -> 1.5820942 | V25: =Elect!BV24 -> 0 | W25: =H25/V25 -> #DIV/0! | X25: =H25*V1 -> 1208.72 | Y25: =IF(X25>0,X25/T25,0) -> 6.328377 | Z25: =IF(X25>0,X25/V25,0) -> #DIV/0!
A26: 20 | B26: 90450 | C26: =IF(B26>=B25,B26-B25,0)*10*0.58 -> 98.6 | D26: 13787 | E26: =IF(D26>=D25,D26-D25,0)*10*0.58 -> 127.6 | F26: 66066 | G26: =IF(F26>=F25,F26-F25,0)*0.58 -> 128.76 | H26: =C26+E26+G26 -> 354.96 | O26: =IF(N26>=N25,N26-N25,0) -> 0 | Q26: =(H26-O26)*0.58 -> 205.8768 | S26: =IF(R26-R25>0,R26-R25,0) -> 0 | T26: =Elect!BT25 -> 233 | U26: =H26/T26 -> 1.5234335 | V26: =Elect!BV25 -> 0 | W26: =H26/V26 -> #DIV/0! | X26: =H26*V1 -> 1419.84 | Y26: =IF(X26>0,X26/T26,0) -> 6.0937339 | Z26: =IF(X26>0,X26/V26,0) -> #DIV/0!
A27: 21 | B27: 90464 | C27: =IF(B27>=B26,B27-B26,0)*10*0.58 -> 81.2 | D27: 13805 | E27: =IF(D27>=D26,D27-D26,0)*10*0.58 -> 104.4 | F27: 66276 | G27: =IF(F27>=F26,F27-F26,0)*0.58 -> 121.8 | H27: =C27+E27+G27 -> 307.4 | O27: =IF(N27>=N26,N27-N26,0) -> 0 | Q27: =(H27-O27)*0.58 -> 178.292 | S27: =IF(R27-R26>0,R27-R26,0) -> 0 | T27: =Elect!BT26 -> 202 | U27: =H27/T27 -> 1.5217822 | V27: =Elect!BV26 -> 0 | W27: =H27/V27 -> #DIV/0! | X27: =H27*V1 -> 1229.6 | Y27: =IF(X27>0,X27/T27,0) -> 6.0871287 | Z27: =IF(X27>0,X27/V27,0) -> #DIV/0!
A28: 22 | B28: 90478.9 | C28: =IF(B28>=B27,B28-B27,0)*10*0.58 -> 86.42 | D28: 13824.1 | E28: =IF(D28>=D27,D28-D27,0)*10*0.58 -> 110.78 | F28: 66489.7 | G28: =IF(F28>=F27,F28-F27,0)*0.58 -> 123.946 | H28: =C28+E28+G28 -> 321.146 | O28: =IF(N28>=N27,N28-N27,0) -> 0 | Q28: =(H28-O28)*0.58 -> 186.26468 | S28: =IF(R28-R27>0,R28-R27,0) -> 0 | T28: =Elect!BT27 -> 209 | U28: =H28/T28 -> 1.5365837 | V28: =Elect!BV27 -> 0 | W28: =H28/V28 -> #DIV/0! | X28: =H28*V1 -> 1284.584 | Y28: =IF(X28>0,X28/T28,0) -> 6.1463349 | Z28: =IF(X28>0,X28/V28,0) -> #DIV/0!
A29: 23 | B29: 90498 | C29: =IF(B29>=B28,B29-B28,0)*10*0.58 -> 110.78 | D29: 13847 | E29: =IF(D29>=D28,D29-D28,0)*10*0.58 -> 132.82 | F29: 66684 | G29: =IF(F29>=F28,F29-F28,0)*0.58 -> 112.694 | H29: =C29+E29+G29 -> 356.294 | O29: =IF(N29>=N28,N29-N28,0) -> 0 | Q29: =(H29-O29)*0.58 -> 206.65052 | S29: =IF(R29-R28>0,R29-R28,0) -> 0 | T29: =Elect!BT28 -> 229 | U29: =H29/T29 -> 1.555869 | V29: =Elect!BV28 -> 0 | W29: =H29/V29 -> #DIV/0! | X29: =H29*V1 -> 1425.176 | Y29: =IF(X29>0,X29/T29,0) -> 6.223476 | Z29: =IF(X29>0,X29/V29,0) -> #DIV/0!
A30: 24 | B30: 90515 | C30: =IF(B30>=B29,B30-B29,0)*10*0.58 -> 98.6 | D30: 13868 | E30: =IF(D30>=D29,D30-D29,0)*10*0.58 -> 121.8 | F30: 66902 | G30: =IF(F30>=F29,F30-F29,0)*0.58 -> 126.44 | H30: =C30+E30+G30 -> 346.84 | O30: =IF(N30>=N29,N30-N29,0) -> 0 | Q30: =(H30-O30)*0.58 -> 201.1672 | S30: =IF(R30-R29>0,R30-R29,0) -> 0 | T30: =Elect!BT29 -> 215 | U30: =H30/T30 -> 1.6132093 | V30: =Elect!BV29 -> 0 | W30: =H30/V30 -> #DIV/0! | X30: =H30*V1 -> 1387.36 | Y30: =IF(X30>0,X30/T30,0) -> 6.4528372 | Z30: =IF(X30>0,X30/V30,0) -> #DIV/0!
A31: 25 | B31: 90534 | C31: =IF(B31>=B30,B31-B30,0)*10*0.58 -> 110.2 | D31: 13889 | E31: =IF(D31>=D30,D31-D30,0)*10*0.58 -> 121.8 | F31: 67110 | G31: =IF(F31>=F30,F31-F30,0)*0.58 -> 120.64 | H31: =C31+E31+G31 -> 352.64 | O31: =IF(N31>=N30,N31-N30,0) -> 0 | Q31: =(H31-O31)*0.58 -> 204.5312 | S31: =IF(R31-R30>0,R31-R30,0) -> 0 | T31: =Elect!BT30 -> 221 | U31: =H31/T31 -> 1.5956561 | V31: =Elect!BV30 -> 0 | W31: =H31/V31 -> #DIV/0! | X31: =H31*V1 -> 1410.56 | Y31: =IF(X31>0,X31/T31,0) -> 6.3826244 | Z31: =IF(X31>0,X31/V31,0) -> #DIV/0!
A32: 26 | B32: 90548 | C32: =IF(B32>=B31,B32-B31,0)*10*0.58 -> 81.2 | D32: 13911 | E32: =IF(D32>=D31,D32-D31,0)*10*0.58 -> 127.6 | F32: 67317 | G32: =IF(F32>=F31,F32-F31,0)*0.58 -> 120.06 | H32: =C32+E32+G32 -> 328.86 | O32: =IF(N32>=N31,N32-N31,0) -> 0 | Q32: =(H32-O32)*0.58 -> 190.7388 | S32: =IF(R32-R31>0,R32-R31,0) -> 0 | T32: =Elect!BT31 -> 231 | U32: =H32/T32 -> 1.4236364 | V32: =Elect!BV31 -> 0 | W32: =H32/V32 -> #DIV/0! | X32: =H32*V1 -> 1315.44 | Y32: =IF(X32>0,X32/T32,0) -> 5.6945455 | Z32: =IF(X32>0,X32/V32,0) -> #DIV/0!
A33: 27 | B33: 90565 | C33: =IF(B33>=B32,B33-B32,0)*10*0.58 -> 98.6 | D33: 13932 | E33: =IF(D33>=D32,D33-D32,0)*10*0.58 -> 121.8 | F33: 67503 | G33: =IF(F33>=F32,F33-F32,0)*0.58 -> 107.88 | H33: =C33+E33+G33 -> 328.28 | O33: =IF(N33>=N32,N33-N32,0) -> 0 | Q33: =(H33-O33)*0.58 -> 190.4024 | S33: =IF(R33-R32>0,R33-R32,0) -> 0 | T33: =Elect!BT32 -> 200 | U33: =H33/T33 -> 1.6414 | V33: =Elect!BV32 -> 0 | W33: =H33/V33 -> #DIV/0! | X33: =H33*V1 -> 1313.12 | Y33: =IF(X33>0,X33/T33,0) -> 6.5656 | Z33: =IF(X33>0,X33/V33,0) -> #DIV/0!
A34: 28 | B34: 90580 | C34: =IF(B34>=B33,B34-B33,0)*10*0.58 -> 87 | D34: 13953.5 | E34: =IF(D34>=D33,D34-D33,0)*10*0.58 -> 124.7 | F34: 67703 | G34: =IF(F34>=F33,F34-F33,0)*0.58 -> 116 | H34: =C34+E34+G34 -> 327.7 | O34: =IF(N34>=N33,N34-N33,0) -> 0 | Q34: =(H34-O34)*0.58 -> 190.066 | S34: =IF(R34-R33>0,R34-R33,0) -> 0 | T34: =Elect!BT33 -> 243 | U34: =H34/T34 -> 1.3485597 | V34: =Elect!BV33 -> 0 | W34: =H34/V34 -> #DIV/0! | X34: =H34*V1 -> 1310.8 | Y34: =IF(X34>0,X34/T34,0) -> 5.3942387 | Z34: =IF(X34>0,X34/V34,0) -> #DIV/0!
A35: 29 | B35: 90595.5 | C35: =IF(B35>=B34,B35-B34,0)*10*0.58 -> 89.9 | D35: 13974.9 | E35: =IF(D35>=D34,D35-D34,0)*10*0.58 -> 124.12 | F35: 67899.5 | G35: =IF(F35>=F34,F35-F34,0)*0.58 -> 113.97 | H35: =C35+E35+G35 -> 327.99 | O35: =IF(N35>=N34,N35-N34,0) -> 0 | Q35: =(H35-O35)*0.58 -> 190.2342 | S35: =IF(R35-R34>0,R35-R34,0) -> 0 | T35: =Elect!BT34 -> 235 | U35: =H35/T35 -> 1.3957021 | V35: =Elect!BV34 -> 0 | W35: =H35/V35 -> #DIV/0! | X35: =H35*V1 -> 1311.96 | Y35: =IF(X35>0,X35/T35,0) -> 5.5828085 | Z35: =IF(X35>0,X35/V35,0) -> #DIV/0!
A36: 30 | B36: 90610.667 | C36: =IF(B36>=B35,B36-B35,0)*10*0.58 -> 87.966667 | D36: 13996.3 | E36: =IF(D36>=D35,D36-D35,0)*10*0.58 -> 124.12 | F36: 68098.333 | G36: =IF(F36>=F35,F36-F35,0)*0.58 -> 115.32333 | H36: =C36+E36+G36 -> 327.41 | O36: =IF(N36>=N35,N36-N35,0) -> 0 | Q36: =(H36-O36)*0.58 -> 189.8978 | S36: =IF(R36-R35>0,R36-R35,0) -> 0 | T36: =Elect!BT35 -> 240 | U36: =H36/T36 -> 1.3642083 | V36: =Elect!BV35 -> 0 | W36: =H36/V36 -> #DIV/0! | X36: =H36*V1 -> 1309.64 | Y36: =IF(X36>0,X36/T36,0) -> 5.4568333 | Z36: =IF(X36>0,X36/V36,0) -> #DIV/0!
A37: 31 | B37: 90625.917 | C37: =IF(B37>=B36,B37-B36,0)*10*0.58 -> 88.45 | D37: 14017.7 | E37: =IF(D37>=D36,D37-D36,0)*10*0.58 -> 124.12 | F37: 68296.583 | G37: =IF(F37>=F36,F37-F36,0)*0.58 -> 114.985 | H37: =C37+E37+G37 -> 327.555 | I37: 322 | K37: 5583 | O37: =IF(N37>=N36,N37-N36,0) -> 0 | Q37: =(H37-O37)*0.58 -> 189.9819 | S37: =IF(R37-R36>0,R37-R36,0) -> 0 | T37: =Elect!BT36 -> 236.33333 | U37: =H37/T37 -> 1.3859873 | V37: =Elect!BV36 -> 0 | W37: =H37/V37 -> #DIV/0! | X37: =H37*V7 -> 0 | Y37: =IF(X37>0,X37/T37,0) -> 0 | Z37: =IF(X37>0,X37/V37,0) -> 0
A38: MTD | C38: =SUM(C7:C37) -> 2845.3833 | E38: =SUM(E7:E37) -> 3661.9267 | G38: =SUM(G7:G37) -> 3772.6583 | H38: =SUM(H7:H37) -> 10279.968 | I38: =I37-I6 -> 12 | K38: =K37-K6 -> 107 | O38: =SUM(O7:O36) -> 0 | Q38: =SUM(Q7:Q34) -> 5392.2677 | S38: =SUM(S7:S34) -> 0 | T38: =SUM(T7:T36) -> 6523 | U38: =IF(H38>0,H38/T38,0) -> 1.5759571 | V38: =SUM(V7:V36) -> 0 | W38: =IF(H38>0,H38/V38,0) -> #DIV/0! | X38: =SUM(X7:X36) -> 39809.653 | Y38: =IF(X38>0,X38/T38,0) -> 6.1029669 | Z38: =IF(X38>0,X38/V38,0) -> #DIV/0!
A39: AVER. Act | C39: =C38/B48 -> 94.846111 | E39: =E38/B48 -> 122.06422 | G39: =G38/B48 -> 125.75528 | H39: =H38/B48 -> 342.66561 | O39: =O38/B48 -> 0 | Q39: =Q38/B48 -> 179.74226 | S39: =S38/C48 -> #DIV/0! | T39: =T38/B48 -> 217.43333 | U39: =IF(H39>0,H39/T39,0) -> 1.5759571 | V39: =V38/B48 -> 0 | W39: =IF(H39>0,H39/V39,0) -> #DIV/0! | X39: =X38/B48 -> 1326.9884 | Y39: =IF(X39>0,X39/T39,0) -> 6.1029669 | Z39: =IF(X39>0,X39/V39,0) -> #DIV/0!
A40: TOTAL Budget | T40: =YTD!Q2341 -> 0 | U40: =IF(#REF!>0,#REF!/T40,0) -> #REF! | V40: =YTD!Q2342 -> 0 | W40: =IF(#REF!>0,#REF!/V40,0) -> #REF! | X40: =YTD!Q2346 -> 0 | Y40: =IF(X40>0,X40/T40,0) -> 0 | Z40: =IF(X40>0,X40/V40,0) -> 0
A41: Budget MTD | F41: 66684 | T41: =T42*C48 -> #VALUE! | U41: =IF(#REF!>0,#REF!/T41,0) -> #REF! | V41: =V42*C48 -> #VALUE! | W41: =IF(#REF!>0,#REF!/V41,0) -> #REF! | X41: =#REF!*5.62 -> #REF! | Y41: =IF(X41>0,X41/T41,0) -> #REF! | Z41: =IF(X41>0,X41/V41,0) -> #REF!
...

Sheet Gas
A1: =Elect!A1 -> 44896 | E1: Gas | H1: Gas UP | J1: 3.9
A4: NO. | B4: Main Gas Flow Meter | D4: Laundry Gas Flow Meter | F4: Grumandiz Gas Flow Meter | H4: Plant Room Gas Share Cost | I4: Hotel Consumption Cost | J4: La Grumandiz Cost | K4: Total Natural Gas Consumption
B5: Read | C5: Cons | D5: Read | E5: Cons | F5: Read | G5: Cons | H5: LE/DAY | I5: LE/DAY | J5: LE/DAY | K5: Cons
B6: 8406888 | C6: =IF(B6>=B5,B6-B5,0)*1.06 -> 0 | D6: 598602.33 | E6: =IF(D6>=D5,D6-D5,0)*0.7 -> 0 | F6: 629322.67 | G6: =IF(F6>=F5,F6-F5,0) -> 0 | K6: =C6+E6 -> 0
A7: 1 | B7: 8408205 | C7: =IF(B7>=B6,B7-B6,0)*1.06 -> 1396.02 | D7: 599184 | E7: =IF(D7>=D6,D7-D6,0)*0.7 -> 407.16667 | F7: 629388.11 | G7: =IF(F7>=F6,F7-F6,0) -> 65.444444 | H7: =(E7*0.55)*1.61 -> 360.54608 | I7: =C7*J1 -> 5444.478 | J7: =G7*J1 -> 255.23333 | K7: =C7+E7 -> 1803.1867
A8: 2 | B8: 8409755 | C8: =IF(B8>=B7,B8-B7,0)*1.06 -> 1643 | D8: 599678 | E8: =IF(D8>=D7,D8-D7,0)*0.7 -> 345.8 | F8: 629479 | G8: =IF(F8>=F7,F8-F7,0) -> 90.888889 | H8: =(E8*0.55)*1.61 -> 306.2059 | I8: =C8*J1 -> 6407.7 | J8: =G8*J1 -> 354.46667 | K8: =C8+E8 -> 1988.8
A9: 3 | B9: 8411305 | C9: =IF(B9>=B8,B9-B8,0)*1.06 -> 1643 | D9: 600172 | E9: =IF(D9>=D8,D9-D8,0)*0.7 -> 345.8 | F9: 629560.33 | G9: =IF(F9>=F8,F9-F8,0) -> 81.333333 | H9: =(E9*0.55)*1.61 -> 306.2059 | I9: =C9*J1 -> 6407.7 | J9: =G9*J1 -> 317.2 | K9: =C9+E9 -> 1988.8
A10: 4 | B10: 8412855 | C10: =IF(B10>=B9,B10-B9,0)*1.06 -> 1643 | D10: 600656 | E10: =IF(D10>=D9,D10-D9,0)*0.7 -> 338.8 | F10: 629656 | G10: =IF(F10>=F9,F10-F9,0) -> 95.666667 | H10: =(E10*0.55)*1.61 -> 300.0074 | I10: =C10*J1 -> 6407.7 | J10: =G10*J1 -> 373.1 | K10: =C10+E10 -> 1981.8
A11: 5 | B11: 8414405 | C11: =IF(B11>=B10,B11-B10,0)*1.06 -> 1643 | D11: 601140 | E11: =IF(D11>=D10,D11-D10,0)*0.7 -> 338.8 | F11: 629753 | G11: =IF(F11>=F10,F11-F10,0) -> 97 | H11: =(E11*0.55)*1.61 -> 300.0074 | I11: =C11*J1 -> 6407.7 | J11: =G11*J1 -> 378.3 | K11: =C11+E11 -> 1981.8
A12: 6 | B12: 8415955 | C12: =IF(B12>=B11,B12-B11,0)*1.06 -> 1643 | D12: 601593 | E12: =IF(D12>=D11,D12-D11,0)*0.7 -> 317.1 | F12: 629848 | G12: =IF(F12>=F11,F12-F11,0) -> 95 | H12: =(E12*0.55)*1.61 -> 280.79205 | I12: =C12*J1 -> 6407.7 | J12: =G12*J1 -> 370.5 | K12: =C12+E12 -> 1960.1
A13: 7 | B13: 8417505 | C13: =IF(B13>=B12,B13-B12,0)*1.06 -> 1643 | D13: 602066.67 | E13: =IF(D13>=D12,D13-D12,0)*0.7 -> 331.56667 | F13: 629944.33 | G13: =IF(F13>=F12,F13-F12,0) -> 96.333333 | H13: =(E13*0.55)*1.61 -> 293.60228 | I13: =C13*J1 -> 6407.7 | J13: =G13*J1 -> 375.7 | K13: =C13+E13 -> 1974.5667
A14: 8 | B14: 8419055 | C14: =IF(B14>=B13,B14-B13,0)*1.06 -> 1643 | D14: 602535.17 | E14: =IF(D14>=D13,D14-D13,0)*0.7 -> 327.95 | F14: 630040.33 | G14: =IF(F14>=F13,F14-F13,0) -> 96 | H14: =(E14*0.55)*1.61 -> 290.39973 | I14: =C14*J1 -> 6407.7 | J14: =G14*J1 -> 374.4 | K14: =C14+E14 -> 1970.95
A15: 9 | B15: 8419880 | C15: =IF(B15>=B14,B15-B14,0)*1.06 -> 874.5 | D15: 603084 | E15: =IF(D15>=D14,D15-D14,0)*0.7 -> 384.18333 | F15: 630131 | G15: =IF(F15>=F14,F15-F14,0) -> 90.666667 | H15: =(E15*0.55)*1.61 -> 340.19434 | I15: =C15*J1 -> 3410.55 | J15: =G15*J1 -> 353.6 | K15: =C15+E15 -> 1258.6833
A16: 10 | B16: 8421268 | C16: =IF(B16>=B15,B16-B15,0)*1.06 -> 1471.28 | D16: 603522 | E16: =IF(D16>=D15,D16-D15,0)*0.7 -> 306.6 | F16: 630221 | G16: =IF(F16>=F15,F16-F15,0) -> 90 | H16: =(E16*0.55)*1.61 -> 271.4943 | I16: =C16*J1 -> 5737.992 | J16: =G16*J1 -> 351 | K16: =C16+E16 -> 1777.88
A17: 11 | B17: 8422600 | C17: =IF(B17>=B16,B17-B16,0)*1.06 -> 1411.92 | D17: 604002 | E17: =IF(D17>=D16,D17-D16,0)*0.7 -> 336 | F17: 630309 | G17: =IF(F17>=F16,F17-F16,0) -> 88 | H17: =(E17*0.55)*1.61 -> 297.528 | I17: =C17*J1 -> 5506.488 | J17: =G17*J1 -> 343.2 | K17: =C17+E17 -> 1747.92
A18: 12 | B18: 8424018 | C18: =IF(B18>=B17,B18-B17,0)*1.06 -> 1503.08 | D18: 604520 | E18: =IF(D18>=D17,D18-D17,0)*0.7 -> 362.6 | F18: 630400 | G18: =IF(F18>=F17,F18-F17,0) -> 91 | H18: =(E18*0.55)*1.61 -> 321.0823 | I18: =C18*J1 -> 5862.012 | J18: =G18*J1 -> 354.9 | K18: =C18+E18 -> 1865.68
A19: 13 | B19: 8425179.8 | C19: =IF(B19>=B18,B19-B18,0)*1.06 -> 1231.508 | D19: 604998.93 | E19: =IF(D19>=D18,D19-D18,0)*0.7 -> 335.25333 | F19: 630491.71 | G19: =IF(F19>=F18,F19-F18,0) -> 91.711111 | H19: =(E19*0.55)*1.61 -> 296.86683 | I19: =C19*J1 -> 4802.8812 | J19: =G19*J1 -> 357.67333 | K19: =C19+E19 -> 1566.7613
A20: 14 | B20: 8426453.7 | C20: =IF(B20>=B19,B20-B19,0)*1.06 -> 1350.3794 | D20: 605487.7 | E20: =IF(D20>=D19,D20-D19,0)*0.7 -> 342.13667 | F20: 630582.41 | G20: =IF(F20>=F19,F20-F19,0) -> 90.695238 | H20: =(E20*0.55)*1.61 -> 302.96202 | I20: =C20*J1 -> 5266.4798 | J20: =G20*J1 -> 353.71143 | K20: =C20+E20 -> 1692.5161
A21: 15 | B21: 8427727.7 | C21: =IF(B21>=B20,B21-B20,0)*1.06 -> 1350.3794 | D21: 605976.47 | E21: =IF(D21>=D20,D21-D20,0)*0.7 -> 342.13667 | F21: 630673.1 | G21: =IF(F21>=F20,F21-F20,0) -> 90.695238 | H21: =(E21*0.55)*1.61 -> 302.96202 | I21: =C21*J1 -> 5266.4798 | J21: =G21*J1 -> 353.71143 | K21: =C21+E21 -> 1692.5161
A22: 16 | B22: 8429001.6 | C22: =IF(B22>=B21,B22-B21,0)*1.06 -> 1350.3794 | D22: 606465.23 | E22: =IF(D22>=D21,D22-D21,0)*0.7 -> 342.13667 | F22: 630763.8 | G22: =IF(F22>=F21,F22-F21,0) -> 90.695238 | H22: =(E22*0.55)*1.61 -> 302.96202 | I22: =C22*J1 -> 5266.4798 | J22: =G22*J1 -> 353.71143 | K22: =C22+E22 -> 1692.5161
A23: 17 | B23: 8431136 | C23: =IF(B23>=B22,B23-B22,0)*1.06 -> 2262.4337 | D23: 607160 | E23: =IF(D23>=D22,D23-D22,0)*0.7 -> 486.33667 | F23: 630863 | G23: =IF(F23>=F22,F23-F22,0) -> 99.203175 | H23: =(E23*0.55)*1.61 -> 430.65112 | I23: =C23*J1 -> 8823.4915 | J23: =G23*J1 -> 386.89238 | K23: =C23+E23 -> 2748.7704
A24: 18 | B24: 8432635 | C24: =IF(B24>=B23,B24-B23,0)*1.06 -> 1588.94 | D24: 607670 | E24: =IF(D24>=D23,D24-D23,0)*0.7 -> 357 | F24: 630965 | G24: =IF(F24>=F23,F24-F23,0) -> 102 | H24: =(E24*0.55)*1.61 -> 316.1235 | I24: =C24*J1 -> 6196.866 | J24: =G24*J1 -> 397.8 | K24: =C24+E24 -> 1945.94
A25: 19 | B25: 8434106 | C25: =IF(B25>=B24,B25-B24,0)*1.06 -> 1559.26 | D25: 608174 | E25: =IF(D25>=D24,D25-D24,0)*0.7 -> 352.8 | F25: 631041 | G25: =IF(F25>=F24,F25-F24,0) -> 76 | H25: =(E25*0.55)*1.61 -> 312.4044 | I25: =C25*J1 -> 6081.114 | J25: =G25*J1 -> 296.4 | K25: =C25+E25 -> 1912.06
A26: 20 | B26: 8435595.7 | C26: =IF(B26>=B25,B26-B25,0)*1.06 -> 1579.0467 | D26: 608735 | E26: =IF(D26>=D25,D26-D25,0)*0.7 -> 392.7 | F26: 631126 | G26: =IF(F26>=F25,F26-F25,0) -> 85 | H26: =(E26*0.55)*1.61 -> 347.73585 | I26: =C26*J1 -> 6158.282 | J26: =G26*J1 -> 331.5 | K26: =C26+E26 -> 1971.7467
A27: 21 | B27: 8437080.7 | C27: =IF(B27>=B26,B27-B26,0)*1.06 -> 1574.1 | D27: 609258 | E27: =IF(D27>=D26,D27-D26,0)*0.7 -> 366.1 | F27: 631203 | G27: =IF(F27>=F26,F27-F26,0) -> 77 | H27: =(E27*0.55)*1.61 -> 324.18155 | I27: =C27*J1 -> 6138.99 | J27: =G27*J1 -> 300.3 | K27: =C27+E27 -> 1940.2
A28: 22 | B28: 8438565.7 | C28: =IF(B28>=B27,B28-B27,0)*1.06 -> 1574.1 | D28: 609790.5 | E28: =IF(D28>=D27,D28-D27,0)*0.7 -> 372.75 | F28: 631285.5 | G28: =IF(F28>=F27,F28-F27,0) -> 82.5 | H28: =(E28*0.55)*1.61 -> 330.07013 | I28: =C28*J1 -> 6138.99 | J28: =G28*J1 -> 321.75
A29: 23 | B29: 8440031 | C29: =IF(B29>=B28,B29-B28,0)*1.06 -> 1553.2533 | D29: 610311 | E29: =IF(D29>=D28,D29-D28,0)*0.7 -> 364.35 | F29: 631391 | G29: =IF(F29>=F28,F29-F28,0) -> 105.5 | H29: =(E29*0.55)*1.61 -> 322.63192 | I29: =C29*J1 -> 6057.688 | J29: =G29*J1 -> 411.45 | K29: =C29+E29 -> 1917.6033
A30: 24 | B30: 8441593 | C30: =IF(B30>=B29,B30-B29,0)*1.06 -> 1655.72 | D30: 610839.5 | E30: =IF(D30>=D29,D30-D29,0)*0.7 -> 369.95 | F30: 631481 | G30: =IF(F30>=F29,F30-F29,0) -> 90 | H30: =(E30*0.55)*1.61 -> 327.59073 | I30: =C30*J1 -> 6457.308 | J30: =G30*J1 -> 351 | K30: =C30+E30 -> 2025.67
A31: 25 | B31: 8443788 | C31: =IF(B31>=B30,B31-B30,0)*1.06 -> 2326.7 | D31: 611443 | E31: =IF(D31>=D30,D31-D30,0)*0.7 -> 422.45 | F31: 631567 | G31: =IF(F31>=F30,F31-F30,0) -> 86 | H31: =(E31*0.55)*1.61 -> 374.07948 | I31: =C31*J3 -> 0 | J31: =G31*J1 -> 335.4 | K31: =C31+E31 -> 2749.15
A32: 26 | B32: 8444914 | C32: =IF(B32>=B31,B32-B31,0)*1.06 -> 1193.56 | D32: 612031 | E32: =IF(D32>=D31,D32-D31,0)*0.7 -> 411.6 | F32: 631655.67 | G32: =IF(F32>=F31,F32-F31,0) -> 88.666667 | H32: =(E32*0.55)*1.61 -> 364.4718 | I32: =C32*J1 -> 4654.884 | J32: =G32*J1 -> 345.8 | K32: =C32+E32 -> 1605.16
A33: 27 | B33: 8446559 | C33: =IF(B33>=B32,B33-B32,0)*1.06 -> 1743.7 | D33: 612566 | E33: =IF(D33>=D32,D33-D32,0)*0.7 -> 374.5 | F33: 631734 | G33: =IF(F33>=F32,F33-F32,0) -> 78.333333 | H33: =(E33*0.55)*1.61 -> 331.61975 | I33: =C33*J1 -> 6800.43 | J33: =G33*J1 -> 305.5 | K33: =C33+E33 -> 2118.2
A34: 28 | B34: 8447858 | C34: =IF(B34>=B33,B34-B33,0)*1.06 -> 1376.94 | D34: 613136.33 | E34: =IF(D34>=D33,D34-D33,0)*0.7 -> 399.23333 | F34: 631819.22 | G34: =IF(F34>=F33,F34-F33,0) -> 85.222222 | H34: =(E34*0.55)*1.61 -> 353.52112 | I34: =C34*J1 -> 5370.066 | J34: =G34*J1 -> 332.36667 | K34: =C34+E34 -> 1776.1733
A35: 29 | B35: 8449243.5 | C35: =IF(B35>=B34,B35-B34,0)*1.06 -> 1468.63 | D35: 613697.83 | E35: =IF(D35>=D34,D35-D34,0)*0.7 -> 393.05 | F35: 631902.72 | G35: =IF(F35>=F34,F35-F34,0) -> 83.5 | H35: =(E35*0.55)*1.61 -> 348.04577 | I35: =C35*J1 -> 5727.657 | J35: =G35*J1 -> 325.65 | K35: =C35+E35 -> 1861.68
A36: 30 | B36: 8450571.3 | C36: =IF(B36>=B35,B36-B35,0)*1.06 -> 1407.5033 | D36: 614265.22 | E36: =IF(D36>=D35,D36-D35,0)*0.7 -> 397.17222 | F36: 631987.37 | G36: =IF(F36>=F35,F36-F35,0) -> 84.648148 | H36: =(E36*0.55)*1.61 -> 351.696 | I36: =C36*J1 -> 5489.263 | J36: =G36*J1 -> 330.12778 | K36: =C36+E36 -> 1804.6756
A37: 31 | B37: 8451913.6 | C37: =IF(B37>=B36,B37-B36,0)*1.06 -> 1422.785 | D37: 614831.14 | E37: =IF(D37>=D36,D37-D36,0)*0.7 -> 396.14167 | F37: 632071.73 | G37: =IF(F37>=F36,F37-F36,0) -> 84.361111 | H37: =(E37*0.55)*1.61 -> 350.78345 | I37: =C37*J1 -> 5548.8615 | J37: =G37*J1 -> 329.00833 | K37: =C37+E37 -> 1818.9267
A38: MTD | C38: =SUM(C7:C37) -> 47727.118 | E38: =SUM(E7:E37) -> 11360.164 | G38: =SUM(G7:G37) -> 2749.0648 | H38: =SUM(H6:H37) -> 10059.425 | I38: =SUM(I6:I37) -> 177061.63 | J38: =SUM(J6:J37) -> 10721.353 | K38: =SUM(K6:K37) -> 57140.432
A39: Average MTD. | C39: =C38/A42 -> 1590.9039 | E39: =E38/A42 -> 378.67213 | G39: =G38/A42 -> 91.635494 | H39: =H38/A42 -> 335.31417 | I39: =I38/A42 -> 5902.0544 | J39: =J38/A42 -> 357.37843
A41: No of Days MTD
A42: =COUNTIF(B7:B36,">0") -> 30

Sheet Sheet1

Sheet Sheet2

Sheet Consp
A1: =Elect!A1 -> 44896 | L1: Summary | P1: =Elect!A1 -> 44896
B2: Elect Consuumption | H2: Water Incoming | U2: Water Consumption | AC2: Irrigation | AG2: Gas | AJ2: Cost | AK2: Solar Meter [ LIT ] | AL2: No. of Eng. | AM2: No. of Gardners | AN2: Cons. (lit) | AO2: Received Gas (tons) | AP2: Fuel Cost | AQ2: Solar level [cm] | AR2: Received Solar (tons) | AS2: Fuel Cost | AT2: Occupancy 10 | AV2: Occupancy07 | AZ2: Elect 2009 | BE2: Elect 2010 | BJ2: Water 2009 | BO2: Water 2010
A3: Date | B3: COUNTER (2) | D3: MD | F3: KVAR | H3: R.O | J3: Qenna | L3: Trucks | N3: Rimievera Line Meter | O3: Total Inc. | Q3: Total Main S.Pool | S3: Total Bar & Beach cons. | U3: Total S. Pool cons. | W3: Hotel consumption. | Y3: Sold Water | AA3: Irr. Water from R.O | AC3: Irr. Consumption. | AE3: Storage Water One tank | AF3: Grand Cons | AG3: % | AH3: Stock | AI3: Cons. | AJ3: 0 | AT3: No of guest | AU3: No. of rooms | AV3: No. of rooms | AW3: No. of guest | AX3: Cons. Per occ. room | AY3: Cons. Per guest | AZ3: Total cost | BA3: cost per room | BB3: cost per guest | BC3: Cons. Per occ. room | BD3: Cons. Per guest | BE3: Total cost | BF3: cost per room | BG3: cost per guest | BH3: Cons. Per occ. room | BI3: Cons. Per guest | BJ3: Total cost | BK3: cost per room | BL3: cost per guest | BM3: Cons. Per occ. room | BN3: Cons. Per guest | BO3: Total cost | BP3: cost per room | BQ3: cost per guest
B4: 2013 | C4: 2014 | D4: 2013 | E4: 2014 | F4: 2013 | G4: 2014 | H4: 2013 | I4: 2014 | J4: 2009 | K4: 2010 | L4: 2009 | M4: 2010 | O4: 2009 | P4: 2010 | Q4: 2009 | R4: 2010 | S4: 2009 | T4: 2010 | U4: 2009 | V4: 2010 | W4: 2009 | X4: 2010 | Y4: 2009 | Z4: 2010 | AA4: 2009 | AB4: 2010 | AC4: 2009 | AD4: 2010
A5: 1 | B5: 33600 | C5: =Elect!J6 -> 5035.1667 | D5: 0 | E5: =Elect!M6 -> 1759.3333 | F5: 20 | G5: =Elect!O6 -> 2390 | H5: 800 | I5: =Water!C7 -> 253.26667 | J5: 0 | K5: =Water!E7 -> 322.86667 | L5: 0 | M5: =Water!#REF! -> #REF! | N5: =Water!#REF! -> #REF! | O5: 1005 | P5: =Water!H7 -> 819.15333 | Q5: 114 | R5: =Water!O7 -> 0 | S5: 13 | T5: =Water!#REF! -> #REF! | U5: 147 | V5: =Water!#REF! -> #REF! | W5: 755 | X5: =Water!Q7 -> 475.10893 | Y5: 0 | Z5: =Water!#REF! -> #REF! | AA5: 0 | AB5: 0 | AC5: 690 | AD5: =Water!#REF! -> #REF! | AE5: =Water!#REF! -> #REF! | AF5: =Water!#REF! -> #REF! | AG5: =Gas!#REF! -> #REF! | AH5: =Gas!C7 -> 1396.02 | AI5: =Gas!#REF! -> #REF! | AJ5: =Gas!J7 -> 255.23333 | AK5: =Gas!#REF! -> #REF! | AL5: =Gas!#REF! -> #REF! | AM5: =Gas!#REF! -> #REF! | AN5: =Gas!#REF! -> #REF! | AO5: =Gas!#REF! -> #REF! | AP5: =Gas!#REF! -> #REF! | AQ5: =Gas!#REF! -> #REF! | AR5: =Gas!#REF! -> #REF! | AS5: =Gas!#REF! -> #REF! | AT5: =Elect!BR6 -> 136.33333 | AU5: =Elect!BP6 -> 137 | AV5: =Elect!#REF! -> #REF! | AW5: =Elect!BR6 -> 136.33333 | AX5: 48.695652 | AY5: 24.705882 | AZ5: 8835.4834 | BA5: 12.805048 | BB5: 6.496679 | BC5: =Elect!#REF! -> #REF! | BD5: =Elect!#REF! -> #REF! | BE5: =Elect!#REF! -> #REF! | BF5: =Elect!#REF! -> #REF! | BG5: =Elect!#REF! -> #REF! | BH5: 1.142029 | BI5: 0.57941176 | BJ5: 4569.1158 | BK5: 6.6219069 | BL5: 3.3596439 | BM5: =Water!U7 -> 3.9007302 | BN5: =Water!W7 -> #DIV/0! | BO5: =Water!X7 -> 3276.6133 | BP5: =Water!Y7 -> 15.602921 | BQ5: =Water!Z7 -> 0
A6: 2 | B6: 31200 | C6: =Elect!J7 -> 6579 | D6: 0 | E6: =Elect!M7 -> 1977 | F6: 20 | G6: =Elect!O7 -> 1530 | H6: 936 | I6: =Water!C8 -> 22.555556 | J6: 0 | K6: =Water!E8 -> 35.766667 | L6: 0 | M6: =Water!#REF! -> #REF! | N6: =Water!#REF! -> #REF! | O6: 1006 | P6: =Water!H8 -> 179.54222 | Q6: 113 | R6: =Water!O8 -> 0 | S6: 17 | T6: =Water!#REF! -> #REF! | U6: 140 | V6: =Water!#REF! -> #REF! | W6: 792 | X6: =Water!Q8 -> 104.13449 | Y6: 0 | Z6: =Water!#REF! -> #REF! | AA6: 0 | AB6: 0 | AC6: 370 | AD6: =Water!#REF! -> #REF! | AE6: =Water!#REF! -> #REF! | AF6: =Water!#REF! -> #REF! | AG6: =Gas!B7 -> 8408205 | AH6: =Gas!C8 -> 1643 | AI6: =Gas!#REF! -> #REF! | AJ6: =Gas!J8 -> 354.46667 | AK6: =Gas!#REF! -> #REF! | AL6: =Gas!#REF! -> #REF! | AM6: =Gas!#REF! -> #REF! | AN6: =Gas!#REF! -> #REF! | AO6: =Gas!#REF! -> #REF! | AP6: =Gas!#REF! -> #REF! | AQ6: =Gas!#REF! -> #REF! | AR6: =Gas!#REF! -> #REF! | AS6: =Gas!#REF! -> #REF! | AT6: =Elect!BR7 -> 134 | AU6: =Elect!BP7 -> 127 | AX6: 47.416413 | AY6: 23.981553 | AZ6: 8299.2754 | BA6: 12.612881 | BB6: 6.379151 | BC6: =Elect!BQ7 -> 562255 | BD6: =Elect!#REF! -> #REF! | BE6: =Elect!#REF! -> #REF! | BF6: =Elect!#REF! -> #REF! | BG6: =Elect!#REF! -> #REF! | BH6: 1.2021277 | BI6: 0.60799385 | BJ6: 5345.8654 | BK6: 8.1244156 | BL6: 4.1090434 | BM6: =Water!U8 -> 0.74191001 | BN6: =Water!W8 -> #DIV/0! | BO6: =Water!X8 -> 718.16889 | BP6: =Water!Y8 -> 2.96764 | BQ6: =Water!Z8 -> #DIV/0!
A7: 3 | B7: 31200 | C7: =Elect!J8 -> 5998 | D7: 0 | E7: =Elect!M8 -> 2024 | F7: 20 | G7: =Elect!O8 -> 1594 | H7: 685 | I7: =Water!C9 -> 85.711111 | J7: 0 | K7: =Water!E9 -> 107.3 | L7: 0 | M7: =Water!#REF! -> #REF! | N7: =Water!#REF! -> #REF! | O7: 902 | P7: =Water!H9 -> 239.41111 | Q7: 126 | R7: =Water!O9 -> 0 | S7: 26 | T7: =Water!#REF! -> #REF! | U7: 134 | V7: =Water!#REF! -> #REF! | W7: 766 | X7: =Water!Q9 -> 138.85844 | Y7: 0 | Z7: =Water!#REF! -> #REF! | AA7: 0 | AB7: 0 | AC7: 740 | AD7: =Water!#REF! -> #REF! | AE7: =Water!#REF! -> #REF! | AF7: =Water!#REF! -> #REF! | AG7: =Gas!B9 -> 8411305 | AH7: =Gas!C9 -> 1643 | AI7: =Gas!#REF! -> #REF! | AJ7: =Gas!J9 -> 317.2 | AK7: =Gas!#REF! -> #REF! | AL7: =Gas!#REF! -> #REF! | AM7: =Gas!#REF! -> #REF! | AN7: =Gas!#REF! -> #REF! | AO7: =Gas!#REF! -> #REF! | AP7: =Gas!#REF! -> #REF! | AQ7: =Gas!#REF! -> #REF! | AR7: =Gas!#REF! -> #REF! | AS7: =Gas!#REF! -> #REF! | AT7: =Elect!BR8 -> 149 | AU7: =Elect!BP8 -> 107 | AX7: 47.926267 | AY7: 24.223602 | AZ7: 8299.2754 | BA7: 12.748503 | BB7: 6.4435368 | BC7: =Elect!BQ8 -> 562404 | BD7: =Elect!#REF! -> #REF! | BE7: =Elect!#REF! -> #REF! | BF7: =Elect!#REF! -> #REF! | BG7: =Elect!#REF! -> #REF! | BH7: 1.0875576 | BI7: 0.54968944 | BJ7: 3912.3054 | BK7: 6.0096857 | BL7: 3.0375042 | BM7: =Water!U9 -> 1.0640494 | BN7: =Water!W9 -> #DIV/0! | BO7: =Water!X9 -> 957.64444 | BP7: =Water!Y9 -> 4.2561975 | BQ7: =Water!Z9 -> #DIV/0!
