Workbook

Sheet TOTAL
A1: Site Name | B1: Day | C1: Month | D1: Year | E1: Total Electricity Kwh | F1: Electricity Tariff ($/Kwh) | G1: Water Utility Supply (m3) m3 | H1: Water Utility Supply (m3) $/m3 | I1: Total Fuel Oil (Liters) | J1: Fuel Oil $/Liter | K1: Room Nights
A2: Kuwait | B2: 1 | C2: 2 | D2: 2023 | E2: =Submetering!E2+Submetering!F2+Submetering!G2+Submetering!H2+Submetering!I2+Submetering!J2+Submetering!K2+Submetering!L2+Submetering!M2+Submetering!N2+Submetering!O2+Submetering!P2+Submetering!Q2 -> 55190 | F2: 0.005 | G2: =Submetering!S2 -> 365.547 | H2: 0.4444 | I2: =Submetering!R2 -> 0 | J2: 0.14 | K2: =Hotel!B7 -> 141
A3: Kuwait | B3: =B2+1 -> 2 | C3: 2 | D3: 2023 | E3: =Submetering!E3+Submetering!F3+Submetering!G3+Submetering!H3+Submetering!I3+Submetering!J3+Submetering!K3+Submetering!L3+Submetering!M3+Submetering!N3+Submetering!O3+Submetering!P3+Submetering!Q3 -> 59780 | F3: 0.005 | G3: =Submetering!S3 -> 438.165 | H3: 0.4444 | I3: =Submetering!R3 -> 0 | J3: 0.14 | K3: =Hotel!B8 -> 144
A4: Kuwait | B4: =B3+1 -> 3 | C4: 2 | D4: 2023 | E4: =Submetering!E4+Submetering!F4+Submetering!G4+Submetering!H4+Submetering!I4+Submetering!J4+Submetering!K4+Submetering!L4+Submetering!M4+Submetering!N4+Submetering!O4+Submetering!P4+Submetering!Q4 -> 55270 | F4: 0.005 | G4: =Submetering!S4 -> 361.998 | H4: 0.4444 | I4: =Submetering!R4 -> 0 | J4: 0.14 | K4: =Hotel!B9 -> 184
A5: Kuwait | B5: =B4+1 -> 4 | C5: 2 | D5: 2023 | E5: =Submetering!E5+Submetering!F5+Submetering!G5+Submetering!H5+Submetering!I5+Submetering!J5+Submetering!K5+Submetering!L5+Submetering!M5+Submetering!N5+Submetering!O5+Submetering!P5+Submetering!Q5 -> 59580 | F5: 0.005 | G5: =Submetering!S5 -> 429.156 | H5: 0.4444 | I5: =Submetering!R5 -> 0 | J5: 0.14 | K5: =Hotel!B10 -> 119
A6: Kuwait | B6: =B5+1 -> 5 | C6: 2 | D6: 2023 | E6: =Submetering!E6+Submetering!F6+Submetering!G6+Submetering!H6+Submetering!I6+Submetering!J6+Submetering!K6+Submetering!L6+Submetering!M6+Submetering!N6+Submetering!O6+Submetering!P6+Submetering!Q6 -> 53010 | F6: 0.005 | G6: =Submetering!S6 -> 398.034 | H6: 0.4444 | I6: =Submetering!R6 -> 0 | J6: 0.14 | K6: =Hotel!B11 -> 125
A7: Kuwait | B7: =B6+1 -> 6 | C7: 2 | D7: 2023 | E7: =Submetering!E7+Submetering!F7+Submetering!G7+Submetering!H7+Submetering!I7+Submetering!J7+Submetering!K7+Submetering!L7+Submetering!M7+Submetering!N7+Submetering!O7+Submetering!P7+Submetering!Q7 -> 59360 | F7: 0.005 | G7: =Submetering!S7 -> 420.42 | H7: 0.4444 | I7: =Submetering!R7 -> 0 | J7: 0.14 | K7: =Hotel!B12 -> 159
A8: Kuwait | B8: =B7+1 -> 7 | C8: 2 | D8: 2023 | E8: =Submetering!E8+Submetering!F8+Submetering!G8+Submetering!H8+Submetering!I8+Submetering!J8+Submetering!K8+Submetering!L8+Submetering!M8+Submetering!N8+Submetering!O8+Submetering!P8+Submetering!Q8 -> 51780 | F8: 0.005 | G8: =Submetering!S8 -> 333.06 | H8: 0.4444 | I8: =Submetering!R8 -> 0 | J8: 0.14 | K8: =Hotel!B13 -> 140
A9: Kuwait | B9: =B8+1 -> 8 | C9: 2 | D9: 2023 | E9: =Submetering!E9+Submetering!F9+Submetering!G9+Submetering!H9+Submetering!I9+Submetering!J9+Submetering!K9+Submetering!L9+Submetering!M9+Submetering!N9+Submetering!O9+Submetering!P9+Submetering!Q9 -> 56020 | F9: 0.005 | G9: =Submetering!S9 -> 526.617 | H9: 0.4444 | I9: =Submetering!R9 -> 0 | J9: 0.14 | K9: =Hotel!B14 -> 142
A10: Kuwait | B10: =B9+1 -> 9 | C10: 2 | D10: 2023 | E10: =Submetering!E10+Submetering!F10+Submetering!G10+Submetering!H10+Submetering!I10+Submetering!J10+Submetering!K10+Submetering!L10+Submetering!M10+Submetering!N10+Submetering!O10+Submetering!P10+Submetering!Q10 -> 59780 | F10: 0.005 | G10: =Submetering!S10 -> 472.836 | H10: 0.4444 | I10: =Submetering!R10 -> 1122.1875 | J10: 0.14 | K10: =Hotel!B15 -> 156
A11: Kuwait | B11: =B10+1 -> 10 | C11: 2 | D11: 2023 | E11: =Submetering!E11+Submetering!F11+Submetering!G11+Submetering!H11+Submetering!I11+Submetering!J11+Submetering!K11+Submetering!L11+Submetering!M11+Submetering!N11+Submetering!O11+Submetering!P11+Submetering!Q11 -> 57830 | F11: 0.005 | G11: =Submetering!S11 -> 332.241 | H11: 0.4444 | I11: =Submetering!R11 -> 0 | J11: 0.14 | K11: =Hotel!B16 -> 161
A12: Kuwait | B12: =B11+1 -> 11 | C12: 2 | D12: 2023 | E12: =Submetering!E12+Submetering!F12+Submetering!G12+Submetering!H12+Submetering!I12+Submetering!J12+Submetering!K12+Submetering!L12+Submetering!M12+Submetering!N12+Submetering!O12+Submetering!P12+Submetering!Q12 -> 59450 | F12: 0.005 | G12: =Submetering!S12 -> 468.741 | H12: 0.4444 | I12: =Submetering!R12 -> 1442.8125 | J12: 0.14 | K12: =Hotel!B17 -> 101
A13: Kuwait | B13: =B12+1 -> 12 | C13: 2 | D13: 2023 | E13: =Submetering!E13+Submetering!F13+Submetering!G13+Submetering!H13+Submetering!I13+Submetering!J13+Submetering!K13+Submetering!L13+Submetering!M13+Submetering!N13+Submetering!O13+Submetering!P13+Submetering!Q13 -> 54730 | F13: 0.005 | G13: =Submetering!S13 -> 419.328 | H13: 0.4444 | I13: =Submetering!R13 -> 783.75 | J13: 0.14 | K13: =Hotel!B18 -> 110
A14: Kuwait | B14: =B13+1 -> 13 | C14: 2 | D14: 2023 | E14: =Submetering!E14+Submetering!F14+Submetering!G14+Submetering!H14+Submetering!I14+Submetering!J14+Submetering!K14+Submetering!L14+Submetering!M14+Submetering!N14+Submetering!O14+Submetering!P14+Submetering!Q14 -> 58320 | F14: 0.005 | G14: =Submetering!S14 -> 412.503 | H14: 0.4444 | I14: =Submetering!R14 -> 0 | J14: 0.14 | K14: =Hotel!B19 -> 150
... A32: Kuwait | B32: =B31+1 -> 31 | C32: 2 | D32: 2023 | E32: =Submetering!E32+Submetering!F32+Submetering!G32+Submetering!H32+Submetering!I32+Submetering!J32+Submetering!K32+Submetering!L32+Submetering!M32+Submetering!N32+Submetering!O32+Submetering!P32+Submetering!Q32 -> 0 | F32: 0.005 | G32: =Submetering!S32 -> 0 | H32: 0.4444 | I32: =Submetering!R32 -> 0 | J32: 0.14 | K32: =Hotel!B37 -> 0

Sheet Submetering
A1: Site Name | B1: Day | C1: Month | D1: Year | E1: HT.02.02 - KWh | F1: HT.02.04 - KWh | G1: HT.02.07 - KWh | H1: HT.02.03 - KWh | I1: HT.02.06 - KWh | J1: HT.03.03 - KWh | K1: HT.03.07 - KWh | L1: HT.03.05 - KWh | M1: HT.03.08 - KWh | N1: HT.03.04 - KWh | O1: HT.03.06 - KWh | P1: HT.03.01 - KWh | Q1: HT.03.02 - KWh | R1: Fuel (Liters) | S1: Water - m3 | T1: Cooling Towers Water | U1: Room Nights
A2: Kuwait | B2: 1 | C2: 2 | D2: 2023 | E2: =Hotel!Q7 -> 560 | F2: =Hotel!R7 -> 1770 | G2: =Hotel!S7 -> 2600 | H2: =Hotel!T7 -> 1370 | I2: =Hotel!U7 -> 6120 | J2: =Hotel!V7 -> 4070 | K2: =Hotel!W7 -> 3620 | L2: =Hotel!X7 -> 4170 | ... Q2: =Hotel!AC7 -> 13140 | R2: =Hotel!AU7 -> 0 | S2: =Hotel!BB7 -> 365.547 | T2: =Hotel!AY7 -> 0 | U2: =Hotel!B7 -> 141
A3: Kuwait | B3: =B2+1 -> 2 | C3: 2 | D3: 2023 | E3: =Hotel!Q8 -> 610 | F3: =Hotel!R8 -> 1940 | G3: =Hotel!S8 -> 2910 | H3: =Hotel!T8 -> 1510 | I3: =Hotel!U8 -> 6700 | J3: =Hotel!V8 -> 4560 | K3: =Hotel!W8 -> 3580 | L3: =Hotel!X8 -> 4420 | ... Q3: =Hotel!AC8 -> 13110 | R3: =Hotel!AU8 -> 0 | S3: =Hotel!BB8 -> 438.165 | T3: =Hotel!AY8 -> 0 | U3: =Hotel!B8 -> 144
A4: Kuwait | B4: =B3+1 -> 3 | C4: 2 | D4: 2023 | E4: =Hotel!Q9 -> 550 | F4: =Hotel!R9 -> 1750 | G4: =Hotel!S9 -> 2600 | H4: =Hotel!T9 -> 1360 | I4: =Hotel!U9 -> 6100 | J4: =Hotel!V9 -> 4130 | K4: =Hotel!W9 -> 3110 | L4: =Hotel!X9 -> 4090 | ... Q4: =Hotel!AC9 -> 12950 | R4: =Hotel!AU9 -> 0 | S4: =Hotel!BB9 -> 361.998 | T4: =Hotel!AY9 -> 0 | U4: =Hotel!B9 -> 184
A5: Kuwait | B5: =B4+1 -> 4 | C5: 2 | D5: 2023 | E5: =Hotel!Q10 -> 600 | F5: =Hotel!R10 -> 1920 | G5: =Hotel!S10 -> 2720 | H5: =Hotel!T10 -> 1510 | I5: =Hotel!U10 -> 6660 | J5: =Hotel!V10 -> 4440 | K5: =Hotel!W10 -> 3220 | L5: =Hotel!X10 -> 4420 | ... Q5: =Hotel!AC10 -> 13520 | R5: =Hotel!AU10 -> 0 | S5: =Hotel!BB10 -> 429.156 | T5: =Hotel!AY10 -> 0 | U5: =Hotel!B10 -> 119
A6: Kuwait | B6: =B5+1 -> 5 | C6: 2 | D6: 2023 | E6: =Hotel!Q11 -> 560 | F6: =Hotel!R11 -> 1770 | G6: =Hotel!S11 -> 2600 | H6: =Hotel!T11 -> 1390 | I6: =Hotel!U11 -> 5900 | J6: =Hotel!V11 -> 4030 | K6: =Hotel!W11 -> 3140 | L6: =Hotel!X11 -> 4020 | ... Q6: =Hotel!AC11 -> 11190 | R6: =Hotel!AU11 -> 0 | S6: =Hotel!BB11 -> 398.034 | T6: =Hotel!AY11 -> 0 | U6: =Hotel!B11 -> 125
A7: Kuwait | B7: =B6+1 -> 6 | C7: 2 | D7: 2023 | E7: =Hotel!Q12 -> 620 | F7: =Hotel!R12 -> 1980 | G7: =Hotel!S12 -> 3020 | H7: =Hotel!T12 -> 1410 | I7: =Hotel!U12 -> 6390 | J7: =Hotel!V12 -> 4460 | K7: =Hotel!W12 -> 3710 | L7: =Hotel!X12 -> 4470 | ... Q7: =Hotel!AC12 -> 13240 | R7: =Hotel!AU12 -> 0 | S7: =Hotel!BB12 -> 420.42 | T7: =Hotel!AY12 -> 0 | U7: =Hotel!B12 -> 159
A8: Kuwait | B8: =B7+1 -> 7 | C8: 2 | D8: 2023 | E8: =Hotel!Q13 -> 540 | F8: =Hotel!R13 -> 1720 | G8: =Hotel!S13 -> 2530 | H8: =Hotel!T13 -> 1110 | I8: =Hotel!U13 -> 5600 | J8: =Hotel!V13 -> 3890 | K8: =Hotel!W13 -> 3080 | L8: =Hotel!X13 -> 4190 | ... Q8: =Hotel!AC13 -> 11270 | R8: =Hotel!AU13 -> 0 | S8: =Hotel!BB13 -> 333.06 | T8: =Hotel!AY13 -> 0 | U8: =Hotel!B13 -> 140
A9: Kuwait | B9: =B8+1 -> 8 | C9: 2 | D9: 2023 | E9: =Hotel!Q14 -> 550 | F9: =Hotel!R14 -> 1840 | G9: =Hotel!S14 -> 2580 | H9: =Hotel!T14 -> 1190 | I9: =Hotel!U14 -> 6200 | J9: =Hotel!V14 -> 4260 | K9: =Hotel!W14 -> 3690 | L9: =Hotel!X14 -> 4460 | ... Q9: =Hotel!AC14 -> 12250 | R9: =Hotel!AU14 -> 0 | S9: =Hotel!BB14 -> 526.617 | T9: =Hotel!AY14 -> 0 | U9: =Hotel!B14 -> 142
A10: Kuwait | B10: =B9+1 -> 9 | C10: 2 | D10: 2023 | E10: =Hotel!Q15 -> 560 | F10: =Hotel!R15 -> 1840 | G10: =Hotel!S15 -> 2500 | H10: =Hotel!T15 -> 1180 | I10: =Hotel!U15 -> 6610 | J10: =Hotel!V15 -> 4380 | K10: =Hotel!W15 -> 3140 | L10: =Hotel!X15 -> 4570 | ... Q10: =Hotel!AC15 -> 15700 | R10: =Hotel!AU15 -> 1122.1875 | S10: =Hotel!BB15 -> 472.836 | T10: =Hotel!AY15 -> 0 | U10: =Hotel!B15 -> 156
A11: Kuwait | B11: =B10+1 -> 10 | C11: 2 | D11: 2023 | E11: =Hotel!Q16 -> 550 | F11: =Hotel!R16 -> 1850 | G11: =Hotel!S16 -> 2390 | H11: =Hotel!T16 -> 1180 | I11: =Hotel!U16 -> 6200 | J11: =Hotel!V16 -> 4300 | K11: =Hotel!W16 -> 2970 | L11: =Hotel!X16 -> 4480 | ... Q11: =Hotel!AC16 -> 14040 | R11: =Hotel!AU16 -> 0 | S11: =Hotel!BB16 -> 332.241 | T11: =Hotel!AY16 -> 0 | U11: =Hotel!B16 -> 161
A12: Kuwait | B12: =B11+1 -> 11 | C12: 2 | D12: 2023 | E12: =Hotel!Q17 -> 570 | F12: =Hotel!R17 -> 1900 | G12: =Hotel!S17 -> 2500 | H12: =Hotel!T17 -> 1220 | I12: =Hotel!U17 -> 6530 | J12: =Hotel!V17 -> 4580 | K12: =Hotel!W17 -> 3030 | L12: =Hotel!X17 -> 4700 | ... Q12: =Hotel!AC17 -> 14250 | R12: =Hotel!AU17 -> 1442.8125 | S12: =Hotel!BB17 -> 468.741 | T12: =Hotel!AY17 -> 0 | U12: =Hotel!B17 -> 101
A13: Kuwait | B13: =B12+1 -> 12 | C13: 2 | D13: 2023 | E13: =Hotel!Q18 -> 530 | F13: =Hotel!R18 -> 1780 | G13: =Hotel!S18 -> 2490 | H13: =Hotel!T18 -> 1150 | I13: =Hotel!U18 -> 5690 | J13: =Hotel!V18 -> 3910 | K13: =Hotel!W18 -> 2830 | L13: =Hotel!X18 -> 4020 | ... Q13: =Hotel!AC18 -> 14510 | R13: =Hotel!AU18 -> 783.75 | S13: =Hotel!BB18 -> 419.328 | T13: =Hotel!AY18 -> 261195.43 | U13: =Hotel!B18 -> 110
A14: Kuwait | B14: =B13+1 -> 13 | C14: 2 | D14: 2023 | E14: =Hotel!Q19 -> 570 | F14: =Hotel!R19 -> 1870 | G14: =Hotel!S19 -> 2390 | H14: =Hotel!T19 -> 1180 | I14: =Hotel!U19 -> 5910 | J14: =Hotel!V19 -> 4300 | K14: =Hotel!W19 -> 3020 | L14: =Hotel!X19 -> 4510 | ... Q14: =Hotel!AC19 -> 15400 | R14: =Hotel!AU19 -> 0 | S14: =Hotel!BB19 -> 412.503 | T14: =Hotel!AY19 -> 121.28 | U14: =Hotel!B19 -> 150
... A32: Kuwait | B32: =B31+1 -> 31 | C32: 2 | D32: 2023 | E32: =Hotel!Q37 -> 0 | F32: =Hotel!R37 -> 0 | G32: =Hotel!S37 -> 0 | H32: =Hotel!T37 -> 0 | I32: =Hotel!U37 -> 0 | J32: =Hotel!V37 -> 0 | K32: =Hotel!W37 -> 0 | L32: =Hotel!X37 -> 0 | ... Q32: =Hotel!AC37 -> 0 | R32: =Hotel!AU37 -> 0 | S32: =Hotel!BB37 -> 0 | T32: =Hotel!AY37 -> 0 | U32: =Hotel!B37 -> 0

Sheet Hotel
C1: 1 | D1: 2 | E1: 3 | F1: 4 | G1: 5 | H1: 6 | I1: 7 | J1: 8 | K1: 9 | L1: 10 | M1: 11 | N1: 12 | O1: 13 | Q1: 1 | R1: 2 | S1: 3 | T1: 4 | U1: 5 | V1: 6 | W1: 7 | X1: 8 | Y1: 9 | Z1: 10 | AA1: 11 | AB1: 12 | AC1: 13
A2: 44957 | B2: 116 | C2: 8814830 | D2: 21180080 | E2: 3940940 | F2: 4462750 | G2: 13260500 | H2: 7913930 | I2: 6822130 | J2: 8559530 | K2: 12355430 | L2: 5390070 | M2: 9757950 | N2: 16373790 | O2: 23059160 | Q2: HT.02.02 | R2: HT.02.04 | S2: HT.02.07 | T2: HT.02.03 | U2: HT.02.06 | V2: HT.03.03 | W2: HT.03.07 | X2: HT.03.05 | Y2: HT.03.08 | Z2: HT.03.04 | AA2: HT.03.06 | AB2: HT.03.01 | AC2: HT.03.02 | AW2: 67633 | AZ2: 407070
A4: Date | B4: Room Night | C4: Feb | D4: Electricity - Meter No | Q4: Electricity Consumption -KWh | AD4: Total KWh | AF4: Electricity Consumption - Amount | AS4: Total Kd | AT4: Fuel Consumption (%) | AU4: Fuel Consumption (Liters) | AW4: CT Water Meter Reading | AX4: CT Consumption Gallons | AY4: CT Consumption Cubic Meter | AZ4: Water Meter Reading | BA4: Consumption Gallons | BB4: Consumption Cubic Meter | BC4: Total KD
A5: 2023 | C5: HT.02.02 | D5: HT.02.04 | E5: HT.02.07 | F5: HT.02.03 | G5: HT.02.06 | H5: HT.03.03 | I5: HT.03.07 | J5: HT.03.05 | K5: HT.03.08 | L5: HT.03.04 | M5: HT.03.06 | N5: HT.03.01 | O5: HT.03.02 | Q5: 8483196 | R5: 8483193 | S5: 8483178 | T5: 8483176 | U5: 8483206 | V5: 8483170 | W5: 8483168 | X5: 8483169 | Y5: 8483194 | Z5: 8483199 | AA5: 8483187 | AB5: 8483188 | AC5: 8483174 | AF5: 1 | AG5: 2 | AH5: 3 | AI5: 4 | AJ5: 5 | AK5: 6 | AL5: 7 | AM5: 8 | AN5: 9 | AO5: 10 | AP5: 11 | AQ5: 12 | AR5: 13
C6: 8483196 | D6: 8483193 | E6: 8483178 | F6: 8483176 | G6: 8483206 | H6: 8483170 | I6: 8483168 | J6: 8483169 | K6: 8483194 | L6: 8483199 | M6: 8483187 | N6: 8483188 | O6: 8483174 | AW6: 67633 | AZ6: 407070
A7: 44958 | B7: 141 | C7: 8815390 | D7: 21181850 | E7: 3943540 | F7: 4464120 | G7: 13266620 | H7: 7918000 | I7: 6825750 | J7: 8563700 | K7: 12361120 | L7: 5392510 | M7: 9760650 | N7: 16380730 | O7: 23072300 | Q7: =IF((C7-C2<0), "0",C7-C2) -> 560 | R7: =IF((D7-D2<0), "0",D7-D2) -> 1770 | S7: =IF((E7-E2<0), "0",E7-E2) -> 2600 | T7: =IF((F7-F2<0), "0",F7-F2) -> 1370 | U7: =IF((G7-G2<0), "0",G7-G2) -> 6120 | V7: =IF((H7-H2<0), "0",H7-H2) -> 4070 | W7: =IF((I7-I2<0), "0",I7-I2) -> 3620 | X7: =IF((J7-J2<0), "0",J7-J2) -> 4170 | ... AC7: =IF((O7-O2<0), "0",O7-O2) -> 13140 | AD7: =SUM(Q7:AC7) -> 55190 | AF7: =Q7*$D$39 -> 2.8 | AG7: =R7*$D$39 -> 8.85 | AH7: =S7*$D$39 -> 13 | AI7: =T7*$D$39 -> 6.85 | AJ7: =U7*$D$39 -> 30.6 | AK7: =V7*$D$39 -> 20.35 | AL7: =W7*$D$39 -> 18.1 | AM7: =X7*$D$39 -> 20.85 | ... AR7: =AC7*$D$39 -> 65.7 | AS7: =SUM(AF7:AR7) -> 275.95 | AU7: =AT7*$AU$43 -> 0 | AW7: 0 | AX7: =(IF((AW7-AW6<0),"0",AW7-AW6))*1000 -> 0 | AY7: =AX7*$AY$44 -> 0 | AZ7: 408409 | BA7: =(IF((AZ7-AZ6<0),"0",AZ7-AZ6))*100 -> 133900 | BB7: =BA7*$BA$44*60% -> 365.547 | BC7: =BB7*0.4444 -> 162.44909
A8: 44959 | B8: 144 | C8: 8816000 | D8: 21183790 | E8: 3946450 | F8: 4465630 | G8: 13273320 | H8: 7922560 | I8: 6829330 | J8: 8568120 | K8: 12367480 | L8: 5395200 | M8: 9764080 | N8: 16388690 | O8: 23085410 | Q8: =IF((C8-C7<0), "0",C8-C7) -> 610 | R8: =IF((D8-D7<0), "0",D8-D7) -> 1940 | S8: =IF((E8-E7<0), "0",E8-E7) -> 2910 | T8: =IF((F8-F7<0), "0",F8-F7) -> 1510 | U8: =IF((G8-G7<0), "0",G8-G7) -> 6700 | V8: =IF((H8-H7<0), "0",H8-H7) -> 4560 | W8: =IF((I8-I7<0), "0",I8-I7) -> 3580 | X8: =IF((J8-J7<0), "0",J8-J7) -> 4420 | ... AC8: =IF((O8-O7<0), "0",O8-O7) -> 13110 | AD8: =SUM(Q8:AC8) -> 59780 | AF8: =Q8*$D$39 -> 3.05 | AG8: =R8*$D$39 -> 9.7 | AH8: =S8*$D$39 -> 14.55 | AI8: =T8*$D$39 -> 7.55 | AJ8: =U8*$D$39 -> 33.5 | AK8: =V8*$D$39 -> 22.8 | AL8: =W8*$D$39 -> 17.9 | AM8: =X8*$D$39 -> 22.1 | ... AR8: =AC8*$D$39 -> 65.55 | AS8: =SUM(AF8:AR8) -> 298.9 | AU8: =AT8*$AU$43 -> 0 | AW8: 0 | AX8: =(IF((AW8-AW7<0),"0",AW8-AW7))*1000 -> 0 | AY8: =AX8*$AY$44 -> 0 | AZ8: 410014 | BA8: =(IF((AZ8-AZ7<0),"0",AZ8-AZ7))*100 -> 160500 | BB8: =BA8*$BA$44*60% -> 438.165 | BC8: =BB8*0.4444 -> 194.72053
A9: 44960 | B9: 184 | C9: 8816550 | D9: 21185540 | E9: 3949050 | F9: 4466990 | G9: 13279420 | H9: 7926690 | I9: 6832440 | J9: 8572210 | K9: 12373280 | L9: 5397730 | M9: 9767370 | N9: 16395700 | O9: 23098360 | Q9: =IF((C9-C8<0), "0",C9-C8) -> 550 | R9: =IF((D9-D8<0), "0",D9-D8) -> 1750 | S9: =IF((E9-E8<0), "0",E9-E8) -> 2600 | T9: =IF((F9-F8<0), "0",F9-F8) -> 1360 | U9: =IF((G9-G8<0), "0",G9-G8) -> 6100 | V9: =IF((H9-H8<0), "0",H9-H8) -> 4130 | W9: =IF((I9-I8<0), "0",I9-I8) -> 3110 | X9: =IF((J9-J8<0), "0",J9-J8) -> 4090 | ... AC9: =IF((O9-O8<0), "0",O9-O8) -> 12950 | AD9: =SUM(Q9:AC9) -> 55270 | AF9: =Q9*$D$39 -> 2.75 | AG9: =R9*$D$39 -> 8.75 | AH9: =S9*$D$39 -> 13 | AI9: =T9*$D$39 -> 6.8 | AJ9: =U9*$D$39 -> 30.5 | AK9: =V9*$D$39 -> 20.65 | AL9: =W9*$D$39 -> 15.55 | AM9: =X9*$D$39 -> 20.45 | ... AR9: =AC9*$D$39 -> 64.75 | AS9: =SUM(AF9:AR9) -> 276.35 | AU9: =AT9*$AU$43 -> 0 | AW9: 0 | AX9: =(IF((AW9-AW8<0),"0",AW9-AW8))*1000 -> 0 | AY9: =AX9*$AY$44 -> 0 | AZ9: 411340 | BA9: =(IF((AZ9-AZ8<0),"0",AZ9-AZ8))*100 -> 132600 | BB9: =BA9*$BA$44*60% -> 361.998 | BC9: =BB9*0.4444 -> 160.87191
A10: 44961 | B10: 119 | C10: 8817150 | D10: 21187460 | E10: 3951770 | F10: 4468500 | G10: 13286080 | H10: 7931130 | I10: 6835660 | J10: 8576630 | K10: 12379870 | L10: 5400480 | M10: 9770770 | N10: 16403530 | O10: 23111880 | Q10: =IF((C10-C9<0), "0",C10-C9) -> 600 | R10: =IF((D10-D9<0), "0",D10-D9) -> 1920 | S10: =IF((E10-E9<0), "0",E10-E9) -> 2720 | T10: =IF((F10-F9<0), "0",F10-F9) -> 1510 | U10: =IF((G10-G9<0), "0",G10-G9) -> 6660 | V10: =IF((H10-H9<0), "0",H10-H9) -> 4440 | W10: =IF((I10-I9<0), "0",I10-I9) -> 3220 | X10: =IF((J10-J9<0), "0",J10-J9) -> 4420 | ... AC10: =IF((O10-O9<0), "0",O10-O9) -> 13520 | AD10: =SUM(Q10:AC10) -> 59580 | AF10: =Q10*$D$39 -> 3 | AG10: =R10*$D$39 -> 9.6 | AH10: =S10*$D$39 -> 13.6 | AI10: =T10*$D$39 -> 7.55 | AJ10: =U10*$D$39 -> 33.3 | AK10: =V10*$D$39 -> 22.2 | AL10: =W10*$D$39 -> 16.1 | AM10: =X10*$D$39 -> 22.1 | ... AR10: =AC10*$D$39 -> 67.6 | AS10: =SUM(AF10:AR10) -> 297.9 | AU10: =AT10*$AU$43 -> 0 | AW10: 0 | AX10: =(IF((AW10-AW9<0),"0",AW10-AW9))*1000 -> 0 | AY10: =AX10*$AY$44 -> 0 | AZ10: 412912 | BA10: =(IF((AZ10-AZ9<0),"0",AZ10-AZ9))*100 -> 157200 | BB10: =BA10*$BA$44*60% -> 429.156 | BC10: =BB10*0.4444 -> 190.71693
A11: 44962 | B11: 125 | C11: 8817710 | D11: 21189230 | E11: 3954370 | F11: 4469890 | G11: 13291980 | H11: 7935160 | I11: 6838800 | J11: 8580650 | K11: 12385580 | L11: 5402920 | M11: 9773860 | N11: 16410700 | O11: 23123070 | Q11: =IF((C11-C10<0), "0",C11-C10) -> 560 | R11: =IF((D11-D10<0), "0",D11-D10) -> 1770 | S11: =IF((E11-E10<0), "0",E11-E10) -> 2600 | T11: =IF((F11-F10<0), "0",F11-F10) -> 1390 | U11: =IF((G11-G10<0), "0",G11-G10) -> 5900 | V11: =IF((H11-H10<0), "0",H11-H10) -> 4030 | W11: =IF((I11-I10<0), "0",I11-I10) -> 3140 | X11: =IF((J11-J10<0), "0",J11-J10) -> 4020 | ... AC11: =IF((O11-O10<0), "0",O11-O10) -> 11190 | AD11: =SUM(Q11:AC11) -> 53010 | AF11: =Q11*$D$39 -> 2.8 | AG11: =R11*$D$39 -> 8.85 | AH11: =S11*$D$39 -> 13 | AI11: =T11*$D$39 -> 6.95 | AJ11: =U11*$D$39 -> 29.5 | AK11: =V11*$D$39 -> 20.15 | AL11: =W11*$D$39 -> 15.7 | AM11: =X11*$D$39 -> 20.1 | ... AR11: =AC11*$D$39 -> 55.95 | AS11: =SUM(AF11:AR11) -> 265.05 | AU11: =AT11*$AU$43 -> 0 | AW11: 0 | AX11: =(IF((AW11-AW10<0),"0",AW11-AW10))*1000 -> 0 | AY11: =AX11*$AY$44 -> 0 | AZ11: 414370 | BA11: =(IF((AZ11-AZ10<0),"0",AZ11-AZ10))*100 -> 145800 | BB11: =BA11*$BA$44*60% -> 398.034 | BC11: =BB11*0.4444 -> 176.88631
A12: 44963 | B12: 159 | C12: 8818330 | D12: 21191210 | E12: 3957390 | F12: 4471300 | G12: 13298370 | H12: 7939620 | I12: 6842510 | J12: 8585120 | K12: 12391900 | L12: 5405680 | M12: 9777010 | N12: 16418530 | O12: 23136310 | Q12: =IF((C12-C11<0), "0",C12-C11) -> 620 | R12: =IF((D12-D11<0), "0",D12-D11) -> 1980 | S12: =IF((E12-E11<0), "0",E12-E11) -> 3020 | T12: =IF((F12-F11<0), "0",F12-F11) -> 1410 | U12: =IF((G12-G11<0), "0",G12-G11) -> 6390 | V12: =IF((H12-H11<0), "0",H12-H11) -> 4460 | W12: =IF((I12-I11<0), "0",I12-I11) -> 3710 | X12: =IF((J12-J11<0), "0",J12-J11) -> 4470 | ... AC12: =IF((O12-O11<0), "0",O12-O11) -> 13240 | AD12: =SUM(Q12:AC12) -> 59360 | AF12: =Q12*$D$39 -> 3.1 | AG12: =R12*$D$39 -> 9.9 | AH12: =S12*$D$39 -> 15.1 | AI12: =T12*$D$39 -> 7.05 | AJ12: =U12*$D$39 -> 31.95 | AK12: =V12*$D$39 -> 22.3 | AL12: =W12*$D$39 -> 18.55 | AM12: =X12*$D$39 -> 22.35 | ... AR12: =AC12*$D$39 -> 66.2 | AS12: =SUM(AF12:AR12) -> 296.8 | AU12: =AT12*$AU$43 -> 0 | AW12: 0 | AX12: =(IF((AW12-AW11<0),"0",AW12-AW11))*1000 -> 0 | AY12: =AX12*$AY$44 -> 0 | AZ12: 415910 | BA12: =(IF((AZ12-AZ11<0),"0",AZ12-AZ11))*100 -> 154000 | BB12: =BA12*$BA$44*60% -> 420.42 | BC12: =BB12*0.4444 -> 186.83465
A13: 44964 | B13: 140 | C13: 8818870 | D13: 21192930 | E13: 3959920 | F13: 4472410 | G13: 13303970 | H13: 7943510 | I13: 6845590 | J13: 8589310 | K13: 12397410 | L13: 5408080 | M13: 9780060 | N13: 16425420 | O13: 23147580 | Q13: =IF((C13-C12<0), "0",C13-C12) -> 540 | R13: =IF((D13-D12<0), "0",D13-D12) -> 1720 | S13: =IF((E13-E12<0), "0",E13-E12) -> 2530 | T13: =IF((F13-F12<0), "0",F13-F12) -> 1110 | U13: =IF((G13-G12<0), "0",G13-G12) -> 5600 | V13: =IF((H13-H12<0), "0",H13-H12) -> 3890 | W13: =IF((I13-I12<0), "0",I13-I12) -> 3080 | X13: =IF((J13-J12<0), "0",J13-J12) -> 4190 | ... AC13: =IF((O13-O12<0), "0",O13-O12) -> 11270 | AD13: =SUM(Q13:AC13) -> 51780 | AF13: =Q13*$D$39 -> 2.7 | AG13: =R13*$D$39 -> 8.6 | AH13: =S13*$D$39 -> 12.65 | AI13: =T13*$D$39 -> 5.55 | AJ13: =U13*$D$39 -> 28 | AK13: =V13*$D$39 -> 19.45 | AL13: =W13*$D$39 -> 15.4 | AM13: =X13*$D$39 -> 20.95 | ... AR13: =AC13*$D$39 -> 56.35 | AS13: =SUM(AF13:AR13) -> 258.9 | AU13: =AT13*$AU$43 -> 0 | AW13: 0 | AX13: =(IF((AW13-AW12<0),"0",AW13-AW12))*1000 -> 0 | AY13: =AX13*$AY$44 -> 0 | AZ13: 417130 | BA13: =(IF((AZ13-AZ12<0),"0",AZ13-AZ12))*100 -> 122000 | BB13: =BA13*$BA$44*60% -> 333.06 | BC13: =BB13*0.4444 -> 148.01186
A14: 44965 | B14: 142 | C14: 8819420 | D14: 21194770 | E14: 3962500 | F14: 4473600 | G14: 13310170 | H14: 7947770 | I14: 6849280 | J14: 8593770 | K14: 12403480 | L14: 5410610 | M14: 9783170 | N14: 16432710 | O14: 23159830 | Q14: =IF((C14-C13<0), "0",C14-C13) -> 550 | R14: =IF((D14-D13<0), "0",D14-D13) -> 1840 | S14: =IF((E14-E13<0), "0",E14-E13) -> 2580 | T14: =IF((F14-F13<0), "0",F14-F13) -> 1190 | U14: =IF((G14-G13<0), "0",G14-G13) -> 6200 | V14: =IF((H14-H13<0), "0",H14-H13) -> 4260 | W14: =IF((I14-I13<0), "0",I14-I13) -> 3690 | X14: =IF((J14-J13<0), "0",J14-J13) -> 4460 | ... AC14: =IF((O14-O13<0), "0",O14-O13) -> 12250 | AD14: =SUM(Q14:AC14) -> 56020 | AF14: =Q14*$D$39 -> 2.75 | AG14: =R14*$D$39 -> 9.2 | AH14: =S14*$D$39 -> 12.9 | AI14: =T14*$D$39 -> 5.95 | AJ14: =U14*$D$39 -> 31 | AK14: =V14*$D$39 -> 21.3 | AL14: =W14*$D$39 -> 18.45 | AM14: =X14*$D$39 -> 22.3 | ... AR14: =AC14*$D$39 -> 61.25 | AS14: =SUM(AF14:AR14) -> 280.1 | AT14: 0 | AU14: =AT14*$AU$43 -> 0 | AW14: 0 | AX14: =(IF((AW14-AW13<0),"0",AW14-AW13))*1000 -> 0 | AY14: =AX14*$AY$44 -> 0 | AZ14: 419059 | BA14: =(IF((AZ14-AZ13<0),"0",AZ14-AZ13))*100 -> 192900 | BB14: =BA14*$BA$44*60% -> 526.617 | BC14: =BB14*0.4444 -> 234.02859
A15: 44966 | B15: 156 | C15: 8819980 | D15: 21196610 | E15: 3965000 | F15: 4474780 | G15: 13316780 | H15: 7952150 | I15: 6852420 | J15: 8598340 | K15: 12409270 | L15: 5413190 | M15: 9786500 | N15: 16440310 | O15: 23175530 | Q15: =IF((C15-C14<0), "0",C15-C14) -> 560 | R15: =IF((D15-D14<0), "0",D15-D14) -> 1840 | S15: =IF((E15-E14<0), "0",E15-E14) -> 2500 | T15: =IF((F15-F14<0), "0",F15-F14) -> 1180 | U15: =IF((G15-G14<0), "0",G15-G14) -> 6610 | V15: =IF((H15-H14<0), "0",H15-H14) -> 4380 | W15: =IF((I15-I14<0), "0",I15-I14) -> 3140 | X15: =IF((J15-J14<0), "0",J15-J14) -> 4570 | ... AC15: =IF((O15-O14<0), "0",O15-O14) -> 15700 | AD15: =SUM(Q15:AC15) -> 59780 | AF15: =Q15*$D$39 -> 2.8 | AG15: =R15*$D$39 -> 9.2 | AH15: =S15*$D$39 -> 12.5 | AI15: =T15*$D$39 -> 5.9 | AJ15: =U15*$D$39 -> 33.05 | AK15: =V15*$D$39 -> 21.9 | AL15: =W15*$D$39 -> 15.7 | AM15: =X15*$D$39 -> 22.85 | ... AR15: =AC15*$D$39 -> 78.5 | AS15: =SUM(AF15:AR15) -> 298.9 | AT15: 6.3 | AU15: =AT15*$AU$43 -> 1122.1875 | AW15: 0 | AX15: =(IF((AW15-AW14<0),"0",AW15-AW14))*1000 -> 0 | AY15: =AX15*$AY$44 -> 0 | AZ15: 420791 | BA15: =(IF((AZ15-AZ14<0),"0",AZ15-AZ14))*100 -> 173200 | BB15: =BA15*$BA$44*60% -> 472.836 | BC15: =BB15*0.4444 -> 210.12832
A16: 44967 | B16: 161 | C16: 8820530 | D16: 21198460 | E16: 3967390 | F16: 4475960 | G16: 13322980 | H16: 7956450 | I16: 6855390 | J16: 8602820 | K16: 12415350 | L16: 5415930 | M16: 9789900 | N16: 16447960 | O16: 23189570 | Q16: =IF((C16-C15<0), "0",C16-C15) -> 550 | R16: =IF((D16-D15<0), "0",D16-D15) -> 1850 | S16: =IF((E16-E15<0), "0",E16-E15) -> 2390 | T16: =IF((F16-F15<0), "0",F16-F15) -> 1180 | U16: =IF((G16-G15<0), "0",G16-G15) -> 6200 | V16: =IF((H16-H15<0), "0",H16-H15) -> 4300 | W16: =IF((I16-I15<0), "0",I16-I15) -> 2970 | X16: =IF((J16-J15<0), "0",J16-J15) -> 4480 | ... AC16: =IF((O16-O15<0), "0",O16-O15) -> 14040 | AD16: =SUM(Q16:AC16) -> 57830 | AF16: =Q16*$D$39 -> 2.75 | AG16: =R16*$D$39 -> 9.25 | AH16: =S16*$D$39 -> 11.95 | AI16: =T16*$D$39 -> 5.9 | AJ16: =U16*$D$39 -> 31 | AK16: =V16*$D$39 -> 21.5 | AL16: =W16*$D$39 -> 14.85 | AM16: =X16*$D$39 -> 22.4 | ... AR16: =AC16*$D$39 -> 70.2 | AS16: =SUM(AF16:AR16) -> 289.15 | AT16: 0 | AU16: =AT16*$AU$43 -> 0 | AW16: 0 | AX16: =(IF((AW16-AW15<0),"0",AW16-AW15))*1000 -> 0 | AY16: =AX16*$AY$44 -> 0 | AZ16: 422008 | BA16: =(IF((AZ16-AZ15<0),"0",AZ16-AZ15))*100 -> 121700 | BB16: =BA16*$BA$44*60% -> 332.241 | BC16: =BB16*0.4444 -> 147.6479
A17: 44968 | B17: 101 | C17: 8821100 | D17: 21200360 | E17: 3969890 | F17: 4477180 | G17: 13329510 | H17: 7961030 | I17: 6858420 | J17: 8607520 | K17: 12421440 | L17: 5418740 | M17: 9793220 | N17: 16455910 | O17: 23203820 | Q17: =IF((C17-C16<0), "0",C17-C16) -> 570 | R17: =IF((D17-D16<0), "0",D17-D16) -> 1900 | S17: =IF((E17-E16<0), "0",E17-E16) -> 2500 | T17: =IF((F17-F16<0), "0",F17-F16) -> 1220 | U17: =IF((G17-G16<0), "0",G17-G16) -> 6530 | V17: =IF((H17-H16<0), "0",H17-H16) -> 4580 | W17: =IF((I17-I16<0), "0",I17-I16) -> 3030 | X17: =IF((J17-J16<0), "0",J17-J16) -> 4700 | ... AC17: =IF((O17-O16<0), "0",O17-O16) -> 14250 | AD17: =SUM(Q17:AC17) -> 59450 | AF17: =Q17*$D$39 -> 2.85 | AG17: =R17*$D$39 -> 9.5 | AH17: =S17*$D$39 -> 12.5 | AI17: =T17*$D$39 -> 6.1 | AJ17: =U17*$D$39 -> 32.65 | AK17: =V17*$D$39 -> 22.9 | AL17: =W17*$D$39 -> 15.15 | AM17: =X17*$D$39 -> 23.5 | ... AR17: =AC17*$D$39 -> 71.25 | AS17: =SUM(AF17:AR17) -> 297.25 | AT17: 8.1 | AU17: =AT17*$AU$43 -> 1442.8125 | AW17: 0 | AX17: =(IF((AW17-AW16<0),"0",AW17-AW16))*1000 -> 0 | AY17: =AX17*$AY$44 -> 0 | AZ17: 423725 | BA17: =(IF((AZ17-AZ16<0),"0",AZ17-AZ16))*100 -> 171700 | BB17: =BA17*$BA$44*60% -> 468.741 | BC17: =BB17*0.4444 -> 208.3085
A18: 44969 | B18: 110 | C18: 8821630 | D18: 21202140 | E18: 3972380 | F18: 4478330 | G18: 13335200 | H18: 7964940 | I18: 6861250 | J18: 8611540 | K18: 12426740 | L18: 5421110 | M18: 9796200 | N18: 16463080 | O18: 23218330 | Q18: =IF((C18-C17<0), "0",C18-C17) -> 530 | R18: =IF((D18-D17<0), "0",D18-D17) -> 1780 | S18: =IF((E18-E17<0), "0",E18-E17) -> 2490 | T18: =IF((F18-F17<0), "0",F18-F17) -> 1150 | U18: =IF((G18-G17<0), "0",G18-G17) -> 5690 | V18: =IF((H18-H17<0), "0",H18-H17) -> 3910 | W18: =IF((I18-I17<0), "0",I18-I17) -> 2830 | X18: =IF((J18-J17<0), "0",J18-J17) -> 4020 | ... AC18: =IF((O18-O17<0), "0",O18-O17) -> 14510 | AD18: =SUM(Q18:AC18) -> 54730 | AF18: =Q18*$D$39 -> 2.65 | AG18: =R18*$D$39 -> 8.9 | AH18: =S18*$D$39 -> 12.45 | AI18: =T18*$D$39 -> 5.75 | AJ18: =U18*$D$39 -> 28.45 | AK18: =V18*$D$39 -> 19.55 | AL18: =W18*$D$39 -> 14.15 | AM18: =X18*$D$39 -> 20.1 | ... AR18: =AC18*$D$39 -> 72.55 | AS18: =SUM(AF18:AR18) -> 273.65 | AT18: 4.4 | AU18: =AT18*$AU$43 -> 783.75 | AW18: 68917 | AX18: =(IF((AW18-AW17<0),"0",AW18-AW17))*1000 -> 68917000 | AY18: =AX18*$AY$44 -> 261195.43 | AZ18: 425261 | BA18: =(IF((AZ18-AZ17<0),"0",AZ18-AZ17))*100 -> 153600 | BB18: =BA18*$BA$44*60% -> 419.328 | BC18: =BB18*0.4444 -> 186.34936
A19: 44970 | B19: 150 | C19: 8822200 | D19: 21204010 | E19: 3974770 | F19: 4479510 | G19: 13341110 | H19: 7969240 | I19: 6864270 | J19: 8616050 | K19: 12432590 | L19: 5423740 | M19: 9799150 | N19: 16470820 | O19: 23233730 | Q19: =IF((C19-C18<0), "0",C19-C18) -> 570 | R19: =IF((D19-D18<0), "0",D19-D18) -> 1870 | S19: =IF((E19-E18<0), "0",E19-E18) -> 2390 | T19: =IF((F19-F18<0), "0",F19-F18) -> 1180 | U19: =IF((G19-G18<0), "0",G19-G18) -> 5910 | V19: =IF((H19-H18<0), "0",H19-H18) -> 4300 | W19: =IF((I19-I18<0), "0",I19-I18) -> 3020 | X19: =IF((J19-J18<0), "0",J19-J18) -> 4510 | ... AC19: =IF((O19-O18<0), "0",O19-O18) -> 15400 | AD19: =SUM(Q19:AC19) -> 58320 | AF19: =Q19*$D$39 -> 2.85 | AG19: =R19*$D$39 -> 9.35 | AH19: =S19*$D$39 -> 11.95 | AI19: =T19*$D$39 -> 5.9 | AJ19: =U19*$D$39 -> 29.55 | AK19: =V19*$D$39 -> 21.5 | AL19: =W19*$D$39 -> 15.1 | AM19: =X19*$D$39 -> 22.55 | ... AR19: =AC19*$D$39 -> 77 | AS19: =SUM(AF19:AR19) -> 291.6 | AT19: 0 | AU19: =AT19*$AU$43 -> 0 | AW19: 68949 | AX19: =(IF((AW19-AW18<0),"0",AW19-AW18))*1000 -> 32000 | AY19: =AX19*$AY$44 -> 121.28 | AZ19: 426772 | BA19: =(IF((AZ19-AZ18<0),"0",AZ19-AZ18))*100 -> 151100 | BB19: =BA19*$BA$44*60% -> 412.503 | BC19: =BB19*0.4444 -> 183.31633
A20: 44971 | B20: 179 | C20: 8822760 | D20: 21205900 | E20: 3977170 | F20: 4480430 | G20: 13347550 | H20: 7973810 | I20: 6867580 | J20: 8620940 | K20: 12438750 | L20: 5425600 | M20: 9802560 | N20: 16478820 | O20: 23250290 | Q20: =IF((C20-C19<0), "0",C20-C19) -> 560 | R20: =IF((D20-D19<0), "0",D20-D19) -> 1890 | S20: =IF((E20-E19<0), "0",E20-E19) -> 2400 | T20: =IF((F20-F19<0), "0",F20-F19) -> 920 | U20: =IF((G20-G19<0), "0",G20-G19) -> 6440 | V20: =IF((H20-H19<0), "0",H20-H19) -> 4570 | W20: =IF((I20-I19<0), "0",I20-I19) -> 3310 | X20: =IF((J20-J19<0), "0",J20-J19) -> 4890 | ... AC20: =IF((O20-O19<0), "0",O20-O19) -> 16560 | AD20: =SUM(Q20:AC20) -> 60970 | AF20: =Q20*$D$39 -> 2.8 | AG20: =R20*$D$39 -> 9.45 | AH20: =S20*$D$39 -> 12 | AI20: =T20*$D$39 -> 4.6 | AJ20: =U20*$D$39 -> 32.2 | AK20: =V20*$D$39 -> 22.85 | AL20: =W20*$D$39 -> 16.55 | AM20: =X20*$D$39 -> 24.45 | ... AR20: =AC20*$D$39 -> 82.8 | AS20: =SUM(AF20:AR20) -> 304.85 | AT20: 2.8 | AU20: =AT20*$AU$43 -> 498.75 | AW20: 68984 | AX20: =(IF((AW20-AW19<0),"0",AW20-AW19))*1000 -> 35000 | AY20: =AX20*$AY$44 -> 132.65 | AZ20: 428439 | BA20: =(IF((AZ20-AZ19<0),"0",AZ20-AZ19))*100 -> 166700 | BB20: =BA20*$BA$44*60% -> 455.091 | BC20: =BB20*0.4444 -> 202.24244
A21: 44972 | B21: 156 | C21: 8823280 | D21: 21207680 | E21: 3979330 | F21: 4481290 | G21: 13353410 | H21: 7978070 | I21: 6870730 | J21: 8625690 | K21: 12444530 | L21: 5429330 | M21: 9805830 | N21: 16486470 | O21: 23265780 | Q21: =IF((C21-C20<0), "0",C21-C20) -> 520 | R21: =IF((D21-D20<0), "0",D21-D20) -> 1780 | S21: =IF((E21-E20<0), "0",E21-E20) -> 2160 | T21: =IF((F21-F20<0), "0",F21-F20) -> 860 | U21: =IF((G21-G20<0), "0",G21-G20) -> 5860 | V21: =IF((H21-H20<0), "0",H21-H20) -> 4260 | W21: =IF((I21-I20<0), "0",I21-I20) -> 3150 | X21: =IF((J21-J20<0), "0",J21-J20) -> 4750 | ... AC21: =IF((O21-O20<0), "0",O21-O20) -> 15490 | AD21: =SUM(Q21:AC21) -> 59260 | AF21: =Q21*$D$39 -> 2.6 | AG21: =R21*$D$39 -> 8.9 | AH21: =S21*$D$39 -> 10.8 | AI21: =T21*$D$39 -> 4.3 | AJ21: =U21*$D$39 -> 29.3 | AK21: =V21*$D$39 -> 21.3 | AL21: =W21*$D$39 -> 15.75 | AM21: =X21*$D$39 -> 23.75 | ... AR21: =AC21*$D$39 -> 77.45 | AS21: =SUM(AF21:AR21) -> 296.3 | AT21: 6.6 | AU21: =AT21*$AU$43 -> 1175.625 | AW21: 69012 | AX21: =(IF((AW21-AW20<0),"0",AW21-AW20))*1000 -> 28000 | AY21: =AX21*$AY$44 -> 106.12 | AZ21: 429916 | BA21: =(IF((AZ21-AZ20<0),"0",AZ21-AZ20))*100 -> 147700 | BB21: =BA21*$BA$44*60% -> 403.221 | BC21: =BB21*0.4444 -> 179.19141
A22: 44973 | B22: 128 | C22: 8823840 | D22: 21209540 | E22: 3981680 | F22: 4482190 | G22: 13359970 | H22: 7982550 | I22: 6873900 | J22: 8630640 | K22: 12450370 | L22: 5432010 | M22: 9809080 | N22: 16494200 | O22: 23281280 | Q22: =IF((C22-C21<0), "0",C22-C21) -> 560 | R22: =IF((D22-D21<0), "0",D22-D21) -> 1860 | S22: =IF((E22-E21<0), "0",E22-E21) -> 2350 | T22: =IF((F22-F21<0), "0",F22-F21) -> 900 | U22: =IF((G22-G21<0), "0",G22-G21) -> 6560 | V22: =IF((H22-H21<0), "0",H22-H21) -> 4480 | W22: =IF((I22-I21<0), "0",I22-I21) -> 3170 | X22: =IF((J22-J21<0), "0",J22-J21) -> 4950 | ... AC22: =IF((O22-O21<0), "0",O22-O21) -> 15500 | AD22: =SUM(Q22:AC22) -> 59830 | AF22: =Q22*$D$39 -> 2.8 | AG22: =R22*$D$39 -> 9.3 | AH22: =S22*$D$39 -> 11.75 | AI22: =T22*$D$39 -> 4.5 | AJ22: =U22*$D$39 -> 32.8 | AK22: =V22*$D$39 -> 22.4 | AL22: =W22*$D$39 -> 15.85 | AM22: =X22*$D$39 -> 24.75 | ... AR22: =AC22*$D$39 -> 77.5 | AS22: =SUM(AF22:AR22) -> 299.15 | AT22: 0 | AU22: =AT22*$AU$43 -> 0 | AW22: 69054 | AX22: =(IF((AW22-AW21<0),"0",AW22-AW21))*1000 -> 42000 | AY22: =AX22*$AY$44 -> 159.18 | AZ22: 431565 | BA22: =(IF((AZ22-AZ21<0),"0",AZ22-AZ21))*100 -> 164900 | BB22: =BA22*$BA$44*60% -> 450.177 | BC22: =BB22*0.4444 -> 200.05866
A23: 44974 | B23: 145 | C23: 8824390 | D23: 21211360 | E23: 3983930 | F23: 4483070 | G23: 13366030 | H23: 7986930 | I23: 6877060 | J23: 8635520 | K23: 12456140 | L23: 5434540 | M23: 9812380 | N23: 16501840 | O23: 23297350 | Q23: =IF((C23-C22<0), "0",C23-C22) -> 550 | R23: =IF((D23-D22<0), "0",D23-D22) -> 1820 | S23: =IF((E23-E22<0), "0",E23-E22) -> 2250 | T23: =IF((F23-F22<0), "0",F23-F22) -> 880 | U23: =IF((G23-G22<0), "0",G23-G22) -> 6060 | V23: =IF((H23-H22<0), "0",H23-H22) -> 4380 | W23: =IF((I23-I22<0), "0",I23-I22) -> 3160 | X23: =IF((J23-J22<0), "0",J23-J22) -> 4880 | ... AC23: =IF((O23-O22<0), "0",O23-O22) -> 16070 | AD23: =SUM(Q23:AC23) -> 59290 | AF23: =Q23*$D$39 -> 2.75 | AG23: =R23*$D$39 -> 9.1 | AH23: =S23*$D$39 -> 11.25 | AI23: =T23*$D$39 -> 4.4 | AJ23: =U23*$D$39 -> 30.3 | AK23: =V23*$D$39 -> 21.9 | AL23: =W23*$D$39 -> 15.8 | AM23: =X23*$D$39 -> 24.4 | ... AR23: =AC23*$D$39 -> 80.35 | AS23: =SUM(AF23:AR23) -> 296.45 | AT23: 6.3 | AU23: =AT23*$AU$43 -> 1122.1875 | AW23: 69119 | AX23: =(IF((AW23-AW22<0),"0",AW23-AW22))*1000 -> 65000 | AY23: =AX23*$AY$44 -> 246.35 | AZ23: 432597 | BA23: =(IF((AZ23-AZ22<0),"0",AZ23-AZ22))*100 -> 103200 | BB23: =BA23*$BA$44*60% -> 281.736 | BC23: =BB23*0.4444 -> 125.20348
A24: 44975 | B24: 95 | C24: 8824960 | D24: 21213270 | E24: 3986190 | F24: 4484000 | G24: 13372640 | H24: 7991650 | I24: 6880790 | J24: 8640530 | K24: 12462450 | L24: 5437210 | M24: 9815760 | N24: 16509680 | O24: 23314360 | Q24: =IF((C24-C23<0), "0",C24-C23) -> 570 | R24: =IF((D24-D23<0), "0",D24-D23) -> 1910 | S24: =IF((E24-E23<0), "0",E24-E23) -> 2260 | T24: =IF((F24-F23<0), "0",F24-F23) -> 930 | U24: =IF((G24-G23<0), "0",G24-G23) -> 6610 | V24: =IF((H24-H23<0), "0",H24-H23) -> 4720 | W24: =IF((I24-I23<0), "0",I24-I23) -> 3730 | X24: =IF((J24-J23<0), "0",J24-J23) -> 5010 | ... AC24: =IF((O24-O23<0), "0",O24-O23) -> 17010 | AD24: =SUM(Q24:AC24) -> 62950 | AF24: =Q24*$D$39 -> 2.85 | AG24: =R24*$D$39 -> 9.55 | AH24: =S24*$D$39 -> 11.3 | AI24: =T24*$D$39 -> 4.65 | AJ24: =U24*$D$39 -> 33.05 | AK24: =V24*$D$39 -> 23.6 | AL24: =W24*$D$39 -> 18.65 | AM24: =X24*$D$39 -> 25.05 | ... AR24: =AC24*$D$39 -> 85.05 | AS24: =SUM(AF24:AR24) -> 314.75 | AT24: 0 | AU24: =AT24*$AU$43 -> 0 | AW24: 69200 | AX24: =(IF((AW24-AW23<0),"0",AW24-AW23))*1000 -> 81000 | AY24: =AX24*$AY$44 -> 306.99 | AZ24: 434226 | BA24: =(IF((AZ24-AZ23<0),"0",AZ24-AZ23))*100 -> 162900 | BB24: =BA24*$BA$44*60% -> 444.717 | BC24: =BB24*0.4444 -> 197.63223
A25: 44976 | B25: 72 | C25: 8825500 | D25: 21215090 | E25: 3988590 | F25: 4484890 | G25: 13378820 | H25: 7995900 | I25: 6883700 | J25: 8644770 | K25: 12468130 | L25: 5439720 | M25: 9818930 | N25: 16517050 | O25: 23330440 | Q25: =IF((C25-C24<0), "0",C25-C24) -> 540 | R25: =IF((D25-D24<0), "0",D25-D24) -> 1820 | S25: =IF((E25-E24<0), "0",E25-E24) -> 2400 | T25: =IF((F25-F24<0), "0",F25-F24) -> 890 | U25: =IF((G25-G24<0), "0",G25-G24) -> 6180 | V25: =IF((H25-H24<0), "0",H25-H24) -> 4250 | W25: =IF((I25-I24<0), "0",I25-I24) -> 2910 | X25: =IF((J25-J24<0), "0",J25-J24) -> 4240 | ... AC25: =IF((O25-O24<0), "0",O25-O24) -> 16080 | AD25: =SUM(Q25:AC25) -> 58040 | AF25: =Q25*$D$39 -> 2.7 | AG25: =R25*$D$39 -> 9.1 | AH25: =S25*$D$39 -> 12 | AI25: =T25*$D$39 -> 4.45 | AJ25: =U25*$D$39 -> 30.9 | AK25: =V25*$D$39 -> 21.25 | AL25: =W25*$D$39 -> 14.55 | AM25: =X25*$D$39 -> 21.2 | ... AR25: =AC25*$D$39 -> 80.4 | AS25: =SUM(AF25:AR25) -> 290.2 | AT25: 0 | AU25: =AT25*$AU$43 -> 0 | AW25: 69310 | AX25: =(IF((AW25-AW24<0),"0",AW25-AW24))*1000 -> 110000 | AY25: =AX25*$AY$44 -> 416.9 | AZ25: 435730 | BA25: =(IF((AZ25-AZ24<0),"0",AZ25-AZ24))*100 -> 150400 | BB25: =BA25*$BA$44*60% -> 410.592 | BC25: =BB25*0.4444 -> 182.46708
A26: 44977 | Q26: =IF((C26-C25<0), "0",C26-C25) -> 0 | R26: =IF((D26-D25<0), "0",D26-D25) -> 0 | S26: =IF((E26-E25<0), "0",E26-E25) -> 0 | T26: =IF((F26-F25<0), "0",F26-F25) -> 0 | U26: =IF((G26-G25<0), "0",G26-G25) -> 0 | V26: =IF((H26-H25<0), "0",H26-H25) -> 0 | W26: =IF((I26-I25<0), "0",I26-I25) -> 0 | X26: =IF((J26-J25<0), "0",J26-J25) -> 0 | ... AC26: =IF((O26-O25<0), "0",O26-O25) -> 0 | AD26: =SUM(Q26:AC26) -> 0 | AF26: =Q26*$D$39 -> 0 | AG26: =R26*$D$39 -> 0 | AH26: =S26*$D$39 -> 0 | AI26: =T26*$D$39 -> 0 | AJ26: =U26*$D$39 -> 0 | AK26: =V26*$D$39 -> 0 | AL26: =W26*$D$39 -> 0 | AM26: =X26*$D$39 -> 0 | ... AR26: =AC26*$D$39 -> 0 | AS26: =SUM(AF26:AR26) -> 0 | AU26: =AT26*$AU$43 -> 0 | AW26: 0 | AX26: =(IF((AW26-AW25<0),"0",AW26-AW25))*1000 -> 0 | AY26: =AX26*$AY$44 -> 0 | BA26: =(IF((AZ26-AZ25<0),"0",AZ26-AZ25))*100 -> 0 | BB26: =BA26*$BA$44*60% -> 0 | BC26: =BB26*0.4444 -> 0
A27: 44978 | Q27: =IF((C27-C26<0), "0",C27-C26) -> 0 | R27: =IF((D27-D26<0), "0",D27-D26) -> 0 | S27: =IF((E27-E26<0), "0",E27-E26) -> 0 | T27: =IF((F27-F26<0), "0",F27-F26) -> 0 | U27: =IF((G27-G26<0), "0",G27-G26) -> 0 | V27: =IF((H27-H26<0), "0",H27-H26) -> 0 | W27: =IF((I27-I26<0), "0",I27-I26) -> 0 | X27: =IF((J27-J26<0), "0",J27-J26) -> 0 | ... AC27: =IF((O27-O26<0), "0",O27-O26) -> 0 | AD27: =SUM(Q27:AC27) -> 0 | AF27: =Q27*$D$39 -> 0 | AG27: =R27*$D$39 -> 0 | AH27: =S27*$D$39 -> 0 | AI27: =T27*$D$39 -> 0 | AJ27: =U27*$D$39 -> 0 | AK27: =V27*$D$39 -> 0 | AL27: =W27*$D$39 -> 0 | AM27: =X27*$D$39 -> 0 | ... AR27: =AC27*$D$39 -> 0 | AS27: =SUM(AF27:AR27) -> 0 | AU27: =AT27*$AU$43 -> 0 | AW27: 0 | AX27: =(IF((AW27-AW26<0),"0",AW27-AW26))*1000 -> 0 | AY27: =AX27*$AY$44 -> 0 | BA27: =(IF((AZ27-AZ26<0),"0",AZ27-AZ26))*100 -> 0 | BB27: =BA27*$BA$44*60% -> 0 | BC27: =BB27*0.4444 -> 0
A28: 44979 | Q28: =IF((C28-C27<0), "0",C28-C27) -> 0 | R28: =IF((D28-D27<0), "0",D28-D27) -> 0 | S28: =IF((E28-E27<0), "0",E28-E27) -> 0 | T28: =IF((F28-F27<0), "0",F28-F27) -> 0 | U28: =IF((G28-G27<0), "0",G28-G27) -> 0 | V28: =IF((H28-H27<0), "0",H28-H27) -> 0 | W28: =IF((I28-I27<0), "0",I28-I27) -> 0 | X28: =IF((J28-J27<0), "0",J28-J27) -> 0 | ... AC28: =IF((O28-O27<0), "0",O28-O27) -> 0 | AD28: =SUM(Q28:AC28) -> 0 | AF28: =Q28*$D$39 -> 0 | AG28: =R28*$D$39 -> 0 | AH28: =S28*$D$39 -> 0 | AI28: =T28*$D$39 -> 0 | AJ28: =U28*$D$39 -> 0 | AK28: =V28*$D$39 -> 0 | AL28: =W28*$D$39 -> 0 | AM28: =X28*$D$39 -> 0 | ... AR28: =AC28*$D$39 -> 0 | AS28: =SUM(AF28:AR28) -> 0 | AU28: =AT28*$AU$43 -> 0 | AW28: 0 | AX28: =(IF((AW28-AW27<0),"0",AW28-AW27))*1000 -> 0 | AY28: =AX28*$AY$44 -> 0 | BA28: =(IF((AZ28-AZ27<0),"0",AZ28-AZ27))*100 -> 0 | BB28: =BA28*$BA$44*60% -> 0 | BC28: =BB28*0.4444 -> 0
A29: 44980 | Q29: =IF((C29-C28<0), "0",C29-C28) -> 0 | R29: =IF((D29-D28<0), "0",D29-D28) -> 0 | S29: =IF((E29-E28<0), "0",E29-E28) -> 0 | T29: =IF((F29-F28<0), "0",F29-F28) -> 0 | U29: =IF((G29-G28<0), "0",G29-G28) -> 0 | V29: =IF((H29-H28<0), "0",H29-H28) -> 0 | W29: =IF((I29-I28<0), "0",I29-I28) -> 0 | X29: =IF((J29-J28<0), "0",J29-J28) -> 0 | ... AC29: =IF((O29-O28<0), "0",O29-O28) -> 0 | AD29: =SUM(Q29:AC29) -> 0 | AF29: =Q29*$D$39 -> 0 | AG29: =R29*$D$39 -> 0 | AH29: =S29*$D$39 -> 0 | AI29: =T29*$D$39 -> 0 | AJ29: =U29*$D$39 -> 0 | AK29: =V29*$D$39 -> 0 | AL29: =W29*$D$39 -> 0 | AM29: =X29*$D$39 -> 0 | ... AR29: =AC29*$D$39 -> 0 | AS29: =SUM(AF29:AR29) -> 0 | AU29: =AT29*$AU$43 -> 0 | AW29: 0 | AX29: =(IF((AW29-AW28<0),"0",AW29-AW28))*1000 -> 0 | AY29: =AX29*$AY$44 -> 0 | BA29: =(IF((AZ29-AZ28<0),"0",AZ29-AZ28))*100 -> 0 | BB29: =BA29*$BA$44*60% -> 0 | BC29: =BB29*0.4444 -> 0
A30: 44981 | Q30: =IF((C30-C29<0), "0",C30-C29) -> 0 | R30: =IF((D30-D29<0), "0",D30-D29) -> 0 | S30: =IF((E30-E29<0), "0",E30-E29) -> 0 | T30: =IF((F30-F29<0), "0",F30-F29) -> 0 | U30: =IF((G30-G29<0), "0",G30-G29) -> 0 | V30: =IF((H30-H29<0), "0",H30-H29) -> 0 | W30: =IF((I30-I29<0), "0",I30-I29) -> 0 | X30: =IF((J30-J29<0), "0",J30-J29) -> 0 | ... AC30: =IF((O30-O29<0), "0",O30-O29) -> 0 | AD30: =SUM(Q30:AC30) -> 0 | AF30: =Q30*$D$39 -> 0 | AG30: =R30*$D$39 -> 0 | AH30: =S30*$D$39 -> 0 | AI30: =T30*$D$39 -> 0 | AJ30: =U30*$D$39 -> 0 | AK30: =V30*$D$39 -> 0 | AL30: =W30*$D$39 -> 0 | AM30: =X30*$D$39 -> 0 | ... AR30: =AC30*$D$39 -> 0 | AS30: =SUM(AF30:AR30) -> 0 | AU30: =AT30*$AU$43 -> 0 | AW30: 0 | AX30: =(IF((AW30-AW29<0),"0",AW30-AW29))*1000 -> 0 | AY30: =AX30*$AY$44 -> 0 | BA30: =(IF((AZ30-AZ29<0),"0",AZ30-AZ29))*100 -> 0 | BB30: =BA30*$BA$44*60% -> 0 | BC30: =BB30*0.4444 -> 0
A31: 44982 | Q31: =IF((C31-C30<0), "0",C31-C30) -> 0 | R31: =IF((D31-D30<0), "0",D31-D30) -> 0 | S31: =IF((E31-E30<0), "0",E31-E30) -> 0 | T31: =IF((F31-F30<0), "0",F31-F30) -> 0 | U31: =IF((G31-G30<0), "0",G31-G30) -> 0 | V31: =IF((H31-H30<0), "0",H31-H30) -> 0 | W31: =IF((I31-I30<0), "0",I31-I30) -> 0 | X31: =IF((J31-J30<0), "0",J31-J30) -> 0 | ... AC31: =IF((O31-O30<0), "0",O31-O30) -> 0 | AD31: =SUM(Q31:AC31) -> 0 | AF31: =Q31*$D$39 -> 0 | AG31: =R31*$D$39 -> 0 | AH31: =S31*$D$39 -> 0 | AI31: =T31*$D$39 -> 0 | AJ31: =U31*$D$39 -> 0 | AK31: =V31*$D$39 -> 0 | AL31: =W31*$D$39 -> 0 | AM31: =X31*$D$39 -> 0 | ... AR31: =AC31*$D$39 -> 0 | AS31: =SUM(AF31:AR31) -> 0 | AU31: =AT31*$AU$43 -> 0 | AW31: 0 | AX31: =(IF((AW31-AW30<0),"0",AW31-AW30))*1000 -> 0 | AY31: =AX31*$AY$44 -> 0 | BA31: =(IF((AZ31-AZ30<0),"0",AZ31-AZ30))*100 -> 0 | BB31: =BA31*$BA$44*60% -> 0 | BC31: =BB31*0.4444 -> 0
A32: 44983 | Q32: =IF((C32-C31<0), "0",C32-C31) -> 0 | R32: =IF((D32-D31<0), "0",D32-D31) -> 0 | S32: =IF((E32-E31<0), "0",E32-E31) -> 0 | T32: =IF((F32-F31<0), "0",F32-F31) -> 0 | U32: =IF((G32-G31<0), "0",G32-G31) -> 0 | V32: =IF((H32-H31<0), "0",H32-H31) -> 0 | W32: =IF((I32-I31<0), "0",I32-I31) -> 0 | X32: =IF((J32-J31<0), "0",J32-J31) -> 0 | ... AC32: =IF((O32-O31<0), "0",O32-O31) -> 0 | AD32: =SUM(Q32:AC32) -> 0 | AF32: =Q32*$D$39 -> 0 | AG32: =R32*$D$39 -> 0 | AH32: =S32*$D$39 -> 0 | AI32: =T32*$D$39 -> 0 | AJ32: =U32*$D$39 -> 0 | AK32: =V32*$D$39 -> 0 | AL32: =W32*$D$39 -> 0 | AM32: =X32*$D$39 -> 0 | ... AR32: =AC32*$D$39 -> 0 | AS32: =SUM(AF32:AR32) -> 0 | AU32: =AT32*$AU$43 -> 0 | AW32: 0 | AX32: =(IF((AW32-AW31<0),"0",AW32-AW31))*1000 -> 0 | AY32: =AX32*$AY$44 -> 0 | BA32: =(IF((AZ32-AZ31<0),"0",AZ32-AZ31))*100 -> 0 | BB32: =BA32*$BA$44*60% -> 0 | BC32: =BB32*0.4444 -> 0
A33: 44984 | Q33: =IF((C33-C32<0), "0",C33-C32) -> 0 | R33: =IF((D33-D32<0), "0",D33-D32) -> 0 | S33: =IF((E33-E32<0), "0",E33-E32) -> 0 | T33: =IF((F33-F32<0), "0",F33-F32) -> 0 | U33: =IF((G33-G32<0), "0",G33-G32) -> 0 | V33: =IF((H33-H32<0), "0",H33-H32) -> 0 | W33: =IF((I33-I32<0), "0",I33-I32) -> 0 | X33: =IF((J33-J32<0), "0",J33-J32) -> 0 | ... AC33: =IF((O33-O32<0), "0",O33-O32) -> 0 | AD33: =SUM(Q33:AC33) -> 0 | AF33: =Q33*$D$39 -> 0 | AG33: =R33*$D$39 -> 0 | AH33: =S33*$D$39 -> 0 | AI33: =T33*$D$39 -> 0 | AJ33: =U33*$D$39 -> 0 | AK33: =V33*$D$39 -> 0 | AL33: =W33*$D$39 -> 0 | AM33: =X33*$D$39 -> 0 | ... AR33: =AC33*$D$39 -> 0 | AS33: =SUM(AF33:AR33) -> 0 | AU33: =AT33*$AU$43 -> 0 | AW33: 0 | AX33: =(IF((AW33-AW32<0),"0",AW33-AW32))*1000 -> 0 | AY33: =AX33*$AY$44 -> 0 | BA33: =(IF((AZ33-AZ32<0),"0",AZ33-AZ32))*100 -> 0 | BB33: =BA33*$BA$44*60% -> 0 | BC33: =BB33*0.4444 -> 0
A34: 44985 | Q34: =IF((C34-C33<0), "0",C34-C33) -> 0 | R34: =IF((D34-D33<0), "0",D34-D33) -> 0 | S34: =IF((E34-E33<0), "0",E34-E33) -> 0 | T34: =IF((F34-F33<0), "0",F34-F33) -> 0 | U34: =IF((G34-G33<0), "0",G34-G33) -> 0 | V34: =IF((H34-H33<0), "0",H34-H33) -> 0 | W34: =IF((I34-I33<0), "0",I34-I33) -> 0 | X34: =IF((J34-J33<0), "0",J34-J33) -> 0 | ... AC34: =IF((O34-O33<0), "0",O34-O33) -> 0 | AD34: =SUM(Q34:AC34) -> 0 | AF34: =Q34*$D$39 -> 0 | AG34: =R34*$D$39 -> 0 | AH34: =S34*$D$39 -> 0 | AI34: =T34*$D$39 -> 0 | AJ34: =U34*$D$39 -> 0 | AK34: =V34*$D$39 -> 0 | AL34: =W34*$D$39 -> 0 | AM34: =X34*$D$39 -> 0 | ... AR34: =AC34*$D$39 -> 0 | AS34: =SUM(AF34:AR34) -> 0 | AU34: =AT34*$AU$43 -> 0 | AW34: 0 | AX34: =(IF((AW34-AW33<0),"0",AW34-AW33))*1000 -> 0 | AY34: =AX34*$AY$44 -> 0 | BA34: =(IF((AZ34-AZ33<0),"0",AZ34-AZ33))*100 -> 0 | BB34: =BA34*$BA$44*60% -> 0 | BC34: =BB34*0.4444 -> 0
Q35: =IF((C35-C34<0), "0",C35-C34) -> 0 | R35: =IF((D35-D34<0), "0",D35-D34) -> 0 | S35: =IF((E35-E34<0), "0",E35-E34) -> 0 | T35: =IF((F35-F34<0), "0",F35-F34) -> 0 | U35: =IF((G35-G34<0), "0",G35-G34) -> 0 | V35: =IF((H35-H34<0), "0",H35-H34) -> 0 | W35: =IF((I35-I34<0), "0",I35-I34) -> 0 | X35: =IF((J35-J34<0), "0",J35-J34) -> 0 | ... AC35: =IF((O35-O34<0), "0",O35-O34) -> 0 | AD35: =SUM(Q35:AC35) -> 0 | AF35: =Q35*$D$39 -> 0 | AG35: =R35*$D$39 -> 0 | AH35: =S35*$D$39 -> 0 | AI35: =T35*$D$39 -> 0 | AJ35: =U35*$D$39 -> 0 | AK35: =V35*$D$39 -> 0 | AL35: =W35*$D$39 -> 0 | AM35: =X35*$D$39 -> 0 | ... AR35: =AC35*$D$39 -> 0 | AS35: =SUM(AF35:AR35) -> 0 | AU35: =AT35*$AU$43 -> 0 | AW35: 0 | AX35: =(IF((AW35-AW34<0),"0",AW35-AW34))*1000 -> 0 | AY35: =AX35*$AY$44 -> 0 | BA35: =(IF((AZ35-AZ34<0),"0",AZ35-AZ34))*100 -> 0 | BB35: =BA35*$BA$44*60% -> 0 | BC35: =BB35*0.4444 -> 0
Q36: =IF((C36-C35<0), "0",C36-C35) -> 0 | R36: =IF((D36-D35<0), "0",D36-D35) -> 0 | S36: =IF((E36-E35<0), "0",E36-E35) -> 0 | T36: =IF((F36-F35<0), "0",F36-F35) -> 0 | U36: =IF((G36-G35<0), "0",G36-G35) -> 0 | V36: =IF((H36-H35<0), "0",H36-H35) -> 0 | W36: =IF((I36-I35<0), "0",I36-I35) -> 0 | X36: =IF((J36-J35<0), "0",J36-J35) -> 0 | ... AC36: =IF((O36-O35<0), "0",O36-O35) -> 0 | AD36: =SUM(Q36:AC36) -> 0 | AF36: =Q36*$D$39 -> 0 | AG36: =R36*$D$39 -> 0 | AH36: =S36*$D$39 -> 0 | AI36: =T36*$D$39 -> 0 | AJ36: =U36*$D$39 -> 0 | AK36: =V36*$D$39 -> 0 | AL36: =W36*$D$39 -> 0 | AM36: =X36*$D$39 -> 0 | ... AR36: =AC36*$D$39 -> 0 | AS36: =SUM(AF36:AR36) -> 0 | AU36: =AT36*$AU$43 -> 0 | AW36: 0 | AX36: =(IF((AW36-AW35<0),"0",AW36-AW35))*1000 -> 0 | AY36: =AX36*$AY$44 -> 0 | BA36: =(IF((AZ36-AZ35<0),"0",AZ36-AZ35))*100 -> 0 | BB36: =BA36*$BA$44*60% -> 0 | BC36: =BB36*0.4444 -> 0
Q37: =IF((C37-C36<0), "0",C37-C36) -> 0 | R37: =IF((D37-D36<0), "0",D37-D36) -> 0 | S37: =IF((E37-E36<0), "0",E37-E36) -> 0 | T37: =IF((F37-F36<0), "0",F37-F36) -> 0 | U37: =IF((G37-G36<0), "0",G37-G36) -> 0 | V37: =IF((H37-H36<0), "0",H37-H36) -> 0 | W37: =IF((I37-I36<0), "0",I37-I36) -> 0 | X37: =IF((J37-J36<0), "0",J37-J36) -> 0 | ... AC37: =IF((O37-O36<0), "0",O37-O36) -> 0 | AD37: =SUM(Q37:AC37) -> 0 | AF37: =Q37*$D$39 -> 0 | AG37: =R37*$D$39 -> 0 | AH37: =S37*$D$39 -> 0 | AI37: =T37*$D$39 -> 0 | AJ37: =U37*$D$39 -> 0 | AK37: =V37*$D$39 -> 0 | AL37: =W37*$D$39 -> 0 | AM37: =X37*$D$39 -> 0 | ... AR37: =AC37*$D$39 -> 0 | AS37: =SUM(AF37:AR37) -> 0 | AU37: =AT37*$AU$43 -> 0 | AW37: 0 | AX37: =(IF((AW37-AW36<0),"0",AW37-AW36))*1000 -> 0 | AY37: =AX37*$AY$44 -> 0 | BA37: =(IF((AZ37-AZ36<0),"0",AZ37-AZ36))*100 -> 0 | BB37: =BA37*$BA$44*60% -> 0 | BC37: =BB37*0.4444 -> 0
Q38: =SUM(Q7:Q37) -> 10670 | R38: =SUM(R7:R37) -> 35010 | S38: =SUM(S7:S37) -> 47650 | T38: =SUM(T7:T37) -> 22140 | U38: =SUM(U7:U37) -> 118320 | V38: =SUM(V7:V37) -> 81970 | W38: =SUM(W7:W37) -> 61570 | X38: =SUM(X7:X37) -> 85240 | ... AD38: =SUM(AD7:AD37) -> 1100440 | AF38: =SUM(AF7:AF37) -> 53.35 | AG38: =SUM(AG7:AG37) -> 175.05 | AH38: =SUM(AH7:AH37) -> 238.25 | AI38: =SUM(AI7:AI37) -> 110.7 | AJ38: =SUM(AJ7:AJ37) -> 591.6 | AK38: =SUM(AK7:AK37) -> 409.85 | AL38: =SUM(AL7:AL37) -> 307.85 | AM38: =SUM(AM7:AM37) -> 426.2 | ... AS38: =SUM(AS7:AS37) -> 5502.2 | AU38: =SUM(AU7:AU37) -> 6145.3125 | AW38: 0 | AX38: =(IF((AW38-AW37<0),"0",AW38-AW37))*1000 -> 0 | AY38: =AX38*$AY$44 -> 0 | BA38: =(IF((AZ38-AZ37<0),"0",AZ38-AZ37))*100 -> 0 | BB38: =SUM(BB7:BB37) -> 7824.18 | BC38: =BB38*0.4444 -> 3477.0656
B39: =SUM(B7:B37) -> 2607 | D39: 0.005 | AW39: 0 | AX39: =(IF((AW39-AW38<0),"0",AW39-AW38))*1000 -> 0 | AY39: =AX39*$AY$44 -> 0 | BB39: =BA39*$BA$44*60% -> 0
D40: 0.002
AU43: 178.125
...
