Workbook

Sheet TOTAL
A1: Site Name | B1: Day | C1: Month | D1: Year | E1: Total Electricity Kwh | F1: Electricity Tariff ($/Kwh) | G1: Natual Gas (m3) | H1: Natural Gas $/m3 | I1: Water Utility Supply (m3) m3 | J1: Water Utility Supply (m3) $/m3 | K1: Room Nights
A2: Orlando | B2: 1 | C2: 1 | D2: 2023 | E2: =Submetering!F3+Submetering!H3+Submetering!J3+Submetering!L3+Submetering!N3+Submetering!P3+Submetering!R3+Submetering!T3+Submetering!V3+Submetering!X3+Submetering!Z3+Submetering!AB3+Submetering!AC3+Submetering!AD3+Submetering!AE3 -> 0 | F2: =((((Submetering!E3+Submetering!AD3)*0.13773+(Submetering!E3+Submetering!AD3)*0.02095)*1.09+(2.85/30)*2)+(((Submetering!F3+Submetering!H3+Submetering!J3+Submetering!L3+Submetering!N3+Submetering!P3+Submetering!R3+Submetering!T3+Submetering!V3+Submetering!X3+Submetering!Z3+Submetering!AB3+Submetering!AC3+Submetering!AE3)*0.05155)+((Submetering!F3+Submetering!H3+Submetering!J3+Submetering!L3+Submetering!N3+Submetering!P3+Submetering!R3+Submetering!T3+Submetering!V3+Submetering!X3+Submetering!Z3+Submetering!AB3+Submetering!AC3+Submetering!AE3)*0.02095)+(20/30)*15)*1.1048)/E2 -> #DIV/0! | G2: =Submetering!AK3+Submetering!AL3+Submetering!AU3 -> 0 | H2: 0.8166 | I2: =Submetering!AF3+Submetering!AG3+Submetering!AH3+Submetering!AI3+Submetering!AJ3+Submetering!AM3+Submetering!AN3+Submetering!AO3+Submetering!AQ3+Submetering!AR3+Submetering!AS3+Submetering!AT3+Submetering!AV3+Submetering!AY3+Submetering!AW3+Submetering!AZ3+Submetering!BA3 -> 0 | J2: =((Submetering!AG3+Submetering!BA3)*0.8868+(1712.96+1070.52)/30+(Submetering!AF3+Submetering!AY3+Submetering!AV3+Submetering!AZ3)*1.1251+(2076.11+129.67+207.57+207.57)/30+(11680.53+56.61)/30)/I2 -> #DIV/0! | K2: =Elect!C5 -> 330
A3: Orlando | B3: 2 | C3: 1 | D3: 2023 | E3: =Submetering!F4+Submetering!H4+Submetering!J4+Submetering!L4+Submetering!N4+Submetering!P4+Submetering!R4+Submetering!T4+Submetering!V4+Submetering!X4+Submetering!Z4+Submetering!AB4+Submetering!AC4+Submetering!AD4+Submetering!AE4 -> 358374 | F3: =((((Submetering!E4+Submetering!AD4)*0.13773+(Submetering!E4+Submetering!AD4)*0.02095)*1.09+(2.85/30)*2)+(((Submetering!F4+Submetering!H4+Submetering!J4+Submetering!L4+Submetering!N4+Submetering!P4+Submetering!R4+Submetering!T4+Submetering!V4+Submetering!X4+Submetering!Z4+Submetering!AB4+Submetering!AC4+Submetering!AE4)*0.05155)+((Submetering!F4+Submetering!H4+Submetering!J4+Submetering!L4+Submetering!N4+Submetering!P4+Submetering!R4+Submetering!T4+Submetering!V4+Submetering!X4+Submetering!Z4+Submetering!AB4+Submetering!AC4+Submetering!AE4)*0.02095)+(20/30)*15)*1.1048)/E3 -> 0.080324738 | G3: =Submetering!AK4+Submetering!AL4+Submetering!AU4 -> 545.7826 | H3: 0.8166 | I3: =Submetering!AF4+Submetering!AG4+Submetering!AH4+Submetering!AI4+Submetering!AJ4+Submetering!AM4+Submetering!AN4+Submetering!AO4+Submetering!AQ4+Submetering!AR4+Submetering!AS4+Submetering!AT4+Submetering!AV4+Submetering!AY4+Submetering!AW4+Submetering!AZ4+Submetering!BA4 -> 19592.797 | J3: =((Submetering!AG4+Submetering!BA4)*0.8868+(1712.96+1070.52)/30+(Submetering!AF4+Submetering!AY4+Submetering!AV4+Submetering!AZ4)*1.1251+(2076.11+129.67+207.57+207.57)/30+(11680.53+56.61)/30)/I3 -> 0.36525235 | K3: =Elect!C6 -> 2418
A4: Orlando | B4: 9 | C4: 1 | D4: 2023 | E4: =Submetering!F5+Submetering!H5+Submetering!J5+Submetering!L5+Submetering!N5+Submetering!P5+Submetering!R5+Submetering!T5+Submetering!V5+Submetering!X5+Submetering!Z5+Submetering!AB5+Submetering!AC5+Submetering!AD5+Submetering!AE5 -> 287533 | F4: =((((Submetering!E5+Submetering!AD5)*0.13773+(Submetering!E5+Submetering!AD5)*0.02095)*1.09+(2.85/30)*2)+(((Submetering!F5+Submetering!H5+Submetering!J5+Submetering!L5+Submetering!N5+Submetering!P5+Submetering!R5+Submetering!T5+Submetering!V5+Submetering!X5+Submetering!Z5+Submetering!AB5+Submetering!AC5+Submetering!AE5)*0.05155)+((Submetering!F5+Submetering!H5+Submetering!J5+Submetering!L5+Submetering!N5+Submetering!P5+Submetering!R5+Submetering!T5+Submetering!V5+Submetering!X5+Submetering!Z5+Submetering!AB5+Submetering!AC5+Submetering!AE5)*0.02095)+(20/30)*15)*1.1048)/E4 -> 0.080380277 | G4: =Submetering!AK5+Submetering!AL5+Submetering!AU5 -> 744.9254 | H4: 0.8166 | I4: =Submetering!AF5+Submetering!AG5+Submetering!AH5+Submetering!AI5+Submetering!AJ5+Submetering!AM5+Submetering!AN5+Submetering!AO5+Submetering!AQ5+Submetering!AR5+Submetering!AS5+Submetering!AT5+Submetering!AV5+Submetering!AY5+Submetering!AW5+Submetering!AZ5+Submetering!BA5 -> 13963.156 | J4: =((Submetering!AG5+Submetering!BA5)*0.8868+(1712.96+1070.52)/30+(Submetering!AF5+Submetering!AY5+Submetering!AV5+Submetering!AZ5)*1.1251+(2076.11+129.67+207.57+207.57)/30+(11680.53+56.61)/30)/I4 -> 0.4809228 | K4: =Elect!C7 -> 1995
A5: Orlando | B5: 16 | C5: 1 | D5: 2023 | E5: =Submetering!F6+Submetering!H6+Submetering!J6+Submetering!L6+Submetering!N6+Submetering!P6+Submetering!R6+Submetering!T6+Submetering!V6+Submetering!X6+Submetering!Z6+Submetering!AB6+Submetering!AC6+Submetering!AD6+Submetering!AE6 -> 311864 | F5: =((((Submetering!E6+Submetering!AD6)*0.13773+(Submetering!E6+Submetering!AD6)*0.02095)*1.09+(2.85/30)*2)+(((Submetering!F6+Submetering!H6+Submetering!J6+Submetering!L6+Submetering!N6+Submetering!P6+Submetering!R6+Submetering!T6+Submetering!V6+Submetering!X6+Submetering!Z6+Submetering!AB6+Submetering!AC6+Submetering!AE6)*0.05155)+((Submetering!F6+Submetering!H6+Submetering!J6+Submetering!L6+Submetering!N6+Submetering!P6+Submetering!R6+Submetering!T6+Submetering!V6+Submetering!X6+Submetering!Z6+Submetering!AB6+Submetering!AC6+Submetering!AE6)*0.02095)+(20/30)*15)*1.1048)/E5 -> 0.08036153 | G5: =Submetering!AK6+Submetering!AL6+Submetering!AU6 -> 598.6558 | H5: 0.8166 | I5: =Submetering!AF6+Submetering!AG6+Submetering!AH6+Submetering!AI6+Submetering!AJ6+Submetering!AM6+Submetering!AN6+Submetering!AO6+Submetering!AQ6+Submetering!AR6+Submetering!AS6+Submetering!AT6+Submetering!AV6+Submetering!AY6+Submetering!AW6+Submetering!AZ6+Submetering!BA6 -> 22459.681 | J5: =((Submetering!AG6+Submetering!BA6)*0.8868+(1712.96+1070.52)/30+(Submetering!AF6+Submetering!AY6+Submetering!AV6+Submetering!AZ6)*1.1251+(2076.11+129.67+207.57+207.57)/30+(11680.53+56.61)/30)/I5 -> 0.51597055 | K5: =Elect!C8 -> 2324
A6: Orlando | B6: 23 | C6: 1 | D6: 2023 | E6: =Submetering!F7+Submetering!H7+Submetering!J7+Submetering!L7+Submetering!N7+Submetering!P7+Submetering!R7+Submetering!T7+Submetering!V7+Submetering!X7+Submetering!Z7+Submetering!AB7+Submetering!AC7+Submetering!AD7+Submetering!AE7 -> 304137 | F6: =((((Submetering!E7+Submetering!AD7)*0.13773+(Submetering!E7+Submetering!AD7)*0.02095)*1.09+(2.85/30)*2)+(((Submetering!F7+Submetering!H7+Submetering!J7+Submetering!L7+Submetering!N7+Submetering!P7+Submetering!R7+Submetering!T7+Submetering!V7+Submetering!X7+Submetering!Z7+Submetering!AB7+Submetering!AC7+Submetering!AE7)*0.05155)+((Submetering!F7+Submetering!H7+Submetering!J7+Submetering!L7+Submetering!N7+Submetering!P7+Submetering!R7+Submetering!T7+Submetering!V7+Submetering!X7+Submetering!Z7+Submetering!AB7+Submetering!AC7+Submetering!AE7)*0.02095)+(20/30)*15)*1.1048)/E6 -> 0.080366088 | G6: =Submetering!AK7+Submetering!AL7+Submetering!AU7 -> 643.5034 | H6: 0.8166 | I6: =Submetering!AF7+Submetering!AG7+Submetering!AH7+Submetering!AI7+Submetering!AJ7+Submetering!AM7+Submetering!AN7+Submetering!AO7+Submetering!AQ7+Submetering!AR7+Submetering!AS7+Submetering!AT7+Submetering!AV7+Submetering!AY7+Submetering!AW7+Submetering!AZ7+Submetering!BA7 -> 21712.061 | J6: =((Submetering!AG7+Submetering!BA7)*0.8868+(1712.96+1070.52)/30+(Submetering!AF7+Submetering!AY7+Submetering!AV7+Submetering!AZ7)*1.1251+(2076.11+129.67+207.57+207.57)/30+(11680.53+56.61)/30)/I6 -> 0.53433392 | K6: =Elect!C9 -> 2633
A7: Orlando | B7: 30 | C7: 1 | D7: 2023 | E7: =Submetering!F8+Submetering!H8+Submetering!J8+Submetering!L8+Submetering!N8+Submetering!P8+Submetering!R8+Submetering!T8+Submetering!V8+Submetering!X8+Submetering!Z8+Submetering!AB8+Submetering!AC8+Submetering!AD8+Submetering!AE8 -> 53548 | F7: =((((Submetering!E8+Submetering!AD8)*0.13773+(Submetering!E8+Submetering!AD8)*0.02095)*1.09+(2.85/30)*2)+(((Submetering!F8+Submetering!H8+Submetering!J8+Submetering!L8+Submetering!N8+Submetering!P8+Submetering!R8+Submetering!T8+Submetering!V8+Submetering!X8+Submetering!Z8+Submetering!AB8+Submetering!AC8+Submetering!AE8)*0.05155)+((Submetering!F8+Submetering!H8+Submetering!J8+Submetering!L8+Submetering!N8+Submetering!P8+Submetering!R8+Submetering!T8+Submetering!V8+Submetering!X8+Submetering!Z8+Submetering!AB8+Submetering!AC8+Submetering!AE8)*0.02095)+(20/30)*15)*1.1048)/E7 -> 0.080529846 | G7: =Submetering!AK8+Submetering!AL8+Submetering!AU8 -> 44.5512 | H7: 0.8166 | I7: =Submetering!AF8+Submetering!AG8+Submetering!AH8+Submetering!AI8+Submetering!AJ8+Submetering!AM8+Submetering!AN8+Submetering!AO8+Submetering!AQ8+Submetering!AR8+Submetering!AS8+Submetering!AT8+Submetering!AV8+Submetering!AY8+Submetering!AW8+Submetering!AZ8+Submetering!BA8 -> 4499.5531 | J7: =((Submetering!AG8+Submetering!BA8)*0.8868+(1712.96+1070.52)/30+(Submetering!AF8+Submetering!AY8+Submetering!AV8+Submetering!AZ8)*1.1251+(2076.11+129.67+207.57+207.57)/30+(11680.53+56.61)/30)/I7 -> 0.60394133 | K7: =Elect!C10 -> 398
A8: Orlando | B8: 31 | C8: 1 | D8: 2023 | E8: =Submetering!F9+Submetering!H9+Submetering!J9+Submetering!L9+Submetering!N9+Submetering!P9+Submetering!R9+Submetering!T9+Submetering!V9+Submetering!X9+Submetering!Z9+Submetering!AB9+Submetering!AC9+Submetering!AD9+Submetering!AE9 -> 260271 | F8: =((((Submetering!E9+Submetering!AD9)*0.13773+(Submetering!E9+Submetering!AD9)*0.02095)*1.09+(2.85/30)*2)+(((Submetering!F9+Submetering!H9+Submetering!J9+Submetering!L9+Submetering!N9+Submetering!P9+Submetering!R9+Submetering!T9+Submetering!V9+Submetering!X9+Submetering!Z9+Submetering!AB9+Submetering!AC9+Submetering!AE9)*0.05155)+((Submetering!F9+Submetering!H9+Submetering!J9+Submetering!L9+Submetering!N9+Submetering!P9+Submetering!R9+Submetering!T9+Submetering!V9+Submetering!X9+Submetering!Z9+Submetering!AB9+Submetering!AC9+Submetering!AE9)*0.02095)+(20/30)*15)*1.1048)/E8 -> 0.080366315 | G8: =Submetering!AK9+Submetering!AL9+Submetering!AU9 -> 386.5056 | H8: 0.8166 | I8: =Submetering!AF9+Submetering!AG9+Submetering!AH9+Submetering!AI9+Submetering!AJ9+Submetering!AM9+Submetering!AN9+Submetering!AO9+Submetering!AQ9+Submetering!AR9+Submetering!AS9+Submetering!AT9+Submetering!AV9+Submetering!AY9+Submetering!AW9+Submetering!AZ9+Submetering!BA9 -> 19028.449 | J8: =((Submetering!AG9+Submetering!BA9)*0.8868+(1712.96+1070.52)/30+(Submetering!AF9+Submetering!AY9+Submetering!AV9+Submetering!AZ9)*1.1251+(2076.11+129.67+207.57+207.57)/30+(11680.53+56.61)/30)/I8 -> 0.39306876 | K8: =Elect!C11 -> 1646
A9: Orlando | B9: 6 | C9: 2 | D9: 2023 | E9: =Submetering!F10+Submetering!H10+Submetering!J10+Submetering!L10+Submetering!N10+Submetering!P10+Submetering!R10+Submetering!T10+Submetering!V10+Submetering!X10+Submetering!Z10+Submetering!AB10+Submetering!AC10+Submetering!AD10+Submetering!AE10 -> 325014 | F9: =((((Submetering!E10+Submetering!AD10)*0.13773+(Submetering!E10+Submetering!AD10)*0.02095)*1.09+(2.85/30)*2)+(((Submetering!F10+Submetering!H10+Submetering!J10+Submetering!L10+Submetering!N10+Submetering!P10+Submetering!R10+Submetering!T10+Submetering!V10+Submetering!X10+Submetering!Z10+Submetering!AB10+Submetering!AC10+Submetering!AE10)*0.05155)+((Submetering!F10+Submetering!H10+Submetering!J10+Submetering!L10+Submetering!N10+Submetering!P10+Submetering!R10+Submetering!T10+Submetering!V10+Submetering!X10+Submetering!Z10+Submetering!AB10+Submetering!AC10+Submetering!AE10)*0.02095)+(20/30)*15)*1.1048)/E9 -> 0.08034801 | G9: =Submetering!AK10+Submetering!AL10+Submetering!AU10 -> 506.6692 | H9: 0.8166 | I9: =Submetering!AF10+Submetering!AG10+Submetering!AH10+Submetering!AI10+Submetering!AJ10+Submetering!AM10+Submetering!AN10+Submetering!AO10+Submetering!AQ10+Submetering!AR10+Submetering!AS10+Submetering!AT10+Submetering!AV10+Submetering!AY10+Submetering!AW10+Submetering!AZ10+Submetering!BA10 -> 23255.697 | J9: =((Submetering!AG10+Submetering!BA10)*0.8868+(1712.96+1070.52)/30+(Submetering!AF10+Submetering!AY10+Submetering!AV10+Submetering!AZ10)*1.1251+(2076.11+129.67+207.57+207.57)/30+(11680.53+56.61)/30)/I9 -> 0.51448453 | K9: =Elect!C12 -> 2108
A10: Orlando | B10: 13 | C10: 2 | D10: 2023 | E10: =Submetering!F11+Submetering!H11+Submetering!J11+Submetering!L11+Submetering!N11+Submetering!P11+Submetering!R11+Submetering!T11+Submetering!V11+Submetering!X11+Submetering!Z11+Submetering!AB11+Submetering!AC11+Submetering!AD11+Submetering!AE11 -> 315412 | F10: =((((Submetering!E11+Submetering!AD11)*0.13773+(Submetering!E11+Submetering!AD11)*0.02095)*1.09+(2.85/30)*2)+(((Submetering!F11+Submetering!H11+Submetering!J11+Submetering!L11+Submetering!N11+Submetering!P11+Submetering!R11+Submetering!T11+Submetering!V11+Submetering!X11+Submetering!Z11+Submetering!AB11+Submetering!AC11+Submetering!AE11)*0.05155)+((Submetering!F11+Submetering!H11+Submetering!J11+Submetering!L11+Submetering!N11+Submetering!P11+Submetering!R11+Submetering!T11+Submetering!V11+Submetering!X11+Submetering!Z11+Submetering!AB11+Submetering!AC11+Submetering!AE11)*0.02095)+(20/30)*15)*1.1048)/E10 -> 0.080355032 | G10: =Submetering!AK11+Submetering!AL11+Submetering!AU11 -> 518.4226 | H10: 0.8166 | I10: =Submetering!AF11+Submetering!AG11+Submetering!AH11+Submetering!AI11+Submetering!AJ11+Submetering!AM11+Submetering!AN11+Submetering!AO11+Submetering!AQ11+Submetering!AR11+Submetering!AS11+Submetering!AT11+Submetering!AV11+Submetering!AY11+Submetering!AW11+Submetering!AZ11+Submetering!BA11 -> 26274.683 | J10: =((Submetering!AG11+Submetering!BA11)*0.8868+(1712.96+1070.52)/30+(Submetering!AF11+Submetering!AY11+Submetering!AV11+Submetering!AZ11)*1.1251+(2076.11+129.67+207.57+207.57)/30+(11680.53+56.61)/30)/I10 -> 0.54275982 | K10: =Elect!C13 -> 2834
A11: Orlando | B11: 20 | C11: 2 | D11: 2023 | E11: =Submetering!F12+Submetering!H12+Submetering!J12+Submetering!L12+Submetering!N12+Submetering!P12+Submetering!R12+Submetering!T12+Submetering!V12+Submetering!X12+Submetering!Z12+Submetering!AB12+Submetering!AC12+Submetering!AD12+Submetering!AE12 -> 0 | F11: =((((Submetering!E12+Submetering!AD12)*0.13773+(Submetering!E12+Submetering!AD12)*0.02095)*1.09+(2.85/30)*2)+(((Submetering!F12+Submetering!H12+Submetering!J12+Submetering!L12+Submetering!N12+Submetering!P12+Submetering!R12+Submetering!T12+Submetering!V12+Submetering!X12+Submetering!Z12+Submetering!AB12+Submetering!AC12+Submetering!AE12)*0.05155)+((Submetering!F12+Submetering!H12+Submetering!J12+Submetering!L12+Submetering!N12+Submetering!P12+Submetering!R12+Submetering!T12+Submetering!V12+Submetering!X12+Submetering!Z12+Submetering!AB12+Submetering!AC12+Submetering!AE12)*0.02095)+(20/30)*15)*1.1048)/E11 -> #DIV/0! | G11: =Submetering!AK12+Submetering!AL12+Submetering!AU12 -> 0 | H11: 0.8166 | I11: =Submetering!AF12+Submetering!AG12+Submetering!AH12+Submetering!AI12+Submetering!AJ12+Submetering!AM12+Submetering!AN12+Submetering!AO12+Submetering!AQ12+Submetering!AR12+Submetering!AS12+Submetering!AT12+Submetering!AV12+Submetering!AY12+Submetering!AW12+Submetering!AZ12+Submetering!BA12 -> 0 | J11: =((Submetering!AG12+Submetering!BA12)*0.8868+(1712.96+1070.52)/30+(Submetering!AF12+Submetering!AY12+Submetering!AV12+Submetering!AZ12)*1.1251+(2076.11+129.67+207.57+207.57)/30+(11680.53+56.61)/30)/I11 -> #DIV/0! | K11: =Elect!C14 -> 2314
A12: Orlando | B12: 27 | C12: 2 | D12: 2023 | E12: =Submetering!F13+Submetering!H13+Submetering!J13+Submetering!L13+Submetering!N13+Submetering!P13+Submetering!R13+Submetering!T13+Submetering!V13+Submetering!X13+Submetering!Z13+Submetering!AB13+Submetering!AC13+Submetering!AD13+Submetering!AE13 -> 0 | F12: =((((Submetering!E13+Submetering!AD13)*0.13773+(Submetering!E13+Submetering!AD13)*0.02095)*1.09+(2.85/30)*2)+(((Submetering!F13+Submetering!H13+Submetering!J13+Submetering!L13+Submetering!N13+Submetering!P13+Submetering!R13+Submetering!T13+Submetering!V13+Submetering!X13+Submetering!Z13+Submetering!AB13+Submetering!AC13+Submetering!AE13)*0.05155)+((Submetering!F13+Submetering!H13+Submetering!J13+Submetering!L13+Submetering!N13+Submetering!P13+Submetering!R13+Submetering!T13+Submetering!V13+Submetering!X13+Submetering!Z13+Submetering!AB13+Submetering!AC13+Submetering!AE13)*0.02095)+(20/30)*15)*1.1048)/E12 -> #DIV/0! | G12: =Submetering!AK13+Submetering!AL13+Submetering!AU13 -> 0 | H12: 0.8166 | I12: =Submetering!AF13+Submetering!AG13+Submetering!AH13+Submetering!AI13+Submetering!AJ13+Submetering!AM13+Submetering!AN13+Submetering!AO13+Submetering!AQ13+Submetering!AR13+Submetering!AS13+Submetering!AT13+Submetering!AV13+Submetering!AY13+Submetering!AW13+Submetering!AZ13+Submetering!BA13 -> 0 | J12: =((Submetering!AG13+Submetering!BA13)*0.8868+(1712.96+1070.52)/30+(Submetering!AF13+Submetering!AY13+Submetering!AV13+Submetering!AZ13)*1.1251+(2076.11+129.67+207.57+207.57)/30+(11680.53+56.61)/30)/I12 -> #DIV/0! | K12: =Elect!C15 -> 413
A13: Orlando | B13: 28 | C13: 2 | D13: 2023 | E13: =Submetering!F14+Submetering!H14+Submetering!J14+Submetering!L14+Submetering!N14+Submetering!P14+Submetering!R14+Submetering!T14+Submetering!V14+Submetering!X14+Submetering!Z14+Submetering!AB14+Submetering!AC14+Submetering!AD14+Submetering!AE14 -> 0 | F13: =((((Submetering!E14+Submetering!AD14)*0.13773+(Submetering!E14+Submetering!AD14)*0.02095)*1.09+(2.85/30)*2)+(((Submetering!F14+Submetering!H14+Submetering!J14+Submetering!L14+Submetering!N14+Submetering!P14+Submetering!R14+Submetering!T14+Submetering!V14+Submetering!X14+Submetering!Z14+Submetering!AB14+Submetering!AC14+Submetering!AE14)*0.05155)+((Submetering!F14+Submetering!H14+Submetering!J14+Submetering!L14+Submetering!N14+Submetering!P14+Submetering!R14+Submetering!T14+Submetering!V14+Submetering!X14+Submetering!Z14+Submetering!AB14+Submetering!AC14+Submetering!AE14)*0.02095)+(20/30)*15)*1.1048)/E13 -> #DIV/0! | G13: =Submetering!AK14+Submetering!AL14+Submetering!AU14 -> 0 | H13: 0.8166 | I13: =Submetering!AF14+Submetering!AG14+Submetering!AH14+Submetering!AI14+Submetering!AJ14+Submetering!AM14+Submetering!AN14+Submetering!AO14+Submetering!AQ14+Submetering!AR14+Submetering!AS14+Submetering!AT14+Submetering!AV14+Submetering!AY14+Submetering!AW14+Submetering!AZ14+Submetering!BA14 -> 0 | J13: =((Submetering!AG14+Submetering!BA14)*0.8868+(1712.96+1070.52)/30+(Submetering!AF14+Submetering!AY14+Submetering!AV14+Submetering!AZ14)*1.1251+(2076.11+129.67+207.57+207.57)/30+(11680.53+56.61)/30)/I13 -> #DIV/0! | K13: =Elect!C16 -> 0
... A65: Orlando | B65: 31 | C65: 12 | D65: 2023 | E65: =Submetering!F66+Submetering!H66+Submetering!J66+Submetering!L66+Submetering!N66+Submetering!P66+Submetering!R66+Submetering!T66+Submetering!V66+Submetering!X66+Submetering!Z66+Submetering!AB66+Submetering!AC66+Submetering!AD66+Submetering!AE66 -> 0 | F65: =((((Submetering!E66+Submetering!AD66)*0.13773+(Submetering!E66+Submetering!AD66)*0.02095)*1.09+(2.85/30)*2)+(((Submetering!F66+Submetering!H66+Submetering!J66+Submetering!L66+Submetering!N66+Submetering!P66+Submetering!R66+Submetering!T66+Submetering!V66+Submetering!X66+Submetering!Z66+Submetering!AB66+Submetering!AC66+Submetering!AE66)*0.05155)+((Submetering!F66+Submetering!H66+Submetering!J66+Submetering!L66+Submetering!N66+Submetering!P66+Submetering!R66+Submetering!T66+Submetering!V66+Submetering!X66+Submetering!Z66+Submetering!AB66+Submetering!AC66+Submetering!AE66)*0.02095)+(20/30)*15)*1.1048)/E65 -> #DIV/0! | G65: =Submetering!AK66+Submetering!AL66+Submetering!AU66 -> 0 | H65: 0.8166 | I65: =Submetering!AF66+Submetering!AG66+Submetering!AH66+Submetering!AI66+Submetering!AJ66+Submetering!AM66+Submetering!AN66+Submetering!AO66+Submetering!AQ66+Submetering!AR66+Submetering!AS66+Submetering!AT66+Submetering!AV66+Submetering!AY66+Submetering!AW66+Submetering!AZ66+Submetering!BA66 -> 0 | J65: =((Submetering!AG66+Submetering!BA66)*0.8868+(1712.96+1070.52)/30+(Submetering!AF66+Submetering!AY66+Submetering!AV66+Submetering!AZ66)*1.1251+(2076.11+129.67+207.57+207.57)/30+(11680.53+56.61)/30)/I65 -> #DIV/0! | K65: =Elect!C68 -> 0

Sheet Submetering
A1: Site Name | B1: Day | C1: Month | D1: Year | E1: 90 630 431 (KWh) | F1: 68 425 010 (KWh) | G1: T2392 (KWh) | H1: 68 425 008 (KWh) | I1: T7384 (KWh) | J1: 68 425 060 (KWh) | K1: T7380 (KWh) | L1: 68 425 097 (KWh) | M1: T7281 (KWh) | N1: 68 425 059 (KWh) | O1: T2390 (KWh) | P1: 68 425 077 (KWh) | Q1: T2395 (KWh) | R1: 68 425 078 (KWh) | S1: T2393 (KWh) | T1: 68 425 071 (KWh) | U1: T7285 (KWh) | V1: 68 425 093 (KWh) | W1: T7382 (KWh) | X1: 68 425 094 (KWh) | Y1: T2391 (KWh) | Z1: 90 625 242 (KWh) | AA1: T7283 (KWh) | AB1: 672 73 163 (KWh) | AC1: 676 62 513 (KWh) | AD1: 61 979 920 (KWh) | AE1: 56 253 208 (KWh) | AF1: Domestic Water from RCES 74860172 (m3) | AG1: Re-use Water from RCES 74860173 (m3) | AH1: Building A Fire Sprinkler System Make-up 44553004 (m3) | AI1: Building A Potable Water Feed 70275191 (m3) | AJ1: Steam Boilers Make-up Water 2130521 (m3) | AK1: Resort Natural Gas Meter 12C004186-C1 (m3) | AL1: Out Buildings Natural Gas Meter 93477704 (m3) | AM1: Cooling Tower Make-up Water 79177804 (m3) | AN1: Cooling Tower Blowdown Line Deduct 79305675 (m3) | AO1: Building E Potable Water Meter 79190041 (m3) | AP1: 7919004D | AQ1: Building J Irrigation Water Meter 79190039 (m3) | AR1: Lazy Pool River Make-up Water 79324776 (m3) | AS1: Pool Hydraunic Boiler Water Make-up 112014001775 (m3) | AT1: SPA Jacuzzi Water Make-up 112014001771 (m3) | AU1: Golf Clubhouse Natural Gas Meter 82SJ729151 (m3) | AV1: 73337589 - 1387142 | AW1: Golf Clubhouse Flushing Valve Deduct 65956268 (m3) | AX1: Clubhouse | AY1: Golf Maintenance Facility 1334021 (m3) | AZ1: Golf Course Comfort Stations 63265094 (m3) | BA1: Golf Course Re-use Irrigation 67327447 (m3)
A2: Orlando | B2: 1 | C2: 1 | D2: 2023 | E2: =IF(Elect!AM4<0,"0",Elect!AM4) -> 0 | F2: =IF(Elect!I4<0,"0",Elect!I4) | G2: =Elect!H4 -> 2.469 | H2: =IF(Elect!F4<0,"0",Elect!F4) | I2: =Elect!E4 -> 2.085 | J2: =IF(Elect!U4<0,"0",Elect!U4) | K2: =Elect!T4 -> 2.072 | L2: =IF(Elect!AJ4<0,"0",Elect!AJ4) | M2: =Elect!AI4 -> 0.405 | N2: =IF(Elect!X4<0,"0",Elect!X4) | O2: =Elect!W4 -> 1.756 | P2: =IF(Elect!O4<0,"0",Elect!O4) | Q2: =Elect!N4 -> 3.68 | R2: =IF(Elect!L4<0,"0",Elect!L4) | S2: =Elect!K4 -> 4.16 | T2: =IF(Elect!R4<0,"0",Elect!R4) | U2: =Elect!Q4 -> 3.76 | V2: =IF(Elect!AA4<0,"0",Elect!AA4) | W2: =Elect!Z4 -> 3 | X2: =IF(Elect!AD4<0,"0",Elect!AD4) | Y2: =Elect!AC4 -> 2.25 | Z2: =IF(Elect!AG4<0,"0",Elect!AG4) | AA2: =Elect!AF4 -> 2.199 | AB2: =IF(Elect!AX4<0,"0",Elect!AX4) | AC2: =IF(Elect!AV4<0,"0",Elect!AV4) | AD2: =IF(Elect!AZ4<0,"0",Elect!AZ4) | AE2: =IF(Elect!BB4<0,"0",Elect!BB4) | AF2: =IF('Wtr-Gas'!E4<0,"0",('Wtr-Gas'!E4)*0.0038) -> #VALUE! | AG2: =IF('Wtr-Gas'!H4<0,"0",('Wtr-Gas'!H4)*0.0038) -> #VALUE! | AH2: =IF('Wtr-Gas'!K4<0,"0",('Wtr-Gas'!K4)*0.0038) -> #VALUE! | AI2: =IF('Wtr-Gas'!N4<0,"0",('Wtr-Gas'!N4)*0.0038) -> #VALUE! | AJ2: =IF('Wtr-Gas'!Q4<0,"0",('Wtr-Gas'!Q4)*0.0038) -> #VALUE! | AK2: =IF('Wtr-Gas'!U4<0,"0",('Wtr-Gas'!U4)*0.0038) -> #VALUE! | AL2: =IF('Wtr-Gas'!X4<0,"0",('Wtr-Gas'!X4)*0.0038) -> #VALUE! | AM2: =IF('Wtr-Gas'!AB4<0,"0",('Wtr-Gas'!AB4)*0.0038) -> #VALUE! | AN2: =IF('Wtr-Gas'!AD4<0,"0",('Wtr-Gas'!AD4)*0.0038) -> #VALUE! | AO2: =IF('Wtr-Gas'!AH4<0,"0",('Wtr-Gas'!AH4)*0.0038) -> #VALUE! | AP2: =IF('Wtr-Gas'!AJ4<0,"0",('Wtr-Gas'!AJ4)*0.0038) -> #VALUE! | AQ2: =IF('Wtr-Gas'!AL4<0,"0",('Wtr-Gas'!AL4)*0.0038) -> #VALUE! | AR2: =IF('Wtr-Gas'!AN4<0,"0",('Wtr-Gas'!AN4)*0.0038) -> #VALUE! | AS2: =IF('Wtr-Gas'!AP4<0,"0",('Wtr-Gas'!AP4)*0.0038) -> #VALUE! | AT2: =IF('Wtr-Gas'!AR4<0,"0",('Wtr-Gas'!AR4)*0.0038) -> #VALUE! | AU2: =IF('Wtr-Gas'!AV4<0,"0",('Wtr-Gas'!AV4)*0.0038) -> #VALUE! | AV2: =IF('Wtr-Gas'!AY4<0,"0",('Wtr-Gas'!AY4)*0.0038) -> #VALUE! | AW2: =IF('Wtr-Gas'!BA4<0,"0",('Wtr-Gas'!BA4)*0.0038) -> #VALUE! | AX2: =IF('Wtr-Gas'!BB4<0,"0",('Wtr-Gas'!BB4)*0.0038) -> #VALUE! | AY2: =IF('Wtr-Gas'!BD4<0,"0",('Wtr-Gas'!BD4)*0.0038) -> #VALUE! | AZ2: =IF('Wtr-Gas'!BF4<0,"0",('Wtr-Gas'!BF4)*0.0038) -> #VALUE! | BA2: =IF('Wtr-Gas'!BH4<0,"0",('Wtr-Gas'!BH4)*0.0038) -> #VALUE!
A3: Orlando | B3: 2 | C3: 1 | D3: 2023 | E3: =IF(Elect!AM5<0,"0",Elect!AM5) -> 0 | F3: =IF(Elect!I5<0,"0",Elect!I5) -> 0 | G3: =Elect!H5 -> 2.469 | H3: =IF(Elect!F5<0,"0",Elect!F5) -> 0 | I3: =Elect!E5 -> 2.085 | J3: =IF(Elect!U5<0,"0",Elect!U5) -> 0 | K3: =Elect!T5 -> 2.072 | L3: =IF(Elect!AJ5<0,"0",Elect!AJ5) -> 0 | M3: =Elect!AI5 -> 0.405 | N3: =IF(Elect!X5<0,"0",Elect!X5) -> 0 | O3: =Elect!W5 -> 1.756 | P3: =IF(Elect!O5<0,"0",Elect!O5) -> 0 | Q3: =Elect!N5 -> 3.68 | R3: =IF(Elect!L5<0,"0",Elect!L5) -> 0 | S3: =Elect!K5 -> 4.16 | T3: =IF(Elect!R5<0,"0",Elect!R5) -> 0 | U3: =Elect!Q5 -> 3.76 | V3: =IF(Elect!AA5<0,"0",Elect!AA5) -> 0 | W3: =Elect!Z5 -> 3 | X3: =IF(Elect!AD5<0,"0",Elect!AD5) -> 0 | Y3: =Elect!AC5 -> 2.25 | Z3: =IF(Elect!AG5<0,"0",Elect!AG5) -> 0 | AA3: =Elect!AF5 -> 2.199 | AB3: =IF(Elect!AX5<0,"0",Elect!AX5) -> 0 | AC3: =IF(Elect!AV5<0,"0",Elect!AV5) -> 0 | AD3: =IF(Elect!AZ5<0,"0",Elect!AZ5) -> 0 | AE3: =IF(Elect!BB5<0,"0",Elect!BB5) -> 0 | AF3: =IF('Wtr-Gas'!E5<0,"0",('Wtr-Gas'!E5)*0.0038) -> 0 | AG3: =IF('Wtr-Gas'!H5<0,"0",('Wtr-Gas'!H5)*0.0038) -> 0 | AH3: =IF('Wtr-Gas'!K5<0,"0",('Wtr-Gas'!K5)*0.0038) -> 0 | AI3: =IF('Wtr-Gas'!N5<0,"0",('Wtr-Gas'!N5)*0.0038) -> 0 | AJ3: =IF('Wtr-Gas'!Q5<0,"0",('Wtr-Gas'!Q5)*0.0038) -> 0 | AK3: =IF('Wtr-Gas'!U5<0,"0",('Wtr-Gas'!U5)*0.0038) -> 0 | AL3: =IF('Wtr-Gas'!X5<0,"0",('Wtr-Gas'!X5)*0.0038) -> 0 | AM3: =IF('Wtr-Gas'!AB5<0,"0",('Wtr-Gas'!AB5)*0.0038) -> 0 | AN3: =IF('Wtr-Gas'!AD5<0,"0",('Wtr-Gas'!AD5)*0.0038) -> 0 | AO3: =IF('Wtr-Gas'!AH5<0,"0",('Wtr-Gas'!AH5)*0.0038) -> 0 | AP3: =IF('Wtr-Gas'!AJ5<0,"0",('Wtr-Gas'!AJ5)*0.0038) -> 0 | AQ3: =IF('Wtr-Gas'!AL5<0,"0",('Wtr-Gas'!AL5)*0.0038) -> 0 | AR3: =IF('Wtr-Gas'!AN5<0,"0",('Wtr-Gas'!AN5)*0.0038) -> 0 | AS3: =IF('Wtr-Gas'!AP5<0,"0",('Wtr-Gas'!AP5)*0.0038) -> 0 | AT3: =IF('Wtr-Gas'!AR5<0,"0",('Wtr-Gas'!AR5)*0.0038) -> 0 | AU3: =IF('Wtr-Gas'!AV5<0,"0",('Wtr-Gas'!AV5)*0.0038) -> 0 | AV3: =IF('Wtr-Gas'!AY5<0,"0",('Wtr-Gas'!AY5)*0.0038) -> 0 | AW3: =IF('Wtr-Gas'!BA5<0,"0",('Wtr-Gas'!BA5)*0.0038) -> 0 | AX3: =IF('Wtr-Gas'!BB5<0,"0",('Wtr-Gas'!BB5)*0.0038) -> 0 | AY3: =IF('Wtr-Gas'!BD5<0,"0",('Wtr-Gas'!BD5)*0.0038) -> 0 | AZ3: =IF('Wtr-Gas'!BF5<0,"0",('Wtr-Gas'!BF5)*0.0038) -> 0 | BA3: =IF('Wtr-Gas'!BH5<0,"0",('Wtr-Gas'!BH5)*0.0038) -> 0
A4: Orlando | B4: 9 | C4: 1 | D4: 2023 | E4: =IF(Elect!AM6<0,"0",Elect!AM6) -> 0 | F4: =IF(Elect!I6<0,"0",Elect!I6) -> 56160 | G4: =Elect!H6 -> 2.469 | H4: =IF(Elect!F6<0,"0",Elect!F6) -> 48800 | I4: =Elect!E6 -> 2.085 | J4: =IF(Elect!U6<0,"0",Elect!U6) -> 59400 | K4: =Elect!T6 -> 2.072 | L4: =IF(Elect!AJ6<0,"0",Elect!AJ6) -> 1600 | M4: =Elect!AI6 -> 0.405 | N4: =IF(Elect!X6<0,"0",Elect!X6) -> 57300 | O4: =Elect!W6 -> 1.958 | P4: =IF(Elect!O6<0,"0",Elect!O6) -> 15200 | Q4: =Elect!N6 -> 3.68 | R4: =IF(Elect!L6<0,"0",Elect!L6) -> 17200 | S4: =Elect!K6 -> 4.16 | T4: =IF(Elect!R6<0,"0",Elect!R6) -> 14400 | U4: =Elect!Q6 -> 3.76 | V4: =IF(Elect!AA6<0,"0",Elect!AA6) -> 8640 | W4: =Elect!Z6 -> 4.94 | X4: =IF(Elect!AD6<0,"0",Elect!AD6) -> 4160 | Y4: =Elect!AC6 -> 2.83 | Z4: =IF(Elect!AG6<0,"0",Elect!AG6) -> 58600 | AA4: =Elect!AF6 -> 2.199 | AB4: =IF(Elect!AX6<0,"0",Elect!AX6) -> 1400 | AC4: =IF(Elect!AV6<0,"0",Elect!AV6) -> 13200 | AD4: =IF(Elect!AZ6<0,"0",Elect!AZ6) -> 754 | AE4: =IF(Elect!BB6<0,"0",Elect!BB6) -> 1560 | AF4: =IF('Wtr-Gas'!E6<0,"0",('Wtr-Gas'!E6)*0.0038) -> 5286.408 | AG4: =IF('Wtr-Gas'!H6<0,"0",('Wtr-Gas'!H6)*0.0038) -> 405.422 | AH4: =IF('Wtr-Gas'!K6<0,"0",('Wtr-Gas'!K6)*0.0038) -> 1.71 | AI4: =IF('Wtr-Gas'!N6<0,"0",('Wtr-Gas'!N6)*0.0038) -> 4111.6 | AJ4: =IF('Wtr-Gas'!Q6<0,"0",('Wtr-Gas'!Q6)*0.0038) -> 114.76 | AK4: =IF('Wtr-Gas'!U6<0,"0",('Wtr-Gas'!U6)*0.0038) -> 0 | AL4: =IF('Wtr-Gas'!X6<0,"0",('Wtr-Gas'!X6)*0.0038) -> 545.3 | AM4: =IF('Wtr-Gas'!AB6<0,"0",('Wtr-Gas'!AB6)*0.0038) -> 6916 | AN4: =IF('Wtr-Gas'!AD6<0,"0",('Wtr-Gas'!AD6)*0.0038) -> 1721.7105 | AO4: =IF('Wtr-Gas'!AH6<0,"0",('Wtr-Gas'!AH6)*0.0038) -> 20.52 | AP4: =IF('Wtr-Gas'!AJ6<0,"0",('Wtr-Gas'!AJ6)*0.0038) -> 256.88 | AQ4: =IF('Wtr-Gas'!AL6<0,"0",('Wtr-Gas'!AL6)*0.0038) -> 72.1544 | AR4: =IF('Wtr-Gas'!AN6<0,"0",('Wtr-Gas'!AN6)*0.0038) -> 524.4 | AS4: =IF('Wtr-Gas'!AP6<0,"0",('Wtr-Gas'!AP6)*0.0038) -> 0.0684 | AT4: =IF('Wtr-Gas'!AR6<0,"0",('Wtr-Gas'!AR6)*0.0038) -> 8.74 | AU4: =IF('Wtr-Gas'!AV6<0,"0",('Wtr-Gas'!AV6)*0.0038) -> 0.4826 | AV4: =IF('Wtr-Gas'!AY6<0,"0",('Wtr-Gas'!AY6)*0.0038) -> 231.591 | AW4: =IF('Wtr-Gas'!BA6<0,"0",('Wtr-Gas'!BA6)*0.0038) -> 162.51266 | AX4: =IF('Wtr-Gas'!BB6<0,"0",('Wtr-Gas'!BB6)*0.0038) -> 69.078338 | AY4: =IF('Wtr-Gas'!BD6<0,"0",('Wtr-Gas'!BD6)*0.0038) -> 14.44 | AZ4: =IF('Wtr-Gas'!BF6<0,"0",('Wtr-Gas'!BF6)*0.0038) -> 0.76 | BA4: =IF('Wtr-Gas'!BH6<0,"0",('Wtr-Gas'!BH6)*0.0038) -> 0
A5: Orlando | B5: 16 | C5: 1 | D5: 2023 | E5: =IF(Elect!AM7<0,"0",Elect!AM7) -> 0 | F5: =IF(Elect!I7<0,"0",Elect!I7) -> 51520 | G5: =Elect!H7 -> 2.469 | H5: =IF(Elect!F7<0,"0",Elect!F7) -> 44480 | I5: =Elect!E7 -> 2.085 | J5: =IF(Elect!U7<0,"0",Elect!U7) -> 33900 | K5: =Elect!T7 -> 2.072 | L5: =IF(Elect!AJ7<0,"0",Elect!AJ7) -> 1360 | M5: =Elect!AI7 -> 0.405 | N5: =IF(Elect!X7<0,"0",Elect!X7) -> 35400 | O5: =Elect!W7 -> 1.958 | P5: =IF(Elect!O7<0,"0",Elect!O7) -> 13600 | Q5: =Elect!N7 -> 3.68 | R5: =IF(Elect!L7<0,"0",Elect!L7) -> 16000 | S5: =Elect!K7 -> 4.16 | T5: =IF(Elect!R7<0,"0",Elect!R7) -> 14000 | U5: =Elect!Q7 -> 3.76 | V5: =IF(Elect!AA7<0,"0",Elect!AA7) -> 7520 | W5: =Elect!Z7 -> 4.94 | X5: =IF(Elect!AD7<0,"0",Elect!AD7) -> 4320 | Y5: =Elect!AC7 -> 2.199 | Z5: =IF(Elect!AG7<0,"0",Elect!AG7) -> 49400 | AA5: =Elect!AF7 -> 2.199 | AB5: =IF(Elect!AX7<0,"0",Elect!AX7) -> 1900 | AC5: =IF(Elect!AV7<0,"0",Elect!AV7) -> 11700 | AD5: =IF(Elect!AZ7<0,"0",Elect!AZ7) -> 753 | AE5: =IF(Elect!BB7<0,"0",Elect!BB7) -> 1680 | AF5: =IF('Wtr-Gas'!E7<0,"0",('Wtr-Gas'!E7)*0.0038) -> 4543.356 | AG5: =IF('Wtr-Gas'!H7<0,"0",('Wtr-Gas'!H7)*0.0038) -> 41.268 | AH5: =IF('Wtr-Gas'!K7<0,"0",('Wtr-Gas'!K7)*0.0038) -> 1.444 | AI5: =IF('Wtr-Gas'!N7<0,"0",('Wtr-Gas'!N7)*0.0038) -> 3412.4 | AJ5: =IF('Wtr-Gas'!Q7<0,"0",('Wtr-Gas'!Q7)*0.0038) -> 100.7 | AK5: =IF('Wtr-Gas'!U7<0,"0",('Wtr-Gas'!U7)*0.0038) -> 0 | AL5: =IF('Wtr-Gas'!X7<0,"0",('Wtr-Gas'!X7)*0.0038) -> 744.42 | AM5: =IF('Wtr-Gas'!AB7<0,"0",('Wtr-Gas'!AB7)*0.0038) -> 3230 | AN5: =IF('Wtr-Gas'!AD7<0,"0",('Wtr-Gas'!AD7)*0.0038) -> 821.03902 | AO5: =IF('Wtr-Gas'!AH7<0,"0",('Wtr-Gas'!AH7)*0.0038) -> 3.458 | AP5: =IF('Wtr-Gas'!AJ7<0,"0",('Wtr-Gas'!AJ7)*0.0038) -> 242.478 | AQ5: =IF('Wtr-Gas'!AL7<0,"0",('Wtr-Gas'!AL7)*0.0038) -> 64.4062 | AR5: =IF('Wtr-Gas'!AN7<0,"0",('Wtr-Gas'!AN7)*0.0038) -> 478.8 | AS5: =IF('Wtr-Gas'!AP7<0,"0",('Wtr-Gas'!AP7)*0.0038) -> 0.0646 | AT5: =IF('Wtr-Gas'!AR7<0,"0",('Wtr-Gas'!AR7)*0.0038) -> 8.74 | AU5: =IF('Wtr-Gas'!AV7<0,"0",('Wtr-Gas'!AV7)*0.0038) -> 0.5054 | AV5: =IF('Wtr-Gas'!AY7<0,"0",('Wtr-Gas'!AY7)*0.0038) -> 270.2674 | AW5: =IF('Wtr-Gas'!BA7<0,"0",('Wtr-Gas'!BA7)*0.0038) -> 212.13785 | AX5: =IF('Wtr-Gas'!BB7<0,"0",('Wtr-Gas'!BB7)*0.0038) -> 58.12955 | AY5: =IF('Wtr-Gas'!BD7<0,"0",('Wtr-Gas'!BD7)*0.0038) -> 15.96 | AZ5: =IF('Wtr-Gas'!BF7<0,"0",('Wtr-Gas'!BF7)*0.0038) -> 1.14 | BA5: =IF('Wtr-Gas'!BH7<0,"0",('Wtr-Gas'!BH7)*0.0038) -> 757.9746
A6: Orlando | B6: 23 | C6: 1 | D6: 2023 | E6: =IF(Elect!AM8<0,"0",Elect!AM8) -> 0 | F6: =IF(Elect!I8<0,"0",Elect!I8) -> 52000 | G6: =Elect!H8 -> 2.312 | H6: =IF(Elect!F8<0,"0",Elect!F8) -> 43840 | I6: =Elect!E8 -> 1.883 | J6: =IF(Elect!U8<0,"0",Elect!U8) -> 46200 | K6: =Elect!T8 -> 1.522 | L6: =IF(Elect!AJ8<0,"0",Elect!AJ8) -> 1480 | M6: =Elect!AI8 -> 0.259 | N6: =IF(Elect!X8<0,"0",Elect!X8) -> 46200 | O6: =Elect!W8 -> 1.744 | P6: =IF(Elect!O8<0,"0",Elect!O8) -> 12800 | Q6: =Elect!N8 -> 2.27 | R6: =IF(Elect!L8<0,"0",Elect!L8) -> 15600 | S6: =Elect!K8 -> 2.96 | T6: =IF(Elect!R8<0,"0",Elect!R8) -> 13600 | U6: =Elect!Q8 -> 2.39 | V6: =IF(Elect!AA8<0,"0",Elect!AA8) -> 6880 | W6: =Elect!Z8 -> 3.11 | X6: =IF(Elect!AD8<0,"0",Elect!AD8) -> 4320 | Y6: =Elect!AC8 -> 2.31 | Z6: =IF(Elect!AG8<0,"0",Elect!AG8) -> 51600 | AA6: =Elect!AF8 -> 1.941 | AB6: =IF(Elect!AX8<0,"0",Elect!AX8) -> 1700 | AC6: =IF(Elect!AV8<0,"0",Elect!AV8) -> 13000 | AD6: =IF(Elect!AZ8<0,"0",Elect!AZ8) -> 764 | AE6: =IF(Elect!BB8<0,"0",Elect!BB8) -> 1880 | AF6: =IF('Wtr-Gas'!E8<0,"0",('Wtr-Gas'!E8)*0.0038) -> 4961.204 | AG6: =IF('Wtr-Gas'!H8<0,"0",('Wtr-Gas'!H8)*0.0038) -> 367.46 | AH6: =IF('Wtr-Gas'!K8<0,"0",('Wtr-Gas'!K8)*0.0038) -> 2.128 | AI6: =IF('Wtr-Gas'!N8<0,"0",('Wtr-Gas'!N8)*0.0038) -> 3910.2 | AJ6: =IF('Wtr-Gas'!Q8<0,"0",('Wtr-Gas'!Q8)*0.0038) -> 124.64 | AK6: =IF('Wtr-Gas'!U8<0,"0",('Wtr-Gas'!U8)*0.0038) -> 0 | AL6: =IF('Wtr-Gas'!X8<0,"0",('Wtr-Gas'!X8)*0.0038) -> 598.12 | AM6: =IF('Wtr-Gas'!AB8<0,"0",('Wtr-Gas'!AB8)*0.0038) -> 5282 | AN6: =IF('Wtr-Gas'!AD8<0,"0",('Wtr-Gas'!AD8)*0.0038) -> 1352.3052 | AO6: =IF('Wtr-Gas'!AH8<0,"0",('Wtr-Gas'!AH8)*0.0038) -> 0.76 | AP6: =IF('Wtr-Gas'!AJ8<0,"0",('Wtr-Gas'!AJ8)*0.0038) -> 143.108 | AQ6: =IF('Wtr-Gas'!AL8<0,"0",('Wtr-Gas'!AL8)*0.0038) -> 78.6524 | AR6: =IF('Wtr-Gas'!AN8<0,"0",('Wtr-Gas'!AN8)*0.0038) -> 513 | AS6: =IF('Wtr-Gas'!AP8<0,"0",('Wtr-Gas'!AP8)*0.0038) -> 0.057 | AT6: =IF('Wtr-Gas'!AR8<0,"0",('Wtr-Gas'!AR8)*0.0038) -> 15.58 | AU6: =IF('Wtr-Gas'!AV8<0,"0",('Wtr-Gas'!AV8)*0.0038) -> 0.5358 | AV6: =IF('Wtr-Gas'!AY8<0,"0",('Wtr-Gas'!AY8)*0.0038) -> 210.9 | AW6: =IF('Wtr-Gas'!BA8<0,"0",('Wtr-Gas'!BA8)*0.0038) -> 151.51235 | AX6: =IF('Wtr-Gas'!BB8<0,"0",('Wtr-Gas'!BB8)*0.0038) -> 59.387654 | AY6: =IF('Wtr-Gas'!BD8<0,"0",('Wtr-Gas'!BD8)*0.0038) -> 15.58 | AZ6: =IF('Wtr-Gas'!BF8<0,"0",('Wtr-Gas'!BF8)*0.0038) -> 2.28 | BA6: =IF('Wtr-Gas'!BH8<0,"0",('Wtr-Gas'!BH8)*0.0038) -> 5471.4224
A7: Orlando | B7: 30 | C7: 1 | D7: 2023 | E7: =IF(Elect!AM9<0,"0",Elect!AM9) -> 0 | F7: =IF(Elect!I9<0,"0",Elect!I9) -> 50400 | G7: =Elect!H9 -> 2.413 | H7: =IF(Elect!F9<0,"0",Elect!F9) -> 44000 | I7: =Elect!E9 -> 2.083 | J7: =IF(Elect!U9<0,"0",Elect!U9) -> 50100 | K7: =Elect!T9 -> 2.253 | L7: =IF(Elect!AJ9<0,"0",Elect!AJ9) -> 1440 | M7: =Elect!AI9 -> 0.324 | N7: =IF(Elect!X9<0,"0",Elect!X9) -> 35700 | O7: =Elect!W9 -> 1.744 | P7: =IF(Elect!O9<0,"0",Elect!O9) -> 13200 | Q7: =Elect!N9 -> 2.76 | R7: =IF(Elect!L9<0,"0",Elect!L9) -> 15200 | S7: =Elect!K9 -> 3.29 | T7: =IF(Elect!R9<0,"0",Elect!R9) -> 13600 | U7: =Elect!Q9 -> 3.07 | V7: =IF(Elect!AA9<0,"0",Elect!AA9) -> 8160 | W7: =Elect!Z9 -> 4.71 | X7: =IF(Elect!AD9<0,"0",Elect!AD9) -> 4320 | Y7: =Elect!AC9 -> 3.32 | Z7: =IF(Elect!AG9<0,"0",Elect!AG9) -> 50000 | AA7: =Elect!AF9 -> 1.941 | AB7: =IF(Elect!AX9<0,"0",Elect!AX9) -> 1800 | AC7: =IF(Elect!AV9<0,"0",Elect!AV9) -> 13300 | AD7: =IF(Elect!AZ9<0,"0",Elect!AZ9) -> 757 | AE7: =IF(Elect!BB9<0,"0",Elect!BB9) -> 2160 | AF7: =IF('Wtr-Gas'!E9<0,"0",('Wtr-Gas'!E9)*0.0038) -> 4531.766 | AG7: =IF('Wtr-Gas'!H9<0,"0",('Wtr-Gas'!H9)*0.0038) -> 389.5 | AH7: =IF('Wtr-Gas'!K9<0,"0",('Wtr-Gas'!K9)*0.0038) -> 0.874 | AI7: =IF('Wtr-Gas'!N9<0,"0",('Wtr-Gas'!N9)*0.0038) -> 3458 | AJ7: =IF('Wtr-Gas'!Q9<0,"0",('Wtr-Gas'!Q9)*0.0038) -> 102.6 | AK7: =IF('Wtr-Gas'!U9<0,"0",('Wtr-Gas'!U9)*0.0038) -> 0 | AL7: =IF('Wtr-Gas'!X9<0,"0",('Wtr-Gas'!X9)*0.0038) -> 642.96 | AM7: =IF('Wtr-Gas'!AB9<0,"0",('Wtr-Gas'!AB9)*0.0038) -> 4978 | AN7: =IF('Wtr-Gas'!AD9<0,"0",('Wtr-Gas'!AD9)*0.0038) -> 1270.15 | AO7: =IF('Wtr-Gas'!AH9<0,"0",('Wtr-Gas'!AH9)*0.0038) -> 1.558 | AP7: =IF('Wtr-Gas'!AJ9<0,"0",('Wtr-Gas'!AJ9)*0.0038) -> 164.122 | AQ7: =IF('Wtr-Gas'!AL9<0,"0",('Wtr-Gas'!AL9)*0.0038) -> 54.777 | AR7: =IF('Wtr-Gas'!AN9<0,"0",('Wtr-Gas'!AN9)*0.0038) -> 516.8 | AS7: =IF('Wtr-Gas'!AP9<0,"0",('Wtr-Gas'!AP9)*0.0038) -> 0.0494 | AT7: =IF('Wtr-Gas'!AR9<0,"0",('Wtr-Gas'!AR9)*0.0038) -> 18.62 | AU7: =IF('Wtr-Gas'!AV9<0,"0",('Wtr-Gas'!AV9)*0.0038) -> 0.5434 | AV7: =IF('Wtr-Gas'!AY9<0,"0",('Wtr-Gas'!AY9)*0.0038) -> 217.835 | AW7: =IF('Wtr-Gas'!BA9<0,"0",('Wtr-Gas'!BA9)*0.0038) -> 151.70094 | AX7: =IF('Wtr-Gas'!BB9<0,"0",('Wtr-Gas'!BB9)*0.0038) -> 66.13406 | AY7: =IF('Wtr-Gas'!BD9<0,"0",('Wtr-Gas'!BD9)*0.0038) -> 9.12 | AZ7: =IF('Wtr-Gas'!BF9<0,"0",('Wtr-Gas'!BF9)*0.0038) -> 1.52 | BA7: =IF('Wtr-Gas'!BH9<0,"0",('Wtr-Gas'!BH9)*0.0038) -> 6009.1908
A8: Orlando | B8: 31 | C8: 1 | D8: 2023 | E8: =IF(Elect!AM10<0,"0",Elect!AM10) -> 0 | F8: =IF(Elect!I10<0,"0",Elect!I10) -> 7680 | G8: =Elect!H10 -> 2.413 | H8: =IF(Elect!F10<0,"0",Elect!F10) -> 7040 | I8: =Elect!E10 -> 2.083 | J8: =IF(Elect!U10<0,"0",Elect!U10) -> 8700 | K8: =Elect!T10 -> 2.253 | L8: =IF(Elect!AJ10<0,"0",Elect!AJ10) -> 200 | M8: =Elect!AI10 -> 0.324 | N8: =IF(Elect!X10<0,"0",Elect!X10) -> 11100 | O8: =Elect!W10 -> 1.828 | P8: =IF(Elect!O10<0,"0",Elect!O10) -> 2000 | Q8: =Elect!N10 -> 2.76 | R8: =IF(Elect!L10<0,"0",Elect!L10) -> 2000 | S8: =Elect!K10 -> 3.29 | T8: =IF(Elect!R10<0,"0",Elect!R10) -> 1600 | U8: =Elect!Q10 -> 3.07 | V8: =IF(Elect!AA10<0,"0",Elect!AA10) -> 960 | W8: =Elect!Z10 -> 4.71 | X8: =IF(Elect!AD10<0,"0",Elect!AD10) -> 480 | Y8: =Elect!AC10 -> 3.32 | Z8: =IF(Elect!AG10<0,"0",Elect!AG10) -> 8200 | AA8: =Elect!AF10 -> 1.941 | AB8: =IF(Elect!AX10<0,"0",Elect!AX10) -> 300 | AC8: =IF(Elect!AV10<0,"0",Elect!AV10) -> 2600 | AD8: =IF(Elect!AZ10<0,"0",Elect!AZ10) -> 128 | AE8: =IF(Elect!BB10<0,"0",Elect!BB10) -> 560 | AF8: =IF('Wtr-Gas'!E10<0,"0",('Wtr-Gas'!E10)*0.0038) -> 608.038 | AG8: =IF('Wtr-Gas'!H10<0,"0",('Wtr-Gas'!H10)*0.0038) -> 1.254 | AH8: =IF('Wtr-Gas'!K10<0,"0",('Wtr-Gas'!K10)*0.0038) -> 0.874 | AI8: =IF('Wtr-Gas'!N10<0,"0",('Wtr-Gas'!N10)*0.0038) -> 456 | AJ8: =IF('Wtr-Gas'!Q10<0,"0",('Wtr-Gas'!Q10)*0.0038) -> 14.06 | AK8: =IF('Wtr-Gas'!U10<0,"0",('Wtr-Gas'!U10)*0.0038) -> 0 | AL8: =IF('Wtr-Gas'!X10<0,"0",('Wtr-Gas'!X10)*0.0038) -> 44.46 | AM8: =IF('Wtr-Gas'!AB10<0,"0",('Wtr-Gas'!AB10)*0.0038) -> 1368 | AN8: =IF('Wtr-Gas'!AD10<0,"0",('Wtr-Gas'!AD10)*0.0038) -> 341.354 | AO8: =IF('Wtr-Gas'!AH10<0,"0",('Wtr-Gas'!AH10)*0.0038) -> 0.342 | AP8: =IF('Wtr-Gas'!AJ10<0,"0",('Wtr-Gas'!AJ10)*0.0038) -> 21.774 | AQ8: =IF('Wtr-Gas'!AL10<0,"0",('Wtr-Gas'!AL10)*0.0038) -> 0 | AR8: =IF('Wtr-Gas'!AN10<0,"0",('Wtr-Gas'!AN10)*0.0038) -> 49.4 | AS8: =IF('Wtr-Gas'!AP10<0,"0",('Wtr-Gas'!AP10)*0.0038) -> 0 | AT8: =IF('Wtr-Gas'!AR10<0,"0",('Wtr-Gas'!AR10)*0.0038) -> 1.52 | AU8: =IF('Wtr-Gas'!AV10<0,"0",('Wtr-Gas'!AV10)*0.0038) -> 0.0912 | AV8: =IF('Wtr-Gas'!AY10<0,"0",('Wtr-Gas'!AY10)*0.0038) -> 30.7496 | AW8: =IF('Wtr-Gas'!BA10<0,"0",('Wtr-Gas'!BA10)*0.0038) -> 21.671058 | AX8: =IF('Wtr-Gas'!BB10<0,"0",('Wtr-Gas'!BB10)*0.0038) -> 9.078542 | AY8: =IF('Wtr-Gas'!BD10<0,"0",('Wtr-Gas'!BD10)*0.0038) -> 6.46 | AZ8: =IF('Wtr-Gas'!BF10<0,"0",('Wtr-Gas'!BF10)*0.0038) -> 1.14 | BA8: =IF('Wtr-Gas'!BH10<0,"0",('Wtr-Gas'!BH10)*0.0038) -> 1598.6904
A9: Orlando | B9: 6 | C9: 2 | D9: 2023 | E9: =IF(Elect!AM11<0,"0",Elect!AM11) -> 0 | F9: =IF(Elect!I11<0,"0",Elect!I11) -> 41440 | G9: =Elect!H11 -> 2.413 | H9: =IF(Elect!F11<0,"0",Elect!F11) -> 35520 | I9: =Elect!E11 -> 2.083 | J9: =IF(Elect!U11<0,"0",Elect!U11) -> 39000 | K9: =Elect!T11 -> 2.253 | L9: =IF(Elect!AJ11<0,"0",Elect!AJ11) -> 1120 | M9: =Elect!AI11 -> 0.324 | N9: =IF(Elect!X11<0,"0",Elect!X11) -> 44100 | O9: =Elect!W11 -> 1.828 | P9: =IF(Elect!O11<0,"0",Elect!O11) -> 9600 | Q9: =Elect!N11 -> 2.76 | R9: =IF(Elect!L11<0,"0",Elect!L11) -> 12000 | S9: =Elect!K11 -> 3.29 | T9: =IF(Elect!R11<0,"0",Elect!R11) -> 10400 | U9: =Elect!Q11 -> 3.07 | V9: =IF(Elect!AA11<0,"0",Elect!AA11) -> 5600 | W9: =Elect!Z11 -> 4.71 | X9: =IF(Elect!AD11<0,"0",Elect!AD11) -> 3680 | Y9: =Elect!AC11 -> 3.32 | Z9: =IF(Elect!AG11<0,"0",Elect!AG11) -> 43000 | AA9: =Elect!AF11 -> 1.941 | AB9: =IF(Elect!AX11<0,"0",Elect!AX11) -> 1500 | AC9: =IF(Elect!AV11<0,"0",Elect!AV11) -> 11600 | AD9: =IF(Elect!AZ11<0,"0",Elect!AZ11) -> 631 | AE9: =IF(Elect!BB11<0,"0",Elect!BB11) -> 1080 | AF9: =IF('Wtr-Gas'!E11<0,"0",('Wtr-Gas'!E11)*0.0038) -> 3743.152 | AG9: =IF('Wtr-Gas'!H11<0,"0",('Wtr-Gas'!H11)*0.0038) -> 370.082 | AH9: =IF('Wtr-Gas'!K11<0,"0",('Wtr-Gas'!K11)*0.0038) -> 1.558 | AI9: =IF('Wtr-Gas'!N11<0,"0",('Wtr-Gas'!N11)*0.0038) -> 2922.2 | AJ9: =IF('Wtr-Gas'!Q11<0,"0",('Wtr-Gas'!Q11)*0.0038) -> 82.84 | AK9: =IF('Wtr-Gas'!U11<0,"0",('Wtr-Gas'!U11)*0.0038) -> 0 | AL9: =IF('Wtr-Gas'!X11<0,"0",('Wtr-Gas'!X11)*0.0038) -> 386.08 | AM9: =IF('Wtr-Gas'!AB11<0,"0",('Wtr-Gas'!AB11)*0.0038) -> 7258 | AN9: =IF('Wtr-Gas'!AD11<0,"0",('Wtr-Gas'!AD11)*0.0038) -> 1409.648 | AO9: =IF('Wtr-Gas'!AH11<0,"0",('Wtr-Gas'!AH11)*0.0038) -> 0.57 | AP9: =IF('Wtr-Gas'!AJ11<0,"0",('Wtr-Gas'!AJ11)*0.0038) -> 90.022 | AQ9: =IF('Wtr-Gas'!AL11<0,"0",('Wtr-Gas'!AL11)*0.0038) -> 41.0742 | AR9: =IF('Wtr-Gas'!AN11<0,"0",('Wtr-Gas'!AN11)*0.0038) -> 437 | AS9: =IF('Wtr-Gas'!AP11<0,"0",('Wtr-Gas'!AP11)*0.0038) -> 0.0494 | AT9: =IF('Wtr-Gas'!AR11<0,"0",('Wtr-Gas'!AR11)*0.0038) -> 11.4 | AU9: =IF('Wtr-Gas'!AV11<0,"0",('Wtr-Gas'!AV11)*0.0038) -> 0.4256 | AV9: =IF('Wtr-Gas'!AY11<0,"0",('Wtr-Gas'!AY11)*0.0038) -> 179.8046 | AW9: =IF('Wtr-Gas'!BA11<0,"0",('Wtr-Gas'!BA11)*0.0038) -> 130.80945 | AX9: =IF('Wtr-Gas'!BB11<0,"0",('Wtr-Gas'!BB11)*0.0038) -> 48.995148 | AY9: =IF('Wtr-Gas'!BD11<0,"0",('Wtr-Gas'!BD11)*0.0038) -> 7.98 | AZ9: =IF('Wtr-Gas'!BF11<0,"0",('Wtr-Gas'!BF11)*0.0038) -> 1.14 | BA9: =IF('Wtr-Gas'!BH11<0,"0",('Wtr-Gas'!BH11)*0.0038) -> 2431.1412
A10: Orlando | B10: 13 | C10: 2 | D10: 2023 | E10: =IF(Elect!AM12<0,"0",Elect!AM12) -> 0 | F10: =IF(Elect!I12<0,"0",Elect!I12) -> 46880 | G10: =Elect!H12 -> 2.413 | H10: =IF(Elect!F12<0,"0",Elect!F12) -> 44800 | I10: =Elect!E12 -> 2.083 | J10: =IF(Elect!U12<0,"0",Elect!U12) -> 48900 | K10: =Elect!T12 -> 2.253 | L10: =IF(Elect!AJ12<0,"0",Elect!AJ12) -> 1280 | M10: =Elect!AI12 -> 0.324 | N10: =IF(Elect!X12<0,"0",Elect!X12) -> 59100 | O10: =Elect!W12 -> 2.162 | P10: =IF(Elect!O12<0,"0",Elect!O12) -> 12400 | Q10: =Elect!N12 -> 3.06 | R10: =IF(Elect!L12<0,"0",Elect!L12) -> 14800 | S10: =Elect!K12 -> 3.63 | T10: =IF(Elect!R12<0,"0",Elect!R12) -> 12800 | U10: =Elect!Q12 -> 3.07 | V10: =IF(Elect!AA12<0,"0",Elect!AA12) -> 8160 | W10: =Elect!Z12 -> 4.77 | X10: =IF(Elect!AD12<0,"0",Elect!AD12) -> 4800 | Y10: =Elect!AC12 -> 3.32 | Z10: =IF(Elect!AG12<0,"0",Elect!AG12) -> 51800 | AA10: =Elect!AF12 -> 1.941 | AB10: =IF(Elect!AX12<0,"0",Elect!AX12) -> 1800 | AC10: =IF(Elect!AV12<0,"0",Elect!AV12) -> 14500 | AD10: =IF(Elect!AZ12<0,"0",Elect!AZ12) -> 754 | AE10: =IF(Elect!BB12<0,"0",Elect!BB12) -> 2240 | AF10: =IF('Wtr-Gas'!E12<0,"0",('Wtr-Gas'!E12)*0.0038) -> 5084.552 | AG10: =IF('Wtr-Gas'!H12<0,"0",('Wtr-Gas'!H12)*0.0038) -> 353.932 | AH10: =IF('Wtr-Gas'!K12<0,"0",('Wtr-Gas'!K12)*0.0038) -> 3.23 | AI10: =IF('Wtr-Gas'!N12<0,"0",('Wtr-Gas'!N12)*0.0038) -> 4123 | AJ10: =IF('Wtr-Gas'!Q12<0,"0",('Wtr-Gas'!Q12)*0.0038) -> 108.68 | AK10: =IF('Wtr-Gas'!U12<0,"0",('Wtr-Gas'!U12)*0.0038) -> 0 | AL10: =IF('Wtr-Gas'!X12<0,"0",('Wtr-Gas'!X12)*0.0038) -> 506.16 | AM10: =IF('Wtr-Gas'!AB12<0,"0",('Wtr-Gas'!AB12)*0.0038) -> 5016 | AN10: =IF('Wtr-Gas'!AD12<0,"0",('Wtr-Gas'!AD12)*0.0038) -> 1675.496 | AO10: =IF('Wtr-Gas'!AH12<0,"0",('Wtr-Gas'!AH12)*0.0038) -> 0.722 | AP10: =IF('Wtr-Gas'!AJ12<0,"0",('Wtr-Gas'!AJ12)*0.0038) -> 77.52 | AQ10: =IF('Wtr-Gas'!AL12<0,"0",('Wtr-Gas'!AL12)*0.0038) -> 280.5958 | AR10: =IF('Wtr-Gas'!AN12<0,"0",('Wtr-Gas'!AN12)*0.0038) -> 463.6 | AS10: =IF('Wtr-Gas'!AP12<0,"0",('Wtr-Gas'!AP12)*0.0038) -> 0.3154 | AT10: =IF('Wtr-Gas'!AR12<0,"0",('Wtr-Gas'!AR12)*0.0038) -> 11.4 | AU10: =IF('Wtr-Gas'!AV12<0,"0",('Wtr-Gas'!AV12)*0.0038) -> 0.5092 | AV10: =IF('Wtr-Gas'!AY12<0,"0",('Wtr-Gas'!AY12)*0.0038) -> 213.5372 | AW10: =IF('Wtr-Gas'!BA12<0,"0",('Wtr-Gas'!BA12)*0.0038) -> 151.85298 | AX10: =IF('Wtr-Gas'!BB12<0,"0",('Wtr-Gas'!BB12)*0.0038) -> 61.684222 | AY10: =IF('Wtr-Gas'!BD12<0,"0",('Wtr-Gas'!BD12)*0.0038) -> 9.88 | AZ10: =IF('Wtr-Gas'!BF12<0,"0",('Wtr-Gas'!BF12)*0.0038) -> 1.9 | BA10: =IF('Wtr-Gas'!BH12<0,"0",('Wtr-Gas'!BH12)*0.0038) -> 5757.0038
A11: Orlando | B11: 20 | C11: 2 | D11: 2023 | E11: =IF(Elect!AM13<0,"0",Elect!AM13) -> 0 | F11: =IF(Elect!I13<0,"0",Elect!I13) -> 52640 | G11: =Elect!H13 -> 2.413 | H11: =IF(Elect!F13<0,"0",Elect!F13) -> 44320 | I11: =Elect!E13 -> 2.083 | J11: =IF(Elect!U13<0,"0",Elect!U13) -> 47700 | K11: =Elect!T13 -> 2.253 | L11: =IF(Elect!AJ13<0,"0",Elect!AJ13) -> 1360 | M11: =Elect!AI13 -> 0.324 | N11: =IF(Elect!X13<0,"0",Elect!X13) -> 47400 | O11: =Elect!W13 -> 2.162 | P11: =IF(Elect!O13<0,"0",Elect!O13) -> 12800 | Q11: =Elect!N13 -> 3.06 | R11: =IF(Elect!L13<0,"0",Elect!L13) -> 15200 | S11: =Elect!K13 -> 3.63 | T11: =IF(Elect!R13<0,"0",Elect!R13) -> 12400 | U11: =Elect!Q13 -> 3.07 | V11: =IF(Elect!AA13<0,"0",Elect!AA13) -> 7200 | W11: =Elect!Z13 -> 4.77 | X11: =IF(Elect!AD13<0,"0",Elect!AD13) -> 4320 | Y11: =Elect!AC13 -> 3.32 | Z11: =IF(Elect!AG13<0,"0",Elect!AG13) -> 51000 | AA11: =Elect!AF13 -> 1.972 | AB11: =IF(Elect!AX13<0,"0",Elect!AX13) -> 1700 | AC11: =IF(Elect!AV13<0,"0",Elect!AV13) -> 13700 | AD11: =IF(Elect!AZ13<0,"0",Elect!AZ13) -> 752 | AE11: =IF(Elect!BB13<0,"0",Elect!BB13) -> 2920 | AF11: =IF('Wtr-Gas'!E13<0,"0",('Wtr-Gas'!E13)*0.0038) -> 4990.844 | AG11: =IF('Wtr-Gas'!H13<0,"0",('Wtr-Gas'!H13)*0.0038) -> 506.464 | AH11: =IF('Wtr-Gas'!K13<0,"0",('Wtr-Gas'!K13)*0.0038) -> 1.71 | AI11: =IF('Wtr-Gas'!N13<0,"0",('Wtr-Gas'!N13)*0.0038) -> 3944.4 | AJ11: =IF('Wtr-Gas'!Q13<0,"0",('Wtr-Gas'!Q13)*0.0038) -> 106.02 | AK11: =IF('Wtr-Gas'!U13<0,"0",('Wtr-Gas'!U13)*0.0038) -> 0 | AL11: =IF('Wtr-Gas'!X13<0,"0",('Wtr-Gas'!X13)*0.0038) -> 517.94 | AM11: =IF('Wtr-Gas'!AB13<0,"0",('Wtr-Gas'!AB13)*0.0038) -> 6042 | AN11: =IF('Wtr-Gas'!AD13<0,"0",('Wtr-Gas'!AD13)*0.0038) -> 1428.192 | AO11: =IF('Wtr-Gas'!AH13<0,"0",('Wtr-Gas'!AH13)*0.0038) -> 0.874 | AP11: =IF('Wtr-Gas'!AJ13<0,"0",('Wtr-Gas'!AJ13)*0.0038) -> 117.61 | AQ11: =IF('Wtr-Gas'!AL13<0,"0",('Wtr-Gas'!AL13)*0.0038) -> 71.3222 | AR11: =IF('Wtr-Gas'!AN13<0,"0",('Wtr-Gas'!AN13)*0.0038) -> 471.2 | AS11: =IF('Wtr-Gas'!AP13<0,"0",('Wtr-Gas'!AP13)*0.0038) -> 0.0646 | AT11: =IF('Wtr-Gas'!AR13<0,"0",('Wtr-Gas'!AR13)*0.0038) -> 21.66 | AU11: =IF('Wtr-Gas'!AV13<0,"0",('Wtr-Gas'!AV13)*0.0038) -> 0.4826 | AV11: =IF('Wtr-Gas'!AY13<0,"0",('Wtr-Gas'!AY13)*0.0038) -> 208.3464 | AW11: =IF('Wtr-Gas'!BA13<0,"0",('Wtr-Gas'!BA13)*0.0038) -> 151.42749 | AX11: =IF('Wtr-Gas'!BB13<0,"0",('Wtr-Gas'!BB13)*0.0038) -> 56.918908 | AY11: =IF('Wtr-Gas'!BD13<0,"0",('Wtr-Gas'!BD13)*0.0038) -> 12.92 | AZ11: =IF('Wtr-Gas'!BF13<0,"0",('Wtr-Gas'!BF13)*0.0038) -> 1.9 | BA11: =IF('Wtr-Gas'!BH13<0,"0",('Wtr-Gas'!BH13)*0.0038) -> 8315.3386
A12: Orlando | B12: 27 | C12: 2 | D12: 2023 | E12: =IF(Elect!AM14<0,"0",Elect!AM14) -> 0 | F12: =IF(Elect!I14<0,"0",Elect!I14) -> 0 | G12: =Elect!H14 -> 0 | H12: =IF(Elect!F14<0,"0",Elect!F14) -> 0 | I12: =Elect!E14 -> 0 | J12: =IF(Elect!U14<0,"0",Elect!U14) -> 0 | K12: =Elect!T14 -> 0 | L12: =IF(Elect!AJ14<0,"0",Elect!AJ14) -> 0 | M12: =Elect!AI14 -> 0 | N12: =IF(Elect!X14<0,"0",Elect!X14) -> 0 | O12: =Elect!W14 -> 0 | P12: =IF(Elect!O14<0,"0",Elect!O14) -> 0 | Q12: =Elect!N14 -> 0 | R12: =IF(Elect!L14<0,"0",Elect!L14) -> 0 | S12: =Elect!K14 -> 0 | T12: =IF(Elect!R14<0,"0",Elect!R14) -> 0 | U12: =Elect!Q14 -> 0 | V12: =IF(Elect!AA14<0,"0",Elect!AA14) -> 0 | W12: =Elect!Z14 -> 0 | X12: =IF(Elect!AD14<0,"0",Elect!AD14) -> 0 | Y12: =Elect!AC14 -> 0 | Z12: =IF(Elect!AG14<0,"0",Elect!AG14) -> 0 | AA12: =Elect!AF14 -> 0 | AB12: =IF(Elect!AX14<0,"0",Elect!AX14) -> 0 | AC12: =IF(Elect!AV14<0,"0",Elect!AV14) -> 0 | AD12: =IF(Elect!AZ14<0,"0",Elect!AZ14) -> 0 | AE12: =IF(Elect!BB14<0,"0",Elect!BB14) -> 0 | AF12: =IF('Wtr-Gas'!E14<0,"0",('Wtr-Gas'!E14)*0.0038) -> 0 | AG12: =IF('Wtr-Gas'!H14<0,"0",('Wtr-Gas'!H14)*0.0038) -> 0 | AH12: =IF('Wtr-Gas'!K14<0,"0",('Wtr-Gas'!K14)*0.0038) -> 0 | AI12: =IF('Wtr-Gas'!N14<0,"0",('Wtr-Gas'!N14)*0.0038) -> 0 | AJ12: =IF('Wtr-Gas'!Q14<0,"0",('Wtr-Gas'!Q14)*0.0038) -> 0 | AK12: =IF('Wtr-Gas'!U14<0,"0",('Wtr-Gas'!U14)*0.0038) -> 0 | AL12: =IF('Wtr-Gas'!X14<0,"0",('Wtr-Gas'!X14)*0.0038) -> 0 | AM12: =IF('Wtr-Gas'!AB14<0,"0",('Wtr-Gas'!AB14)*0.0038) -> 0 | AN12: =IF('Wtr-Gas'!AD14<0,"0",('Wtr-Gas'!AD14)*0.0038) -> 0 | AO12: =IF('Wtr-Gas'!AH14<0,"0",('Wtr-Gas'!AH14)*0.0038) -> 0 | AP12: =IF('Wtr-Gas'!AJ14<0,"0",('Wtr-Gas'!AJ14)*0.0038) -> 0 | AQ12: =IF('Wtr-Gas'!AL14<0,"0",('Wtr-Gas'!AL14)*0.0038) -> 0 | AR12: =IF('Wtr-Gas'!AN14<0,"0",('Wtr-Gas'!AN14)*0.0038) -> 0 | AS12: =IF('Wtr-Gas'!AP14<0,"0",('Wtr-Gas'!AP14)*0.0038) -> 0 | AT12: =IF('Wtr-Gas'!AR14<0,"0",('Wtr-Gas'!AR14)*0.0038) -> 0 | AU12: =IF('Wtr-Gas'!AV14<0,"0",('Wtr-Gas'!AV14)*0.0038) -> 0 | AV12: =IF('Wtr-Gas'!AY14<0,"0",('Wtr-Gas'!AY14)*0.0038) -> 0 | AW12: =IF('Wtr-Gas'!BA14<0,"0",('Wtr-Gas'!BA14)*0.0038) -> 0 | AX12: =IF('Wtr-Gas'!BB14<0,"0",('Wtr-Gas'!BB14)*0.0038) -> 0 | AY12: =IF('Wtr-Gas'!BD14<0,"0",('Wtr-Gas'!BD14)*0.0038) -> 0 | AZ12: =IF('Wtr-Gas'!BF14<0,"0",('Wtr-Gas'!BF14)*0.0038) -> 0 | BA12: =IF('Wtr-Gas'!BH14<0,"0",('Wtr-Gas'!BH14)*0.0038) -> 0
A13: Orlando | B13: 28 | C13: 2 | D13: 2023 | E13: =IF(Elect!AM15<0,"0",Elect!AM15) -> 0 | F13: =IF(Elect!I15<0,"0",Elect!I15) -> 0 | G13: =Elect!H15 -> 0 | H13: =IF(Elect!F15<0,"0",Elect!F15) -> 0 | I13: =Elect!E15 -> 0 | J13: =IF(Elect!U15<0,"0",Elect!U15) -> 0 | K13: =Elect!T15 -> 0 | L13: =IF(Elect!AJ15<0,"0",Elect!AJ15) -> 0 | M13: =Elect!AI15 -> 0 | N13: =IF(Elect!X15<0,"0",Elect!X15) -> 0 | O13: =Elect!W15 -> 0 | P13: =IF(Elect!O15<0,"0",Elect!O15) -> 0 | Q13: =Elect!N15 -> 0 | R13: =IF(Elect!L15<0,"0",Elect!L15) -> 0 | S13: =Elect!K15 -> 0 | T13: =IF(Elect!R15<0,"0",Elect!R15) -> 0 | U13: =Elect!Q15 -> 0 | V13: =IF(Elect!AA15<0,"0",Elect!AA15) -> 0 | W13: =Elect!Z15 -> 0 | X13: =IF(Elect!AD15<0,"0",Elect!AD15) -> 0 | Y13: =Elect!AC15 -> 0 | Z13: =IF(Elect!AG15<0,"0",Elect!AG15) -> 0 | AA13: =Elect!AF15 -> 0 | AB13: =IF(Elect!AX15<0,"0",Elect!AX15) -> 0 | AC13: =IF(Elect!AV15<0,"0",Elect!AV15) -> 0 | AD13: =IF(Elect!AZ15<0,"0",Elect!AZ15) -> 0 | AE13: =IF(Elect!BB15<0,"0",Elect!BB15) -> 0 | AF13: =IF('Wtr-Gas'!E15<0,"0",('Wtr-Gas'!E15)*0.0038) -> 0 | AG13: =IF('Wtr-Gas'!H15<0,"0",('Wtr-Gas'!H15)*0.0038) -> 0 | AH13: =IF('Wtr-Gas'!K15<0,"0",('Wtr-Gas'!K15)*0.0038) -> 0 | AI13: =IF('Wtr-Gas'!N15<0,"0",('Wtr-Gas'!N15)*0.0038) -> 0 | AJ13: =IF('Wtr-Gas'!Q15<0,"0",('Wtr-Gas'!Q15)*0.0038) -> 0 | AK13: =IF('Wtr-Gas'!U15<0,"0",('Wtr-Gas'!U15)*0.0038) -> 0 | AL13: =IF('Wtr-Gas'!X15<0,"0",('Wtr-Gas'!X15)*0.0038) -> 0 | AM13: =IF('Wtr-Gas'!AB15<0,"0",('Wtr-Gas'!AB15)*0.0038) -> 0 | AN13: =IF('Wtr-Gas'!AD15<0,"0",('Wtr-Gas'!AD15)*0.0038) -> 0 | AO13: =IF('Wtr-Gas'!AH15<0,"0",('Wtr-Gas'!AH15)*0.0038) -> 0 | AP13: =IF('Wtr-Gas'!AJ15<0,"0",('Wtr-Gas'!AJ15)*0.0038) -> 0 | AQ13: =IF('Wtr-Gas'!AL15<0,"0",('Wtr-Gas'!AL15)*0.0038) -> 0 | AR13: =IF('Wtr-Gas'!AN15<0,"0",('Wtr-Gas'!AN15)*0.0038) -> 0 | AS13: =IF('Wtr-Gas'!AP15<0,"0",('Wtr-Gas'!AP15)*0.0038) -> 0 | AT13: =IF('Wtr-Gas'!AR15<0,"0",('Wtr-Gas'!AR15)*0.0038) -> 0 | AU13: =IF('Wtr-Gas'!AV15<0,"0",('Wtr-Gas'!AV15)*0.0038) -> 0 | AV13: =IF('Wtr-Gas'!AY15<0,"0",('Wtr-Gas'!AY15)*0.0038) -> 0 | AW13: =IF('Wtr-Gas'!BA15<0,"0",('Wtr-Gas'!BA15)*0.0038) -> 0 | AX13: =IF('Wtr-Gas'!BB15<0,"0",('Wtr-Gas'!BB15)*0.0038) -> 0 | AY13: =IF('Wtr-Gas'!BD15<0,"0",('Wtr-Gas'!BD15)*0.0038) -> 0 | AZ13: =IF('Wtr-Gas'!BF15<0,"0",('Wtr-Gas'!BF15)*0.0038) -> 0 | BA13: =IF('Wtr-Gas'!BH15<0,"0",('Wtr-Gas'!BH15)*0.0038) -> 0
... A65: Orlando | B65: 31 | C65: 12 | D65: 2023 | E65: =IF(Elect!AM67<0,"0",Elect!AM67) -> 0 | F65: =IF(Elect!I67<0,"0",Elect!I67) -> 0 | G65: =Elect!H67 -> 0 | H65: =IF(Elect!F67<0,"0",Elect!F67) -> 0 | I65: =Elect!E67 -> 0 | J65: =IF(Elect!U67<0,"0",Elect!U67) -> 0 | K65: =Elect!T67 -> 0 | L65: =IF(Elect!AJ67<0,"0",Elect!AJ67) -> 0 | M65: =Elect!AI67 -> 0 | N65: =IF(Elect!X67<0,"0",Elect!X67) -> 0 | O65: =Elect!W67 -> 0 | P65: =IF(Elect!O67<0,"0",Elect!O67) -> 0 | Q65: =Elect!N67 -> 0 | R65: =IF(Elect!L67<0,"0",Elect!L67) -> 0 | S65: =Elect!K67 -> 0 | T65: =IF(Elect!R67<0,"0",Elect!R67) -> 0 | U65: =Elect!Q67 -> 0 | V65: =IF(Elect!AA67<0,"0",Elect!AA67) -> 0 | W65: =Elect!Z67 -> 0 | X65: =IF(Elect!AD67<0,"0",Elect!AD67) -> 0 | Y65: =Elect!AC67 -> 0 | Z65: =IF(Elect!AG67<0,"0",Elect!AG67) -> 0 | AA65: =Elect!AF67 -> 0 | AB65: =IF(Elect!AX67<0,"0",Elect!AX67) -> 0 | AC65: =IF(Elect!AV67<0,"0",Elect!AV67) -> 0 | AD65: =IF(Elect!AZ67<0,"0",Elect!AZ67) -> 0 | AE65: =IF(Elect!BB67<0,"0",Elect!BB67) -> 0 | AF65: =IF('Wtr-Gas'!E67<0,"0",('Wtr-Gas'!E67)*0.0038) -> 0 | AG65: =IF('Wtr-Gas'!H67<0,"0",('Wtr-Gas'!H67)*0.0038) -> 0 | AH65: =IF('Wtr-Gas'!K67<0,"0",('Wtr-Gas'!K67)*0.0038) -> 0 | AI65: =IF('Wtr-Gas'!N67<0,"0",('Wtr-Gas'!N67)*0.0038) -> 0 | AJ65: =IF('Wtr-Gas'!Q67<0,"0",('Wtr-Gas'!Q67)*0.0038) -> 0 | AK65: =IF('Wtr-Gas'!U67<0,"0",('Wtr-Gas'!U67)*0.0038) -> 0 | AL65: =IF('Wtr-Gas'!X67<0,"0",('Wtr-Gas'!X67)*0.0038) -> 0 | AM65: =IF('Wtr-Gas'!AB67<0,"0",('Wtr-Gas'!AB67)*0.0038) -> 0 | AN65: =IF('Wtr-Gas'!AD67<0,"0",('Wtr-Gas'!AD67)*0.0038) -> 0 | AO65: =IF('Wtr-Gas'!AH67<0,"0",('Wtr-Gas'!AH67)*0.0038) -> 0 | AP65: =IF('Wtr-Gas'!AJ67<0,"0",('Wtr-Gas'!AJ67)*0.0038) -> 0 | AQ65: =IF('Wtr-Gas'!AL67<0,"0",('Wtr-Gas'!AL67)*0.0038) -> 0 | AR65: =IF('Wtr-Gas'!AN67<0,"0",('Wtr-Gas'!AN67)*0.0038) -> 0 | AS65: =IF('Wtr-Gas'!AP67<0,"0",('Wtr-Gas'!AP67)*0.0038) -> 0 | AT65: =IF('Wtr-Gas'!AR67<0,"0",('Wtr-Gas'!AR67)*0.0038) -> 0 | AU65: =IF('Wtr-Gas'!AV67<0,"0",('Wtr-Gas'!AV67)*0.0038) -> 0 | AV65: =IF('Wtr-Gas'!AY67<0,"0",('Wtr-Gas'!AY67)*0.0038) -> 0 | AW65: =IF('Wtr-Gas'!BA67<0,"0",('Wtr-Gas'!BA67)*0.0038) -> 0 | AX65: =IF('Wtr-Gas'!BB67<0,"0",('Wtr-Gas'!BB67)*0.0038) -> 0 | AY65: =IF('Wtr-Gas'!BD67<0,"0",('Wtr-Gas'!BD67)*0.0038) -> 0 | AZ65: =IF('Wtr-Gas'!BF67<0,"0",('Wtr-Gas'!BF67)*0.0038) -> 0 | BA65: =IF('Wtr-Gas'!BH67<0,"0",('Wtr-Gas'!BH67)*0.0038) -> 0

Sheet Elect
B1: 2023 | D1: CC0913A018 | G1: CC0913A020 | J1: CC0913A060 | M1: CC0913A059 | P1: CC0913A081 | S1: CC0913A054 | V1: CC0913A053 | Y1: CC0913A075 | AB1: CC0913A076 | AE1: CC0912A18 | AH1: CC0913A095 | AK1: CS0212A003 | AP1: Water Pk | AQ1: % of KWH | AU1: CG0612A084 | AW1: CC0612A036 | AY1: CS0210A030 | BA1: IIC0608A03 | BF1: KWH
B2: Date | C2: Occupancy | D2: 68 425 008 | E2: T7384 | F2: KWH Total | G2: 68 425 010 | H2: T2392 | I2: KWH Total | J2: 68 425 078 | K2: T2393 | L2: KWH Total | M2: 68 425 077 | N2: T2395 | O2: KWH Total | P2: 68 425 071 | Q2: T7285 | R2: KWH Total | S2: 68 425 060 | T2: T7380 | U2: KWH Total | V2: 68 425 059 | W2: T2390 | X2: KWH Total | Y2: 68 425 093 | Z2: T7382 | AA2: KWH Total | AB2: 68 425 094 | AC2: T2391 | AD2: KWH Total | AE2: 90 625 242 | AF2: T7283 | AG2: KWH Total | AH2: 68 425 097 | AI2: T7281 | AJ2: KWH Total | AK2: 90 630 431 | AM2: KWH Total | AO2: Total KWH | AP2: KWH | AR2: Total Mnth | AU2: 676 62 513 | AV2: KWH Total | AW2: 672 73 163 | AX2: KWH Total | AY2: 61 979 920 | AZ2: KWH Total | BA2: 56 253 208 | BB2: KWH Total | BD2: Total KWH | BE2: Total Mnth | BF2: Total
C3: Room Nights | D3: KWH | E3: Demand | F3: (x160) | G3: KWH | H3: Demand | I3: (x160) | J3: KWH | K3: Demand | L3: (x400) | M3: KWH | N3: Demand | O3: (x400) | P3: KWH | Q3: Demand | R3: (x400) | S3: KWH | T3: Demand | U3: (x300) | V3: KWH | W3: Demand | X3: (x300) | Y3: KWH | Z3: Demand | AA3: (x160) | AB3: KWH | AC3: Demand | AD3: (x160) | AE3: KWH | AF3: Demand | AG3: (X200) | AH3: KWH | AI3: Demand | AJ3: (x40) | AK3: KWH | AM3: (x1) | AR3: KWH | AU3: KWH | AV3: (x100) | AW3: KWH | AX3: (x100) | AY3: KWH | AZ3: (x1) | BA3: KWH | BB3: (x40) | BD3: Golf | BE3: Golf | BF3: Resort
B4: 44927 | C4: =(Occupancy!K8) -> 377 | D4: 25218 | E4: 2.085 | G4: 26434 | H4: 2.469 | J4: 14104 | K4: 4.16 | M4: 13667 | N4: 3.68 | P4: 14287 | Q4: 3.76 | S4: 98693 | T4: 2.072 | V4: 95337 | W4: 1.756 | Y4: 21867 | Z4: 3 | AB4: 14164 | AC4: 2.25 | AE4: 21139 | AF4: 2.199 | AH4: 21357 | AI4: 0.405 | AK4: 26321 | AT4: =B4 -> 44927 | AU4: 78443 | AW4: 9958 | AY4: 15883 | BA4: 6876
B5: 44928 | C5: =(Occupancy!K9) -> 330 | D5: 25218 | E5: 2.085 | F5: =SUM(D5-D4)*160 -> 0 | G5: 26434 | H5: 2.469 | I5: =SUM(G5-G4)*160 -> 0 | J5: 14104 | K5: 4.16 | L5: =SUM(J5-J4)*400 -> 0 | M5: 13667 | N5: 3.68 | O5: =SUM(M5-M4)*400 -> 0 | P5: 14287 | Q5: 3.76 | R5: =SUM(P5-P4)*400 -> 0 | S5: 98693 | T5: 2.072 | U5: =SUM(S5-S4)*300 -> 0 | V5: 95337 | W5: 1.756 | X5: =SUM(V5-V4)*300 -> 0 | Y5: 21867 | Z5: 3 | AA5: =SUM(Y5-Y4)*160 -> 0 | AB5: 14164 | AC5: 2.25 | AD5: =SUM(AB5-AB4)*160 -> 0 | AE5: 21139 | AF5: 2.199 | AG5: =SUM(AE5-AE4)*200 -> 0 | AH5: 21357 | AI5: 0.405 | AJ5: =SUM(AH5-AH4)*40 -> 0 | AK5: 26321 | AL5: =SUM(AK5-AK4) -> 0 | AO5: =SUM(AG5+AD5+AA5+X5+U5+R5+O5+L5+I5+F5+AJ5+AL5) -> 0 | AP5: =SUM(AG5+AJ5) -> 0 | AQ5: =SUM(AP5/AO5) -> #DIV/0! | AR5: =SUM(AO1:AO5) -> 0 | AT5: =B5 -> 44928 | AU5: 78443 | AV5: =SUM(AU5-AU4)*100 -> 0 | AW5: 9958 | AX5: =SUM(AW5-AW4)*100 -> 0 | AY5: 15883 | AZ5: =SUM(AY5-AY4) -> 0 | BA5: 6876 | BB5: =SUM(BA5-BA4)*40 -> 0
B6: 44935 | C6: =SUM(Occupancy!K10:K16) -> 2418 | D6: 25523 | E6: 2.085 | F6: =SUM(D6-D5)*160 -> 48800 | G6: 26785 | H6: 2.469 | I6: =SUM(G6-G5)*160 -> 56160 | J6: 14147 | K6: 4.16 | L6: =SUM(J6-J5)*400 -> 17200 | M6: 13705 | N6: 3.68 | O6: =SUM(M6-M5)*400 -> 15200 | P6: 14323 | Q6: 3.76 | R6: =SUM(P6-P5)*400 -> 14400 | S6: 98891 | T6: 2.072 | U6: =SUM(S6-S5)*300 -> 59400 | V6: 95528 | W6: 1.958 | X6: =SUM(V6-V5)*300 -> 57300 | Y6: 21921 | Z6: 4.94 | AA6: =SUM(Y6-Y5)*160 -> 8640 | AB6: 14190 | AC6: 2.83 | AD6: =SUM(AB6-AB5)*160 -> 4160 | AE6: 21432 | AF6: 2.199 | AG6: =SUM(AE6-AE5)*200 -> 58600 | AH6: 21397 | AI6: 0.405 | AJ6: =SUM(AH6-AH5)*40 -> 1600 | AK6: 26889 | AL6: =SUM(AK6-AK5) -> 568 | AT6: =B6 -> 44935 | AU6: 78575 | AV6: =SUM(AU6-AU5)*100 -> 13200 | AW6: 9972 | AX6: =SUM(AW6-AW5)*100 -> 1400 | AY6: 16637 | AZ6: =SUM(AY6-AY5) -> 754 | BA6: 6915 | BB6: =SUM(BA6-BA5)*40 -> 1560
B7: 44942 | C7: =SUM(Occupancy!K17:K23) -> 1995 | D7: 25801 | E7: 2.085 | F7: =SUM(D7-D6)*160 -> 44480 | G7: 27107 | H7: 2.469 | I7: =SUM(G7-G6)*160 -> 51520 | J7: 14187 | K7: 4.16 | L7: =SUM(J7-J6)*400 -> 16000 | M7: 13739 | N7: 3.68 | O7: =SUM(M7-M6)*400 -> 13600 | P7: 14358 | Q7: 3.76 | R7: =SUM(P7-P6)*400 -> 14000 | S7: 99004 | T7: 2.072 | U7: =SUM(S7-S6)*300 -> 33900 | V7: 95646 | W7: 1.958 | X7: =SUM(V7-V6)*300 -> 35400 | Y7: 21968 | Z7: 4.94 | AA7: =SUM(Y7-Y6)*160 -> 7520 | AB7: 14217 | AC7: 2.199 | AD7: =SUM(AB7-AB6)*160 -> 4320 | AE7: 21679 | AF7: 2.199 | AG7: =SUM(AE7-AE6)*200 -> 49400 | AH7: 21431 | AI7: 0.405 | AJ7: =SUM(AH7-AH6)*40 -> 1360 | AK7: 27487 | AL7: =SUM(AK7-AK6) -> 598 | AT7: =B7 -> 44942 | AU7: 78692 | AV7: =SUM(AU7-AU6)*100 -> 11700 | AW7: 9991 | AX7: =SUM(AW7-AW6)*100 -> 1900 | AY7: 17390 | AZ7: =SUM(AY7-AY6) -> 753 | BA7: 6957 | BB7: =SUM(BA7-BA6)*40 -> 1680
B8: 44949 | C8: =SUM(Occupancy!K24:K30) -> 2324 | D8: 26075 | E8: 1.883 | F8: =SUM(D8-D7)*160 -> 43840 | G8: 27432 | H8: 2.312 | I8: =SUM(G8-G7)*160 -> 52000 | J8: 14226 | K8: 2.96 | L8: =SUM(J8-J7)*400 -> 15600 | M8: 13771 | N8: 2.27 | O8: =SUM(M8-M7)*400 -> 12800 | P8: 14392 | Q8: 2.39 | R8: =SUM(P8-P7)*400 -> 13600 | S8: 99158 | T8: 1.522 | U8: =SUM(S8-S7)*300 -> 46200 | V8: 95800 | W8: 1.744 | X8: =SUM(V8-V7)*300 -> 46200 | Y8: 22011 | Z8: 3.11 | AA8: =SUM(Y8-Y7)*160 -> 6880 | AB8: 14244 | AC8: 2.31 | AD8: =SUM(AB8-AB7)*160 -> 4320 | AE8: 21937 | AF8: 1.941 | AG8: =SUM(AE8-AE7)*200 -> 51600 | AH8: 21468 | AI8: 0.259 | AJ8: =SUM(AH8-AH7)*40 -> 1480 | AK8: 28047 | AL8: =SUM(AK8-AK7) -> 560 | AT8: =B8 -> 44949 | AU8: 78822 | AV8: =SUM(AU8-AU7)*100 -> 13000 | AW8: 10008 | AX8: =SUM(AW8-AW7)*100 -> 1700 | AY8: 18154 | AZ8: =SUM(AY8-AY7) -> 764 | BA8: 7004 | BB8: =SUM(BA8-BA7)*40 -> 1880
