Workbook

Sheet TOTAL
A1: Site Name | B1: Day | C1: Month | D1: Year | E1: Total Electricity Kwh | F1: Electricity Tariff ($/Kwh) | G1: Total Fuel Oil (Liter) | H1: Fuel Oil $/Liter | I1: Water Utility Supply (m3) m3 | J1: Water Utility Supply (m3) $/m3 | K1: LPG (Kg) | L1: LPG $/Kg | M1: Room Nights | N1: Total Guests | O1: Food Covers
A2: Maldives at Kuda Huraa | B2: 1 | C2: 2 | D2: 2023 | E2: 18540 | G2: 5045 | I2: 301 | M2: 31.3 | N2: 67 | O2: 173
A3: Maldives at Kuda Huraa | B3: =B2+1 -> 2 | C3: 2 | D3: 2023 | E3: 18450 | G3: 5090 | I3: 310 | M3: 34.4 | N3: 83 | O3: 215
A4: Maldives at Kuda Huraa | B4: =B3+1 -> 3 | C4: 2 | D4: 2023 | E4: 18760 | G4: 3516.2031 | I4: 286 | M4: 38.5 | N4: 89 | O4: 251
A5: Maldives at Kuda Huraa | B5: =B4+1 -> 4 | C5: 2 | D5: 2023 | E5: 18030 | G5: 3656.12 | I5: 362 | M5: 41.7 | N5: 95 | O5: 256
A6: Maldives at Kuda Huraa | B6: =B5+1 -> 5 | C6: 2 | D6: 2023 | E6: 18980 | G6: 3739.7889 | I6: 346 | M6: 32.3 | N6: 76 | O6: 211
A7: Maldives at Kuda Huraa | B7: =B6+1 -> 6 | C7: 2 | D7: 2023 | E7: 19650 | G7: 3689.1657 | I7: 385 | M7: 34.4 | N7: 79 | O7: 210
A8: Maldives at Kuda Huraa | B8: =B7+1 -> 7 | C8: 2 | D8: 2023 | E8: 18610 | G8: 3662.4479 | I8: 336 | M8: 37.5 | N8: 81 | O8: 225
A9: Maldives at Kuda Huraa | B9: =B8+1 -> 8 | C9: 2 | D9: 2023 | E9: 18950 | G9: 3639.9487 | I9: 378 | M9: 35.4 | N9: 76 | O9: 219
A10: Maldives at Kuda Huraa | B10: =B9+1 -> 9 | C10: 2 | D10: 2023 | E10: 18280 | G10: 4966 | I10: 352 | M10: 35.4 | N10: 71 | O10: 191
A11: Maldives at Kuda Huraa | B11: =B10+1 -> 10 | C11: 2 | D11: 2023 | E11: 18440 | G11: 4879 | I11: 319 | M11: 42.7 | N11: 91 | O11: 245
A12: Maldives at Kuda Huraa | B12: =B11+1 -> 11 | C12: 2 | D12: 2023 | E12: 17980 | G12: 5187 | I12: 340 | M12: 50 | N12: 126 | O12: 303
A13: Maldives at Kuda Huraa | B13: =B12+1 -> 12 | C13: 2 | D13: 2023 | E13: 18260 | G13: 4978 | I13: 345 | M13: 55.2 | N13: 142 | O13: 367
A14: Maldives at Kuda Huraa | B14: =B13+1 -> 13 | C14: 2 | D14: 2023 | E14: 19210 | G14: 5111 | I14: 359 | M14: 61.5 | N14: 159 | O14: 391
... A20: Maldives at Kuda Huraa | B20: =B19+1 -> 19 | C20: 2 | D20: 2023 | E20: 19020 | G20: 5314 | I20: 338 | M20: 54.2 | N20: 154 | O20: 443
A21: Maldives at Kuda Huraa | B21: =B20+1 -> 20 | C21: 2 | D21: 2023
A22: Maldives at Kuda Huraa | B22: =B21+1 -> 21 | C22: 2 | D22: 2023
A23: Maldives at Kuda Huraa | B23: =B22+1 -> 22 | C23: 2 | D23: 2023
A24: Maldives at Kuda Huraa | B24: =B23+1 -> 23 | C24: 2 | D24: 2023
A25: Maldives at Kuda Huraa | B25: =B24+1 -> 24 | C25: 2 | D25: 2023
A26: Maldives at Kuda Huraa | B26: =B25+1 -> 25 | C26: 2 | D26: 2023
A27: Maldives at Kuda Huraa | B27: =B26+1 -> 26 | C27: 2 | D27: 2023
A28: Maldives at Kuda Huraa | B28: =B27+1 -> 27 | C28: 2 | D28: 2023
A29: Maldives at Kuda Huraa | B29: =B28+1 -> 28 | C29: 2 | D29: 2023
A30: Maldives at Kuda Huraa | B30: =B29+1 -> 29 | C30: 2 | D30: 2023
A31: Maldives at Kuda Huraa | B31: =B30+1 -> 30 | C31: 2 | D31: 2023
A32: Maldives at Kuda Huraa | B32: =B31+1 -> 31 | C32: 2 | D32: 2023
A33: Total | E33: =SUM(E2:E32) -> 360050 | F33: 0 | G33: =SUM(G2:G32) -> 89447.674 | H33: 0 | I33: =SUM(I2:I32) -> 6662 | J33: 0 | K33: =SUM(K2:K31) -> 0 | L33: 0 | M33: =SUM(M2:M32) -> 911.5 | N33: =SUM(N2:N32) -> 2234 | O33: =SUM(O2:O32) -> 5805

Sheet Submeters
A1: Site Name | B1: Day | C1: Month | D1: Year | E1: Reef Club | F1: Kitchen | G1: Pastry | H1: Laundry | I1: Laundry A | J1: Laundry B | K1: Laundry C | L1: STP -1 | M1: M - Block /PC | N1: B&C Block | O1: Feeder -101-112 | P1: Feeder -113-123 | Q1: Feeder -124-134 | R1: Feeder -201-208 | S1: Feeder -209-216 | T1: Feeder -217-224 | U1: Feeder -301-319 | V1: Feeder 401-419 | W1: Spa
A2: Maldives at Kuda Huraa | B2: 1 | C2: 2 | D2: 2023 | E2: 480 | F2: 2500 | G2: 260 | H2: =I2+J2+K2 -> 1140 | I2: =('Kwh Reading'!J5-'Kwh Reading'!J4)*1000 -> 440 | J2: =('Kwh Reading'!K5-'Kwh Reading'!K4)*1000 -> 370 | K2: =('Kwh Reading'!L5-'Kwh Reading'!L4)*1000 -> 330 | L2: =('Kwh Reading'!R5-'Kwh Reading'!R4) -> 134.2 | M2: =('Kwh Reading'!I5-'Kwh Reading'!I4)*1000 -> 290 | N2: =('Kwh Reading'!B5-'Kwh Reading'!B4)*1000000 -> 1100 | O2: =('Kwh Reading'!M5-'Kwh Reading'!M4)*1000 -> 370 | P2: =('Kwh Reading'!H5-'Kwh Reading'!H4)*1000000 -> 700 | Q2: =('Kwh Reading'!P5-'Kwh Reading'!P4)*1000000 -> 500 | R2: =('Kwh Reading'!G5-'Kwh Reading'!G4)*1000000 -> 500 | S2: =('Kwh Reading'!Q5-'Kwh Reading'!Q4)*1000 -> 290 | T2: =('Kwh Reading'!N5-'Kwh Reading'!N4)*1000 -> 390 | U2: ='Kwh Reading'!E5-'Kwh Reading'!E4 -> 2415.5 | V2: ='Kwh Reading'!D5-'Kwh Reading'!D4 -> 1697.2 | W2: =('Kwh Reading'!O5-'Kwh Reading'!O4)*1000 -> 220
A3: Maldives at Kuda Huraa | B3: =B2+1 -> 2 | C3: 2 | D3: 2023 | E3: =('Kwh Reading'!S6-'Kwh Reading'!S5)*1000 -> 530 | F3: =('Kwh Reading'!F6-'Kwh Reading'!F5)*1000000 -> 2500 | G3: =('Kwh Reading'!C6-'Kwh Reading'!C5)*1000 -> 270 | H3: =I3+J3+K3 -> 1000 | I3: =('Kwh Reading'!J6-'Kwh Reading'!J5)*1000 -> 440 | J3: =('Kwh Reading'!K6-'Kwh Reading'!K5)*1000 -> 270 | K3: =('Kwh Reading'!L6-'Kwh Reading'!L5)*1000 -> 290 | L3: =('Kwh Reading'!R6-'Kwh Reading'!R5) -> 131.3 | M3: =('Kwh Reading'!I6-'Kwh Reading'!I5)*1000 -> 330 | N3: =('Kwh Reading'!B6-'Kwh Reading'!B5)*1000000 -> 1100 | O3: =('Kwh Reading'!M6-'Kwh Reading'!M5)*1000 -> 400 | P3: =('Kwh Reading'!H6-'Kwh Reading'!H5)*1000000 -> 600 | Q3: =('Kwh Reading'!P6-'Kwh Reading'!P5)*1000000 -> 500 | R3: =('Kwh Reading'!G6-'Kwh Reading'!G5)*1000000 -> 500 | S3: =('Kwh Reading'!Q6-'Kwh Reading'!Q5)*1000 -> 300 | T3: =('Kwh Reading'!N6-'Kwh Reading'!N5)*1000 -> 450 | U3: ='Kwh Reading'!E6-'Kwh Reading'!E5 -> 2362.8 | V3: ='Kwh Reading'!D6-'Kwh Reading'!D5 -> 1667.27 | W3: =('Kwh Reading'!O6-'Kwh Reading'!O5)*1000 -> 230
A4: Maldives at Kuda Huraa | B4: =B3+1 -> 3 | C4: 2 | D4: 2023 | E4: =('Kwh Reading'!S7-'Kwh Reading'!S6)*1000 -> 410 | F4: =('Kwh Reading'!F7-'Kwh Reading'!F6)*1000000 -> 2600 | G4: =('Kwh Reading'!C7-'Kwh Reading'!C6)*1000 -> 240 | H4: =I4+J4+K4 -> 1020 | I4: =('Kwh Reading'!J7-'Kwh Reading'!J6)*1000 -> 450 | J4: =('Kwh Reading'!K7-'Kwh Reading'!K6)*1000 -> 290 | K4: =('Kwh Reading'!L7-'Kwh Reading'!L6)*1000 -> 280 | L4: =('Kwh Reading'!R7-'Kwh Reading'!R6) -> 132.8 | M4: =('Kwh Reading'!I7-'Kwh Reading'!I6)*1000 -> 290 | N4: =('Kwh Reading'!B7-'Kwh Reading'!B6)*1000000 -> 1100 | O4: =('Kwh Reading'!M7-'Kwh Reading'!M6)*1000 -> 450 | P4: =('Kwh Reading'!H7-'Kwh Reading'!H6)*1000000 -> 600 | Q4: =('Kwh Reading'!P7-'Kwh Reading'!P6)*1000000 -> 500 | R4: =('Kwh Reading'!G7-'Kwh Reading'!G6)*1000000 -> 500 | S4: =('Kwh Reading'!Q7-'Kwh Reading'!Q6)*1000 -> 330 | T4: =('Kwh Reading'!N7-'Kwh Reading'!N6)*1000 -> 450 | U4: ='Kwh Reading'!E7-'Kwh Reading'!E6 -> 2342.51 | V4: ='Kwh Reading'!D7-'Kwh Reading'!D6 -> 1643.17 | W4: =('Kwh Reading'!O7-'Kwh Reading'!O6)*1000 -> 230
A5: Maldives at Kuda Huraa | B5: =B4+1 -> 4 | C5: 2 | D5: 2023 | E5: =('Kwh Reading'!S8-'Kwh Reading'!S7)*1000 -> 330 | F5: =('Kwh Reading'!F8-'Kwh Reading'!F7)*1000000 -> 2600 | G5: =('Kwh Reading'!C8-'Kwh Reading'!C7)*1000 -> 250 | H5: =I5+J5+K5 -> 980 | I5: =('Kwh Reading'!J8-'Kwh Reading'!J7)*1000 -> 430 | J5: =('Kwh Reading'!K8-'Kwh Reading'!K7)*1000 -> 270 | K5: =('Kwh Reading'!L8-'Kwh Reading'!L7)*1000 -> 280 | L5: =('Kwh Reading'!R8-'Kwh Reading'!R7) -> 134.8 | M5: =('Kwh Reading'!I8-'Kwh Reading'!I7)*1000 -> 300 | N5: =('Kwh Reading'!B8-'Kwh Reading'!B7)*1000000 -> 1200 | O5: =('Kwh Reading'!M8-'Kwh Reading'!M7)*1000 -> 430 | P5: =('Kwh Reading'!H8-'Kwh Reading'!H7)*1000000 -> 600 | Q5: =('Kwh Reading'!P8-'Kwh Reading'!P7)*1000000 -> 500 | R5: =('Kwh Reading'!G8-'Kwh Reading'!G7)*1000000 -> 500 | S5: =('Kwh Reading'!Q8-'Kwh Reading'!Q7)*1000 -> 350 | T5: =('Kwh Reading'!N8-'Kwh Reading'!N7)*1000 -> 440 | U5: ='Kwh Reading'!E8-'Kwh Reading'!E7 -> 1974.64 | V5: ='Kwh Reading'!D8-'Kwh Reading'!D7 -> 1627.17 | W5: =('Kwh Reading'!O8-'Kwh Reading'!O7)*1000 -> 250
A6: Maldives at Kuda Huraa | B6: =B5+1 -> 5 | C6: 2 | D6: 2023 | E6: =('Kwh Reading'!S9-'Kwh Reading'!S8)*1000 -> 550 | F6: =('Kwh Reading'!F9-'Kwh Reading'!F8)*1000000 -> 2600 | G6: =('Kwh Reading'!C9-'Kwh Reading'!C8)*1000 -> 250 | H6: =I6+J6+K6 -> 1130 | I6: =('Kwh Reading'!J9-'Kwh Reading'!J8)*1000 -> 530 | J6: =('Kwh Reading'!K9-'Kwh Reading'!K8)*1000 -> 310 | K6: =('Kwh Reading'!L9-'Kwh Reading'!L8)*1000 -> 290 | L6: =('Kwh Reading'!R9-'Kwh Reading'!R8) -> 129.7 | M6: =('Kwh Reading'!I9-'Kwh Reading'!I8)*1000 -> 310 | N6: =('Kwh Reading'!B9-'Kwh Reading'!B8)*1000000 -> 1100 | O6: =('Kwh Reading'!M9-'Kwh Reading'!M8)*1000 -> 450 | P6: =('Kwh Reading'!H9-'Kwh Reading'!H8)*1000000 -> 600 | Q6: =('Kwh Reading'!P9-'Kwh Reading'!P8)*1000000 -> 400 | R6: =('Kwh Reading'!G9-'Kwh Reading'!G8)*1000000 -> 600 | S6: =('Kwh Reading'!Q9-'Kwh Reading'!Q8)*1000 -> 350 | T6: =('Kwh Reading'!N9-'Kwh Reading'!N8)*1000 -> 430 | U6: ='Kwh Reading'!E9-'Kwh Reading'!E8 -> 2777.15 | V6: ='Kwh Reading'!D9-'Kwh Reading'!D8 -> 1637.02 | W6: =('Kwh Reading'!O9-'Kwh Reading'!O8)*1000 -> 220
A7: Maldives at Kuda Huraa | B7: =B6+1 -> 6 | C7: 2 | D7: 2023 | E7: =('Kwh Reading'!S10-'Kwh Reading'!S9)*1000 -> 500 | F7: =('Kwh Reading'!F10-'Kwh Reading'!F9)*1000000 -> 2600 | G7: =('Kwh Reading'!C10-'Kwh Reading'!C9)*1000 -> 250 | H7: =I7+J7+K7 -> 1220 | I7: =('Kwh Reading'!J10-'Kwh Reading'!J9)*1000 -> 590 | J7: =('Kwh Reading'!K10-'Kwh Reading'!K9)*1000 -> 320 | K7: =('Kwh Reading'!L10-'Kwh Reading'!L9)*1000 -> 310 | L7: =('Kwh Reading'!R10-'Kwh Reading'!R9) -> 130.4 | M7: =('Kwh Reading'!I10-'Kwh Reading'!I9)*1000 -> 290 | N7: =('Kwh Reading'!B10-'Kwh Reading'!B9)*1000000 -> 1200 | O7: =('Kwh Reading'!M10-'Kwh Reading'!M9)*1000 -> 440 | P7: =('Kwh Reading'!H10-'Kwh Reading'!H9)*1000000 -> 600 | Q7: =('Kwh Reading'!P10-'Kwh Reading'!P9)*1000000 -> 500 | R7: =('Kwh Reading'!G10-'Kwh Reading'!G9)*1000000 -> 600 | S7: =('Kwh Reading'!Q10-'Kwh Reading'!Q9)*1000 -> 330 | T7: =('Kwh Reading'!N10-'Kwh Reading'!N9)*1000 -> 440 | U7: ='Kwh Reading'!E10-'Kwh Reading'!E9 -> 2554.58 | V7: ='Kwh Reading'!D10-'Kwh Reading'!D9 -> 1387.56 | W7: =('Kwh Reading'!O10-'Kwh Reading'!O9)*1000 -> 220
A8: Maldives at Kuda Huraa | B8: =B7+1 -> 7 | C8: 2 | D8: 2023 | E8: =('Kwh Reading'!S11-'Kwh Reading'!S10)*1000 -> 470 | F8: =('Kwh Reading'!F11-'Kwh Reading'!F10)*1000000 -> 2500 | G8: =('Kwh Reading'!C11-'Kwh Reading'!C10)*1000 -> 270 | H8: =I8+J8+K8 -> 1180 | I8: =('Kwh Reading'!J11-'Kwh Reading'!J10)*1000 -> 510 | J8: =('Kwh Reading'!K11-'Kwh Reading'!K10)*1000 -> 370 | K8: =('Kwh Reading'!L11-'Kwh Reading'!L10)*1000 -> 300 | L8: =('Kwh Reading'!R11-'Kwh Reading'!R10) -> 131.4 | M8: =('Kwh Reading'!I11-'Kwh Reading'!I10)*1000 -> 300 | N8: =('Kwh Reading'!B11-'Kwh Reading'!B10)*1000000 -> 1200 | O8: =('Kwh Reading'!M11-'Kwh Reading'!M10)*1000 -> 410 | P8: =('Kwh Reading'!H11-'Kwh Reading'!H10)*1000000 -> 600 | Q8: =('Kwh Reading'!P11-'Kwh Reading'!P10)*1000000 -> 600 | R8: =('Kwh Reading'!G11-'Kwh Reading'!G10)*1000000 -> 500 | S8: =('Kwh Reading'!Q11-'Kwh Reading'!Q10)*1000 -> 370 | T8: =('Kwh Reading'!N11-'Kwh Reading'!N10)*1000 -> 430 | U8: ='Kwh Reading'!E11-'Kwh Reading'!E10 -> 2307.03 | V8: ='Kwh Reading'!D11-'Kwh Reading'!D10 -> 1598.8 | W8: =('Kwh Reading'!O11-'Kwh Reading'!O10)*1000 -> 230
A9: Maldives at Kuda Huraa | B9: =B8+1 -> 8 | C9: 2 | D9: 2023 | E9: =('Kwh Reading'!S12-'Kwh Reading'!S11)*1000 -> 470 | F9: =('Kwh Reading'!F12-'Kwh Reading'!F11)*1000000 -> 2600 | G9: =('Kwh Reading'!C12-'Kwh Reading'!C11)*1000 -> 250 | H9: =I9+J9+K9 -> 1200 | I9: =('Kwh Reading'!J12-'Kwh Reading'!J11)*1000 -> 540 | J9: =('Kwh Reading'!K12-'Kwh Reading'!K11)*1000 -> 360 | K9: =('Kwh Reading'!L12-'Kwh Reading'!L11)*1000 -> 300 | L9: =('Kwh Reading'!R12-'Kwh Reading'!R11) -> 133.5 | M9: =('Kwh Reading'!I12-'Kwh Reading'!I11)*1000 -> 300 | N9: =('Kwh Reading'!B12-'Kwh Reading'!B11)*1000000 -> 1100 | O9: =('Kwh Reading'!M12-'Kwh Reading'!M11)*1000 -> 440 | P9: =('Kwh Reading'!H12-'Kwh Reading'!H11)*1000000 -> 600 | Q9: =('Kwh Reading'!P12-'Kwh Reading'!P11)*1000000 -> 500 | R9: =('Kwh Reading'!G12-'Kwh Reading'!G11)*1000000 -> 500 | S9: =('Kwh Reading'!Q12-'Kwh Reading'!Q11)*1000 -> 400 | T9: =('Kwh Reading'!N12-'Kwh Reading'!N11)*1000 -> 380 | U9: ='Kwh Reading'!E12-'Kwh Reading'!E11 -> 2296.28 | V9: ='Kwh Reading'!D12-'Kwh Reading'!D11 -> 1699.82 | W9: =('Kwh Reading'!O12-'Kwh Reading'!O11)*1000 -> 240
A10: Maldives at Kuda Huraa | B10: =B9+1 -> 9 | C10: 2 | D10: 2023 | E10: =('Kwh Reading'!S13-'Kwh Reading'!S12)*1000 -> 470 | F10: =('Kwh Reading'!F13-'Kwh Reading'!F12)*1000000 -> 2600 | G10: =('Kwh Reading'!C13-'Kwh Reading'!C12)*1000 -> 250 | H10: =I10+J10+K10 -> 1030 | I10: =('Kwh Reading'!J13-'Kwh Reading'!J12)*1000 -> 480 | J10: =('Kwh Reading'!K13-'Kwh Reading'!K12)*1000 -> 290 | K10: =('Kwh Reading'!L13-'Kwh Reading'!L12)*1000 -> 260 | L10: =('Kwh Reading'!R13-'Kwh Reading'!R12) -> 130.2 | M10: =('Kwh Reading'!I13-'Kwh Reading'!I12)*1000 -> 280 | N10: =('Kwh Reading'!B13-'Kwh Reading'!B12)*1000000 -> 1100 | O10: =('Kwh Reading'!M13-'Kwh Reading'!M12)*1000 -> 400 | P10: =('Kwh Reading'!H13-'Kwh Reading'!H12)*1000000 -> 600 | Q10: =('Kwh Reading'!P13-'Kwh Reading'!P12)*1000000 -> 600 | R10: =('Kwh Reading'!G13-'Kwh Reading'!G12)*1000000 -> 500 | S10: =('Kwh Reading'!Q13-'Kwh Reading'!Q12)*1000 -> 380 | T10: =('Kwh Reading'!N13-'Kwh Reading'!N12)*1000 -> 330 | U10: ='Kwh Reading'!E13-'Kwh Reading'!E12 -> 2323.25 | V10: ='Kwh Reading'!D13-'Kwh Reading'!D12 -> 1512.66 | W10: =('Kwh Reading'!O13-'Kwh Reading'!O12)*1000 -> 210
A11: Maldives at Kuda Huraa | B11: =B10+1 -> 10 | C11: 2 | D11: 2023 | E11: =('Kwh Reading'!S14-'Kwh Reading'!S13)*1000 -> 450 | F11: =('Kwh Reading'!F14-'Kwh Reading'!F13)*1000000 -> 2500 | G11: =('Kwh Reading'!C14-'Kwh Reading'!C13)*1000 -> 240 | H11: =I11+J11+K11 -> 940 | I11: =('Kwh Reading'!J14-'Kwh Reading'!J13)*1000 -> 390 | J11: =('Kwh Reading'!K14-'Kwh Reading'!K13)*1000 -> 280 | K11: =('Kwh Reading'!L14-'Kwh Reading'!L13)*1000 -> 270 | L11: =('Kwh Reading'!R14-'Kwh Reading'!R13) -> 125.8 | M11: =('Kwh Reading'!I14-'Kwh Reading'!I13)*1000 -> 270 | N11: =('Kwh Reading'!B14-'Kwh Reading'!B13)*1000000 -> 1100 | O11: =('Kwh Reading'!M14-'Kwh Reading'!M13)*1000 -> 450 | P11: =('Kwh Reading'!H14-'Kwh Reading'!H13)*1000000 -> 500 | Q11: =('Kwh Reading'!P14-'Kwh Reading'!P13)*1000000 -> 500 | R11: =('Kwh Reading'!G14-'Kwh Reading'!G13)*1000000 -> 500 | S11: =('Kwh Reading'!Q14-'Kwh Reading'!Q13)*1000 -> 360 | T11: =('Kwh Reading'!N14-'Kwh Reading'!N13)*1000 -> 350 | U11: ='Kwh Reading'!E14-'Kwh Reading'!E13 -> 2327.61 | V11: ='Kwh Reading'!D14-'Kwh Reading'!D13 -> 1515 | W11: =('Kwh Reading'!O14-'Kwh Reading'!O13)*1000 -> 250
A12: Maldives at Kuda Huraa | B12: =B11+1 -> 11 | C12: 2 | D12: 2023 | E12: =('Kwh Reading'!S15-'Kwh Reading'!S14)*1000 -> 440 | F12: =('Kwh Reading'!F15-'Kwh Reading'!F14)*1000000 -> 2600 | G12: =('Kwh Reading'!C15-'Kwh Reading'!C14)*1000 -> 270 | H12: =I12+J12+K12 -> 1140 | I12: =('Kwh Reading'!J15-'Kwh Reading'!J14)*1000 -> 540 | J12: =('Kwh Reading'!K15-'Kwh Reading'!K14)*1000 -> 290 | K12: =('Kwh Reading'!L15-'Kwh Reading'!L14)*1000 -> 310 | L12: =('Kwh Reading'!R15-'Kwh Reading'!R14) -> 130.2 | M12: =('Kwh Reading'!I15-'Kwh Reading'!I14)*1000 -> 270 | N12: =('Kwh Reading'!B15-'Kwh Reading'!B14)*1000000 -> 1100 | O12: =('Kwh Reading'!M15-'Kwh Reading'!M14)*1000 -> 460 | P12: =('Kwh Reading'!H15-'Kwh Reading'!H14)*1000000 -> 600 | Q12: =('Kwh Reading'!P15-'Kwh Reading'!P14)*1000000 -> 500 | R12: =('Kwh Reading'!G15-'Kwh Reading'!G14)*1000000 -> 600 | S12: =('Kwh Reading'!Q15-'Kwh Reading'!Q14)*1000 -> 430 | T12: =('Kwh Reading'!N15-'Kwh Reading'!N14)*1000 -> 410 | U12: ='Kwh Reading'!E15-'Kwh Reading'!E14 -> 2048 | V12: ='Kwh Reading'!D15-'Kwh Reading'!D14 -> 1511 | W12: =('Kwh Reading'!O15-'Kwh Reading'!O14)*1000 -> 270
A13: Maldives at Kuda Huraa | B13: =B12+1 -> 12 | C13: 2 | D13: 2023 | E13: =('Kwh Reading'!S16-'Kwh Reading'!S15)*1000 -> 490 | F13: =('Kwh Reading'!F16-'Kwh Reading'!F15)*1000000 -> 2500 | G13: =('Kwh Reading'!C16-'Kwh Reading'!C15)*1000 -> 270 | H13: =I13+J13+K13 -> 1170 | I13: =('Kwh Reading'!J16-'Kwh Reading'!J15)*1000 -> 560 | J13: =('Kwh Reading'!K16-'Kwh Reading'!K15)*1000 -> 330 | K13: =('Kwh Reading'!L16-'Kwh Reading'!L15)*1000 -> 280 | L13: =('Kwh Reading'!R16-'Kwh Reading'!R15) -> 122.3 | M13: =('Kwh Reading'!I16-'Kwh Reading'!I15)*1000 -> 250 | N13: =('Kwh Reading'!B16-'Kwh Reading'!B15)*1000000 -> 1100 | O13: =('Kwh Reading'!M16-'Kwh Reading'!M15)*1000 -> 400 | P13: =('Kwh Reading'!H16-'Kwh Reading'!H15)*1000000 -> 600 | Q13: =('Kwh Reading'!P16-'Kwh Reading'!P15)*1000000 -> 500 | R13: =('Kwh Reading'!G16-'Kwh Reading'!G15)*1000000 -> 500 | S13: =('Kwh Reading'!Q16-'Kwh Reading'!Q15)*1000 -> 390 | T13: =('Kwh Reading'!N16-'Kwh Reading'!N15)*1000 -> 380 | U13: ='Kwh Reading'!E16-'Kwh Reading'!E15 -> 2393.91 | V13: ='Kwh Reading'!D16-'Kwh Reading'!D15 -> 1582.2 | W13: =('Kwh Reading'!O16-'Kwh Reading'!O15)*1000 -> 250
A14: Maldives at Kuda Huraa | B14: =B13+1 -> 13 | C14: 2 | D14: 2023 | E14: =('Kwh Reading'!S17-'Kwh Reading'!S16)*1000 -> 530 | F14: =('Kwh Reading'!F17-'Kwh Reading'!F16)*1000000 -> 2600 | G14: =('Kwh Reading'!C17-'Kwh Reading'!C16)*1000 -> 240 | H14: =I14+J14+K14 -> 1210 | I14: =('Kwh Reading'!J17-'Kwh Reading'!J16)*1000 -> 660 | J14: =('Kwh Reading'!K17-'Kwh Reading'!K16)*1000 -> 250 | K14: =('Kwh Reading'!L17-'Kwh Reading'!L16)*1000 -> 300 | L14: =('Kwh Reading'!R17-'Kwh Reading'!R16) -> 124.5 | M14: =('Kwh Reading'!I17-'Kwh Reading'!I16)*1000 -> 260 | N14: =('Kwh Reading'!B17-'Kwh Reading'!B16)*1000000 -> 1100 | O14: =('Kwh Reading'!M17-'Kwh Reading'!M16)*1000 -> 440 | P14: =('Kwh Reading'!H17-'Kwh Reading'!H16)*1000000 -> 600 | Q14: =('Kwh Reading'!P17-'Kwh Reading'!P16)*1000000 -> 500 | R14: =('Kwh Reading'!G17-'Kwh Reading'!G16)*1000000 -> 600 | S14: =('Kwh Reading'!Q17-'Kwh Reading'!Q16)*1000 -> 370 | T14: =('Kwh Reading'!N17-'Kwh Reading'!N16)*1000 -> 420 | U14: ='Kwh Reading'!E17-'Kwh Reading'!E16 -> 2300.77 | V14: ='Kwh Reading'!D17-'Kwh Reading'!D16 -> 1557.78 | W14: =('Kwh Reading'!O17-'Kwh Reading'!O16)*1000 -> 250
... A32: Maldives at Kuda Huraa | B32: =B31+1 -> 31 | C32: 2 | D32: 2023 | E32: =('Kwh Reading'!S35-'Kwh Reading'!S34)*1000 -> 0 | F32: =('Kwh Reading'!F35-'Kwh Reading'!F34)*1000000 -> 0 | G32: =('Kwh Reading'!C35-'Kwh Reading'!C34)*1000 -> 0 | H32: =I32+J32+K32 -> 0 | I32: =('Kwh Reading'!J35-'Kwh Reading'!J34)*1000 -> 0 | J32: =('Kwh Reading'!K35-'Kwh Reading'!K34)*1000 -> 0 | K32: =('Kwh Reading'!L35-'Kwh Reading'!L34)*1000 -> 0 | L32: =('Kwh Reading'!R35-'Kwh Reading'!R34) -> 0 | M32: =('Kwh Reading'!I35-'Kwh Reading'!I34)*1000 -> 0 | N32: =('Kwh Reading'!B35-'Kwh Reading'!B34)*1000000 -> 0 | O32: =('Kwh Reading'!M35-'Kwh Reading'!M34)*1000 -> 0 | P32: =('Kwh Reading'!H35-'Kwh Reading'!H34)*1000000 -> 0 | Q32: =('Kwh Reading'!P35-'Kwh Reading'!P34)*1000000 -> 0 | R32: =('Kwh Reading'!G35-'Kwh Reading'!G34)*1000000 -> 0 | S32: =('Kwh Reading'!Q35-'Kwh Reading'!Q34)*1000 -> 0 | T32: =('Kwh Reading'!N35-'Kwh Reading'!N34)*1000 -> 0 | U32: ='Kwh Reading'!E35-'Kwh Reading'!E34 -> 0 | V32: ='Kwh Reading'!D35-'Kwh Reading'!D34 -> 0 | W32: =('Kwh Reading'!O35-'Kwh Reading'!O34)*1000 -> 0
A33: Total | E33: =SUM(E2:E31) -> -702400 | F33: =SUM(F2:F31) -> -3888200 | G33: =SUM(G2:G31) -> -376250 | I33: =SUM(I2:I31) -> -591270 | J33: =SUM(J2:J31) -> -538330 | K33: =SUM(K2:K31) -> -376480 | L33: =SUM(L2:L31) -> -23868.5 | M33: =SUM(M2:M31) -> -409130 | N33: =SUM(N2:N31) -> -1635300 | O33: =SUM(O2:O31) -> -901700 | P33: =SUM(P2:P31) -> -1128300 | ... W33: =SUM(W2:W31) -> -276480

Sheet Kwh Reading
A1: Electric Consumption Record (4pm)
A2: Month | B2: BOH-1/ B&C Block GWH | C2: Pastry MWH | D2: Feeder 401-419 KWH | E2: Feeder 301-319 KWH | F2: Kitchen GWH | G2: Feeder 201-208 GWH | H2: Feeder 113-123 | I2: M - Block /PC MWH | J2: Laundry MWH | M2: Feeder 101-112 MWH | N2: Feeder 217-224 | O2: Spa MWH | P2: Feeder 124-134 | Q2: Feeder 209-216 | R2: STP -1 MWH | S2: Reef Club MWH | U2: Room Nights | V2: Total Guests | W2: Food Covers
J3: A | K3: B | L3: C
A4: 44958 | B4: 1.6353 | C4: 376.25 | D4: 182986.33 | E4: 9721330.7 | F4: 3.8882 | G4: 1.1969 | H4: 1.1283 | I4: 409.13 | J4: 591.27 | K4: 538.33 | L4: 376.48 | M4: 901.7 | N4: 814.13 | O4: 276.48 | P4: 1.091 | Q4: 790.64 | R4: 23868.5 | S4: 702.4
A5: 44959 | B5: 1.6364 | C5: 376.51 | D5: 184683.53 | E5: 9723746.2 | F5: 3.8907 | G5: 1.1974 | H5: 1.129 | I5: 409.42 | J5: 591.71 | K5: 538.7 | L5: 376.81 | M5: 902.07 | N5: 814.52 | O5: 276.7 | P5: 1.0915 | Q5: 790.93 | R5: 24002.7 | S5: 702.88
A6: 44960 | B6: 1.6375 | C6: 376.78 | D6: 186350.8 | E6: 9726108.9 | F6: 3.8932 | G6: 1.1979 | H6: 1.1296 | I6: 409.75 | J6: 592.15 | K6: 538.97 | L6: 377.1 | M6: 902.47 | N6: 814.97 | O6: 276.93 | P6: 1.092 | Q6: 791.23 | R6: 24134 | S6: 703.41
A7: 44961 | B7: 1.6386 | C7: 377.02 | D7: 187993.97 | E7: 9728451.5 | F7: 3.8958 | G7: 1.1984 | H7: 1.1302 | I7: 410.04 | J7: 592.6 | K7: 539.26 | L7: 377.38 | M7: 902.92 | N7: 815.42 | O7: 277.16 | P7: 1.0925 | Q7: 791.56 | R7: 24266.8 | S7: 703.82
A8: 44962 | B8: 1.6398 | C8: 377.27 | D8: 189621.14 | E8: 9730426.1 | F8: 3.8984 | G8: 1.1989 | H8: 1.1308 | I8: 410.34 | J8: 593.03 | K8: 539.53 | L8: 377.66 | M8: 903.35 | N8: 815.86 | O8: 277.41 | P8: 1.093 | Q8: 791.91 | R8: 24401.6 | S8: 704.15
A9: 44963 | B9: 1.6409 | C9: 377.52 | D9: 191258.16 | E9: 9733203.2 | F9: 3.901 | G9: 1.1995 | H9: 1.1314 | I9: 410.65 | J9: 593.56 | K9: 539.84 | L9: 377.95 | M9: 903.8 | N9: 816.29 | O9: 277.63 | P9: 1.0934 | Q9: 792.26 | R9: 24531.3 | S9: 704.7
A10: 44964 | B10: 1.6421 | C10: 377.77 | D10: 192645.72 | E10: 9735757.8 | F10: 3.9036 | G10: 1.2001 | H10: 1.132 | I10: 410.94 | J10: 594.15 | K10: 540.16 | L10: 378.26 | M10: 904.24 | N10: 816.73 | O10: 277.85 | P10: 1.0939 | Q10: 792.59 | R10: 24661.7 | S10: 705.2
A11: 44965 | B11: 1.6433 | C11: 378.04 | D11: 194244.52 | E11: 9738064.9 | F11: 3.9061 | G11: 1.2006 | H11: 1.1326 | I11: 411.24 | J11: 594.66 | K11: 540.53 | L11: 378.56 | M11: 904.65 | N11: 817.16 | O11: 278.08 | P11: 1.0945 | Q11: 792.96 | R11: 24793.1 | S11: 705.67
A12: 44966 | B12: 1.6444 | C12: 378.29 | D12: 195944.34 | E12: 9740361.1 | F12: 3.9087 | G12: 1.2011 | H12: 1.1332 | I12: 411.54 | J12: 595.2 | K12: 540.89 | L12: 378.86 | M12: 905.09 | N12: 817.54 | O12: 278.32 | P12: 1.095 | Q12: 793.36 | R12: 24926.6 | S12: 706.14
A13: 44967 | B13: 1.6455 | C13: 378.54 | D13: 197457 | E13: 9742684.4 | F13: 3.9113 | G13: 1.2016 | H13: 1.1338 | I13: 411.82 | J13: 595.68 | K13: 541.18 | L13: 379.12 | M13: 905.49 | N13: 817.87 | O13: 278.53 | P13: 1.0956 | Q13: 793.74 | R13: 25056.8 | S13: 706.61
A14: 44968 | B14: 1.6466 | C14: 378.78 | D14: 198972 | E14: 9745012 | F14: 3.9138 | G14: 1.2021 | H14: 1.1343 | I14: 412.09 | J14: 596.07 | K14: 541.46 | L14: 379.39 | M14: 905.94 | N14: 818.22 | O14: 278.78 | P14: 1.0961 | Q14: 794.1 | R14: 25182.6 | S14: 707.06
A15: 44969 | B15: 1.6477 | C15: 379.05 | D15: 200483 | E15: 9747060 | F15: 3.9164 | G15: 1.2027 | H15: 1.1349 | I15: 412.36 | J15: 596.61 | K15: 541.75 | L15: 379.7 | M15: 906.4 | N15: 818.63 | O15: 279.05 | P15: 1.0966 | Q15: 794.53 | R15: 25312.8 | S15: 707.5
... A23: 44977 | B23: 1.6565 | C23: 380.98 | D23: 213866.3 | E23: 9766300.5 | F23: 3.9371 | G23: 1.2079 | H23: 1.1398 | I23: 414.6 | J23: 601.83 | K23: 544.61 | L23: 382.14 | M23: 910.17 | N23: 822.16 | O23: 281.16 | P23: 1.1006 | Q23: 797.5 | R23: 26363.9 | S23: 711.57
A24: 44978 | R24: 0
A25: 44979 | R25: 0
A26: 44980 | R26: 0
A27: 44981 | R27: 0
A28: 44982 | R28: 0
A29: 44983 | R29: 0
A30: 44984 | R30: 0
A31: 44985 | R31: 0
A32: 44986 | R32: 0
A33: 44987 | R33: 0
A34: 44988 | R34: 0 | U34: =SUM(U4:U33) -> 0 | V34: =SUM(V4:V33) -> 0 | W34: =SUM(W4:W33) -> 0
A35: 44989 | R35: 0
S41: ……..

Sheet Kwh area wise 
A2: Month | B2: Total KWH | C2: Reef Club Kitchen KWH | D2: Main Kitchen KWH | E2: Pastry Kitchen KWH | F2: Laundry KWH | G2: STP KWH | H2: Kuda Huraa Accomodation KWH | I2: Guest Room Beach Pavilion & Beach Bungalow KWH | J2: Guest Room Water Bungalow KWH | K2: Spa KWH | L2: Others KWH
A3: ='Kwh Reading'!A4 -> 44958 | B3: =TOTAL!E2 -> 18540 | C3: ='Kwh area wise '!E3 -> 260 | D3: =Submeters!F2 -> 2500 | E3: =Submeters!G2 -> 260 | F3: =(Submeters!I2+Submeters!J2+Submeters!K2) -> 1140 | G3: =Submeters!L2 -> 134.2 | H3: =(Submeters!M2+Submeters!N2) -> 1390 | I3: =(Submeters!O2+Submeters!P2+Submeters!Q2+Submeters!R2+Submeters!S2+Submeters!T2) -> 2750 | J3: =(Submeters!U2+Submeters!V2) -> 4112.7 | K3: =Submeters!W2 -> 220 | L3: =B3-C3-D3-E3-F3-G3-H3-I3-J3-K3 -> 5773.1
A4: ='Kwh Reading'!A5 -> 44959 | B4: =TOTAL!E3 -> 18450 | C4: =Submeters!E3 -> 530 | D4: =Submeters!F3 -> 2500 | E4: =Submeters!G3 -> 270 | F4: =(Submeters!I3+Submeters!J3+Submeters!K3) -> 1000 | G4: =Submeters!L3 -> 131.3 | H4: =(Submeters!M3+Submeters!N3) -> 1430 | I4: =(Submeters!O3+Submeters!P3+Submeters!Q3+Submeters!R3+Submeters!S3+Submeters!T3) -> 2750 | J4: =(Submeters!U3+Submeters!V3) -> 4030.07 | K4: =Submeters!W3 -> 230 | L4: =B4-C4-D4-E4-F4-G4-H4-I4-J4-K4 -> 5578.63
A5: ='Kwh Reading'!A6 -> 44960 | B5: =TOTAL!E4 -> 18760 | C5: =Submeters!E4 -> 410 | D5: =Submeters!F4 -> 2600 | E5: =Submeters!G4 -> 240 | F5: =(Submeters!I4+Submeters!J4+Submeters!K4) -> 1020 | G5: =Submeters!L4 -> 132.8 | H5: =(Submeters!M4+Submeters!N4) -> 1390 | I5: =(Submeters!O4+Submeters!P4+Submeters!Q4+Submeters!R4+Submeters!S4+Submeters!T4) -> 2830 | J5: =(Submeters!U4+Submeters!V4) -> 3985.68 | K5: =Submeters!W4 -> 230 | L5: =B5-C5-D5-E5-F5-G5-H5-I5-J5-K5 -> 5921.52
A6: ='Kwh Reading'!A7 -> 44961 | B6: =TOTAL!E5 -> 18030 | C6: =Submeters!E5 -> 330 | D6: =Submeters!F5 -> 2600 | E6: =Submeters!G5 -> 250 | F6: =(Submeters!I5+Submeters!J5+Submeters!K5) -> 980 | G6: =Submeters!L5 -> 134.8 | H6: =(Submeters!M5+Submeters!N5) -> 1500 | I6: =(Submeters!O5+Submeters!P5+Submeters!Q5+Submeters!R5+Submeters!S5+Submeters!T5) -> 2820 | J6: =(Submeters!U5+Submeters!V5) -> 3601.81 | K6: =Submeters!W5 -> 250 | L6: =B6-C6-D6-E6-F6-G6-H6-I6-J6-K6 -> 5563.39
A7: ='Kwh Reading'!A8 -> 44962 | B7: =TOTAL!E6 -> 18980 | C7: =Submeters!E6 -> 550 | D7: =Submeters!F6 -> 2600 | E7: =Submeters!G6 -> 250 | F7: =(Submeters!I6+Submeters!J6+Submeters!K6) -> 1130 | G7: =Submeters!L6 -> 129.7 | H7: =(Submeters!M6+Submeters!N6) -> 1410 | I7: =(Submeters!O6+Submeters!P6+Submeters!Q6+Submeters!R6+Submeters!S6+Submeters!T6) -> 2830 | J7: =(Submeters!U6+Submeters!V6) -> 4414.17 | K7: =Submeters!W6 -> 220 | L7: =B7-C7-D7-E7-F7-G7-H7-I7-J7-K7 -> 5446.13
A8: ='Kwh Reading'!A9 -> 44963 | B8: =TOTAL!E7 -> 19650 | C8: =Submeters!E7 -> 500 | D8: =Submeters!F7 -> 2600 | E8: =Submeters!G7 -> 250 | F8: =(Submeters!I7+Submeters!J7+Submeters!K7) -> 1220 | G8: =Submeters!L7 -> 130.4 | H8: =(Submeters!M7+Submeters!N7) -> 1490 | I8: =(Submeters!O7+Submeters!P7+Submeters!Q7+Submeters!R7+Submeters!S7+Submeters!T7) -> 2910 | J8: =(Submeters!U7+Submeters!V7) -> 3942.14 | K8: =Submeters!W7 -> 220 | L8: =B8-C8-D8-E8-F8-G8-H8-I8-J8-K8 -> 6387.46
A9: ='Kwh Reading'!A10 -> 44964 | B9: =TOTAL!E8 -> 18610 | C9: =Submeters!E8 -> 470 | D9: =Submeters!F8 -> 2500 | E9: =Submeters!G8 -> 270 | F9: =(Submeters!I8+Submeters!J8+Submeters!K8) -> 1180 | G9: =Submeters!L8 -> 131.4 | H9: =(Submeters!M8+Submeters!N8) -> 1500 | I9: =(Submeters!O8+Submeters!P8+Submeters!Q8+Submeters!R8+Submeters!S8+Submeters!T8) -> 2910 | J9: =(Submeters!U8+Submeters!V8) -> 3905.83 | K9: =Submeters!W8 -> 230 | L9: =B9-C9-D9-E9-F9-G9-H9-I9-J9-K9 -> 5512.77
A10: ='Kwh Reading'!A11 -> 44965 | B10: =TOTAL!E9 -> 18950 | C10: =Submeters!E9 -> 470 | D10: =Submeters!F9 -> 2600 | E10: =Submeters!G9 -> 250 | F10: =(Submeters!I9+Submeters!J9+Submeters!K9) -> 1200 | G10: =Submeters!L9 -> 133.5 | H10: =(Submeters!M9+Submeters!N9) -> 1400 | I10: =(Submeters!O9+Submeters!P9+Submeters!Q9+Submeters!R9+Submeters!S9+Submeters!T9) -> 2820 | J10: =(Submeters!U9+Submeters!V9) -> 3996.1 | K10: =Submeters!W9 -> 240 | L10: =B10-C10-D10-E10-F10-G10-H10-I10-J10-K10 -> 5840.4
A11: ='Kwh Reading'!A12 -> 44966 | B11: =TOTAL!E10 -> 18280 | C11: =Submeters!E10 -> 470 | D11: =Submeters!F10 -> 2600 | E11: =Submeters!G10 -> 250 | F11: =(Submeters!I10+Submeters!J10+Submeters!K10) -> 1030 | G11: =Submeters!L10 -> 130.2 | H11: =(Submeters!M10+Submeters!N10) -> 1380 | I11: =(Submeters!O10+Submeters!P10+Submeters!Q10+Submeters!R10+Submeters!S10+Submeters!T10) -> 2810 | J11: =(Submeters!U10+Submeters!V10) -> 3835.91 | K11: =Submeters!W10 -> 210 | L11: =B11-C11-D11-E11-F11-G11-H11-I11-J11-K11 -> 5563.89
A12: ='Kwh Reading'!A13 -> 44967 | B12: =TOTAL!E11 -> 18440 | C12: =Submeters!E11 -> 450 | D12: =Submeters!F11 -> 2500 | E12: =Submeters!G11 -> 240 | F12: =(Submeters!I11+Submeters!J11+Submeters!K11) -> 940 | G12: =Submeters!L11 -> 125.8 | H12: =(Submeters!M11+Submeters!N11) -> 1370 | I12: =(Submeters!O11+Submeters!P11+Submeters!Q11+Submeters!R11+Submeters!S11+Submeters!T11) -> 2660 | J12: =(Submeters!U11+Submeters!V11) -> 3842.61 | K12: =Submeters!W11 -> 250 | L12: =B12-C12-D12-E12-F12-G12-H12-I12-J12-K12 -> 6061.59
A13: ='Kwh Reading'!A14 -> 44968 | B13: =TOTAL!E12 -> 17980 | C13: =Submeters!E12 -> 440 | D13: =Submeters!F12 -> 2600 | E13: =Submeters!G12 -> 270 | F13: =(Submeters!I12+Submeters!J12+Submeters!K12) -> 1140 | G13: =Submeters!L12 -> 130.2 | H13: =(Submeters!M12+Submeters!N12) -> 1370 | I13: =(Submeters!O12+Submeters!P12+Submeters!Q12+Submeters!R12+Submeters!S12+Submeters!T12) -> 3000 | J13: =(Submeters!U12+Submeters!V12) -> 3559 | K13: =Submeters!W12 -> 270 | L13: =B13-C13-D13-E13-F13-G13-H13-I13-J13-K13 -> 5200.8
A14: ='Kwh Reading'!A15 -> 44969 | B14: =TOTAL!E13 -> 18260 | C14: =Submeters!E13 -> 490 | D14: =Submeters!F13 -> 2500 | E14: =Submeters!G13 -> 270 | F14: =(Submeters!I13+Submeters!J13+Submeters!K13) -> 1170 | G14: =Submeters!L13 -> 122.3 | H14: =(Submeters!M13+Submeters!N13) -> 1350 | I14: =(Submeters!O13+Submeters!P13+Submeters!Q13+Submeters!R13+Submeters!S13+Submeters!T13) -> 2770 | J14: =(Submeters!U13+Submeters!V13) -> 3976.11 | K14: =Submeters!W13 -> 250 | L14: =B14-C14-D14-E14-F14-G14-H14-I14-J14-K14 -> 5361.59
A15: ='Kwh Reading'!A16 -> 44970 | B15: =TOTAL!E14 -> 19210 | C15: =Submeters!E14 -> 530 | D15: =Submeters!F14 -> 2600 | E15: =Submeters!G14 -> 240 | F15: =(Submeters!I14+Submeters!J14+Submeters!K14) -> 1210 | G15: =Submeters!L14 -> 124.5 | H15: =(Submeters!M14+Submeters!N14) -> 1360 | I15: =(Submeters!O14+Submeters!P14+Submeters!Q14+Submeters!R14+Submeters!S14+Submeters!T14) -> 2930 | J15: =(Submeters!U14+Submeters!V14) -> 3858.55 | K15: =Submeters!W14 -> 250 | L15: =B15-C15-D15-E15-F15-G15-H15-I15-J15-K15 -> 6106.95
... A30: ='Kwh Reading'!A31 -> 44985 | B30: =TOTAL!E29 -> 0 | C30: =Submeters!E29 -> 0 | D30: =Submeters!F29 -> 0 | E30: =Submeters!G29 -> 0 | F30: =(Submeters!I29+Submeters!J29+Submeters!K29) -> 0 | G30: =Submeters!L29 -> 0 | H30: =(Submeters!M29+Submeters!N29) -> 0 | I30: =(Submeters!O29+Submeters!P29+Submeters!Q29+Submeters!R29+Submeters!S29+Submeters!T29) -> 0 | J30: =(Submeters!U29+Submeters!V29) -> 0 | K30: =Submeters!W29 -> 0 | L30: =B30-C30-D30-E30-F30-G30-H30-I30-J30-K30 -> 0
A31: Total kwh | B31: =SUM(B3:B30) -> 360050 | C31: =SUM(C3:C30) -> -702620 | D31: =SUM(D3:D30) -> -3888200 | E31: =SUM(E3:E30) -> -376250 | F31: =SUM(F3:F30) -> -1506080 | G31: =SUM(G3:G30) -> -23868.5 | H31: =SUM(H3:H30) -> -2044430 | I31: =SUM(I3:I30) -> -5922670 | ... L31: =SUM(L3:L30) -> 25004965 | M31: =C31+D31+E31+F31+G31+H31+I31+J31+K31+L31 -> 360050
A33: Total $ | B33: =TOTAL!F2 -> 0 | C33: =C31*B33 -> 0 | D33: =D31*B33 -> 0 | E33: =E31*B33 -> 0 | F33: =F31*B33 -> 0 | G33: =G31*B33 -> 0 | H33: =H31*B33 -> 0 | I33: =I31*B33 -> 0 | J33: =J31*B33 -> 0 | K33: =K31*B33 -> 0 | L33: =L31*B33 -> 0 | M33: =C33+D33+E33+F33+G33+H33+I33+J33+K33+L33 -> 0

Sheet  Kwh area wise $ 
A2: Month | B2: $ /Per KWH | C2: Total $ | D2: Reef Club $ | E2: Kitchen $ | F2: Pastry $ | G2: Laundry $ | H2: STP $ | I2: Kuda Huraa Accomodation $ | J2: Guest Room Beach Pavilion & Beach Bungalow $ | K2: Guest Room Water Bungalow $ | L2: Spa $ | M2: Others $
A3: ='Kwh Reading'!A4 -> 44958 | B3: =TOTAL!F2 -> 0 | C3: =D3+E3+F3+G3+H3=I3+J3+K3+L3+M3 -> #REF! | D3: =Submeters!E2*' Kwh area wise $ '!B3 -> 0 | E3: =Submeters!F2*' Kwh area wise $ '!B3 -> 0 | F3: =Submeters!G2*' Kwh area wise $ '!B3 -> 0 | G3: =(Submeters!I2+Submeters!J2+Submeters!K2)*' Kwh area wise $ '!B3 -> 0 | H3: =(Submeters!L2)*' Kwh area wise $ '!B3 -> 0 | I3: =(Submeters!M2+Submeters!N2)*' Kwh area wise $ '!B3 -> 0 | J3: =(Submeters!O2+Submeters!P2+Submeters!Q2+Submeters!R2+Submeters!S2+Submeters!T2)*' Kwh area wise $ '!B3 -> 0 | K3: =(Submeters!U2+Submeters!V2)*' Kwh area wise $ '!B3 -> 0 | L3: =Submeters!W2*' Kwh area wise $ '!B3 -> 0 | M3: =Submeters!#REF!*' Kwh area wise $ '!B3 -> #REF!
A4: ='Kwh Reading'!A5 -> 44959 | B4: =TOTAL!F3 -> 0 | C4: =D4+E4+F4+G4+H4=I4+J4+K4+L4+M4 -> #REF! | D4: =Submeters!E3*' Kwh area wise $ '!B4 -> 0 | E4: =Submeters!F3*' Kwh area wise $ '!B4 -> 0 | F4: =Submeters!G3*' Kwh area wise $ '!B4 -> 0 | G4: =(Submeters!I3+Submeters!J3+Submeters!K3)*' Kwh area wise $ '!B4 -> 0 | H4: =(Submeters!L3)*' Kwh area wise $ '!B4 -> 0 | I4: =(Submeters!M3+Submeters!N3)*' Kwh area wise $ '!B4 -> 0 | J4: =(Submeters!O3+Submeters!P3+Submeters!Q3+Submeters!R3+Submeters!S3+Submeters!T3)*' Kwh area wise $ '!B4 -> 0 | K4: =(Submeters!U3+Submeters!V3)*' Kwh area wise $ '!B4 -> 0 | L4: =Submeters!W3*' Kwh area wise $ '!B4 -> 0 | M4: =Submeters!#REF!*' Kwh area wise $ '!B4 -> #REF!
A5: ='Kwh Reading'!A6 -> 44960 | B5: =TOTAL!F4 -> 0 | C5: =D5+E5+F5+G5+H5=I5+J5+K5+L5+M5 -> #REF! | D5: =Submeters!E4*' Kwh area wise $ '!B5 -> 0 | E5: =Submeters!F4*' Kwh area wise $ '!B5 -> 0 | F5: =Submeters!G4*' Kwh area wise $ '!B5 -> 0 | G5: =(Submeters!I4+Submeters!J4+Submeters!K4)*' Kwh area wise $ '!B5 -> 0 | H5: =(Submeters!L4)*' Kwh area wise $ '!B5 -> 0 | I5: =(Submeters!M4+Submeters!N4)*' Kwh area wise $ '!B5 -> 0 | J5: =(Submeters!O4+Submeters!P4+Submeters!Q4+Submeters!R4+Submeters!S4+Submeters!T4)*' Kwh area wise $ '!B5 -> 0 | K5: =(Submeters!U4+Submeters!V4)*' Kwh area wise $ '!B5 -> 0 | L5: =Submeters!W4*' Kwh area wise $ '!B5 -> 0 | M5: =Submeters!#REF!*' Kwh area wise $ '!B5 -> #REF!
A6: ='Kwh Reading'!A7 -> 44961 | B6: =TOTAL!F5 -> 0 | C6: =D6+E6+F6+G6+H6=I6+J6+K6+L6+M6 -> #REF! | D6: =Submeters!E5*' Kwh area wise $ '!B6 -> 0 | E6: =Submeters!F5*' Kwh area wise $ '!B6 -> 0 | F6: =Submeters!G5*' Kwh area wise $ '!B6 -> 0 | G6: =(Submeters!I5+Submeters!J5+Submeters!K5)*' Kwh area wise $ '!B6 -> 0 | H6: =(Submeters!L5)*' Kwh area wise $ '!B6 -> 0 | I6: =(Submeters!M5+Submeters!N5)*' Kwh area wise $ '!B6 -> 0 | J6: =(Submeters!O5+Submeters!P5+Submeters!Q5+Submeters!R5+Submeters!S5+Submeters!T5)*' Kwh area wise $ '!B6 -> 0 | K6: =(Submeters!U5+Submeters!V5)*' Kwh area wise $ '!B6 -> 0 | L6: =Submeters!W5*' Kwh area wise $ '!B6 -> 0 | M6: =Submeters!#REF!*' Kwh area wise $ '!B6 -> #REF!
A7: ='Kwh Reading'!A8 -> 44962 | B7: =TOTAL!F6 -> 0 | C7: =D7+E7+F7+G7+H7=I7+J7+K7+L7+M7 -> #REF! | D7: =Submeters!E6*' Kwh area wise $ '!B7 -> 0 | E7: =Submeters!F6*' Kwh area wise $ '!B7 -> 0 | F7: =Submeters!G6*' Kwh area wise $ '!B7 -> 0 | G7: =(Submeters!I6+Submeters!J6+Submeters!K6)*' Kwh area wise $ '!B7 -> 0 | H7: =(Submeters!L6)*' Kwh area wise $ '!B7 -> 0 | I7: =(Submeters!M6+Submeters!N6)*' Kwh area wise $ '!B7 -> 0 | J7: =(Submeters!O6+Submeters!P6+Submeters!Q6+Submeters!R6+Submeters!S6+Submeters!T6)*' Kwh area wise $ '!B7 -> 0 | K7: =(Submeters!U6+Submeters!V6)*' Kwh area wise $ '!B7 -> 0 | L7: =Submeters!W6*' Kwh area wise $ '!B7 -> 0 | M7: =Submeters!#REF!*' Kwh area wise $ '!B7 -> #REF!
A8: ='Kwh Reading'!A9 -> 44963 | B8: =TOTAL!F7 -> 0 | C8: =D8+E8+F8+G8+H8=I8+J8+K8+L8+M8 -> #REF! | D8: =Submeters!E7*' Kwh area wise $ '!B8 -> 0 | E8: =Submeters!F7*' Kwh area wise $ '!B8 -> 0 | F8: =Submeters!G7*' Kwh area wise $ '!B8 -> 0 | G8: =(Submeters!I7+Submeters!J7+Submeters!K7)*' Kwh area wise $ '!B8 -> 0 | H8: =(Submeters!L7)*' Kwh area wise $ '!B8 -> 0 | I8: =(Submeters!M7+Submeters!N7)*' Kwh area wise $ '!B8 -> 0 | J8: =(Submeters!O7+Submeters!P7+Submeters!Q7+Submeters!R7+Submeters!S7+Submeters!T7)*' Kwh area wise $ '!B8 -> 0 | K8: =(Submeters!U7+Submeters!V7)*' Kwh area wise $ '!B8 -> 0 | L8: =Submeters!W7*' Kwh area wise $ '!B8 -> 0 | M8: =Submeters!#REF!*' Kwh area wise $ '!B8 -> #REF!
A9: ='Kwh Reading'!A10 -> 44964 | B9: =TOTAL!F8 -> 0 | C9: =D9+E9+F9+G9+H9=I9+J9+K9+L9+M9 -> #REF! | D9: =Submeters!E8*' Kwh area wise $ '!B9 -> 0 | E9: =Submeters!F8*' Kwh area wise $ '!B9 -> 0 | F9: =Submeters!G8*' Kwh area wise $ '!B9 -> 0 | G9: =(Submeters!I8+Submeters!J8+Submeters!K8)*' Kwh area wise $ '!B9 -> 0 | H9: =(Submeters!L8)*' Kwh area wise $ '!B9 -> 0 | I9: =(Submeters!M8+Submeters!N8)*' Kwh area wise $ '!B9 -> 0 | J9: =(Submeters!O8+Submeters!P8+Submeters!Q8+Submeters!R8+Submeters!S8+Submeters!T8)*' Kwh area wise $ '!B9 -> 0 | K9: =(Submeters!U8+Submeters!V8)*' Kwh area wise $ '!B9 -> 0 | L9: =Submeters!W8*' Kwh area wise $ '!B9 -> 0 | M9: =Submeters!#REF!*' Kwh area wise $ '!B9 -> #REF!
A10: ='Kwh Reading'!A11 -> 44965 | B10: =TOTAL!F9 -> 0 | C10: =D10+E10+F10+G10+H10=I10+J10+K10+L10+M10 -> #REF! | D10: =Submeters!E9*' Kwh area wise $ '!B10 -> 0 | E10: =Submeters!F9*' Kwh area wise $ '!B10 -> 0 | F10: =Submeters!G9*' Kwh area wise $ '!B10 -> 0 | G10: =(Submeters!I9+Submeters!J9+Submeters!K9)*' Kwh area wise $ '!B10 -> 0 | H10: =(Submeters!L9)*' Kwh area wise $ '!B10 -> 0 | I10: =(Submeters!M9+Submeters!N9)*' Kwh area wise $ '!B10 -> 0 | J10: =(Submeters!O9+Submeters!P9+Submeters!Q9+Submeters!R9+Submeters!S9+Submeters!T9)*' Kwh area wise $ '!B10 -> 0 | K10: =(Submeters!U9+Submeters!V9)*' Kwh area wise $ '!B10 -> 0 | L10: =Submeters!W9*' Kwh area wise $ '!B10 -> 0 | M10: =Submeters!#REF!*' Kwh area wise $ '!B10 -> #REF!
A11: ='Kwh Reading'!A12 -> 44966 | B11: =TOTAL!F10 -> 0 | C11: =D11+E11+F11+G11+H11=I11+J11+K11+L11+M11 -> #REF! | D11: =Submeters!E10*' Kwh area wise $ '!B11 -> 0 | E11: =Submeters!F10*' Kwh area wise $ '!B11 -> 0 | F11: =Submeters!G10*' Kwh area wise $ '!B11 -> 0 | G11: =(Submeters!I10+Submeters!J10+Submeters!K10)*' Kwh area wise $ '!B11 -> 0 | H11: =(Submeters!L10)*' Kwh area wise $ '!B11 -> 0 | I11: =(Submeters!M10+Submeters!N10)*' Kwh area wise $ '!B11 -> 0 | J11: =(Submeters!O10+Submeters!P10+Submeters!Q10+Submeters!R10+Submeters!S10+Submeters!T10)*' Kwh area wise $ '!B11 -> 0 | K11: =(Submeters!U10+Submeters!V10)*' Kwh area wise $ '!B11 -> 0 | L11: =Submeters!W10*' Kwh area wise $ '!B11 -> 0 | M11: =Submeters!#REF!*' Kwh area wise $ '!B11 -> #REF!
A12: ='Kwh Reading'!A13 -> 44967 | B12: =TOTAL!F11 -> 0 | C12: =D12+E12+F12+G12+H12=I12+J12+K12+L12+M12 -> #REF! | D12: =Submeters!E11*' Kwh area wise $ '!B12 -> 0 | E12: =Submeters!F11*' Kwh area wise $ '!B12 -> 0 | F12: =Submeters!G11*' Kwh area wise $ '!B12 -> 0 | G12: =(Submeters!I11+Submeters!J11+Submeters!K11)*' Kwh area wise $ '!B12 -> 0 | H12: =(Submeters!L11)*' Kwh area wise $ '!B12 -> 0 | I12: =(Submeters!M11+Submeters!N11)*' Kwh area wise $ '!B12 -> 0 | J12: =(Submeters!O11+Submeters!P11+Submeters!Q11+Submeters!R11+Submeters!S11+Submeters!T11)*' Kwh area wise $ '!B12 -> 0 | K12: =(Submeters!U11+Submeters!V11)*' Kwh area wise $ '!B12 -> 0 | L12: =Submeters!W11*' Kwh area wise $ '!B12 -> 0 | M12: =Submeters!#REF!*' Kwh area wise $ '!B12 -> #REF!
A13: ='Kwh Reading'!A14 -> 44968 | B13: =TOTAL!F12 -> 0 | C13: =D13+E13+F13+G13+H13=I13+J13+K13+L13+M13 -> #REF! | D13: =Submeters!E12*' Kwh area wise $ '!B13 -> 0 | E13: =Submeters!F12*' Kwh area wise $ '!B13 -> 0 | F13: =Submeters!G12*' Kwh area wise $ '!B13 -> 0 | G13: =(Submeters!I12+Submeters!J12+Submeters!K12)*' Kwh area wise $ '!B13 -> 0 | H13: =(Submeters!L12)*' Kwh area wise $ '!B13 -> 0 | I13: =(Submeters!M12+Submeters!N12)*' Kwh area wise $ '!B13 -> 0 | J13: =(Submeters!O12+Submeters!P12+Submeters!Q12+Submeters!R12+Submeters!S12+Submeters!T12)*' Kwh area wise $ '!B13 -> 0 | K13: =(Submeters!U12+Submeters!V12)*' Kwh area wise $ '!B13 -> 0 | L13: =Submeters!W12*' Kwh area wise $ '!B13 -> 0 | M13: =Submeters!#REF!*' Kwh area wise $ '!B13 -> #REF!
A14: ='Kwh Reading'!A15 -> 44969 | B14: =TOTAL!F13 -> 0 | C14: =D14+E14+F14+G14+H14=I14+J14+K14+L14+M14 -> #REF! | D14: =Submeters!E13*' Kwh area wise $ '!B14 -> 0 | E14: =Submeters!F13*' Kwh area wise $ '!B14 -> 0 | F14: =Submeters!G13*' Kwh area wise $ '!B14 -> 0 | G14: =(Submeters!I13+Submeters!J13+Submeters!K13)*' Kwh area wise $ '!B14 -> 0 | H14: =(Submeters!L13)*' Kwh area wise $ '!B14 -> 0 | I14: =(Submeters!M13+Submeters!N13)*' Kwh area wise $ '!B14 -> 0 | J14: =(Submeters!O13+Submeters!P13+Submeters!Q13+Submeters!R13+Submeters!S13+Submeters!T13)*' Kwh area wise $ '!B14 -> 0 | K14: =(Submeters!U13+Submeters!V13)*' Kwh area wise $ '!B14 -> 0 | L14: =Submeters!W13*' Kwh area wise $ '!B14 -> 0 | M14: =Submeters!#REF!*' Kwh area wise $ '!B14 -> #REF!
... A30: ='Kwh Reading'!A31 -> 44985 | B30: =TOTAL!F29 -> 0 | C30: =D30+E30+F30+G30+H30=I30+J30+K30+L30+M30 -> #REF! | D30: =Submeters!E29*' Kwh area wise $ '!B30 -> 0 | E30: =Submeters!F29*' Kwh area wise $ '!B30 -> 0 | F30: =Submeters!G29*' Kwh area wise $ '!B30 -> 0 | G30: =(Submeters!I29+Submeters!J29+Submeters!K29)*' Kwh area wise $ '!B30 -> 0 | H30: =(Submeters!L29)*' Kwh area wise $ '!B30 -> 0 | I30: =(Submeters!M29+Submeters!N29)*' Kwh area wise $ '!B30 -> 0 | J30: =(Submeters!O29+Submeters!P29+Submeters!Q29+Submeters!R29+Submeters!S29+Submeters!T29)*' Kwh area wise $ '!B30 -> 0 | K30: =(Submeters!U29+Submeters!V29)*' Kwh area wise $ '!B30 -> 0 | L30: =Submeters!W29*' Kwh area wise $ '!B30 -> 0 | M30: =Submeters!#REF!*' Kwh area wise $ '!B30 -> #REF!
A31: Total | C31: =SUM(C3:C30) -> #REF! | D31: =SUM(D3:D30) -> 0 | E31: =SUM(E3:E30) -> 0 | F31: =SUM(F3:F30) -> 0 | G31: =SUM(G3:G30) -> 0 | H31: =SUM(H3:H30) -> 0 | I31: =SUM(I3:I30) -> 0 | J31: =SUM(J3:J30) -> 0 | ... M31: =SUM(M3:M30) -> #REF! | N31: =D31+E31+F31+G31+H31+I31+J31+K31+L31+M31 -> #REF!

Sheet Water Reading
B1: Meter 1 | C1: Meter 2 | D1: Meter 6 | E1: Meter 8 | F1: Meter 7 | G1: Meter 9 | H1: Meter 3 | I1: Meter 5 | J1: Meter 10 | K1: Meter 13 | L1: Meter 16 | M1: Meter 17 | N1: Meter 15 | O1: Meter 14 | P1: Meter 4 | Q1: Meter 11 | R1: Meter 12 | S1: Meter 18
A2: Date | B2: Main Meter 1 | C2: Main Meter 2 | D2: Beach Bunglow | E2: Kuda Huraa staff | F2: Bodu hura staff | G2: Laundry | H2: Water Bunglow | I2: Main Kitchen | J2: Second stage | K2: Supply jetty | L2: Staff housing A | M2: Staff housing B | N2: Spa | O2: Staff jetty | P2: Main pool | Q2: Reef club pool | R2: Reef club kitchen | S2: STP Product
A3: 44958 | B3: 31326 | C3: 48552 | D3: 306913 | E3: 288985 | F3: 27275 | G3: 125667 | H3: 1786 | I3: 80875 | J3: 24278 | K3: 1024 | L3: 1967 | M3: 28964 | N3: 9184 | O3: 2550 | P3: 33374 | Q3: 2526 | R3: 1159 | S3: 67037
A4: 44959 | B4: 31433 | C4: 48745 | D4: 307032 | E4: 289064 | F4: 27305 | G4: 125692 | H4: 1821 | I4: 80882 | J4: 24284 | K4: 1024 | L4: 19700 | M4: 28970 | N4: 9190 | O4: 2552 | P4: 33388 | Q4: 2537 | R4: 1162 | S4: 67157
A5: 44960 | B5: 31544 | C5: 48944 | D5: 307157 | E5: 289137 | F5: 27332 | G5: 125713 | H5: 1851 | I5: 80910 | J5: 24290 | K5: 1024 | L5: 19703 | M5: 28977 | N5: 9193 | O5: 2553 | P5: 33409 | Q5: 2544 | R5: 1167 | S5: 67261
A6: 44961 | B6: 31646 | C6: 49128 | D6: 307269 | E6: 289210 | F6: 27361 | G6: 125736 | H6: 1887 | I6: 80917 | J6: 24296 | K6: 1024 | L6: 19706 | M6: 28981 | N6: 9197 | O6: 2555 | P6: 33412 | Q6: 2545 | R6: 1171 | S6: 67364
A7: 44962 | B7: 31774 | C7: 49357 | D7: 307430 | E7: 289287 | F7: 27393 | G7: 125757 | H7: 1917 | I7: 80952 | J7: 24302 | K7: 1024 | L7: 19709 | M7: 28985 | N7: 9199 | O7: 2557 | P7: 33439 | Q7: 2554 | R7: 1172 | S7: 67497
A8: 44963 | B8: 31897 | C8: 49577 | D8: 307583 | E8: 289362 | F8: 27424 | G8: 125780 | H8: 1957 | I8: 80970 | J8: 24308 | K8: 1024 | L8: 19712 | M8: 28991 | N8: 9202 | O8: 2559 | P8: 33453 | Q8: 2559 | R8: 1178 | S8: 67612
A9: 44964 | B9: 32037 | C9: 49820 | D9: 307769 | E9: 289443 | F9: 27458 | G9: 125806 | H9: 1985 | I9: 80994 | J9: 24314 | K9: 1024 | L9: 19715 | M9: 28998 | N9: 9206 | O9: 2561 | P9: 33473 | Q9: 2567 | R9: 1180 | S9: 67720
A10: 44965 | B10: 32177 | C10: 50067 | D10: 307944 | E10: 289515 | F10: 27480 | G10: 125830 | H10: 2051 | I10: 81013 | J10: 24320 | K10: 1024 | L10: 19718 | M10: 29004 | N10: 9208 | O10: 2564 | P10: 33488 | Q10: 2569 | R10: 1185 | S10: 67831
A11: 44966 | B11: 32309 | C11: 50305 | D11: 308121 | E11: 289588 | F11: 27516 | G11: 125855 | H11: 2084 | I11: 81041 | J11: 24326 | K11: 1024 | L11: 19722 | M11: 29012 | N11: 9211 | O11: 2566 | P11: 33511 | Q11: 2578 | R11: 1188 | S11: 67942
A12: 44967 | B12: 32436 | C12: 50530 | D12: 308298 | E12: 289659 | F12: 27543 | G12: 125879 | H12: 2113 | I12: 81059 | J12: 24332 | K12: 1024 | L12: 19735 | M12: 29018 | N12: 9214 | O12: 2567 | P12: 33525 | Q12: 2588 | R12: 1190 | S12: 68060
A13: 44968 | B13: 32549 | C13: 50737 | D13: 308428 | E13: 289731 | F13: 27574 | G13: 125901 | H13: 2146 | I13: 81083 | J13: 24339 | K13: 1024 | L13: 19747 | M13: 29024 | N13: 9218 | O13: 2568 | P13: 33527 | Q13: 2588 | R13: 1193 | S13: 68165
A14: 44969 | B14: 32673 | C14: 50957 | D14: 308599 | E14: 289812 | F14: 27605 | G14: 125926 | H14: 2170 | I14: 81085 | J14: 24345 | K14: 1024 | L14: 19758 | M14: 29030 | N14: 9222 | O14: 2570 | P14: 33539 | Q14: 2596 | R14: 1197 | S14: 68275
... A22: 44977 | B22: 33756 | C22: 52877 | D22: 310017 | E22: 290420 | F22: 27859 | G22: 126149 | H22: 2429 | I22: 81215 | J22: 24400 | K22: 1024 | L22: 19757 | M22: 29076 | N22: 9248 | O22: 2588 | P22: 33648 | Q22: 2626 | R22: 1232 | S22: 68655
A23: 44978
A24: 44979
A25: 44980
A26: 44981
A27: 44982
A28: 44983
A29: 44984
A30: 44985
A31: 44986

Sheet Water consumption
A2: Date | B2: RO production (Ro 1 : 4) | C2: Total Consumption M3 (Meter 1 : 2) | E2: Water Bunglow | G2: Beach bunglow | I2: Main Pool | K2: Main kitchen | M2: Reef club kitchen | O2: Reef club pool | Q2: Bodu Huraa staff | S2: Kuda Huraa staff | U2: Laundry | W2: Second stage | Y2: Total | AA2: Total STP product
C3: M3 | D3: % of Total production | E3: M3 | F3: % | G3: M3 | H3: % | I3: M3 | J3: % | K3: M3 | L3: % | M3: M3 | N3: % | O3: M3 | P3: % | Q3: M3 | R3: % | S3: M3 | T3: % | U3: M3 | V3: % | W3: M3 | X3: % | Y3: M3 | Z3: % | AA3: M3 | AB3: %
A4: ='Water Reading'!A3 -> 44958 | B4: =TOTAL!I2 -> 301 | C4: =('Water Reading'!B4-'Water Reading'!B3)+('Water Reading'!C4-'Water Reading'!C3) -> 300 | D4: =C4/B4 -> 0.99667774 | E4: ='Water Reading'!H4-'Water Reading'!H3 -> 35 | F4: =E4/C4 -> 0.11666667 | G4: =('Water Reading'!D4-'Water Reading'!D3)-('Water Reading'!R4-'Water Reading'!R3)-('Water Reading'!Q4-'Water Reading'!Q3) -> 105 | H4: =G4/C4 -> 0.35 | I4: ='Water Reading'!P4-'Water Reading'!P3 -> 14 | J4: =I4/C4 -> 0.046666667 | K4: =('Water Reading'!I4-'Water Reading'!I3)-('Water Reading'!P4-'Water Reading'!P3) -> -7 | L4: =K4/C4 -> -0.023333333 | M4: ='Water Reading'!R4-'Water Reading'!R3 -> 3 | N4: =M4/C4 -> 0.01 | O4: ='Water Reading'!Q4-'Water Reading'!Q3 -> 11 | P4: =O4/C4 -> 0.036666667 | Q4: ='Water Reading'!F4-'Water Reading'!F3 -> 30 | R4: =Q4/C4 -> 0.1 | S4: ='Water Reading'!E4-'Water Reading'!E3 -> 79 | T4: =S4/C4 -> 0.26333333 | U4: ='Water Reading'!G4-'Water Reading'!G3 -> 25 | V4: =U4/C4 -> 0.083333333 | W4: ='Water Reading'!J4-'Water Reading'!J3 -> 6 | X4: =W4/C4 -> 0.02 | Y4: =E4+I4+K4+M4+O4+G4+Q4+S4+U4+W4 -> 301 | Z4: =Y4/B4 -> 1 | AA4: ='Water Reading'!S4-'Water Reading'!S3 -> 120 | AB4: =AA4/C4 -> 0.4
A5: ='Water Reading'!A4 -> 44959 | B5: =TOTAL!I3 -> 310 | C5: =('Water Reading'!B5-'Water Reading'!B4)+('Water Reading'!C5-'Water Reading'!C4) -> 310 | D5: =C5/B5 -> 1 | E5: ='Water Reading'!H5-'Water Reading'!H4 -> 30 | F5: =E5/C5 -> 0.096774194 | G5: =('Water Reading'!D5-'Water Reading'!D4)-('Water Reading'!R5-'Water Reading'!R4)-('Water Reading'!Q5-'Water Reading'!Q4) -> 113 | H5: =G5/C5 -> 0.36451613 | I5: ='Water Reading'!P5-'Water Reading'!P4 -> 21 | J5: =I5/C5 -> 0.067741935 | K5: =('Water Reading'!I5-'Water Reading'!I4)-('Water Reading'!P5-'Water Reading'!P4) -> 7 | L5: =K5/C5 -> 0.022580645 | M5: ='Water Reading'!R5-'Water Reading'!R4 -> 5 | N5: =M5/C5 -> 0.016129032 | O5: ='Water Reading'!Q5-'Water Reading'!Q4 -> 7 | P5: =O5/C5 -> 0.022580645 | Q5: ='Water Reading'!F5-'Water Reading'!F4 -> 27 | R5: =Q5/C5 -> 0.087096774 | S5: ='Water Reading'!E5-'Water Reading'!E4 -> 73 | T5: =S5/C5 -> 0.23548387 | U5: ='Water Reading'!G5-'Water Reading'!G4 -> 21 | V5: =U5/C5 -> 0.067741935 | W5: ='Water Reading'!J5-'Water Reading'!J4 -> 6 | X5: =W5/C5 -> 0.019354839 | Y5: =E5+I5+K5+M5+O5+G5+Q5+S5+U5+W5 -> 310 | Z5: =Y5/B5 -> 1 | AA5: ='Water Reading'!S5-'Water Reading'!S4 -> 104 | AB5: =AA5/C5 -> 0.33548387
A6: ='Water Reading'!A5 -> 44960 | B6: =TOTAL!I4 -> 286 | C6: =('Water Reading'!B6-'Water Reading'!B5)+('Water Reading'!C6-'Water Reading'!C5) -> 286 | D6: =C6/B6 -> 1 | E6: ='Water Reading'!H6-'Water Reading'!H5 -> 36 | F6: =E6/C6 -> 0.12587413 | G6: =('Water Reading'!D6-'Water Reading'!D5)-('Water Reading'!R6-'Water Reading'!R5)-('Water Reading'!Q6-'Water Reading'!Q5) -> 107 | H6: =G6/C6 -> 0.37412587 | I6: ='Water Reading'!P6-'Water Reading'!P5 -> 3 | J6: =I6/C6 -> 0.01048951 | K6: =('Water Reading'!I6-'Water Reading'!I5)-('Water Reading'!P6-'Water Reading'!P5) -> 4 | L6: =K6/C6 -> 0.013986014 | M6: ='Water Reading'!R6-'Water Reading'!R5 -> 4 | N6: =M6/C6 -> 0.013986014 | O6: ='Water Reading'!Q6-'Water Reading'!Q5 -> 1 | P6: =O6/C6 -> 0.0034965035 | Q6: ='Water Reading'!F6-'Water Reading'!F5 -> 29 | R6: =Q6/C6 -> 0.1013986 | S6: ='Water Reading'!E6-'Water Reading'!E5 -> 73 | T6: =S6/C6 -> 0.25524476 | U6: ='Water Reading'!G6-'Water Reading'!G5 -> 23 | V6: =U6/C6 -> 0.08041958 | W6: ='Water Reading'!J6-'Water Reading'!J5 -> 6 | X6: =W6/C6 -> 0.020979021 | Y6: =E6+I6+K6+M6+O6+G6+Q6+S6+U6+W6 -> 286 | Z6: =Y6/B6 -> 1 | AA6: ='Water Reading'!S6-'Water Reading'!S5 -> 103 | AB6: =AA6/C6 -> 0.36013986
A7: ='Water Reading'!A6 -> 44961 | B7: =TOTAL!I5 -> 362 | C7: =('Water Reading'!B7-'Water Reading'!B6)+('Water Reading'!C7-'Water Reading'!C6) -> 357 | D7: =C7/B7 -> 0.98618785 | E7: ='Water Reading'!H7-'Water Reading'!H6 -> 30 | F7: =E7/C7 -> 0.084033613 | G7: =('Water Reading'!D7-'Water Reading'!D6)-('Water Reading'!R7-'Water Reading'!R6)-('Water Reading'!Q7-'Water Reading'!Q6) -> 151 | H7: =G7/C7 -> 0.42296919 | I7: ='Water Reading'!P7-'Water Reading'!P6 -> 27 | J7: =I7/C7 -> 0.075630252 | K7: =('Water Reading'!I7-'Water Reading'!I6)-('Water Reading'!P7-'Water Reading'!P6) -> 8 | L7: =K7/C7 -> 0.022408964 | M7: ='Water Reading'!R7-'Water Reading'!R6 -> 1 | N7: =M7/C7 -> 0.0028011204 | O7: ='Water Reading'!Q7-'Water Reading'!Q6 -> 9 | P7: =O7/C7 -> 0.025210084 | Q7: ='Water Reading'!F7-'Water Reading'!F6 -> 32 | R7: =Q7/C7 -> 0.089635854 | S7: ='Water Reading'!E7-'Water Reading'!E6 -> 77 | T7: =S7/C7 -> 0.21568627 | U7: ='Water Reading'!G7-'Water Reading'!G6 -> 21 | V7: =U7/C7 -> 0.058823529 | W7: ='Water Reading'!J7-'Water Reading'!J6 -> 6 | X7: =W7/C7 -> 0.016806723 | Y7: =E7+I7+K7+M7+O7+G7+Q7+S7+U7+W7 -> 362 | Z7: =Y7/B7 -> 1 | AA7: ='Water Reading'!S7-'Water Reading'!S6 -> 133 | AB7: =AA7/C7 -> 0.37254902
A8: ='Water Reading'!A7 -> 44962 | B8: =TOTAL!I6 -> 346 | C8: =('Water Reading'!B8-'Water Reading'!B7)+('Water Reading'!C8-'Water Reading'!C7) -> 343 | D8: =C8/B8 -> 0.99132948 | E8: ='Water Reading'!H8-'Water Reading'!H7 -> 40 | F8: =E8/C8 -> 0.11661808 | G8: =('Water Reading'!D8-'Water Reading'!D7)-('Water Reading'!R8-'Water Reading'!R7)-('Water Reading'!Q8-'Water Reading'!Q7) -> 142 | H8: =G8/C8 -> 0.41399417 | I8: ='Water Reading'!P8-'Water Reading'!P7 -> 14 | J8: =I8/C8 -> 0.040816327 | K8: =('Water Reading'!I8-'Water Reading'!I7)-('Water Reading'!P8-'Water Reading'!P7) -> 4 | L8: =K8/C8 -> 0.011661808 | M8: ='Water Reading'!R8-'Water Reading'!R7 -> 6 | N8: =M8/C8 -> 0.017492711 | O8: ='Water Reading'!Q8-'Water Reading'!Q7 -> 5 | P8: =O8/C8 -> 0.014577259 | Q8: ='Water Reading'!F8-'Water Reading'!F7 -> 31 | R8: =Q8/C8 -> 0.090379009 | S8: ='Water Reading'!E8-'Water Reading'!E7 -> 75 | T8: =S8/C8 -> 0.21865889 | U8: ='Water Reading'!G8-'Water Reading'!G7 -> 23 | V8: =U8/C8 -> 0.067055394 | W8: ='Water Reading'!J8-'Water Reading'!J7 -> 6 | X8: =W8/C8 -> 0.017492711 | Y8: =E8+I8+K8+M8+O8+G8+Q8+S8+U8+W8 -> 346 | Z8: =Y8/B8 -> 1 | AA8: ='Water Reading'!S8-'Water Reading'!S7 -> 115 | AB8: =AA8/C8 -> 0.33527697
A9: ='Water Reading'!A8 -> 44963 | B9: =TOTAL!I7 -> 385 | C9: =('Water Reading'!B9-'Water Reading'!B8)+('Water Reading'!C9-'Water Reading'!C8) -> 383 | D9: =C9/B9 -> 0.99480519 | E9: ='Water Reading'!H9-'Water Reading'!H8 -> 28 | F9: =E9/C9 -> 0.07310705 | G9: =('Water Reading'!D9-'Water Reading'!D8)-('Water Reading'!R9-'Water Reading'!R8)-('Water Reading'!Q9-'Water Reading'!Q8) -> 176 | H9: =G9/C9 -> 0.45953003 | I9: ='Water Reading'!P9-'Water Reading'!P8 -> 20 | J9: =I9/C9 -> 0.052219321 | K9: =('Water Reading'!I9-'Water Reading'!I8)-('Water Reading'!P9-'Water Reading'!P8) -> 4 | L9: =K9/C9 -> 0.010443864 | M9: ='Water Reading'!R9-'Water Reading'!R8 -> 2 | N9: =M9/C9 -> 0.0052219321 | O9: ='Water Reading'!Q9-'Water Reading'!Q8 -> 8 | P9: =O9/C9 -> 0.020887728 | Q9: ='Water Reading'!F9-'Water Reading'!F8 -> 34 | R9: =Q9/C9 -> 0.088772846 | S9: ='Water Reading'!E9-'Water Reading'!E8 -> 81 | T9: =S9/C9 -> 0.21148825 | U9: ='Water Reading'!G9-'Water Reading'!G8 -> 26 | V9: =U9/C9 -> 0.067885117 | W9: ='Water Reading'!J9-'Water Reading'!J8 -> 6 | X9: =W9/C9 -> 0.015665796 | Y9: =E9+I9+K9+M9+O9+G9+Q9+S9+U9+W9 -> 385 | Z9: =Y9/B9 -> 1 | AA9: ='Water Reading'!S9-'Water Reading'!S8 -> 108 | AB9: =AA9/C9 -> 0.28198433
A10: ='Water Reading'!A9 -> 44964 | B10: =TOTAL!I8 -> 336 | C10: =('Water Reading'!B10-'Water Reading'!B9)+('Water Reading'!C10-'Water Reading'!C9) -> 387 | D10: =C10/B10 -> 1.1517857 | E10: 18 | F10: 0.061016949 | G10: =('Water Reading'!D10-'Water Reading'!D9)-('Water Reading'!R10-'Water Reading'!R9)-('Water Reading'!Q10-'Water Reading'!Q9) -> 168 | H10: =G10/C10 -> 0.43410853 | I10: ='Water Reading'!P10-'Water Reading'!P9 -> 15 | J10: =I10/C10 -> 0.03875969 | K10: =('Water Reading'!I10-'Water Reading'!I9)-('Water Reading'!P10-'Water Reading'!P9) -> 4 | L10: =K10/C10 -> 0.010335917 | M10: ='Water Reading'!R10-'Water Reading'!R9 -> 5 | N10: =M10/C10 -> 0.012919897 | O10: ='Water Reading'!Q10-'Water Reading'!Q9 -> 2 | P10: =O10/C10 -> 0.0051679587 | Q10: ='Water Reading'!F10-'Water Reading'!F9 -> 22 | R10: =Q10/C10 -> 0.056847545 | S10: ='Water Reading'!E10-'Water Reading'!E9 -> 72 | T10: =S10/C10 -> 0.18604651 | U10: ='Water Reading'!G10-'Water Reading'!G9 -> 24 | V10: =U10/C10 -> 0.062015504 | W10: ='Water Reading'!J10-'Water Reading'!J9 -> 6 | X10: =W10/C10 -> 0.015503876 | Y10: =E10+I10+K10+M10+O10+G10+Q10+S10+U10+W10 -> 336 | Z10: =Y10/B10 -> 1 | AA10: ='Water Reading'!S10-'Water Reading'!S9 -> 111 | AB10: =AA10/C10 -> 0.28682171
A11: ='Water Reading'!A10 -> 44965 | B11: =TOTAL!I9 -> 378 | C11: =('Water Reading'!B11-'Water Reading'!B10)+('Water Reading'!C11-'Water Reading'!C10) -> 370 | D11: =C11/B11 -> 0.97883598 | E11: ='Water Reading'!H11-'Water Reading'!H10 -> 33 | F11: =E11/C11 -> 0.089189189 | G11: =('Water Reading'!D11-'Water Reading'!D10)-('Water Reading'!R11-'Water Reading'!R10)-('Water Reading'!Q11-'Water Reading'!Q10) -> 165 | H11: =G11/C11 -> 0.44594595 | I11: ='Water Reading'!P11-'Water Reading'!P10 -> 23 | J11: =I11/C11 -> 0.062162162 | K11: =('Water Reading'!I11-'Water Reading'!I10)-('Water Reading'!P11-'Water Reading'!P10) -> 5 | L11: =K11/C11 -> 0.013513514 | M11: ='Water Reading'!R11-'Water Reading'!R10 -> 3 | N11: =M11/C11 -> 0.0081081081 | O11: ='Water Reading'!Q11-'Water Reading'!Q10 -> 9 | P11: =O11/C11 -> 0.024324324 | Q11: ='Water Reading'!F11-'Water Reading'!F10 -> 36 | R11: =Q11/C11 -> 0.097297297 | S11: ='Water Reading'!E11-'Water Reading'!E10 -> 73 | T11: =S11/C11 -> 0.1972973 | U11: ='Water Reading'!G11-'Water Reading'!G10 -> 25 | V11: =U11/C11 -> 0.067567568 | W11: ='Water Reading'!J11-'Water Reading'!J10 -> 6 | X11: =W11/C11 -> 0.016216216 | Y11: =E11+I11+K11+M11+O11+G11+Q11+S11+U11+W11 -> 378 | Z11: =Y11/B11 -> 1 | AA11: ='Water Reading'!S11-'Water Reading'!S10 -> 111 | AB11: =AA11/C11 -> 0.3
A12: ='Water Reading'!A11 -> 44966 | B12: =TOTAL!I10 -> 352 | C12: =('Water Reading'!B12-'Water Reading'!B11)+('Water Reading'!C12-'Water Reading'!C11) -> 352 | D12: =C12/B12 -> 1 | E12: ='Water Reading'!H12-'Water Reading'!H11 -> 29 | F12: =E12/C12 -> 0.082386364 | G12: =('Water Reading'!D12-'Water Reading'!D11)-('Water Reading'!R12-'Water Reading'!R11)-('Water Reading'!Q12-'Water Reading'!Q11) -> 165 | H12: =G12/C12 -> 0.46875 | I12: ='Water Reading'!P12-'Water Reading'!P11 -> 14 | J12: =I12/C12 -> 0.039772727 | K12: =('Water Reading'!I12-'Water Reading'!I11)-('Water Reading'!P12-'Water Reading'!P11) -> 4 | L12: =K12/C12 -> 0.011363636 | M12: ='Water Reading'!R12-'Water Reading'!R11 -> 2 | N12: =M12/C12 -> 0.0056818182 | O12: ='Water Reading'!Q12-'Water Reading'!Q11 -> 10 | P12: =O12/C12 -> 0.028409091 | Q12: ='Water Reading'!F12-'Water Reading'!F11 -> 27 | R12: =Q12/C12 -> 0.076704545 | S12: ='Water Reading'!E12-'Water Reading'!E11 -> 71 | T12: =S12/C12 -> 0.20170455 | U12: ='Water Reading'!G12-'Water Reading'!G11 -> 24 | V12: =U12/C12 -> 0.068181818 | W12: ='Water Reading'!J12-'Water Reading'!J11 -> 6 | X12: =W12/C12 -> 0.017045455 | Y12: =E12+I12+K12+M12+O12+G12+Q12+S12+U12+W12 -> 352 | Z12: =Y12/B12 -> 1 | AA12: ='Water Reading'!S12-'Water Reading'!S11 -> 118 | AB12: =AA12/C12 -> 0.33522727
A13: ='Water Reading'!A12 -> 44967 | B13: =TOTAL!I11 -> 319 | C13: =('Water Reading'!B13-'Water Reading'!B12)+('Water Reading'!C13-'Water Reading'!C12) -> 320 | D13: =C13/B13 -> 1.0031348 | E13: ='Water Reading'!H13-'Water Reading'!H12 -> 33 | F13: =E13/C13 -> 0.103125 | G13: =('Water Reading'!D13-'Water Reading'!D12)-('Water Reading'!R13-'Water Reading'!R12)-('Water Reading'!Q13-'Water Reading'!Q12) -> 127 | H13: =G13/C13 -> 0.396875 | I13: ='Water Reading'!P13-'Water Reading'!P12 -> 2 | J13: =I13/C13 -> 0.00625 | K13: =('Water Reading'!I13-'Water Reading'!I12)-('Water Reading'!P13-'Water Reading'!P12) -> 22 | L13: =K13/C13 -> 0.06875 | M13: ='Water Reading'!R13-'Water Reading'!R12 -> 3 | N13: =M13/C13 -> 0.009375 | O13: ='Water Reading'!Q13-'Water Reading'!Q12 -> 0 | P13: =O13/C13 -> 0 | Q13: ='Water Reading'!F13-'Water Reading'!F12 -> 31 | R13: =Q13/C13 -> 0.096875 | S13: ='Water Reading'!E13-'Water Reading'!E12 -> 72 | T13: =S13/C13 -> 0.225 | U13: ='Water Reading'!G13-'Water Reading'!G12 -> 22 | V13: =U13/C13 -> 0.06875 | W13: ='Water Reading'!J13-'Water Reading'!J12 -> 7 | X13: =W13/C13 -> 0.021875 | Y13: =E13+I13+K13+M13+O13+G13+Q13+S13+U13+W13 -> 319 | Z13: =Y13/B13 -> 1 | AA13: ='Water Reading'!S13-'Water Reading'!S12 -> 105 | AB13: =AA13/C13 -> 0.328125
A14: ='Water Reading'!A13 -> 44968 | B14: =TOTAL!I12 -> 340 | C14: =('Water Reading'!B14-'Water Reading'!B13)+('Water Reading'!C14-'Water Reading'!C13) -> 344 | D14: =C14/B14 -> 1.0117647 | E14: ='Water Reading'!H14-'Water Reading'!H13 -> 24 | F14: =E14/C14 -> 0.069767442 | G14: =('Water Reading'!D14-'Water Reading'!D13)-('Water Reading'!R14-'Water Reading'!R13)-('Water Reading'!Q14-'Water Reading'!Q13) -> 159 | H14: =G14/C14 -> 0.4622093 | I14: ='Water Reading'!P14-'Water Reading'!P13 -> 12 | J14: =I14/C14 -> 0.034883721 | K14: =('Water Reading'!I14-'Water Reading'!I13)-('Water Reading'!P14-'Water Reading'!P13) -> -10 | L14: =K14/C14 -> -0.029069767 | M14: ='Water Reading'!R14-'Water Reading'!R13 -> 4 | N14: =M14/C14 -> 0.011627907 | O14: ='Water Reading'!Q14-'Water Reading'!Q13 -> 8 | P14: =O14/C14 -> 0.023255814 | Q14: ='Water Reading'!F14-'Water Reading'!F13 -> 31 | R14: =Q14/C14 -> 0.090116279 | S14: ='Water Reading'!E14-'Water Reading'!E13 -> 81 | T14: =S14/C14 -> 0.23546512 | U14: ='Water Reading'!G14-'Water Reading'!G13 -> 25 | V14: =U14/C14 -> 0.072674419 | W14: ='Water Reading'!J14-'Water Reading'!J13 -> 6 | X14: =W14/C14 -> 0.01744186 | Y14: =E14+I14+K14+M14+O14+G14+Q14+S14+U14+W14 -> 340 | Z14: =Y14/B14 -> 1 | AA14: ='Water Reading'!S14-'Water Reading'!S13 -> 110 | AB14: =AA14/C14 -> 0.31976744
