Workbook

Sheet TOTAL
A1: Site Name | B1: Day | C1: Month | D1: Year | E1: Total Electricity Kwh | F1: Electricity Tariff ($/Kwh) | G1: LPG (Kg) | H1: LPG $/Kg | I1: Water Utility Supply (m3) m3 | J1: Water Utility Supply (m3) $/m3 | K1: Room Nights | L1: Food Covers
A2: Maldives at Landaa Giraavaru | B2: 1 | C2: 9 | D2: 2022 | E2: ='Maldives at LG Daily'!D5+'SOLAR METER READING'!D9 -> 22002 | F2: 0.832 | G2: ='Maldives at LG Daily'!E5 -> 270 | H2: 1.24 | I2: ='Maldives at LG Daily'!H5 -> 303 | J2: 0 | K2: ='Maldives at LG Daily'!I5 -> 13.6 | L2: ='Maldives at LG Daily'!J5 -> 102
A3: Maldives at Landaa Giraavaru | B3: 2 | C3: 9 | D3: 2022 | E3: ='Maldives at LG Daily'!D6+'SOLAR METER READING'!D10 -> 23410 | F3: 0.832 | G3: ='Maldives at LG Daily'!E6 -> 270 | H3: 1.24 | I3: ='Maldives at LG Daily'!H6 -> 320 | J3: 0 | K3: ='Maldives at LG Daily'!I6 -> 14.6 | L3: ='Maldives at LG Daily'!J6 -> 114
A4: Maldives at Landaa Giraavaru | B4: 3 | C4: 9 | D4: 2022 | E4: ='Maldives at LG Daily'!D7+'SOLAR METER READING'!D11 -> 23407 | F4: 0.832 | G4: ='Maldives at LG Daily'!E7 -> 225 | H4: 1.24 | I4: ='Maldives at LG Daily'!H7 -> 324 | J4: 0 | K4: ='Maldives at LG Daily'!I7 -> 14.6 | L4: ='Maldives at LG Daily'!J7 -> 169
A5: Maldives at Landaa Giraavaru | B5: 4 | C5: 9 | D5: 2022 | E5: ='Maldives at LG Daily'!D8+'SOLAR METER READING'!D12 -> 23591 | F5: 0.832 | G5: ='Maldives at LG Daily'!E8 -> 270 | H5: 1.24 | I5: ='Maldives at LG Daily'!H8 -> 299 | J5: 0 | K5: ='Maldives at LG Daily'!I8 -> 10.7 | L5: ='Maldives at LG Daily'!J8 -> 108
A6: Maldives at Landaa Giraavaru | B6: 5 | C6: 9 | D6: 2022 | E6: ='Maldives at LG Daily'!D9+'SOLAR METER READING'!D13 -> 21640 | F6: 0.832 | G6: ='Maldives at LG Daily'!E9 -> 225 | H6: 1.24 | I6: ='Maldives at LG Daily'!H9 -> 265 | J6: 0 | K6: ='Maldives at LG Daily'!I9 -> 10.7 | L6: ='Maldives at LG Daily'!J9 -> 106
A7: Maldives at Landaa Giraavaru | B7: 6 | C7: 9 | D7: 2022 | E7: ='Maldives at LG Daily'!D10+'SOLAR METER READING'!D14 -> 20706 | F7: 0.832 | G7: ='Maldives at LG Daily'!E10 -> 180 | H7: 1.24 | I7: ='Maldives at LG Daily'!H10 -> 303 | J7: 0 | K7: ='Maldives at LG Daily'!I10 -> 13.6 | L7: ='Maldives at LG Daily'!J10 -> 124
A8: Maldives at Landaa Giraavaru | B8: 7 | C8: 9 | D8: 2022 | E8: ='Maldives at LG Daily'!D11+'SOLAR METER READING'!D15 -> 23963 | F8: 0.832 | G8: ='Maldives at LG Daily'!E11 -> 315 | H8: 1.24 | I8: ='Maldives at LG Daily'!H11 -> 283 | J8: 0 | K8: ='Maldives at LG Daily'!I11 -> 13.6 | L8: ='Maldives at LG Daily'!J11 -> 133
A9: Maldives at Landaa Giraavaru | B9: 8 | C9: 9 | D9: 2022 | E9: ='Maldives at LG Daily'!D12+'SOLAR METER READING'!D16 -> 24491 | F9: 0.832 | G9: ='Maldives at LG Daily'!E12 -> 225 | H9: 1.24 | I9: ='Maldives at LG Daily'!H12 -> 288 | J9: 0 | K9: ='Maldives at LG Daily'!I12 -> 15 | L9: ='Maldives at LG Daily'!J12 -> 119
A10: Maldives at Landaa Giraavaru | B10: 9 | C10: 9 | D10: 2022 | E10: ='Maldives at LG Daily'!D13+'SOLAR METER READING'!D17 -> 24409 | F10: 0.832 | G10: ='Maldives at LG Daily'!E13 -> 225 | H10: 1.24 | I10: ='Maldives at LG Daily'!H13 -> 429 | J10: 0 | K10: ='Maldives at LG Daily'!I13 -> 12 | L10: ='Maldives at LG Daily'!J13 -> 105
A11: Maldives at Landaa Giraavaru | B11: 10 | C11: 9 | D11: 2022 | E11: ='Maldives at LG Daily'!D14+'SOLAR METER READING'!D18 -> 25409 | F11: 0.832 | G11: ='Maldives at LG Daily'!E14 -> 270 | H11: 1.24 | I11: ='Maldives at LG Daily'!H14 -> 199 | J11: 0 | K11: ='Maldives at LG Daily'!I14 -> 12 | L11: ='Maldives at LG Daily'!J14 -> 101
A12: Maldives at Landaa Giraavaru | B12: 11 | C12: 9 | D12: 2022 | E12: ='Maldives at LG Daily'!D15+'SOLAR METER READING'!D19 -> 25414 | F12: 0.832 | G12: ='Maldives at LG Daily'!E15 -> 225 | H12: 1.24 | I12: ='Maldives at LG Daily'!H15 -> 319 | J12: 0 | K12: ='Maldives at LG Daily'!I15 -> 11 | L12: ='Maldives at LG Daily'!J15 -> 80
A13: Maldives at Landaa Giraavaru | B13: 12 | C13: 9 | D13: 2022 | E13: ='Maldives at LG Daily'!D16+'SOLAR METER READING'!D20 -> 25673 | F13: 0.832 | G13: ='Maldives at LG Daily'!E16 -> 225 | H13: 1.24 | I13: ='Maldives at LG Daily'!H16 -> 302 | J13: 0 | K13: ='Maldives at LG Daily'!I16 -> 14 | L13: ='Maldives at LG Daily'!J16 -> 157
... A30: Maldives at Landaa Giraavaru | B30: 29 | C30: 9 | D30: 2022 | E30: ='Maldives at LG Daily'!D33+'SOLAR METER READING'!D37 -> 27325 | F30: 0.832 | G30: ='Maldives at LG Daily'!E33 -> 270 | H30: 1.24 | I30: ='Maldives at LG Daily'!H33 -> 373 | J30: 0 | K30: ='Maldives at LG Daily'!I33 -> 17.5 | L30: ='Maldives at LG Daily'!J33 -> 143
A31: Maldives at Landaa Giraavaru | B31: 30 | C31: 9 | D31: 2022 | E31: ='Maldives at LG Daily'!D34+'SOLAR METER READING'!D38 -> 23008 | F31: 0.832 | G31: ='Maldives at LG Daily'!E34 -> 225 | H31: 1.24 | I31: ='Maldives at LG Daily'!H35 -> 0 | J31: 0 | K31: ='Maldives at LG Daily'!I35 -> 0 | L31: ='Maldives at LG Daily'!J35 -> 0
E32: =SUM(E2:E31) -> 746484

Sheet Maldives at LG Daily
A2: Days | C2: Electricity Meter (KWh) | E2: Gas Kg | G2: Water m3
A3: Date | C3: Reading KWH | D3: Difference KWH | E3: Reading Kg | F3: Difference Kg | G3: Reading m³ | H3: Daily Consumption m³ | I3: ROOM NIGHTS | J3: Total Food Covers
A4: 44804 | C4: 102548445 | D4: 31701 | E4: ='Gas-2'!G5 -> 0 | F4: 90 | G4: =SUM(WATER!G6,WATER!L6,WATER!Q6,WATER!B6) -> 1137309 | H4: 318 | I4: 16 | J4: 116
A5: =A4+1 -> 44805 | C5: =SUM('GENSET #1'!C10+'GENSET #2'!C10+'GENSET #3'!C10+'GENSET #4'!C10+'GENSET #5'!C10) -> 102568553 | D5: =IF((C5-C4<0), "0",C5-C4) -> 20108 | E5: ='Gas-2'!G6 -> 270 | F5: =IF((E5-E4<0), "0",E5-E4) -> 270 | G5: =SUM(WATER!C6,WATER!H6,WATER!M6,WATER!R6) -> 1137612 | H5: =IF((G5-G4<0), "0",G5-G4) -> 303 | I5: 13.6 | J5: 102
A6: =A5+1 -> 44806 | C6: =SUM('GENSET #1'!C11+'GENSET #2'!C11+'GENSET #3'!C11+'GENSET #4'!C11+'GENSET #5'!C11) -> 102589189 | D6: =IF((C6-C5<0), "0",C6-C5) -> 20636 | E6: ='Gas-2'!G7 -> 270 | F6: =IF((E6-E5<0), "0",E6-E5) -> 0 | G6: =SUM(WATER!C7,WATER!H7,WATER!M7,WATER!R7) -> 1137932 | H6: =IF((G6-G5<0), "0",G6-G5) -> 320 | I6: 14.6 | J6: 114
A7: =A6+1 -> 44807 | C7: =SUM('GENSET #1'!C12+'GENSET #2'!C12+'GENSET #3'!C12+'GENSET #4'!C12+'GENSET #5'!C12) -> 102609785 | D7: =IF((C7-C6<0), "0",C7-C6) -> 20596 | E7: ='Gas-2'!G8 -> 225 | F7: =IF((E7-E6<0), "0",E7-E6) -> 0 | G7: =SUM(WATER!C8,WATER!H8,WATER!M8,WATER!R8) -> 1138256 | H7: =IF((G7-G6<0), "0",G7-G6) -> 324 | I7: 14.6 | J7: 169
A8: =A7+1 -> 44808 | C8: =SUM('GENSET #1'!C13+'GENSET #2'!C13+'GENSET #3'!C13+'GENSET #4'!C13+'GENSET #5'!C13) -> 102631267 | D8: =IF((C8-C7<0), "0",C8-C7) -> 21482 | E8: ='Gas-2'!G9 -> 270 | F8: =IF((E8-E7<0), "0",E8-E7) -> 45 | G8: =SUM(WATER!C9,WATER!H9,WATER!M9,WATER!R9) -> 1138555 | H8: =IF((G8-G7<0), "0",G8-G7) -> 299 | I8: 10.7 | J8: 108
A9: =A8+1 -> 44809 | C9: =SUM('GENSET #1'!C14+'GENSET #2'!C14+'GENSET #3'!C14+'GENSET #4'!C14+'GENSET #5'!C14) -> 102652028 | D9: =IF((C9-C8<0), "0",C9-C8) -> 20761 | E9: ='Gas-2'!G10 -> 225 | F9: =IF((E9-E8<0), "0",E9-E8) -> 0 | G9: =SUM(WATER!C10,WATER!H10,WATER!M10,WATER!R10) -> 1138820 | H9: =IF((G9-G8<0), "0",G9-G8) -> 265 | I9: 10.7 | J9: 106
A10: =A9+1 -> 44810 | C10: =SUM('GENSET #1'!C15+'GENSET #2'!C15+'GENSET #3'!C15+'GENSET #4'!C15+'GENSET #5'!C15) -> 102670963 | D10: =IF((C10-C9<0), "0",C10-C9) -> 18935 | E10: ='Gas-2'!G11 -> 180 | F10: =IF((E10-E9<0), "0",E10-E9) -> 0 | G10: =SUM(WATER!C11,WATER!H11,WATER!M11,WATER!R11) -> 1139123 | H10: =IF((G10-G9<0), "0",G10-G9) -> 303 | I10: 13.6 | J10: 124
A11: =A10+1 -> 44811 | C11: =SUM('GENSET #1'!C16+'GENSET #2'!C16+'GENSET #3'!C16+'GENSET #4'!C16+'GENSET #5'!C16) -> 102692349 | D11: =IF((C11-C10<0), "0",C11-C10) -> 21386 | E11: ='Gas-2'!G12 -> 315 | F11: =IF((E11-E10<0), "0",E11-E10) -> 135 | G11: =SUM(WATER!C12,WATER!H12,WATER!M12,WATER!R12) -> 1139406 | H11: =IF((G11-G10<0), "0",G11-G10) -> 283 | I11: 13.6 | J11: 133
A12: =A11+1 -> 44812 | C12: =SUM('GENSET #1'!C17+'GENSET #2'!C17+'GENSET #3'!C17+'GENSET #4'!C17+'GENSET #5'!C17) -> 102714033 | D12: =IF((C12-C11<0), "0",C12-C11) -> 21684 | E12: ='Gas-2'!G13 -> 225 | F12: =IF((E12-E11<0), "0",E12-E11) -> 0 | G12: =SUM(WATER!C13,WATER!H13,WATER!M13,WATER!R13) -> 1139694 | H12: =IF((G12-G11<0), "0",G12-G11) -> 288 | I12: 15 | J12: 119
A13: =A12+1 -> 44813 | C13: =SUM('GENSET #1'!C18+'GENSET #2'!C18+'GENSET #3'!C18+'GENSET #4'!C18+'GENSET #5'!C18) -> 102735264 | D13: =IF((C13-C12<0), "0",C13-C12) -> 21231 | E13: ='Gas-2'!G14 -> 225 | F13: =IF((E13-E12<0), "0",E13-E12) -> 0 | G13: =SUM(WATER!C14,WATER!H14,WATER!M14,WATER!R14) -> 1140123 | H13: =IF((G13-G12<0), "0",G13-G12) -> 429 | I13: 12 | J13: 105
A14: =A13+1 -> 44814 | C14: =SUM('GENSET #1'!C19+'GENSET #2'!C19+'GENSET #3'!C19+'GENSET #4'!C19+'GENSET #5'!C19) -> 102757447 | D14: =IF((C14-C13<0), "0",C14-C13) -> 22183 | E14: ='Gas-2'!G15 -> 270 | F14: =IF((E14-E13<0), "0",E14-E13) -> 45 | G14: =SUM(WATER!C15,WATER!H15,WATER!M15,WATER!R15) -> 1140322 | H14: =IF((G14-G13<0), "0",G14-G13) -> 199 | I14: 12 | J14: 101
A15: =A14+1 -> 44815 | C15: =SUM('GENSET #1'!C20+'GENSET #2'!C20+'GENSET #3'!C20+'GENSET #4'!C20+'GENSET #5'!C20) -> 102779689 | D15: =IF((C15-C14<0), "0",C15-C14) -> 22242 | E15: ='Gas-2'!G16 -> 225 | F15: =IF((E15-E14<0), "0",E15-E14) -> 0 | G15: =SUM(WATER!C16,WATER!H16,WATER!M16,WATER!R16) -> 1140641 | H15: =IF((G15-G14<0), "0",G15-G14) -> 319 | I15: 11 | J15: 80
A16: =A15+1 -> 44816 | C16: =SUM('GENSET #1'!C21+'GENSET #2'!C21+'GENSET #3'!C21+'GENSET #4'!C21+'GENSET #5'!C21) -> 102802125 | D16: =IF((C16-C15<0), "0",C16-C15) -> 22436 | E16: ='Gas-2'!G17 -> 225 | F16: =IF((E16-E15<0), "0",E16-E15) -> 0 | G16: =SUM(WATER!C17,WATER!H17,WATER!M17,WATER!R17) -> 1140943 | H16: =IF((G16-G15<0), "0",G16-G15) -> 302 | I16: 14 | J16: 157
... A23: =A22+1 -> 44823 | C23: =SUM('GENSET #1'!C28+'GENSET #2'!C28+'GENSET #3'!C28+'GENSET #4'!C28+'GENSET #5'!C28) -> 102958697 | D23: =IF((C23-C22<0), "0",C23-C22) -> 23461 | E23: ='Gas-2'!G24 -> 270 | F23: =IF((E23-E22<0), "0",E23-E22) -> 0 | G23: =SUM(WATER!C24,WATER!H24,WATER!M24,WATER!R24) -> 1143346 | H23: =IF((G23-G22<0), "0",G23-G22) -> 339 | I23: 15.5 | J23: 118
A24: =A23+1 -> 44824 | C24: =SUM('GENSET #1'!C29+'GENSET #2'!C29+'GENSET #3'!C29+'GENSET #4'!C29+'GENSET #5'!C29) -> 102980793 | D24: =IF((C24-C23<0), "0",C24-C23) -> 22096 | E24: ='Gas-2'!G25 -> 315 | F24: =IF((E24-E23<0), "0",E24-E23) -> 45 | G24: =SUM(WATER!C25,WATER!H25,WATER!M25,WATER!R25) -> 1143673 | H24: =IF((G24-G23<0), "0",G24-G23) -> 327 | I24: 12.6 | J24: 83 | Q24: 6348755
A25: =A24+1 -> 44825 | C25: =SUM('GENSET #1'!C30+'GENSET #2'!C30+'GENSET #3'!C30+'GENSET #4'!C30+'GENSET #5'!C30) -> 103001486 | D25: =IF((C25-C24<0), "0",C25-C24) -> 20693 | E25: ='Gas-2'!G26 -> 270 | F25: =IF((E25-E24<0), "0",E25-E24) -> 0 | G25: =SUM(WATER!C26,WATER!H26,WATER!M26,WATER!R26) -> 1143912 | H25: =IF((G25-G24<0), "0",G25-G24) -> 239 | I25: 21.4 | J25: 121
A26: =A25+1 -> 44826 | C26: =SUM('GENSET #1'!C31+'GENSET #2'!C31+'GENSET #3'!C31+'GENSET #4'!C31+'GENSET #5'!C31) -> 103022772 | D26: =IF((C26-C25<0), "0",C26-C25) -> 21286 | E26: ='Gas-2'!G27 -> 225 | F26: =IF((E26-E25<0), "0",E26-E25) -> 0 | G26: =SUM(WATER!C27,WATER!H27,WATER!M27,WATER!R27) -> 1144097 | H26: =IF((G26-G25<0), "0",G26-G25) -> 185 | I26: 26.2 | J26: 116
A27: =A26+1 -> 44827 | C27: =SUM('GENSET #1'!C32+'GENSET #2'!C32+'GENSET #3'!C32+'GENSET #4'!C32+'GENSET #5'!C32) -> 103045638 | D27: =IF((C27-C26<0), "0",C27-C26) -> 22866 | E27: ='Gas-2'!G28 -> 225 | F27: =IF((E27-E26<0), "0",E27-E26) -> 0 | G27: =SUM(WATER!C28,WATER!H28,WATER!M28,WATER!R28) -> 1144385 | H27: =IF((G27-G26<0), "0",G27-G26) -> 288 | I27: 26.2 | J27: 196
A28: =A27+1 -> 44828 | C28: =SUM('GENSET #1'!C33+'GENSET #2'!C33+'GENSET #3'!C33+'GENSET #4'!C33+'GENSET #5'!C33) -> 103069797 | D28: =IF((C28-C27<0), "0",C28-C27) -> 24159 | E28: ='Gas-2'!G29 -> 270 | F28: =IF((E28-E27<0), "0",E28-E27) -> 45 | G28: =SUM(WATER!C29,WATER!H29,WATER!M29,WATER!R29) -> 1144695 | H28: =IF((G28-G27<0), "0",G28-G27) -> 310 | I28: 26.2 | J28: 179
A29: =A28+1 -> 44829 | C29: =SUM('GENSET #1'!C34+'GENSET #2'!C34+'GENSET #3'!C34+'GENSET #4'!C34+'GENSET #5'!C34) -> 103094912 | D29: =IF((C29-C28<0), "0",C29-C28) -> 25115 | E29: ='Gas-2'!G30 -> 180 | F29: =IF((E29-E28<0), "0",E29-E28) -> 0 | G29: =SUM(WATER!C30,WATER!H30,WATER!M30,WATER!R30) -> 1145023 | H29: =IF((G29-G28<0), "0",G29-G28) -> 328 | I29: 23.8 | J29: 141
A30: =A29+1 -> 44830 | C30: =SUM('GENSET #1'!C35+'GENSET #2'!C35+'GENSET #3'!C35+'GENSET #4'!C35+'GENSET #5'!C35) -> 103118207 | D30: =IF((C30-C29<0), "0",C30-C29) -> 23295 | E30: ='Gas-2'!G31 -> 225 | F30: =IF((E30-E29<0), "0",E30-E29) -> 45 | G30: =SUM(WATER!C31,WATER!H31,WATER!M31,WATER!R31) -> 1145373 | H30: =IF((G30-G29<0), "0",G30-G29) -> 350 | I30: 11.7 | J30: 93
A31: =A30+1 -> 44831 | C31: =SUM('GENSET #1'!C36+'GENSET #2'!C36+'GENSET #3'!C36+'GENSET #4'!C36+'GENSET #5'!C36) -> 103142157 | D31: =IF((C31-C30<0), "0",C31-C30) -> 23950 | E31: ='Gas-2'!G32 -> 270 | F31: =IF((E31-E30<0), "0",E31-E30) -> 45 | G31: =SUM(WATER!C32,WATER!H32,WATER!M32,WATER!R32) -> 1145670 | H31: =IF((G31-G30<0), "0",G31-G30) -> 297 | I31: 14.6 | J31: 115
A32: =A31+1 -> 44832 | C32: =SUM('GENSET #1'!C37+'GENSET #2'!C37+'GENSET #3'!C37+'GENSET #4'!C37+'GENSET #5'!C37) -> 103165249 | D32: =IF((C32-C31<0), "0",C32-C31) -> 23092 | E32: ='Gas-2'!G33 -> 180 | F32: =IF((E32-E31<0), "0",E32-E31) -> 0 | G32: =SUM(WATER!C33,WATER!H33,WATER!M33,WATER!R33) -> 1145960 | H32: =IF((G32-G31<0), "0",G32-G31) -> 290 | I32: 16.5 | J32: 125
A33: =A32+1 -> 44833 | C33: =SUM('GENSET #1'!C38+'GENSET #2'!C38+'GENSET #3'!C38+'GENSET #4'!C38+'GENSET #5'!C38) -> 103189401 | D33: =IF((C33-C32<0), "0",C33-C32) -> 24152 | E33: ='Gas-2'!G34 -> 270 | F33: =IF((E33-E32<0), "0",E33-E32) -> 90 | G33: =SUM(WATER!C34,WATER!H34,WATER!M34,WATER!R34) -> 1146333 | H33: =IF((G33-G32<0), "0",G33-G32) -> 373 | I33: 17.5 | J33: 143
A34: =A33+1 -> 44834 | C34: =SUM('GENSET #1'!C39+'GENSET #2'!C39+'GENSET #3'!C39+'GENSET #4'!C39+'GENSET #5'!C39) -> 103210660 | D34: =IF((C34-C33<0), "0",C34-C33) -> 21259 | E34: ='Gas-2'!G35 -> 225 | F34: =IF((E34-E33<0), "0",E34-E33) -> 0 | G34: =SUM(WATER!C35,WATER!H35,WATER!M35,WATER!R35) -> 1146602 | H34: =IF((G34-G33<0), "0",G34-G33) -> 269
A35: =A34+1 -> 44835 | C35: =SUM('GENSET #1'!C40+'GENSET #2'!C40+'GENSET #3'!C40+'GENSET #4'!C40+'GENSET #5'!C40) -> 0 | D35: =IF((C35-C34<0), "0",C35-C34) -> 0 | E35: ='Gas-2'!G36 -> 0 | F35: =IF((E35-E34<0), "0",E35-E34) -> 0 | G35: =SUM(WATER!C36,WATER!H36,WATER!M36,WATER!R36) -> 0 | H35: =IF((G35-G34<0), "0",G35-G34) -> 0

Sheet Finance Only
A1: Four Seasons Landaa Giraavaru
A3: Property | B3: MLG | G3: 44470 | H3: =NOW() -> 44979.431 | J3: =H3-G3 -> 509.43103
A4: Month | B4: 44806
A5: Year | B5: 2022
A7: DAY | B7: Electricity Consumption ( kwh) | C7: Diesel Consumption (Liters) | D7: Solar Power Consumption(kwh) | E7: Gas Consumption (kg) | F7: Water Consumption ( m3) | G7: Occupancy | H7: Weather | I7: Ambian Temperature | J7: Electricity Variance (Today vs Yesterday)
A8: 1 | B8: =SUM('GENSET #1:GENSET #5'!D10) -> 20108 | C8: ='Diesel consumption'!D5 -> 5680 | D8: ='SOLAR METER READING'!D9 -> 1894 | E8: ='Gas-2'!G6 -> 270 | F8: =WATER!V6 -> 303 | G8: =WATER!W6 -> 13.6 | H8: ='SOLAR METER READING'!E9 -> 0 | I8: ='SOLAR METER READING'!F9 -> 0
A9: 2 | B9: =SUM('GENSET #1:GENSET #5'!D11) -> 20636 | C9: ='Diesel consumption'!D6 -> 5720 | D9: ='SOLAR METER READING'!D10 -> 2774 | E9: ='Gas-2'!G7 -> 270 | F9: =WATER!V7 -> 320 | G9: =WATER!W7 -> 14.6 | H9: ='SOLAR METER READING'!E10 -> 0 | I9: ='SOLAR METER READING'!F10 -> 0 | J9: =B9-B8 -> 528
A10: 3 | B10: =SUM('GENSET #1:GENSET #5'!D12) -> 20596 | C10: ='Diesel consumption'!D7 -> 5750 | D10: ='SOLAR METER READING'!D11 -> 2811 | E10: ='Gas-2'!G8 -> 225 | F10: =WATER!V8 -> 324 | G10: =WATER!W8 -> 14.6 | H10: ='SOLAR METER READING'!E11 -> 0 | I10: ='SOLAR METER READING'!F11 -> 0 | J10: =B10-B9 -> -40
A11: 4 | B11: =SUM('GENSET #1:GENSET #5'!D13) -> 21482 | C11: ='Diesel consumption'!D8 -> 6090 | D11: ='SOLAR METER READING'!D12 -> 2109 | E11: ='Gas-2'!G9 -> 270 | F11: =WATER!V9 -> 299 | G11: =WATER!W9 -> 10.7 | H11: ='SOLAR METER READING'!E12 -> 0 | I11: ='SOLAR METER READING'!F12 -> 0 | J11: =B11-B10 -> 886
A12: 5 | B12: =SUM('GENSET #1:GENSET #5'!D14) -> 20761 | C12: ='Diesel consumption'!D9 -> 5720 | D12: ='SOLAR METER READING'!D13 -> 879 | E12: ='Gas-2'!G10 -> 225 | F12: =WATER!V10 -> 265 | G12: =WATER!W10 -> 10.7 | H12: ='SOLAR METER READING'!E13 -> 0 | I12: ='SOLAR METER READING'!F13 -> 0 | J12: =B12-B11 -> -721
A13: 6 | B13: =SUM('GENSET #1:GENSET #5'!D15) -> 18935 | C13: ='Diesel consumption'!D10 -> 5840 | D13: ='SOLAR METER READING'!D14 -> 1771 | E13: ='Gas-2'!G11 -> 180 | F13: =WATER!V11 -> 303 | G13: =WATER!W11 -> 13.6 | H13: ='SOLAR METER READING'!E14 -> 0 | I13: ='SOLAR METER READING'!F14 -> 0 | J13: =B13-B12 -> -1826
A14: 7 | B14: =SUM('GENSET #1:GENSET #5'!D16) -> 21386 | C14: ='Diesel consumption'!D11 -> 5120 | D14: ='SOLAR METER READING'!D15 -> 2577 | E14: ='Gas-2'!G12 -> 315 | F14: =WATER!V12 -> 283 | G14: =WATER!W12 -> 13.6 | H14: ='SOLAR METER READING'!E15 -> 0 | I14: ='SOLAR METER READING'!F15 -> 0 | J14: =B14-B13 -> 2451
A15: 8 | B15: =SUM('GENSET #1:GENSET #5'!D17) -> 21684 | C15: ='Diesel consumption'!D12 -> 6130 | D15: ='SOLAR METER READING'!D16 -> 2807 | E15: ='Gas-2'!G13 -> 225 | F15: =WATER!V13 -> 288 | G15: =WATER!W13 -> 15 | H15: ='SOLAR METER READING'!E16 -> 0 | I15: ='SOLAR METER READING'!F16 -> 0 | J15: =B15-B14 -> 298
A16: 9 | B16: =SUM('GENSET #1:GENSET #5'!D18) -> 21231 | C16: ='Diesel consumption'!D13 -> 5750 | D16: ='SOLAR METER READING'!D17 -> 3178 | E16: ='Gas-2'!G14 -> 225 | F16: =WATER!V14 -> 429 | G16: =WATER!W14 -> 12 | H16: ='SOLAR METER READING'!E17 -> 0 | I16: ='SOLAR METER READING'!F17 -> 0 | J16: =B16-B15 -> -453
A17: 10 | B17: =SUM('GENSET #1:GENSET #5'!D19) -> 22183 | C17: ='Diesel consumption'!D14 -> 6080 | D17: ='SOLAR METER READING'!D18 -> 3226 | E17: ='Gas-2'!G15 -> 270 | F17: =WATER!V15 -> 199 | G17: =WATER!W15 -> 12 | H17: ='SOLAR METER READING'!E18 -> 0 | I17: ='SOLAR METER READING'!F18 -> 0 | J17: =B17-B16 -> 952
A18: 11 | B18: =SUM('GENSET #1:GENSET #5'!D20) -> 22242 | C18: ='Diesel consumption'!D15 -> 6250 | D18: ='SOLAR METER READING'!D19 -> 3172 | E18: ='Gas-2'!G16 -> 225 | F18: =WATER!V16 -> 319 | G18: =WATER!W16 -> 11 | H18: ='SOLAR METER READING'!E19 -> 0 | I18: ='SOLAR METER READING'!F19 -> 0 | J18: =B18-B17 -> 59
A19: 12 | B19: =SUM('GENSET #1:GENSET #5'!D21) -> 22436 | C19: ='Diesel consumption'!D16 -> 5990 | D19: ='SOLAR METER READING'!D20 -> 3237 | E19: ='Gas-2'!G17 -> 225 | F19: =WATER!V17 -> 302 | G19: =WATER!W17 -> 14 | H19: ='SOLAR METER READING'!E20 -> 0 | I19: ='SOLAR METER READING'!F20 -> 0 | J19: =B19-B18 -> 194
A20: 13 | B20: =SUM('GENSET #1:GENSET #5'!D22) -> 22085 | C20: ='Diesel consumption'!D17 -> 6140 | D20: ='SOLAR METER READING'!D21 -> 3356 | E20: ='Gas-2'!G18 -> 270 | F20: =WATER!V18 -> 342 | G20: =WATER!W18 -> 12 | H20: ='SOLAR METER READING'!E21 -> 0 | I20: ='SOLAR METER READING'!F21 -> 0 | J20: =B20-B19 -> -351
... A36: 29 | B36: =SUM('GENSET #1:GENSET #5'!D38) -> 24152 | C36: ='Diesel consumption'!D33 -> 6850 | D36: ='SOLAR METER READING'!D37 -> 3173 | E36: ='Gas-2'!G34 -> 270 | F36: =WATER!V34 -> 373 | G36: =WATER!W34 -> 17.5 | H36: ='SOLAR METER READING'!E37 -> 0 | I36: ='SOLAR METER READING'!F37 -> 0 | J36: =B36-B35 -> 1060
A37: 30 | B37: =SUM('GENSET #1:GENSET #5'!D39) -> 21259 | C37: ='Diesel consumption'!D34 -> 5960 | D37: ='SOLAR METER READING'!D38 -> 1749 | E37: ='Gas-2'!G35 -> 225 | F37: =WATER!V35 -> 269 | G37: 18 | H37: ='SOLAR METER READING'!E38 -> 0 | I37: ='SOLAR METER READING'!F38 -> 0 | J37: =B37-B36 -> -2893
A38: 31 | B38: =SUM('GENSET #1:GENSET #5'!D40) -> 0 | C38: ='Diesel consumption'!D35 -> 0 | D38: ='SOLAR METER READING'!D39 -> 0 | E38: ='Gas-2'!G36 -> 0 | F38: =WATER!V36 -> 0 | G38: =WATER!W36 -> 0 | H38: ='SOLAR METER READING'!E39 -> 0
A39: Total | B39: =SUM(B8:B38) -> 662215 | C39: =SUM(C8:C38) -> 186180 | D39: =SUM(D8:D38) -> 84269 | E39: =SUM(E8:E38) -> 7290 | F39: =SUM(F8:F38) -> 9293 | G39: =SUM(G8:G37)/30 -> 15.686667 | H39: ='SOLAR METER READING'!E40 -> 0 | I39: ='SOLAR METER READING'!F40 -> 0
A40: Avg | B40: =B39/A41 -> 22073.833 | C40: =C39/A41 -> 6206 | D40: =D39/A41 -> 2808.9667 | E40: =E39/A41 -> 243 | F40: =F39/A41 -> 309.76667
A41: 30

Sheet GENSET #1
C1: 1000 KVA
C3: NO#1
A6: 44806
B8: GENSET NO 1
A9: DAY | B9: YESTARDAY | C9: TODAY | D9: Final Electricity Consumption( KWh)
A10: 1 | B10: 19819910 | C10: 19827799 | D10: =MAX(0,C10-B10) -> 7889
A11: 2 | B11: =C10 -> 19827799 | C11: 19830786 | D11: =MAX(0,C11-B11) -> 2987
A12: 3 | B12: =C11 -> 19830786 | C12: 19838488 | D12: =MAX(0,C12-B12) -> 7702
A13: 4 | B13: =C12 -> 19838488 | C13: 19841791 | D13: =MAX(0,C13-B13) -> 3303
A14: 5 | B14: =C13 -> 19841791 | C14: 19849147 | D14: =MAX(0,C14-B14) -> 7356
A15: 6 | B15: =C14 -> 19849147 | C15: 19854694 | D15: =MAX(0,C15-B15) -> 5547
A16: 7 | B16: =C15 -> 19854694 | C16: 19856585 | D16: =MAX(0,C16-B16) -> 1891
A17: 8 | B17: =C16 -> 19856585 | C17: 19859887 | D17: =MAX(0,C17-B17) -> 3302
A18: 9 | B18: =C17 -> 19859887 | C18: 19862821 | D18: =MAX(0,C18-B18) -> 2934
A19: 10 | B19: =C18 -> 19862821 | C19: 19867038 | D19: =MAX(0,C19-B19) -> 4217
A20: 11 | B20: =C19 -> 19867038 | C20: 19875344 | D20: =MAX(0,C20-B20) -> 8306
A21: 12 | B21: =C20 -> 19875344 | C21: 19875746 | D21: =MAX(0,C21-B21) -> 402
A22: 13 | B22: =C21 -> 19875746 | C22: 19883912 | D22: =MAX(0,C22-B22) -> 8166
... A38: 29 | B38: =C37 -> 19994540 | C38: 20000707 | D38: =MAX(0,C38-B38) -> 6167
A39: 30 | B39: =C38 -> 20000707 | C39: 20007701 | D39: =MAX(0,C39-B39) -> 6994 | G39: NEW ENGINE PURCHASED FROM UK
A40: 31 | B40: =C39 -> 20007701 | D40: =MAX(0,C40-B40) -> 0
A41: Total | D41: =SUM(D10:D40) -> 187791 | G41: INSTALLED: NOV 30 2013

Sheet GENSET #2
C1: 1600 KVA
C3: NO#2
A6: 44806
B8: GENSET NO 2
A9: DAY | B9: YESTARDAY | C9: TODAY | D9: Final Electricity Consumption( KW h)
A10: 1 | B10: 33909471 | C10: 33914638 | D10: =MAX(0,C10-B10) -> 5167
A11: 2 | B11: =C10 -> 33914638 | C11: 33919814 | D11: =MAX(0,C11-B11) -> 5176
A12: 3 | B12: =C11 -> 33919814 | C12: 33925402 | D12: =MAX(0,C12-B12) -> 5588
A13: 4 | B13: =C12 -> 33925402 | C13: 33931996 | D13: =MAX(0,C13-B13) -> 6594
A14: 5 | B14: =C13 -> 33931996 | C14: 33937970 | D14: =MAX(0,C14-B14) -> 5974
A15: 6 | B15: =C14 -> 33937970 | C15: 33944077 | D15: =MAX(0,C15-B15) -> 6107
A16: 7 | B16: =C15 -> 33944077 | C16: 33950082 | D16: =MAX(0,C16-B16) -> 6005
A17: 8 | B17: =C16 -> 33950082 | C17: 33956447 | D17: =MAX(0,C17-B17) -> 6365
A18: 9 | B18: =C17 -> 33956447 | C18: 33962868 | D18: =MAX(0,C18-B18) -> 6421
A19: 10 | B19: =C18 -> 33962868 | C19: 33969372 | D19: =MAX(0,C19-B19) -> 6504
A20: 11 | B20: =C19 -> 33969372 | C20: 33974230 | D20: =MAX(0,C20-B20) -> 4858
A21: 12 | B21: =C20 -> 33974230 | C21: 33978886 | D21: =MAX(0,C21-B21) -> 4656
A22: 13 | B22: =C21 -> 33978886 | C22: 33984311 | D22: =MAX(0,C22-B22) -> 5425
... A39: 30 | B39: =C38 -> 34098226 | C39: 34105185 | D39: =MAX(0,C39-B39) -> 6959
A40: 31 | B40: =C39 -> 34105185 | D40: =MAX(0,C40-B40) -> 0
A41: Total | B41: =#REF! -> #REF! | D41: =SUM(D10:D40) -> 195714

Sheet GENSET #3
C1: 900 KVA
C3: NO#3
A6: 44806
B8: GENSET NO 3
A9: DAY | B9: YESTARDAY | C9: TODAY | D9: Final Electricity Consumption( KW h)
A10: 1 | B10: 15377497 | C10: 15384549 | D10: =MAX(0,C10-B10) -> 7052
A11: 2 | B11: =C10 -> 15384549 | C11: 15389062 | D11: =MAX(0,C11-B11) -> 4513
A12: 3 | B12: =C11 -> 15389062 | C12: 15393038 | D12: =MAX(0,C12-B12) -> 3976
A13: 4 | B13: =C12 -> 15393038 | C13: 15396718 | D13: =MAX(0,C13-B13) -> 3680
A14: 5 | B14: =C13 -> 15396718 | C14: 15396718 | D14: =MAX(0,C14-B14) -> 0
A15: 6 | B15: =C14 -> 15396718 | C15: 15400649 | D15: =MAX(0,C15-B15) -> 3931
A16: 7 | B16: =C15 -> 15400649 | C16: 15407018 | D16: =MAX(0,C16-B16) -> 6369
A17: 8 | B17: =C16 -> 15407018 | C17: 15411206 | D17: =MAX(0,C17-B17) -> 4188
A18: 9 | B18: =C17 -> 15411206 | C18: 15415486 | D18: =MAX(0,C18-B18) -> 4280
A19: 10 | B19: =C18 -> 15415486 | C19: 15418805 | D19: =MAX(0,C19-B19) -> 3319
A20: 11 | B20: =C19 -> 15418805 | C20: 15425465 | D20: =MAX(0,C20-B20) -> 6660
A21: 12 | B21: =C20 -> 15425465 | C21: 15432979 | D21: =MAX(0,C21-B21) -> 7514
A22: 13 | B22: =C21 -> 15432979 | C22: 15433036 | D22: =MAX(0,C22-B22) -> 57
... A39: 30 | B39: =C38 -> 15433036 | C39: 15433036 | D39: =MAX(0,C39-B39) -> 0
A40: 31 | B40: =C39 -> 15433036 | D40: =MAX(0,C40-B40) -> 0
A41: Total | B41: =#REF! -> #REF! | D41: =SUM(D10:D40) -> 55539

Sheet GENSET #4
C1: 500 KVA
C3: NO#4
A6: 44806
B8: GENSET NO 4
A9: DAY | B9: YESTARDAY | C9: TODAY | D9: Final Electricity Consumption( KW h)
A10: 1 | B10: 12652507 | C10: 12652507 | D10: =MAX(0,C10-B10) -> 0
A11: 2 | B11: =C10 -> 12652507 | C11: 12652691 | D11: =MAX(0,C11-B11) -> 184
A12: 3 | B12: =C11 -> 12652691 | C12: 12652740 | D12: =MAX(0,C12-B12) -> 49
A13: 4 | B13: =C12 -> 12652740 | C13: 12653248 | D13: =MAX(0,C13-B13) -> 508
A14: 5 | B14: =C13 -> 12653248 | C14: 12653248 | D14: =MAX(0,C14-B14) -> 0
A15: 6 | B15: =C14 -> 12653248 | C15: 12653585 | D15: =MAX(0,C15-B15) -> 337
A16: 7 | B16: =C15 -> 12653585 | C16: 12653585 | D16: =MAX(0,C16-B16) -> 0
A17: 8 | B17: =C16 -> 12653585 | C17: 12653585 | D17: =MAX(0,C17-B17) -> 0
A18: 9 | B18: =C17 -> 12653585 | C18: 12653585 | D18: =MAX(0,C18-B18) -> 0
A19: 10 | B19: =C18 -> 12653585 | C19: 12653860 | D19: =MAX(0,C19-B19) -> 275
A20: 11 | B20: =C19 -> 12653860 | C20: 12655418 | D20: =MAX(0,C20-B20) -> 1558
A21: 12 | B21: =C20 -> 12655418 | C21: 12657371 | D21: =MAX(0,C21-B21) -> 1953
A22: 13 | B22: =C21 -> 12657371 | C22: 12657589 | D22: =MAX(0,C22-B22) -> 218
... A39: 30 | B39: =C38 -> 12676822 | C39: 12677148 | D39: =MAX(0,C39-B39) -> 326
A40: 31 | B40: =C39 -> 12677148 | D40: =MAX(0,C40-B40) -> 0
A41: Total | B41: =#REF! -> #REF! | D41: =SUM(D10:D40) -> 24641

Sheet GENSET #5
C1: 1000 KVA
C3: NO#5
A6: 44806
B8: GENSET NO 5
A9: DAY | B9: YESTARDAY | C9: TODAY | D9: Final Electricity Consumption( KWh)
A10: 1 | B10: 20789060 | C10: 20789060 | D10: =MAX(0,C10-B10) -> 0 | I10: 7040
A11: 2 | B11: =C10 -> 20789060 | C11: 20796836 | D11: =MAX(0,C11-B11) -> 7776 | I11: 8505
A12: 3 | B12: =C11 -> 20796836 | C12: 20800117 | D12: =MAX(0,C12-B12) -> 3281 | I12: 8591
A13: 4 | B13: =C12 -> 20800117 | C13: 20807514 | D13: =MAX(0,C13-B13) -> 7397 | I13: 8045
A14: 5 | B14: =C13 -> 20807514 | C14: 20814945 | D14: =MAX(0,C14-B14) -> 7431
A15: 6 | B15: =C14 -> 20814945 | C15: 20817958 | D15: =MAX(0,C15-B15) -> 3013
A16: 7 | B16: =C15 -> 20817958 | C16: 20825079 | D16: =MAX(0,C16-B16) -> 7121
A17: 8 | B17: =C16 -> 20825079 | C17: 20832908 | D17: =MAX(0,C17-B17) -> 7829
A18: 9 | B18: =C17 -> 20832908 | C18: 20840504 | D18: =MAX(0,C18-B18) -> 7596
A19: 10 | B19: =C18 -> 20840504 | C19: 20848372 | D19: =MAX(0,C19-B19) -> 7868
A20: 11 | B20: =C19 -> 20848372 | C20: 20849232 | D20: =MAX(0,C20-B20) -> 860
A21: 12 | B21: =C20 -> 20849232 | C21: 20857143 | D21: =MAX(0,C21-B21) -> 7911
A22: 13 | B22: =C21 -> 20857143 | C22: 20865362 | D22: =MAX(0,C22-B22) -> 8219
A23: 14 | B23: =C22 -> 20865362 | C23: 20869167 | D23: =MAX(0,C23-B23) -> 3805
A24: 15 | B24: =C23 -> 20869167 | C24: 20878246 | D24: =MAX(0,C24-B24) -> 9079
A25: 16 | B25: =C24 -> 20878246 | C25: 20884682 | D25: =MAX(0,C25-B25) -> 6436
... A39: 30 | B39: =C38 -> 20980610 | C39: 20987590 | D39: =MAX(0,C39-B39) -> 6980
A40: 31 | B40: =C39 -> 20987590 | D40: =MAX(0,C40-B40) -> 0
A41: Total | D41: =SUM(D10:D40) -> 198530

Sheet Diesel consumption
A1: Diesel Consumption - Powerhouse | F1: Diesel Tank Jetty Meter
A2: 44806
D3: Liters | F3: Boat meter Reading
A4: Date | B4: Yesterday | C4: Today | D4: ConsumptionIn 24 hrs | F4: Yesterday | G4: Today | H4: Consumption (Liters) | J4: In Barrels | L4: Carbon Emmision
A5: 1 | B5: 47452760 | C5: 47458440 | D5: =MAX(0,C5-B5) -> 5680 | F5: 1271440 | G5: 1271440 | H5: =MAX(0,G5-F5) -> 0 | J5: =D5/200 -> 28.4 | L5: =2.68*D5 -> 15222.4 | M5: =L5/1000 -> 15.2224
A6: 2 | B6: =C5 -> 47458440 | C6: 47464160 | D6: =MAX(0,C6-B6) -> 5720 | F6: =G5 -> 1271440 | G6: 1273250 | H6: =MAX(0,G6-F6) -> 1810 | J6: =D6/200 -> 28.6 | L6: =2.68*D6 -> 15329.6 | M6: =L6/1000 -> 15.3296
A7: 3 | B7: =C6 -> 47464160 | C7: 47469910 | D7: =MAX(0,C7-B7) -> 5750 | F7: =G6 -> 1273250 | G7: 1274100 | H7: =MAX(0,G7-F7) -> 850 | J7: =D7/200 -> 28.75 | L7: =2.68*D7 -> 15410 | M7: =L7/1000 -> 15.41
A8: 4 | B8: =C7 -> 47469910 | C8: 47476000 | D8: =MAX(0,C8-B8) -> 6090 | F8: =G7 -> 1274100 | G8: 1274100 | H8: =MAX(0,G8-F8) -> 0 | J8: =D8/200 -> 30.45 | L8: =2.68*D8 -> 16321.2 | M8: =L8/1000 -> 16.3212
A9: 5 | B9: =C8 -> 47476000 | C9: 47481720 | D9: =MAX(0,C9-B9) -> 5720 | F9: =G8 -> 1274100 | G9: 1275600 | H9: =MAX(0,G9-F9) -> 1500 | J9: =D9/200 -> 28.6 | L9: =2.68*D9 -> 15329.6 | M9: =L9/1000 -> 15.3296
A10: 6 | B10: =C9 -> 47481720 | C10: 47487560 | D10: =MAX(0,C10-B10) -> 5840 | F10: =G9 -> 1275600 | G10: 1276800 | H10: =MAX(0,G10-F10) -> 1200 | J10: =D10/200 -> 29.2 | L10: =2.68*D10 -> 15651.2 | M10: =L10/1000 -> 15.6512
A11: 7 | B11: =C10 -> 47487560 | C11: 47492680 | D11: =MAX(0,C11-B11) -> 5120 | F11: =G10 -> 1276800 | G11: 1276800 | H11: =MAX(0,G11-F11) -> 0 | J11: =D11/200 -> 25.6 | L11: =2.68*D11 -> 13721.6 | M11: =L11/1000 -> 13.7216
A12: 8 | B12: =C11 -> 47492680 | C12: 47498810 | D12: =MAX(0,C12-B12) -> 6130 | F12: =G11 -> 1276800 | G12: 1279440 | H12: =MAX(0,G12-F12) -> 2640 | J12: =D12/200 -> 30.65 | L12: =2.68*D12 -> 16428.4 | M12: =L12/1000 -> 16.4284
A13: 9 | B13: =C12 -> 47498810 | C13: 47504560 | D13: =MAX(0,C13-B13) -> 5750 | F13: =G12 -> 1279440 | G13: 1279440 | H13: =MAX(0,G13-F13) -> 0 | J13: =D13/200 -> 28.75 | L13: =2.68*D13 -> 15410 | M13: =L13/1000 -> 15.41
A14: 10 | B14: =C13 -> 47504560 | C14: 47510640 | D14: =MAX(0,C14-B14) -> 6080 | F14: =G13 -> 1279440 | G14: 1280780 | H14: =MAX(0,G14-F14) -> 1340 | J14: =D14/200 -> 30.4 | L14: =2.68*D14 -> 16294.4 | M14: =L14/1000 -> 16.2944
A15: 11 | B15: =C14 -> 47510640 | C15: 47516890 | D15: =MAX(0,C15-B15) -> 6250 | F15: =G14 -> 1280780 | G15: 1281080 | H15: =MAX(0,G15-F15) -> 300 | J15: =D15/200 -> 31.25 | L15: =2.68*D15 -> 16750 | M15: =L15/1000 -> 16.75
A16: 12 | B16: =C15 -> 47516890 | C16: 47522880 | D16: =MAX(0,C16-B16) -> 5990 | F16: =G15 -> 1281080 | G16: 1283310 | H16: =MAX(0,G16-F16) -> 2230 | J16: =D16/200 -> 29.95 | L16: =2.68*D16 -> 16053.2 | M16: =L16/1000 -> 16.0532
A17: 13 | B17: =C16 -> 47522880 | C17: 47529020 | D17: =MAX(0,C17-B17) -> 6140 | F17: =G16 -> 1283310 | G17: 1284070 | H17: =MAX(0,G17-F17) -> 760 | J17: =D17/200 -> 30.7 | L17: =2.68*D17 -> 16455.2 | M17: =L17/1000 -> 16.4552
... A34: 30 | B34: =C33 -> 47632980 | C34: 47638940 | D34: =MAX(0,C34-B34) -> 5960 | F34: =G33 -> 1300410 | G34: 1301040 | H34: =MAX(0,G34-F34) -> 630 | J34: =D34/200 -> 29.8 | L34: =2.68*D34 -> 15972.8 | M34: =L34/1000 -> 15.9728
A35: 31 | B35: =C34 -> 47638940 | D35: =MAX(0,C35-B35) -> 0 | F35: =G34 -> 1301040 | H35: =MAX(0,G35-F35) -> 0 | J35: =D35/200 -> 0 | L35: =2.68*D35 -> 0
D36: =SUM(D5:D35) -> 186180 | J36: =SUM(J5:J34) -> 930.9 | L36: =2.68*D36 -> 498962.4 | M36: =L36/1000 -> 498.9624

Sheet SOLAR METER READING
C3: solar reading
B5: 44806
B7: Solar meter reading
A8: DAY | B8: YESTARDAY | C8: TODAY | D8: Final Electricity Consumption( KW h) | E8: Weather Condition | F8: Temperature
A9: 1 | B9: 3938228 | C9: 3940122 | D9: =MAX(0,C9-B9) -> 1894
A10: 2 | B10: =C9 -> 3940122 | C10: 3942896 | D10: =MAX(0,C10-B10) -> 2774
A11: 3 | B11: =C10 -> 3942896 | C11: 3945707 | D11: =MAX(0,C11-B11) -> 2811
A12: 4 | B12: =C11 -> 3945707 | C12: 3947816 | D12: =MAX(0,C12-B12) -> 2109
A13: 5 | B13: =C12 -> 3947816 | C13: 3948695 | D13: =MAX(0,C13-B13) -> 879 | J13: 1 liter diesel | K13: 3.61 kwh
A14: 6 | B14: =C13 -> 3948695 | C14: 3950466 | D14: =MAX(0,C14-B14) -> 1771 | J14: 212.88 diesel | K14: 768.50 kwh
A15: 7 | B15: =C14 -> 3950466 | C15: 3953043 | D15: =MAX(0,C15-B15) -> 2577
A16: 8 | B16: =C15 -> 3953043 | C16: 3955850 | D16: =MAX(0,C16-B16) -> 2807
A17: 9 | B17: =C16 -> 3955850 | C17: 3959028 | D17: =MAX(0,C17-B17) -> 3178
A18: 10 | B18: =C17 -> 3959028 | C18: 3962254 | D18: =MAX(0,C18-B18) -> 3226
A19: 11 | B19: =C18 -> 3962254 | C19: 3965426 | D19: =MAX(0,C19-B19) -> 3172
A20: 12 | B20: =C19 -> 3965426 | C20: 3968663 | D20: =MAX(0,C20-B20) -> 3237
A21: 13 | B21: =C20 -> 3968663 | C21: 3972019 | D21: =MAX(0,C21-B21) -> 3356
A22: 14 | B22: =C21 -> 3972019 | C22: 3975042 | D22: =MAX(0,C22-B22) -> 3023
A23: 15 | B23: =C22 -> 3975042 | C23: 3977952 | D23: =MAX(0,C23-B23) -> 2910
A24: 16 | B24: =C23 -> 3977952 | C24: 3981057 | D24: =MAX(0,C24-B24) -> 3105
A25: 17 | B25: =C24 -> 3981057 | C25: 3984442 | D25: =MAX(0,C25-B25) -> 3385
A26: 18 | B26: =C25 -> 3984442 | C26: 3987512 | D26: =MAX(0,C26-B26) -> 3070
... A38: 30 | B38: =C37 -> 4020748 | C38: 4022497 | D38: =MAX(0,C38-B38) -> 1749
A39: 31 | B39: =C38 -> 4022497 | D39: =MAX(0,C39-B39) -> 0
A40: Total | D40: =SUM(D9:D39) -> 84269

Sheet FEEDER Consumption 
A1: 44806 | GC1: Daily Electricity (Kwh) Consumption by Building Categories
A2: POWER HOUSE FEEDER READING
C3: Main BLU FEEDER PANEL 1 | H3: Main BLU FEEDER PANEL 2 | M3: Main POWER HOUSE FEEDER PANEL NO:3 | R3: Main Kitchen -7 | W3: Main Kitchen -10 | AB3: Water treatment Plant | AH3: Sewage treatment Plant | AM3: Laundry--8SSB (Machineries) | AR3: Laundry-9 (HR/Tuck Shop Building) | AW3: New staff accomodation (E0) | BB3: Staff block-16(E2-E3) | BG3: Staff Block Feeder-3(E4-E5) | BL3: Management block-5 (M1 to M6) | BQ3: SNR STAFF BLOCK (PC Block) | BV3: BOAT DOCK FEEDER - 22 | CA3: RECEPTION Building Full (Finance/Reservation) | CF3: DIVE CENTER (Inc MDC and Recreation) | CK3: 301-307 | CP3: 308-314 | CU3: 315-320 | CZ3: 401-407 | DE3: 408-414 | DJ3: 415-420 | DO3: SPA - 1 | DT3: SPA - 2 | DY3: BLU KITCHEN - 1 | ED3: BLU KITCHEN - 2 | EI3: AL BARAKATH | EN3: STAFF KITCHEN | ES3: MANAGR BLOCK GARDEN (White House) | EX3: 121-131 | FC3: 113-120 | FH3: Room 855 Hot Water Boiler Kw reading | FM3: Room 911 Hot Water Boiler kw reading | FR3: Room 403 Hot Water Boiler kw reading | FW3: Room 131 Hot Water Boiler kw reading | GC3: Blu Feeders | GE3: ALL Kitchens | GG3: Laundry + HR Buidling | GI3: Employee Block | GK3: Managers Block + SNR Block | GM3: HPL Project Team Usage
A4: DAY | B4: Occupancy | C4: Yesterday | D4: Today | E4: Consumption | F4: Variance (Tdy vs Ystdy) | G4: % | H4: Yesterday | I4: Today | J4: Consumption | K4: Var(Tdy vs Ystdy) | L4: % | M4: Yesterday | N4: Today | O4: Consumption | P4: Var (Tdy vs Ystdy) | Q4: % | R4: Yesterday | S4: Today | T4: Consumption | U4: Var(Tdy vs Ystdy) | V4: % | W4: Yesterday | X4: Today | Y4: Consumption | Z4: Var(Tdy vs Ystdy) | AA4: % | AB4: Yesterday | AC4: Today | AD4: Consumption | AE4: Kwh per cubic meter | AF4: Var(Tdy vs Ystdy) | AG4: % | AH4: Yesterday | AI4: Today | AJ4: Consumption | AK4: Var(Tdy vs Ystdy) | AL4: % | AM4: Yesterday | AN4: Today | AO4: Consumption | AP4: Var(Tdy vs Ystdy) | AQ4: % | AR4: Yesterday | AS4: Today | AT4: Consumption | AU4: Var(Tdy vs Ystdy) | AV4: % | AW4: Yesterday | AX4: Today | AY4: Consumption | AZ4: Var(Tdy vs Ystdy) | BA4: % | BB4: Yesterday | BC4: Today | BD4: Consumption | BE4: Var(Tdy vs Ystdy) | BF4: % | BG4: Yesterday | BH4: Today | BI4: Consumption | BJ4: Var(Tdy vs Ystdy) | BK4: % | BL4: Yesterday | BM4: Today | BN4: Consumption | BO4: Var(Tdy vs Ystdy) | BP4: % | BQ4: Yesterday | BR4: Today | BS4: Consumption | BT4: Var(Tdy vs Ystdy) | BU4: % | BV4: Yesterday | BW4: Today | BX4: Consumption | BY4: Var(Tdy vs Ystdy) | BZ4: % | CA4: Yesterday | CB4: Today | CC4: Consumption | CD4: Var(Tdy vs Ystdy) | CE4: % | CF4: Yesterday | CG4: Today | CH4: Consumption | CI4: Var(Tdy vs Ystdy) | CJ4: % | CK4: Yesterday | CL4: Today | CM4: Consumption | CN4: Var(Tdy vs Ystdy) | CO4: % | CP4: Yesterday | CQ4: Today | CR4: Consumption | CS4: Var(Tdy vs Ystdy) | CT4: % | CU4: Yesterday | CV4: Today | CW4: Consumption | CX4: Var(Tdy vs Ystdy) | CY4: % | CZ4: Yesterday | DA4: Today | DB4: Consumption | DC4: Var(Tdy vs Ystdy) | DD4: % | DE4: Yesterday | DF4: Today | DG4: Consumption | DH4: Var(Tdy vs Ystdy) | DI4: % | DJ4: Yesterday | DK4: Today | DL4: Consumption | DM4: Var(Tdy vs Ystdy) | DN4: % | DO4: Yesterday | DP4: Today | DQ4: Consumption | DR4: Var(Tdy vs Ystdy) | DS4: % | DT4: Yesterday | DU4: Today | DV4: Consumption | DW4: Var(Tdy vs Ystdy) | DX4: % | DY4: Yesterday | DZ4: Today | EA4: Consumption | EB4: Var(Tdy vs Ystdy) | EC4: % | ED4: Yesterday | EE4: Today | EF4: Consumption | EG4: Var(Tdy vs Ystdy) | EH4: % | EI4: Yesterday | EJ4: Today | EK4: Consumption | EL4: Var(Tdy vs Ystdy) | EM4: % | EN4: Yesterday | EO4: Today | EP4: Consumption | EQ4: Var(Tdy vs Ystdy) | ER4: % | ES4: Yesterday | ET4: Today | EU4: Consumption | EV4: Var(Tdy vs Ystdy) | EW4: % | EX4: Yesterday | EY4: Today | EZ4: Consumption | FA4: Var(Tdy vs Ystdy) | FB4: % | FC4: Yesterday | FD4: Today | FE4: Consumption | FF4: Var(Tdy vs Ystdy) | FG4: % | FM4: Yesterday | FN4: Today | FO4: Consumption | FP4: Var(Tdy vs Ystdy) | FQ4: % | FR4: Yesterday | FS4: Today | FT4: Consumption | FU4: Var(Tdy vs Ystdy) | FV4: % | FW4: Yesterday | FX4: Today | FY4: Consumption | FZ4: Var(Tdy vs Ystdy) | GA4: % | GC4: Total (Kwh) | GD4: Avg | GE4: Total (Kwh) | GF4: Avg | GG4: Total (Kwh) | GH4: Avg | GI4: Total (Kwh) | GJ4: Avg | GK4: Total (Kwh) | GL4: Avg | GM4: Total (Kwh) | GN4: Avg
A5: 1 | B5: ='Finance Only'!G8 -> 13.6 | C5: 26994672 | D5: 26996974 | E5: =MAX(0,D5-C5) -> 2302 | H5: 24893152 | I5: 24896226 | J5: =MAX(0,I5-H5) -> 3074 | M5: 91816490 | N5: 91826475 | O5: =MAX(0,N5-M5) -> 9985 | R5: 2999800 | S5: 3001900 | T5: =MAX(0,S5-R5) -> 2100 | W5: 4062638 | X5: 4065171 | Y5: =MAX(0,X5-W5) -> 2533 | AB5: 2640200 | AC5: 2642000 | AD5: =MAX(0,AC5-AB5) -> 1800 | AE5: =AD5/WATER!V6 -> 5.9405941 | AH5: 1075773 | AI5: 1076327 | AJ5: =MAX(0,AI5-AH5) -> 554 | AM5: 1077400 | AN5: 1078000 | AO5: =AN5-AM5 -> 600 | AR5: 2433000 | AS5: 2433700 | AT5: =AS5-AR5 -> 700 | AW5: 3932.1 | AX5: 4212.2 | AY5: =AX5-AW5 -> 280.1 | BB5: 984650 | BC5: 985010 | BD5: =BC5-BB5 -> 360 | BG5: 1065100 | BH5: 1065300 | BI5: =BH5-BG5 -> 200 | BL5: 1576400 | BM5: 1576800 | BN5: =BM5-BL5 -> 400 | BQ5: 132710 | BR5: 132830 | BS5: =BR5-BQ5 -> 120 | BV5: 568720 | BW5: 569150 | BX5: =BW5-BV5 -> 430 | CA5: 1045500 | CB5: 1046600 | CC5: =CB5-CA5 -> 1100 | CF5: 3389000 | CG5: 3392000 | CH5: =CG5-CF5 -> 3000 | CK5: 804440 | CL5: 805110 | CM5: =MAX(0,CL5-CK5) -> 670 | CP5: 665180 | CQ5: 665690 | CR5: =MAX(0,CQ5-CP5) -> 510 | CU5: 552600 | CV5: 552990 | CW5: =MAX(0,CV5-CU5) -> 390 | CZ5: 924380 | DA5: 925090 | DB5: =MAX(0,DA5-CZ5) -> 710 | DE5: 705910 | DF5: 706490 | DG5: =MAX(0,DF5-DE5) -> 580 | DJ5: 615270 | DK5: 615790 | DL5: =MAX(0,DK5-DJ5) -> 520 | DO5: 334860 | DP5: 335240 | DQ5: =MAX(0,DP5-DO5) -> 380 | DT5: 109100 | DU5: 109260 | DV5: =MAX(0,DU5-DT5) -> 160 | DY5: 696210 | DZ5: 69707 | EA5: =MAX(0,DZ5-DY5) -> 0 | ED5: 222480 | EE5: 222740 | EF5: =MAX(0,EE5-ED5) -> 260 | EI5: 249530 | EJ5: 249880 | EK5: =MAX(0,EJ5-EI5) -> 350 | EN5: 412360 | EO5: 412830 | EP5: =MAX(0,EO5-EN5) -> 470 | ES5: 69098 | EU5: =MAX(0,ET5-ES5) -> 0 | EX5: 131740 | EZ5: =MAX(0,EY5-EX5) -> 0 | FC5: 74909 | FE5: =MAX(0,FD5-FC5) -> 0 | FM5: 91210 | FO5: =MAX(0,FN5-FM5) -> 0 | FR5: 0 | FT5: =MAX(0,FS5-FR5) -> 0 | FW5: 0 | FY5: =MAX(0,FX5-FW5) -> 0 | GC5: =SUM(E5+J5) -> 5376 | GE5: =SUM(T5+Y5+EA5+EF5+EK5+EP5) -> 5713 | GG5: =SUM(AO5+AT5) -> 1300 | GI5: =SUM(AY5+BD5+BI5) -> 840.1 | GK5: =SUM(BN5+BS5+EU5) -> 520 | GM5: =SUM(EZ5+FE5) -> 0
A6: 2 | B6: ='Finance Only'!G9 -> 14.6 | C6: =D5 -> 26996974 | D6: 26999417 | E6: =MAX(0,D6-C6) -> 2443 | F6: =E6-E5 -> 141 | G6: =(E6/'Finance Only'!B9)*100 -> 11.838535 | H6: =I5 -> 24896226 | I6: 24899691 | J6: =MAX(0,I6-H6) -> 3465 | K6: =J6-J5 -> 391 | L6: =(J6/'Finance Only'!B9)*100 -> 16.791045 | M6: =N5 -> 91826475 | N6: 91835969 | O6: =MAX(0,N6-M6) -> 9494 | P6: =O6-O5 -> -491 | Q6: =(O6/'Finance Only'!B9)*100 -> 46.006978 | R6: =S5 -> 3001900 | S6: 3004200 | T6: =MAX(0,S6-R6) -> 2300 | U6: =T6-T5 -> 200 | V6: =(T6/'Finance Only'!B9)*100 -> 11.145571 | W6: =X5 -> 4065171 | X6: 4067786 | Y6: =MAX(0,X6-W6) -> 2615 | Z6: =Y6-Y5 -> 82 | AA6: =(Y6/'Finance Only'!B9)*100 -> 12.672029 | AB6: =AC5 -> 2642000 | AC6: 2643700 | AD6: =MAX(0,AC6-AB6) -> 1700 | AE6: =AD6/WATER!V7 -> 5.3125 | AF6: =AD6-AD5 -> -100 | AG6: =(AD6/'Finance Only'!B9)*100 -> 8.2380306 | AH6: =AI5 -> 1076327 | AI6: 1076843 | AJ6: =MAX(0,AI6-AH6) -> 516 | AK6: =AJ6-AJ5 -> -38 | AL6: =(AJ6/'Finance Only'!B9)*100 -> 2.5004846 | AM6: =AN5 -> 1078000 | AN6: 1078700 | AO6: =MAX(0,AN6-AM6) -> 700 | AP6: =AO6-AO5 -> 100 | AQ6: =(AO6/'Finance Only'!B9)*100 -> 3.3921303 | AR6: =AS5 -> 2433700 | AS6: 2435100 | AT6: =MAX(0,AS6-AR6) -> 1400 | AU6: =AT6-AT5 -> 700 | AV6: =(AT6/'Finance Only'!B9)*100 -> 6.7842605 | AW6: =AX5 -> 4212.2 | AX6: 4540.2 | AY6: =MAX(0,AX6-AW6) -> 328 | AZ6: =AY6-AY5 -> 47.9 | BA6: =(AY6/'Finance Only'!B9)*100 -> 1.5894553 | BB6: =BC5 -> 985010 | BC6: 985340 | BD6: =MAX(0,BC6-BB6) -> 330 | BE6: =BD6-BD5 -> -30 | BF6: =(BD6/'Finance Only'!B9)*100 -> 1.5991471 | BG6: =BH5 -> 1065300 | BH6: 1065600 | BI6: =MAX(0,BH6-BG6) -> 300 | BJ6: =BI6-BI5 -> 100 | BK6: =(BI6/'Finance Only'!B9)*100 -> 1.4537701 | BL6: =BM5 -> 1576800 | BM6: 1577300 | BN6: =MAX(0,BM6-BL6) -> 500 | BO6: =BN6-BN5 -> 100 | BP6: =(BN6/'Finance Only'!B9)*100 -> 2.4229502 | BQ6: =BR5 -> 132830 | BR6: 132950 | BS6: =MAX(0,BR6-BQ6) -> 120 | BT6: =BS6-BS5 -> 0 | BU6: =(BS6/'Finance Only'!B9)*100 -> 0.58150804 | BV6: =BW5 -> 569150 | BW6: 569540 | BX6: =MAX(0,BW6-BV6) -> 390 | BY6: =BX6-BX5 -> -40 | BZ6: =(BX6/'Finance Only'!B9)*100 -> 1.8899011 | CA6: =CB5 -> 1046600 | CB6: 1047700 | CC6: =MAX(0,CB6-CA6) -> 1100 | CD6: =CC6-CC5 -> 0 | CE6: =(CC6/'Finance Only'!B9)*100 -> 5.3304904 | CF6: =CG5 -> 3392000 | CG6: 3395900 | CH6: =MAX(0,CG6-CF6) -> 3900 | CI6: =CH6-CH5 -> 900 | CJ6: =(CH6/'Finance Only'!B9)*100 -> 18.899011 | CK6: =CL5 -> 805110 | CL6: 805830 | CM6: =MAX(0,CL6-CK6) -> 720 | CN6: =CM6-CM5 -> 50 | CO6: =(CM6/'Finance Only'!B9)*100 -> 3.4890483 | CP6: =CQ5 -> 665690 | CQ6: 666140 | CR6: =MAX(0,CQ6-CP6) -> 450 | CS6: =CR6-CR5 -> -60 | CT6: =(CR6/'Finance Only'!B9)*100 -> 2.1806552 | CU6: =CV5 -> 552990 | CV6: 553460 | CW6: =MAX(0,CV6-CU6) -> 470 | CX6: =CW6-CW5 -> 80 | CY6: =(CW6/'Finance Only'!B9)*100 -> 2.2775732 | CZ6: =DA5 -> 925090 | DA6: 925890 | DB6: =MAX(0,DA6-CZ6) -> 800 | DC6: =DB6-DB5 -> 90 | DD6: =(DB6/'Finance Only'!B9)*100 -> 3.8767203 | DE6: =DF5 -> 706490 | DF6: 707190 | DG6: =MAX(0,DF6-DE6) -> 700 | DH6: =DG6-DG5 -> 120 | DI6: =(DG6/'Finance Only'!B9)*100 -> 3.3921303 | DJ6: =DK5 -> 615790 | DK6: 616360 | DL6: =MAX(0,DK6-DJ6) -> 570 | DM6: =DL6-DL5 -> 50 | DN6: =(DL6/'Finance Only'!B9)*100 -> 2.7621632 | DO6: =DP5 -> 335240 | DP6: 335620 | DQ6: =MAX(0,DP6-DO6) -> 380 | DR6: =DQ6-DQ5 -> 0 | DS6: =(DQ6/'Finance Only'!B9)*100 -> 1.8414421 | DT6: =DU5 -> 109260 | DU6: 109340 | DV6: =MAX(0,DU6-DT6) -> 80 | DW6: =DV6-DV5 -> -80 | DX6: =(DV6/'Finance Only'!B9)*100 -> 0.38767203 | DY6: =DZ5 -> 69707 | DZ6: 69795 | EA6: =MAX(0,DZ6-DY6) -> 88 | EB6: =EA6-EA5 -> 88 | EC6: =(EA6/'Finance Only'!B9)*100 -> 0.42643923 | ED6: =EE5 -> 222740 | EE6: 222990 | EF6: =MAX(0,EE6-ED6) -> 250 | EG6: =EF6-EF5 -> -10 | EH6: =(EF6/'Finance Only'!B9)*100 -> 1.2114751 | EI6: =EJ5 -> 249880 | EJ6: 250140 | EK6: =MAX(0,EJ6-EI6) -> 260 | EL6: =EK6-EK5 -> -90 | EM6: =(EK6/'Finance Only'!B9)*100 -> 1.2599341 | EN6: =EO5 -> 412830 | EO6: 413280 | EP6: =MAX(0,EO6-EN6) -> 450 | EQ6: =EP6-EP5 -> -20 | ER6: =(EP6/'Finance Only'!B9)*100 -> 2.1806552 | ES6: =ET5 -> 0 | EU6: =MAX(0,ET6-ES6) -> 0 | EV6: =EU6-EU5 -> 0 | EW6: =(EU6/'Finance Only'!B9)*100 -> 0 | EX6: =EY5 -> 0 | EZ6: =MAX(0,EY6-EX6) -> 0 | FA6: =EZ6-EZ5 -> 0 | FB6: =(EZ6/'Finance Only'!G9)*100 -> 0 | FC6: =FD5 -> 0 | FE6: =MAX(0,FD6-FC6) -> 0 | FF6: =FE6-FE5 -> 0 | FG6: =(FE6/'Finance Only'!M9)*100 -> #DIV/0! | FM6: =FN5 -> 0 | FO6: =MAX(0,FN6-FM6) -> 0 | FP6: =FO6-FO5 -> 0 | FQ6: =(FO6/'Finance Only'!R9)*100 -> #DIV/0! | FR6: =FS5 -> 0 | FT6: =MAX(0,FS6-FR6) -> 0 | FU6: =FT6-FT5 -> 0 | FV6: =(FT6/'Finance Only'!W9)*100 -> #DIV/0! | FW6: =FX5 -> 0 | FY6: =MAX(0,FX6-FW6) -> 0 | FZ6: =FY6-FY5 -> 0 | GA6: =(FY6/'Finance Only'!AB9)*100 -> #DIV/0! | GC6: =SUM(E6+J6) -> 5908 | GE6: =SUM(T6+Y6+EA6+EF6+EK6+EP6) -> 5963 | GG6: =SUM(AO6+AT6) -> 2100 | GI6: =SUM(AY6+BD6+BI6) -> 958 | GK6: =SUM(BN6+BS6+EU6) -> 620 | GM6: =SUM(EZ6+FE6) -> 0
A7: 3 | B7: ='Finance Only'!G10 -> 14.6 | C7: =D6 -> 26999417 | D7: 27001955 | E7: =MAX(0,D7-C7) -> 2538 | F7: =E7-E6 -> 95 | G7: =(E7/'Finance Only'!B10)*100 -> 12.322781 | H7: =I6 -> 24899691 | I7: 24903145 | J7: =MAX(0,I7-H7) -> 3454 | K7: =J7-J6 -> -11 | L7: =(J7/'Finance Only'!B10)*100 -> 16.770247 | M7: =N6 -> 91835969 | N7: 91845685 | O7: =MAX(0,N7-M7) -> 9716 | P7: =O7-O6 -> 222 | Q7: =(O7/'Finance Only'!B10)*100 -> 47.174209 | R7: =S6 -> 3004200 | S7: 3006400 | T7: =MAX(0,S7-R7) -> 2200 | U7: =T7-T6 -> -100 | V7: =(T7/'Finance Only'!B10)*100 -> 10.681686 | W7: =X6 -> 4067786 | X7: 4070454 | Y7: =MAX(0,X7-W7) -> 2668 | Z7: =Y7-Y6 -> 53 | AA7: =(Y7/'Finance Only'!B10)*100 -> 12.953972 | AB7: =AC6 -> 2643700 | AC7: 2645400 | AD7: =MAX(0,AC7-AB7) -> 1700 | AE7: =AD7/WATER!V8 -> 5.2469136 | AF7: =AD7-AD6 -> 0 | AG7: =(AD7/'Finance Only'!B10)*100 -> 8.2540299 | AH7: =AI6 -> 1076843 | AI7: 1077379 | AJ7: =MAX(0,AI7-AH7) -> 536 | AK7: =AJ7-AJ6 -> 20 | AL7: =(AJ7/'Finance Only'!B10)*100 -> 2.6024471 | AM7: =AN6 -> 1078700 | AN7: 1079400 | AO7: =MAX(0,AN7-AM7) -> 700 | AP7: =AO7-AO6 -> 0 | AQ7: =(AO7/'Finance Only'!B10)*100 -> 3.3987182 | AR7: =AS6 -> 2435100 | AS7: 2436000 | AT7: =MAX(0,AS7-AR7) -> 900 | AU7: =AT7-AT6 -> -500 | AV7: =(AT7/'Finance Only'!B10)*100 -> 4.3697805 | AW7: =AX6 -> 4540.2 | AX7: 4853.9 | AY7: =MAX(0,AX7-AW7) -> 313.7 | AZ7: =AY7-AY6 -> -14.3 | BA7: =(AY7/'Finance Only'!B10)*100 -> 1.5231113 | BB7: =BC6 -> 985340 | BC7: 985710 | BD7: =MAX(0,BC7-BB7) -> 370 | BE7: =BD7-BD6 -> 40 | BF7: =(BD7/'Finance Only'!B10)*100 -> 1.7964653 | BG7: =BH6 -> 1065600 | BH7: 1065800 | BI7: =MAX(0,BH7-BG7) -> 200 | BJ7: =BI7-BI6 -> -100 | BK7: =(BI7/'Finance Only'!B10)*100 -> 0.97106234 | BL7: =BM6 -> 1577300 | BM7: 1577780 | BN7: =MAX(0,BM7-BL7) -> 480 | BO7: =BN7-BN6 -> -20 | BP7: =(BN7/'Finance Only'!B10)*100 -> 2.3305496 | BQ7: =BR6 -> 132950 | BR7: 133060 | BS7: =MAX(0,BR7-BQ7) -> 110 | BT7: =BS7-BS6 -> -10 | BU7: =(BS7/'Finance Only'!B10)*100 -> 0.53408429 | BV7: =BW6 -> 569540 | BW7: 569900 | BX7: =MAX(0,BW7-BV7) -> 360 | BY7: =BX7-BX6 -> -30 | BZ7: =(BX7/'Finance Only'!B10)*100 -> 1.7479122 | CA7: =CB6 -> 1047700 | CB7: 1048900 | CC7: =MAX(0,CB7-CA7) -> 1200 | CD7: =CC7-CC6 -> 100 | CE7: =(CC7/'Finance Only'!B10)*100 -> 5.8263741 | CF7: =CG6 -> 3395900 | CG7: 3399300 | CH7: =MAX(0,CG7-CF7) -> 3400 | CI7: =CH7-CH6 -> -500 | CJ7: =(CH7/'Finance Only'!B10)*100 -> 16.50806 | CK7: =CL6 -> 805830 | CL7: 806500 | CM7: =MAX(0,CL7-CK7) -> 670 | CN7: =CM7-CM6 -> -50 | CO7: =(CM7/'Finance Only'!B10)*100 -> 3.2530588 | CP7: =CQ6 -> 666140 | CQ7: 666660 | CR7: =MAX(0,CQ7-CP7) -> 520 | CS7: =CR7-CR6 -> 70 | CT7: =(CR7/'Finance Only'!B10)*100 -> 2.5247621 | CU7: =CV6 -> 553460 | CV7: 553890 | CW7: =MAX(0,CV7-CU7) -> 430 | CX7: =CW7-CW6 -> -40 | CY7: =(CW7/'Finance Only'!B10)*100 -> 2.087784 | CZ7: =DA6 -> 925890 | DA7: 926760 | DB7: =MAX(0,DA7-CZ7) -> 870 | DC7: =DB7-DB6 -> 70 | DD7: =(DB7/'Finance Only'!B10)*100 -> 4.2241212 | DE7: =DF6 -> 707190 | DF7: 707850 | DG7: =MAX(0,DF7-DE7) -> 660 | DH7: =DG7-DG6 -> -40 | DI7: =(DG7/'Finance Only'!B10)*100 -> 3.2045057 | DJ7: =DK6 -> 616360 | DK7: 616930 | DL7: =MAX(0,DK7-DJ7) -> 570 | DM7: =DL7-DL6 -> 0 | DN7: =(DL7/'Finance Only'!B10)*100 -> 2.7675277 | DO7: =DP6 -> 335620 | DP7: 335990 | DQ7: =MAX(0,DP7-DO7) -> 370 | DR7: =DQ7-DQ6 -> -10 | DS7: =(DQ7/'Finance Only'!B10)*100 -> 1.7964653 | DT7: =DU6 -> 109340 | DU7: 109460 | DV7: =MAX(0,DU7-DT7) -> 120 | DW7: =DV7-DV6 -> 40 | DX7: =(DV7/'Finance Only'!B10)*100 -> 0.58263741 | DY7: =DZ6 -> 69795 | DZ7: 69884 | EA7: =MAX(0,DZ7-DY7) -> 89 | EB7: =EA7-EA6 -> 1 | EC7: =(EA7/'Finance Only'!B10)*100 -> 0.43212274 | ED7: =EE6 -> 222990 | EE7: 223250 | EF7: =MAX(0,EE7-ED7) -> 260 | EG7: =EF7-EF6 -> 10 | EH7: =(EF7/'Finance Only'!B10)*100 -> 1.262381 | EI7: =EJ6 -> 250140 | EJ7: 250470 | EK7: =MAX(0,EJ7-EI7) -> 330 | EL7: =EK7-EK6 -> 70 | EM7: =(EK7/'Finance Only'!B10)*100 -> 1.6022529 | EN7: =EO6 -> 413280 | EO7: 413750 | EP7: =MAX(0,EO7-EN7) -> 470 | EQ7: =EP7-EP6 -> 20 | ER7: =(EP7/'Finance Only'!B10)*100 -> 2.2819965 | ES7: =ET6 -> 0 | EU7: =MAX(0,ET7-ES7) -> 0 | EV7: =EU7-EU6 -> 0 | EW7: =(EU7/'Finance Only'!B10)*100 -> 0 | EX7: =EY6 -> 0 | EZ7: =MAX(0,EY7-EX7) -> 0 | FA7: =EZ7-EZ6 -> 0 | FB7: =(EZ7/'Finance Only'!G10)*100 -> 0 | FC7: =FD6 -> 0 | FE7: =MAX(0,FD7-FC7) -> 0 | FF7: =FE7-FE6 -> 0 | FG7: =(FE7/'Finance Only'!M10)*100 -> #DIV/0! | FM7: =FN6 -> 0 | FO7: =MAX(0,FN7-FM7) -> 0 | FP7: =FO7-FO6 -> 0 | FQ7: =(FO7/'Finance Only'!R10)*100 -> #DIV/0! | FR7: =FS6 -> 0 | FT7: =MAX(0,FS7-FR7) -> 0 | FU7: =FT7-FT6 -> 0 | FV7: =(FT7/'Finance Only'!W10)*100 -> #DIV/0! | FW7: =FX6 -> 0 | FY7: =MAX(0,FX7-FW7) -> 0 | FZ7: =FY7-FY6 -> 0 | GA7: =(FY7/'Finance Only'!AB10)*100 -> #DIV/0! | GC7: =SUM(E7+J7) -> 5992 | GE7: =SUM(T7+Y7+EA7+EF7+EK7+EP7) -> 6017 | GG7: =SUM(AO7+AT7) -> 1600 | GI7: =SUM(AY7+BD7+BI7) -> 883.7 | GK7: =SUM(BN7+BS7+EU7) -> 590 | GM7: =SUM(EZ7+FE7) -> 0
A8: 4 | B8: ='Finance Only'!G11 -> 10.7 | C8: =D7 -> 27001955 | D8: 27004548 | E8: =MAX(0,D8-C8) -> 2593 | F8: =E8-E7 -> 55 | G8: =(E8/'Finance Only'!B11)*100 -> 12.070571 | H8: =I7 -> 24903145 | I8: 24906698 | J8: =MAX(0,I8-H8) -> 3553 | K8: =J8-J7 -> 99 | L8: =(J8/'Finance Only'!B11)*100 -> 16.539428 | M8: =N7 -> 91845685 | N8: 91855584 | O8: =MAX(0,N8-M8) -> 9899 | P8: =O8-O7 -> 183 | Q8: =(O8/'Finance Only'!B11)*100 -> 46.080439 | R8: =S7 -> 3006400 | S8: 3008500 | T8: =MAX(0,S8-R8) -> 2100 | U8: =T8-T7 -> -100 | V8: =(T8/'Finance Only'!B11)*100 -> 9.7756261 | W8: =X7 -> 4070454 | X8: 4072997 | Y8: =MAX(0,X8-W8) -> 2543 | Z8: =Y8-Y7 -> -125 | AA8: =(Y8/'Finance Only'!B11)*100 -> 11.837818 | AB8: =AC7 -> 2645400 | AC8: 2646900 | AD8: =MAX(0,AC8-AB8) -> 1500 | AE8: =AD8/WATER!V9 -> 5.0167224 | AF8: =AD8-AD7 -> -200 | AG8: =(AD8/'Finance Only'!B11)*100 -> 6.9825901 | AH8: =AI7 -> 1077379 | AI8: 1077893 | AJ8: =MAX(0,AI8-AH8) -> 514 | AK8: =AJ8-AJ7 -> -22 | AL8: =(AJ8/'Finance Only'!B11)*100 -> 2.3927009 | AM8: =AN7 -> 1079400 | AN8: 1080000 | AO8: =MAX(0,AN8-AM8) -> 600 | AP8: =AO8-AO7 -> -100 | AQ8: =(AO8/'Finance Only'!B11)*100 -> 2.793036 | AR8: =AS7 -> 2436000 | AS8: 2437300 | AT8: =MAX(0,AS8-AR8) -> 1300 | AU8: =AT8-AT7 -> 400 | AV8: =(AT8/'Finance Only'!B11)*100 -> 6.0515781 | AW8: =AX7 -> 4853.9 | AX8: 5181.4 | AY8: =MAX(0,AX8-AW8) -> 327.5 | AZ8: =AY8-AY7 -> 13.8 | BA8: =(AY8/'Finance Only'!B11)*100 -> 1.5245322 | BB8: =BC7 -> 985710 | BC8: 986080 | BD8: =MAX(0,BC8-BB8) -> 370 | BE8: =BD8-BD7 -> 0 | BF8: =(BD8/'Finance Only'!B11)*100 -> 1.7223722 | BG8: =BH7 -> 1065800 | BH8: 1066100 | BI8: =MAX(0,BH8-BG8) -> 300 | BJ8: =BI8-BI7 -> 100 | BK8: =(BI8/'Finance Only'!B11)*100 -> 1.396518 | BL8: =BM7 -> 1577780 | BM8: 1578300 | BN8: =MAX(0,BM8-BL8) -> 520 | BO8: =BN8-BN7 -> 40 | BP8: =(BN8/'Finance Only'!B11)*100 -> 2.4206312 | BQ8: =BR7 -> 133060 | BR8: 133190 | BS8: =MAX(0,BR8-BQ8) -> 130 | BT8: =BS8-BS7 -> 20 | BU8: =(BS8/'Finance Only'!B11)*100 -> 0.60515781 | BV8: =BW7 -> 569900 | BW8: 570300 | BX8: =MAX(0,BW8-BV8) -> 400 | BY8: =BX8-BX7 -> 40 | BZ8: =(BX8/'Finance Only'!B11)*100 -> 1.862024 | CA8: =CB7 -> 1048900 | CB8: 1050000 | CC8: =MAX(0,CB8-CA8) -> 1100 | CD8: =CC8-CC7 -> -100 | CE8: =(CC8/'Finance Only'!B11)*100 -> 5.1205661 | CF8: =CG7 -> 3399300 | CG8: 3403300 | CH8: =MAX(0,CG8-CF8) -> 4000 | CI8: =CH8-CH7 -> 600 | CJ8: =(CH8/'Finance Only'!B11)*100 -> 18.62024 | CK8: =CL7 -> 806500 | CL8: 807230 | CM8: =MAX(0,CL8-CK8) -> 730 | CN8: =CM8-CM7 -> 60 | CO8: =(CM8/'Finance Only'!B11)*100 -> 3.3981938 | CP8: =CQ7 -> 666660 | CQ8: 667240 | CR8: =MAX(0,CQ8-CP8) -> 580 | CS8: =CR8-CR7 -> 60 | CT8: =(CR8/'Finance Only'!B11)*100 -> 2.6999348 | CU8: =CV7 -> 553890 | CV8: 554370 | CW8: =MAX(0,CV8-CU8) -> 480 | CX8: =CW8-CW7 -> 50 | CY8: =(CW8/'Finance Only'!B11)*100 -> 2.2344288 | CZ8: =DA7 -> 926760 | DA8: 927730 | DB8: =MAX(0,DA8-CZ8) -> 970 | DC8: =DB8-DB7 -> 100 | DD8: =(DB8/'Finance Only'!B11)*100 -> 4.5154082 | DE8: =DF7 -> 707850 | DF8: 708530 | DG8: =MAX(0,DF8-DE8) -> 680 | DH8: =DG8-DG7 -> 20 | DI8: =(DG8/'Finance Only'!B11)*100 -> 3.1654408 | DJ8: =DK7 -> 616930 | DK8: 617500 | DL8: =MAX(0,DK8-DJ8) -> 570 | DM8: =DL8-DL7 -> 0 | DN8: =(DL8/'Finance Only'!B11)*100 -> 2.6533842 | DO8: =DP7 -> 335990 | DP8: 336430 | DQ8: =MAX(0,DP8-DO8) -> 440 | DR8: =DQ8-DQ7 -> 70 | DS8: =(DQ8/'Finance Only'!B11)*100 -> 2.0482264 | DT8: =DU7 -> 109460 | DU8: 109570 | DV8: =MAX(0,DU8-DT8) -> 110 | DW8: =DV8-DV7 -> -10 | DX8: =(DV8/'Finance Only'!B11)*100 -> 0.51205661 | DY8: =DZ7 -> 69884 | DZ8: 69975 | EA8: =MAX(0,DZ8-DY8) -> 91 | EB8: =EA8-EA7 -> 2 | EC8: =(EA8/'Finance Only'!B11)*100 -> 0.42361046 | ED8: =EE7 -> 223250 | EE8: 223510 | EF8: =MAX(0,EE8-ED8) -> 260 | EG8: =EF8-EF7 -> 0 | EH8: =(EF8/'Finance Only'!B11)*100 -> 1.2103156 | EI8: =EJ7 -> 250470 | EJ8: 250840 | EK8: =MAX(0,EJ8-EI8) -> 370 | EL8: =EK8-EK7 -> 40 | EM8: =(EK8/'Finance Only'!B11)*100 -> 1.7223722 | EN8: =EO7 -> 413750 | EO8: 414270 | EP8: =MAX(0,EO8-EN8) -> 520 | EQ8: =EP8-EP7 -> 50 | ER8: =(EP8/'Finance Only'!B11)*100 -> 2.4206312 | ES8: =ET7 -> 0 | EU8: =MAX(0,ET8-ES8) -> 0 | EV8: =EU8-EU7 -> 0 | EW8: =(EU8/'Finance Only'!B11)*100 -> 0 | EX8: =EY7 -> 0 | EZ8: =MAX(0,EY8-EX8) -> 0 | FA8: =EZ8-EZ7 -> 0 | FB8: =(EZ8/'Finance Only'!G11)*100 -> 0 | FC8: =FD7 -> 0 | FE8: =MAX(0,FD8-FC8) -> 0 | FF8: =FE8-FE7 -> 0 | FG8: =(FE8/'Finance Only'!M11)*100 -> #DIV/0! | FM8: =FN7 -> 0 | FO8: =MAX(0,FN8-FM8) -> 0 | FP8: =FO8-FO7 -> 0 | FQ8: =(FO8/'Finance Only'!R11)*100 -> #DIV/0! | FR8: =FS7 -> 0 | FT8: =MAX(0,FS8-FR8) -> 0 | FU8: =FT8-FT7 -> 0 | FV8: =(FT8/'Finance Only'!W11)*100 -> #DIV/0! | FW8: =FX7 -> 0 | FY8: =MAX(0,FX8-FW8) -> 0 | FZ8: =FY8-FY7 -> 0 | GA8: =(FY8/'Finance Only'!AB11)*100 -> #DIV/0! | GC8: =SUM(E8+J8) -> 6146 | GE8: =SUM(T8+Y8+EA8+EF8+EK8+EP8) -> 5884 | GG8: =SUM(AO8+AT8) -> 1900 | GI8: =SUM(AY8+BD8+BI8) -> 997.5 | GK8: =SUM(BN8+BS8+EU8) -> 650 | GM8: =SUM(EZ8+FE8) -> 0
A9: 5 | B9: ='Finance Only'!G12 -> 10.7 | C9: =D8 -> 27004548 | D9: 27007034 | E9: =MAX(0,D9-C9) -> 2486 | F9: =E9-E8 -> -107 | G9: =(E9/'Finance Only'!B12)*100 -> 11.974375 | H9: =I8 -> 24906698 | I9: 24909588 | J9: =MAX(0,I9-H9) -> 2890 | K9: =J9-J8 -> -663 | L9: =(J9/'Finance Only'!B12)*100 -> 13.920331 | M9: =N8 -> 91855584 | N9: 91866074 | O9: =MAX(0,N9-M9) -> 10490 | P9: =O9-O8 -> 591 | Q9: =(O9/'Finance Only'!B12)*100 -> 50.527431 | R9: =S8 -> 3008500 | S9: 3010700 | T9: =MAX(0,S9-R9) -> 2200 | U9: =T9-T8 -> 100 | V9: =(T9/'Finance Only'!B12)*100 -> 10.596792 | W9: =X8 -> 4072997 | X9: 4075600 | Y9: =MAX(0,X9-W9) -> 2603 | Z9: =Y9-Y8 -> 60 | AA9: =(Y9/'Finance Only'!B12)*100 -> 12.537932 | AB9: =AC8 -> 2646900 | AC9: 2648400 | AD9: =MAX(0,AC9-AB9) -> 1500 | AE9: =AD9/WATER!V10 -> 5.6603774 | AF9: =AD9-AD8 -> 0 | AG9: =(AD9/'Finance Only'!B12)*100 -> 7.2250855 | AH9: =AI8 -> 1077893 | AI9: 1078472 | AJ9: =MAX(0,AI9-AH9) -> 579 | AK9: =AJ9-AJ8 -> 65 | AL9: =(AJ9/'Finance Only'!B12)*100 -> 2.788883 | AM9: =AN8 -> 1080000 | AN9: 1080600 | AO9: =MAX(0,AN9-AM9) -> 600 | AP9: =AO9-AO8 -> 0 | AQ9: =(AO9/'Finance Only'!B12)*100 -> 2.8900342 | AR9: =AS8 -> 2437300 | AS9: 2438200 | AT9: =MAX(0,AS9-AR9) -> 900 | AU9: =AT9-AT8 -> -400 | AV9: =(AT9/'Finance Only'!B12)*100 -> 4.3350513 | AW9: =AX8 -> 5181.4 | AX9: 5492.2 | AY9: =MAX(0,AX9-AW9) -> 310.8 | AZ9: =AY9-AY8 -> -16.7 | BA9: =(AY9/'Finance Only'!B12)*100 -> 1.4970377 | BB9: =BC8 -> 986080 | BC9: 986460 | BD9: =MAX(0,BC9-BB9) -> 380 | BE9: =BD9-BD8 -> 10 | BF9: =(BD9/'Finance Only'!B12)*100 -> 1.830355 | BG9: =BH8 -> 1066100 | BH9: 1066300 | BI9: =MAX(0,BH9-BG9) -> 200 | BJ9: =BI9-BI8 -> -100 | BK9: =(BI9/'Finance Only'!B12)*100 -> 0.96334473 | BL9: =BM8 -> 1578300 | BM9: 1578700 | BN9: =MAX(0,BM9-BL9) -> 400 | BO9: =BN9-BN8 -> -120 | BP9: =(BN9/'Finance Only'!B12)*100 -> 1.9266895 | BQ9: =BR8 -> 133190 | BR9: 133340 | BS9: =MAX(0,BR9-BQ9) -> 150 | BT9: =BS9-BS8 -> 20 | BU9: =(BS9/'Finance Only'!B12)*100 -> 0.72250855 | BV9: =BW8 -> 570300 | BW9: 570790 | BX9: =MAX(0,BW9-BV9) -> 490 | BY9: =BX9-BX8 -> 90 | BZ9: =(BX9/'Finance Only'!B12)*100 -> 2.3601946 | CA9: =CB8 -> 1050000 | CB9: 1051100 | CC9: =MAX(0,CB9-CA9) -> 1100 | CD9: =CC9-CC8 -> 0 | CE9: =(CC9/'Finance Only'!B12)*100 -> 5.298396 | CF9: =CG8 -> 3403300 | CG9: 3406800 | CH9: =MAX(0,CG9-CF9) -> 3500 | CI9: =CH9-CH8 -> -500 | CJ9: =(CH9/'Finance Only'!B12)*100 -> 16.858533 | CK9: =CL8 -> 807230 | CL9: 807790 | CM9: =MAX(0,CL9-CK9) -> 560 | CN9: =CM9-CM8 -> -170 | CO9: =(CM9/'Finance Only'!B12)*100 -> 2.6973653 | CP9: =CQ8 -> 667240 | CQ9: 667690 | CR9: =MAX(0,CQ9-CP9) -> 450 | CS9: =CR9-CR8 -> -130 | CT9: =(CR9/'Finance Only'!B12)*100 -> 2.1675256 | CU9: =CV8 -> 554370 | CV9: 554680 | CW9: =MAX(0,CV9-CU9) -> 310 | CX9: =CW9-CW8 -> -170 | CY9: =(CW9/'Finance Only'!B12)*100 -> 1.4931843 | CZ9: =DA8 -> 927730 | DA9: 928390 | DB9: =MAX(0,DA9-CZ9) -> 660 | DC9: =DB9-DB8 -> -310 | DD9: =(DB9/'Finance Only'!B12)*100 -> 3.1790376 | DE9: =DF8 -> 708530 | DF9: 709020 | DG9: =MAX(0,DF9-DE9) -> 490 | DH9: =DG9-DG8 -> -190 | DI9: =(DG9/'Finance Only'!B12)*100 -> 2.3601946 | DJ9: =DK8 -> 617500 | DK9: 617930 | DL9: =MAX(0,DK9-DJ9) -> 430 | DM9: =DL9-DL8 -> -140 | DN9: =(DL9/'Finance Only'!B12)*100 -> 2.0711912 | DO9: =DP8 -> 336430 | DP9: 336790 | DQ9: =MAX(0,DP9-DO9) -> 360 | DR9: =DQ9-DQ8 -> -80 | DS9: =(DQ9/'Finance Only'!B12)*100 -> 1.7340205 | DT9: =DU8 -> 109570 | DU9: 109690 | DV9: =MAX(0,DU9-DT9) -> 120 | DW9: =DV9-DV8 -> 10 | DX9: =(DV9/'Finance Only'!B12)*100 -> 0.57800684 | DY9: =DZ8 -> 69975 | DZ9: 70059 | EA9: =MAX(0,DZ9-DY9) -> 84 | EB9: =EA9-EA8 -> -7 | EC9: =(EA9/'Finance Only'!B12)*100 -> 0.40460479 | ED9: =EE8 -> 223510 | EE9: 223790 | EF9: =MAX(0,EE9-ED9) -> 280 | EG9: =EF9-EF8 -> 20 | EH9: =(EF9/'Finance Only'!B12)*100 -> 1.3486826 | EI9: =EJ8 -> 250840 | EJ9: 251130 | EK9: =MAX(0,EJ9-EI9) -> 290 | EL9: =EK9-EK8 -> -80 | EM9: =(EK9/'Finance Only'!B12)*100 -> 1.3968499 | EN9: =EO8 -> 414270 | EO9: 414780 | EP9: =MAX(0,EO9-EN9) -> 510 | EQ9: =EP9-EP8 -> -10 | ER9: =(EP9/'Finance Only'!B12)*100 -> 2.4565291 | ES9: =ET8 -> 0 | EU9: =MAX(0,ET9-ES9) -> 0 | EV9: =EU9-EU8 -> 0 | EW9: =(EU9/'Finance Only'!B12)*100 -> 0 | EX9: =EY8 -> 0 | EZ9: =MAX(0,EY9-EX9) -> 0 | FA9: =EZ9-EZ8 -> 0 | FB9: =(EZ9/'Finance Only'!G12)*100 -> 0 | FC9: =FD8 -> 0 | FE9: =MAX(0,FD9-FC9) -> 0 | FF9: =FE9-FE8 -> 0 | FG9: =(FE9/'Finance Only'!M12)*100 -> #DIV/0! | FM9: =FN8 -> 0 | FO9: =MAX(0,FN9-FM9) -> 0 | FP9: =FO9-FO8 -> 0 | FQ9: =(FO9/'Finance Only'!R12)*100 -> #DIV/0! | FR9: =FS8 -> 0 | FT9: =MAX(0,FS9-FR9) -> 0 | FU9: =FT9-FT8 -> 0 | FV9: =(FT9/'Finance Only'!W12)*100 -> #DIV/0! | FW9: =FX8 -> 0 | FY9: =MAX(0,FX9-FW9) -> 0 | FZ9: =FY9-FY8 -> 0 | GA9: =(FY9/'Finance Only'!AB12)*100 -> #DIV/0! | GC9: =SUM(E9+J9) -> 5376 | GE9: =SUM(T9+Y9+EA9+EF9+EK9+EP9) -> 5967 | GG9: =SUM(AO9+AT9) -> 1500 | GI9: =SUM(AY9+BD9+BI9) -> 890.8 | GK9: =SUM(BN9+BS9+EU9) -> 550 | GM9: =SUM(EZ9+FE9) -> 0
