Workbook

Sheet Sheet1
A1: Site Name | B1: Month | C1: Year | D1: Total (per Unit) bottles cans | E1: Total cost bottles cans | F1: Total (per Unit) cardboard | G1: Total cost cardboard | H1: Total (per Unit) paper | I1: Total cost paper | J1: Total (per Unit) mixed glass | K1: Total cost mixed glass | L1: Total (per Unit) aluminum | M1: Total cost aluminum | N1: Total (per Unit) other plastics | O1: Total cost other plastics | P1: Total (per Unit) soap bars | Q1: Total cost soap bars | R1: Total (per Unit) e waste | S1: Total cost e waste | T1: Total (per Unit) durable goods | U1: Total cost durable goods | V1: Total (per Unit) solid food waste | W1: Total cost solid food waste | X1: Total (per Unit) leftover food | Y1: Total cost leftover food | Z1: Total (per Unit) inedible parts | AA1: Total cost inedible parts | AB1: Total (per Unit) liquid food waste | AC1: Total cost liquid food waste | AD1: Total (per Unit) kitchen grease | AE1: Total cost kitchen grease | AF1: Total (per Unit) liquid hazardous waste | AG1: Total cost liquid hazardous waste | AH1: Total (per Unit) other hazardous waste | AI1: Total cost other hazardous waste | AJ1: Total (per Unit) batteries | AK1: Total cost batteries | AL1: Total (per Unit) light bulbs | AM1: Total cost light bulbs | AN1: Total (per Unit) textiles | AO1: Total cost textiles | AP1: Total (per Unit) paint | AQ1: Total cost paint | AR1: Total (per Unit) recyclable | AS1: Total cost recyclable | AT1: Total (per Unit) commingled recyclables | AU1: Total cost commingled recyclables | AV1: Total (per Unit) paper cardboard | AW1: Total cost paper cardboard | AX1: Total (per Unit) mixed metals | AY1: Total cost mixed metals | AZ1: Total (per Unit) plastics | BA1: Total cost plastics | BB1: Total (per Unit) biodegradable | BC1: Total cost biodegradable | BD1: Total (per Unit) food waste | BE1: Total cost food waste | BF1: Total (per Unit) hazardous waste | BG1: Total cost hazardous waste | BH1: Total (per Unit) universal waste | BI1: Total cost universal waste | BJ1: Total (per Unit) hazardous and universal waste | BK1: Total cost hazardous and universal waste | BL1: Total (per Unit) medical waste | BM1: Total cost medical waste | BN1: Total (per Unit) tin | BO1: Total cost tin
A2: Bali Jimbaran | B2: 1 | C2: 2018 | D2: 220.7 | E2: 0 | F2: 0 | G2: 0 | H2: 0 | I2: 0 | J2: 624.9 | K2: 0 | L2: 0 | M2: 0 | N2: 873.1 | O2: 0 | P2: 0 | Q2: 0 | R2: 0 | S2: 0 | T2: 0 | U2: 0 | V2: 17160 | W2: 8284726 | X2: 0 | Y2: 0 | Z2: 0 | AA2: 0 | AB2: 0 | AC2: 0 | AD2: 0 | AE2: 0 | AF2: 0 | AG2: 0 | AH2: 0 | AI2: 0 | AJ2: 0 | AK2: 0 | AL2: 0 | AM2: 0 | AN2: 0 | AO2: 0 | AP2: 0 | AQ2: 0 | AR2: 0 | AS2: 0 | AT2: 0 | AU2: 0 | AV2: 760.7 | AW2: 0 | AX2: 0 | AY2: 0 | AZ2: 0 | BA2: 0 | BB2: 21450 | BC2: 0 | BD2: 0 | BE2: 0 | BF2: 0 | BG2: 0 | BH2: 0 | BI2: 0 | BJ2: 0 | BK2: 0 | BL2: 0 | BM2: 0 | BN2: 0 | BO2: 0
A3: Bali Jimbaran | B3: 2 | C3: 2018 | D3: 152.9 | E3: 0 | F3: 0 | G3: 0 | H3: 0 | I3: 0 | J3: 661.5 | K3: 0 | L3: 0 | M3: 0 | N3: 463.6 | O3: 0 | P3: 0 | Q3: 0 | R3: 0 | S3: 0 | T3: 0 | U3: 0 | V3: 16590 | W3: 8284726 | X3: 0 | Y3: 0 | Z3: 0 | AA3: 0 | AB3: 0 | AC3: 0 | AD3: 0 | AE3: 0 | AF3: 0 | AG3: 0 | AH3: 0 | AI3: 0 | AJ3: 0 | AK3: 0 | AL3: 0 | AM3: 0 | AN3: 0 | AO3: 0 | AP3: 0 | AQ3: 0 | AR3: 0 | AS3: 0 | AT3: 0 | AU3: 0 | AV3: 496.1 | AW3: 0 | AX3: 0 | AY3: 0 | AZ3: 0 | BA3: 0 | BB3: 18890 | BC3: 0 | BD3: 0 | BE3: 0 | BF3: 0 | BG3: 0 | BH3: 0 | BI3: 0 | BJ3: 0 | BK3: 0 | BL3: 0 | BM3: 0 | BN3: 0 | BO3: 0
A4: Bali Jimbaran | B4: 3 | C4: 2018 | D4: 144.3 | E4: 0 | F4: 0 | G4: 0 | H4: 0 | I4: 0 | J4: 534.6 | K4: 0 | L4: 0 | M4: 0 | N4: 413.2 | O4: 0 | P4: 0 | Q4: 0 | R4: 0 | S4: 0 | T4: 0 | U4: 0 | V4: 17310 | W4: 8284726 | X4: 0 | Y4: 0 | Z4: 0 | AA4: 0 | AB4: 0 | AC4: 0 | AD4: 0 | AE4: 0 | AF4: 0 | AG4: 0 | AH4: 0 | AI4: 0 | AJ4: 0 | AK4: 0 | AL4: 0 | AM4: 0 | AN4: 0 | AO4: 0 | AP4: 0 | AQ4: 0 | AR4: 0 | AS4: 0 | AT4: 0 | AU4: 0 | AV4: 444 | AW4: 0 | AX4: 0 | AY4: 0 | AZ4: 0 | BA4: 0 | BB4: 26010 | BC4: 0 | BD4: 0 | BE4: 0 | BF4: 0 | BG4: 0 | BH4: 0 | BI4: 0 | BJ4: 0 | BK4: 0 | BL4: 0 | BM4: 0 | BN4: 0 | BO4: 0
A5: Bali Jimbaran | B5: 4 | C5: 2018 | D5: 142.5 | E5: 0 | F5: 0 | G5: 0 | H5: 0 | I5: 0 | J5: 493.4 | K5: 0 | L5: 0 | M5: 0 | N5: 429.4 | O5: 0 | P5: 0 | Q5: 0 | R5: 0 | S5: 0 | T5: 0 | U5: 0 | V5: 19184 | W5: 8284726 | X5: 0 | Y5: 0 | Z5: 0 | AA5: 0 | AB5: 0 | AC5: 0 | AD5: 0 | AE5: 0 | AF5: 0 | AG5: 0 | AH5: 0 | AI5: 0 | AJ5: 0 | AK5: 0 | AL5: 0 | AM5: 0 | AN5: 0 | AO5: 0 | AP5: 0 | AQ5: 0 | AR5: 0 | AS5: 0 | AT5: 0 | AU5: 0 | AV5: 429.8 | AW5: 0 | AX5: 0 | AY5: 0 | AZ5: 0 | BA5: 0 | BB5: 15920 | BC5: 0 | BD5: 0 | BE5: 0 | BF5: 0 | BG5: 0 | BH5: 0 | BI5: 0 | BJ5: 0 | BK5: 0 | BL5: 0 | BM5: 0 | BN5: 0 | BO5: 0
A6: Bali Jimbaran | B6: 5 | C6: 2018 | D6: 134.9 | E6: 0 | F6: 0 | G6: 0 | H6: 0 | I6: 0 | J6: 439.8 | K6: 0 | L6: 0 | M6: 0 | N6: 444.6 | O6: 0 | P6: 0 | Q6: 0 | R6: 0 | S6: 0 | T6: 0 | U6: 0 | V6: 17570 | W6: 8284726 | X6: 0 | Y6: 0 | Z6: 0 | AA6: 0 | AB6: 0 | AC6: 0 | AD6: 0 | AE6: 0 | AF6: 0 | AG6: 0 | AH6: 0 | AI6: 0 | AJ6: 0 | AK6: 0 | AL6: 0 | AM6: 0 | AN6: 0 | AO6: 0 | AP6: 0 | AQ6: 0 | AR6: 0 | AS6: 0 | AT6: 0 | AU6: 0 | AV6: 425.7 | AW6: 0 | AX6: 0 | AY6: 0 | AZ6: 0 | BA6: 0 | BB6: 20360 | BC6: 0 | BD6: 0 | BE6: 0 | BF6: 0 | BG6: 0 | BH6: 0 | BI6: 0 | BJ6: 0 | BK6: 0 | BL6: 0 | BM6: 0 | BN6: 0 | BO6: 0
A7: Bali Jimbaran | B7: 6 | C7: 2018
A8: Bali Jimbaran | B8: 7 | C8: 2018
A9: Bali Jimbaran | B9: 8 | C9: 2018
A10: Bali Jimbaran | B10: 9 | C10: 2018
A11: Bali Jimbaran | B11: 10 | C11: 2018
A12: Bali Jimbaran | B12: 11 | C12: 2018
A13: Bali Jimbaran | B13: 12 | C13: 2018

Sheet TOTAL
A1: Site Name | B1: Day | C1: Month | D1: Year | E1: Total (per Unit) bottles cans | F1: Total cost bottles cans | G1: Total (per Unit) cardboard | H1: Total cost cardboard | I1: Total (per Unit) paper | J1: Total cost paper | K1: Total (per Unit) mixed glass | L1: Total cost mixed glass | M1: Total (per Unit) aluminum | N1: Total cost aluminum | O1: Total (per Unit) other plastics | P1: Total cost other plastics | Q1: Total (per Unit) soap bars | R1: Total cost soap bars | S1: Total (per Unit) e waste | T1: Total cost e waste | U1: Total (per Unit) durable goods | V1: Total cost durable goods | W1: Total (per Unit) solid food waste | X1: Total cost solid food waste | Y1: Total (per Unit) leftover food | Z1: Total cost leftover food | AA1: Total (per Unit) inedible parts | AB1: Total cost inedible parts | AC1: Total (per Unit) liquid food waste | AD1: Total cost liquid food waste | AE1: Total (per Unit) kitchen grease | AF1: Total cost kitchen grease | AG1: Total (per Unit) liquid hazardous waste | AH1: Total cost liquid hazardous waste | AI1: Total (per Unit) other hazardous waste | AJ1: Total cost other hazardous waste | AK1: Total (per Unit) batteries | AL1: Total cost batteries | AM1: Total (per Unit) light bulbs | AN1: Total cost light bulbs | AO1: Total (per Unit) textiles | AP1: Total cost textiles | AQ1: Total (per Unit) paint | AR1: Total cost paint | AS1: Total (per Unit) recyclable | AT1: Total cost recyclable | AU1: Total (per Unit) commingled recyclables | AV1: Total cost commingled recyclables | AW1: Total (per Unit) paper cardboard | AX1: Total cost paper cardboard | AY1: Total (per Unit) mixed metals | AZ1: Total cost mixed metals | BA1: Total (per Unit) plastics | BB1: Total cost plastics | BC1: Total (per Unit) biodegradable | BD1: Total cost biodegradable | BE1: Total (per Unit) food waste | BF1: Total cost food waste | BG1: Total (per Unit) hazardous waste | BH1: Total cost hazardous waste | BI1: Total (per Unit) universal waste | BJ1: Total cost universal waste | BK1: Total (per Unit) hazardous and universal waste | BL1: Total cost hazardous and universal waste | BM1: Total (per Unit) medical waste | BN1: Total cost medical waste | BO1: Total (per Unit) tin | BP1: Total cost tin
A2: Bali Jimbaran | B2: 1 | C2: 5 | D2: 2018 | E2: ='FS Jimbaran May 2018'!M12 -> 3.7 | F2: ='FS Jimbaran May 2018'!N12 -> 0 | G2: 0 | H2: ='FS Jimbaran May 2018'!H12 -> 0 | I2: ='FS Jimbaran May 2018'!I12 -> 0 | J2: ='FS Jimbaran May 2018'!J12 -> 0 | K2: ='FS Jimbaran May 2018'!K12 -> 12.6 | L2: ='FS Jimbaran May 2018'!L12 -> 0 | M2: ='FS Jimbaran May 2018'!S12 -> 0 | N2: ='FS Jimbaran May 2018'!T12 -> 0 | O2: ='FS Jimbaran May 2018'!U12 -> 16.2 | P2: ='FS Jimbaran May 2018'!V12 -> 0 | Q2: ='FS Jimbaran May 2018'!BE12 -> 0 | R2: ='FS Jimbaran May 2018'!BF12 -> 0 | S2: ='FS Jimbaran May 2018'!BH12 -> 0 | T2: ='FS Jimbaran May 2018'!BH12 -> 0 | U2: ='FS Jimbaran May 2018'!BI12 -> 0 | V2: ='FS Jimbaran May 2018'!BJ12 -> 0 | W2: ='FS Jimbaran May 2018'!Y12 -> 650 | X2: ='FS Jimbaran May 2018'!Z12 -> 8284726 | Y2: ='FS Jimbaran May 2018'!AA12 -> 0 | Z2: ='FS Jimbaran May 2018'!AB12 -> 0 | AA2: ='FS Jimbaran May 2018'!AC12 -> 0 | AB2: ='FS Jimbaran May 2018'!AD12 -> 0 | AC2: ='FS Jimbaran May 2018'!AE12 -> 0 | AD2: ='FS Jimbaran May 2018'!AF12 -> 0 | ... AF2: ='FS Jimbaran May 2018'!AH12 -> 0 | AG2: ='FS Jimbaran May 2018'!AM12 -> 0 | AH2: ='FS Jimbaran May 2018'!AR12 -> 0 | AI2: ='FS Jimbaran May 2018'!AQ12 -> 0 | AJ2: ='FS Jimbaran May 2018'!AR12 -> 0 | AK2: ='FS Jimbaran May 2018'!AY12 -> 0 | AL2: ='FS Jimbaran May 2018'!AZ12 -> 0 | AM2: ='FS Jimbaran May 2018'!BB12 -> 0 | AN2: ='FS Jimbaran May 2018'!BB12 -> 0 | AO2: ='FS Jimbaran May 2018'!BK12 -> 0 | AP2: ='FS Jimbaran May 2018'!BL12 -> 0 | AQ2: ='FS Jimbaran May 2018'!BC12 -> 0 | AR2: ='FS Jimbaran May 2018'!BD12 -> 0 | AS2: ='FS Jimbaran May 2018'!BM12 -> 0 | AT2: ='FS Jimbaran May 2018'!BN12 -> 0 | AU2: ='FS Jimbaran May 2018'!BO12 -> 0 | AV2: ='FS Jimbaran May 2018'!BP12 -> 0 | AW2: ='FS Jimbaran May 2018'!E12 -> 10.1 | AX2: ='FS Jimbaran May 2018'!F12 -> 0 | AY2: ='FS Jimbaran May 2018'!O12 -> 0 | AZ2: ='FS Jimbaran May 2018'!P12 -> 0 | BA2: ='FS Jimbaran May 2018'!W12 -> 0 | BB2: ='FS Jimbaran May 2018'!X12 -> 0 | BC2: ='FS Jimbaran May 2018'!AI12 -> 570 | BD2: ='FS Jimbaran May 2018'!AJ12 -> 0 | BE2: ='FS Jimbaran May 2018'!AK12 -> 0 | BF2: ='FS Jimbaran May 2018'!AL12 -> 0 | BG2: ='FS Jimbaran May 2018'!AM12 -> 0 | BH2: ='FS Jimbaran May 2018'!AN12 -> 0 | BI2: ='FS Jimbaran May 2018'!AO12 -> 0 | BJ2: ='FS Jimbaran May 2018'!AO12 -> 0 | BK2: ='FS Jimbaran May 2018'!AQ12 -> 0 | BL2: ='FS Jimbaran May 2018'!AR12 -> 0 | BM2: 0 | BN2: 0 | BO2: ='FS Jimbaran May 2018'!Q12 -> 0 | BP2: ='FS Jimbaran May 2018'!R12 -> 0
A3: Bali Jimbaran | B3: =B2+1 -> 2 | C3: 5 | D3: 2018 | E3: ='FS Jimbaran May 2018'!M13 -> 3.3 | F3: ='FS Jimbaran May 2018'!N13 -> 0 | G3: 0 | H3: ='FS Jimbaran May 2018'!H13 -> 0 | I3: ='FS Jimbaran May 2018'!I13 -> 0 | J3: ='FS Jimbaran May 2018'!J13 -> 0 | K3: ='FS Jimbaran May 2018'!K13 -> 14.5 | L3: ='FS Jimbaran May 2018'!L13 -> 0 | M3: ='FS Jimbaran May 2018'!S13 -> 0 | N3: ='FS Jimbaran May 2018'!T13 -> 0 | O3: ='FS Jimbaran May 2018'!U13 -> 18.2 | P3: ='FS Jimbaran May 2018'!V13 -> 0 | Q3: ='FS Jimbaran May 2018'!BE13 -> 0 | R3: ='FS Jimbaran May 2018'!BF13 -> 0 | S3: ='FS Jimbaran May 2018'!BH13 -> 0 | T3: ='FS Jimbaran May 2018'!BH13 -> 0 | U3: ='FS Jimbaran May 2018'!BI13 -> 0 | V3: ='FS Jimbaran May 2018'!BJ13 -> 0 | W3: ='FS Jimbaran May 2018'!Y13 -> 570 | X3: ='FS Jimbaran May 2018'!Z13 -> 0 | Y3: ='FS Jimbaran May 2018'!AA13 -> 0 | Z3: ='FS Jimbaran May 2018'!AB13 -> 0 | AA3: ='FS Jimbaran May 2018'!AC13 -> 0 | AB3: ='FS Jimbaran May 2018'!AD13 -> 0 | AC3: ='FS Jimbaran May 2018'!AE13 -> 0 | AD3: ='FS Jimbaran May 2018'!AF13 -> 0 | ... AF3: ='FS Jimbaran May 2018'!AH13 -> 0 | AG3: ='FS Jimbaran May 2018'!AM13 -> 0 | AH3: ='FS Jimbaran May 2018'!AR13 -> 0 | AI3: ='FS Jimbaran May 2018'!AQ13 -> 0 | AJ3: ='FS Jimbaran May 2018'!AR13 -> 0 | AK3: ='FS Jimbaran May 2018'!AY13 -> 0 | AL3: ='FS Jimbaran May 2018'!AZ13 -> 0 | AM3: ='FS Jimbaran May 2018'!BB13 -> 0 | AN3: ='FS Jimbaran May 2018'!BB13 -> 0 | AO3: ='FS Jimbaran May 2018'!BK13 -> 0 | AP3: ='FS Jimbaran May 2018'!BL13 -> 0 | AQ3: ='FS Jimbaran May 2018'!BC13 -> 0 | AR3: ='FS Jimbaran May 2018'!BD13 -> 0 | AS3: ='FS Jimbaran May 2018'!BM13 -> 0 | AT3: ='FS Jimbaran May 2018'!BN13 -> 0 | AU3: ='FS Jimbaran May 2018'!BO13 -> 0 | AV3: ='FS Jimbaran May 2018'!BP13 -> 0 | AW3: ='FS Jimbaran May 2018'!E13 -> 9.1 | AX3: ='FS Jimbaran May 2018'!F13 -> 0 | AY3: ='FS Jimbaran May 2018'!O13 -> 0 | AZ3: ='FS Jimbaran May 2018'!P13 -> 0 | BA3: ='FS Jimbaran May 2018'!W13 -> 0 | BB3: ='FS Jimbaran May 2018'!X13 -> 0 | BC3: ='FS Jimbaran May 2018'!AI13 -> 520 | BD3: ='FS Jimbaran May 2018'!AJ13 -> 0 | BE3: ='FS Jimbaran May 2018'!AK13 -> 0 | BF3: ='FS Jimbaran May 2018'!AL13 -> 0 | BG3: ='FS Jimbaran May 2018'!AM13 -> 0 | BH3: ='FS Jimbaran May 2018'!AN13 -> 0 | BI3: ='FS Jimbaran May 2018'!AO13 -> 0 | BJ3: ='FS Jimbaran May 2018'!AO13 -> 0 | BK3: ='FS Jimbaran May 2018'!AQ13 -> 0 | BL3: ='FS Jimbaran May 2018'!AR13 -> 0 | BM3: 0 | BN3: 0 | BO3: ='FS Jimbaran May 2018'!Q13 -> 0 | BP3: ='FS Jimbaran May 2018'!R13 -> 0
A4: Bali Jimbaran | B4: =B3+1 -> 3 | C4: 5 | D4: 2018 | E4: ='FS Jimbaran May 2018'!M14 -> 1.9 | F4: ='FS Jimbaran May 2018'!N14 -> 0 | G4: 0 | H4: ='FS Jimbaran May 2018'!H14 -> 0 | I4: ='FS Jimbaran May 2018'!I14 -> 0 | J4: ='FS Jimbaran May 2018'!J14 -> 0 | K4: ='FS Jimbaran May 2018'!K14 -> 11.9 | L4: ='FS Jimbaran May 2018'!L14 -> 0 | M4: ='FS Jimbaran May 2018'!S14 -> 0 | N4: ='FS Jimbaran May 2018'!T14 -> 0 | O4: ='FS Jimbaran May 2018'!U14 -> 10.6 | P4: ='FS Jimbaran May 2018'!V14 -> 0 | Q4: ='FS Jimbaran May 2018'!BE14 -> 0 | R4: ='FS Jimbaran May 2018'!BF14 -> 0 | S4: ='FS Jimbaran May 2018'!BH14 -> 0 | T4: ='FS Jimbaran May 2018'!BH14 -> 0 | U4: ='FS Jimbaran May 2018'!BI14 -> 0 | V4: ='FS Jimbaran May 2018'!BJ14 -> 0 | W4: ='FS Jimbaran May 2018'!Y14 -> 470 | X4: ='FS Jimbaran May 2018'!Z14 -> 0 | Y4: ='FS Jimbaran May 2018'!AA14 -> 0 | Z4: ='FS Jimbaran May 2018'!AB14 -> 0 | AA4: ='FS Jimbaran May 2018'!AC14 -> 0 | AB4: ='FS Jimbaran May 2018'!AD14 -> 0 | AC4: ='FS Jimbaran May 2018'!AE14 -> 0 | AD4: ='FS Jimbaran May 2018'!AF14 -> 0 | ... AF4: ='FS Jimbaran May 2018'!AH14 -> 0 | AG4: ='FS Jimbaran May 2018'!AM14 -> 0 | AH4: ='FS Jimbaran May 2018'!AR14 -> 0 | AI4: ='FS Jimbaran May 2018'!AQ14 -> 0 | AJ4: ='FS Jimbaran May 2018'!AR14 -> 0 | AK4: ='FS Jimbaran May 2018'!AY14 -> 0 | AL4: ='FS Jimbaran May 2018'!AZ14 -> 0 | AM4: ='FS Jimbaran May 2018'!BB14 -> 0 | AN4: ='FS Jimbaran May 2018'!BB14 -> 0 | AO4: ='FS Jimbaran May 2018'!BK14 -> 0 | AP4: ='FS Jimbaran May 2018'!BL14 -> 0 | AQ4: ='FS Jimbaran May 2018'!BC14 -> 0 | AR4: ='FS Jimbaran May 2018'!BD14 -> 0 | AS4: ='FS Jimbaran May 2018'!BM14 -> 0 | AT4: ='FS Jimbaran May 2018'!BN14 -> 0 | AU4: ='FS Jimbaran May 2018'!BO14 -> 0 | AV4: ='FS Jimbaran May 2018'!BP14 -> 0 | AW4: ='FS Jimbaran May 2018'!E14 -> 8.7 | AX4: ='FS Jimbaran May 2018'!F14 -> 0 | AY4: ='FS Jimbaran May 2018'!O14 -> 0 | AZ4: ='FS Jimbaran May 2018'!P14 -> 0 | BA4: ='FS Jimbaran May 2018'!W14 -> 0 | BB4: ='FS Jimbaran May 2018'!X14 -> 0 | BC4: ='FS Jimbaran May 2018'!AI14 -> 510 | BD4: ='FS Jimbaran May 2018'!AJ14 -> 0 | BE4: ='FS Jimbaran May 2018'!AK14 -> 0 | BF4: ='FS Jimbaran May 2018'!AL14 -> 0 | BG4: ='FS Jimbaran May 2018'!AM14 -> 0 | BH4: ='FS Jimbaran May 2018'!AN14 -> 0 | BI4: ='FS Jimbaran May 2018'!AO14 -> 0 | BJ4: ='FS Jimbaran May 2018'!AO14 -> 0 | BK4: ='FS Jimbaran May 2018'!AQ14 -> 0 | BL4: ='FS Jimbaran May 2018'!AR14 -> 0 | BM4: 0 | BN4: 0 | BO4: ='FS Jimbaran May 2018'!Q14 -> 0 | BP4: ='FS Jimbaran May 2018'!R14 -> 0
A5: Bali Jimbaran | B5: =B4+1 -> 4 | C5: 5 | D5: 2018 | E5: ='FS Jimbaran May 2018'!M15 -> 2.6 | F5: ='FS Jimbaran May 2018'!N15 -> 0 | G5: 0 | H5: ='FS Jimbaran May 2018'!H15 -> 0 | I5: ='FS Jimbaran May 2018'!I15 -> 0 | J5: ='FS Jimbaran May 2018'!J15 -> 0 | K5: ='FS Jimbaran May 2018'!K15 -> 16 | L5: ='FS Jimbaran May 2018'!L15 -> 0 | M5: ='FS Jimbaran May 2018'!S15 -> 0 | N5: ='FS Jimbaran May 2018'!T15 -> 0 | O5: ='FS Jimbaran May 2018'!U15 -> 16.2 | P5: ='FS Jimbaran May 2018'!V15 -> 0 | Q5: ='FS Jimbaran May 2018'!BE15 -> 0 | R5: ='FS Jimbaran May 2018'!BF15 -> 0 | S5: ='FS Jimbaran May 2018'!BH15 -> 0 | T5: ='FS Jimbaran May 2018'!BH15 -> 0 | U5: ='FS Jimbaran May 2018'!BI15 -> 0 | V5: ='FS Jimbaran May 2018'!BJ15 -> 0 | W5: ='FS Jimbaran May 2018'!Y15 -> 510 | X5: ='FS Jimbaran May 2018'!Z15 -> 0 | Y5: ='FS Jimbaran May 2018'!AA15 -> 0 | Z5: ='FS Jimbaran May 2018'!AB15 -> 0 | AA5: ='FS Jimbaran May 2018'!AC15 -> 0 | AB5: ='FS Jimbaran May 2018'!AD15 -> 0 | AC5: ='FS Jimbaran May 2018'!AE15 -> 0 | AD5: ='FS Jimbaran May 2018'!AF15 -> 0 | ... AF5: ='FS Jimbaran May 2018'!AH15 -> 0 | AG5: ='FS Jimbaran May 2018'!AM15 -> 0 | AH5: ='FS Jimbaran May 2018'!AR15 -> 0 | AI5: ='FS Jimbaran May 2018'!AQ15 -> 0 | AJ5: ='FS Jimbaran May 2018'!AR15 -> 0 | AK5: ='FS Jimbaran May 2018'!AY15 -> 0 | AL5: ='FS Jimbaran May 2018'!AZ15 -> 0 | AM5: ='FS Jimbaran May 2018'!BB15 -> 0 | AN5: ='FS Jimbaran May 2018'!BB15 -> 0 | AO5: ='FS Jimbaran May 2018'!BK15 -> 0 | AP5: ='FS Jimbaran May 2018'!BL15 -> 0 | AQ5: ='FS Jimbaran May 2018'!BC15 -> 0 | AR5: ='FS Jimbaran May 2018'!BD15 -> 0 | AS5: ='FS Jimbaran May 2018'!BM15 -> 0 | AT5: ='FS Jimbaran May 2018'!BN15 -> 0 | AU5: ='FS Jimbaran May 2018'!BO15 -> 0 | AV5: ='FS Jimbaran May 2018'!BP15 -> 0 | AW5: ='FS Jimbaran May 2018'!E15 -> 9.1 | AX5: ='FS Jimbaran May 2018'!F15 -> 0 | AY5: ='FS Jimbaran May 2018'!O15 -> 0 | AZ5: ='FS Jimbaran May 2018'!P15 -> 0 | BA5: ='FS Jimbaran May 2018'!W15 -> 0 | BB5: ='FS Jimbaran May 2018'!X15 -> 0 | BC5: ='FS Jimbaran May 2018'!AI15 -> 550 | BD5: ='FS Jimbaran May 2018'!AJ15 -> 0 | BE5: ='FS Jimbaran May 2018'!AK15 -> 0 | BF5: ='FS Jimbaran May 2018'!AL15 -> 0 | BG5: ='FS Jimbaran May 2018'!AM15 -> 0 | BH5: ='FS Jimbaran May 2018'!AN15 -> 0 | BI5: ='FS Jimbaran May 2018'!AO15 -> 0 | BJ5: ='FS Jimbaran May 2018'!AO15 -> 0 | BK5: ='FS Jimbaran May 2018'!AQ15 -> 0 | BL5: ='FS Jimbaran May 2018'!AR15 -> 0 | BM5: 0 | BN5: 0 | BO5: ='FS Jimbaran May 2018'!Q15 -> 0 | BP5: ='FS Jimbaran May 2018'!R15 -> 0
A6: Bali Jimbaran | B6: =B5+1 -> 5 | C6: 5 | D6: 2018 | E6: ='FS Jimbaran May 2018'!M16 -> 3.5 | F6: ='FS Jimbaran May 2018'!N16 -> 0 | G6: 0 | H6: ='FS Jimbaran May 2018'!H16 -> 0 | I6: ='FS Jimbaran May 2018'!I16 -> 0 | J6: ='FS Jimbaran May 2018'!J16 -> 0 | K6: ='FS Jimbaran May 2018'!K16 -> 19.7 | L6: ='FS Jimbaran May 2018'!L16 -> 0 | M6: ='FS Jimbaran May 2018'!S16 -> 0 | N6: ='FS Jimbaran May 2018'!T16 -> 0 | O6: ='FS Jimbaran May 2018'!U16 -> 14.6 | P6: ='FS Jimbaran May 2018'!V16 -> 0 | Q6: ='FS Jimbaran May 2018'!BE16 -> 0 | R6: ='FS Jimbaran May 2018'!BF16 -> 0 | S6: ='FS Jimbaran May 2018'!BH16 -> 0 | T6: ='FS Jimbaran May 2018'!BH16 -> 0 | U6: ='FS Jimbaran May 2018'!BI16 -> 0 | V6: ='FS Jimbaran May 2018'!BJ16 -> 0 | W6: ='FS Jimbaran May 2018'!Y16 -> 630 | X6: ='FS Jimbaran May 2018'!Z16 -> 0 | Y6: ='FS Jimbaran May 2018'!AA16 -> 0 | Z6: ='FS Jimbaran May 2018'!AB16 -> 0 | AA6: ='FS Jimbaran May 2018'!AC16 -> 0 | AB6: ='FS Jimbaran May 2018'!AD16 -> 0 | AC6: ='FS Jimbaran May 2018'!AE16 -> 0 | AD6: ='FS Jimbaran May 2018'!AF16 -> 0 | ... AF6: ='FS Jimbaran May 2018'!AH16 -> 0 | AG6: ='FS Jimbaran May 2018'!AM16 -> 0 | AH6: ='FS Jimbaran May 2018'!AR16 -> 0 | AI6: ='FS Jimbaran May 2018'!AQ16 -> 0 | AJ6: ='FS Jimbaran May 2018'!AR16 -> 0 | AK6: ='FS Jimbaran May 2018'!AY16 -> 0 | AL6: ='FS Jimbaran May 2018'!AZ16 -> 0 | AM6: ='FS Jimbaran May 2018'!BB16 -> 0 | AN6: ='FS Jimbaran May 2018'!BB16 -> 0 | AO6: ='FS Jimbaran May 2018'!BK16 -> 0 | AP6: ='FS Jimbaran May 2018'!BL16 -> 0 | AQ6: ='FS Jimbaran May 2018'!BC16 -> 0 | AR6: ='FS Jimbaran May 2018'!BD16 -> 0 | AS6: ='FS Jimbaran May 2018'!BM16 -> 0 | AT6: ='FS Jimbaran May 2018'!BN16 -> 0 | AU6: ='FS Jimbaran May 2018'!BO16 -> 0 | AV6: ='FS Jimbaran May 2018'!BP16 -> 0 | AW6: ='FS Jimbaran May 2018'!E16 -> 8.8 | AX6: ='FS Jimbaran May 2018'!F16 -> 0 | AY6: ='FS Jimbaran May 2018'!O16 -> 0 | AZ6: ='FS Jimbaran May 2018'!P16 -> 0 | BA6: ='FS Jimbaran May 2018'!W16 -> 0 | BB6: ='FS Jimbaran May 2018'!X16 -> 0 | BC6: ='FS Jimbaran May 2018'!AI16 -> 750 | BD6: ='FS Jimbaran May 2018'!AJ16 -> 0 | BE6: ='FS Jimbaran May 2018'!AK16 -> 0 | BF6: ='FS Jimbaran May 2018'!AL16 -> 0 | BG6: ='FS Jimbaran May 2018'!AM16 -> 0 | BH6: ='FS Jimbaran May 2018'!AN16 -> 0 | BI6: ='FS Jimbaran May 2018'!AO16 -> 0 | BJ6: ='FS Jimbaran May 2018'!AO16 -> 0 | BK6: ='FS Jimbaran May 2018'!AQ16 -> 0 | BL6: ='FS Jimbaran May 2018'!AR16 -> 0 | BM6: 0 | BN6: 0 | BO6: ='FS Jimbaran May 2018'!Q16 -> 0 | BP6: ='FS Jimbaran May 2018'!R16 -> 0
A7: Bali Jimbaran | B7: =B6+1 -> 6 | C7: 5 | D7: 2018 | E7: ='FS Jimbaran May 2018'!M17 -> 2.3 | F7: ='FS Jimbaran May 2018'!N17 -> 0 | G7: 0 | H7: ='FS Jimbaran May 2018'!H17 -> 0 | I7: ='FS Jimbaran May 2018'!I17 -> 0 | J7: ='FS Jimbaran May 2018'!J17 -> 0 | K7: ='FS Jimbaran May 2018'!K17 -> 12.4 | L7: ='FS Jimbaran May 2018'!L17 -> 0 | M7: ='FS Jimbaran May 2018'!S17 -> 0 | N7: ='FS Jimbaran May 2018'!T17 -> 0 | O7: ='FS Jimbaran May 2018'!U17 -> 5 | P7: ='FS Jimbaran May 2018'!V17 -> 0 | Q7: ='FS Jimbaran May 2018'!BE17 -> 0 | R7: ='FS Jimbaran May 2018'!BF17 -> 0 | S7: ='FS Jimbaran May 2018'!BH17 -> 0 | T7: ='FS Jimbaran May 2018'!BH17 -> 0 | U7: ='FS Jimbaran May 2018'!BI17 -> 0 | V7: ='FS Jimbaran May 2018'!BJ17 -> 0 | W7: ='FS Jimbaran May 2018'!Y17 -> 470 | X7: ='FS Jimbaran May 2018'!Z17 -> 0 | Y7: ='FS Jimbaran May 2018'!AA17 -> 0 | Z7: ='FS Jimbaran May 2018'!AB17 -> 0 | AA7: ='FS Jimbaran May 2018'!AC17 -> 0 | AB7: ='FS Jimbaran May 2018'!AD17 -> 0 | AC7: ='FS Jimbaran May 2018'!AE17 -> 0 | AD7: ='FS Jimbaran May 2018'!AF17 -> 0 | ... AF7: ='FS Jimbaran May 2018'!AH17 -> 0 | AG7: ='FS Jimbaran May 2018'!AM17 -> 0 | AH7: ='FS Jimbaran May 2018'!AR17 -> 0 | AI7: ='FS Jimbaran May 2018'!AQ17 -> 0 | AJ7: ='FS Jimbaran May 2018'!AR17 -> 0 | AK7: ='FS Jimbaran May 2018'!AY17 -> 0 | AL7: ='FS Jimbaran May 2018'!AZ17 -> 0 | AM7: ='FS Jimbaran May 2018'!BB17 -> 0 | AN7: ='FS Jimbaran May 2018'!BB17 -> 0 | AO7: ='FS Jimbaran May 2018'!BK17 -> 0 | AP7: ='FS Jimbaran May 2018'!BL17 -> 0 | AQ7: ='FS Jimbaran May 2018'!BC17 -> 0 | AR7: ='FS Jimbaran May 2018'!BD17 -> 0 | AS7: ='FS Jimbaran May 2018'!BM17 -> 0 | AT7: ='FS Jimbaran May 2018'!BN17 -> 0 | AU7: ='FS Jimbaran May 2018'!BO17 -> 0 | AV7: ='FS Jimbaran May 2018'!BP17 -> 0 | AW7: ='FS Jimbaran May 2018'!E17 -> 10.9 | AX7: ='FS Jimbaran May 2018'!F17 -> 0 | AY7: ='FS Jimbaran May 2018'!O17 -> 0 | AZ7: ='FS Jimbaran May 2018'!P17 -> 0 | BA7: ='FS Jimbaran May 2018'!W17 -> 0 | BB7: ='FS Jimbaran May 2018'!X17 -> 0 | BC7: ='FS Jimbaran May 2018'!AI17 -> 500 | BD7: ='FS Jimbaran May 2018'!AJ17 -> 0 | BE7: ='FS Jimbaran May 2018'!AK17 -> 0 | BF7: ='FS Jimbaran May 2018'!AL17 -> 0 | BG7: ='FS Jimbaran May 2018'!AM17 -> 0 | BH7: ='FS Jimbaran May 2018'!AN17 -> 0 | BI7: ='FS Jimbaran May 2018'!AO17 -> 0 | BJ7: ='FS Jimbaran May 2018'!AO17 -> 0 | BK7: ='FS Jimbaran May 2018'!AQ17 -> 0 | BL7: ='FS Jimbaran May 2018'!AR17 -> 0 | BM7: 0 | BN7: 0 | BO7: ='FS Jimbaran May 2018'!Q17 -> 0 | BP7: ='FS Jimbaran May 2018'!R17 -> 0
A8: Bali Jimbaran | B8: =B7+1 -> 7 | C8: 5 | D8: 2018 | E8: ='FS Jimbaran May 2018'!M18 -> 4.2 | F8: ='FS Jimbaran May 2018'!N18 -> 0 | G8: 0 | H8: ='FS Jimbaran May 2018'!H18 -> 0 | I8: ='FS Jimbaran May 2018'!I18 -> 0 | J8: ='FS Jimbaran May 2018'!J18 -> 0 | K8: ='FS Jimbaran May 2018'!K18 -> 14.1 | L8: ='FS Jimbaran May 2018'!L18 -> 0 | M8: ='FS Jimbaran May 2018'!S18 -> 0 | N8: ='FS Jimbaran May 2018'!T18 -> 0 | O8: ='FS Jimbaran May 2018'!U18 -> 16.2 | P8: ='FS Jimbaran May 2018'!V18 -> 0 | Q8: ='FS Jimbaran May 2018'!BE18 -> 0 | R8: ='FS Jimbaran May 2018'!BF18 -> 0 | S8: ='FS Jimbaran May 2018'!BH18 -> 0 | T8: ='FS Jimbaran May 2018'!BH18 -> 0 | U8: ='FS Jimbaran May 2018'!BI18 -> 0 | V8: ='FS Jimbaran May 2018'!BJ18 -> 0 | W8: ='FS Jimbaran May 2018'!Y18 -> 530 | X8: ='FS Jimbaran May 2018'!Z18 -> 0 | Y8: ='FS Jimbaran May 2018'!AA18 -> 0 | Z8: ='FS Jimbaran May 2018'!AB18 -> 0 | AA8: ='FS Jimbaran May 2018'!AC18 -> 0 | AB8: ='FS Jimbaran May 2018'!AD18 -> 0 | AC8: ='FS Jimbaran May 2018'!AE18 -> 0 | AD8: ='FS Jimbaran May 2018'!AF18 -> 0 | ... AF8: ='FS Jimbaran May 2018'!AH18 -> 0 | AG8: ='FS Jimbaran May 2018'!AM18 -> 0 | AH8: ='FS Jimbaran May 2018'!AR18 -> 0 | AI8: ='FS Jimbaran May 2018'!AQ18 -> 0 | AJ8: ='FS Jimbaran May 2018'!AR18 -> 0 | AK8: ='FS Jimbaran May 2018'!AY18 -> 0 | AL8: ='FS Jimbaran May 2018'!AZ18 -> 0 | AM8: ='FS Jimbaran May 2018'!BB18 -> 0 | AN8: ='FS Jimbaran May 2018'!BB18 -> 0 | AO8: ='FS Jimbaran May 2018'!BK18 -> 0 | AP8: ='FS Jimbaran May 2018'!BL18 -> 0 | AQ8: ='FS Jimbaran May 2018'!BC18 -> 0 | AR8: ='FS Jimbaran May 2018'!BD18 -> 0 | AS8: ='FS Jimbaran May 2018'!BM18 -> 0 | AT8: ='FS Jimbaran May 2018'!BN18 -> 0 | AU8: ='FS Jimbaran May 2018'!BO18 -> 0 | AV8: ='FS Jimbaran May 2018'!BP18 -> 0 | AW8: ='FS Jimbaran May 2018'!E18 -> 10.2 | AX8: ='FS Jimbaran May 2018'!F18 -> 0 | AY8: ='FS Jimbaran May 2018'!O18 -> 0 | AZ8: ='FS Jimbaran May 2018'!P18 -> 0 | BA8: ='FS Jimbaran May 2018'!W18 -> 0 | BB8: ='FS Jimbaran May 2018'!X18 -> 0 | BC8: ='FS Jimbaran May 2018'!AI18 -> 540 | BD8: ='FS Jimbaran May 2018'!AJ18 -> 0 | BE8: ='FS Jimbaran May 2018'!AK18 -> 0 | BF8: ='FS Jimbaran May 2018'!AL18 -> 0 | BG8: ='FS Jimbaran May 2018'!AM18 -> 0 | BH8: ='FS Jimbaran May 2018'!AN18 -> 0 | BI8: ='FS Jimbaran May 2018'!AO18 -> 0 | BJ8: ='FS Jimbaran May 2018'!AO18 -> 0 | BK8: ='FS Jimbaran May 2018'!AQ18 -> 0 | BL8: ='FS Jimbaran May 2018'!AR18 -> 0 | BM8: 0 | BN8: 0 | BO8: ='FS Jimbaran May 2018'!Q18 -> 0 | BP8: ='FS Jimbaran May 2018'!R18 -> 0
A9: Bali Jimbaran | B9: =B8+1 -> 8 | C9: 5 | D9: 2018 | E9: ='FS Jimbaran May 2018'!M19 -> 3.8 | F9: ='FS Jimbaran May 2018'!N19 -> 0 | G9: 0 | H9: ='FS Jimbaran May 2018'!H19 -> 0 | I9: ='FS Jimbaran May 2018'!I19 -> 0 | J9: ='FS Jimbaran May 2018'!J19 -> 0 | K9: ='FS Jimbaran May 2018'!K19 -> 13.3 | L9: ='FS Jimbaran May 2018'!L19 -> 0 | M9: ='FS Jimbaran May 2018'!S19 -> 0 | N9: ='FS Jimbaran May 2018'!T19 -> 0 | O9: ='FS Jimbaran May 2018'!U19 -> 12.6 | P9: ='FS Jimbaran May 2018'!V19 -> 0 | Q9: ='FS Jimbaran May 2018'!BE19 -> 0 | R9: ='FS Jimbaran May 2018'!BF19 -> 0 | S9: ='FS Jimbaran May 2018'!BH19 -> 0 | T9: ='FS Jimbaran May 2018'!BH19 -> 0 | U9: ='FS Jimbaran May 2018'!BI19 -> 0 | V9: ='FS Jimbaran May 2018'!BJ19 -> 0 | W9: ='FS Jimbaran May 2018'!Y19 -> 480 | X9: ='FS Jimbaran May 2018'!Z19 -> 0 | Y9: ='FS Jimbaran May 2018'!AA19 -> 0 | Z9: ='FS Jimbaran May 2018'!AB19 -> 0 | AA9: ='FS Jimbaran May 2018'!AC19 -> 0 | AB9: ='FS Jimbaran May 2018'!AD19 -> 0 | AC9: ='FS Jimbaran May 2018'!AE19 -> 0 | AD9: ='FS Jimbaran May 2018'!AF19 -> 0 | ... AF9: ='FS Jimbaran May 2018'!AH19 -> 0 | AG9: ='FS Jimbaran May 2018'!AM19 -> 0 | AH9: ='FS Jimbaran May 2018'!AR19 -> 0 | AI9: ='FS Jimbaran May 2018'!AQ19 -> 0 | AJ9: ='FS Jimbaran May 2018'!AR19 -> 0 | AK9: ='FS Jimbaran May 2018'!AY19 -> 0 | AL9: ='FS Jimbaran May 2018'!AZ19 -> 0 | AM9: ='FS Jimbaran May 2018'!BB19 -> 0 | AN9: ='FS Jimbaran May 2018'!BB19 -> 0 | AO9: ='FS Jimbaran May 2018'!BK19 -> 0 | AP9: ='FS Jimbaran May 2018'!BL19 -> 0 | AQ9: ='FS Jimbaran May 2018'!BC19 -> 0 | AR9: ='FS Jimbaran May 2018'!BD19 -> 0 | AS9: ='FS Jimbaran May 2018'!BM19 -> 0 | AT9: ='FS Jimbaran May 2018'!BN19 -> 0 | AU9: ='FS Jimbaran May 2018'!BO19 -> 0 | AV9: ='FS Jimbaran May 2018'!BP19 -> 0 | AW9: ='FS Jimbaran May 2018'!E19 -> 10.4 | AX9: ='FS Jimbaran May 2018'!F19 -> 0 | AY9: ='FS Jimbaran May 2018'!O19 -> 0 | AZ9: ='FS Jimbaran May 2018'!P19 -> 0 | BA9: ='FS Jimbaran May 2018'!W19 -> 0 | BB9: ='FS Jimbaran May 2018'!X19 -> 0 | BC9: ='FS Jimbaran May 2018'!AI19 -> 790 | BD9: ='FS Jimbaran May 2018'!AJ19 -> 0 | BE9: ='FS Jimbaran May 2018'!AK19 -> 0 | BF9: ='FS Jimbaran May 2018'!AL19 -> 0 | BG9: ='FS Jimbaran May 2018'!AM19 -> 0 | BH9: ='FS Jimbaran May 2018'!AN19 -> 0 | BI9: ='FS Jimbaran May 2018'!AO19 -> 0 | BJ9: ='FS Jimbaran May 2018'!AO19 -> 0 | BK9: ='FS Jimbaran May 2018'!AQ19 -> 0 | BL9: ='FS Jimbaran May 2018'!AR19 -> 0 | BM9: 0 | BN9: 0 | BO9: ='FS Jimbaran May 2018'!Q19 -> 0 | BP9: ='FS Jimbaran May 2018'!R19 -> 0
A10: Bali Jimbaran | B10: =B9+1 -> 9 | C10: 5 | D10: 2018 | E10: ='FS Jimbaran May 2018'!M20 -> 3.2 | F10: ='FS Jimbaran May 2018'!N20 -> 0 | G10: 0 | H10: ='FS Jimbaran May 2018'!H20 -> 0 | I10: ='FS Jimbaran May 2018'!I20 -> 0 | J10: ='FS Jimbaran May 2018'!J20 -> 0 | K10: ='FS Jimbaran May 2018'!K20 -> 15.9 | L10: ='FS Jimbaran May 2018'!L20 -> 0 | M10: ='FS Jimbaran May 2018'!S20 -> 0 | N10: ='FS Jimbaran May 2018'!T20 -> 0 | O10: ='FS Jimbaran May 2018'!U20 -> 18.2 | P10: ='FS Jimbaran May 2018'!V20 -> 0 | Q10: ='FS Jimbaran May 2018'!BE20 -> 0 | R10: ='FS Jimbaran May 2018'!BF20 -> 0 | S10: ='FS Jimbaran May 2018'!BH20 -> 0 | T10: ='FS Jimbaran May 2018'!BH20 -> 0 | U10: ='FS Jimbaran May 2018'!BI20 -> 0 | V10: ='FS Jimbaran May 2018'!BJ20 -> 0 | W10: ='FS Jimbaran May 2018'!Y20 -> 510 | X10: ='FS Jimbaran May 2018'!Z20 -> 0 | Y10: ='FS Jimbaran May 2018'!AA20 -> 0 | Z10: ='FS Jimbaran May 2018'!AB20 -> 0 | AA10: ='FS Jimbaran May 2018'!AC20 -> 0 | AB10: ='FS Jimbaran May 2018'!AD20 -> 0 | AC10: ='FS Jimbaran May 2018'!AE20 -> 0 | AD10: ='FS Jimbaran May 2018'!AF20 -> 0 | ... AF10: ='FS Jimbaran May 2018'!AH20 -> 0 | AG10: ='FS Jimbaran May 2018'!AM20 -> 0 | AH10: ='FS Jimbaran May 2018'!AR20 -> 0 | AI10: ='FS Jimbaran May 2018'!AQ20 -> 0 | AJ10: ='FS Jimbaran May 2018'!AR20 -> 0 | AK10: ='FS Jimbaran May 2018'!AY20 -> 0 | AL10: ='FS Jimbaran May 2018'!AZ20 -> 0 | AM10: ='FS Jimbaran May 2018'!BB20 -> 0 | AN10: ='FS Jimbaran May 2018'!BB20 -> 0 | AO10: ='FS Jimbaran May 2018'!BK20 -> 0 | AP10: ='FS Jimbaran May 2018'!BL20 -> 0 | AQ10: ='FS Jimbaran May 2018'!BC20 -> 0 | AR10: ='FS Jimbaran May 2018'!BD20 -> 0 | AS10: ='FS Jimbaran May 2018'!BM20 -> 0 | AT10: ='FS Jimbaran May 2018'!BN20 -> 0 | AU10: ='FS Jimbaran May 2018'!BO20 -> 0 | AV10: ='FS Jimbaran May 2018'!BP20 -> 0 | AW10: ='FS Jimbaran May 2018'!E20 -> 8 | AX10: ='FS Jimbaran May 2018'!F20 -> 0 | AY10: ='FS Jimbaran May 2018'!O20 -> 0 | AZ10: ='FS Jimbaran May 2018'!P20 -> 0 | BA10: ='FS Jimbaran May 2018'!W20 -> 0 | BB10: ='FS Jimbaran May 2018'!X20 -> 0 | BC10: ='FS Jimbaran May 2018'!AI20 -> 600 | BD10: ='FS Jimbaran May 2018'!AJ20 -> 0 | BE10: ='FS Jimbaran May 2018'!AK20 -> 0 | BF10: ='FS Jimbaran May 2018'!AL20 -> 0 | BG10: ='FS Jimbaran May 2018'!AM20 -> 0 | BH10: ='FS Jimbaran May 2018'!AN20 -> 0 | BI10: ='FS Jimbaran May 2018'!AO20 -> 0 | BJ10: ='FS Jimbaran May 2018'!AO20 -> 0 | BK10: ='FS Jimbaran May 2018'!AQ20 -> 0 | BL10: ='FS Jimbaran May 2018'!AR20 -> 0 | BM10: 0 | BN10: 0 | BO10: ='FS Jimbaran May 2018'!Q20 -> 0 | BP10: ='FS Jimbaran May 2018'!R20 -> 0
A11: Bali Jimbaran | B11: =B10+1 -> 10 | C11: 5 | D11: 2018 | E11: ='FS Jimbaran May 2018'!M21 -> 6.5 | F11: ='FS Jimbaran May 2018'!N21 -> 0 | G11: 0 | H11: ='FS Jimbaran May 2018'!H21 -> 0 | I11: ='FS Jimbaran May 2018'!I21 -> 0 | J11: ='FS Jimbaran May 2018'!J21 -> 0 | K11: ='FS Jimbaran May 2018'!K21 -> 11.8 | L11: ='FS Jimbaran May 2018'!L21 -> 0 | M11: ='FS Jimbaran May 2018'!S21 -> 0 | N11: ='FS Jimbaran May 2018'!T21 -> 0 | O11: ='FS Jimbaran May 2018'!U21 -> 12.4 | P11: ='FS Jimbaran May 2018'!V21 -> 0 | Q11: ='FS Jimbaran May 2018'!BE21 -> 0 | R11: ='FS Jimbaran May 2018'!BF21 -> 0 | S11: ='FS Jimbaran May 2018'!BH21 -> 0 | T11: ='FS Jimbaran May 2018'!BH21 -> 0 | U11: ='FS Jimbaran May 2018'!BI21 -> 0 | V11: ='FS Jimbaran May 2018'!BJ21 -> 0 | W11: ='FS Jimbaran May 2018'!Y21 -> 450 | X11: ='FS Jimbaran May 2018'!Z21 -> 0 | Y11: ='FS Jimbaran May 2018'!AA21 -> 0 | Z11: ='FS Jimbaran May 2018'!AB21 -> 0 | AA11: ='FS Jimbaran May 2018'!AC21 -> 0 | AB11: ='FS Jimbaran May 2018'!AD21 -> 0 | AC11: ='FS Jimbaran May 2018'!AE21 -> 0 | AD11: ='FS Jimbaran May 2018'!AF21 -> 0 | ... AF11: ='FS Jimbaran May 2018'!AH21 -> 0 | AG11: ='FS Jimbaran May 2018'!AM21 -> 0 | AH11: ='FS Jimbaran May 2018'!AR21 -> 0 | AI11: ='FS Jimbaran May 2018'!AQ21 -> 0 | AJ11: ='FS Jimbaran May 2018'!AR21 -> 0 | AK11: ='FS Jimbaran May 2018'!AY21 -> 0 | AL11: ='FS Jimbaran May 2018'!AZ21 -> 0 | AM11: ='FS Jimbaran May 2018'!BB21 -> 0 | AN11: ='FS Jimbaran May 2018'!BB21 -> 0 | AO11: ='FS Jimbaran May 2018'!BK21 -> 0 | AP11: ='FS Jimbaran May 2018'!BL21 -> 0 | AQ11: ='FS Jimbaran May 2018'!BC21 -> 0 | AR11: ='FS Jimbaran May 2018'!BD21 -> 0 | AS11: ='FS Jimbaran May 2018'!BM21 -> 0 | AT11: ='FS Jimbaran May 2018'!BN21 -> 0 | AU11: ='FS Jimbaran May 2018'!BO21 -> 0 | AV11: ='FS Jimbaran May 2018'!BP21 -> 0 | AW11: ='FS Jimbaran May 2018'!E21 -> 19 | AX11: ='FS Jimbaran May 2018'!F21 -> 0 | AY11: ='FS Jimbaran May 2018'!O21 -> 0 | AZ11: ='FS Jimbaran May 2018'!P21 -> 0 | BA11: ='FS Jimbaran May 2018'!W21 -> 0 | BB11: ='FS Jimbaran May 2018'!X21 -> 0 | BC11: ='FS Jimbaran May 2018'!AI21 -> 690 | BD11: ='FS Jimbaran May 2018'!AJ21 -> 0 | BE11: ='FS Jimbaran May 2018'!AK21 -> 0 | BF11: ='FS Jimbaran May 2018'!AL21 -> 0 | BG11: ='FS Jimbaran May 2018'!AM21 -> 0 | BH11: ='FS Jimbaran May 2018'!AN21 -> 0 | BI11: ='FS Jimbaran May 2018'!AO21 -> 0 | BJ11: ='FS Jimbaran May 2018'!AO21 -> 0 | BK11: ='FS Jimbaran May 2018'!AQ21 -> 0 | BL11: ='FS Jimbaran May 2018'!AR21 -> 0 | BM11: 0 | BN11: 0 | BO11: ='FS Jimbaran May 2018'!Q21 -> 0 | BP11: ='FS Jimbaran May 2018'!R21 -> 0
A12: Bali Jimbaran | B12: =B11+1 -> 11 | C12: 5 | D12: 2018 | E12: ='FS Jimbaran May 2018'!M22 -> 6.1 | F12: ='FS Jimbaran May 2018'!N22 -> 0 | G12: 0 | H12: ='FS Jimbaran May 2018'!H22 -> 0 | I12: ='FS Jimbaran May 2018'!I22 -> 0 | J12: ='FS Jimbaran May 2018'!J22 -> 0 | K12: ='FS Jimbaran May 2018'!K22 -> 10.1 | L12: ='FS Jimbaran May 2018'!L22 -> 0 | M12: ='FS Jimbaran May 2018'!S22 -> 0 | N12: ='FS Jimbaran May 2018'!T22 -> 0 | O12: ='FS Jimbaran May 2018'!U22 -> 17 | P12: ='FS Jimbaran May 2018'!V22 -> 0 | Q12: ='FS Jimbaran May 2018'!BE22 -> 0 | R12: ='FS Jimbaran May 2018'!BF22 -> 0 | S12: ='FS Jimbaran May 2018'!BH22 -> 0 | T12: ='FS Jimbaran May 2018'!BH22 -> 0 | U12: ='FS Jimbaran May 2018'!BI22 -> 0 | V12: ='FS Jimbaran May 2018'!BJ22 -> 0 | W12: ='FS Jimbaran May 2018'!Y22 -> 470 | X12: ='FS Jimbaran May 2018'!Z22 -> 0 | Y12: ='FS Jimbaran May 2018'!AA22 -> 0 | Z12: ='FS Jimbaran May 2018'!AB22 -> 0 | AA12: ='FS Jimbaran May 2018'!AC22 -> 0 | AB12: ='FS Jimbaran May 2018'!AD22 -> 0 | AC12: ='FS Jimbaran May 2018'!AE22 -> 0 | AD12: ='FS Jimbaran May 2018'!AF22 -> 0 | ... AF12: ='FS Jimbaran May 2018'!AH22 -> 0 | AG12: ='FS Jimbaran May 2018'!AM22 -> 0 | AH12: ='FS Jimbaran May 2018'!AR22 -> 0 | AI12: ='FS Jimbaran May 2018'!AQ22 -> 0 | AJ12: ='FS Jimbaran May 2018'!AR22 -> 0 | AK12: ='FS Jimbaran May 2018'!AY22 -> 0 | AL12: ='FS Jimbaran May 2018'!AZ22 -> 0 | AM12: ='FS Jimbaran May 2018'!BB22 -> 0 | AN12: ='FS Jimbaran May 2018'!BB22 -> 0 | AO12: ='FS Jimbaran May 2018'!BK22 -> 0 | AP12: ='FS Jimbaran May 2018'!BL22 -> 0 | AQ12: ='FS Jimbaran May 2018'!BC22 -> 0 | AR12: ='FS Jimbaran May 2018'!BD22 -> 0 | AS12: ='FS Jimbaran May 2018'!BM22 -> 0 | AT12: ='FS Jimbaran May 2018'!BN22 -> 0 | AU12: ='FS Jimbaran May 2018'!BO22 -> 0 | AV12: ='FS Jimbaran May 2018'!BP22 -> 0 | AW12: ='FS Jimbaran May 2018'!E22 -> 16.5 | AX12: ='FS Jimbaran May 2018'!F22 -> 0 | AY12: ='FS Jimbaran May 2018'!O22 -> 0 | AZ12: ='FS Jimbaran May 2018'!P22 -> 0 | BA12: ='FS Jimbaran May 2018'!W22 -> 0 | BB12: ='FS Jimbaran May 2018'!X22 -> 0 | BC12: ='FS Jimbaran May 2018'!AI22 -> 560 | BD12: ='FS Jimbaran May 2018'!AJ22 -> 0 | BE12: ='FS Jimbaran May 2018'!AK22 -> 0 | BF12: ='FS Jimbaran May 2018'!AL22 -> 0 | BG12: ='FS Jimbaran May 2018'!AM22 -> 0 | BH12: ='FS Jimbaran May 2018'!AN22 -> 0 | BI12: ='FS Jimbaran May 2018'!AO22 -> 0 | BJ12: ='FS Jimbaran May 2018'!AO22 -> 0 | BK12: ='FS Jimbaran May 2018'!AQ22 -> 0 | BL12: ='FS Jimbaran May 2018'!AR22 -> 0 | BM12: 0 | BN12: 0 | BO12: ='FS Jimbaran May 2018'!Q22 -> 0 | BP12: ='FS Jimbaran May 2018'!R22 -> 0
A13: Bali Jimbaran | B13: =B12+1 -> 12 | C13: 5 | D13: 2018 | E13: ='FS Jimbaran May 2018'!M23 -> 7 | F13: ='FS Jimbaran May 2018'!N23 -> 0 | G13: 0 | H13: ='FS Jimbaran May 2018'!H23 -> 0 | I13: ='FS Jimbaran May 2018'!I23 -> 0 | J13: ='FS Jimbaran May 2018'!J23 -> 0 | K13: ='FS Jimbaran May 2018'!K23 -> 12.2 | L13: ='FS Jimbaran May 2018'!L23 -> 0 | M13: ='FS Jimbaran May 2018'!S23 -> 0 | N13: ='FS Jimbaran May 2018'!T23 -> 0 | O13: ='FS Jimbaran May 2018'!U23 -> 14.8 | P13: ='FS Jimbaran May 2018'!V23 -> 0 | Q13: ='FS Jimbaran May 2018'!BE23 -> 0 | R13: ='FS Jimbaran May 2018'!BF23 -> 0 | S13: ='FS Jimbaran May 2018'!BH23 -> 0 | T13: ='FS Jimbaran May 2018'!BH23 -> 0 | U13: ='FS Jimbaran May 2018'!BI23 -> 0 | V13: ='FS Jimbaran May 2018'!BJ23 -> 0 | W13: ='FS Jimbaran May 2018'!Y23 -> 520 | X13: ='FS Jimbaran May 2018'!Z23 -> 0 | Y13: ='FS Jimbaran May 2018'!AA23 -> 0 | Z13: ='FS Jimbaran May 2018'!AB23 -> 0 | AA13: ='FS Jimbaran May 2018'!AC23 -> 0 | AB13: ='FS Jimbaran May 2018'!AD23 -> 0 | AC13: ='FS Jimbaran May 2018'!AE23 -> 0 | AD13: ='FS Jimbaran May 2018'!AF23 -> 0 | ... AF13: ='FS Jimbaran May 2018'!AH23 -> 0 | AG13: ='FS Jimbaran May 2018'!AM23 -> 0 | AH13: ='FS Jimbaran May 2018'!AR23 -> 0 | AI13: ='FS Jimbaran May 2018'!AQ23 -> 0 | AJ13: ='FS Jimbaran May 2018'!AR23 -> 0 | AK13: ='FS Jimbaran May 2018'!AY23 -> 0 | AL13: ='FS Jimbaran May 2018'!AZ23 -> 0 | AM13: ='FS Jimbaran May 2018'!BB23 -> 0 | AN13: ='FS Jimbaran May 2018'!BB23 -> 0 | AO13: ='FS Jimbaran May 2018'!BK23 -> 0 | AP13: ='FS Jimbaran May 2018'!BL23 -> 0 | AQ13: ='FS Jimbaran May 2018'!BC23 -> 0 | AR13: ='FS Jimbaran May 2018'!BD23 -> 0 | AS13: ='FS Jimbaran May 2018'!BM23 -> 0 | AT13: ='FS Jimbaran May 2018'!BN23 -> 0 | AU13: ='FS Jimbaran May 2018'!BO23 -> 0 | AV13: ='FS Jimbaran May 2018'!BP23 -> 0 | AW13: ='FS Jimbaran May 2018'!E23 -> 19.8 | AX13: ='FS Jimbaran May 2018'!F23 -> 0 | AY13: ='FS Jimbaran May 2018'!O23 -> 0 | AZ13: ='FS Jimbaran May 2018'!P23 -> 0 | BA13: ='FS Jimbaran May 2018'!W23 -> 0 | BB13: ='FS Jimbaran May 2018'!X23 -> 0 | BC13: ='FS Jimbaran May 2018'!AI23 -> 530 | BD13: ='FS Jimbaran May 2018'!AJ23 -> 0 | BE13: ='FS Jimbaran May 2018'!AK23 -> 0 | BF13: ='FS Jimbaran May 2018'!AL23 -> 0 | BG13: ='FS Jimbaran May 2018'!AM23 -> 0 | BH13: ='FS Jimbaran May 2018'!AN23 -> 0 | BI13: ='FS Jimbaran May 2018'!AO23 -> 0 | BJ13: ='FS Jimbaran May 2018'!AO23 -> 0 | BK13: ='FS Jimbaran May 2018'!AQ23 -> 0 | BL13: ='FS Jimbaran May 2018'!AR23 -> 0 | BM13: 0 | BN13: 0 | BO13: ='FS Jimbaran May 2018'!Q23 -> 0 | BP13: ='FS Jimbaran May 2018'!R23 -> 0
A14: Bali Jimbaran | B14: =B13+1 -> 13 | C14: 5 | D14: 2018 | E14: ='FS Jimbaran May 2018'!M24 -> 4.1 | F14: ='FS Jimbaran May 2018'!N24 -> 0 | G14: 0 | H14: ='FS Jimbaran May 2018'!H24 -> 0 | I14: ='FS Jimbaran May 2018'!I24 -> 0 | J14: ='FS Jimbaran May 2018'!J24 -> 0 | K14: ='FS Jimbaran May 2018'!K24 -> 11.4 | L14: ='FS Jimbaran May 2018'!L24 -> 0 | M14: ='FS Jimbaran May 2018'!S24 -> 0 | N14: ='FS Jimbaran May 2018'!T24 -> 0 | O14: ='FS Jimbaran May 2018'!U24 -> 17 | P14: ='FS Jimbaran May 2018'!V24 -> 0 | Q14: ='FS Jimbaran May 2018'!BE24 -> 0 | R14: ='FS Jimbaran May 2018'!BF24 -> 0 | S14: ='FS Jimbaran May 2018'!BH24 -> 0 | T14: ='FS Jimbaran May 2018'!BH24 -> 0 | U14: ='FS Jimbaran May 2018'!BI24 -> 0 | V14: ='FS Jimbaran May 2018'!BJ24 -> 0 | W14: ='FS Jimbaran May 2018'!Y24 -> 530 | X14: ='FS Jimbaran May 2018'!Z24 -> 0 | Y14: ='FS Jimbaran May 2018'!AA24 -> 0 | Z14: ='FS Jimbaran May 2018'!AB24 -> 0 | AA14: ='FS Jimbaran May 2018'!AC24 -> 0 | AB14: ='FS Jimbaran May 2018'!AD24 -> 0 | AC14: ='FS Jimbaran May 2018'!AE24 -> 0 | AD14: ='FS Jimbaran May 2018'!AF24 -> 0 | ... AF14: ='FS Jimbaran May 2018'!AH24 -> 0 | AG14: ='FS Jimbaran May 2018'!AM24 -> 0 | AH14: ='FS Jimbaran May 2018'!AR24 -> 0 | AI14: ='FS Jimbaran May 2018'!AQ24 -> 0 | AJ14: ='FS Jimbaran May 2018'!AR24 -> 0 | AK14: ='FS Jimbaran May 2018'!AY24 -> 0 | AL14: ='FS Jimbaran May 2018'!AZ24 -> 0 | AM14: ='FS Jimbaran May 2018'!BB24 -> 0 | AN14: ='FS Jimbaran May 2018'!BB24 -> 0 | AO14: ='FS Jimbaran May 2018'!BK24 -> 0 | AP14: ='FS Jimbaran May 2018'!BL24 -> 0 | AQ14: ='FS Jimbaran May 2018'!BC24 -> 0 | AR14: ='FS Jimbaran May 2018'!BD24 -> 0 | AS14: ='FS Jimbaran May 2018'!BM24 -> 0 | AT14: ='FS Jimbaran May 2018'!BN24 -> 0 | AU14: ='FS Jimbaran May 2018'!BO24 -> 0 | AV14: ='FS Jimbaran May 2018'!BP24 -> 0 | AW14: ='FS Jimbaran May 2018'!E24 -> 15.1 | AX14: ='FS Jimbaran May 2018'!F24 -> 0 | AY14: ='FS Jimbaran May 2018'!O24 -> 0 | AZ14: ='FS Jimbaran May 2018'!P24 -> 0 | BA14: ='FS Jimbaran May 2018'!W24 -> 0 | BB14: ='FS Jimbaran May 2018'!X24 -> 0 | BC14: ='FS Jimbaran May 2018'!AI24 -> 640 | BD14: ='FS Jimbaran May 2018'!AJ24 -> 0 | BE14: ='FS Jimbaran May 2018'!AK24 -> 0 | BF14: ='FS Jimbaran May 2018'!AL24 -> 0 | BG14: ='FS Jimbaran May 2018'!AM24 -> 0 | BH14: ='FS Jimbaran May 2018'!AN24 -> 0 | BI14: ='FS Jimbaran May 2018'!AO24 -> 0 | BJ14: ='FS Jimbaran May 2018'!AO24 -> 0 | BK14: ='FS Jimbaran May 2018'!AQ24 -> 0 | BL14: ='FS Jimbaran May 2018'!AR24 -> 0 | BM14: 0 | BN14: 0 | BO14: ='FS Jimbaran May 2018'!Q24 -> 0 | BP14: ='FS Jimbaran May 2018'!R24 -> 0
... A29: Bali Jimbaran | B29: =B28+1 -> 28 | C29: 5 | D29: 2018 | E29: ='FS Jimbaran May 2018'!M39 -> 3.5 | F29: ='FS Jimbaran May 2018'!N39 -> 0 | G29: 0 | H29: ='FS Jimbaran May 2018'!H39 -> 0 | I29: ='FS Jimbaran May 2018'!I39 -> 0 | J29: ='FS Jimbaran May 2018'!J39 -> 0 | K29: ='FS Jimbaran May 2018'!K39 -> 13.6 | L29: ='FS Jimbaran May 2018'!L39 -> 0 | M29: ='FS Jimbaran May 2018'!S39 -> 0 | N29: ='FS Jimbaran May 2018'!T39 -> 0 | O29: ='FS Jimbaran May 2018'!U39 -> 16.8 | P29: ='FS Jimbaran May 2018'!V39 -> 0 | Q29: ='FS Jimbaran May 2018'!BE39 -> 0 | R29: ='FS Jimbaran May 2018'!BF39 -> 0 | S29: ='FS Jimbaran May 2018'!BH39 -> 0 | T29: ='FS Jimbaran May 2018'!BH39 -> 0 | U29: ='FS Jimbaran May 2018'!BI39 -> 0 | V29: ='FS Jimbaran May 2018'!BJ39 -> 0 | W29: ='FS Jimbaran May 2018'!Y39 -> 610 | X29: ='FS Jimbaran May 2018'!Z39 -> 0 | Y29: ='FS Jimbaran May 2018'!AA39 -> 0 | Z29: ='FS Jimbaran May 2018'!AB39 -> 0 | AA29: ='FS Jimbaran May 2018'!AC39 -> 0 | AB29: ='FS Jimbaran May 2018'!AD39 -> 0 | AC29: ='FS Jimbaran May 2018'!AE39 -> 0 | AD29: ='FS Jimbaran May 2018'!AF39 -> 0 | ... AF29: ='FS Jimbaran May 2018'!AH39 -> 0 | AG29: ='FS Jimbaran May 2018'!AM39 -> 0 | AH29: ='FS Jimbaran May 2018'!AR39 -> 0 | AI29: ='FS Jimbaran May 2018'!AQ39 -> 0 | AJ29: ='FS Jimbaran May 2018'!AR39 -> 0 | AK29: ='FS Jimbaran May 2018'!AY39 -> 0 | AL29: ='FS Jimbaran May 2018'!AZ39 -> 0 | AM29: ='FS Jimbaran May 2018'!BB39 -> 0 | AN29: ='FS Jimbaran May 2018'!BB39 -> 0 | AO29: ='FS Jimbaran May 2018'!BK39 -> 0 | AP29: ='FS Jimbaran May 2018'!BL39 -> 0 | AQ29: ='FS Jimbaran May 2018'!BC39 -> 0 | AR29: ='FS Jimbaran May 2018'!BD39 -> 0 | AS29: ='FS Jimbaran May 2018'!BM39 -> 0 | AT29: ='FS Jimbaran May 2018'!BN39 -> 0 | AU29: ='FS Jimbaran May 2018'!BO39 -> 0 | AV29: ='FS Jimbaran May 2018'!BP39 -> 0 | AW29: ='FS Jimbaran May 2018'!E39 -> 14.7 | AX29: ='FS Jimbaran May 2018'!F39 -> 0 | AY29: ='FS Jimbaran May 2018'!O39 -> 0 | AZ29: ='FS Jimbaran May 2018'!P39 -> 0 | BA29: ='FS Jimbaran May 2018'!W39 -> 0 | BB29: ='FS Jimbaran May 2018'!X39 -> 0 | BC29: ='FS Jimbaran May 2018'!AI39 -> 610 | BD29: ='FS Jimbaran May 2018'!AJ39 -> 0 | BE29: ='FS Jimbaran May 2018'!AK39 -> 0 | BF29: ='FS Jimbaran May 2018'!AL39 -> 0 | BG29: ='FS Jimbaran May 2018'!AM39 -> 0 | BH29: ='FS Jimbaran May 2018'!AN39 -> 0 | BI29: ='FS Jimbaran May 2018'!AO39 -> 0 | BJ29: ='FS Jimbaran May 2018'!AO39 -> 0 | BK29: ='FS Jimbaran May 2018'!AQ39 -> 0 | BL29: ='FS Jimbaran May 2018'!AR39 -> 0 | BM29: 0 | BN29: 0 | BO29: ='FS Jimbaran May 2018'!Q39 -> 0 | BP29: ='FS Jimbaran May 2018'!R39 -> 0
A30: Bali Jimbaran | B30: =B29+1 -> 29 | C30: 5 | D30: 2018 | E30: ='FS Jimbaran May 2018'!M40 -> 3.3 | F30: ='FS Jimbaran May 2018'!N40 -> 0 | G30: 0 | H30: ='FS Jimbaran May 2018'!H40 -> 0 | I30: ='FS Jimbaran May 2018'!I40 -> 0 | J30: ='FS Jimbaran May 2018'!J40 -> 0 | K30: ='FS Jimbaran May 2018'!K40 -> 14.7 | L30: ='FS Jimbaran May 2018'!L40 -> 0 | M30: ='FS Jimbaran May 2018'!S40 -> 0 | N30: ='FS Jimbaran May 2018'!T40 -> 0 | O30: ='FS Jimbaran May 2018'!U40 -> 12.4 | P30: =SUM(P2:P29) -> 0 | Q30: =SUM(Q2:Q29) -> 0 | R30: =SUM(R2:R29) -> 0 | S30: =SUM(S2:S29) -> 0 | T30: =SUM(T2:T29) -> 0 | U30: =SUM(U2:U29) -> 0 | V30: =SUM(V2:V29) -> 0 | W30: ='FS Jimbaran May 2018'!Y40 -> 670 | X30: ='FS Jimbaran May 2018'!Z40 -> 0 | Y30: =SUM(Y2:Y29) -> 0 | Z30: =SUM(Z2:Z29) -> 0 | AA30: =SUM(AA2:AA29) -> 0 | AB30: =SUM(AB2:AB29) -> 0 | AC30: =SUM(AC2:AC29) -> 0 | AD30: =SUM(AD2:AD29) -> 0 | AE30: =SUM(AE2:AE29) -> 0 | AF30: =SUM(AF2:AF29) -> 0 | ... AV30: =SUM(AV2:AV29) -> 0 | AW30: ='FS Jimbaran May 2018'!E40 -> 15.8 | AX30: ='FS Jimbaran May 2018'!F40 -> 0 | AY30: ='FS Jimbaran May 2018'!O40 -> 0 | AZ30: ='FS Jimbaran May 2018'!P40 -> 0 | BA30: ='FS Jimbaran May 2018'!W40 -> 0 | BB30: ='FS Jimbaran May 2018'!X40 -> 0 | BC30: ='FS Jimbaran May 2018'!AI40 -> 370 | BD30: ='FS Jimbaran May 2018'!AJ40 -> 0 | BE30: ='FS Jimbaran May 2018'!AK40 -> 0 | BF30: ='FS Jimbaran May 2018'!AL40 -> 0 | BG30: ='FS Jimbaran May 2018'!AM40 -> 0 | BH30: ='FS Jimbaran May 2018'!AN40 -> 0 | BI30: ='FS Jimbaran May 2018'!AO40 -> 0 | BJ30: ='FS Jimbaran May 2018'!AO40 -> 0 | BK30: ='FS Jimbaran May 2018'!AQ40 -> 0 | BL30: ='FS Jimbaran May 2018'!AR40 -> 0 | BM30: 0 | BN30: 0 | BO30: ='FS Jimbaran May 2018'!Q40 -> 0 | BP30: ='FS Jimbaran May 2018'!R40 -> 0
A31: Bali Jimbaran | B31: =B30+1 -> 30 | C31: 5 | D31: 2018 | E31: ='FS Jimbaran May 2018'!M41 -> 6.2 | F31: ='FS Jimbaran May 2018'!N41 -> 0 | G31: 0 | H31: ='FS Jimbaran May 2018'!H41 -> 0 | I31: ='FS Jimbaran May 2018'!I41 -> 0 | J31: ='FS Jimbaran May 2018'!J41 -> 0 | K31: ='FS Jimbaran May 2018'!K41 -> 16.5 | L31: ='FS Jimbaran May 2018'!L41 -> 0 | M31: ='FS Jimbaran May 2018'!S41 -> 0 | N31: ='FS Jimbaran May 2018'!T41 -> 0 | O31: ='FS Jimbaran May 2018'!U41 -> 13.4 | P31: =SUM(P3:P30) -> 0 | Q31: =SUM(Q3:Q30) -> 0 | R31: =SUM(R3:R30) -> 0 | S31: =SUM(S3:S30) -> 0 | T31: =SUM(T3:T30) -> 0 | U31: =SUM(U3:U30) -> 0 | V31: =SUM(V3:V30) -> 0 | W31: ='FS Jimbaran May 2018'!Y41 -> 520 | X31: ='FS Jimbaran May 2018'!Z41 -> 0 | Y31: =SUM(Y3:Y30) -> 0 | Z31: =SUM(Z3:Z30) -> 0 | AA31: =SUM(AA3:AA30) -> 0 | AB31: =SUM(AB3:AB30) -> 0 | AC31: =SUM(AC3:AC30) -> 0 | AD31: =SUM(AD3:AD30) -> 0 | AE31: =SUM(AE3:AE30) -> 0 | AF31: =SUM(AF3:AF30) -> 0 | ... AV31: =SUM(AV3:AV30) -> 0 | AW31: ='FS Jimbaran May 2018'!E41 -> 14 | AX31: ='FS Jimbaran May 2018'!F41 -> 0 | AY31: ='FS Jimbaran May 2018'!O41 -> 0 | AZ31: ='FS Jimbaran May 2018'!P41 -> 0 | BA31: ='FS Jimbaran May 2018'!W41 -> 0 | BB31: ='FS Jimbaran May 2018'!X41 -> 0 | BC31: ='FS Jimbaran May 2018'!AI41 -> 440 | BD31: ='FS Jimbaran May 2018'!AJ41 -> 0 | BE31: ='FS Jimbaran May 2018'!AK41 -> 0 | BF31: ='FS Jimbaran May 2018'!AL41 -> 0 | BG31: ='FS Jimbaran May 2018'!AM41 -> 0 | BH31: ='FS Jimbaran May 2018'!AN41 -> 0 | BI31: ='FS Jimbaran May 2018'!AO41 -> 0 | BJ31: ='FS Jimbaran May 2018'!AO41 -> 0 | BK31: ='FS Jimbaran May 2018'!AQ41 -> 0 | BL31: ='FS Jimbaran May 2018'!AR41 -> 0 | BM31: 0 | BN31: 0 | BO31: ='FS Jimbaran May 2018'!Q41 -> 0 | BP31: ='FS Jimbaran May 2018'!R41 -> 0
A32: Bali Jimbaran | B32: =B31+1 -> 31 | C32: 5 | D32: 2018 | E32: ='FS Jimbaran May 2018'!M42 -> 5.3 | F32: ='FS Jimbaran May 2018'!N42 -> 0 | G32: 0 | H32: ='FS Jimbaran May 2018'!H42 -> 0 | I32: ='FS Jimbaran May 2018'!I42 -> 0 | J32: ='FS Jimbaran May 2018'!J42 -> 0 | K32: ='FS Jimbaran May 2018'!K42 -> 16.4 | L32: ='FS Jimbaran May 2018'!L42 -> 0 | M32: ='FS Jimbaran May 2018'!S42 -> 0 | N32: ='FS Jimbaran May 2018'!T42 -> 0 | O32: ='FS Jimbaran May 2018'!U42 -> 16.4 | P32: =SUM(P5:P31) -> 0 | Q32: =SUM(Q5:Q31) -> 0 | R32: =SUM(R5:R31) -> 0 | S32: =SUM(S5:S31) -> 0 | T32: =SUM(T5:T31) -> 0 | U32: =SUM(U5:U31) -> 0 | V32: =SUM(V5:V31) -> 0 | W32: ='FS Jimbaran May 2018'!Y42 -> 550 | X32: ='FS Jimbaran May 2018'!Z42 -> 0 | Y32: =SUM(Y5:Y31) -> 0 | Z32: =SUM(Z5:Z31) -> 0 | AA32: =SUM(AA5:AA31) -> 0 | AB32: =SUM(AB5:AB31) -> 0 | AC32: =SUM(AC5:AC31) -> 0 | AD32: =SUM(AD5:AD31) -> 0 | AE32: =SUM(AE5:AE31) -> 0 | AF32: =SUM(AF5:AF31) -> 0 | ... AV32: =SUM(AV5:AV31) -> 0 | AW32: ='FS Jimbaran May 2018'!E42 -> 14.2 | AX32: ='FS Jimbaran May 2018'!F42 -> 0 | AY32: ='FS Jimbaran May 2018'!O42 -> 0 | AZ32: ='FS Jimbaran May 2018'!P42 -> 0 | BA32: ='FS Jimbaran May 2018'!W42 -> 0 | BB32: ='FS Jimbaran May 2018'!X42 -> 0 | BC32: ='FS Jimbaran May 2018'!AI42 -> 460 | BD32: ='FS Jimbaran May 2018'!AJ42 -> 0 | BE32: ='FS Jimbaran May 2018'!AK42 -> 0 | BF32: ='FS Jimbaran May 2018'!AL42 -> 0 | BG32: ='FS Jimbaran May 2018'!AM42 -> 0 | BH32: ='FS Jimbaran May 2018'!AN42 -> 0 | BI32: ='FS Jimbaran May 2018'!AO42 -> 0 | BJ32: ='FS Jimbaran May 2018'!AO42 -> 0 | BK32: ='FS Jimbaran May 2018'!AQ42 -> 0 | BL32: ='FS Jimbaran May 2018'!AR42 -> 0 | BM32: 0 | BN32: 0 | BO32: ='FS Jimbaran May 2018'!Q42 -> 0 | BP32: ='FS Jimbaran May 2018'!R42 -> 0
E33: ='FS Jimbaran May 2018'!M43 -> 134.9 | F33: ='FS Jimbaran May 2018'!N43 -> 0 | G33: 0 | H33: ='FS Jimbaran May 2018'!H43 -> 0 | I33: ='FS Jimbaran May 2018'!I43 -> 0 | J33: ='FS Jimbaran May 2018'!J43 -> 0 | K33: ='FS Jimbaran May 2018'!K43 -> 439.8 | L33: ='FS Jimbaran May 2018'!L43 -> 0 | M33: ='FS Jimbaran May 2018'!S43 -> 0 | N33: ='FS Jimbaran May 2018'!T43 -> 0 | O33: ='FS Jimbaran May 2018'!U43 -> 444.6 | P33: =SUM(P6:P32) -> 0 | Q33: =SUM(Q6:Q32) -> 0 | R33: =SUM(R6:R32) -> 0 | S33: =SUM(S6:S32) -> 0 | T33: =SUM(T6:T32) -> 0 | U33: =SUM(U6:U32) -> 0 | V33: =SUM(V6:V32) -> 0 | W33: ='FS Jimbaran May 2018'!Y43 -> 17570 | X33: ='FS Jimbaran May 2018'!Z43 -> 8284726 | Y33: =SUM(Y6:Y32) -> 0 | Z33: =SUM(Z6:Z32) -> 0 | AA33: =SUM(AA6:AA32) -> 0 | AB33: =SUM(AB6:AB32) -> 0 | AC33: =SUM(AC6:AC32) -> 0 | AD33: =SUM(AD6:AD32) -> 0 | AE33: =SUM(AE6:AE32) -> 0 | AF33: =SUM(AF6:AF32) -> 0 | ... AV33: =SUM(AV6:AV32) -> 0 | AW33: ='FS Jimbaran May 2018'!E43 -> 425.7 | AX33: ='FS Jimbaran May 2018'!F43 -> 0 | AY33: ='FS Jimbaran May 2018'!O43 -> 0 | AZ33: ='FS Jimbaran May 2018'!P43 -> 0 | BA33: ='FS Jimbaran May 2018'!W43 -> 0 | BB33: ='FS Jimbaran May 2018'!X43 -> 0 | BC33: ='FS Jimbaran May 2018'!AI43 -> 20360 | BD33: ='FS Jimbaran May 2018'!AJ43 -> 0 | BE33: ='FS Jimbaran May 2018'!AK43 -> 0 | BF33: ='FS Jimbaran May 2018'!AL43 -> 0 | BG33: ='FS Jimbaran May 2018'!AM43 -> 0 | BH33: ='FS Jimbaran May 2018'!AN43 -> 0 | BI33: ='FS Jimbaran May 2018'!AO43 -> 0 | BJ33: ='FS Jimbaran May 2018'!AO43 -> 0 | BK33: ='FS Jimbaran May 2018'!AQ43 -> 0 | BL33: ='FS Jimbaran May 2018'!AR43 -> 0 | BM33: 0 | BN33: 0 | BO33: ='FS Jimbaran May 2018'!Q43 -> 0 | BP33: ='FS Jimbaran May 2018'!R43 -> 0

Sheet FS Jimbaran May 2018
B6: Four Seasons Resort Bali at Jimbaran Bay
B7: May 2018
B8: Date | C8: Room Nights | D8: Food Covers | E8: Paper Waste | K8: Glass Waste | M8: Metal Waste | U8: Plastic Waste | Y8: Organic Waste | AM8: Hazardous Waste | BE8: Recycleable
E10: Total (per Unit) paper cardboard | F10: Total cost paper cardboard | G10: Total (per Unit) cardboard | H10: Total cost cardboard | I10: Total (per Unit) paper | J10: Total cost paper | K10: Total (per Unit) mixed glass | L10: Total cost mixed glass | M10: Total (per Unit) bottles cans | N10: Total cost bottles cans | O10: Total (per Unit) mixed metals | P10: Total cost mixed metals | Q10: Total (per Unit) tin | R10: Total cost tin | S10: Total (per Unit) aluminum | T10: Total cost aluminum | U10: Total (per Unit) plastics | V10: Total cost plastics | W10: Total (per Unit) other plastics | X10: Total cost other plastics | Y10: Total (per Unit) solid food waste | Z10: Total cost solid food waste | AA10: Total (per Unit) leftover food | AB10: Total cost leftover food | AC10: Total (per Unit) inedible parts | AD10: Total cost inedible parts | AE10: Total (per Unit) liquid food waste | AF10: Total cost liquid food waste | AG10: Total (per Unit) kitchen grease | AH10: Total cost kitchen grease | AI10: Total (per Unit) biodegradable | AJ10: Total cost biodegradable | AK10: Total (per Unit) food waste | AL10: Total cost food waste | AM10: Total (per Unit) hazardous waste | AN10: Total cost hazardous waste | AO10: Total (per Unit) universal waste | AP10: Total cost universal waste | AQ10: Total (per Unit) hazardous and universal waste | AR10: Total cost hazardous and universal waste | AS10: Total (per Unit) medical waste | AT10: Total cost medical waste | AU10: Total (per Unit) liquid hazardous waste | AV10: Total cost liquid hazardous waste | AW10: Total (per Unit) other hazardous waste | AX10: Total cost other hazardous waste | AY10: Total (per Unit) batteries | AZ10: Total cost batteries | BA10: Total (per Unit) light bulbs | BB10: Total cost light bulbs | BC10: Total (per Unit) paint | BD10: Total cost paint | BE10: Total (per Unit) soap bars | BF10: Total cost soap bars | BG10: Total (per Unit) e waste | BH10: Total cost e waste | BI10: Total (per Unit) durable goods | BJ10: Total cost durable goods | BK10: Total (per Unit) textiles | BL10: Total cost textiles | BM10: Total (per Unit) recyclable | BN10: Total cost recyclable | BO10: Total (per Unit) commingled recyclables | BP10: Total cost commingled recyclables
B12: 1 | E12: 10.1 | F12: 0 | G12: 0 | H12: 0 | I12: 0 | J12: 0 | K12: 12.6 | L12: 0 | M12: 3.7 | N12: 0 | O12: 0 | P12: 0 | Q12: 0 | R12: 0 | S12: 0 | T12: 0 | U12: 16.2 | V12: 0 | W12: 0 | X12: 0 | Y12: 650 | Z12: 8284726 | AA12: 0 | AB12: 0 | AC12: 0 | AD12: 0 | AE12: 0 | AF12: 0 | AG12: 0 | AH12: 0 | AI12: 570 | AJ12: 0 | AK12: 0 | AL12: 0 | AM12: 0 | AN12: 0 | AO12: 0 | AP12: 0 | AQ12: 0 | AR12: 0 | AS12: 0 | AT12: 0 | AU12: 0 | AV12: 0 | AW12: 0 | AX12: 0 | AY12: 0 | AZ12: 0 | BA12: 0 | BB12: 0 | BC12: 0 | BD12: 0 | BE12: 0 | BF12: 0 | BG12: 0 | BH12: 0 | BI12: 0 | BJ12: 0 | BK12: 0 | BL12: 0 | BM12: 0 | BN12: 0 | BO12: 0 | BP12: 0
B13: 2 | E13: 9.1 | F13: 0 | G13: 0 | H13: 0 | I13: 0 | J13: 0 | K13: 14.5 | L13: 0 | M13: 3.3 | N13: 0 | O13: 0 | P13: 0 | Q13: 0 | R13: 0 | S13: 0 | T13: 0 | U13: 18.2 | V13: 0 | W13: 0 | X13: 0 | Y13: 570 | Z13: 0 | AA13: 0 | AB13: 0 | AC13: 0 | AD13: 0 | AE13: 0 | AF13: 0 | AG13: 0 | AH13: 0 | AI13: 520 | AJ13: 0 | AK13: 0 | AL13: 0 | AM13: 0 | AN13: 0 | AO13: 0 | AP13: 0 | AQ13: 0 | AR13: 0 | AS13: 0 | AT13: 0 | AU13: 0 | AV13: 0 | AW13: 0 | AX13: 0 | AY13: 0 | AZ13: 0 | BA13: 0 | BB13: 0 | BC13: 0 | BD13: 0 | BE13: 0 | BF13: 0 | BG13: 0 | BH13: 0 | BI13: 0 | BJ13: 0 | BK13: 0 | BL13: 0 | BM13: 0 | BN13: 0 | BO13: 0 | BP13: 0
B14: 3 | E14: 8.7 | F14: 0 | G14: 0 | H14: 0 | I14: 0 | J14: 0 | K14: 11.9 | L14: 0 | M14: 1.9 | N14: 0 | O14: 0 | P14: 0 | Q14: 0 | R14: 0 | S14: 0 | T14: 0 | U14: 10.6 | V14: 0 | W14: 0 | X14: 0 | Y14: 470 | Z14: 0 | AA14: 0 | AB14: 0 | AC14: 0 | AD14: 0 | AE14: 0 | AF14: 0 | AG14: 0 | AH14: 0 | AI14: 510 | AJ14: 0 | AK14: 0 | AL14: 0 | AM14: 0 | AN14: 0 | AO14: 0 | AP14: 0 | AQ14: 0 | AR14: 0 | AS14: 0 | AT14: 0 | AU14: 0 | AV14: 0 | AW14: 0 | AX14: 0 | AY14: 0 | AZ14: 0 | BA14: 0 | BB14: 0 | BC14: 0 | BD14: 0 | BE14: 0 | BF14: 0 | BG14: 0 | BH14: 0 | BI14: 0 | BJ14: 0 | BK14: 0 | BL14: 0 | BM14: 0 | BN14: 0 | BO14: 0 | BP14: 0
B15: 4 | E15: 9.1 | F15: 0 | G15: 0 | H15: 0 | I15: 0 | J15: 0 | K15: 16 | L15: 0 | M15: 2.6 | N15: 0 | O15: 0 | P15: 0 | Q15: 0 | R15: 0 | S15: 0 | T15: 0 | U15: 16.2 | V15: 0 | W15: 0 | X15: 0 | Y15: 510 | Z15: 0 | AA15: 0 | AB15: 0 | AC15: 0 | AD15: 0 | AE15: 0 | AF15: 0 | AG15: 0 | AH15: 0 | AI15: 550 | AJ15: 0 | AK15: 0 | AL15: 0 | AM15: 0 | AN15: 0 | AO15: 0 | AP15: 0 | AQ15: 0 | AR15: 0 | AS15: 0 | AT15: 0 | AU15: 0 | AV15: 0 | AW15: 0 | AX15: 0 | AY15: 0 | AZ15: 0 | BA15: 0 | BB15: 0 | BC15: 0 | BD15: 0 | BE15: 0 | BF15: 0 | BG15: 0 | BH15: 0 | BI15: 0 | BJ15: 0 | BK15: 0 | BL15: 0 | BM15: 0 | BN15: 0 | BO15: 0 | BP15: 0
B16: 5 | E16: 8.8 | F16: 0 | G16: 0 | H16: 0 | I16: 0 | J16: 0 | K16: 19.7 | L16: 0 | M16: 3.5 | N16: 0 | O16: 0 | P16: 0 | Q16: 0 | R16: 0 | S16: 0 | T16: 0 | U16: 14.6 | V16: 0 | W16: 0 | X16: 0 | Y16: 630 | Z16: 0 | AA16: 0 | AB16: 0 | AC16: 0 | AD16: 0 | AE16: 0 | AF16: 0 | AG16: 0 | AH16: 0 | AI16: 750 | AJ16: 0 | AK16: 0 | AL16: 0 | AM16: 0 | AN16: 0 | AO16: 0 | AP16: 0 | AQ16: 0 | AR16: 0 | AS16: 0 | AT16: 0 | AU16: 0 | AV16: 0 | AW16: 0 | AX16: 0 | AY16: 0 | AZ16: 0 | BA16: 0 | BB16: 0 | BC16: 0 | BD16: 0 | BE16: 0 | BF16: 0 | BG16: 0 | BH16: 0 | BI16: 0 | BJ16: 0 | BK16: 0 | BL16: 0 | BM16: 0 | BN16: 0 | BO16: 0 | BP16: 0
B17: 6 | E17: 10.9 | F17: 0 | G17: 0 | H17: 0 | I17: 0 | J17: 0 | K17: 12.4 | L17: 0 | M17: 2.3 | N17: 0 | O17: 0 | P17: 0 | Q17: 0 | R17: 0 | S17: 0 | T17: 0 | U17: 5 | V17: 0 | W17: 0 | X17: 0 | Y17: 470 | Z17: 0 | AA17: 0 | AB17: 0 | AC17: 0 | AD17: 0 | AE17: 0 | AF17: 0 | AG17: 0 | AH17: 0 | AI17: 500 | AJ17: 0 | AK17: 0 | AL17: 0 | AM17: 0 | AN17: 0 | AO17: 0 | AP17: 0 | AQ17: 0 | AR17: 0 | AS17: 0 | AT17: 0 | AU17: 0 | AV17: 0 | AW17: 0 | AX17: 0 | AY17: 0 | AZ17: 0 | BA17: 0 | BB17: 0 | BC17: 0 | BD17: 0 | BE17: 0 | BF17: 0 | BG17: 0 | BH17: 0 | BI17: 0 | BJ17: 0 | BK17: 0 | BL17: 0 | BM17: 0 | BN17: 0 | BO17: 0 | BP17: 0
B18: 7 | E18: 10.2 | F18: 0 | G18: 0 | H18: 0 | I18: 0 | J18: 0 | K18: 14.1 | L18: 0 | M18: 4.2 | N18: 0 | O18: 0 | P18: 0 | Q18: 0 | R18: 0 | S18: 0 | T18: 0 | U18: 16.2 | V18: 0 | W18: 0 | X18: 0 | Y18: 530 | Z18: 0 | AA18: 0 | AB18: 0 | AC18: 0 | AD18: 0 | AE18: 0 | AF18: 0 | AG18: 0 | AH18: 0 | AI18: 540 | AJ18: 0 | AK18: 0 | AL18: 0 | AM18: 0 | AN18: 0 | AO18: 0 | AP18: 0 | AQ18: 0 | AR18: 0 | AS18: 0 | AT18: 0 | AU18: 0 | AV18: 0 | AW18: 0 | AX18: 0 | AY18: 0 | AZ18: 0 | BA18: 0 | BB18: 0 | BC18: 0 | BD18: 0 | BE18: 0 | BF18: 0 | BG18: 0 | BH18: 0 | BI18: 0 | BJ18: 0 | BK18: 0 | BL18: 0 | BM18: 0 | BN18: 0 | BO18: 0 | BP18: 0
B19: 8 | E19: 10.4 | F19: 0 | G19: 0 | H19: 0 | I19: 0 | J19: 0 | K19: 13.3 | L19: 0 | M19: 3.8 | N19: 0 | O19: 0 | P19: 0 | Q19: 0 | R19: 0 | S19: 0 | T19: 0 | U19: 12.6 | V19: 0 | W19: 0 | X19: 0 | Y19: 480 | Z19: 0 | AA19: 0 | AB19: 0 | AC19: 0 | AD19: 0 | AE19: 0 | AF19: 0 | AG19: 0 | AH19: 0 | AI19: 790 | AJ19: 0 | AK19: 0 | AL19: 0 | AM19: 0 | AN19: 0 | AO19: 0 | AP19: 0 | AQ19: 0 | AR19: 0 | AS19: 0 | AT19: 0 | AU19: 0 | AV19: 0 | AW19: 0 | AX19: 0 | AY19: 0 | AZ19: 0 | BA19: 0 | BB19: 0 | BC19: 0 | BD19: 0 | BE19: 0 | BF19: 0 | BG19: 0 | BH19: 0 | BI19: 0 | BJ19: 0 | BK19: 0 | BL19: 0 | BM19: 0 | BN19: 0 | BO19: 0 | BP19: 0
B20: 9 | E20: 8 | F20: 0 | G20: 0 | H20: 0 | I20: 0 | J20: 0 | K20: 15.9 | L20: 0 | M20: 3.2 | N20: 0 | O20: 0 | P20: 0 | Q20: 0 | R20: 0 | S20: 0 | T20: 0 | U20: 18.2 | V20: 0 | W20: 0 | X20: 0 | Y20: 510 | Z20: 0 | AA20: 0 | AB20: 0 | AC20: 0 | AD20: 0 | AE20: 0 | AF20: 0 | AG20: 0 | AH20: 0 | AI20: 600 | AJ20: 0 | AK20: 0 | AL20: 0 | AM20: 0 | AN20: 0 | AO20: 0 | AP20: 0 | AQ20: 0 | AR20: 0 | AS20: 0 | AT20: 0 | AU20: 0 | AV20: 0 | AW20: 0 | AX20: 0 | AY20: 0 | AZ20: 0 | BA20: 0 | BB20: 0 | BC20: 0 | BD20: 0 | BE20: 0 | BF20: 0 | BG20: 0 | BH20: 0 | BI20: 0 | BJ20: 0 | BK20: 0 | BL20: 0 | BM20: 0 | BN20: 0 | BO20: 0 | BP20: 0
B21: 10 | E21: 19 | F21: 0 | G21: 0 | H21: 0 | I21: 0 | J21: 0 | K21: 11.8 | L21: 0 | M21: 6.5 | N21: 0 | O21: 0 | P21: 0 | Q21: 0 | R21: 0 | S21: 0 | T21: 0 | U21: 12.4 | V21: 0 | W21: 0 | X21: 0 | Y21: 450 | Z21: 0 | AA21: 0 | AB21: 0 | AC21: 0 | AD21: 0 | AE21: 0 | AF21: 0 | AG21: 0 | AH21: 0 | AI21: 690 | AJ21: 0 | AK21: 0 | AL21: 0 | AM21: 0 | AN21: 0 | AO21: 0 | AP21: 0 | AQ21: 0 | AR21: 0 | AS21: 0 | AT21: 0 | AU21: 0 | AV21: 0 | AW21: 0 | AX21: 0 | AY21: 0 | AZ21: 0 | BA21: 0 | BB21: 0 | BC21: 0 | BD21: 0 | BE21: 0 | BF21: 0 | BG21: 0 | BH21: 0 | BI21: 0 | BJ21: 0 | BK21: 0 | BL21: 0 | BM21: 0 | BN21: 0 | BO21: 0 | BP21: 0
