Workbook

Sheet Sheet1
A1: Site Name | B1: Month | C1: Year | D1: Total (per Unit) bottles cans | E1: Total cost bottles cans | F1: Total (per Unit) cardboard | G1: Total cost cardboard | H1: Total (per Unit) paper | I1: Total cost paper | J1: Total (per Unit) mixed glass | K1: Total cost mixed glass | L1: Total (per Unit) aluminum | M1: Total cost aluminum | N1: Total (per Unit) other plastics | O1: Total cost other plastics | P1: Total (per Unit) soap bars | Q1: Total cost soap bars | R1: Total (per Unit) e waste | S1: Total cost e waste | T1: Total (per Unit) durable goods | U1: Total cost durable goods | V1: Total (per Unit) solid food waste | W1: Total cost solid food waste | X1: Total (per Unit) leftover food | Y1: Total cost leftover food | Z1: Total (per Unit) inedible parts | AA1: Total cost inedible parts | AB1: Total (per Unit) liquid food waste | AC1: Total cost liquid food waste | AD1: Total (per Unit) kitchen grease | AE1: Total cost kitchen grease | AF1: Total (per Unit) liquid hazardous waste | AG1: Total cost liquid hazardous waste | AH1: Total (per Unit) other hazardous waste | AI1: Total cost other hazardous waste | AJ1: Total (per Unit) batteries | AK1: Total cost batteries | AL1: Total (per Unit) light bulbs | AM1: Total cost light bulbs | AN1: Total (per Unit) textiles | AO1: Total cost textiles | AP1: Total (per Unit) paint | AQ1: Total cost paint | AR1: Total (per Unit) recyclable | AS1: Total cost recyclable | AT1: Total (per Unit) commingled recyclables | AU1: Total cost commingled recyclables | AV1: Total (per Unit) paper cardboard | AW1: Total cost paper cardboard | AX1: Total (per Unit) mixed metals | AY1: Total cost mixed metals | AZ1: Total (per Unit) plastics | BA1: Total cost plastics | BB1: Total (per Unit) biodegradable | BC1: Total cost biodegradable | BD1: Total (per Unit) food waste | BE1: Total cost food waste | BF1: Total (per Unit) hazardous waste | BG1: Total cost hazardous waste | BH1: Total (per Unit) universal waste | BI1: Total cost universal waste | BJ1: Total (per Unit) hazardous and universal waste | BK1: Total cost hazardous and universal waste | BL1: Total (per Unit) medical waste | BM1: Total cost medical waste | BN1: Total (per Unit) tin | BO1: Total cost tin
A2: Bali Jimbaran | B2: 1 | C2: 2019 | D2: 127.7 | E2: 0 | F2: 0 | G2: 0 | H2: 0 | I2: 0 | J2: 314.9 | K2: 0 | L2: 0 | M2: 0 | N2: 506.2 | O2: 0 | P2: 0 | Q2: 0 | R2: 0 | S2: 0 | T2: 0 | U2: 0 | V2: 13728 | W2: 8284726 | X2: 0 | Y2: 0 | Z2: 0 | AA2: 0 | AB2: 0 | AC2: 0 | AD2: 0 | AE2: 0 | AF2: 0 | AG2: 0 | AH2: 0 | AI2: 0 | AJ2: 0 | AK2: 0 | AL2: 0 | AM2: 0 | AN2: 0 | AO2: 0 | AP2: 0 | AQ2: 0 | AR2: 0 | AS2: 0 | AT2: 0 | AU2: 0 | AV2: 388.7 | AW2: 0 | AX2: 0 | AY2: 0 | AZ2: 0 | BA2: 0 | BB2: 17160 | BC2: 0 | BD2: 0 | BE2: 0 | BF2: 0 | BG2: 0 | BH2: 0 | BI2: 0 | BJ2: 0 | BK2: 0 | BL2: 0 | BM2: 0 | BN2: 0 | BO2: 0
A3: Bali Jimbaran | B3: 2 | C3: 2019 | D3: 96.9 | E3: 0 | F3: 0 | G3: 0 | H3: 0 | I3: 0 | J3: 360.5 | K3: 0 | L3: 0 | M3: 0 | N3: 463.6 | O3: 0 | P3: 0 | Q3: 0 | R3: 0 | S3: 0 | T3: 0 | U3: 0 | V3: 11613 | W3: 8284726 | X3: 0 | Y3: 0 | Z3: 0 | AA3: 0 | AB3: 0 | AC3: 0 | AD3: 0 | AE3: 0 | AF3: 0 | AG3: 0 | AH3: 0 | AI3: 0 | AJ3: 0 | AK3: 0 | AL3: 0 | AM3: 0 | AN3: 0 | AO3: 0 | AP3: 0 | AQ3: 0 | AR3: 0 | AS3: 0 | AT3: 0 | AU3: 0 | AV3: 356.1 | AW3: 0 | AX3: 0 | AY3: 0 | AZ3: 0 | BA3: 0 | BB3: 14664 | BC3: 0 | BD3: 0 | BE3: 0 | BF3: 0 | BG3: 0 | BH3: 0 | BI3: 0 | BJ3: 0 | BK3: 0 | BL3: 0 | BM3: 0 | BN3: 0 | BO3: 0
A4: Bali Jimbaran | B4: 3 | C4: 2019 | D4: 113.3 | E4: 0 | F4: 0 | G4: 0 | H4: 0 | I4: 0 | J4: 267.3 | K4: 0 | L4: 0 | M4: 0 | N4: 413.2 | O4: 0 | P4: 0 | Q4: 0 | R4: 0 | S4: 0 | T4: 0 | U4: 0 | V4: 12117 | W4: 8284726 | X4: 0 | Y4: 0 | Z4: 0 | AA4: 0 | AB4: 0 | AC4: 0 | AD4: 0 | AE4: 0 | AF4: 0 | AG4: 0 | AH4: 0 | AI4: 0 | AJ4: 0 | AK4: 0 | AL4: 0 | AM4: 0 | AN4: 0 | AO4: 0 | AP4: 0 | AQ4: 0 | AR4: 0 | AS4: 0 | AT4: 0 | AU4: 0 | AV4: 382 | AW4: 0 | AX4: 0 | AY4: 0 | AZ4: 0 | BA4: 0 | BB4: 11574 | BC4: 0 | BD4: 0 | BE4: 0 | BF4: 0 | BG4: 0 | BH4: 0 | BI4: 0 | BJ4: 0 | BK4: 0 | BL4: 0 | BM4: 0 | BN4: 0 | BO4: 0
A5: Bali Jimbaran | B5: 4 | C5: 2019 | D5: 112.5 | E5: 0 | F5: 0 | G5: 0 | H5: 0 | I5: 0 | J5: 246.7 | K5: 0 | L5: 0 | M5: 0 | N5: 429.4 | O5: 0 | P5: 0 | Q5: 0 | R5: 0 | S5: 0 | T5: 0 | U5: 0 | V5: 15696 | W5: 8284726 | X5: 0 | Y5: 0 | Z5: 0 | AA5: 0 | AB5: 0 | AC5: 0 | AD5: 0 | AE5: 0 | AF5: 0 | AG5: 0 | AH5: 0 | AI5: 0 | AJ5: 0 | AK5: 0 | AL5: 0 | AM5: 0 | AN5: 0 | AO5: 0 | AP5: 0 | AQ5: 0 | AR5: 0 | AS5: 0 | AT5: 0 | AU5: 0 | AV5: 369.8 | AW5: 0 | AX5: 0 | AY5: 0 | AZ5: 0 | BA5: 0 | BB5: 10944 | BC5: 0 | BD5: 0 | BE5: 0 | BF5: 0 | BG5: 0 | BH5: 0 | BI5: 0 | BJ5: 0 | BK5: 0 | BL5: 0 | BM5: 0 | BN5: 0 | BO5: 0
A6: Bali Jimbaran | B6: 5 | C6: 2019 | D6: 103.9 | E6: 0 | F6: 0 | G6: 0 | H6: 0 | I6: 0 | J6: 222.8 | K6: 0 | L6: 0 | M6: 0 | N6: 444.6 | O6: 0 | P6: 0 | Q6: 0 | R6: 0 | S6: 0 | T6: 0 | U6: 0 | V6: 12299 | W6: 8284726 | X6: 0 | Y6: 0 | Z6: 0 | AA6: 0 | AB6: 0 | AC6: 0 | AD6: 0 | AE6: 0 | AF6: 0 | AG6: 0 | AH6: 0 | AI6: 0 | AJ6: 0 | AK6: 0 | AL6: 0 | AM6: 0 | AN6: 0 | AO6: 0 | AP6: 0 | AQ6: 0 | AR6: 0 | AS6: 0 | AT6: 0 | AU6: 0 | AV6: 413.6 | AW6: 0 | AX6: 0 | AY6: 0 | AZ6: 0 | BA6: 0 | BB6: 16288 | BC6: 0 | BD6: 0 | BE6: 0 | BF6: 0 | BG6: 0 | BH6: 0 | BI6: 0 | BJ6: 0 | BK6: 0 | BL6: 0 | BM6: 0 | BN6: 0 | BO6: 0
A7: Bali Jimbaran | B7: 6 | C7: 2019 | D7: 108.8 | E7: 0 | F7: 0 | G7: 0 | H7: 0 | I7: 0 | J7: 305.5 | K7: 0 | L7: 0 | M7: 0 | N7: 322.8 | O7: 0 | P7: 0 | Q7: 0 | R7: 0 | S7: 0 | T7: 0 | U7: 0 | V7: 15410 | W7: 8284726 | X7: 0 | Y7: 0 | Z7: 0 | AA7: 0 | AB7: 0 | AC7: 0 | AD7: 0 | AE7: 0 | AF7: 0 | AG7: 0 | AH7: 0 | AI7: 0 | AJ7: 0 | AK7: 0 | AL7: 0 | AM7: 0 | AN7: 0 | AO7: 0 | AP7: 0 | AQ7: 0 | AR7: 0 | AS7: 0 | AT7: 0 | AU7: 0 | AV7: 579.2 | AW7: 0 | AX7: 0 | AY7: 0 | AZ7: 0 | BA7: 0 | BB7: 16520 | BC7: 0 | BD7: 0 | BE7: 0 | BF7: 0 | BG7: 0 | BH7: 0 | BI7: 0 | BJ7: 0 | BK7: 0 | BL7: 0 | BM7: 0 | BN7: 0 | BO7: 0
A8: Bali Jimbaran | B8: 7 | C8: 2019 | D8: 87.6 | E8: 0 | F8: 0 | G8: 0 | H8: 0 | I8: 0 | J8: 238.2 | K8: 0 | L8: 0 | M8: 0 | N8: 572.7 | O8: 0 | P8: 0 | Q8: 0 | R8: 0 | S8: 0 | T8: 0 | U8: 0 | V8: 16730 | W8: 8284726 | X8: 0 | Y8: 0 | Z8: 0 | AA8: 0 | AB8: 0 | AC8: 0 | AD8: 0 | AE8: 0 | AF8: 0 | AG8: 0 | AH8: 0 | AI8: 0 | AJ8: 0 | AK8: 0 | AL8: 0 | AM8: 0 | AN8: 0 | AO8: 0 | AP8: 0 | AQ8: 0 | AR8: 0 | AS8: 0 | AT8: 0 | AU8: 0 | AV8: 347.4 | AW8: 0 | AX8: 0 | AY8: 0 | AZ8: 0 | BA8: 0 | BB8: 13302 | BC8: 0 | BD8: 0 | BE8: 0 | BF8: 0 | BG8: 0 | BH8: 0 | BI8: 0 | BJ8: 0 | BK8: 0 | BL8: 0 | BM8: 0 | BN8: 0 | BO8: 0
A9: Bali Jimbaran | B9: 8 | C9: 2019 | D9: 135 | E9: 0 | F9: 0 | G9: 0 | H9: 0 | I9: 0 | J9: 3218 | K9: 0 | L9: 0 | M9: 0 | N9: 399 | O9: 0 | P9: 0 | Q9: 0 | R9: 0 | S9: 0 | T9: 0 | U9: 0 | V9: 14161 | W9: 8284726 | X9: 0 | Y9: 0 | Z9: 0 | AA9: 0 | AB9: 0 | AC9: 0 | AD9: 0 | AE9: 0 | AF9: 0 | AG9: 0 | AH9: 0 | AI9: 0 | AJ9: 0 | AK9: 0 | AL9: 0 | AM9: 0 | AN9: 0 | AO9: 0 | AP9: 0 | AQ9: 0 | AR9: 0 | AS9: 0 | AT9: 0 | AU9: 0 | AV9: 771.6 | AW9: 0 | AX9: 0 | AY9: 0 | AZ9: 0 | BA9: 0 | BB9: 15696 | BC9: 0 | BD9: 0 | BE9: 0 | BF9: 0 | BG9: 0 | BH9: 0 | BI9: 0 | BJ9: 0 | BK9: 0 | BL9: 0 | BM9: 0 | BN9: 0 | BO9: 0
A10: Bali Jimbaran | B10: 9 | C10: 2019 | D10: 182.6 | E10: 0 | F10: 0 | G10: 0 | H10: 0 | I10: 0 | J10: 3106 | K10: 0 | L10: 0 | M10: 0 | N10: 520 | O10: 0 | P10: 0 | Q10: 0 | R10: 0 | S10: 0 | T10: 0 | U10: 0 | V10: 19500 | W10: 8284726 | X10: 0 | Y10: 0 | Z10: 0 | AA10: 0 | AB10: 0 | AC10: 0 | AD10: 0 | AE10: 0 | AF10: 0 | AG10: 0 | AH10: 0 | AI10: 0 | AJ10: 0 | AK10: 0 | AL10: 0 | AM10: 0 | AN10: 0 | AO10: 0 | AP10: 0 | AQ10: 0 | AR10: 0 | AS10: 0 | AT10: 0 | AU10: 0 | AV10: 1108.4 | AW10: 0 | AX10: 0 | AY10: 0 | AZ10: 0 | BA10: 0 | BB10: 17190 | BC10: 0 | BD10: 0 | BE10: 0 | BF10: 0 | BG10: 0 | BH10: 0 | BI10: 0 | BJ10: 0 | BK10: 0 | BL10: 0 | BM10: 0 | BN10: 0 | BO10: 0
A11: Bali Jimbaran | B11: 10 | C11: 2019 | D11: 189.9 | E11: 0 | F11: 0 | G11: 0 | H11: 0 | I11: 0 | J11: 2770 | K11: 0 | L11: 0 | M11: 0 | N11: 510 | O11: 0 | P11: 0 | Q11: 0 | R11: 0 | S11: 0 | T11: 0 | U11: 0 | V11: 19168 | W11: 8284726 | X11: 0 | Y11: 0 | Z11: 0 | AA11: 0 | AB11: 0 | AC11: 0 | AD11: 0 | AE11: 0 | AF11: 0 | AG11: 0 | AH11: 0 | AI11: 0 | AJ11: 0 | AK11: 0 | AL11: 0 | AM11: 0 | AN11: 0 | AO11: 0 | AP11: 0 | AQ11: 0 | AR11: 0 | AS11: 0 | AT11: 0 | AU11: 0 | AV11: 1684.4 | AW11: 0 | AX11: 0 | AY11: 0 | AZ11: 0 | BA11: 0 | BB11: 12817 | BC11: 0 | BD11: 0 | BE11: 0 | BF11: 0 | BG11: 0 | BH11: 0 | BI11: 0 | BJ11: 0 | BK11: 0 | BL11: 0 | BM11: 0 | BN11: 0 | BO11: 0
A12: Bali Jimbaran | B12: 11 | C12: 2019 | D12: 154.8 | E12: 0 | F12: 0 | G12: 0 | H12: 0 | I12: 0 | J12: 2640 | K12: 0 | L12: 0 | M12: 0 | N12: 392 | O12: 0 | P12: 0 | Q12: 0 | R12: 0 | S12: 0 | T12: 0 | U12: 0 | V12: 18392 | W12: 8284726 | X12: 0 | Y12: 0 | Z12: 0 | AA12: 0 | AB12: 0 | AC12: 0 | AD12: 0 | AE12: 0 | AF12: 0 | AG12: 0 | AH12: 0 | AI12: 0 | AJ12: 0 | AK12: 0 | AL12: 0 | AM12: 0 | AN12: 0 | AO12: 0 | AP12: 0 | AQ12: 0 | AR12: 0 | AS12: 0 | AT12: 0 | AU12: 0 | AV12: 2706.8 | AW12: 0 | AX12: 0 | AY12: 0 | AZ12: 0 | BA12: 0 | BB12: 19600 | BC12: 0 | BD12: 0 | BE12: 0 | BF12: 0 | BG12: 0 | BH12: 0 | BI12: 0 | BJ12: 0 | BK12: 0 | BL12: 0 | BM12: 0 | BN12: 0 | BO12: 0
A13: Bali Jimbaran | B13: 12 | C13: 2019

Sheet TOTAL
A1: Site Name | B1: Day | C1: Month | D1: Year | E1: Total (per Unit) bottles cans | F1: Total cost bottles cans | G1: Total (per Unit) cardboard | H1: Total cost cardboard | I1: Total (per Unit) paper | J1: Total cost paper | K1: Total (per Unit) mixed glass | L1: Total cost mixed glass | M1: Total (per Unit) aluminum | N1: Total cost aluminum | O1: Total (per Unit) other plastics | P1: Total cost other plastics | Q1: Total (per Unit) soap bars | R1: Total cost soap bars | S1: Total (per Unit) e waste | T1: Total cost e waste | U1: Total (per Unit) durable goods | V1: Total cost durable goods | W1: Total (per Unit) solid food waste | X1: Total cost solid food waste | Y1: Total (per Unit) leftover food | Z1: Total cost leftover food | AA1: Total (per Unit) inedible parts | AB1: Total cost inedible parts | AC1: Total (per Unit) liquid food waste | AD1: Total cost liquid food waste | AE1: Total (per Unit) kitchen grease | AF1: Total cost kitchen grease | AG1: Total (per Unit) liquid hazardous waste | AH1: Total cost liquid hazardous waste | AI1: Total (per Unit) other hazardous waste | AJ1: Total cost other hazardous waste | AK1: Total (per Unit) batteries | AL1: Total cost batteries | AM1: Total (per Unit) light bulbs | AN1: Total cost light bulbs | AO1: Total (per Unit) textiles | AP1: Total cost textiles | AQ1: Total (per Unit) paint | AR1: Total cost paint | AS1: Total (per Unit) recyclable | AT1: Total cost recyclable | AU1: Total (per Unit) commingled recyclables | AV1: Total cost commingled recyclables | AW1: Total (per Unit) paper cardboard | AX1: Total cost paper cardboard | AY1: Total (per Unit) mixed metals | AZ1: Total cost mixed metals | BA1: Total (per Unit) plastics | BB1: Total cost plastics | BC1: Total (per Unit) biodegradable | BD1: Total cost biodegradable | BE1: Total (per Unit) food waste | BF1: Total cost food waste | BG1: Total (per Unit) hazardous waste | BH1: Total cost hazardous waste | BI1: Total (per Unit) universal waste | BJ1: Total cost universal waste | BK1: Total (per Unit) hazardous and universal waste | BL1: Total cost hazardous and universal waste | BM1: Total (per Unit) medical waste | BN1: Total cost medical waste | BO1: Total (per Unit) tin | BP1: Total cost tin
A2: Bali Jimbaran | B2: 1 | C2: 11 | D2: 2019 | E2: ='FS Jimbaran Nov 2019'!M12 -> 5.3 | F2: ='FS Jimbaran Nov 2019'!N12 -> 0 | G2: 0 | H2: ='FS Jimbaran Nov 2019'!H12 -> 0 | I2: ='FS Jimbaran Nov 2019'!I12 -> 0 | J2: ='FS Jimbaran Nov 2019'!J12 -> 0 | K2: ='FS Jimbaran Nov 2019'!K12 -> 75 | L2: ='FS Jimbaran Nov 2019'!L12 -> 0 | M2: ='FS Jimbaran Nov 2019'!S12 -> 0 | N2: ='FS Jimbaran Nov 2019'!T12 -> 0 | O2: ='FS Jimbaran Nov 2019'!U12 -> 10.5 | P2: ='FS Jimbaran Nov 2019'!V12 -> 0 | Q2: ='FS Jimbaran Nov 2019'!BE12 -> 0 | R2: ='FS Jimbaran Nov 2019'!BF12 -> 0 | S2: ='FS Jimbaran Nov 2019'!BH12 -> 0 | T2: ='FS Jimbaran Nov 2019'!BH12 -> 0 | U2: ='FS Jimbaran Nov 2019'!BI12 -> 0 | V2: ='FS Jimbaran Nov 2019'!BJ12 -> 0 | W2: ='FS Jimbaran Nov 2019'!Y12 -> 600 | X2: ='FS Jimbaran Nov 2019'!Z12 -> 8284726 | Y2: ='FS Jimbaran Nov 2019'!AA12 -> 0 | Z2: ='FS Jimbaran Nov 2019'!AB12 -> 0 | AA2: ='FS Jimbaran Nov 2019'!AC12 -> 0 | AB2: ='FS Jimbaran Nov 2019'!AD12 -> 0 | AC2: ='FS Jimbaran Nov 2019'!AE12 -> 0 | AD2: ='FS Jimbaran Nov 2019'!AF12 -> 0 | ... AF2: ='FS Jimbaran Nov 2019'!AH12 -> 0 | AG2: ='FS Jimbaran Nov 2019'!AM12 -> 0 | AH2: ='FS Jimbaran Nov 2019'!AR12 -> 0 | AI2: ='FS Jimbaran Nov 2019'!AQ12 -> 0 | AJ2: ='FS Jimbaran Nov 2019'!AR12 -> 0 | AK2: ='FS Jimbaran Nov 2019'!AY12 -> 0 | AL2: ='FS Jimbaran Nov 2019'!AZ12 -> 0 | AM2: ='FS Jimbaran Nov 2019'!BB12 -> 0 | AN2: ='FS Jimbaran Nov 2019'!BB12 -> 0 | AO2: ='FS Jimbaran Nov 2019'!BK12 -> 0 | AP2: ='FS Jimbaran Nov 2019'!BL12 -> 0 | AQ2: ='FS Jimbaran Nov 2019'!BC12 -> 0 | AR2: ='FS Jimbaran Nov 2019'!BD12 -> 0 | AS2: ='FS Jimbaran Nov 2019'!BM12 -> 0 | AT2: ='FS Jimbaran Nov 2019'!BN12 -> 0 | AU2: ='FS Jimbaran Nov 2019'!BO12 -> 0 | AV2: ='FS Jimbaran Nov 2019'!BP12 -> 0 | AW2: ='FS Jimbaran Nov 2019'!E12 -> 77.4 | AX2: ='FS Jimbaran Nov 2019'!F12 -> 0 | AY2: ='FS Jimbaran Nov 2019'!O12 -> 0 | AZ2: ='FS Jimbaran Nov 2019'!P12 -> 0 | BA2: ='FS Jimbaran Nov 2019'!W12 -> 0 | BB2: ='FS Jimbaran Nov 2019'!X12 -> 0 | BC2: ='FS Jimbaran Nov 2019'!AI12 -> 670 | BD2: ='FS Jimbaran Nov 2019'!AJ12 -> 0 | BE2: ='FS Jimbaran Nov 2019'!AK12 -> 0 | BF2: ='FS Jimbaran Nov 2019'!AL12 -> 0 | BG2: ='FS Jimbaran Nov 2019'!AM12 -> 0 | BH2: ='FS Jimbaran Nov 2019'!AN12 -> 0 | BI2: ='FS Jimbaran Nov 2019'!AO12 -> 0 | BJ2: ='FS Jimbaran Nov 2019'!AO12 -> 0 | BK2: ='FS Jimbaran Nov 2019'!AQ12 -> 0 | BL2: ='FS Jimbaran Nov 2019'!AR12 -> 0 | BM2: 0 | BN2: 0 | BO2: ='FS Jimbaran Nov 2019'!Q12 -> 0 | BP2: ='FS Jimbaran Nov 2019'!R12 -> 0
A3: Bali Jimbaran | B3: =B2+1 -> 2 | C3: 11 | D3: 2019 | E3: ='FS Jimbaran Nov 2019'!M13 -> 5.6 | F3: ='FS Jimbaran Nov 2019'!N13 -> 0 | G3: 0 | H3: ='FS Jimbaran Nov 2019'!H13 -> 0 | I3: ='FS Jimbaran Nov 2019'!I13 -> 0 | J3: ='FS Jimbaran Nov 2019'!J13 -> 0 | K3: ='FS Jimbaran Nov 2019'!K13 -> 90 | L3: ='FS Jimbaran Nov 2019'!L13 -> 0 | M3: ='FS Jimbaran Nov 2019'!S13 -> 0 | N3: ='FS Jimbaran Nov 2019'!T13 -> 0 | O3: ='FS Jimbaran Nov 2019'!U13 -> 17 | P3: ='FS Jimbaran Nov 2019'!V13 -> 0 | Q3: ='FS Jimbaran Nov 2019'!BE13 -> 0 | R3: ='FS Jimbaran Nov 2019'!BF13 -> 0 | S3: ='FS Jimbaran Nov 2019'!BH13 -> 0 | T3: ='FS Jimbaran Nov 2019'!BH13 -> 0 | U3: ='FS Jimbaran Nov 2019'!BI13 -> 0 | V3: ='FS Jimbaran Nov 2019'!BJ13 -> 0 | W3: ='FS Jimbaran Nov 2019'!Y13 -> 640 | X3: ='FS Jimbaran Nov 2019'!Z13 -> 0 | Y3: ='FS Jimbaran Nov 2019'!AA13 -> 0 | Z3: ='FS Jimbaran Nov 2019'!AB13 -> 0 | AA3: ='FS Jimbaran Nov 2019'!AC13 -> 0 | AB3: ='FS Jimbaran Nov 2019'!AD13 -> 0 | AC3: ='FS Jimbaran Nov 2019'!AE13 -> 0 | AD3: ='FS Jimbaran Nov 2019'!AF13 -> 0 | ... AF3: ='FS Jimbaran Nov 2019'!AH13 -> 0 | AG3: ='FS Jimbaran Nov 2019'!AM13 -> 0 | AH3: ='FS Jimbaran Nov 2019'!AR13 -> 0 | AI3: ='FS Jimbaran Nov 2019'!AQ13 -> 0 | AJ3: ='FS Jimbaran Nov 2019'!AR13 -> 0 | AK3: ='FS Jimbaran Nov 2019'!AY13 -> 0 | AL3: ='FS Jimbaran Nov 2019'!AZ13 -> 0 | AM3: ='FS Jimbaran Nov 2019'!BB13 -> 0 | AN3: ='FS Jimbaran Nov 2019'!BB13 -> 0 | AO3: ='FS Jimbaran Nov 2019'!BK13 -> 0 | AP3: ='FS Jimbaran Nov 2019'!BL13 -> 0 | AQ3: ='FS Jimbaran Nov 2019'!BC13 -> 0 | AR3: ='FS Jimbaran Nov 2019'!BD13 -> 0 | AS3: ='FS Jimbaran Nov 2019'!BM13 -> 0 | AT3: ='FS Jimbaran Nov 2019'!BN13 -> 0 | AU3: ='FS Jimbaran Nov 2019'!BO13 -> 0 | AV3: ='FS Jimbaran Nov 2019'!BP13 -> 0 | AW3: ='FS Jimbaran Nov 2019'!E13 -> 70.7 | AX3: ='FS Jimbaran Nov 2019'!F13 -> 0 | AY3: ='FS Jimbaran Nov 2019'!O13 -> 0 | AZ3: ='FS Jimbaran Nov 2019'!P13 -> 0 | BA3: ='FS Jimbaran Nov 2019'!W13 -> 0 | BB3: ='FS Jimbaran Nov 2019'!X13 -> 0 | BC3: ='FS Jimbaran Nov 2019'!AI13 -> 600 | BD3: ='FS Jimbaran Nov 2019'!AJ13 -> 0 | BE3: ='FS Jimbaran Nov 2019'!AK13 -> 0 | BF3: ='FS Jimbaran Nov 2019'!AL13 -> 0 | BG3: ='FS Jimbaran Nov 2019'!AM13 -> 0 | BH3: ='FS Jimbaran Nov 2019'!AN13 -> 0 | BI3: ='FS Jimbaran Nov 2019'!AO13 -> 0 | BJ3: ='FS Jimbaran Nov 2019'!AO13 -> 0 | BK3: ='FS Jimbaran Nov 2019'!AQ13 -> 0 | BL3: ='FS Jimbaran Nov 2019'!AR13 -> 0 | BM3: 0 | BN3: 0 | BO3: ='FS Jimbaran Nov 2019'!Q13 -> 0 | BP3: ='FS Jimbaran Nov 2019'!R13 -> 0
A4: Bali Jimbaran | B4: =B3+1 -> 3 | C4: 11 | D4: 2019 | E4: ='FS Jimbaran Nov 2019'!M14 -> 2.6 | F4: ='FS Jimbaran Nov 2019'!N14 -> 0 | G4: 0 | H4: ='FS Jimbaran Nov 2019'!H14 -> 0 | I4: ='FS Jimbaran Nov 2019'!I14 -> 0 | J4: ='FS Jimbaran Nov 2019'!J14 -> 0 | K4: ='FS Jimbaran Nov 2019'!K14 -> 80 | L4: ='FS Jimbaran Nov 2019'!L14 -> 0 | M4: ='FS Jimbaran Nov 2019'!S14 -> 0 | N4: ='FS Jimbaran Nov 2019'!T14 -> 0 | O4: ='FS Jimbaran Nov 2019'!U14 -> 12.5 | P4: ='FS Jimbaran Nov 2019'!V14 -> 0 | Q4: ='FS Jimbaran Nov 2019'!BE14 -> 0 | R4: ='FS Jimbaran Nov 2019'!BF14 -> 0 | S4: ='FS Jimbaran Nov 2019'!BH14 -> 0 | T4: ='FS Jimbaran Nov 2019'!BH14 -> 0 | U4: ='FS Jimbaran Nov 2019'!BI14 -> 0 | V4: ='FS Jimbaran Nov 2019'!BJ14 -> 0 | W4: ='FS Jimbaran Nov 2019'!Y14 -> 608 | X4: ='FS Jimbaran Nov 2019'!Z14 -> 0 | Y4: ='FS Jimbaran Nov 2019'!AA14 -> 0 | Z4: ='FS Jimbaran Nov 2019'!AB14 -> 0 | AA4: ='FS Jimbaran Nov 2019'!AC14 -> 0 | AB4: ='FS Jimbaran Nov 2019'!AD14 -> 0 | AC4: ='FS Jimbaran Nov 2019'!AE14 -> 0 | AD4: ='FS Jimbaran Nov 2019'!AF14 -> 0 | ... AF4: ='FS Jimbaran Nov 2019'!AH14 -> 0 | AG4: ='FS Jimbaran Nov 2019'!AM14 -> 0 | AH4: ='FS Jimbaran Nov 2019'!AR14 -> 0 | AI4: ='FS Jimbaran Nov 2019'!AQ14 -> 0 | AJ4: ='FS Jimbaran Nov 2019'!AR14 -> 0 | AK4: ='FS Jimbaran Nov 2019'!AY14 -> 0 | AL4: ='FS Jimbaran Nov 2019'!AZ14 -> 0 | AM4: ='FS Jimbaran Nov 2019'!BB14 -> 0 | AN4: ='FS Jimbaran Nov 2019'!BB14 -> 0 | AO4: ='FS Jimbaran Nov 2019'!BK14 -> 0 | AP4: ='FS Jimbaran Nov 2019'!BL14 -> 0 | AQ4: ='FS Jimbaran Nov 2019'!BC14 -> 0 | AR4: ='FS Jimbaran Nov 2019'!BD14 -> 0 | AS4: ='FS Jimbaran Nov 2019'!BM14 -> 0 | AT4: ='FS Jimbaran Nov 2019'!BN14 -> 0 | AU4: ='FS Jimbaran Nov 2019'!BO14 -> 0 | AV4: ='FS Jimbaran Nov 2019'!BP14 -> 0 | AW4: ='FS Jimbaran Nov 2019'!E14 -> 96.6 | AX4: ='FS Jimbaran Nov 2019'!F14 -> 0 | AY4: ='FS Jimbaran Nov 2019'!O14 -> 0 | AZ4: ='FS Jimbaran Nov 2019'!P14 -> 0 | BA4: ='FS Jimbaran Nov 2019'!W14 -> 0 | BB4: ='FS Jimbaran Nov 2019'!X14 -> 0 | BC4: ='FS Jimbaran Nov 2019'!AI14 -> 640 | BD4: ='FS Jimbaran Nov 2019'!AJ14 -> 0 | BE4: ='FS Jimbaran Nov 2019'!AK14 -> 0 | BF4: ='FS Jimbaran Nov 2019'!AL14 -> 0 | BG4: ='FS Jimbaran Nov 2019'!AM14 -> 0 | BH4: ='FS Jimbaran Nov 2019'!AN14 -> 0 | BI4: ='FS Jimbaran Nov 2019'!AO14 -> 0 | BJ4: ='FS Jimbaran Nov 2019'!AO14 -> 0 | BK4: ='FS Jimbaran Nov 2019'!AQ14 -> 0 | BL4: ='FS Jimbaran Nov 2019'!AR14 -> 0 | BM4: 0 | BN4: 0 | BO4: ='FS Jimbaran Nov 2019'!Q14 -> 0 | BP4: ='FS Jimbaran Nov 2019'!R14 -> 0
A5: Bali Jimbaran | B5: =B4+1 -> 4 | C5: 11 | D5: 2019 | E5: ='FS Jimbaran Nov 2019'!M15 -> 5 | F5: ='FS Jimbaran Nov 2019'!N15 -> 0 | G5: 0 | H5: ='FS Jimbaran Nov 2019'!H15 -> 0 | I5: ='FS Jimbaran Nov 2019'!I15 -> 0 | J5: ='FS Jimbaran Nov 2019'!J15 -> 0 | K5: ='FS Jimbaran Nov 2019'!K15 -> 80 | L5: ='FS Jimbaran Nov 2019'!L15 -> 0 | M5: ='FS Jimbaran Nov 2019'!S15 -> 0 | N5: ='FS Jimbaran Nov 2019'!T15 -> 0 | O5: ='FS Jimbaran Nov 2019'!U15 -> 6.5 | P5: ='FS Jimbaran Nov 2019'!V15 -> 0 | Q5: ='FS Jimbaran Nov 2019'!BE15 -> 0 | R5: ='FS Jimbaran Nov 2019'!BF15 -> 0 | S5: ='FS Jimbaran Nov 2019'!BH15 -> 0 | T5: ='FS Jimbaran Nov 2019'!BH15 -> 0 | U5: ='FS Jimbaran Nov 2019'!BI15 -> 0 | V5: ='FS Jimbaran Nov 2019'!BJ15 -> 0 | W5: ='FS Jimbaran Nov 2019'!Y15 -> 592 | X5: ='FS Jimbaran Nov 2019'!Z15 -> 0 | Y5: ='FS Jimbaran Nov 2019'!AA15 -> 0 | Z5: ='FS Jimbaran Nov 2019'!AB15 -> 0 | AA5: ='FS Jimbaran Nov 2019'!AC15 -> 0 | AB5: ='FS Jimbaran Nov 2019'!AD15 -> 0 | AC5: ='FS Jimbaran Nov 2019'!AE15 -> 0 | AD5: ='FS Jimbaran Nov 2019'!AF15 -> 0 | ... AF5: ='FS Jimbaran Nov 2019'!AH15 -> 0 | AG5: ='FS Jimbaran Nov 2019'!AM15 -> 0 | AH5: ='FS Jimbaran Nov 2019'!AR15 -> 0 | AI5: ='FS Jimbaran Nov 2019'!AQ15 -> 0 | AJ5: ='FS Jimbaran Nov 2019'!AR15 -> 0 | AK5: ='FS Jimbaran Nov 2019'!AY15 -> 0 | AL5: ='FS Jimbaran Nov 2019'!AZ15 -> 0 | AM5: ='FS Jimbaran Nov 2019'!BB15 -> 0 | AN5: ='FS Jimbaran Nov 2019'!BB15 -> 0 | AO5: ='FS Jimbaran Nov 2019'!BK15 -> 0 | AP5: ='FS Jimbaran Nov 2019'!BL15 -> 0 | AQ5: ='FS Jimbaran Nov 2019'!BC15 -> 0 | AR5: ='FS Jimbaran Nov 2019'!BD15 -> 0 | AS5: ='FS Jimbaran Nov 2019'!BM15 -> 0 | AT5: ='FS Jimbaran Nov 2019'!BN15 -> 0 | AU5: ='FS Jimbaran Nov 2019'!BO15 -> 0 | AV5: ='FS Jimbaran Nov 2019'!BP15 -> 0 | AW5: ='FS Jimbaran Nov 2019'!E15 -> 72.4 | AX5: ='FS Jimbaran Nov 2019'!F15 -> 0 | AY5: ='FS Jimbaran Nov 2019'!O15 -> 0 | AZ5: ='FS Jimbaran Nov 2019'!P15 -> 0 | BA5: ='FS Jimbaran Nov 2019'!W15 -> 0 | BB5: ='FS Jimbaran Nov 2019'!X15 -> 0 | BC5: ='FS Jimbaran Nov 2019'!AI15 -> 600 | BD5: ='FS Jimbaran Nov 2019'!AJ15 -> 0 | BE5: ='FS Jimbaran Nov 2019'!AK15 -> 0 | BF5: ='FS Jimbaran Nov 2019'!AL15 -> 0 | BG5: ='FS Jimbaran Nov 2019'!AM15 -> 0 | BH5: ='FS Jimbaran Nov 2019'!AN15 -> 0 | BI5: ='FS Jimbaran Nov 2019'!AO15 -> 0 | BJ5: ='FS Jimbaran Nov 2019'!AO15 -> 0 | BK5: ='FS Jimbaran Nov 2019'!AQ15 -> 0 | BL5: ='FS Jimbaran Nov 2019'!AR15 -> 0 | BM5: 0 | BN5: 0 | BO5: ='FS Jimbaran Nov 2019'!Q15 -> 0 | BP5: ='FS Jimbaran Nov 2019'!R15 -> 0
A6: Bali Jimbaran | B6: =B5+1 -> 5 | C6: 11 | D6: 2019 | E6: ='FS Jimbaran Nov 2019'!M16 -> 4.7 | F6: ='FS Jimbaran Nov 2019'!N16 -> 0 | G6: 0 | H6: ='FS Jimbaran Nov 2019'!H16 -> 0 | I6: ='FS Jimbaran Nov 2019'!I16 -> 0 | J6: ='FS Jimbaran Nov 2019'!J16 -> 0 | K6: ='FS Jimbaran Nov 2019'!K16 -> 91 | L6: ='FS Jimbaran Nov 2019'!L16 -> 0 | M6: ='FS Jimbaran Nov 2019'!S16 -> 0 | N6: ='FS Jimbaran Nov 2019'!T16 -> 0 | O6: ='FS Jimbaran Nov 2019'!U16 -> 18 | P6: ='FS Jimbaran Nov 2019'!V16 -> 0 | Q6: ='FS Jimbaran Nov 2019'!BE16 -> 0 | R6: ='FS Jimbaran Nov 2019'!BF16 -> 0 | S6: ='FS Jimbaran Nov 2019'!BH16 -> 0 | T6: ='FS Jimbaran Nov 2019'!BH16 -> 0 | U6: ='FS Jimbaran Nov 2019'!BI16 -> 0 | V6: ='FS Jimbaran Nov 2019'!BJ16 -> 0 | W6: ='FS Jimbaran Nov 2019'!Y16 -> 624 | X6: ='FS Jimbaran Nov 2019'!Z16 -> 0 | Y6: ='FS Jimbaran Nov 2019'!AA16 -> 0 | Z6: ='FS Jimbaran Nov 2019'!AB16 -> 0 | AA6: ='FS Jimbaran Nov 2019'!AC16 -> 0 | AB6: ='FS Jimbaran Nov 2019'!AD16 -> 0 | AC6: ='FS Jimbaran Nov 2019'!AE16 -> 0 | AD6: ='FS Jimbaran Nov 2019'!AF16 -> 0 | ... AF6: ='FS Jimbaran Nov 2019'!AH16 -> 0 | AG6: ='FS Jimbaran Nov 2019'!AM16 -> 0 | AH6: ='FS Jimbaran Nov 2019'!AR16 -> 0 | AI6: ='FS Jimbaran Nov 2019'!AQ16 -> 0 | AJ6: ='FS Jimbaran Nov 2019'!AR16 -> 0 | AK6: ='FS Jimbaran Nov 2019'!AY16 -> 0 | AL6: ='FS Jimbaran Nov 2019'!AZ16 -> 0 | AM6: ='FS Jimbaran Nov 2019'!BB16 -> 0 | AN6: ='FS Jimbaran Nov 2019'!BB16 -> 0 | AO6: ='FS Jimbaran Nov 2019'!BK16 -> 0 | AP6: ='FS Jimbaran Nov 2019'!BL16 -> 0 | AQ6: ='FS Jimbaran Nov 2019'!BC16 -> 0 | AR6: ='FS Jimbaran Nov 2019'!BD16 -> 0 | AS6: ='FS Jimbaran Nov 2019'!BM16 -> 0 | AT6: ='FS Jimbaran Nov 2019'!BN16 -> 0 | AU6: ='FS Jimbaran Nov 2019'!BO16 -> 0 | AV6: ='FS Jimbaran Nov 2019'!BP16 -> 0 | AW6: ='FS Jimbaran Nov 2019'!E16 -> 86.1 | AX6: ='FS Jimbaran Nov 2019'!F16 -> 0 | AY6: ='FS Jimbaran Nov 2019'!O16 -> 0 | AZ6: ='FS Jimbaran Nov 2019'!P16 -> 0 | BA6: ='FS Jimbaran Nov 2019'!W16 -> 0 | BB6: ='FS Jimbaran Nov 2019'!X16 -> 0 | BC6: ='FS Jimbaran Nov 2019'!AI16 -> 530 | BD6: ='FS Jimbaran Nov 2019'!AJ16 -> 0 | BE6: ='FS Jimbaran Nov 2019'!AK16 -> 0 | BF6: ='FS Jimbaran Nov 2019'!AL16 -> 0 | BG6: ='FS Jimbaran Nov 2019'!AM16 -> 0 | BH6: ='FS Jimbaran Nov 2019'!AN16 -> 0 | BI6: ='FS Jimbaran Nov 2019'!AO16 -> 0 | BJ6: ='FS Jimbaran Nov 2019'!AO16 -> 0 | BK6: ='FS Jimbaran Nov 2019'!AQ16 -> 0 | BL6: ='FS Jimbaran Nov 2019'!AR16 -> 0 | BM6: 0 | BN6: 0 | BO6: ='FS Jimbaran Nov 2019'!Q16 -> 0 | BP6: ='FS Jimbaran Nov 2019'!R16 -> 0
A7: Bali Jimbaran | B7: =B6+1 -> 6 | C7: 11 | D7: 2019 | E7: ='FS Jimbaran Nov 2019'!M17 -> 6.3 | F7: ='FS Jimbaran Nov 2019'!N17 -> 0 | G7: 0 | H7: ='FS Jimbaran Nov 2019'!H17 -> 0 | I7: ='FS Jimbaran Nov 2019'!I17 -> 0 | J7: ='FS Jimbaran Nov 2019'!J17 -> 0 | K7: ='FS Jimbaran Nov 2019'!K17 -> 85 | L7: ='FS Jimbaran Nov 2019'!L17 -> 0 | M7: ='FS Jimbaran Nov 2019'!S17 -> 0 | N7: ='FS Jimbaran Nov 2019'!T17 -> 0 | O7: ='FS Jimbaran Nov 2019'!U17 -> 11 | P7: ='FS Jimbaran Nov 2019'!V17 -> 0 | Q7: ='FS Jimbaran Nov 2019'!BE17 -> 0 | R7: ='FS Jimbaran Nov 2019'!BF17 -> 0 | S7: ='FS Jimbaran Nov 2019'!BH17 -> 0 | T7: ='FS Jimbaran Nov 2019'!BH17 -> 0 | U7: ='FS Jimbaran Nov 2019'!BI17 -> 0 | V7: ='FS Jimbaran Nov 2019'!BJ17 -> 0 | W7: ='FS Jimbaran Nov 2019'!Y17 -> 640 | X7: ='FS Jimbaran Nov 2019'!Z17 -> 0 | Y7: ='FS Jimbaran Nov 2019'!AA17 -> 0 | Z7: ='FS Jimbaran Nov 2019'!AB17 -> 0 | AA7: ='FS Jimbaran Nov 2019'!AC17 -> 0 | AB7: ='FS Jimbaran Nov 2019'!AD17 -> 0 | AC7: ='FS Jimbaran Nov 2019'!AE17 -> 0 | AD7: ='FS Jimbaran Nov 2019'!AF17 -> 0 | ... AF7: ='FS Jimbaran Nov 2019'!AH17 -> 0 | AG7: ='FS Jimbaran Nov 2019'!AM17 -> 0 | AH7: ='FS Jimbaran Nov 2019'!AR17 -> 0 | AI7: ='FS Jimbaran Nov 2019'!AQ17 -> 0 | AJ7: ='FS Jimbaran Nov 2019'!AR17 -> 0 | AK7: ='FS Jimbaran Nov 2019'!AY17 -> 0 | AL7: ='FS Jimbaran Nov 2019'!AZ17 -> 0 | AM7: ='FS Jimbaran Nov 2019'!BB17 -> 0 | AN7: ='FS Jimbaran Nov 2019'!BB17 -> 0 | AO7: ='FS Jimbaran Nov 2019'!BK17 -> 0 | AP7: ='FS Jimbaran Nov 2019'!BL17 -> 0 | AQ7: ='FS Jimbaran Nov 2019'!BC17 -> 0 | AR7: ='FS Jimbaran Nov 2019'!BD17 -> 0 | AS7: ='FS Jimbaran Nov 2019'!BM17 -> 0 | AT7: ='FS Jimbaran Nov 2019'!BN17 -> 0 | AU7: ='FS Jimbaran Nov 2019'!BO17 -> 0 | AV7: ='FS Jimbaran Nov 2019'!BP17 -> 0 | AW7: ='FS Jimbaran Nov 2019'!E17 -> 86.9 | AX7: ='FS Jimbaran Nov 2019'!F17 -> 0 | AY7: ='FS Jimbaran Nov 2019'!O17 -> 0 | AZ7: ='FS Jimbaran Nov 2019'!P17 -> 0 | BA7: ='FS Jimbaran Nov 2019'!W17 -> 0 | BB7: ='FS Jimbaran Nov 2019'!X17 -> 0 | BC7: ='FS Jimbaran Nov 2019'!AI17 -> 640 | BD7: ='FS Jimbaran Nov 2019'!AJ17 -> 0 | BE7: ='FS Jimbaran Nov 2019'!AK17 -> 0 | BF7: ='FS Jimbaran Nov 2019'!AL17 -> 0 | BG7: ='FS Jimbaran Nov 2019'!AM17 -> 0 | BH7: ='FS Jimbaran Nov 2019'!AN17 -> 0 | BI7: ='FS Jimbaran Nov 2019'!AO17 -> 0 | BJ7: ='FS Jimbaran Nov 2019'!AO17 -> 0 | BK7: ='FS Jimbaran Nov 2019'!AQ17 -> 0 | BL7: ='FS Jimbaran Nov 2019'!AR17 -> 0 | BM7: 0 | BN7: 0 | BO7: ='FS Jimbaran Nov 2019'!Q17 -> 0 | BP7: ='FS Jimbaran Nov 2019'!R17 -> 0
A8: Bali Jimbaran | B8: =B7+1 -> 7 | C8: 11 | D8: 2019 | E8: ='FS Jimbaran Nov 2019'!M18 -> 6.1 | F8: ='FS Jimbaran Nov 2019'!N18 -> 0 | G8: 0 | H8: ='FS Jimbaran Nov 2019'!H18 -> 0 | I8: ='FS Jimbaran Nov 2019'!I18 -> 0 | J8: ='FS Jimbaran Nov 2019'!J18 -> 0 | K8: ='FS Jimbaran Nov 2019'!K18 -> 95 | L8: ='FS Jimbaran Nov 2019'!L18 -> 0 | M8: ='FS Jimbaran Nov 2019'!S18 -> 0 | N8: ='FS Jimbaran Nov 2019'!T18 -> 0 | O8: ='FS Jimbaran Nov 2019'!U18 -> 7.5 | P8: ='FS Jimbaran Nov 2019'!V18 -> 0 | Q8: ='FS Jimbaran Nov 2019'!BE18 -> 0 | R8: ='FS Jimbaran Nov 2019'!BF18 -> 0 | S8: ='FS Jimbaran Nov 2019'!BH18 -> 0 | T8: ='FS Jimbaran Nov 2019'!BH18 -> 0 | U8: ='FS Jimbaran Nov 2019'!BI18 -> 0 | V8: ='FS Jimbaran Nov 2019'!BJ18 -> 0 | W8: ='FS Jimbaran Nov 2019'!Y18 -> 648 | X8: ='FS Jimbaran Nov 2019'!Z18 -> 0 | Y8: ='FS Jimbaran Nov 2019'!AA18 -> 0 | Z8: ='FS Jimbaran Nov 2019'!AB18 -> 0 | AA8: ='FS Jimbaran Nov 2019'!AC18 -> 0 | AB8: ='FS Jimbaran Nov 2019'!AD18 -> 0 | AC8: ='FS Jimbaran Nov 2019'!AE18 -> 0 | AD8: ='FS Jimbaran Nov 2019'!AF18 -> 0 | ... AF8: ='FS Jimbaran Nov 2019'!AH18 -> 0 | AG8: ='FS Jimbaran Nov 2019'!AM18 -> 0 | AH8: ='FS Jimbaran Nov 2019'!AR18 -> 0 | AI8: ='FS Jimbaran Nov 2019'!AQ18 -> 0 | AJ8: ='FS Jimbaran Nov 2019'!AR18 -> 0 | AK8: ='FS Jimbaran Nov 2019'!AY18 -> 0 | AL8: ='FS Jimbaran Nov 2019'!AZ18 -> 0 | AM8: ='FS Jimbaran Nov 2019'!BB18 -> 0 | AN8: ='FS Jimbaran Nov 2019'!BB18 -> 0 | AO8: ='FS Jimbaran Nov 2019'!BK18 -> 0 | AP8: ='FS Jimbaran Nov 2019'!BL18 -> 0 | AQ8: ='FS Jimbaran Nov 2019'!BC18 -> 0 | AR8: ='FS Jimbaran Nov 2019'!BD18 -> 0 | AS8: ='FS Jimbaran Nov 2019'!BM18 -> 0 | AT8: ='FS Jimbaran Nov 2019'!BN18 -> 0 | AU8: ='FS Jimbaran Nov 2019'!BO18 -> 0 | AV8: ='FS Jimbaran Nov 2019'!BP18 -> 0 | AW8: ='FS Jimbaran Nov 2019'!E18 -> 82.7 | AX8: ='FS Jimbaran Nov 2019'!F18 -> 0 | AY8: ='FS Jimbaran Nov 2019'!O18 -> 0 | AZ8: ='FS Jimbaran Nov 2019'!P18 -> 0 | BA8: ='FS Jimbaran Nov 2019'!W18 -> 0 | BB8: ='FS Jimbaran Nov 2019'!X18 -> 0 | BC8: ='FS Jimbaran Nov 2019'!AI18 -> 480 | BD8: ='FS Jimbaran Nov 2019'!AJ18 -> 0 | BE8: ='FS Jimbaran Nov 2019'!AK18 -> 0 | BF8: ='FS Jimbaran Nov 2019'!AL18 -> 0 | BG8: ='FS Jimbaran Nov 2019'!AM18 -> 0 | BH8: ='FS Jimbaran Nov 2019'!AN18 -> 0 | BI8: ='FS Jimbaran Nov 2019'!AO18 -> 0 | BJ8: ='FS Jimbaran Nov 2019'!AO18 -> 0 | BK8: ='FS Jimbaran Nov 2019'!AQ18 -> 0 | BL8: ='FS Jimbaran Nov 2019'!AR18 -> 0 | BM8: 0 | BN8: 0 | BO8: ='FS Jimbaran Nov 2019'!Q18 -> 0 | BP8: ='FS Jimbaran Nov 2019'!R18 -> 0
A9: Bali Jimbaran | B9: =B8+1 -> 8 | C9: 11 | D9: 2019 | E9: ='FS Jimbaran Nov 2019'!M19 -> 6.1 | F9: ='FS Jimbaran Nov 2019'!N19 -> 0 | G9: 0 | H9: ='FS Jimbaran Nov 2019'!H19 -> 0 | I9: ='FS Jimbaran Nov 2019'!I19 -> 0 | J9: ='FS Jimbaran Nov 2019'!J19 -> 0 | K9: ='FS Jimbaran Nov 2019'!K19 -> 105 | L9: ='FS Jimbaran Nov 2019'!L19 -> 0 | M9: ='FS Jimbaran Nov 2019'!S19 -> 0 | N9: ='FS Jimbaran Nov 2019'!T19 -> 0 | O9: ='FS Jimbaran Nov 2019'!U19 -> 14 | P9: ='FS Jimbaran Nov 2019'!V19 -> 0 | Q9: ='FS Jimbaran Nov 2019'!BE19 -> 0 | R9: ='FS Jimbaran Nov 2019'!BF19 -> 0 | S9: ='FS Jimbaran Nov 2019'!BH19 -> 0 | T9: ='FS Jimbaran Nov 2019'!BH19 -> 0 | U9: ='FS Jimbaran Nov 2019'!BI19 -> 0 | V9: ='FS Jimbaran Nov 2019'!BJ19 -> 0 | W9: ='FS Jimbaran Nov 2019'!Y19 -> 640 | X9: ='FS Jimbaran Nov 2019'!Z19 -> 0 | Y9: ='FS Jimbaran Nov 2019'!AA19 -> 0 | Z9: ='FS Jimbaran Nov 2019'!AB19 -> 0 | AA9: ='FS Jimbaran Nov 2019'!AC19 -> 0 | AB9: ='FS Jimbaran Nov 2019'!AD19 -> 0 | AC9: ='FS Jimbaran Nov 2019'!AE19 -> 0 | AD9: ='FS Jimbaran Nov 2019'!AF19 -> 0 | ... AF9: ='FS Jimbaran Nov 2019'!AH19 -> 0 | AG9: ='FS Jimbaran Nov 2019'!AM19 -> 0 | AH9: ='FS Jimbaran Nov 2019'!AR19 -> 0 | AI9: ='FS Jimbaran Nov 2019'!AQ19 -> 0 | AJ9: ='FS Jimbaran Nov 2019'!AR19 -> 0 | AK9: ='FS Jimbaran Nov 2019'!AY19 -> 0 | AL9: ='FS Jimbaran Nov 2019'!AZ19 -> 0 | AM9: ='FS Jimbaran Nov 2019'!BB19 -> 0 | AN9: ='FS Jimbaran Nov 2019'!BB19 -> 0 | AO9: ='FS Jimbaran Nov 2019'!BK19 -> 0 | AP9: ='FS Jimbaran Nov 2019'!BL19 -> 0 | AQ9: ='FS Jimbaran Nov 2019'!BC19 -> 0 | AR9: ='FS Jimbaran Nov 2019'!BD19 -> 0 | AS9: ='FS Jimbaran Nov 2019'!BM19 -> 0 | AT9: ='FS Jimbaran Nov 2019'!BN19 -> 0 | AU9: ='FS Jimbaran Nov 2019'!BO19 -> 0 | AV9: ='FS Jimbaran Nov 2019'!BP19 -> 0 | AW9: ='FS Jimbaran Nov 2019'!E19 -> 92.1 | AX9: ='FS Jimbaran Nov 2019'!F19 -> 0 | AY9: ='FS Jimbaran Nov 2019'!O19 -> 0 | AZ9: ='FS Jimbaran Nov 2019'!P19 -> 0 | BA9: ='FS Jimbaran Nov 2019'!W19 -> 0 | BB9: ='FS Jimbaran Nov 2019'!X19 -> 0 | BC9: ='FS Jimbaran Nov 2019'!AI19 -> 700 | BD9: ='FS Jimbaran Nov 2019'!AJ19 -> 0 | BE9: ='FS Jimbaran Nov 2019'!AK19 -> 0 | BF9: ='FS Jimbaran Nov 2019'!AL19 -> 0 | BG9: ='FS Jimbaran Nov 2019'!AM19 -> 0 | BH9: ='FS Jimbaran Nov 2019'!AN19 -> 0 | BI9: ='FS Jimbaran Nov 2019'!AO19 -> 0 | BJ9: ='FS Jimbaran Nov 2019'!AO19 -> 0 | BK9: ='FS Jimbaran Nov 2019'!AQ19 -> 0 | BL9: ='FS Jimbaran Nov 2019'!AR19 -> 0 | BM9: 0 | BN9: 0 | BO9: ='FS Jimbaran Nov 2019'!Q19 -> 0 | BP9: ='FS Jimbaran Nov 2019'!R19 -> 0
A10: Bali Jimbaran | B10: =B9+1 -> 9 | C10: 11 | D10: 2019 | E10: ='FS Jimbaran Nov 2019'!M20 -> 5.3 | F10: ='FS Jimbaran Nov 2019'!N20 -> 0 | G10: 0 | H10: ='FS Jimbaran Nov 2019'!H20 -> 0 | I10: ='FS Jimbaran Nov 2019'!I20 -> 0 | J10: ='FS Jimbaran Nov 2019'!J20 -> 0 | K10: ='FS Jimbaran Nov 2019'!K20 -> 75 | L10: ='FS Jimbaran Nov 2019'!L20 -> 0 | M10: ='FS Jimbaran Nov 2019'!S20 -> 0 | N10: ='FS Jimbaran Nov 2019'!T20 -> 0 | O10: ='FS Jimbaran Nov 2019'!U20 -> 15.5 | P10: ='FS Jimbaran Nov 2019'!V20 -> 0 | Q10: ='FS Jimbaran Nov 2019'!BE20 -> 0 | R10: ='FS Jimbaran Nov 2019'!BF20 -> 0 | S10: ='FS Jimbaran Nov 2019'!BH20 -> 0 | T10: ='FS Jimbaran Nov 2019'!BH20 -> 0 | U10: ='FS Jimbaran Nov 2019'!BI20 -> 0 | V10: ='FS Jimbaran Nov 2019'!BJ20 -> 0 | W10: ='FS Jimbaran Nov 2019'!Y20 -> 640 | X10: ='FS Jimbaran Nov 2019'!Z20 -> 0 | Y10: ='FS Jimbaran Nov 2019'!AA20 -> 0 | Z10: ='FS Jimbaran Nov 2019'!AB20 -> 0 | AA10: ='FS Jimbaran Nov 2019'!AC20 -> 0 | AB10: ='FS Jimbaran Nov 2019'!AD20 -> 0 | AC10: ='FS Jimbaran Nov 2019'!AE20 -> 0 | AD10: ='FS Jimbaran Nov 2019'!AF20 -> 0 | ... AF10: ='FS Jimbaran Nov 2019'!AH20 -> 0 | AG10: ='FS Jimbaran Nov 2019'!AM20 -> 0 | AH10: ='FS Jimbaran Nov 2019'!AR20 -> 0 | AI10: ='FS Jimbaran Nov 2019'!AQ20 -> 0 | AJ10: ='FS Jimbaran Nov 2019'!AR20 -> 0 | AK10: ='FS Jimbaran Nov 2019'!AY20 -> 0 | AL10: ='FS Jimbaran Nov 2019'!AZ20 -> 0 | AM10: ='FS Jimbaran Nov 2019'!BB20 -> 0 | AN10: ='FS Jimbaran Nov 2019'!BB20 -> 0 | AO10: ='FS Jimbaran Nov 2019'!BK20 -> 0 | AP10: ='FS Jimbaran Nov 2019'!BL20 -> 0 | AQ10: ='FS Jimbaran Nov 2019'!BC20 -> 0 | AR10: ='FS Jimbaran Nov 2019'!BD20 -> 0 | AS10: ='FS Jimbaran Nov 2019'!BM20 -> 0 | AT10: ='FS Jimbaran Nov 2019'!BN20 -> 0 | AU10: ='FS Jimbaran Nov 2019'!BO20 -> 0 | AV10: ='FS Jimbaran Nov 2019'!BP20 -> 0 | AW10: ='FS Jimbaran Nov 2019'!E20 -> 87.1 | AX10: ='FS Jimbaran Nov 2019'!F20 -> 0 | AY10: ='FS Jimbaran Nov 2019'!O20 -> 0 | AZ10: ='FS Jimbaran Nov 2019'!P20 -> 0 | BA10: ='FS Jimbaran Nov 2019'!W20 -> 0 | BB10: ='FS Jimbaran Nov 2019'!X20 -> 0 | BC10: ='FS Jimbaran Nov 2019'!AI20 -> 610 | BD10: ='FS Jimbaran Nov 2019'!AJ20 -> 0 | BE10: ='FS Jimbaran Nov 2019'!AK20 -> 0 | BF10: ='FS Jimbaran Nov 2019'!AL20 -> 0 | BG10: ='FS Jimbaran Nov 2019'!AM20 -> 0 | BH10: ='FS Jimbaran Nov 2019'!AN20 -> 0 | BI10: ='FS Jimbaran Nov 2019'!AO20 -> 0 | BJ10: ='FS Jimbaran Nov 2019'!AO20 -> 0 | BK10: ='FS Jimbaran Nov 2019'!AQ20 -> 0 | BL10: ='FS Jimbaran Nov 2019'!AR20 -> 0 | BM10: 0 | BN10: 0 | BO10: ='FS Jimbaran Nov 2019'!Q20 -> 0 | BP10: ='FS Jimbaran Nov 2019'!R20 -> 0
A11: Bali Jimbaran | B11: =B10+1 -> 10 | C11: 11 | D11: 2019 | E11: ='FS Jimbaran Nov 2019'!M21 -> 5.6 | F11: ='FS Jimbaran Nov 2019'!N21 -> 0 | G11: 0 | H11: ='FS Jimbaran Nov 2019'!H21 -> 0 | I11: ='FS Jimbaran Nov 2019'!I21 -> 0 | J11: ='FS Jimbaran Nov 2019'!J21 -> 0 | K11: ='FS Jimbaran Nov 2019'!K21 -> 90 | L11: ='FS Jimbaran Nov 2019'!L21 -> 0 | M11: ='FS Jimbaran Nov 2019'!S21 -> 0 | N11: ='FS Jimbaran Nov 2019'!T21 -> 0 | O11: ='FS Jimbaran Nov 2019'!U21 -> 7 | P11: ='FS Jimbaran Nov 2019'!V21 -> 0 | Q11: ='FS Jimbaran Nov 2019'!BE21 -> 0 | R11: ='FS Jimbaran Nov 2019'!BF21 -> 0 | S11: ='FS Jimbaran Nov 2019'!BH21 -> 0 | T11: ='FS Jimbaran Nov 2019'!BH21 -> 0 | U11: ='FS Jimbaran Nov 2019'!BI21 -> 0 | V11: ='FS Jimbaran Nov 2019'!BJ21 -> 0 | W11: ='FS Jimbaran Nov 2019'!Y21 -> 624 | X11: ='FS Jimbaran Nov 2019'!Z21 -> 0 | Y11: ='FS Jimbaran Nov 2019'!AA21 -> 0 | Z11: ='FS Jimbaran Nov 2019'!AB21 -> 0 | AA11: ='FS Jimbaran Nov 2019'!AC21 -> 0 | AB11: ='FS Jimbaran Nov 2019'!AD21 -> 0 | AC11: ='FS Jimbaran Nov 2019'!AE21 -> 0 | AD11: ='FS Jimbaran Nov 2019'!AF21 -> 0 | ... AF11: ='FS Jimbaran Nov 2019'!AH21 -> 0 | AG11: ='FS Jimbaran Nov 2019'!AM21 -> 0 | AH11: ='FS Jimbaran Nov 2019'!AR21 -> 0 | AI11: ='FS Jimbaran Nov 2019'!AQ21 -> 0 | AJ11: ='FS Jimbaran Nov 2019'!AR21 -> 0 | AK11: ='FS Jimbaran Nov 2019'!AY21 -> 0 | AL11: ='FS Jimbaran Nov 2019'!AZ21 -> 0 | AM11: ='FS Jimbaran Nov 2019'!BB21 -> 0 | AN11: ='FS Jimbaran Nov 2019'!BB21 -> 0 | AO11: ='FS Jimbaran Nov 2019'!BK21 -> 0 | AP11: ='FS Jimbaran Nov 2019'!BL21 -> 0 | AQ11: ='FS Jimbaran Nov 2019'!BC21 -> 0 | AR11: ='FS Jimbaran Nov 2019'!BD21 -> 0 | AS11: ='FS Jimbaran Nov 2019'!BM21 -> 0 | AT11: ='FS Jimbaran Nov 2019'!BN21 -> 0 | AU11: ='FS Jimbaran Nov 2019'!BO21 -> 0 | AV11: ='FS Jimbaran Nov 2019'!BP21 -> 0 | AW11: ='FS Jimbaran Nov 2019'!E21 -> 80.1 | AX11: ='FS Jimbaran Nov 2019'!F21 -> 0 | AY11: ='FS Jimbaran Nov 2019'!O21 -> 0 | AZ11: ='FS Jimbaran Nov 2019'!P21 -> 0 | BA11: ='FS Jimbaran Nov 2019'!W21 -> 0 | BB11: ='FS Jimbaran Nov 2019'!X21 -> 0 | BC11: ='FS Jimbaran Nov 2019'!AI21 -> 640 | BD11: ='FS Jimbaran Nov 2019'!AJ21 -> 0 | BE11: ='FS Jimbaran Nov 2019'!AK21 -> 0 | BF11: ='FS Jimbaran Nov 2019'!AL21 -> 0 | BG11: ='FS Jimbaran Nov 2019'!AM21 -> 0 | BH11: ='FS Jimbaran Nov 2019'!AN21 -> 0 | BI11: ='FS Jimbaran Nov 2019'!AO21 -> 0 | BJ11: ='FS Jimbaran Nov 2019'!AO21 -> 0 | BK11: ='FS Jimbaran Nov 2019'!AQ21 -> 0 | BL11: ='FS Jimbaran Nov 2019'!AR21 -> 0 | BM11: 0 | BN11: 0 | BO11: ='FS Jimbaran Nov 2019'!Q21 -> 0 | BP11: ='FS Jimbaran Nov 2019'!R21 -> 0
A12: Bali Jimbaran | B12: =B11+1 -> 11 | C12: 11 | D12: 2019 | E12: ='FS Jimbaran Nov 2019'!M22 -> 3.8 | F12: ='FS Jimbaran Nov 2019'!N22 -> 0 | G12: 0 | H12: ='FS Jimbaran Nov 2019'!H22 -> 0 | I12: ='FS Jimbaran Nov 2019'!I22 -> 0 | J12: ='FS Jimbaran Nov 2019'!J22 -> 0 | K12: ='FS Jimbaran Nov 2019'!K22 -> 105 | L12: ='FS Jimbaran Nov 2019'!L22 -> 0 | M12: ='FS Jimbaran Nov 2019'!S22 -> 0 | N12: ='FS Jimbaran Nov 2019'!T22 -> 0 | O12: ='FS Jimbaran Nov 2019'!U22 -> 16.5 | P12: ='FS Jimbaran Nov 2019'!V22 -> 0 | Q12: ='FS Jimbaran Nov 2019'!BE22 -> 0 | R12: ='FS Jimbaran Nov 2019'!BF22 -> 0 | S12: ='FS Jimbaran Nov 2019'!BH22 -> 0 | T12: ='FS Jimbaran Nov 2019'!BH22 -> 0 | U12: ='FS Jimbaran Nov 2019'!BI22 -> 0 | V12: ='FS Jimbaran Nov 2019'!BJ22 -> 0 | W12: ='FS Jimbaran Nov 2019'!Y22 -> 608 | X12: ='FS Jimbaran Nov 2019'!Z22 -> 0 | Y12: ='FS Jimbaran Nov 2019'!AA22 -> 0 | Z12: ='FS Jimbaran Nov 2019'!AB22 -> 0 | AA12: ='FS Jimbaran Nov 2019'!AC22 -> 0 | AB12: ='FS Jimbaran Nov 2019'!AD22 -> 0 | AC12: ='FS Jimbaran Nov 2019'!AE22 -> 0 | AD12: ='FS Jimbaran Nov 2019'!AF22 -> 0 | ... AF12: ='FS Jimbaran Nov 2019'!AH22 -> 0 | AG12: ='FS Jimbaran Nov 2019'!AM22 -> 0 | AH12: ='FS Jimbaran Nov 2019'!AR22 -> 0 | AI12: ='FS Jimbaran Nov 2019'!AQ22 -> 0 | AJ12: ='FS Jimbaran Nov 2019'!AR22 -> 0 | AK12: ='FS Jimbaran Nov 2019'!AY22 -> 0 | AL12: ='FS Jimbaran Nov 2019'!AZ22 -> 0 | AM12: ='FS Jimbaran Nov 2019'!BB22 -> 0 | AN12: ='FS Jimbaran Nov 2019'!BB22 -> 0 | AO12: ='FS Jimbaran Nov 2019'!BK22 -> 0 | AP12: ='FS Jimbaran Nov 2019'!BL22 -> 0 | AQ12: ='FS Jimbaran Nov 2019'!BC22 -> 0 | AR12: ='FS Jimbaran Nov 2019'!BD22 -> 0 | AS12: ='FS Jimbaran Nov 2019'!BM22 -> 0 | AT12: ='FS Jimbaran Nov 2019'!BN22 -> 0 | AU12: ='FS Jimbaran Nov 2019'!BO22 -> 0 | AV12: ='FS Jimbaran Nov 2019'!BP22 -> 0 | AW12: ='FS Jimbaran Nov 2019'!E22 -> 88.5 | AX12: ='FS Jimbaran Nov 2019'!F22 -> 0 | AY12: ='FS Jimbaran Nov 2019'!O22 -> 0 | AZ12: ='FS Jimbaran Nov 2019'!P22 -> 0 | BA12: ='FS Jimbaran Nov 2019'!W22 -> 0 | BB12: ='FS Jimbaran Nov 2019'!X22 -> 0 | BC12: ='FS Jimbaran Nov 2019'!AI22 -> 620 | BD12: ='FS Jimbaran Nov 2019'!AJ22 -> 0 | BE12: ='FS Jimbaran Nov 2019'!AK22 -> 0 | BF12: ='FS Jimbaran Nov 2019'!AL22 -> 0 | BG12: ='FS Jimbaran Nov 2019'!AM22 -> 0 | BH12: ='FS Jimbaran Nov 2019'!AN22 -> 0 | BI12: ='FS Jimbaran Nov 2019'!AO22 -> 0 | BJ12: ='FS Jimbaran Nov 2019'!AO22 -> 0 | BK12: ='FS Jimbaran Nov 2019'!AQ22 -> 0 | BL12: ='FS Jimbaran Nov 2019'!AR22 -> 0 | BM12: 0 | BN12: 0 | BO12: ='FS Jimbaran Nov 2019'!Q22 -> 0 | BP12: ='FS Jimbaran Nov 2019'!R22 -> 0
A13: Bali Jimbaran | B13: =B12+1 -> 12 | C13: 11 | D13: 2019 | E13: ='FS Jimbaran Nov 2019'!M23 -> 5 | F13: ='FS Jimbaran Nov 2019'!N23 -> 0 | G13: 0 | H13: ='FS Jimbaran Nov 2019'!H23 -> 0 | I13: ='FS Jimbaran Nov 2019'!I23 -> 0 | J13: ='FS Jimbaran Nov 2019'!J23 -> 0 | K13: ='FS Jimbaran Nov 2019'!K23 -> 85 | L13: ='FS Jimbaran Nov 2019'!L23 -> 0 | M13: ='FS Jimbaran Nov 2019'!S23 -> 0 | N13: ='FS Jimbaran Nov 2019'!T23 -> 0 | O13: ='FS Jimbaran Nov 2019'!U23 -> 12.5 | P13: ='FS Jimbaran Nov 2019'!V23 -> 0 | Q13: ='FS Jimbaran Nov 2019'!BE23 -> 0 | R13: ='FS Jimbaran Nov 2019'!BF23 -> 0 | S13: ='FS Jimbaran Nov 2019'!BH23 -> 0 | T13: ='FS Jimbaran Nov 2019'!BH23 -> 0 | U13: ='FS Jimbaran Nov 2019'!BI23 -> 0 | V13: ='FS Jimbaran Nov 2019'!BJ23 -> 0 | W13: ='FS Jimbaran Nov 2019'!Y23 -> 640 | X13: ='FS Jimbaran Nov 2019'!Z23 -> 0 | Y13: ='FS Jimbaran Nov 2019'!AA23 -> 0 | Z13: ='FS Jimbaran Nov 2019'!AB23 -> 0 | AA13: ='FS Jimbaran Nov 2019'!AC23 -> 0 | AB13: ='FS Jimbaran Nov 2019'!AD23 -> 0 | AC13: ='FS Jimbaran Nov 2019'!AE23 -> 0 | AD13: ='FS Jimbaran Nov 2019'!AF23 -> 0 | ... AF13: ='FS Jimbaran Nov 2019'!AH23 -> 0 | AG13: ='FS Jimbaran Nov 2019'!AM23 -> 0 | AH13: ='FS Jimbaran Nov 2019'!AR23 -> 0 | AI13: ='FS Jimbaran Nov 2019'!AQ23 -> 0 | AJ13: ='FS Jimbaran Nov 2019'!AR23 -> 0 | AK13: ='FS Jimbaran Nov 2019'!AY23 -> 0 | AL13: ='FS Jimbaran Nov 2019'!AZ23 -> 0 | AM13: ='FS Jimbaran Nov 2019'!BB23 -> 0 | AN13: ='FS Jimbaran Nov 2019'!BB23 -> 0 | AO13: ='FS Jimbaran Nov 2019'!BK23 -> 0 | AP13: ='FS Jimbaran Nov 2019'!BL23 -> 0 | AQ13: ='FS Jimbaran Nov 2019'!BC23 -> 0 | AR13: ='FS Jimbaran Nov 2019'!BD23 -> 0 | AS13: ='FS Jimbaran Nov 2019'!BM23 -> 0 | AT13: ='FS Jimbaran Nov 2019'!BN23 -> 0 | AU13: ='FS Jimbaran Nov 2019'!BO23 -> 0 | AV13: ='FS Jimbaran Nov 2019'!BP23 -> 0 | AW13: ='FS Jimbaran Nov 2019'!E23 -> 81 | AX13: ='FS Jimbaran Nov 2019'!F23 -> 0 | AY13: ='FS Jimbaran Nov 2019'!O23 -> 0 | AZ13: ='FS Jimbaran Nov 2019'!P23 -> 0 | BA13: ='FS Jimbaran Nov 2019'!W23 -> 0 | BB13: ='FS Jimbaran Nov 2019'!X23 -> 0 | BC13: ='FS Jimbaran Nov 2019'!AI23 -> 590 | BD13: ='FS Jimbaran Nov 2019'!AJ23 -> 0 | BE13: ='FS Jimbaran Nov 2019'!AK23 -> 0 | BF13: ='FS Jimbaran Nov 2019'!AL23 -> 0 | BG13: ='FS Jimbaran Nov 2019'!AM23 -> 0 | BH13: ='FS Jimbaran Nov 2019'!AN23 -> 0 | BI13: ='FS Jimbaran Nov 2019'!AO23 -> 0 | BJ13: ='FS Jimbaran Nov 2019'!AO23 -> 0 | BK13: ='FS Jimbaran Nov 2019'!AQ23 -> 0 | BL13: ='FS Jimbaran Nov 2019'!AR23 -> 0 | BM13: 0 | BN13: 0 | BO13: ='FS Jimbaran Nov 2019'!Q23 -> 0 | BP13: ='FS Jimbaran Nov 2019'!R23 -> 0
A14: Bali Jimbaran | B14: =B13+1 -> 13 | C14: 11 | D14: 2019 | E14: ='FS Jimbaran Nov 2019'!M24 -> 5.1 | F14: ='FS Jimbaran Nov 2019'!N24 -> 0 | G14: 0 | H14: ='FS Jimbaran Nov 2019'!H24 -> 0 | I14: ='FS Jimbaran Nov 2019'!I24 -> 0 | J14: ='FS Jimbaran Nov 2019'!J24 -> 0 | K14: ='FS Jimbaran Nov 2019'!K24 -> 105 | L14: ='FS Jimbaran Nov 2019'!L24 -> 0 | M14: ='FS Jimbaran Nov 2019'!S24 -> 0 | N14: ='FS Jimbaran Nov 2019'!T24 -> 0 | O14: ='FS Jimbaran Nov 2019'!U24 -> 7 | P14: ='FS Jimbaran Nov 2019'!V24 -> 0 | Q14: ='FS Jimbaran Nov 2019'!BE24 -> 0 | R14: ='FS Jimbaran Nov 2019'!BF24 -> 0 | S14: ='FS Jimbaran Nov 2019'!BH24 -> 0 | T14: ='FS Jimbaran Nov 2019'!BH24 -> 0 | U14: ='FS Jimbaran Nov 2019'!BI24 -> 0 | V14: ='FS Jimbaran Nov 2019'!BJ24 -> 0 | W14: ='FS Jimbaran Nov 2019'!Y24 -> 616 | X14: ='FS Jimbaran Nov 2019'!Z24 -> 0 | Y14: ='FS Jimbaran Nov 2019'!AA24 -> 0 | Z14: ='FS Jimbaran Nov 2019'!AB24 -> 0 | AA14: ='FS Jimbaran Nov 2019'!AC24 -> 0 | AB14: ='FS Jimbaran Nov 2019'!AD24 -> 0 | AC14: ='FS Jimbaran Nov 2019'!AE24 -> 0 | AD14: ='FS Jimbaran Nov 2019'!AF24 -> 0 | ... AF14: ='FS Jimbaran Nov 2019'!AH24 -> 0 | AG14: ='FS Jimbaran Nov 2019'!AM24 -> 0 | AH14: ='FS Jimbaran Nov 2019'!AR24 -> 0 | AI14: ='FS Jimbaran Nov 2019'!AQ24 -> 0 | AJ14: ='FS Jimbaran Nov 2019'!AR24 -> 0 | AK14: ='FS Jimbaran Nov 2019'!AY24 -> 0 | AL14: ='FS Jimbaran Nov 2019'!AZ24 -> 0 | AM14: ='FS Jimbaran Nov 2019'!BB24 -> 0 | AN14: ='FS Jimbaran Nov 2019'!BB24 -> 0 | AO14: ='FS Jimbaran Nov 2019'!BK24 -> 0 | AP14: ='FS Jimbaran Nov 2019'!BL24 -> 0 | AQ14: ='FS Jimbaran Nov 2019'!BC24 -> 0 | AR14: ='FS Jimbaran Nov 2019'!BD24 -> 0 | AS14: ='FS Jimbaran Nov 2019'!BM24 -> 0 | AT14: ='FS Jimbaran Nov 2019'!BN24 -> 0 | AU14: ='FS Jimbaran Nov 2019'!BO24 -> 0 | AV14: ='FS Jimbaran Nov 2019'!BP24 -> 0 | AW14: ='FS Jimbaran Nov 2019'!E24 -> 77.7 | AX14: ='FS Jimbaran Nov 2019'!F24 -> 0 | AY14: ='FS Jimbaran Nov 2019'!O24 -> 0 | AZ14: ='FS Jimbaran Nov 2019'!P24 -> 0 | BA14: ='FS Jimbaran Nov 2019'!W24 -> 0 | BB14: ='FS Jimbaran Nov 2019'!X24 -> 0 | BC14: ='FS Jimbaran Nov 2019'!AI24 -> 810 | BD14: ='FS Jimbaran Nov 2019'!AJ24 -> 0 | BE14: ='FS Jimbaran Nov 2019'!AK24 -> 0 | BF14: ='FS Jimbaran Nov 2019'!AL24 -> 0 | BG14: ='FS Jimbaran Nov 2019'!AM24 -> 0 | BH14: ='FS Jimbaran Nov 2019'!AN24 -> 0 | BI14: ='FS Jimbaran Nov 2019'!AO24 -> 0 | BJ14: ='FS Jimbaran Nov 2019'!AO24 -> 0 | BK14: ='FS Jimbaran Nov 2019'!AQ24 -> 0 | BL14: ='FS Jimbaran Nov 2019'!AR24 -> 0 | BM14: 0 | BN14: 0 | BO14: ='FS Jimbaran Nov 2019'!Q24 -> 0 | BP14: ='FS Jimbaran Nov 2019'!R24 -> 0
... A31: Bali Jimbaran | B31: =B30+1 -> 30 | C31: 11 | D31: 2019 | E31: ='FS Jimbaran Nov 2019'!M41 -> 4.7 | F31: ='FS Jimbaran Nov 2019'!N41 -> 0 | G31: 0 | H31: ='FS Jimbaran Nov 2019'!H41 -> 0 | I31: ='FS Jimbaran Nov 2019'!I41 -> 0 | J31: ='FS Jimbaran Nov 2019'!J41 -> 0 | K31: ='FS Jimbaran Nov 2019'!K41 -> 95 | L31: ='FS Jimbaran Nov 2019'!L41 -> 0 | M31: ='FS Jimbaran Nov 2019'!S41 -> 0 | N31: ='FS Jimbaran Nov 2019'!T41 -> 0 | O31: ='FS Jimbaran Nov 2019'!U41 -> 6.5 | P31: ='FS Jimbaran Nov 2019'!V41 -> 0 | Q31: ='FS Jimbaran Nov 2019'!BE41 -> 0 | R31: ='FS Jimbaran Nov 2019'!BF41 -> 0 | S31: ='FS Jimbaran Nov 2019'!BH41 -> 0 | T31: ='FS Jimbaran Nov 2019'!BH41 -> 0 | U31: ='FS Jimbaran Nov 2019'!BI41 -> 0 | V31: ='FS Jimbaran Nov 2019'!BJ41 -> 0 | W31: ='FS Jimbaran Nov 2019'!Y41 -> 592 | X31: ='FS Jimbaran Nov 2019'!Z41 -> 0 | Y31: ='FS Jimbaran Nov 2019'!AA41 -> 0 | Z31: ='FS Jimbaran Nov 2019'!AB41 -> 0 | AA31: ='FS Jimbaran Nov 2019'!AC41 -> 0 | AB31: ='FS Jimbaran Nov 2019'!AD41 -> 0 | AC31: ='FS Jimbaran Nov 2019'!AE41 -> 0 | AD31: ='FS Jimbaran Nov 2019'!AF41 -> 0 | ... AF31: ='FS Jimbaran Nov 2019'!AH41 -> 0 | AG31: ='FS Jimbaran Nov 2019'!AM41 -> 0 | AH31: ='FS Jimbaran Nov 2019'!AR41 -> 0 | AI31: ='FS Jimbaran Nov 2019'!AQ41 -> 0 | AJ31: ='FS Jimbaran Nov 2019'!AR41 -> 0 | AK31: ='FS Jimbaran Nov 2019'!AY41 -> 0 | AL31: ='FS Jimbaran Nov 2019'!AZ41 -> 0 | AM31: ='FS Jimbaran Nov 2019'!BB41 -> 0 | AN31: ='FS Jimbaran Nov 2019'!BB41 -> 0 | AO31: ='FS Jimbaran Nov 2019'!BK41 -> 0 | AP31: ='FS Jimbaran Nov 2019'!BL41 -> 0 | AQ31: ='FS Jimbaran Nov 2019'!BC41 -> 0 | AR31: ='FS Jimbaran Nov 2019'!BD41 -> 0 | AS31: ='FS Jimbaran Nov 2019'!BM41 -> 0 | AT31: ='FS Jimbaran Nov 2019'!BN41 -> 0 | AU31: ='FS Jimbaran Nov 2019'!BO41 -> 0 | AV31: ='FS Jimbaran Nov 2019'!BP41 -> 0 | AW31: ='FS Jimbaran Nov 2019'!E41 -> 85.7 | AX31: ='FS Jimbaran Nov 2019'!F41 -> 0 | AY31: ='FS Jimbaran Nov 2019'!O41 -> 0 | AZ31: ='FS Jimbaran Nov 2019'!P41 -> 0 | BA31: ='FS Jimbaran Nov 2019'!W41 -> 0 | BB31: ='FS Jimbaran Nov 2019'!X41 -> 0 | BC31: ='FS Jimbaran Nov 2019'!AI41 -> 700 | BD31: ='FS Jimbaran Nov 2019'!AJ41 -> 0 | BE31: ='FS Jimbaran Nov 2019'!AK41 -> 0 | BF31: ='FS Jimbaran Nov 2019'!AL41 -> 0 | BG31: ='FS Jimbaran Nov 2019'!AM41 -> 0 | BH31: ='FS Jimbaran Nov 2019'!AN41 -> 0 | BI31: ='FS Jimbaran Nov 2019'!AO41 -> 0 | BJ31: ='FS Jimbaran Nov 2019'!AO41 -> 0 | BK31: ='FS Jimbaran Nov 2019'!AQ41 -> 0 | BL31: ='FS Jimbaran Nov 2019'!AR41 -> 0 | BM31: 0 | BN31: 0 | BO31: ='FS Jimbaran Nov 2019'!Q41 -> 0 | BP31: ='FS Jimbaran Nov 2019'!R41 -> 0
E32: ='FS Jimbaran Nov 2019'!M42 -> 154.8 | F32: =SUM(F2:F31) -> 0 | G32: =SUM(G2:G31) -> 0 | H32: =SUM(H2:H31) -> 0 | I32: =SUM(I2:I31) -> 0 | J32: =SUM(J2:J31) -> 0 | K32: ='FS Jimbaran Nov 2019'!K42 -> 2640 | L32: =SUM(L2:L31) -> 0 | M32: =SUM(M2:M31) -> 0 | N32: =SUM(N2:N31) -> 0 | O32: ='FS Jimbaran Nov 2019'!U42 -> 392 | P32: =SUM(P2:P31) -> 0 | Q32: =SUM(Q2:Q31) -> 0 | R32: =SUM(R2:R31) -> 0 | S32: =SUM(S2:S31) -> 0 | T32: =SUM(T2:T31) -> 0 | U32: =SUM(U2:U31) -> 0 | V32: =SUM(V2:V31) -> 0 | W32: ='FS Jimbaran Nov 2019'!Y42 -> 18392 | X32: =SUM(X2:X31) -> 8284726 | Y32: =SUM(Y2:Y31) -> 0 | Z32: =SUM(Z2:Z31) -> 0 | AA32: =SUM(AA2:AA31) -> 0 | AB32: =SUM(AB2:AB31) -> 0 | AC32: =SUM(AC2:AC31) -> 0 | AD32: =SUM(AD2:AD31) -> 0 | AE32: =SUM(AE2:AE31) -> 0 | ... BP32: =SUM(BP2:BP31) -> 0

Sheet FS Jimbaran Nov 2019
B6: Four Seasons Resort Bali at Jimbaran Bay
B7: Nov 2019
B8: Date | C8: Room Nights | D8: Food Covers | E8: Paper Waste | K8: Glass Waste | M8: Metal Waste | U8: Plastic Waste | Y8: Organic Waste | AM8: Hazardous Waste | BE8: Recycleable
E10: Total (per Unit) paper cardboard | F10: Total cost paper cardboard | G10: Total (per Unit) cardboard | H10: Total cost cardboard | I10: Total (per Unit) paper | J10: Total cost paper | K10: Total (per Unit) mixed glass | L10: Total cost mixed glass | M10: Total (per Unit) bottles cans | N10: Total cost bottles cans | O10: Total (per Unit) mixed metals | P10: Total cost mixed metals | Q10: Total (per Unit) tin | R10: Total cost tin | S10: Total (per Unit) aluminum | T10: Total cost aluminum | U10: Total (per Unit) plastics | V10: Total cost plastics | W10: Total (per Unit) other plastics | X10: Total cost other plastics | Y10: Total (per Unit) solid food waste | Z10: Total cost solid food waste | AA10: Total (per Unit) leftover food | AB10: Total cost leftover food | AC10: Total (per Unit) inedible parts | AD10: Total cost inedible parts | AE10: Total (per Unit) liquid food waste | AF10: Total cost liquid food waste | AG10: Total (per Unit) kitchen grease | AH10: Total cost kitchen grease | AI10: Total (per Unit) biodegradable | AJ10: Total cost biodegradable | AK10: Total (per Unit) food waste | AL10: Total cost food waste | AM10: Total (per Unit) hazardous waste | AN10: Total cost hazardous waste | AO10: Total (per Unit) universal waste | AP10: Total cost universal waste | AQ10: Total (per Unit) hazardous and universal waste | AR10: Total cost hazardous and universal waste | AS10: Total (per Unit) medical waste | AT10: Total cost medical waste | AU10: Total (per Unit) liquid hazardous waste | AV10: Total cost liquid hazardous waste | AW10: Total (per Unit) other hazardous waste | AX10: Total cost other hazardous waste | AY10: Total (per Unit) batteries | AZ10: Total cost batteries | BA10: Total (per Unit) light bulbs | BB10: Total cost light bulbs | BC10: Total (per Unit) paint | BD10: Total cost paint | BE10: Total (per Unit) soap bars | BF10: Total cost soap bars | BG10: Total (per Unit) e waste | BH10: Total cost e waste | BI10: Total (per Unit) durable goods | BJ10: Total cost durable goods | BK10: Total (per Unit) textiles | BL10: Total cost textiles | BM10: Total (per Unit) recyclable | BN10: Total cost recyclable | BO10: Total (per Unit) commingled recyclables | BP10: Total cost commingled recyclables
B12: 1 | C12: 55 | D12: 497 | E12: 77.4 | F12: 0 | G12: 0 | H12: 0 | I12: 0 | J12: 0 | K12: 75 | L12: 0 | M12: 5.3 | N12: 0 | O12: 0 | P12: 0 | Q12: 0 | R12: 0 | S12: 0 | T12: 0 | U12: 10.5 | V12: 0 | W12: 0 | X12: 0 | Y12: 600 | Z12: 8284726 | AA12: 0 | AB12: 0 | AC12: 0 | AD12: 0 | AE12: 0 | AF12: 0 | AG12: 0 | AH12: 0 | AI12: 670 | AJ12: 0 | AK12: 0 | AL12: 0 | AM12: 0 | AN12: 0 | AO12: 0 | AP12: 0 | AQ12: 0 | AR12: 0 | AS12: 0 | AT12: 0 | AU12: 0 | AV12: 0 | AW12: 0 | AX12: 0 | AY12: 0 | AZ12: 0 | BA12: 0 | BB12: 0 | BC12: 0 | BD12: 0 | BE12: 0 | BF12: 0 | BG12: 0 | BH12: 0 | BI12: 0 | BJ12: 0 | BK12: 0 | BL12: 0 | BM12: 0 | BN12: 0 | BO12: 0 | BP12: 0
B13: 2 | C13: 51 | D13: 419 | E13: 70.7 | F13: 0 | G13: 0 | H13: 0 | I13: 0 | J13: 0 | K13: 90 | L13: 0 | M13: 5.6 | N13: 0 | O13: 0 | P13: 0 | Q13: 0 | R13: 0 | S13: 0 | T13: 0 | U13: 17 | V13: 0 | W13: 0 | X13: 0 | Y13: 640 | Z13: 0 | AA13: 0 | AB13: 0 | AC13: 0 | AD13: 0 | AE13: 0 | AF13: 0 | AG13: 0 | AH13: 0 | AI13: 600 | AJ13: 0 | AK13: 0 | AL13: 0 | AM13: 0 | AN13: 0 | AO13: 0 | AP13: 0 | AQ13: 0 | AR13: 0 | AS13: 0 | AT13: 0 | AU13: 0 | AV13: 0 | AW13: 0 | AX13: 0 | AY13: 0 | AZ13: 0 | BA13: 0 | BB13: 0 | BC13: 0 | BD13: 0 | BE13: 0 | BF13: 0 | BG13: 0 | BH13: 0 | BI13: 0 | BJ13: 0 | BK13: 0 | BL13: 0 | BM13: 0 | BN13: 0 | BO13: 0 | BP13: 0
B14: 3 | C14: 47 | D14: 390 | E14: 96.6 | F14: 0 | G14: 0 | H14: 0 | I14: 0 | J14: 0 | K14: 80 | L14: 0 | M14: 2.6 | N14: 0 | O14: 0 | P14: 0 | Q14: 0 | R14: 0 | S14: 0 | T14: 0 | U14: 12.5 | V14: 0 | W14: 0 | X14: 0 | Y14: 608 | Z14: 0 | AA14: 0 | AB14: 0 | AC14: 0 | AD14: 0 | AE14: 0 | AF14: 0 | AG14: 0 | AH14: 0 | AI14: 640 | AJ14: 0 | AK14: 0 | AL14: 0 | AM14: 0 | AN14: 0 | AO14: 0 | AP14: 0 | AQ14: 0 | AR14: 0 | AS14: 0 | AT14: 0 | AU14: 0 | AV14: 0 | AW14: 0 | AX14: 0 | AY14: 0 | AZ14: 0 | BA14: 0 | BB14: 0 | BC14: 0 | BD14: 0 | BE14: 0 | BF14: 0 | BG14: 0 | BH14: 0 | BI14: 0 | BJ14: 0 | BK14: 0 | BL14: 0 | BM14: 0 | BN14: 0 | BO14: 0 | BP14: 0
B15: 4 | C15: 62 | D15: 439 | E15: 72.4 | F15: 0 | G15: 0 | H15: 0 | I15: 0 | J15: 0 | K15: 80 | L15: 0 | M15: 5 | N15: 0 | O15: 0 | P15: 0 | Q15: 0 | R15: 0 | S15: 0 | T15: 0 | U15: 6.5 | V15: 0 | W15: 0 | X15: 0 | Y15: 592 | Z15: 0 | AA15: 0 | AB15: 0 | AC15: 0 | AD15: 0 | AE15: 0 | AF15: 0 | AG15: 0 | AH15: 0 | AI15: 600 | AJ15: 0 | AK15: 0 | AL15: 0 | AM15: 0 | AN15: 0 | AO15: 0 | AP15: 0 | AQ15: 0 | AR15: 0 | AS15: 0 | AT15: 0 | AU15: 0 | AV15: 0 | AW15: 0 | AX15: 0 | AY15: 0 | AZ15: 0 | BA15: 0 | BB15: 0 | BC15: 0 | BD15: 0 | BE15: 0 | BF15: 0 | BG15: 0 | BH15: 0 | BI15: 0 | BJ15: 0 | BK15: 0 | BL15: 0 | BM15: 0 | BN15: 0 | BO15: 0 | BP15: 0
B16: 5 | C16: 89 | D16: 464 | E16: 86.1 | F16: 0 | G16: 0 | H16: 0 | I16: 0 | J16: 0 | K16: 91 | L16: 0 | M16: 4.7 | N16: 0 | O16: 0 | P16: 0 | Q16: 0 | R16: 0 | S16: 0 | T16: 0 | U16: 18 | V16: 0 | W16: 0 | X16: 0 | Y16: 624 | Z16: 0 | AA16: 0 | AB16: 0 | AC16: 0 | AD16: 0 | AE16: 0 | AF16: 0 | AG16: 0 | AH16: 0 | AI16: 530 | AJ16: 0 | AK16: 0 | AL16: 0 | AM16: 0 | AN16: 0 | AO16: 0 | AP16: 0 | AQ16: 0 | AR16: 0 | AS16: 0 | AT16: 0 | AU16: 0 | AV16: 0 | AW16: 0 | AX16: 0 | AY16: 0 | AZ16: 0 | BA16: 0 | BB16: 0 | BC16: 0 | BD16: 0 | BE16: 0 | BF16: 0 | BG16: 0 | BH16: 0 | BI16: 0 | BJ16: 0 | BK16: 0 | BL16: 0 | BM16: 0 | BN16: 0 | BO16: 0 | BP16: 0
B17: 6 | C17: 96 | D17: 473 | E17: 86.9 | F17: 0 | G17: 0 | H17: 0 | I17: 0 | J17: 0 | K17: 85 | L17: 0 | M17: 6.3 | N17: 0 | O17: 0 | P17: 0 | Q17: 0 | R17: 0 | S17: 0 | T17: 0 | U17: 11 | V17: 0 | W17: 0 | X17: 0 | Y17: 640 | Z17: 0 | AA17: 0 | AB17: 0 | AC17: 0 | AD17: 0 | AE17: 0 | AF17: 0 | AG17: 0 | AH17: 0 | AI17: 640 | AJ17: 0 | AK17: 0 | AL17: 0 | AM17: 0 | AN17: 0 | AO17: 0 | AP17: 0 | AQ17: 0 | AR17: 0 | AS17: 0 | AT17: 0 | AU17: 0 | AV17: 0 | AW17: 0 | AX17: 0 | AY17: 0 | AZ17: 0 | BA17: 0 | BB17: 0 | BC17: 0 | BD17: 0 | BE17: 0 | BF17: 0 | BG17: 0 | BH17: 0 | BI17: 0 | BJ17: 0 | BK17: 0 | BL17: 0 | BM17: 0 | BN17: 0 | BO17: 0 | BP17: 0
B18: 7 | C18: 98 | D18: 520 | E18: 82.7 | F18: 0 | G18: 0 | H18: 0 | I18: 0 | J18: 0 | K18: 95 | L18: 0 | M18: 6.1 | N18: 0 | O18: 0 | P18: 0 | Q18: 0 | R18: 0 | S18: 0 | T18: 0 | U18: 7.5 | V18: 0 | W18: 0 | X18: 0 | Y18: 648 | Z18: 0 | AA18: 0 | AB18: 0 | AC18: 0 | AD18: 0 | AE18: 0 | AF18: 0 | AG18: 0 | AH18: 0 | AI18: 480 | AJ18: 0 | AK18: 0 | AL18: 0 | AM18: 0 | AN18: 0 | AO18: 0 | AP18: 0 | AQ18: 0 | AR18: 0 | AS18: 0 | AT18: 0 | AU18: 0 | AV18: 0 | AW18: 0 | AX18: 0 | AY18: 0 | AZ18: 0 | BA18: 0 | BB18: 0 | BC18: 0 | BD18: 0 | BE18: 0 | BF18: 0 | BG18: 0 | BH18: 0 | BI18: 0 | BJ18: 0 | BK18: 0 | BL18: 0 | BM18: 0 | BN18: 0 | BO18: 0 | BP18: 0
B19: 8 | C19: 72 | D19: 465 | E19: 92.1 | F19: 0 | G19: 0 | H19: 0 | I19: 0 | J19: 0 | K19: 105 | L19: 0 | M19: 6.1 | N19: 0 | O19: 0 | P19: 0 | Q19: 0 | R19: 0 | S19: 0 | T19: 0 | U19: 14 | V19: 0 | W19: 0 | X19: 0 | Y19: 640 | Z19: 0 | AA19: 0 | AB19: 0 | AC19: 0 | AD19: 0 | AE19: 0 | AF19: 0 | AG19: 0 | AH19: 0 | AI19: 700 | AJ19: 0 | AK19: 0 | AL19: 0 | AM19: 0 | AN19: 0 | AO19: 0 | AP19: 0 | AQ19: 0 | AR19: 0 | AS19: 0 | AT19: 0 | AU19: 0 | AV19: 0 | AW19: 0 | AX19: 0 | AY19: 0 | AZ19: 0 | BA19: 0 | BB19: 0 | BC19: 0 | BD19: 0 | BE19: 0 | BF19: 0 | BG19: 0 | BH19: 0 | BI19: 0 | BJ19: 0 | BK19: 0 | BL19: 0 | BM19: 0 | BN19: 0 | BO19: 0 | BP19: 0
B20: 9 | C20: 68 | D20: 479 | E20: 87.1 | F20: 0 | G20: 0 | H20: 0 | I20: 0 | J20: 0 | K20: 75 | L20: 0 | M20: 5.3 | N20: 0 | O20: 0 | P20: 0 | Q20: 0 | R20: 0 | S20: 0 | T20: 0 | U20: 15.5 | V20: 0 | W20: 0 | X20: 0 | Y20: 640 | Z20: 0 | AA20: 0 | AB20: 0 | AC20: 0 | AD20: 0 | AE20: 0 | AF20: 0 | AG20: 0 | AH20: 0 | AI20: 610 | AJ20: 0 | AK20: 0 | AL20: 0 | AM20: 0 | AN20: 0 | AO20: 0 | AP20: 0 | AQ20: 0 | AR20: 0 | AS20: 0 | AT20: 0 | AU20: 0 | AV20: 0 | AW20: 0 | AX20: 0 | AY20: 0 | AZ20: 0 | BA20: 0 | BB20: 0 | BC20: 0 | BD20: 0 | BE20: 0 | BF20: 0 | BG20: 0 | BH20: 0 | BI20: 0 | BJ20: 0 | BK20: 0 | BL20: 0 | BM20: 0 | BN20: 0 | BO20: 0 | BP20: 0
B21: 10 | C21: 51 | D21: 427 | E21: 80.1 | F21: 0 | G21: 0 | H21: 0 | I21: 0 | J21: 0 | K21: 90 | L21: 0 | M21: 5.6 | N21: 0 | O21: 0 | P21: 0 | Q21: 0 | R21: 0 | S21: 0 | T21: 0 | U21: 7 | V21: 0 | W21: 0 | X21: 0 | Y21: 624 | Z21: 0 | AA21: 0 | AB21: 0 | AC21: 0 | AD21: 0 | AE21: 0 | AF21: 0 | AG21: 0 | AH21: 0 | AI21: 640 | AJ21: 0 | AK21: 0 | AL21: 0 | AM21: 0 | AN21: 0 | AO21: 0 | AP21: 0 | AQ21: 0 | AR21: 0 | AS21: 0 | AT21: 0 | AU21: 0 | AV21: 0 | AW21: 0 | AX21: 0 | AY21: 0 | AZ21: 0 | BA21: 0 | BB21: 0 | BC21: 0 | BD21: 0 | BE21: 0 | BF21: 0 | BG21: 0 | BH21: 0 | BI21: 0 | BJ21: 0 | BK21: 0 | BL21: 0 | BM21: 0 | BN21: 0 | BO21: 0 | BP21: 0
B22: 11 | C22: 43 | D22: 268 | E22: 88.5 | F22: 0 | G22: 0 | H22: 0 | I22: 0 | J22: 0 | K22: 105 | L22: 0 | M22: 3.8 | N22: 0 | O22: 0 | P22: 0 | Q22: 0 | R22: 0 | S22: 0 | T22: 0 | U22: 16.5 | V22: 0 | W22: 0 | X22: 0 | Y22: 608 | Z22: 0 | AA22: 0 | AB22: 0 | AC22: 0 | AD22: 0 | AE22: 0 | AF22: 0 | AG22: 0 | AH22: 0 | AI22: 620 | AJ22: 0 | AK22: 0 | AL22: 0 | AM22: 0 | AN22: 0 | AO22: 0 | AP22: 0 | AQ22: 0 | AR22: 0 | AS22: 0 | AT22: 0 | AU22: 0 | AV22: 0 | AW22: 0 | AX22: 0 | AY22: 0 | AZ22: 0 | BA22: 0 | BB22: 0 | BC22: 0 | BD22: 0 | BE22: 0 | BF22: 0 | BG22: 0 | BH22: 0 | BI22: 0 | BJ22: 0 | BK22: 0 | BL22: 0 | BM22: 0 | BN22: 0 | BO22: 0 | BP22: 0
B23: 12 | C23: 49 | D23: 266 | E23: 81 | F23: 0 | G23: 0 | H23: 0 | I23: 0 | J23: 0 | K23: 85 | L23: 0 | M23: 5 | N23: 0 | O23: 0 | P23: 0 | Q23: 0 | R23: 0 | S23: 0 | T23: 0 | U23: 12.5 | V23: 0 | W23: 0 | X23: 0 | Y23: 640 | Z23: 0 | AA23: 0 | AB23: 0 | AC23: 0 | AD23: 0 | AE23: 0 | AF23: 0 | AG23: 0 | AH23: 0 | AI23: 590 | AJ23: 0 | AK23: 0 | AL23: 0 | AM23: 0 | AN23: 0 | AO23: 0 | AP23: 0 | AQ23: 0 | AR23: 0 | AS23: 0 | AT23: 0 | AU23: 0 | AV23: 0 | AW23: 0 | AX23: 0 | AY23: 0 | AZ23: 0 | BA23: 0 | BB23: 0 | BC23: 0 | BD23: 0 | BE23: 0 | BF23: 0 | BG23: 0 | BH23: 0 | BI23: 0 | BJ23: 0 | BK23: 0 | BL23: 0 | BM23: 0 | BN23: 0 | BO23: 0 | BP23: 0
... B39: 28 | C39: 57 | D39: 444 | E39: 102 | F39: 0 | G39: 0 | H39: 0 | I39: 0 | J39: 0 | K39: 100 | L39: 0 | M39: 6.1 | N39: 0 | O39: 0 | P39: 0 | Q39: 0 | R39: 0 | S39: 0 | T39: 0 | U39: 7 | V39: 0 | W39: 0 | X39: 0 | Y39: 592 | Z39: 0 | AA39: 0 | AB39: 0 | AC39: 0 | AD39: 0 | AE39: 0 | AF39: 0 | AG39: 0 | AH39: 0 | AI39: 660 | AJ39: 0 | AK39: 0 | AL39: 0 | AM39: 0 | AN39: 0 | AO39: 0 | AP39: 0 | AQ39: 0 | AR39: 0 | AS39: 0 | AT39: 0 | AU39: 0 | AV39: 0 | AW39: 0 | AX39: 0 | AY39: 0 | AZ39: 0 | BA39: 0 | BB39: 0 | BC39: 0 | BD39: 0 | BE39: 0 | BF39: 0 | BG39: 0 | BH39: 0 | BI39: 0 | BJ39: 0 | BK39: 0 | BL39: 0 | BM39: 0 | BN39: 0 | BO39: 0 | BP39: 0
B40: 29 | C40: 53 | D40: 450 | E40: 93 | F40: 0 | G40: 0 | H40: 0 | I40: 0 | J40: 0 | K40: 86 | L40: =SUM(L12:L39) -> 0 | M40: 6 | N40: 0 | O40: 0 | P40: 0 | Q40: 0 | R40: 0 | S40: 0 | T40: 0 | U40: 14 | V40: =SUM(V12:V39) -> 0 | W40: =SUM(W12:W39) -> 0 | X40: =SUM(X12:X39) -> 0 | Y40: 560 | Z40: 0 | AA40: =SUM(AA12:AA39) -> 0 | AB40: =SUM(AB12:AB39) -> 0 | AC40: =SUM(AC12:AC39) -> 0 | AD40: =SUM(AD12:AD39) -> 0 | AE40: =SUM(AE12:AE39) -> 0 | AF40: =SUM(AF12:AF39) -> 0 | AG40: =SUM(AG12:AG39) -> 0 | AH40: =SUM(AH12:AH39) -> 0 | AI40: 610 | AJ40: 0 | AK40: =SUM(AK12:AK39) -> 0 | AL40: =SUM(AL12:AL39) -> 0 | AM40: =SUM(AM12:AM39) -> 0 | AN40: =SUM(AN12:AN39) -> 0 | AO40: =SUM(AO12:AO39) -> 0 | AP40: =SUM(AP12:AP39) -> 0 | AQ40: =SUM(AQ12:AQ39) -> 0 | AR40: =SUM(AR12:AR39) -> 0 | ... BP40: =SUM(BP12:BP39) -> 0
