Workbook

Sheet Sheet1
A1: Site Name | B1: Month | C1: Year | D1: Total (per Unit) bottles cans | E1: Total cost bottles cans | F1: Total (per Unit) cardboard | G1: Total cost cardboard | H1: Total (per Unit) paper | I1: Total cost paper | J1: Total (per Unit) mixed metal | K1: Total cost mixed metal | L1: Total (per Unit) aluminum | M1: Total cost aluminum | N1: Total (per Unit) other plastics | O1: Total cost other plastics | P1: Total (per Unit) soap bars | Q1: Total cost soap bars | R1: Total (per Unit) e waste | S1: Total cost e waste | T1: Total (per Unit) durable goods | U1: Total cost durable goods | V1: Total (per Unit) solid food waste | W1: Total cost solid food waste | X1: Total (per Unit) leftover food | Y1: Total cost leftover food | Z1: Total (per Unit) inedible parts | AA1: Total cost inedible parts | AB1: Total (per Unit) liquid food waste | AC1: Total cost liquid food waste | AD1: Total (per Unit) kitchen grease | AE1: Total cost kitchen grease | AF1: Total (per Unit) liquid hazardous waste | AG1: Total cost liquid hazardous waste | AH1: Total (per Unit) other hazardous waste | AI1: Total cost other hazardous waste | AJ1: Total (per Unit) batteries | AK1: Total cost batteries | AL1: Total (per Unit) light bulbs | AM1: Total cost light bulbs | AN1: Total (per Unit) textiles | AO1: Total cost textiles | AP1: Total (per Unit) paint | AQ1: Total cost paint | AR1: Total (per Unit) recyclable | AS1: Total cost recyclable | AT1: Total (per Unit) commingled recyclables | AU1: Total cost commingled recyclables | AV1: Total (per Unit) paper cardboard | AW1: Total cost paper cardboard | AX1: Total (per Unit) mixed metals | AY1: Total cost mixed metals | AZ1: Total (per Unit) plastics | BA1: Total cost plastics | BB1: Total (per Unit) biodegradable | BC1: Total cost biodegradable | BD1: Total (per Unit) food waste | BE1: Total cost food waste | BF1: Total (per Unit) hazardous waste | BG1: Total cost hazardous waste | BH1: Total (per Unit) universal waste | BI1: Total cost universal waste | BJ1: Total (per Unit) hazardous and universal waste | BK1: Total cost hazardous and universal waste | BL1: Total (per Unit) medical waste | BM1: Total cost medical waste | BN1: Total (per Unit) tin | BO1: Total cost tin
A2: Bali at Sayan | B2: 1 | C2: 2020 | D2: 85.3 | E2: 0 | F2: 0 | G2: 0 | H2: 0 | I2: 0 | J2: 554.2 | K2: 0 | L2: 0 | M2: 0 | N2: 91.7 | O2: 0 | P2: 0 | Q2: 0 | R2: 0 | S2: 0 | T2: 0 | U2: 0 | V2: 4765 | W2: 17800000 | X2: 0 | Y2: 0 | Z2: 0 | AA2: 0 | AB2: 0 | AC2: 0 | AD2: 0 | AE2: 0 | AF2: 0 | AG2: 0 | AH2: 0 | AI2: 0 | AJ2: 0 | AK2: 0 | AL2: 0 | AM2: 0 | AN2: 0 | AO2: 0 | AP2: 0 | AQ2: 0 | AR2: 0 | AS2: 0 | AT2: 0 | AU2: 0 | AV2: 328.3 | AW2: 0 | AX2: 85.3 | AY2: 0 | AZ2: 0 | BA2: 0 | BB2: 14530 | BC2: 0 | BD2: 0 | BE2: 0 | BF2: 0 | BG2: 0 | BH2: 0 | BI2: 0 | BJ2: 0 | BK2: 0 | BL2: 0 | BM2: 0 | BN2: 0 | BO2: 0
A3: Bali at Sayan | B3: 2 | C3: 2020 | D3: 120.1 | E3: 0 | F3: 0 | G3: 0 | H3: 0 | I3: 0 | J3: 302.7 | K3: 0 | L3: 0 | M3: 0 | N3: 94.4 | O3: 0 | P3: 0 | Q3: 0 | R3: 0 | S3: 0 | T3: 0 | U3: 0 | V3: 3577.5 | W3: 17800000 | X3: 0 | Y3: 0 | Z3: 0 | AA3: 0 | AB3: 0 | AC3: 0 | AD3: 0 | AE3: 0 | AF3: 0 | AG3: 0 | AH3: 0 | AI3: 0 | AJ3: 0 | AK3: 0 | AL3: 0 | AM3: 0 | AN3: 0 | AO3: 0 | AP3: 0 | AQ3: 0 | AR3: 0 | AS3: 0 | AT3: 0 | AU3: 0 | AV3: 280.7 | AW3: 0 | AX3: 120.1 | AY3: 0 | AZ3: 0 | BA3: 0 | BB3: 13500 | BC3: 0 | BD3: 0 | BE3: 0 | BF3: 0 | BG3: 0 | BH3: 0 | BI3: 0 | BJ3: 0 | BK3: 0 | BL3: 0 | BM3: 0 | BN3: 0 | BO3: 0
A4: Bali at Sayan | B4: 3 | C4: 2020
A5: Bali at Sayan | B5: 4 | C5: 2020
A6: Bali at Sayan | B6: 5 | C6: 2020
A7: Bali at Sayan | B7: 6 | C7: 2020
A8: Bali at Sayan | B8: 7 | C8: 2020
A9: Bali at Sayan | B9: 8 | C9: 2020
A10: Bali at Sayan | B10: 9 | C10: 2020
A11: Bali at Sayan | B11: 10 | C11: 2020
A12: Bali at Sayan | B12: 11 | C12: 2020
A13: Bali at Sayan | B13: 12 | C13: 2020

Sheet TOTAL
A1: Site Name | B1: Day | C1: Month | D1: Year | E1: Total (per Unit) bottles cans | F1: Total cost bottles cans | G1: Total (per Unit) cardboard | H1: Total cost cardboard | I1: Total (per Unit) paper | J1: Total cost paper | K1: Total (per Unit) mixed glass | L1: Total cost mixed glass | M1: Total (per Unit) aluminum | N1: Total cost aluminum | O1: Total (per Unit) other plastics | P1: Total cost other plastics | Q1: Total (per Unit) soap bars | R1: Total cost soap bars | S1: Total (per Unit) e waste | T1: Total cost e waste | U1: Total (per Unit) durable goods | V1: Total cost durable goods | W1: Total (per Unit) solid food waste | X1: Total cost solid food waste | Y1: Total (per Unit) leftover food | Z1: Total cost leftover food | AA1: Total (per Unit) inedible parts | AB1: Total cost inedible parts | AC1: Total (per Unit) liquid food waste | AD1: Total cost liquid food waste | AE1: Total (per Unit) kitchen grease | AF1: Total cost kitchen grease | AG1: Total (per Unit) liquid hazardous waste | AH1: Total cost liquid hazardous waste | AI1: Total (per Unit) other hazardous waste | AJ1: Total cost other hazardous waste | AK1: Total (per Unit) batteries | AL1: Total cost batteries | AM1: Total (per Unit) light bulbs | AN1: Total cost light bulbs | AO1: Total (per Unit) textiles | AP1: Total cost textiles | AQ1: Total (per Unit) paint | AR1: Total cost paint | AS1: Total (per Unit) recyclable | AT1: Total cost recyclable | AU1: Total (per Unit) commingled recyclables | AV1: Total cost commingled recyclables | AW1: Total (per Unit) paper cardboard | AX1: Total cost paper cardboard | AY1: Total (per Unit) mixed metals | AZ1: Total cost mixed metals | BA1: Total (per Unit) plastics | BB1: Total cost plastics | BC1: Total (per Unit) biodegradable | BD1: Total cost biodegradable | BE1: Total (per Unit) food waste | BF1: Total cost food waste | BG1: Total (per Unit) hazardous waste | BH1: Total cost hazardous waste | BI1: Total (per Unit) universal waste | BJ1: Total cost universal waste | BK1: Total (per Unit) hazardous and universal waste | BL1: Total cost hazardous and universal waste | BM1: Total (per Unit) medical waste | BN1: Total cost medical waste | BO1: Total (per Unit) tin | BP1: Total cost tin
A2: Bali Sayan | B2: 1 | C2: 2 | D2: 2020 | E2: ='FS Sayan Feb 2020'!M8 -> 2.6 | F2: ='FS Sayan Feb 2020'!N8 -> 0 | G2: ='FS Sayan Feb 2020'!G8 -> 0 | H2: ='FS Sayan Feb 2020'!H8 -> 0 | I2: ='FS Sayan Feb 2020'!I8 -> 0 | J2: ='FS Sayan Feb 2020'!J8 -> 0 | K2: ='FS Sayan Feb 2020'!K8 -> 9.5 | L2: ='FS Sayan Feb 2020'!L8 -> 0 | M2: ='FS Sayan Feb 2020'!S8 -> 0 | N2: ='FS Sayan Feb 2020'!T8 -> 0 | O2: ='FS Sayan Feb 2020'!U8 -> 2.4 | P2: ='FS Sayan Feb 2020'!V8 -> 0 | Q2: ='FS Sayan Feb 2020'!BC8 -> 0 | R2: ='FS Sayan Feb 2020'!BD8 -> 0 | S2: ='FS Sayan Feb 2020'!BF8 -> 0 | T2: ='FS Sayan Feb 2020'!BF8 -> 0 | U2: ='FS Sayan Feb 2020'!BG8 -> 0 | V2: ='FS Sayan Feb 2020'!BH8 -> 0 | W2: ='FS Sayan Feb 2020'!W8 -> 108 | X2: ='FS Sayan Feb 2020'!X8 -> 17800000 | Y2: ='FS Sayan Feb 2020'!Y8 -> 0 | Z2: ='FS Sayan Feb 2020'!Z8 -> 0 | AA2: ='FS Sayan Feb 2020'!AA8 -> 0 | AB2: ='FS Sayan Feb 2020'!AB8 -> 0 | AC2: ='FS Sayan Feb 2020'!AC8 -> 0 | AD2: ='FS Sayan Feb 2020'!AD8 -> 0 | ... AF2: ='FS Sayan Feb 2020'!AF8 -> 0 | AG2: ='FS Sayan Feb 2020'!AK8 -> 0 | AH2: ='FS Sayan Feb 2020'!AP8 -> 0 | AI2: ='FS Sayan Feb 2020'!AO8 -> 0 | AJ2: ='FS Sayan Feb 2020'!AP8 -> 0 | AK2: ='FS Sayan Feb 2020'!AW8 -> 0 | AL2: ='FS Sayan Feb 2020'!AX8 -> 0 | AM2: ='FS Sayan Feb 2020'!AZ8 -> 0 | AN2: ='FS Sayan Feb 2020'!AZ8 -> 0 | AO2: ='FS Sayan Feb 2020'!BI8 -> 0 | AP2: ='FS Sayan Feb 2020'!BJ8 -> 0 | AQ2: ='FS Sayan Feb 2020'!BA8 -> 0 | AR2: ='FS Sayan Feb 2020'!BB8 -> 0 | AS2: ='FS Sayan Feb 2020'!BK8 -> 0 | AT2: ='FS Sayan Feb 2020'!BL8 -> 0 | AU2: ='FS Sayan Feb 2020'!BM8 -> 0 | AV2: ='FS Sayan Feb 2020'!BN8 -> 0 | AW2: ='FS Sayan Feb 2020'!E8 -> 7.9 | AX2: ='FS Sayan Feb 2020'!F8 -> 0 | AY2: ='FS Sayan Feb 2020'!M8 -> 2.6 | AZ2: ='FS Sayan Feb 2020'!P8 -> 0 | BA2: 0 | BB2: ='FS Sayan Feb 2020'!V22 -> 0 | BC2: ='FS Sayan Feb 2020'!AG8 -> 430 | BD2: ='FS Sayan Feb 2020'!AH8 -> 0 | BE2: ='FS Sayan Feb 2020'!AI8 -> 0 | BF2: ='FS Sayan Feb 2020'!AJ8 -> 0 | BG2: ='FS Sayan Feb 2020'!AK8 -> 0 | BH2: ='FS Sayan Feb 2020'!AL8 -> 0 | BI2: ='FS Sayan Feb 2020'!AM8 -> 0 | BJ2: ='FS Sayan Feb 2020'!AM8 -> 0 | BK2: ='FS Sayan Feb 2020'!AO8 -> 0 | BL2: ='FS Sayan Feb 2020'!AP8 -> 0 | BM2: 0 | BN2: 0 | BO2: ='FS Sayan Feb 2020'!Q8 -> 0 | BP2: ='FS Sayan Feb 2020'!R8 -> 0
A3: Bali Sayan | B3: =B2+1 -> 2 | C3: 2 | D3: 2020 | E3: ='FS Sayan Feb 2020'!M9 -> 3.4 | F3: ='FS Sayan Feb 2020'!N9 -> 0 | G3: ='FS Sayan Feb 2020'!G9 -> 0 | H3: ='FS Sayan Feb 2020'!H9 -> 0 | I3: ='FS Sayan Feb 2020'!I9 -> 0 | J3: ='FS Sayan Feb 2020'!J9 -> 0 | K3: ='FS Sayan Feb 2020'!K9 -> 12.4 | L3: ='FS Sayan Feb 2020'!L9 -> 0 | M3: ='FS Sayan Feb 2020'!S9 -> 0 | N3: ='FS Sayan Feb 2020'!T9 -> 0 | O3: ='FS Sayan Feb 2020'!U9 -> 2.8 | P3: ='FS Sayan Feb 2020'!V9 -> 0 | Q3: ='FS Sayan Feb 2020'!BC9 -> 0 | R3: ='FS Sayan Feb 2020'!BD9 -> 0 | S3: ='FS Sayan Feb 2020'!BF9 -> 0 | T3: ='FS Sayan Feb 2020'!BF9 -> 0 | U3: ='FS Sayan Feb 2020'!BG9 -> 0 | V3: ='FS Sayan Feb 2020'!BH9 -> 0 | W3: ='FS Sayan Feb 2020'!W9 -> 117 | X3: ='FS Sayan Feb 2020'!X9 -> 0 | Y3: ='FS Sayan Feb 2020'!Y9 -> 0 | Z3: ='FS Sayan Feb 2020'!Z9 -> 0 | AA3: ='FS Sayan Feb 2020'!AA9 -> 0 | AB3: ='FS Sayan Feb 2020'!AB9 -> 0 | AC3: ='FS Sayan Feb 2020'!AC9 -> 0 | AD3: ='FS Sayan Feb 2020'!AD9 -> 0 | ... AF3: ='FS Sayan Feb 2020'!AF9 -> 0 | AG3: ='FS Sayan Feb 2020'!AK9 -> 0 | AH3: ='FS Sayan Feb 2020'!AP9 -> 0 | AI3: ='FS Sayan Feb 2020'!AO9 -> 0 | AJ3: ='FS Sayan Feb 2020'!AP9 -> 0 | AK3: ='FS Sayan Feb 2020'!AW9 -> 0 | AL3: ='FS Sayan Feb 2020'!AX9 -> 0 | AM3: ='FS Sayan Feb 2020'!AZ9 -> 0 | AN3: ='FS Sayan Feb 2020'!AZ9 -> 0 | AO3: ='FS Sayan Feb 2020'!BI9 -> 0 | AP3: ='FS Sayan Feb 2020'!BJ9 -> 0 | AQ3: ='FS Sayan Feb 2020'!BA9 -> 0 | AR3: ='FS Sayan Feb 2020'!BB9 -> 0 | AS3: ='FS Sayan Feb 2020'!BK9 -> 0 | AT3: ='FS Sayan Feb 2020'!BL9 -> 0 | AU3: ='FS Sayan Feb 2020'!BM9 -> 0 | AV3: ='FS Sayan Feb 2020'!BN9 -> 0 | AW3: ='FS Sayan Feb 2020'!E9 -> 10.3 | AX3: ='FS Sayan Feb 2020'!F9 -> 0 | AY3: ='FS Sayan Feb 2020'!M9 -> 3.4 | AZ3: ='FS Sayan Feb 2020'!P9 -> 0 | BA3: 0 | BB3: ='FS Sayan Feb 2020'!V23 -> 0 | BC3: ='FS Sayan Feb 2020'!AG9 -> 465 | BD3: ='FS Sayan Feb 2020'!AH9 -> 0 | BE3: ='FS Sayan Feb 2020'!AI9 -> 0 | BF3: ='FS Sayan Feb 2020'!AJ9 -> 0 | BG3: ='FS Sayan Feb 2020'!AK9 -> 0 | BH3: ='FS Sayan Feb 2020'!AL9 -> 0 | BI3: ='FS Sayan Feb 2020'!AM9 -> 0 | BJ3: ='FS Sayan Feb 2020'!AM9 -> 0 | BK3: ='FS Sayan Feb 2020'!AO9 -> 0 | BL3: ='FS Sayan Feb 2020'!AP9 -> 0 | BM3: 0 | BN3: 0 | BO3: ='FS Sayan Feb 2020'!Q9 -> 0 | BP3: ='FS Sayan Feb 2020'!R9 -> 0
A4: Bali Sayan | B4: =B3+1 -> 3 | C4: 2 | D4: 2020 | E4: ='FS Sayan Feb 2020'!M10 -> 3 | F4: ='FS Sayan Feb 2020'!N10 -> 0 | G4: ='FS Sayan Feb 2020'!G10 -> 0 | H4: ='FS Sayan Feb 2020'!H10 -> 0 | I4: ='FS Sayan Feb 2020'!I10 -> 0 | J4: ='FS Sayan Feb 2020'!J10 -> 0 | K4: ='FS Sayan Feb 2020'!K10 -> 10.3 | L4: ='FS Sayan Feb 2020'!L10 -> 0 | M4: ='FS Sayan Feb 2020'!S10 -> 0 | N4: ='FS Sayan Feb 2020'!T10 -> 0 | O4: ='FS Sayan Feb 2020'!U10 -> 2.6 | P4: ='FS Sayan Feb 2020'!V10 -> 0 | Q4: ='FS Sayan Feb 2020'!BC10 -> 0 | R4: ='FS Sayan Feb 2020'!BD10 -> 0 | S4: ='FS Sayan Feb 2020'!BF10 -> 0 | T4: ='FS Sayan Feb 2020'!BF10 -> 0 | U4: ='FS Sayan Feb 2020'!BG10 -> 0 | V4: ='FS Sayan Feb 2020'!BH10 -> 0 | W4: ='FS Sayan Feb 2020'!W10 -> 126 | X4: ='FS Sayan Feb 2020'!X10 -> 0 | Y4: ='FS Sayan Feb 2020'!Y10 -> 0 | Z4: ='FS Sayan Feb 2020'!Z10 -> 0 | AA4: ='FS Sayan Feb 2020'!AA10 -> 0 | AB4: ='FS Sayan Feb 2020'!AB10 -> 0 | AC4: ='FS Sayan Feb 2020'!AC10 -> 0 | AD4: ='FS Sayan Feb 2020'!AD10 -> 0 | ... AF4: ='FS Sayan Feb 2020'!AF10 -> 0 | AG4: ='FS Sayan Feb 2020'!AK10 -> 0 | AH4: ='FS Sayan Feb 2020'!AP10 -> 0 | AI4: ='FS Sayan Feb 2020'!AO10 -> 0 | AJ4: ='FS Sayan Feb 2020'!AP10 -> 0 | AK4: ='FS Sayan Feb 2020'!AW10 -> 0 | AL4: ='FS Sayan Feb 2020'!AX10 -> 0 | AM4: ='FS Sayan Feb 2020'!AZ10 -> 0 | AN4: ='FS Sayan Feb 2020'!AZ10 -> 0 | AO4: ='FS Sayan Feb 2020'!BI10 -> 0 | AP4: ='FS Sayan Feb 2020'!BJ10 -> 0 | AQ4: ='FS Sayan Feb 2020'!BA10 -> 0 | AR4: ='FS Sayan Feb 2020'!BB10 -> 0 | AS4: ='FS Sayan Feb 2020'!BK10 -> 0 | AT4: ='FS Sayan Feb 2020'!BL10 -> 0 | AU4: ='FS Sayan Feb 2020'!BM10 -> 0 | AV4: ='FS Sayan Feb 2020'!BN10 -> 0 | AW4: ='FS Sayan Feb 2020'!E10 -> 8.5 | AX4: ='FS Sayan Feb 2020'!F10 -> 0 | AY4: ='FS Sayan Feb 2020'!M10 -> 3 | AZ4: ='FS Sayan Feb 2020'!P10 -> 0 | BA4: 0 | BB4: ='FS Sayan Feb 2020'!V24 -> 0 | BC4: ='FS Sayan Feb 2020'!AG10 -> 420 | BD4: ='FS Sayan Feb 2020'!AH10 -> 0 | BE4: ='FS Sayan Feb 2020'!AI10 -> 0 | BF4: ='FS Sayan Feb 2020'!AJ10 -> 0 | BG4: ='FS Sayan Feb 2020'!AK10 -> 0 | BH4: ='FS Sayan Feb 2020'!AL10 -> 0 | BI4: ='FS Sayan Feb 2020'!AM10 -> 0 | BJ4: ='FS Sayan Feb 2020'!AM10 -> 0 | BK4: ='FS Sayan Feb 2020'!AO10 -> 0 | BL4: ='FS Sayan Feb 2020'!AP10 -> 0 | BM4: 0 | BN4: 0 | BO4: ='FS Sayan Feb 2020'!Q10 -> 0 | BP4: ='FS Sayan Feb 2020'!R10 -> 0
A5: Bali Sayan | B5: =B4+1 -> 4 | C5: 2 | D5: 2020 | E5: ='FS Sayan Feb 2020'!M11 -> 3.8 | F5: ='FS Sayan Feb 2020'!N11 -> 0 | G5: ='FS Sayan Feb 2020'!G11 -> 0 | H5: ='FS Sayan Feb 2020'!H11 -> 0 | I5: ='FS Sayan Feb 2020'!I11 -> 0 | J5: ='FS Sayan Feb 2020'!J11 -> 0 | K5: ='FS Sayan Feb 2020'!K11 -> 11.3 | L5: ='FS Sayan Feb 2020'!L11 -> 0 | M5: ='FS Sayan Feb 2020'!S11 -> 0 | N5: ='FS Sayan Feb 2020'!T11 -> 0 | O5: ='FS Sayan Feb 2020'!U11 -> 5 | P5: ='FS Sayan Feb 2020'!V11 -> 0 | Q5: ='FS Sayan Feb 2020'!BC11 -> 0 | R5: ='FS Sayan Feb 2020'!BD11 -> 0 | S5: ='FS Sayan Feb 2020'!BF11 -> 0 | T5: ='FS Sayan Feb 2020'!BF11 -> 0 | U5: ='FS Sayan Feb 2020'!BG11 -> 0 | V5: ='FS Sayan Feb 2020'!BH11 -> 0 | W5: ='FS Sayan Feb 2020'!W11 -> 144 | X5: ='FS Sayan Feb 2020'!X11 -> 0 | Y5: ='FS Sayan Feb 2020'!Y11 -> 0 | Z5: ='FS Sayan Feb 2020'!Z11 -> 0 | AA5: ='FS Sayan Feb 2020'!AA11 -> 0 | AB5: ='FS Sayan Feb 2020'!AB11 -> 0 | AC5: ='FS Sayan Feb 2020'!AC11 -> 0 | AD5: ='FS Sayan Feb 2020'!AD11 -> 0 | ... AF5: ='FS Sayan Feb 2020'!AF11 -> 0 | AG5: ='FS Sayan Feb 2020'!AK11 -> 0 | AH5: ='FS Sayan Feb 2020'!AP11 -> 0 | AI5: ='FS Sayan Feb 2020'!AO11 -> 0 | AJ5: ='FS Sayan Feb 2020'!AP11 -> 0 | AK5: ='FS Sayan Feb 2020'!AW11 -> 0 | AL5: ='FS Sayan Feb 2020'!AX11 -> 0 | AM5: ='FS Sayan Feb 2020'!AZ11 -> 0 | AN5: ='FS Sayan Feb 2020'!AZ11 -> 0 | AO5: ='FS Sayan Feb 2020'!BI11 -> 0 | AP5: ='FS Sayan Feb 2020'!BJ11 -> 0 | AQ5: ='FS Sayan Feb 2020'!BA11 -> 0 | AR5: ='FS Sayan Feb 2020'!BB11 -> 0 | AS5: ='FS Sayan Feb 2020'!BK11 -> 0 | AT5: ='FS Sayan Feb 2020'!BL11 -> 0 | AU5: ='FS Sayan Feb 2020'!BM11 -> 0 | AV5: ='FS Sayan Feb 2020'!BN11 -> 0 | AW5: ='FS Sayan Feb 2020'!E11 -> 11.6 | AX5: ='FS Sayan Feb 2020'!F11 -> 0 | AY5: ='FS Sayan Feb 2020'!M11 -> 3.8 | AZ5: ='FS Sayan Feb 2020'!P11 -> 0 | BA5: 0 | BB5: ='FS Sayan Feb 2020'!V25 -> 0 | BC5: ='FS Sayan Feb 2020'!AG11 -> 435 | BD5: ='FS Sayan Feb 2020'!AH11 -> 0 | BE5: ='FS Sayan Feb 2020'!AI11 -> 0 | BF5: ='FS Sayan Feb 2020'!AJ11 -> 0 | BG5: ='FS Sayan Feb 2020'!AK11 -> 0 | BH5: ='FS Sayan Feb 2020'!AL11 -> 0 | BI5: ='FS Sayan Feb 2020'!AM11 -> 0 | BJ5: ='FS Sayan Feb 2020'!AM11 -> 0 | BK5: ='FS Sayan Feb 2020'!AO11 -> 0 | BL5: ='FS Sayan Feb 2020'!AP11 -> 0 | BM5: 0 | BN5: 0 | BO5: ='FS Sayan Feb 2020'!Q11 -> 0 | BP5: ='FS Sayan Feb 2020'!R11 -> 0
A6: Bali Sayan | B6: =B5+1 -> 5 | C6: 2 | D6: 2020 | E6: ='FS Sayan Feb 2020'!M12 -> 4.3 | F6: ='FS Sayan Feb 2020'!N12 -> 0 | G6: ='FS Sayan Feb 2020'!G12 -> 0 | H6: ='FS Sayan Feb 2020'!H12 -> 0 | I6: ='FS Sayan Feb 2020'!I12 -> 0 | J6: ='FS Sayan Feb 2020'!J12 -> 0 | K6: ='FS Sayan Feb 2020'!K12 -> 12.5 | L6: ='FS Sayan Feb 2020'!L12 -> 0 | M6: ='FS Sayan Feb 2020'!S12 -> 0 | N6: ='FS Sayan Feb 2020'!T12 -> 0 | O6: ='FS Sayan Feb 2020'!U12 -> 2.2 | P6: ='FS Sayan Feb 2020'!V12 -> 0 | Q6: ='FS Sayan Feb 2020'!BC12 -> 0 | R6: ='FS Sayan Feb 2020'!BD12 -> 0 | S6: ='FS Sayan Feb 2020'!BF12 -> 0 | T6: ='FS Sayan Feb 2020'!BF12 -> 0 | U6: ='FS Sayan Feb 2020'!BG12 -> 0 | V6: ='FS Sayan Feb 2020'!BH12 -> 0 | W6: ='FS Sayan Feb 2020'!W12 -> 108 | X6: ='FS Sayan Feb 2020'!X12 -> 0 | Y6: ='FS Sayan Feb 2020'!Y12 -> 0 | Z6: ='FS Sayan Feb 2020'!Z12 -> 0 | AA6: ='FS Sayan Feb 2020'!AA12 -> 0 | AB6: ='FS Sayan Feb 2020'!AB12 -> 0 | AC6: ='FS Sayan Feb 2020'!AC12 -> 0 | AD6: ='FS Sayan Feb 2020'!AD12 -> 0 | ... AF6: ='FS Sayan Feb 2020'!AF12 -> 0 | AG6: ='FS Sayan Feb 2020'!AK12 -> 0 | AH6: ='FS Sayan Feb 2020'!AP12 -> 0 | AI6: ='FS Sayan Feb 2020'!AO12 -> 0 | AJ6: ='FS Sayan Feb 2020'!AP12 -> 0 | AK6: ='FS Sayan Feb 2020'!AW12 -> 0 | AL6: ='FS Sayan Feb 2020'!AX12 -> 0 | AM6: ='FS Sayan Feb 2020'!AZ12 -> 0 | AN6: ='FS Sayan Feb 2020'!AZ12 -> 0 | AO6: ='FS Sayan Feb 2020'!BI12 -> 0 | AP6: ='FS Sayan Feb 2020'!BJ12 -> 0 | AQ6: ='FS Sayan Feb 2020'!BA12 -> 0 | AR6: ='FS Sayan Feb 2020'!BB12 -> 0 | AS6: ='FS Sayan Feb 2020'!BK12 -> 0 | AT6: ='FS Sayan Feb 2020'!BL12 -> 0 | AU6: ='FS Sayan Feb 2020'!BM12 -> 0 | AV6: ='FS Sayan Feb 2020'!BN12 -> 0 | AW6: ='FS Sayan Feb 2020'!E12 -> 10.3 | AX6: ='FS Sayan Feb 2020'!F12 -> 0 | AY6: ='FS Sayan Feb 2020'!M12 -> 4.3 | AZ6: ='FS Sayan Feb 2020'!P12 -> 0 | BA6: 0 | BB6: ='FS Sayan Feb 2020'!V26 -> 0 | BC6: ='FS Sayan Feb 2020'!AG12 -> 490 | BD6: ='FS Sayan Feb 2020'!AH12 -> 0 | BE6: ='FS Sayan Feb 2020'!AI12 -> 0 | BF6: ='FS Sayan Feb 2020'!AJ12 -> 0 | BG6: ='FS Sayan Feb 2020'!AK12 -> 0 | BH6: ='FS Sayan Feb 2020'!AL12 -> 0 | BI6: ='FS Sayan Feb 2020'!AM12 -> 0 | BJ6: ='FS Sayan Feb 2020'!AM12 -> 0 | BK6: ='FS Sayan Feb 2020'!AO12 -> 0 | BL6: ='FS Sayan Feb 2020'!AP12 -> 0 | BM6: 0 | BN6: 0 | BO6: ='FS Sayan Feb 2020'!Q12 -> 0 | BP6: ='FS Sayan Feb 2020'!R12 -> 0
A7: Bali Sayan | B7: =B6+1 -> 6 | C7: 2 | D7: 2020 | E7: ='FS Sayan Feb 2020'!M13 -> 2.9 | F7: ='FS Sayan Feb 2020'!N13 -> 0 | G7: ='FS Sayan Feb 2020'!G13 -> 0 | H7: ='FS Sayan Feb 2020'!H13 -> 0 | I7: ='FS Sayan Feb 2020'!I13 -> 0 | J7: ='FS Sayan Feb 2020'!J13 -> 0 | K7: ='FS Sayan Feb 2020'!K13 -> 9.4 | L7: ='FS Sayan Feb 2020'!L13 -> 0 | M7: ='FS Sayan Feb 2020'!S13 -> 0 | N7: ='FS Sayan Feb 2020'!T13 -> 0 | O7: ='FS Sayan Feb 2020'!U13 -> 3.2 | P7: ='FS Sayan Feb 2020'!V13 -> 0 | Q7: ='FS Sayan Feb 2020'!BC13 -> 0 | R7: ='FS Sayan Feb 2020'!BD13 -> 0 | S7: ='FS Sayan Feb 2020'!BF13 -> 0 | T7: ='FS Sayan Feb 2020'!BF13 -> 0 | U7: ='FS Sayan Feb 2020'!BG13 -> 0 | V7: ='FS Sayan Feb 2020'!BH13 -> 0 | W7: ='FS Sayan Feb 2020'!W13 -> 121.5 | X7: ='FS Sayan Feb 2020'!X13 -> 0 | Y7: ='FS Sayan Feb 2020'!Y13 -> 0 | Z7: ='FS Sayan Feb 2020'!Z13 -> 0 | AA7: ='FS Sayan Feb 2020'!AA13 -> 0 | AB7: ='FS Sayan Feb 2020'!AB13 -> 0 | AC7: ='FS Sayan Feb 2020'!AC13 -> 0 | AD7: ='FS Sayan Feb 2020'!AD13 -> 0 | ... AF7: ='FS Sayan Feb 2020'!AF13 -> 0 | AG7: ='FS Sayan Feb 2020'!AK13 -> 0 | AH7: ='FS Sayan Feb 2020'!AP13 -> 0 | AI7: ='FS Sayan Feb 2020'!AO13 -> 0 | AJ7: ='FS Sayan Feb 2020'!AP13 -> 0 | AK7: ='FS Sayan Feb 2020'!AW13 -> 0 | AL7: ='FS Sayan Feb 2020'!AX13 -> 0 | AM7: ='FS Sayan Feb 2020'!AZ13 -> 0 | AN7: ='FS Sayan Feb 2020'!AZ13 -> 0 | AO7: ='FS Sayan Feb 2020'!BI13 -> 0 | AP7: ='FS Sayan Feb 2020'!BJ13 -> 0 | AQ7: ='FS Sayan Feb 2020'!BA13 -> 0 | AR7: ='FS Sayan Feb 2020'!BB13 -> 0 | AS7: ='FS Sayan Feb 2020'!BK13 -> 0 | AT7: ='FS Sayan Feb 2020'!BL13 -> 0 | AU7: ='FS Sayan Feb 2020'!BM13 -> 0 | AV7: ='FS Sayan Feb 2020'!BN13 -> 0 | AW7: ='FS Sayan Feb 2020'!E13 -> 10.5 | AX7: ='FS Sayan Feb 2020'!F13 -> 0 | AY7: ='FS Sayan Feb 2020'!M13 -> 2.9 | AZ7: ='FS Sayan Feb 2020'!P13 -> 0 | BA7: 0 | BB7: ='FS Sayan Feb 2020'!V27 -> 0 | BC7: ='FS Sayan Feb 2020'!AG13 -> 500 | BD7: ='FS Sayan Feb 2020'!AH13 -> 0 | BE7: ='FS Sayan Feb 2020'!AI13 -> 0 | BF7: ='FS Sayan Feb 2020'!AJ13 -> 0 | BG7: ='FS Sayan Feb 2020'!AK13 -> 0 | BH7: ='FS Sayan Feb 2020'!AL13 -> 0 | BI7: ='FS Sayan Feb 2020'!AM13 -> 0 | BJ7: ='FS Sayan Feb 2020'!AM13 -> 0 | BK7: ='FS Sayan Feb 2020'!AO13 -> 0 | BL7: ='FS Sayan Feb 2020'!AP13 -> 0 | BM7: 0 | BN7: 0 | BO7: ='FS Sayan Feb 2020'!Q13 -> 0 | BP7: ='FS Sayan Feb 2020'!R13 -> 0
A8: Bali Sayan | B8: =B7+1 -> 7 | C8: 2 | D8: 2020 | E8: ='FS Sayan Feb 2020'!M14 -> 4.7 | F8: ='FS Sayan Feb 2020'!N14 -> 0 | G8: ='FS Sayan Feb 2020'!G14 -> 0 | H8: ='FS Sayan Feb 2020'!H14 -> 0 | I8: ='FS Sayan Feb 2020'!I14 -> 0 | J8: ='FS Sayan Feb 2020'!J14 -> 0 | K8: ='FS Sayan Feb 2020'!K14 -> 12.5 | L8: ='FS Sayan Feb 2020'!L14 -> 0 | M8: ='FS Sayan Feb 2020'!S14 -> 0 | N8: ='FS Sayan Feb 2020'!T14 -> 0 | O8: ='FS Sayan Feb 2020'!U14 -> 4.8 | P8: ='FS Sayan Feb 2020'!V14 -> 0 | Q8: ='FS Sayan Feb 2020'!BC14 -> 0 | R8: ='FS Sayan Feb 2020'!BD14 -> 0 | S8: ='FS Sayan Feb 2020'!BF14 -> 0 | T8: ='FS Sayan Feb 2020'!BF14 -> 0 | U8: ='FS Sayan Feb 2020'!BG14 -> 0 | V8: ='FS Sayan Feb 2020'!BH14 -> 0 | W8: ='FS Sayan Feb 2020'!W14 -> 126 | X8: ='FS Sayan Feb 2020'!X14 -> 0 | Y8: ='FS Sayan Feb 2020'!Y14 -> 0 | Z8: ='FS Sayan Feb 2020'!Z14 -> 0 | AA8: ='FS Sayan Feb 2020'!AA14 -> 0 | AB8: ='FS Sayan Feb 2020'!AB14 -> 0 | AC8: ='FS Sayan Feb 2020'!AC14 -> 0 | AD8: ='FS Sayan Feb 2020'!AD14 -> 0 | ... AF8: ='FS Sayan Feb 2020'!AF14 -> 0 | AG8: ='FS Sayan Feb 2020'!AK14 -> 0 | AH8: ='FS Sayan Feb 2020'!AP14 -> 0 | AI8: ='FS Sayan Feb 2020'!AO14 -> 0 | AJ8: ='FS Sayan Feb 2020'!AP14 -> 0 | AK8: ='FS Sayan Feb 2020'!AW14 -> 0 | AL8: ='FS Sayan Feb 2020'!AX14 -> 0 | AM8: ='FS Sayan Feb 2020'!AZ14 -> 0 | AN8: ='FS Sayan Feb 2020'!AZ14 -> 0 | AO8: ='FS Sayan Feb 2020'!BI14 -> 0 | AP8: ='FS Sayan Feb 2020'!BJ14 -> 0 | AQ8: ='FS Sayan Feb 2020'!BA14 -> 0 | AR8: ='FS Sayan Feb 2020'!BB14 -> 0 | AS8: ='FS Sayan Feb 2020'!BK14 -> 0 | AT8: ='FS Sayan Feb 2020'!BL14 -> 0 | AU8: ='FS Sayan Feb 2020'!BM14 -> 0 | AV8: ='FS Sayan Feb 2020'!BN14 -> 0 | AW8: ='FS Sayan Feb 2020'!E14 -> 8.1 | AX8: ='FS Sayan Feb 2020'!F14 -> 0 | AY8: ='FS Sayan Feb 2020'!M14 -> 4.7 | AZ8: ='FS Sayan Feb 2020'!P14 -> 0 | BA8: 0 | BB8: ='FS Sayan Feb 2020'!V28 -> 0 | BC8: ='FS Sayan Feb 2020'!AG14 -> 520 | BD8: ='FS Sayan Feb 2020'!AH14 -> 0 | BE8: ='FS Sayan Feb 2020'!AI14 -> 0 | BF8: ='FS Sayan Feb 2020'!AJ14 -> 0 | BG8: ='FS Sayan Feb 2020'!AK14 -> 0 | BH8: ='FS Sayan Feb 2020'!AL14 -> 0 | BI8: ='FS Sayan Feb 2020'!AM14 -> 0 | BJ8: ='FS Sayan Feb 2020'!AM14 -> 0 | BK8: ='FS Sayan Feb 2020'!AO14 -> 0 | BL8: ='FS Sayan Feb 2020'!AP14 -> 0 | BM8: 0 | BN8: 0 | BO8: ='FS Sayan Feb 2020'!Q14 -> 0 | BP8: ='FS Sayan Feb 2020'!R14 -> 0
A9: Bali Sayan | B9: =B8+1 -> 8 | C9: 2 | D9: 2020 | E9: ='FS Sayan Feb 2020'!M15 -> 5.2 | F9: ='FS Sayan Feb 2020'!N15 -> 0 | G9: ='FS Sayan Feb 2020'!G15 -> 0 | H9: ='FS Sayan Feb 2020'!H15 -> 0 | I9: ='FS Sayan Feb 2020'!I15 -> 0 | J9: ='FS Sayan Feb 2020'!J15 -> 0 | K9: ='FS Sayan Feb 2020'!K15 -> 9.3 | L9: ='FS Sayan Feb 2020'!L15 -> 0 | M9: ='FS Sayan Feb 2020'!S15 -> 0 | N9: ='FS Sayan Feb 2020'!T15 -> 0 | O9: ='FS Sayan Feb 2020'!U15 -> 3 | P9: ='FS Sayan Feb 2020'!V15 -> 0 | Q9: ='FS Sayan Feb 2020'!BC15 -> 0 | R9: ='FS Sayan Feb 2020'!BD15 -> 0 | S9: ='FS Sayan Feb 2020'!BF15 -> 0 | T9: ='FS Sayan Feb 2020'!BF15 -> 0 | U9: ='FS Sayan Feb 2020'!BG15 -> 0 | V9: ='FS Sayan Feb 2020'!BH15 -> 0 | W9: ='FS Sayan Feb 2020'!W15 -> 135 | X9: ='FS Sayan Feb 2020'!X15 -> 0 | Y9: ='FS Sayan Feb 2020'!Y15 -> 0 | Z9: ='FS Sayan Feb 2020'!Z15 -> 0 | AA9: ='FS Sayan Feb 2020'!AA15 -> 0 | AB9: ='FS Sayan Feb 2020'!AB15 -> 0 | AC9: ='FS Sayan Feb 2020'!AC15 -> 0 | AD9: ='FS Sayan Feb 2020'!AD15 -> 0 | ... AF9: ='FS Sayan Feb 2020'!AF15 -> 0 | AG9: ='FS Sayan Feb 2020'!AK15 -> 0 | AH9: ='FS Sayan Feb 2020'!AP15 -> 0 | AI9: ='FS Sayan Feb 2020'!AO15 -> 0 | AJ9: ='FS Sayan Feb 2020'!AP15 -> 0 | AK9: ='FS Sayan Feb 2020'!AW15 -> 0 | AL9: ='FS Sayan Feb 2020'!AX15 -> 0 | AM9: ='FS Sayan Feb 2020'!AZ15 -> 0 | AN9: ='FS Sayan Feb 2020'!AZ15 -> 0 | AO9: ='FS Sayan Feb 2020'!BI15 -> 0 | AP9: ='FS Sayan Feb 2020'!BJ15 -> 0 | AQ9: ='FS Sayan Feb 2020'!BA15 -> 0 | AR9: ='FS Sayan Feb 2020'!BB15 -> 0 | AS9: ='FS Sayan Feb 2020'!BK15 -> 0 | AT9: ='FS Sayan Feb 2020'!BL15 -> 0 | AU9: ='FS Sayan Feb 2020'!BM15 -> 0 | AV9: ='FS Sayan Feb 2020'!BN15 -> 0 | AW9: ='FS Sayan Feb 2020'!E15 -> 9 | AX9: ='FS Sayan Feb 2020'!F15 -> 0 | AY9: ='FS Sayan Feb 2020'!M15 -> 5.2 | AZ9: ='FS Sayan Feb 2020'!P15 -> 0 | BA9: 0 | BB9: ='FS Sayan Feb 2020'!V29 -> 0 | BC9: ='FS Sayan Feb 2020'!AG15 -> 355 | BD9: ='FS Sayan Feb 2020'!AH15 -> 0 | BE9: ='FS Sayan Feb 2020'!AI15 -> 0 | BF9: ='FS Sayan Feb 2020'!AJ15 -> 0 | BG9: ='FS Sayan Feb 2020'!AK15 -> 0 | BH9: ='FS Sayan Feb 2020'!AL15 -> 0 | BI9: ='FS Sayan Feb 2020'!AM15 -> 0 | BJ9: ='FS Sayan Feb 2020'!AM15 -> 0 | BK9: ='FS Sayan Feb 2020'!AO15 -> 0 | BL9: ='FS Sayan Feb 2020'!AP15 -> 0 | BM9: 0 | BN9: 0 | BO9: ='FS Sayan Feb 2020'!Q15 -> 0 | BP9: ='FS Sayan Feb 2020'!R15 -> 0
A10: Bali Sayan | B10: =B9+1 -> 9 | C10: 2 | D10: 2020 | E10: ='FS Sayan Feb 2020'!M16 -> 3.7 | F10: ='FS Sayan Feb 2020'!N16 -> 0 | G10: ='FS Sayan Feb 2020'!G16 -> 0 | H10: ='FS Sayan Feb 2020'!H16 -> 0 | I10: ='FS Sayan Feb 2020'!I16 -> 0 | J10: ='FS Sayan Feb 2020'!J16 -> 0 | K10: ='FS Sayan Feb 2020'!K16 -> 12.4 | L10: ='FS Sayan Feb 2020'!L16 -> 0 | M10: ='FS Sayan Feb 2020'!S16 -> 0 | N10: ='FS Sayan Feb 2020'!T16 -> 0 | O10: ='FS Sayan Feb 2020'!U16 -> 2.8 | P10: ='FS Sayan Feb 2020'!V16 -> 0 | Q10: ='FS Sayan Feb 2020'!BC16 -> 0 | R10: ='FS Sayan Feb 2020'!BD16 -> 0 | S10: ='FS Sayan Feb 2020'!BF16 -> 0 | T10: ='FS Sayan Feb 2020'!BF16 -> 0 | U10: ='FS Sayan Feb 2020'!BG16 -> 0 | V10: ='FS Sayan Feb 2020'!BH16 -> 0 | W10: ='FS Sayan Feb 2020'!W16 -> 144 | X10: ='FS Sayan Feb 2020'!X16 -> 0 | Y10: ='FS Sayan Feb 2020'!Y16 -> 0 | Z10: ='FS Sayan Feb 2020'!Z16 -> 0 | AA10: ='FS Sayan Feb 2020'!AA16 -> 0 | AB10: ='FS Sayan Feb 2020'!AB16 -> 0 | AC10: ='FS Sayan Feb 2020'!AC16 -> 0 | AD10: ='FS Sayan Feb 2020'!AD16 -> 0 | ... AF10: ='FS Sayan Feb 2020'!AF16 -> 0 | AG10: ='FS Sayan Feb 2020'!AK16 -> 0 | AH10: ='FS Sayan Feb 2020'!AP16 -> 0 | AI10: ='FS Sayan Feb 2020'!AO16 -> 0 | AJ10: ='FS Sayan Feb 2020'!AP16 -> 0 | AK10: ='FS Sayan Feb 2020'!AW16 -> 0 | AL10: ='FS Sayan Feb 2020'!AX16 -> 0 | AM10: ='FS Sayan Feb 2020'!AZ16 -> 0 | AN10: ='FS Sayan Feb 2020'!AZ16 -> 0 | AO10: ='FS Sayan Feb 2020'!BI16 -> 0 | AP10: ='FS Sayan Feb 2020'!BJ16 -> 0 | AQ10: ='FS Sayan Feb 2020'!BA16 -> 0 | AR10: ='FS Sayan Feb 2020'!BB16 -> 0 | AS10: ='FS Sayan Feb 2020'!BK16 -> 0 | AT10: ='FS Sayan Feb 2020'!BL16 -> 0 | AU10: ='FS Sayan Feb 2020'!BM16 -> 0 | AV10: ='FS Sayan Feb 2020'!BN16 -> 0 | AW10: ='FS Sayan Feb 2020'!E16 -> 11.7 | AX10: ='FS Sayan Feb 2020'!F16 -> 0 | AY10: ='FS Sayan Feb 2020'!M16 -> 3.7 | AZ10: ='FS Sayan Feb 2020'!P16 -> 0 | BA10: 0 | BB10: ='FS Sayan Feb 2020'!V30 -> 0 | BC10: ='FS Sayan Feb 2020'!AG16 -> 400 | BD10: ='FS Sayan Feb 2020'!AH16 -> 0 | BE10: ='FS Sayan Feb 2020'!AI16 -> 0 | BF10: ='FS Sayan Feb 2020'!AJ16 -> 0 | BG10: ='FS Sayan Feb 2020'!AK16 -> 0 | BH10: ='FS Sayan Feb 2020'!AL16 -> 0 | BI10: ='FS Sayan Feb 2020'!AM16 -> 0 | BJ10: ='FS Sayan Feb 2020'!AM16 -> 0 | BK10: ='FS Sayan Feb 2020'!AO16 -> 0 | BL10: ='FS Sayan Feb 2020'!AP16 -> 0 | BM10: 0 | BN10: 0 | BO10: ='FS Sayan Feb 2020'!Q16 -> 0 | BP10: ='FS Sayan Feb 2020'!R16 -> 0
A11: Bali Sayan | B11: =B10+1 -> 10 | C11: 2 | D11: 2020 | E11: ='FS Sayan Feb 2020'!M17 -> 2.7 | F11: ='FS Sayan Feb 2020'!N17 -> 0 | G11: ='FS Sayan Feb 2020'!G17 -> 0 | H11: ='FS Sayan Feb 2020'!H17 -> 0 | I11: ='FS Sayan Feb 2020'!I17 -> 0 | J11: ='FS Sayan Feb 2020'!J17 -> 0 | K11: ='FS Sayan Feb 2020'!K17 -> 9.7 | L11: ='FS Sayan Feb 2020'!L17 -> 0 | M11: ='FS Sayan Feb 2020'!S17 -> 0 | N11: ='FS Sayan Feb 2020'!T17 -> 0 | O11: ='FS Sayan Feb 2020'!U17 -> 2.6 | P11: ='FS Sayan Feb 2020'!V17 -> 0 | Q11: ='FS Sayan Feb 2020'!BC17 -> 0 | R11: ='FS Sayan Feb 2020'!BD17 -> 0 | S11: ='FS Sayan Feb 2020'!BF17 -> 0 | T11: ='FS Sayan Feb 2020'!BF17 -> 0 | U11: ='FS Sayan Feb 2020'!BG17 -> 0 | V11: ='FS Sayan Feb 2020'!BH17 -> 0 | W11: ='FS Sayan Feb 2020'!W17 -> 117 | X11: ='FS Sayan Feb 2020'!X17 -> 0 | Y11: ='FS Sayan Feb 2020'!Y17 -> 0 | Z11: ='FS Sayan Feb 2020'!Z17 -> 0 | AA11: ='FS Sayan Feb 2020'!AA17 -> 0 | AB11: ='FS Sayan Feb 2020'!AB17 -> 0 | AC11: ='FS Sayan Feb 2020'!AC17 -> 0 | AD11: ='FS Sayan Feb 2020'!AD17 -> 0 | ... AF11: ='FS Sayan Feb 2020'!AF17 -> 0 | AG11: ='FS Sayan Feb 2020'!AK17 -> 0 | AH11: ='FS Sayan Feb 2020'!AP17 -> 0 | AI11: ='FS Sayan Feb 2020'!AO17 -> 0 | AJ11: ='FS Sayan Feb 2020'!AP17 -> 0 | AK11: ='FS Sayan Feb 2020'!AW17 -> 0 | AL11: ='FS Sayan Feb 2020'!AX17 -> 0 | AM11: ='FS Sayan Feb 2020'!AZ17 -> 0 | AN11: ='FS Sayan Feb 2020'!AZ17 -> 0 | AO11: ='FS Sayan Feb 2020'!BI17 -> 0 | AP11: ='FS Sayan Feb 2020'!BJ17 -> 0 | AQ11: ='FS Sayan Feb 2020'!BA17 -> 0 | AR11: ='FS Sayan Feb 2020'!BB17 -> 0 | AS11: ='FS Sayan Feb 2020'!BK17 -> 0 | AT11: ='FS Sayan Feb 2020'!BL17 -> 0 | AU11: ='FS Sayan Feb 2020'!BM17 -> 0 | AV11: ='FS Sayan Feb 2020'!BN17 -> 0 | AW11: ='FS Sayan Feb 2020'!E17 -> 11.9 | AX11: ='FS Sayan Feb 2020'!F17 -> 0 | AY11: ='FS Sayan Feb 2020'!M17 -> 2.7 | AZ11: ='FS Sayan Feb 2020'!P17 -> 0 | BA11: 0 | BB11: ='FS Sayan Feb 2020'!V31 -> 0 | BC11: ='FS Sayan Feb 2020'!AG17 -> 605 | BD11: ='FS Sayan Feb 2020'!AH17 -> 0 | BE11: ='FS Sayan Feb 2020'!AI17 -> 0 | BF11: ='FS Sayan Feb 2020'!AJ17 -> 0 | BG11: ='FS Sayan Feb 2020'!AK17 -> 0 | BH11: ='FS Sayan Feb 2020'!AL17 -> 0 | BI11: ='FS Sayan Feb 2020'!AM17 -> 0 | BJ11: ='FS Sayan Feb 2020'!AM17 -> 0 | BK11: ='FS Sayan Feb 2020'!AO17 -> 0 | BL11: ='FS Sayan Feb 2020'!AP17 -> 0 | BM11: 0 | BN11: 0 | BO11: ='FS Sayan Feb 2020'!Q17 -> 0 | BP11: ='FS Sayan Feb 2020'!R17 -> 0
A12: Bali Sayan | B12: =B11+1 -> 11 | C12: 2 | D12: 2020 | E12: ='FS Sayan Feb 2020'!M18 -> 2.7 | F12: ='FS Sayan Feb 2020'!N18 -> 0 | G12: ='FS Sayan Feb 2020'!G18 -> 0 | H12: ='FS Sayan Feb 2020'!H18 -> 0 | I12: ='FS Sayan Feb 2020'!I18 -> 0 | J12: ='FS Sayan Feb 2020'!J18 -> 0 | K12: ='FS Sayan Feb 2020'!K18 -> 10.4 | L12: ='FS Sayan Feb 2020'!L18 -> 0 | M12: ='FS Sayan Feb 2020'!S18 -> 0 | N12: ='FS Sayan Feb 2020'!T18 -> 0 | O12: ='FS Sayan Feb 2020'!U18 -> 4.8 | P12: ='FS Sayan Feb 2020'!V18 -> 0 | Q12: ='FS Sayan Feb 2020'!BC18 -> 0 | R12: ='FS Sayan Feb 2020'!BD18 -> 0 | S12: ='FS Sayan Feb 2020'!BF18 -> 0 | T12: ='FS Sayan Feb 2020'!BF18 -> 0 | U12: ='FS Sayan Feb 2020'!BG18 -> 0 | V12: ='FS Sayan Feb 2020'!BH18 -> 0 | W12: ='FS Sayan Feb 2020'!W18 -> 126 | X12: ='FS Sayan Feb 2020'!X18 -> 0 | Y12: ='FS Sayan Feb 2020'!Y18 -> 0 | Z12: ='FS Sayan Feb 2020'!Z18 -> 0 | AA12: ='FS Sayan Feb 2020'!AA18 -> 0 | AB12: ='FS Sayan Feb 2020'!AB18 -> 0 | AC12: ='FS Sayan Feb 2020'!AC18 -> 0 | AD12: ='FS Sayan Feb 2020'!AD18 -> 0 | ... AF12: ='FS Sayan Feb 2020'!AF18 -> 0 | AG12: ='FS Sayan Feb 2020'!AK18 -> 0 | AH12: ='FS Sayan Feb 2020'!AP18 -> 0 | AI12: ='FS Sayan Feb 2020'!AO18 -> 0 | AJ12: ='FS Sayan Feb 2020'!AP18 -> 0 | AK12: ='FS Sayan Feb 2020'!AW18 -> 0 | AL12: ='FS Sayan Feb 2020'!AX18 -> 0 | AM12: ='FS Sayan Feb 2020'!AZ18 -> 0 | AN12: ='FS Sayan Feb 2020'!AZ18 -> 0 | AO12: ='FS Sayan Feb 2020'!BI18 -> 0 | AP12: ='FS Sayan Feb 2020'!BJ18 -> 0 | AQ12: ='FS Sayan Feb 2020'!BA18 -> 0 | AR12: ='FS Sayan Feb 2020'!BB18 -> 0 | AS12: ='FS Sayan Feb 2020'!BK18 -> 0 | AT12: ='FS Sayan Feb 2020'!BL18 -> 0 | AU12: ='FS Sayan Feb 2020'!BM18 -> 0 | AV12: ='FS Sayan Feb 2020'!BN18 -> 0 | AW12: ='FS Sayan Feb 2020'!E18 -> 9.2 | AX12: ='FS Sayan Feb 2020'!F18 -> 0 | AY12: ='FS Sayan Feb 2020'!M18 -> 2.7 | AZ12: ='FS Sayan Feb 2020'!P18 -> 0 | BA12: 0 | BB12: ='FS Sayan Feb 2020'!V32 -> 0 | BC12: ='FS Sayan Feb 2020'!AG18 -> 615 | BD12: ='FS Sayan Feb 2020'!AH18 -> 0 | BE12: ='FS Sayan Feb 2020'!AI18 -> 0 | BF12: ='FS Sayan Feb 2020'!AJ18 -> 0 | BG12: ='FS Sayan Feb 2020'!AK18 -> 0 | BH12: ='FS Sayan Feb 2020'!AL18 -> 0 | BI12: ='FS Sayan Feb 2020'!AM18 -> 0 | BJ12: ='FS Sayan Feb 2020'!AM18 -> 0 | BK12: ='FS Sayan Feb 2020'!AO18 -> 0 | BL12: ='FS Sayan Feb 2020'!AP18 -> 0 | BM12: 0 | BN12: 0 | BO12: ='FS Sayan Feb 2020'!Q18 -> 0 | BP12: ='FS Sayan Feb 2020'!R18 -> 0
A13: Bali Sayan | B13: =B12+1 -> 12 | C13: 2 | D13: 2020 | E13: ='FS Sayan Feb 2020'!M19 -> 4.3 | F13: ='FS Sayan Feb 2020'!N19 -> 0 | G13: ='FS Sayan Feb 2020'!G19 -> 0 | H13: ='FS Sayan Feb 2020'!H19 -> 0 | I13: ='FS Sayan Feb 2020'!I19 -> 0 | J13: ='FS Sayan Feb 2020'!J19 -> 0 | K13: ='FS Sayan Feb 2020'!K19 -> 12 | L13: ='FS Sayan Feb 2020'!L19 -> 0 | M13: ='FS Sayan Feb 2020'!S19 -> 0 | N13: ='FS Sayan Feb 2020'!T19 -> 0 | O13: ='FS Sayan Feb 2020'!U19 -> 3 | P13: ='FS Sayan Feb 2020'!V19 -> 0 | Q13: ='FS Sayan Feb 2020'!BC19 -> 0 | R13: ='FS Sayan Feb 2020'!BD19 -> 0 | S13: ='FS Sayan Feb 2020'!BF19 -> 0 | T13: ='FS Sayan Feb 2020'!BF19 -> 0 | U13: ='FS Sayan Feb 2020'!BG19 -> 0 | V13: ='FS Sayan Feb 2020'!BH19 -> 0 | W13: ='FS Sayan Feb 2020'!W19 -> 121.5 | X13: ='FS Sayan Feb 2020'!X19 -> 0 | Y13: ='FS Sayan Feb 2020'!Y19 -> 0 | Z13: ='FS Sayan Feb 2020'!Z19 -> 0 | AA13: ='FS Sayan Feb 2020'!AA19 -> 0 | AB13: ='FS Sayan Feb 2020'!AB19 -> 0 | AC13: ='FS Sayan Feb 2020'!AC19 -> 0 | AD13: ='FS Sayan Feb 2020'!AD19 -> 0 | ... AF13: ='FS Sayan Feb 2020'!AF19 -> 0 | AG13: ='FS Sayan Feb 2020'!AK19 -> 0 | AH13: ='FS Sayan Feb 2020'!AP19 -> 0 | AI13: ='FS Sayan Feb 2020'!AO19 -> 0 | AJ13: ='FS Sayan Feb 2020'!AP19 -> 0 | AK13: ='FS Sayan Feb 2020'!AW19 -> 0 | AL13: ='FS Sayan Feb 2020'!AX19 -> 0 | AM13: ='FS Sayan Feb 2020'!AZ19 -> 0 | AN13: ='FS Sayan Feb 2020'!AZ19 -> 0 | AO13: ='FS Sayan Feb 2020'!BI19 -> 0 | AP13: ='FS Sayan Feb 2020'!BJ19 -> 0 | AQ13: ='FS Sayan Feb 2020'!BA19 -> 0 | AR13: ='FS Sayan Feb 2020'!BB19 -> 0 | AS13: ='FS Sayan Feb 2020'!BK19 -> 0 | AT13: ='FS Sayan Feb 2020'!BL19 -> 0 | AU13: ='FS Sayan Feb 2020'!BM19 -> 0 | AV13: ='FS Sayan Feb 2020'!BN19 -> 0 | AW13: ='FS Sayan Feb 2020'!E19 -> 8.4 | AX13: ='FS Sayan Feb 2020'!F19 -> 0 | AY13: ='FS Sayan Feb 2020'!M19 -> 4.3 | AZ13: ='FS Sayan Feb 2020'!P19 -> 0 | BA13: 0 | BB13: ='FS Sayan Feb 2020'!V33 -> 0 | BC13: ='FS Sayan Feb 2020'!AG19 -> 465 | BD13: ='FS Sayan Feb 2020'!AH19 -> 0 | BE13: ='FS Sayan Feb 2020'!AI19 -> 0 | BF13: ='FS Sayan Feb 2020'!AJ19 -> 0 | BG13: ='FS Sayan Feb 2020'!AK19 -> 0 | BH13: ='FS Sayan Feb 2020'!AL19 -> 0 | BI13: ='FS Sayan Feb 2020'!AM19 -> 0 | BJ13: ='FS Sayan Feb 2020'!AM19 -> 0 | BK13: ='FS Sayan Feb 2020'!AO19 -> 0 | BL13: ='FS Sayan Feb 2020'!AP19 -> 0 | BM13: 0 | BN13: 0 | BO13: ='FS Sayan Feb 2020'!Q19 -> 0 | BP13: ='FS Sayan Feb 2020'!R19 -> 0
A14: Bali Sayan | B14: =B13+1 -> 13 | C14: 2 | D14: 2020 | E14: ='FS Sayan Feb 2020'!M20 -> 4.2 | F14: ='FS Sayan Feb 2020'!N20 -> 0 | G14: ='FS Sayan Feb 2020'!G20 -> 0 | H14: ='FS Sayan Feb 2020'!H20 -> 0 | I14: ='FS Sayan Feb 2020'!I20 -> 0 | J14: ='FS Sayan Feb 2020'!J20 -> 0 | K14: ='FS Sayan Feb 2020'!K20 -> 10.9 | L14: ='FS Sayan Feb 2020'!L20 -> 0 | M14: ='FS Sayan Feb 2020'!S20 -> 0 | N14: ='FS Sayan Feb 2020'!T20 -> 0 | O14: ='FS Sayan Feb 2020'!U20 -> 4.4 | P14: ='FS Sayan Feb 2020'!V20 -> 0 | Q14: ='FS Sayan Feb 2020'!BC20 -> 0 | R14: ='FS Sayan Feb 2020'!BD20 -> 0 | S14: ='FS Sayan Feb 2020'!BF20 -> 0 | T14: ='FS Sayan Feb 2020'!BF20 -> 0 | U14: ='FS Sayan Feb 2020'!BG20 -> 0 | V14: ='FS Sayan Feb 2020'!BH20 -> 0 | W14: ='FS Sayan Feb 2020'!W20 -> 126 | X14: ='FS Sayan Feb 2020'!X20 -> 0 | Y14: ='FS Sayan Feb 2020'!Y20 -> 0 | Z14: ='FS Sayan Feb 2020'!Z20 -> 0 | AA14: ='FS Sayan Feb 2020'!AA20 -> 0 | AB14: ='FS Sayan Feb 2020'!AB20 -> 0 | AC14: ='FS Sayan Feb 2020'!AC20 -> 0 | AD14: ='FS Sayan Feb 2020'!AD20 -> 0 | ... AF14: ='FS Sayan Feb 2020'!AF20 -> 0 | AG14: ='FS Sayan Feb 2020'!AK20 -> 0 | AH14: ='FS Sayan Feb 2020'!AP20 -> 0 | AI14: ='FS Sayan Feb 2020'!AO20 -> 0 | AJ14: ='FS Sayan Feb 2020'!AP20 -> 0 | AK14: ='FS Sayan Feb 2020'!AW20 -> 0 | AL14: ='FS Sayan Feb 2020'!AX20 -> 0 | AM14: ='FS Sayan Feb 2020'!AZ20 -> 0 | AN14: ='FS Sayan Feb 2020'!AZ20 -> 0 | AO14: ='FS Sayan Feb 2020'!BI20 -> 0 | AP14: ='FS Sayan Feb 2020'!BJ20 -> 0 | AQ14: ='FS Sayan Feb 2020'!BA20 -> 0 | AR14: ='FS Sayan Feb 2020'!BB20 -> 0 | AS14: ='FS Sayan Feb 2020'!BK20 -> 0 | AT14: ='FS Sayan Feb 2020'!BL20 -> 0 | AU14: ='FS Sayan Feb 2020'!BM20 -> 0 | AV14: ='FS Sayan Feb 2020'!BN20 -> 0 | AW14: ='FS Sayan Feb 2020'!E20 -> 11 | AX14: ='FS Sayan Feb 2020'!F20 -> 0 | AY14: ='FS Sayan Feb 2020'!M20 -> 4.2 | AZ14: ='FS Sayan Feb 2020'!P20 -> 0 | BA14: 0 | BB14: ='FS Sayan Feb 2020'!V34 -> 0 | BC14: ='FS Sayan Feb 2020'!AG20 -> 610 | BD14: ='FS Sayan Feb 2020'!AH20 -> 0 | BE14: ='FS Sayan Feb 2020'!AI20 -> 0 | BF14: ='FS Sayan Feb 2020'!AJ20 -> 0 | BG14: ='FS Sayan Feb 2020'!AK20 -> 0 | BH14: ='FS Sayan Feb 2020'!AL20 -> 0 | BI14: ='FS Sayan Feb 2020'!AM20 -> 0 | BJ14: ='FS Sayan Feb 2020'!AM20 -> 0 | BK14: ='FS Sayan Feb 2020'!AO20 -> 0 | BL14: ='FS Sayan Feb 2020'!AP20 -> 0 | BM14: 0 | BN14: 0 | BO14: ='FS Sayan Feb 2020'!Q20 -> 0 | BP14: ='FS Sayan Feb 2020'!R20 -> 0
... A22: Bali Sayan | B22: =B21+1 -> 21 | C22: 2 | D22: 2020 | E22: ='FS Sayan Feb 2020'!M28 -> 5 | F22: ='FS Sayan Feb 2020'!N28 -> 0 | G22: ='FS Sayan Feb 2020'!G28 -> 0 | H22: ='FS Sayan Feb 2020'!H28 -> 0 | I22: ='FS Sayan Feb 2020'!I28 -> 0 | J22: ='FS Sayan Feb 2020'!J28 -> 0 | K22: ='FS Sayan Feb 2020'!K28 -> 10.7 | L22: ='FS Sayan Feb 2020'!L28 -> 0 | M22: ='FS Sayan Feb 2020'!S28 -> 0 | N22: ='FS Sayan Feb 2020'!T28 -> 0 | O22: ='FS Sayan Feb 2020'!U28 -> 5 | P22: ='FS Sayan Feb 2020'!V28 -> 0 | Q22: ='FS Sayan Feb 2020'!BC28 -> 0 | R22: ='FS Sayan Feb 2020'!BD28 -> 0 | S22: ='FS Sayan Feb 2020'!BF28 -> 0 | T22: ='FS Sayan Feb 2020'!BF28 -> 0 | U22: ='FS Sayan Feb 2020'!BG28 -> 0 | V22: ='FS Sayan Feb 2020'!BH28 -> 0 | W22: ='FS Sayan Feb 2020'!W28 -> 135 | X22: ='FS Sayan Feb 2020'!X28 -> 0 | Y22: ='FS Sayan Feb 2020'!Y28 -> 0 | Z22: ='FS Sayan Feb 2020'!Z28 -> 0 | AA22: ='FS Sayan Feb 2020'!AA28 -> 0 | AB22: ='FS Sayan Feb 2020'!AB28 -> 0 | AC22: ='FS Sayan Feb 2020'!AC28 -> 0 | AD22: ='FS Sayan Feb 2020'!AD28 -> 0 | ... AF22: ='FS Sayan Feb 2020'!AF28 -> 0 | AG22: ='FS Sayan Feb 2020'!AK28 -> 0 | AH22: ='FS Sayan Feb 2020'!AP28 -> 0 | AI22: ='FS Sayan Feb 2020'!AO28 -> 0 | AJ22: ='FS Sayan Feb 2020'!AP28 -> 0 | AK22: ='FS Sayan Feb 2020'!AW28 -> 0 | AL22: ='FS Sayan Feb 2020'!AX28 -> 0 | AM22: ='FS Sayan Feb 2020'!AZ28 -> 0 | AN22: ='FS Sayan Feb 2020'!AZ28 -> 0 | AO22: ='FS Sayan Feb 2020'!BI28 -> 0 | AP22: ='FS Sayan Feb 2020'!BJ28 -> 0 | AQ22: ='FS Sayan Feb 2020'!BA28 -> 0 | AR22: ='FS Sayan Feb 2020'!BB28 -> 0 | AS22: ='FS Sayan Feb 2020'!BK28 -> 0 | AT22: ='FS Sayan Feb 2020'!BL28 -> 0 | AU22: ='FS Sayan Feb 2020'!BM28 -> 0 | AV22: ='FS Sayan Feb 2020'!BN28 -> 0 | AW22: ='FS Sayan Feb 2020'!E28 -> 11.1 | AX22: ='FS Sayan Feb 2020'!F28 -> 0 | AY22: ='FS Sayan Feb 2020'!M28 -> 5 | AZ22: ='FS Sayan Feb 2020'!P28 -> 0 | BA22: 0 | BB22: ='FS Sayan Feb 2020'!V42 -> 0 | BC22: ='FS Sayan Feb 2020'!AG28 -> 460 | BD22: ='FS Sayan Feb 2020'!AH28 -> 0 | BE22: ='FS Sayan Feb 2020'!AI28 -> 0 | BF22: ='FS Sayan Feb 2020'!AJ28 -> 0 | BG22: ='FS Sayan Feb 2020'!AK28 -> 0 | BH22: ='FS Sayan Feb 2020'!AL28 -> 0 | BI22: ='FS Sayan Feb 2020'!AM28 -> 0 | BJ22: ='FS Sayan Feb 2020'!AM28 -> 0 | BK22: ='FS Sayan Feb 2020'!AO28 -> 0 | BL22: ='FS Sayan Feb 2020'!AP28 -> 0 | BM22: 0 | BN22: 0 | BO22: ='FS Sayan Feb 2020'!Q28 -> 0 | BP22: ='FS Sayan Feb 2020'!R28 -> 0
A23: Bali Sayan | B23: =B22+1 -> 22 | C23: 2 | D23: 2020 | E23: ='FS Sayan Feb 2020'!M29 -> 4.3 | F23: ='FS Sayan Feb 2020'!N29 -> 0 | G23: ='FS Sayan Feb 2020'!G29 -> 0 | H23: ='FS Sayan Feb 2020'!H29 -> 0 | I23: ='FS Sayan Feb 2020'!I29 -> 0 | J23: ='FS Sayan Feb 2020'!J29 -> 0 | K23: ='FS Sayan Feb 2020'!K29 -> 11.6 | L23: ='FS Sayan Feb 2020'!L29 -> 0 | M23: ='FS Sayan Feb 2020'!S29 -> 0 | N23: ='FS Sayan Feb 2020'!T29 -> 0 | O23: ='FS Sayan Feb 2020'!U29 -> 2.6 | P23: ='FS Sayan Feb 2020'!V29 -> 0 | Q23: ='FS Sayan Feb 2020'!BC29 -> 0 | R23: ='FS Sayan Feb 2020'!BD29 -> 0 | S23: ='FS Sayan Feb 2020'!BF29 -> 0 | T23: ='FS Sayan Feb 2020'!BF29 -> 0 | U23: ='FS Sayan Feb 2020'!BG29 -> 0 | V23: ='FS Sayan Feb 2020'!BH29 -> 0 | W23: ='FS Sayan Feb 2020'!W29 -> 108 | X23: ='FS Sayan Feb 2020'!X29 -> 0 | Y23: ='FS Sayan Feb 2020'!Y29 -> 0 | Z23: ='FS Sayan Feb 2020'!Z29 -> 0 | AA23: ='FS Sayan Feb 2020'!AA29 -> 0 | AB23: ='FS Sayan Feb 2020'!AB29 -> 0 | AC23: ='FS Sayan Feb 2020'!AC29 -> 0 | AD23: ='FS Sayan Feb 2020'!AD29 -> 0 | ... AF23: ='FS Sayan Feb 2020'!AF29 -> 0 | AG23: ='FS Sayan Feb 2020'!AK29 -> 0 | AH23: ='FS Sayan Feb 2020'!AP29 -> 0 | AI23: ='FS Sayan Feb 2020'!AO29 -> 0 | AJ23: ='FS Sayan Feb 2020'!AP29 -> 0 | AK23: ='FS Sayan Feb 2020'!AW29 -> 0 | AL23: ='FS Sayan Feb 2020'!AX29 -> 0 | AM23: ='FS Sayan Feb 2020'!AZ29 -> 0 | AN23: ='FS Sayan Feb 2020'!AZ29 -> 0 | AO23: ='FS Sayan Feb 2020'!BI29 -> 0 | AP23: ='FS Sayan Feb 2020'!BJ29 -> 0 | AQ23: ='FS Sayan Feb 2020'!BA29 -> 0 | AR23: ='FS Sayan Feb 2020'!BB29 -> 0 | AS23: ='FS Sayan Feb 2020'!BK29 -> 0 | AT23: ='FS Sayan Feb 2020'!BL29 -> 0 | AU23: ='FS Sayan Feb 2020'!BM29 -> 0 | AV23: ='FS Sayan Feb 2020'!BN29 -> 0 | AW23: ='FS Sayan Feb 2020'!E29 -> 9.2 | AX23: ='FS Sayan Feb 2020'!F29 -> 0 | AY23: ='FS Sayan Feb 2020'!M29 -> 4.3 | AZ23: ='FS Sayan Feb 2020'!P29 -> 0 | BA23: 0 | BB23: 0 | BC23: ='FS Sayan Feb 2020'!AG29 -> 570 | BD23: ='FS Sayan Feb 2020'!AH29 -> 0 | BE23: ='FS Sayan Feb 2020'!AI29 -> 0 | BF23: ='FS Sayan Feb 2020'!AJ29 -> 0 | BG23: ='FS Sayan Feb 2020'!AK29 -> 0 | BH23: ='FS Sayan Feb 2020'!AL29 -> 0 | BI23: ='FS Sayan Feb 2020'!AM29 -> 0 | BJ23: ='FS Sayan Feb 2020'!AM29 -> 0 | BK23: ='FS Sayan Feb 2020'!AO29 -> 0 | BL23: ='FS Sayan Feb 2020'!AP29 -> 0 | BM23: 0 | BN23: 0 | BO23: ='FS Sayan Feb 2020'!Q29 -> 0 | BP23: ='FS Sayan Feb 2020'!R29 -> 0
A24: Bali Sayan | B24: =B23+1 -> 23 | C24: 2 | D24: 2020 | E24: ='FS Sayan Feb 2020'!M30 -> 5.6 | F24: ='FS Sayan Feb 2020'!N30 -> 0 | G24: ='FS Sayan Feb 2020'!G30 -> 0 | H24: ='FS Sayan Feb 2020'!H30 -> 0 | I24: ='FS Sayan Feb 2020'!I30 -> 0 | J24: ='FS Sayan Feb 2020'!J30 -> 0 | K24: ='FS Sayan Feb 2020'!K30 -> 10.6 | L24: ='FS Sayan Feb 2020'!L30 -> 0 | M24: ='FS Sayan Feb 2020'!S30 -> 0 | N24: ='FS Sayan Feb 2020'!T30 -> 0 | O24: ='FS Sayan Feb 2020'!U30 -> 3 | P24: ='FS Sayan Feb 2020'!V30 -> 0 | Q24: ='FS Sayan Feb 2020'!BC30 -> 0 | R24: ='FS Sayan Feb 2020'!BD30 -> 0 | S24: ='FS Sayan Feb 2020'!BF30 -> 0 | T24: ='FS Sayan Feb 2020'!BF30 -> 0 | U24: ='FS Sayan Feb 2020'!BG30 -> 0 | V24: ='FS Sayan Feb 2020'!BH30 -> 0 | W24: ='FS Sayan Feb 2020'!W30 -> 126 | X24: ='FS Sayan Feb 2020'!X30 -> 0 | Y24: ='FS Sayan Feb 2020'!Y30 -> 0 | Z24: ='FS Sayan Feb 2020'!Z30 -> 0 | AA24: ='FS Sayan Feb 2020'!AA30 -> 0 | AB24: ='FS Sayan Feb 2020'!AB30 -> 0 | AC24: ='FS Sayan Feb 2020'!AC30 -> 0 | AD24: ='FS Sayan Feb 2020'!AD30 -> 0 | ... AF24: ='FS Sayan Feb 2020'!AF30 -> 0 | AG24: ='FS Sayan Feb 2020'!AK30 -> 0 | AH24: ='FS Sayan Feb 2020'!AP30 -> 0 | AI24: ='FS Sayan Feb 2020'!AO30 -> 0 | AJ24: ='FS Sayan Feb 2020'!AP30 -> 0 | AK24: ='FS Sayan Feb 2020'!AW30 -> 0 | AL24: ='FS Sayan Feb 2020'!AX30 -> 0 | AM24: ='FS Sayan Feb 2020'!AZ30 -> 0 | AN24: ='FS Sayan Feb 2020'!AZ30 -> 0 | AO24: ='FS Sayan Feb 2020'!BI30 -> 0 | AP24: ='FS Sayan Feb 2020'!BJ30 -> 0 | AQ24: ='FS Sayan Feb 2020'!BA30 -> 0 | AR24: ='FS Sayan Feb 2020'!BB30 -> 0 | AS24: ='FS Sayan Feb 2020'!BK30 -> 0 | AT24: ='FS Sayan Feb 2020'!BL30 -> 0 | AU24: ='FS Sayan Feb 2020'!BM30 -> 0 | AV24: ='FS Sayan Feb 2020'!BN30 -> 0 | AW24: ='FS Sayan Feb 2020'!E30 -> 9.9 | AX24: ='FS Sayan Feb 2020'!F30 -> 0 | AY24: ='FS Sayan Feb 2020'!M30 -> 5.6 | AZ24: ='FS Sayan Feb 2020'!P30 -> 0 | BA24: 0 | BB24: ='FS Sayan Feb 2020'!V44 -> 0 | BC24: ='FS Sayan Feb 2020'!AG30 -> 590 | BD24: ='FS Sayan Feb 2020'!AH30 -> 0 | BE24: ='FS Sayan Feb 2020'!AI30 -> 0 | BF24: ='FS Sayan Feb 2020'!AJ30 -> 0 | BG24: ='FS Sayan Feb 2020'!AK30 -> 0 | BH24: ='FS Sayan Feb 2020'!AL30 -> 0 | BI24: ='FS Sayan Feb 2020'!AM30 -> 0 | BJ24: ='FS Sayan Feb 2020'!AM30 -> 0 | BK24: ='FS Sayan Feb 2020'!AO30 -> 0 | BL24: ='FS Sayan Feb 2020'!AP30 -> 0 | BM24: 0 | BN24: 0 | BO24: ='FS Sayan Feb 2020'!Q30 -> 0 | BP24: ='FS Sayan Feb 2020'!R30 -> 0
A25: Bali Sayan | B25: =B24+1 -> 24 | C25: 2 | D25: 2020 | E25: ='FS Sayan Feb 2020'!M31 -> 4.9 | F25: ='FS Sayan Feb 2020'!N31 -> 0 | G25: ='FS Sayan Feb 2020'!G31 -> 0 | H25: ='FS Sayan Feb 2020'!H31 -> 0 | I25: ='FS Sayan Feb 2020'!I31 -> 0 | J25: ='FS Sayan Feb 2020'!J31 -> 0 | K25: ='FS Sayan Feb 2020'!K31 -> 9.6 | L25: ='FS Sayan Feb 2020'!L31 -> 0 | M25: ='FS Sayan Feb 2020'!S31 -> 0 | N25: ='FS Sayan Feb 2020'!T31 -> 0 | O25: ='FS Sayan Feb 2020'!U31 -> 2.6 | P25: ='FS Sayan Feb 2020'!V31 -> 0 | Q25: ='FS Sayan Feb 2020'!BC31 -> 0 | R25: ='FS Sayan Feb 2020'!BD31 -> 0 | S25: ='FS Sayan Feb 2020'!BF31 -> 0 | T25: ='FS Sayan Feb 2020'!BF31 -> 0 | U25: ='FS Sayan Feb 2020'!BG31 -> 0 | V25: ='FS Sayan Feb 2020'!BH31 -> 0 | W25: ='FS Sayan Feb 2020'!W31 -> 108 | X25: ='FS Sayan Feb 2020'!X31 -> 0 | Y25: ='FS Sayan Feb 2020'!Y31 -> 0 | Z25: ='FS Sayan Feb 2020'!Z31 -> 0 | AA25: ='FS Sayan Feb 2020'!AA31 -> 0 | AB25: ='FS Sayan Feb 2020'!AB31 -> 0 | AC25: ='FS Sayan Feb 2020'!AC31 -> 0 | AD25: ='FS Sayan Feb 2020'!AD31 -> 0 | ... AF25: ='FS Sayan Feb 2020'!AF31 -> 0 | AG25: ='FS Sayan Feb 2020'!AK31 -> 0 | AH25: ='FS Sayan Feb 2020'!AP31 -> 0 | AI25: ='FS Sayan Feb 2020'!AO31 -> 0 | AJ25: ='FS Sayan Feb 2020'!AP31 -> 0 | AK25: ='FS Sayan Feb 2020'!AW31 -> 0 | AL25: ='FS Sayan Feb 2020'!AX31 -> 0 | AM25: ='FS Sayan Feb 2020'!AZ31 -> 0 | AN25: ='FS Sayan Feb 2020'!AZ31 -> 0 | AO25: ='FS Sayan Feb 2020'!BI31 -> 0 | AP25: ='FS Sayan Feb 2020'!BJ31 -> 0 | AQ25: ='FS Sayan Feb 2020'!BA31 -> 0 | AR25: ='FS Sayan Feb 2020'!BB31 -> 0 | AS25: ='FS Sayan Feb 2020'!BK31 -> 0 | AT25: ='FS Sayan Feb 2020'!BL31 -> 0 | AU25: ='FS Sayan Feb 2020'!BM31 -> 0 | AV25: ='FS Sayan Feb 2020'!BN31 -> 0 | AW25: ='FS Sayan Feb 2020'!E31 -> 10.3 | AX25: ='FS Sayan Feb 2020'!F31 -> 0 | AY25: ='FS Sayan Feb 2020'!M31 -> 4.9 | AZ25: ='FS Sayan Feb 2020'!P31 -> 0 | BA25: 0 | BB25: ='FS Sayan Feb 2020'!V45 -> 0 | BC25: ='FS Sayan Feb 2020'!AG31 -> 495 | BD25: ='FS Sayan Feb 2020'!AH31 -> 0 | BE25: ='FS Sayan Feb 2020'!AI31 -> 0 | BF25: ='FS Sayan Feb 2020'!AJ31 -> 0 | BG25: ='FS Sayan Feb 2020'!AK31 -> 0 | BH25: ='FS Sayan Feb 2020'!AL31 -> 0 | BI25: ='FS Sayan Feb 2020'!AM31 -> 0 | BJ25: ='FS Sayan Feb 2020'!AM31 -> 0 | BK25: ='FS Sayan Feb 2020'!AO31 -> 0 | BL25: ='FS Sayan Feb 2020'!AP31 -> 0 | BM25: 0 | BN25: 0 | BO25: ='FS Sayan Feb 2020'!Q31 -> 0 | BP25: ='FS Sayan Feb 2020'!R31 -> 0
A26: Bali Sayan | B26: =B25+1 -> 25 | C26: 2 | D26: 2020 | E26: ='FS Sayan Feb 2020'!M32 -> 4.1 | F26: ='FS Sayan Feb 2020'!N32 -> 0 | G26: ='FS Sayan Feb 2020'!G32 -> 0 | H26: ='FS Sayan Feb 2020'!H32 -> 0 | I26: ='FS Sayan Feb 2020'!I32 -> 0 | J26: ='FS Sayan Feb 2020'!J32 -> 0 | K26: ='FS Sayan Feb 2020'!K32 -> 12.8 | L26: ='FS Sayan Feb 2020'!L32 -> 0 | M26: ='FS Sayan Feb 2020'!S32 -> 0 | N26: ='FS Sayan Feb 2020'!T32 -> 0 | O26: ='FS Sayan Feb 2020'!U32 -> 3 | P26: ='FS Sayan Feb 2020'!V32 -> 0 | Q26: ='FS Sayan Feb 2020'!BC32 -> 0 | R26: ='FS Sayan Feb 2020'!BD32 -> 0 | S26: ='FS Sayan Feb 2020'!BF32 -> 0 | T26: ='FS Sayan Feb 2020'!BF32 -> 0 | U26: ='FS Sayan Feb 2020'!BG32 -> 0 | V26: ='FS Sayan Feb 2020'!BH32 -> 0 | W26: ='FS Sayan Feb 2020'!W32 -> 117 | X26: ='FS Sayan Feb 2020'!X32 -> 0 | Y26: ='FS Sayan Feb 2020'!Y32 -> 0 | Z26: ='FS Sayan Feb 2020'!Z32 -> 0 | AA26: ='FS Sayan Feb 2020'!AA32 -> 0 | AB26: ='FS Sayan Feb 2020'!AB32 -> 0 | AC26: ='FS Sayan Feb 2020'!AC32 -> 0 | AD26: ='FS Sayan Feb 2020'!AD32 -> 0 | ... AF26: ='FS Sayan Feb 2020'!AF32 -> 0 | AG26: ='FS Sayan Feb 2020'!AK32 -> 0 | AH26: ='FS Sayan Feb 2020'!AP32 -> 0 | AI26: ='FS Sayan Feb 2020'!AO32 -> 0 | AJ26: ='FS Sayan Feb 2020'!AP32 -> 0 | AK26: ='FS Sayan Feb 2020'!AW32 -> 0 | AL26: ='FS Sayan Feb 2020'!AX32 -> 0 | AM26: ='FS Sayan Feb 2020'!AZ32 -> 0 | AN26: ='FS Sayan Feb 2020'!AZ32 -> 0 | AO26: ='FS Sayan Feb 2020'!BI32 -> 0 | AP26: ='FS Sayan Feb 2020'!BJ32 -> 0 | AQ26: ='FS Sayan Feb 2020'!BA32 -> 0 | AR26: ='FS Sayan Feb 2020'!BB32 -> 0 | AS26: ='FS Sayan Feb 2020'!BK32 -> 0 | AT26: ='FS Sayan Feb 2020'!BL32 -> 0 | AU26: ='FS Sayan Feb 2020'!BM32 -> 0 | AV26: ='FS Sayan Feb 2020'!BN32 -> 0 | AW26: ='FS Sayan Feb 2020'!E32 -> 10.7 | AX26: ='FS Sayan Feb 2020'!F32 -> 0 | AY26: ='FS Sayan Feb 2020'!M32 -> 4.1 | AZ26: ='FS Sayan Feb 2020'!P32 -> 0 | BA26: 0 | BB26: ='FS Sayan Feb 2020'!V46 -> 0 | BC26: ='FS Sayan Feb 2020'!AG32 -> 500 | BD26: ='FS Sayan Feb 2020'!AH32 -> 0 | BE26: ='FS Sayan Feb 2020'!AI32 -> 0 | BF26: ='FS Sayan Feb 2020'!AJ32 -> 0 | BG26: ='FS Sayan Feb 2020'!AK32 -> 0 | BH26: ='FS Sayan Feb 2020'!AL32 -> 0 | BI26: ='FS Sayan Feb 2020'!AM32 -> 0 | BJ26: ='FS Sayan Feb 2020'!AM32 -> 0 | BK26: ='FS Sayan Feb 2020'!AO32 -> 0 | BL26: ='FS Sayan Feb 2020'!AP32 -> 0 | BM26: 0 | BN26: 0 | BO26: ='FS Sayan Feb 2020'!Q32 -> 0 | BP26: ='FS Sayan Feb 2020'!R32 -> 0
A27: Bali Sayan | B27: =B26+1 -> 26 | C27: 2 | D27: 2020 | E27: ='FS Sayan Feb 2020'!M33 -> 3.4 | F27: ='FS Sayan Feb 2020'!N33 -> 0 | G27: ='FS Sayan Feb 2020'!G33 -> 0 | H27: ='FS Sayan Feb 2020'!H33 -> 0 | I27: ='FS Sayan Feb 2020'!I33 -> 0 | J27: ='FS Sayan Feb 2020'!J33 -> 0 | K27: ='FS Sayan Feb 2020'!K33 -> 9.5 | L27: ='FS Sayan Feb 2020'!L33 -> 0 | M27: ='FS Sayan Feb 2020'!S33 -> 0 | N27: ='FS Sayan Feb 2020'!T33 -> 0 | O27: ='FS Sayan Feb 2020'!U33 -> 3.2 | P27: ='FS Sayan Feb 2020'!V33 -> 0 | Q27: ='FS Sayan Feb 2020'!BC33 -> 0 | R27: ='FS Sayan Feb 2020'!BD33 -> 0 | S27: ='FS Sayan Feb 2020'!BF33 -> 0 | T27: ='FS Sayan Feb 2020'!BF33 -> 0 | U27: ='FS Sayan Feb 2020'!BG33 -> 0 | V27: ='FS Sayan Feb 2020'!BH33 -> 0 | W27: ='FS Sayan Feb 2020'!W33 -> 126 | X27: ='FS Sayan Feb 2020'!X33 -> 0 | Y27: ='FS Sayan Feb 2020'!Y33 -> 0 | Z27: ='FS Sayan Feb 2020'!Z33 -> 0 | AA27: ='FS Sayan Feb 2020'!AA33 -> 0 | AB27: ='FS Sayan Feb 2020'!AB33 -> 0 | AC27: ='FS Sayan Feb 2020'!AC33 -> 0 | AD27: ='FS Sayan Feb 2020'!AD33 -> 0 | ... AF27: ='FS Sayan Feb 2020'!AF33 -> 0 | AG27: ='FS Sayan Feb 2020'!AK33 -> 0 | AH27: ='FS Sayan Feb 2020'!AP33 -> 0 | AI27: ='FS Sayan Feb 2020'!AO33 -> 0 | AJ27: ='FS Sayan Feb 2020'!AP33 -> 0 | AK27: ='FS Sayan Feb 2020'!AW33 -> 0 | AL27: ='FS Sayan Feb 2020'!AX33 -> 0 | AM27: ='FS Sayan Feb 2020'!AZ33 -> 0 | AN27: ='FS Sayan Feb 2020'!AZ33 -> 0 | AO27: ='FS Sayan Feb 2020'!BI33 -> 0 | AP27: ='FS Sayan Feb 2020'!BJ33 -> 0 | AQ27: ='FS Sayan Feb 2020'!BA33 -> 0 | AR27: ='FS Sayan Feb 2020'!BB33 -> 0 | AS27: ='FS Sayan Feb 2020'!BK33 -> 0 | AT27: ='FS Sayan Feb 2020'!BL33 -> 0 | AU27: ='FS Sayan Feb 2020'!BM33 -> 0 | AV27: ='FS Sayan Feb 2020'!BN33 -> 0 | AW27: ='FS Sayan Feb 2020'!E33 -> 9 | AX27: ='FS Sayan Feb 2020'!F33 -> 0 | AY27: ='FS Sayan Feb 2020'!M33 -> 3.4 | AZ27: ='FS Sayan Feb 2020'!P33 -> 0 | BA27: 0 | BB27: ='FS Sayan Feb 2020'!V47 -> 0 | BC27: ='FS Sayan Feb 2020'!AG33 -> 385 | BD27: ='FS Sayan Feb 2020'!AH33 -> 0 | BE27: ='FS Sayan Feb 2020'!AI33 -> 0 | BF27: ='FS Sayan Feb 2020'!AJ33 -> 0 | BG27: ='FS Sayan Feb 2020'!AK33 -> 0 | BH27: ='FS Sayan Feb 2020'!AL33 -> 0 | BI27: ='FS Sayan Feb 2020'!AM33 -> 0 | BJ27: ='FS Sayan Feb 2020'!AM33 -> 0 | BK27: ='FS Sayan Feb 2020'!AO33 -> 0 | BL27: ='FS Sayan Feb 2020'!AP33 -> 0 | BM27: 0 | BN27: 0 | BO27: ='FS Sayan Feb 2020'!Q33 -> 0 | BP27: ='FS Sayan Feb 2020'!R33 -> 0
A28: Bali Sayan | B28: =B27+1 -> 27 | C28: 2 | D28: 2020 | E28: ='FS Sayan Feb 2020'!M34 -> 5.1 | F28: ='FS Sayan Feb 2020'!N34 -> 0 | G28: ='FS Sayan Feb 2020'!G34 -> 0 | H28: ='FS Sayan Feb 2020'!H34 -> 0 | I28: ='FS Sayan Feb 2020'!I34 -> 0 | J28: ='FS Sayan Feb 2020'!J34 -> 0 | K28: ='FS Sayan Feb 2020'!K34 -> 9.9 | L28: ='FS Sayan Feb 2020'!L34 -> 0 | M28: ='FS Sayan Feb 2020'!S34 -> 0 | N28: ='FS Sayan Feb 2020'!T34 -> 0 | O28: ='FS Sayan Feb 2020'!U34 -> 3.4 | P28: ='FS Sayan Feb 2020'!V34 -> 0 | Q28: ='FS Sayan Feb 2020'!BC34 -> 0 | R28: ='FS Sayan Feb 2020'!BD34 -> 0 | S28: ='FS Sayan Feb 2020'!BF34 -> 0 | T28: ='FS Sayan Feb 2020'!BF34 -> 0 | U28: ='FS Sayan Feb 2020'!BG34 -> 0 | V28: ='FS Sayan Feb 2020'!BH34 -> 0 | W28: ='FS Sayan Feb 2020'!W34 -> 108 | X28: ='FS Sayan Feb 2020'!X34 -> 0 | Y28: ='FS Sayan Feb 2020'!Y34 -> 0 | Z28: ='FS Sayan Feb 2020'!Z34 -> 0 | AA28: ='FS Sayan Feb 2020'!AA34 -> 0 | AB28: ='FS Sayan Feb 2020'!AB34 -> 0 | AC28: ='FS Sayan Feb 2020'!AC34 -> 0 | AD28: ='FS Sayan Feb 2020'!AD34 -> 0 | ... AF28: ='FS Sayan Feb 2020'!AF34 -> 0 | AG28: ='FS Sayan Feb 2020'!AK34 -> 0 | AH28: ='FS Sayan Feb 2020'!AP34 -> 0 | AI28: ='FS Sayan Feb 2020'!AO34 -> 0 | AJ28: ='FS Sayan Feb 2020'!AP34 -> 0 | AK28: ='FS Sayan Feb 2020'!AW34 -> 0 | AL28: ='FS Sayan Feb 2020'!AX34 -> 0 | AM28: ='FS Sayan Feb 2020'!AZ34 -> 0 | AN28: ='FS Sayan Feb 2020'!AZ34 -> 0 | AO28: ='FS Sayan Feb 2020'!BI34 -> 0 | AP28: ='FS Sayan Feb 2020'!BJ34 -> 0 | AQ28: ='FS Sayan Feb 2020'!BA34 -> 0 | AR28: ='FS Sayan Feb 2020'!BB34 -> 0 | AS28: ='FS Sayan Feb 2020'!BK34 -> 0 | AT28: ='FS Sayan Feb 2020'!BL34 -> 0 | AU28: ='FS Sayan Feb 2020'!BM34 -> 0 | AV28: ='FS Sayan Feb 2020'!BN34 -> 0 | AW28: ='FS Sayan Feb 2020'!E34 -> 10.1 | AX28: ='FS Sayan Feb 2020'!F34 -> 0 | AY28: ='FS Sayan Feb 2020'!M34 -> 5.1 | AZ28: ='FS Sayan Feb 2020'!P34 -> 0 | BA28: 0 | BB28: ='FS Sayan Feb 2020'!V48 -> 0 | BC28: ='FS Sayan Feb 2020'!AG34 -> 390 | BD28: ='FS Sayan Feb 2020'!AH34 -> 0 | BE28: ='FS Sayan Feb 2020'!AI34 -> 0 | BF28: ='FS Sayan Feb 2020'!AJ34 -> 0 | BG28: ='FS Sayan Feb 2020'!AK34 -> 0 | BH28: ='FS Sayan Feb 2020'!AL34 -> 0 | BI28: ='FS Sayan Feb 2020'!AM34 -> 0 | BJ28: ='FS Sayan Feb 2020'!AM34 -> 0 | BK28: ='FS Sayan Feb 2020'!AO34 -> 0 | BL28: ='FS Sayan Feb 2020'!AP34 -> 0 | BM28: 0 | BN28: 0 | BO28: ='FS Sayan Feb 2020'!Q34 -> 0 | BP28: ='FS Sayan Feb 2020'!R34 -> 0
A29: Bali Sayan | B29: =B28+1 -> 28 | C29: 2 | D29: 2020 | E29: ='FS Sayan Feb 2020'!M35 -> 3.9 | F29: ='FS Sayan Feb 2020'!N35 -> 0 | G29: ='FS Sayan Feb 2020'!G35 -> 0 | H29: ='FS Sayan Feb 2020'!H35 -> 0 | I29: ='FS Sayan Feb 2020'!I35 -> 0 | J29: ='FS Sayan Feb 2020'!J35 -> 0 | K29: ='FS Sayan Feb 2020'!K35 -> 11.6 | L29: ='FS Sayan Feb 2020'!L35 -> 0 | M29: ='FS Sayan Feb 2020'!S35 -> 0 | N29: ='FS Sayan Feb 2020'!T35 -> 0 | O29: ='FS Sayan Feb 2020'!U35 -> 2.8 | P29: ='FS Sayan Feb 2020'!V35 -> 0 | Q29: ='FS Sayan Feb 2020'!BC35 -> 0 | R29: ='FS Sayan Feb 2020'!BD35 -> 0 | S29: ='FS Sayan Feb 2020'!BF35 -> 0 | T29: ='FS Sayan Feb 2020'!BF35 -> 0 | U29: ='FS Sayan Feb 2020'!BG35 -> 0 | V29: ='FS Sayan Feb 2020'!BH35 -> 0 | W29: ='FS Sayan Feb 2020'!W35 -> 117 | X29: ='FS Sayan Feb 2020'!X35 -> 0 | Y29: ='FS Sayan Feb 2020'!Y35 -> 0 | Z29: ='FS Sayan Feb 2020'!Z35 -> 0 | AA29: ='FS Sayan Feb 2020'!AA35 -> 0 | AB29: ='FS Sayan Feb 2020'!AB35 -> 0 | AC29: ='FS Sayan Feb 2020'!AC35 -> 0 | AD29: ='FS Sayan Feb 2020'!AD35 -> 0 | ... AF29: ='FS Sayan Feb 2020'!AF35 -> 0 | AG29: ='FS Sayan Feb 2020'!AK35 -> 0 | AH29: ='FS Sayan Feb 2020'!AP35 -> 0 | AI29: ='FS Sayan Feb 2020'!AO35 -> 0 | AJ29: ='FS Sayan Feb 2020'!AP35 -> 0 | AK29: ='FS Sayan Feb 2020'!AW35 -> 0 | AL29: ='FS Sayan Feb 2020'!AX35 -> 0 | AM29: ='FS Sayan Feb 2020'!AZ35 -> 0 | AN29: ='FS Sayan Feb 2020'!AZ35 -> 0 | AO29: ='FS Sayan Feb 2020'!BI35 -> 0 | AP29: ='FS Sayan Feb 2020'!BJ35 -> 0 | AQ29: ='FS Sayan Feb 2020'!BA35 -> 0 | AR29: ='FS Sayan Feb 2020'!BB35 -> 0 | AS29: ='FS Sayan Feb 2020'!BK35 -> 0 | AT29: ='FS Sayan Feb 2020'!BL35 -> 0 | AU29: ='FS Sayan Feb 2020'!BM35 -> 0 | AV29: ='FS Sayan Feb 2020'!BN35 -> 0 | AW29: ='FS Sayan Feb 2020'!E35 -> 8 | AX29: ='FS Sayan Feb 2020'!F35 -> 0 | AY29: ='FS Sayan Feb 2020'!M35 -> 3.9 | AZ29: ='FS Sayan Feb 2020'!P35 -> 0 | BA29: 0 | BB29: ='FS Sayan Feb 2020'!V49 -> 0 | BC29: ='FS Sayan Feb 2020'!AG35 -> 415 | BD29: ='FS Sayan Feb 2020'!AH35 -> 0 | BE29: ='FS Sayan Feb 2020'!AI35 -> 0 | BF29: ='FS Sayan Feb 2020'!AJ35 -> 0 | BG29: ='FS Sayan Feb 2020'!AK35 -> 0 | BH29: ='FS Sayan Feb 2020'!AL35 -> 0 | BI29: ='FS Sayan Feb 2020'!AM35 -> 0 | BJ29: ='FS Sayan Feb 2020'!AM35 -> 0 | BK29: ='FS Sayan Feb 2020'!AO35 -> 0 | BL29: ='FS Sayan Feb 2020'!AP35 -> 0 | BM29: 0 | BN29: 0 | BO29: ='FS Sayan Feb 2020'!Q35 -> 0 | BP29: ='FS Sayan Feb 2020'!R35 -> 0
A30: Bali Sayan | B30: =B29+1 -> 29 | C30: 2 | D30: 2020 | E30: ='FS Sayan Feb 2020'!M36 -> 5.8 | K30: ='FS Sayan Feb 2020'!K36 -> 10 | O30: ='FS Sayan Feb 2020'!U36 -> 4.6 | W30: ='FS Sayan Feb 2020'!W36 -> 126 | AW30: ='FS Sayan Feb 2020'!E36 -> 10.1 | AY30: ='FS Sayan Feb 2020'!M36 -> 5.8 | BB30: ='FS Sayan Feb 2020'!V50 -> 0 | BC30: ='FS Sayan Feb 2020'!AG36 -> 410
E31: =SUM(E2:E30) -> 120.1 | F31: =SUM(F2:F30) -> 0 | G31: =SUM(G2:G30) -> 0 | H31: =SUM(H2:H30) -> 0 | I31: =SUM(I2:I30) -> 0 | J31: =SUM(J2:J30) -> 0 | K31: ='FS Sayan Feb 2020'!K37 -> 302.7 | L31: =SUM(L2:L30) -> 0 | M31: =SUM(M2:M30) -> 0 | N31: =SUM(N2:N30) -> 0 | O31: ='FS Sayan Feb 2020'!U37 -> 94.4 | P31: =SUM(P2:P30) -> 0 | Q31: =SUM(Q2:Q30) -> 0 | R31: =SUM(R2:R30) -> 0 | S31: =SUM(S2:S30) -> 0 | T31: =SUM(T2:T30) -> 0 | U31: =SUM(U2:U30) -> 0 | V31: =SUM(V2:V30) -> 0 | W31: =SUM(W2:W30) -> 3577.5 | ... BB31: =SUM(BB2:BB30) -> 0 | BC31: ='FS Sayan Feb 2020'!AG37 -> 13500 | BD31: =SUM(BD2:BD30) -> 0 | BE31: =SUM(BE2:BE30) -> 0 | BF31: =SUM(BF2:BF30) -> 0 | BG31: =SUM(BG2:BG30) -> 0 | BH31: =SUM(BH2:BH30) -> 0 | BI31: =SUM(BI2:BI30) -> 0 | BJ31: =SUM(BJ2:BJ30) -> 0 | BK31: =SUM(BK2:BK30) -> 0 | ... BP31: =SUM(BP2:BP30) -> 0

Sheet FS Sayan Feb 2020
B2: Four Seasons Resort Bali at Sayan
B3: Feb 2020
B4: Date | C4: Room Nights | D4: Food Covers | E4: Paper Waste | K4: Glass Waste | M4: Metal Waste | U4: Plastic Waste | W4: Organic Waste | AK4: Hazardous Waste | BC4: Recycleable
E6: Total (per Unit) paper cardboard | F6: Total cost paper cardboard | G6: Total (per Unit) cardboard | H6: Total cost cardboard | I6: Total (per Unit) paper | J6: Total cost paper | K6: Total (per Unit) mixed glass | L6: Total cost mixed glass | M6: Total (per Unit) bottles cans | N6: Total cost bottles cans | O6: Total (per Unit) mixed metals | P6: Total cost mixed metals | Q6: Total (per Unit) tin | R6: Total cost tin | S6: Total (per Unit) aluminum | T6: Total cost aluminum | U6: Total (per Unit) other plastics | V6: Total cost plastics | W6: Total (per Unit) solid food waste | X6: Total cost solid food waste | Y6: Total (per Unit) leftover food | Z6: Total cost leftover food | AA6: Total (per Unit) inedible parts | AB6: Total cost inedible parts | AC6: Total (per Unit) liquid food waste | AD6: Total cost liquid food waste | AE6: Total (per Unit) kitchen grease | AF6: Total cost kitchen grease | AG6: Total (per Unit) biodegradable | AH6: Total cost biodegradable | AI6: Total (per Unit) food waste | AJ6: Total cost food waste | AK6: Total (per Unit) hazardous waste | AL6: Total cost hazardous waste | AM6: Total (per Unit) universal waste | AN6: Total cost universal waste | AO6: Total (per Unit) hazardous and universal waste | AP6: Total cost hazardous and universal waste | AQ6: Total (per Unit) medical waste | AR6: Total cost medical waste | AS6: Total (per Unit) liquid hazardous waste | AT6: Total cost liquid hazardous waste | AU6: Total (per Unit) other hazardous waste | AV6: Total cost other hazardous waste | AW6: Total (per Unit) batteries | AX6: Total cost batteries | AY6: Total (per Unit) light bulbs | AZ6: Total cost light bulbs | BA6: Total (per Unit) paint | BB6: Total cost paint | BC6: Total (per Unit) soap bars | BD6: Total cost soap bars | BE6: Total (per Unit) e waste | BF6: Total cost e waste | BG6: Total (per Unit) durable goods | BH6: Total cost durable goods | BI6: Total (per Unit) textiles | BJ6: Total cost textiles | BK6: Total (per Unit) recyclable | BL6: Total cost recyclable | BM6: Total (per Unit) commingled recyclables | BN6: Total cost commingled recyclables
