Workbook

Sheet TOTAL
A1: Site Name | B1: Day | C1: Month | D1: Year | E1: Total Electricity Kwh | F1: Electricity Tariff ($/Kwh) | G1: LPG (Kg) | H1: LPG $/Kg | I1: Water Utility Supply (m3) m3 | J1: Water Utility Supply (m3) $/m3 | K1: Room Nights | L1: Total Guests | M1: Utilities day cost dh
A2: Casablanca | B2: 1 | C2: 7 | D2: 2019 | E2: =submetering!E2+submetering!F2+submetering!G2 -> 17195 | F2: 1.05 | G2: ='Consommation mensuel énergie'!V10 -> 543.98657 | H2: 7.8 | I2: ='Consommation mensuel énergie'!F10 -> 319.8 | J2: 11.4 | K2: ='Consommation mensuel énergie'!D10 -> 132 | L2: ='Consommation mensuel énergie'!E10 -> 193 | M2: =E2*F2+G2*H2+#REF!*#REF!+I2*J2 -> #REF!
A3: Casablanca | B3: =B2+1 -> 2 | C3: 7 | D3: 2019 | E3: =submetering!E3+submetering!F3+submetering!G3 -> 16097 | F3: 1.05 | G3: ='Consommation mensuel énergie'!V11 -> 255.99368 | H3: 7.8 | I3: ='Consommation mensuel énergie'!F11 -> 169.7 | J3: 11.4 | K3: ='Consommation mensuel énergie'!D11 -> 180 | L3: ='Consommation mensuel énergie'!E11 -> 259 | M3: =E3*F3+G3*H3+#REF!*#REF!+I3*J3 -> #REF!
A4: Casablanca | B4: =B3+1 -> 3 | C4: 7 | D4: 2019 | E4: =submetering!E4+submetering!F4+submetering!G4 -> 16302 | F4: 1.05 | G4: ='Consommation mensuel énergie'!V12 -> 575.98578 | H4: 7.8 | I4: ='Consommation mensuel énergie'!F12 -> 163.7 | J4: 11.4 | K4: ='Consommation mensuel énergie'!D12 -> 180 | L4: ='Consommation mensuel énergie'!E12 -> 266 | M4: =E4*F4+G4*H4+#REF!*#REF!+I4*J4 -> #REF!
A5: Casablanca | B5: =B4+1 -> 4 | C5: 7 | D5: 2019 | E5: =submetering!E5+submetering!F5+submetering!G5 -> 17073 | F5: 1.05 | G5: ='Consommation mensuel énergie'!V13 -> 287.99289 | H5: 7.8 | I5: ='Consommation mensuel énergie'!F13 -> 194.3 | J5: 11.4 | K5: ='Consommation mensuel énergie'!D13 -> 174 | L5: ='Consommation mensuel énergie'!E13 -> 263 | M5: =E5*F5+G5*H5+#REF!*#REF!+I5*J5 -> #REF!
A6: Casablanca | B6: =B5+1 -> 5 | C6: 7 | D6: 2019 | E6: =submetering!E6+submetering!F6+submetering!G6 -> 17849 | F6: 1.05 | G6: ='Consommation mensuel énergie'!V14 -> 351.99131 | H6: 7.8 | I6: ='Consommation mensuel énergie'!F14 -> 191.5 | J6: 11.4 | K6: ='Consommation mensuel énergie'!D14 -> 176 | L6: ='Consommation mensuel énergie'!E14 -> 279 | M6: =E6*F6+G6*H6+#REF!*#REF!+I6*J6 -> #REF!
A7: Casablanca | B7: =B6+1 -> 6 | C7: 7 | D7: 2019 | E7: =submetering!E7+submetering!F7+submetering!G7 -> 18544 | F7: 1.05 | G7: ='Consommation mensuel énergie'!V15 -> 287.99289 | H7: 7.8 | I7: ='Consommation mensuel énergie'!F15 -> 185.9 | J7: 11.4 | K7: ='Consommation mensuel énergie'!D15 -> 166 | L7: ='Consommation mensuel énergie'!E15 -> 282 | M7: =E7*F7+G7*H7+#REF!*#REF!+I7*J7 -> #REF!
A8: Casablanca | B8: =B7+1 -> 7 | C8: 7 | D8: 2019 | E8: =submetering!E8+submetering!F8+submetering!G8 -> 17788 | F8: 1.05 | G8: ='Consommation mensuel énergie'!V16 -> 415.98973 | H8: 7.8 | I8: ='Consommation mensuel énergie'!F16 -> 172.6 | J8: 11.4 | K8: ='Consommation mensuel énergie'!D16 -> 139 | L8: ='Consommation mensuel énergie'!E16 -> 224 | M8: =E8*F8+G8*H8+#REF!*#REF!+I8*J8 -> #REF!
A9: Casablanca | B9: =B8+1 -> 8 | C9: 7 | D9: 2019 | E9: =submetering!E9+submetering!F9+submetering!G9 -> 18200 | F9: 1.05 | G9: ='Consommation mensuel énergie'!V17 -> 415.98973 | H9: 7.8 | I9: ='Consommation mensuel énergie'!F17 -> 151.6 | J9: 11.4 | K9: ='Consommation mensuel énergie'!D17 -> 150 | L9: ='Consommation mensuel énergie'!E17 -> 231 | M9: =E9*F9+G9*H9+#REF!*#REF!+I9*J9 -> #REF!
A10: Casablanca | B10: =B9+1 -> 9 | C10: 7 | D10: 2019 | E10: =submetering!E10+submetering!F10+submetering!G10 -> 20034 | F10: 1.05 | G10: ='Consommation mensuel énergie'!V18 -> 319.9921 | H10: 7.8 | I10: ='Consommation mensuel énergie'!F18 -> 177.9 | J10: 11.4 | K10: ='Consommation mensuel énergie'!D18 -> 151 | L10: ='Consommation mensuel énergie'!E18 -> 249 | M10: =E10*F10+G10*H10+#REF!*#REF!+I10*J10 -> #REF!
A11: Casablanca | B11: =B10+1 -> 10 | C11: 7 | D11: 2019 | E11: =submetering!E11+submetering!F11+submetering!G11 -> 18766 | F11: 1.05 | G11: ='Consommation mensuel énergie'!V19 -> 447.98894 | H11: 7.8 | I11: ='Consommation mensuel énergie'!F19 -> 192 | J11: 11.4 | K11: ='Consommation mensuel énergie'!D19 -> 131 | L11: ='Consommation mensuel énergie'!E19 -> 240 | M11: =E11*F11+G11*H11+#REF!*#REF!+I11*J11 -> #REF!
A12: Casablanca | B12: =B11+1 -> 11 | C12: 7 | D12: 2019 | E12: =submetering!E12+submetering!F12+submetering!G12 -> 18013 | F12: 1.05 | G12: ='Consommation mensuel énergie'!V20 -> 223.99447 | H12: 7.8 | I12: ='Consommation mensuel énergie'!F20 -> 187 | J12: 11.4 | K12: ='Consommation mensuel énergie'!D20 -> 141 | L12: ='Consommation mensuel énergie'!E20 -> 239 | M12: =E12*F12+G12*H12+#REF!*#REF!+I12*J12 -> #REF!
A13: Casablanca | B13: =B12+1 -> 12 | C13: 7 | D13: 2019 | E13: =submetering!E13+submetering!F13+submetering!G13 -> 19076 | F13: 1.05 | G13: ='Consommation mensuel énergie'!V21 -> 639.9842 | H13: 7.8 | I13: ='Consommation mensuel énergie'!F21 -> 182 | J13: 11.4 | K13: ='Consommation mensuel énergie'!D21 -> 157 | L13: ='Consommation mensuel énergie'!E21 -> 271 | M13: =E13*F13+G13*H13+#REF!*#REF!+I13*J13 -> #REF!
A14: Casablanca | B14: =B13+1 -> 13 | C14: 7 | D14: 2019 | E14: =submetering!E14+submetering!F14+submetering!G14 -> 19622 | F14: 1.05 | G14: ='Consommation mensuel énergie'!V22 -> 447.98894 | H14: 7.8 | I14: ='Consommation mensuel énergie'!F22 -> 187 | J14: 11.4 | K14: ='Consommation mensuel énergie'!D22 -> 129 | L14: ='Consommation mensuel énergie'!E22 -> 246 | M14: =E14*F14+G14*H14+#REF!*#REF!+I14*J14 -> #REF!
... A30: Casablanca | B30: =B29+1 -> 29 | C30: 7 | D30: 2019 | E30: =submetering!E30+submetering!F30+submetering!G30 -> 17099 | F30: 1.05 | G30: ='Consommation mensuel énergie'!V38 -> 415.98973 | H30: 7.8 | I30: ='Consommation mensuel énergie'!F38 -> 140 | J30: 11.4 | K30: ='Consommation mensuel énergie'!D38 -> 144 | L30: ='Consommation mensuel énergie'!E38 -> 252 | M30: =E30*F30+G30*H30+#REF!*#REF!+I30*J30 -> #REF!
A31: Casablanca | B31: =B30+1 -> 30 | C31: 7 | D31: 2019 | E31: =submetering!E31+submetering!F31+submetering!G31 -> 18690 | F31: 1.05 | G31: ='Consommation mensuel énergie'!V39 -> 223.99447 | H31: 7.8 | I31: ='Consommation mensuel énergie'!F39 -> 184.8 | J31: 11.4 | K31: ='Consommation mensuel énergie'!D39 -> 148 | L31: ='Consommation mensuel énergie'!E39 -> 247
A32: Casablanca | B32: =B31+1 -> 31 | C32: 7 | D32: 2019 | E32: =submetering!E32+submetering!F32+submetering!G32 -> 18622 | F32: 1.05 | G32: ='Consommation mensuel énergie'!V40 -> 287.99289 | H32: 7.8 | I32: ='Consommation mensuel énergie'!F40 -> 161 | J32: 11.4 | K32: ='Consommation mensuel énergie'!D40 -> 146 | L32: ='Consommation mensuel énergie'!E40 -> 261 | M32: =E32*F32+G32*H32+#REF!*#REF!+I32*J32 -> #REF!

Sheet submetering
A1: Site Name | B1: Day | C1: Month | D1: Year | E1: Creuse 81 - KWh | F1: Pleine 82-KWh | G1: Pointe 83 - KWh | H1: Room Nights | I1: Total Guests | J1: Utilities day cost dh
A2: Casablanca | B2: 1 | C2: 7 | D2: 2019 | E2: ='Consommation mensuel énergie'!L10 -> 4753 | F2: ='Consommation mensuel énergie'!M10 -> 9058 | G2: ='Consommation mensuel énergie'!N10 -> 3384 | H2: ='Consommation mensuel énergie'!D10 -> 132 | I2: ='Consommation mensuel énergie'!E10 -> 193 | J2: =E2*F2+G2*#REF!+#REF!*#REF!+#REF!*#REF! -> #REF!
A3: Casablanca | B3: =B2+1 -> 2 | C3: 7 | D3: 2019 | E3: ='Consommation mensuel énergie'!L11 -> 4280 | F3: ='Consommation mensuel énergie'!M11 -> 8622 | G3: ='Consommation mensuel énergie'!N11 -> 3195 | H3: ='Consommation mensuel énergie'!D11 -> 180 | I3: ='Consommation mensuel énergie'!E11 -> 259 | J3: =E3*F3+G3*#REF!+#REF!*#REF!+#REF!*#REF! -> #REF!
A4: Casablanca | B4: =B3+1 -> 3 | C4: 7 | D4: 2019 | E4: ='Consommation mensuel énergie'!L12 -> 4213 | F4: ='Consommation mensuel énergie'!M12 -> 8656 | G4: ='Consommation mensuel énergie'!N12 -> 3433 | H4: ='Consommation mensuel énergie'!D12 -> 180 | I4: ='Consommation mensuel énergie'!E12 -> 266 | J4: =E4*F4+G4*#REF!+#REF!*#REF!+#REF!*#REF! -> #REF!
A5: Casablanca | B5: =B4+1 -> 4 | C5: 7 | D5: 2019 | E5: ='Consommation mensuel énergie'!L13 -> 3743 | F5: ='Consommation mensuel énergie'!M13 -> 9721 | G5: ='Consommation mensuel énergie'!N13 -> 3609 | H5: ='Consommation mensuel énergie'!D13 -> 174 | I5: ='Consommation mensuel énergie'!E13 -> 263 | J5: =E5*F5+G5*#REF!+#REF!*#REF!+#REF!*#REF! -> #REF!
A6: Casablanca | B6: =B5+1 -> 5 | C6: 7 | D6: 2019 | E6: ='Consommation mensuel énergie'!L14 -> 5010 | F6: ='Consommation mensuel énergie'!M14 -> 9305 | G6: ='Consommation mensuel énergie'!N14 -> 3534 | H6: ='Consommation mensuel énergie'!D14 -> 176 | I6: ='Consommation mensuel énergie'!E14 -> 279 | J6: =E6*F6+G6*#REF!+#REF!*#REF!+#REF!*#REF! -> #REF!
A7: Casablanca | B7: =B6+1 -> 6 | C7: 7 | D7: 2019 | E7: ='Consommation mensuel énergie'!L15 -> 4704 | F7: ='Consommation mensuel énergie'!M15 -> 10133 | G7: ='Consommation mensuel énergie'!N15 -> 3707 | H7: ='Consommation mensuel énergie'!D15 -> 166 | I7: ='Consommation mensuel énergie'!E15 -> 282 | J7: =E7*F7+G7*#REF!+#REF!*#REF!+#REF!*#REF! -> #REF!
A8: Casablanca | B8: =B7+1 -> 7 | C8: 7 | D8: 2019 | E8: ='Consommation mensuel énergie'!L16 -> 3989 | F8: ='Consommation mensuel énergie'!M16 -> 10438 | G8: ='Consommation mensuel énergie'!N16 -> 3361 | H8: ='Consommation mensuel énergie'!D16 -> 139 | I8: ='Consommation mensuel énergie'!E16 -> 224 | J8: =E8*F8+G8*#REF!+#REF!*#REF!+#REF!*#REF! -> #REF!
A9: Casablanca | B9: =B8+1 -> 8 | C9: 7 | D9: 2019 | E9: ='Consommation mensuel énergie'!L17 -> 4414 | F9: ='Consommation mensuel énergie'!M17 -> 10165 | G9: ='Consommation mensuel énergie'!N17 -> 3621 | H9: ='Consommation mensuel énergie'!D17 -> 150 | I9: ='Consommation mensuel énergie'!E17 -> 231 | J9: =E9*F9+G9*#REF!+#REF!*#REF!+#REF!*#REF! -> #REF!
A10: Casablanca | B10: =B9+1 -> 9 | C10: 7 | D10: 2019 | E10: ='Consommation mensuel énergie'!L18 -> 5812 | F10: ='Consommation mensuel énergie'!M18 -> 10373 | G10: ='Consommation mensuel énergie'!N18 -> 3849 | H10: ='Consommation mensuel énergie'!D18 -> 151 | I10: ='Consommation mensuel énergie'!E18 -> 249 | J10: =E10*F10+G10*#REF!+#REF!*#REF!+#REF!*#REF! -> #REF!
A11: Casablanca | B11: =B10+1 -> 10 | C11: 7 | D11: 2019 | E11: ='Consommation mensuel énergie'!L19 -> 4903 | F11: ='Consommation mensuel énergie'!M19 -> 10097 | G11: ='Consommation mensuel énergie'!N19 -> 3766 | H11: ='Consommation mensuel énergie'!D19 -> 131 | I11: ='Consommation mensuel énergie'!E19 -> 240 | J11: =E11*F11+G11*#REF!+#REF!*#REF!+#REF!*#REF! -> #REF!
A12: Casablanca | B12: =B11+1 -> 11 | C12: 7 | D12: 2019 | E12: ='Consommation mensuel énergie'!L20 -> 4784 | F12: ='Consommation mensuel énergie'!M20 -> 9346 | G12: ='Consommation mensuel énergie'!N20 -> 3883 | H12: ='Consommation mensuel énergie'!D20 -> 141 | I12: ='Consommation mensuel énergie'!E20 -> 239 | J12: =E12*F12+G12*#REF!+#REF!*#REF!+#REF!*#REF! -> #REF!
A13: Casablanca | B13: =B12+1 -> 12 | C13: 7 | D13: 2019 | E13: ='Consommation mensuel énergie'!L21 -> 5221 | F13: ='Consommation mensuel énergie'!M21 -> 10100 | G13: ='Consommation mensuel énergie'!N21 -> 3755 | H13: ='Consommation mensuel énergie'!D21 -> 157 | I13: ='Consommation mensuel énergie'!E21 -> 271 | J13: =E13*F13+G13*#REF!+#REF!*#REF!+#REF!*#REF! -> #REF!
A14: Casablanca | B14: =B13+1 -> 13 | C14: 7 | D14: 2019 | E14: ='Consommation mensuel énergie'!L22 -> 5512 | F14: ='Consommation mensuel énergie'!M22 -> 10235 | G14: ='Consommation mensuel énergie'!N22 -> 3875 | H14: ='Consommation mensuel énergie'!D22 -> 129 | I14: ='Consommation mensuel énergie'!E22 -> 246 | J14: =E14*F14+G14*#REF!+#REF!*#REF!+#REF!*#REF! -> #REF!
... A30: Casablanca | B30: =B29+1 -> 29 | C30: 7 | D30: 2019 | E30: ='Consommation mensuel énergie'!L38 -> 4563 | F30: ='Consommation mensuel énergie'!M38 -> 9132 | G30: ='Consommation mensuel énergie'!N38 -> 3404 | H30: ='Consommation mensuel énergie'!D38 -> 144 | I30: ='Consommation mensuel énergie'!E38 -> 252 | J30: =E30*F30+G30*#REF!+#REF!*#REF!+#REF!*#REF! -> #REF!
A31: Casablanca | B31: =B30+1 -> 30 | C31: 7 | D31: 2019 | E31: ='Consommation mensuel énergie'!L39 -> 5815 | F31: ='Consommation mensuel énergie'!M39 -> 9234 | G31: ='Consommation mensuel énergie'!N39 -> 3641 | H31: ='Consommation mensuel énergie'!D39 -> 148 | I31: ='Consommation mensuel énergie'!E39 -> 247
A32: Casablanca | B32: =B31+1 -> 31 | C32: 7 | D32: 2019 | E32: ='Consommation mensuel énergie'!L40 -> 5044 | F32: ='Consommation mensuel énergie'!M40 -> 9803 | G32: ='Consommation mensuel énergie'!N40 -> 3775 | H32: ='Consommation mensuel énergie'!D40 -> 146 | I32: ='Consommation mensuel énergie'!E40 -> 261 | J32: =E32*F32+G32*#REF!+#REF!*#REF!+#REF!*#REF! -> #REF!

Sheet Consommation mensuel énergie
I2: Consommation mensuel Eau /électricité/Gaz
B8: Date | D8: ROOM Nights | E8: Guests | F8: Cons Eau/Hotel | H8: Consommation du jour en DH | K8: date / électr | L8: ELECTRICITE en KWH | O8: total | Q8: Consommation du jour en DH | S8: Cons Elec/Villa | U8: Cons Elec/RIAD | V8: GAZ en Kg | X8: Consommation du jour en DH
L9: creuse 81 | M9: pleine 82 | N9: pointe 83
B10: 43647 | D10: 132 | E10: 193 | F10: ='Suivi EAU-ELEC'!E9 -> 319.8 | H10: =F10*8.79 -> 2811.042 | K10: 42278 | L10: ='Suivi EAU-ELEC'!G9 -> 4753 | M10: ='Suivi EAU-ELEC'!I9 -> 9058 | N10: ='Suivi EAU-ELEC'!K9 -> 3384 | O10: =L10+M10+N10 -> 17195 | Q10: =L10*0.6985+M10*0.9514+N10*1.3304 -> 16439.825 | V10: ='Suvi Gaz'!O4 -> 543.98657 | X10: =V10*7.8 -> 4243.0952
B11: 43648 | D11: 180 | E11: 259 | F11: ='Suivi EAU-ELEC'!E10 -> 169.7 | H11: =F11*8.79 -> 1491.663 | K11: 42279 | L11: ='Suivi EAU-ELEC'!G10 -> 4280 | M11: ='Suivi EAU-ELEC'!I10 -> 8622 | N11: ='Suivi EAU-ELEC'!K10 -> 3195 | O11: =L11+M11+N11 -> 16097 | Q11: =L11*0.6985+M11*0.9514+N11*1.3304 -> 15443.179 | V11: ='Suvi Gaz'!O5 -> 255.99368 | X11: =V11*7.8 -> 1996.7507
B12: 43649 | D12: 180 | E12: 266 | F12: ='Suivi EAU-ELEC'!E11 -> 163.7 | H12: =F12*8.79 -> 1438.923 | K12: 42280 | L12: ='Suivi EAU-ELEC'!G11 -> 4213 | M12: ='Suivi EAU-ELEC'!I11 -> 8656 | N12: ='Suivi EAU-ELEC'!K11 -> 3433 | O12: =L12+M12+N12 -> 16302 | Q12: =L12*0.6985+M12*0.9514+N12*1.3304 -> 15745.362 | V12: ='Suvi Gaz'!O6 -> 575.98578 | X12: =V12*7.8 -> 4492.6891
B13: 43650 | D13: 174 | E13: 263 | F13: ='Suivi EAU-ELEC'!E12 -> 194.3 | H13: =F13*8.79 -> 1707.897 | K13: 42281 | L13: ='Suivi EAU-ELEC'!G12 -> 3743 | M13: ='Suivi EAU-ELEC'!I12 -> 9721 | N13: ='Suivi EAU-ELEC'!K12 -> 3609 | O13: =L13+M13+N13 -> 17073 | Q13: =L13*0.6985+M13*0.9514+N13*1.3304 -> 16664.459 | V13: ='Suvi Gaz'!O7 -> 287.99289 | X13: =V13*7.8 -> 2246.3445
B14: 43651 | D14: 176 | E14: 279 | F14: ='Suivi EAU-ELEC'!E13 -> 191.5 | H14: =F14*8.79 -> 1683.285 | K14: 42282 | L14: ='Suivi EAU-ELEC'!G13 -> 5010 | M14: ='Suivi EAU-ELEC'!I13 -> 9305 | N14: ='Suivi EAU-ELEC'!K13 -> 3534 | O14: =L14+M14+N14 -> 17849 | Q14: =L14*0.6985+M14*0.9514+N14*1.3304 -> 17053.896 | V14: ='Suvi Gaz'!O8 -> 351.99131 | X14: =V14*7.8 -> 2745.5322
B15: 43652 | D15: 166 | E15: 282 | F15: ='Suivi EAU-ELEC'!E14 -> 185.9 | H15: =F15*8.79 -> 1634.061 | K15: 42283 | L15: ='Suivi EAU-ELEC'!G14 -> 4704 | M15: ='Suivi EAU-ELEC'!I14 -> 10133 | N15: ='Suivi EAU-ELEC'!K14 -> 3707 | O15: =L15+M15+N15 -> 18544 | Q15: =L15*0.6985+M15*0.9514+N15*1.3304 -> 17858.073 | V15: ='Suvi Gaz'!O9 -> 287.99289 | X15: =V15*7.8 -> 2246.3445
B16: 43653 | D16: 139 | E16: 224 | F16: ='Suivi EAU-ELEC'!E15 -> 172.6 | H16: =F16*8.79 -> 1517.154 | K16: 42284 | L16: ='Suivi EAU-ELEC'!G15 -> 3989 | M16: ='Suivi EAU-ELEC'!I15 -> 10438 | N16: ='Suivi EAU-ELEC'!K15 -> 3361 | O16: =L16+M16+N16 -> 17788 | Q16: =L16*0.6985+M16*0.9514+N16*1.3304 -> 17188.504 | V16: ='Suvi Gaz'!O10 -> 415.98973 | X16: =V16*7.8 -> 3244.7199
B17: 43654 | D17: 150 | E17: 231 | F17: ='Suivi EAU-ELEC'!E16 -> 151.6 | H17: =F17*8.79 -> 1332.564 | K17: 42285 | L17: ='Suivi EAU-ELEC'!G16 -> 4414 | M17: ='Suivi EAU-ELEC'!I16 -> 10165 | N17: ='Suivi EAU-ELEC'!K16 -> 3621 | O17: =L17+M17+N17 -> 18200 | Q17: =L17*0.6985+M17*0.9514+N17*1.3304 -> 17571.538 | V17: ='Suvi Gaz'!O11 -> 415.98973 | X17: =V17*7.8 -> 3244.7199
B18: 43655 | D18: 151 | E18: 249 | F18: ='Suivi EAU-ELEC'!E17 -> 177.9 | H18: =F18*8.79 -> 1563.741 | K18: 42286 | L18: ='Suivi EAU-ELEC'!G17 -> 5812 | M18: ='Suivi EAU-ELEC'!I17 -> 10373 | N18: ='Suivi EAU-ELEC'!K17 -> 3849 | O18: =L18+M18+N18 -> 20034 | Q18: =L18*0.6985+M18*0.9514+N18*1.3304 -> 19049.264 | V18: ='Suvi Gaz'!O12 -> 319.9921 | X18: =V18*7.8 -> 2495.9384
B19: 43656 | D19: 131 | E19: 240 | F19: ='Suivi EAU-ELEC'!E18 -> 192 | H19: =F19*8.79 -> 1687.68 | K19: 42287 | L19: ='Suivi EAU-ELEC'!G18 -> 4903 | M19: ='Suivi EAU-ELEC'!I18 -> 10097 | N19: ='Suivi EAU-ELEC'!K18 -> 3766 | O19: =L19+M19+N19 -> 18766 | Q19: =L19*0.6985+M19*0.9514+N19*1.3304 -> 18041.318 | V19: ='Suvi Gaz'!O13 -> 447.98894 | X19: =V19*7.8 -> 3494.3137
B20: 43657 | D20: 141 | E20: 239 | F20: ='Suivi EAU-ELEC'!E19 -> 187 | H20: =F20*8.79 -> 1643.73 | K20: 42288 | L20: ='Suivi EAU-ELEC'!G19 -> 4784 | M20: ='Suivi EAU-ELEC'!I19 -> 9346 | N20: ='Suivi EAU-ELEC'!K19 -> 3883 | O20: =L20+M20+N20 -> 18013 | Q20: =L20*0.6985+M20*0.9514+N20*1.3304 -> 17399.352 | V20: ='Suvi Gaz'!O14 -> 223.99447 | X20: =V20*7.8 -> 1747.1569
B21: 43658 | D21: 157 | E21: 271 | F21: ='Suivi EAU-ELEC'!E20 -> 182 | H21: =F21*8.79 -> 1599.78 | K21: 42289 | L21: ='Suivi EAU-ELEC'!G20 -> 5221 | M21: ='Suivi EAU-ELEC'!I20 -> 10100 | N21: ='Suivi EAU-ELEC'!K20 -> 3755 | O21: =L21+M21+N21 -> 19076 | Q21: =L21*0.6985+M21*0.9514+N21*1.3304 -> 18251.66 | V21: ='Suvi Gaz'!O15 -> 639.9842 | X21: =V21*7.8 -> 4991.8768
... B37: 43674 | D37: 147 | E37: 262 | F37: ='Suivi EAU-ELEC'!E36 -> 158.1 | H37: =F37*8.79 -> 1389.699 | K37: 42305 | L37: ='Suivi EAU-ELEC'!G36 -> 4045 | M37: ='Suivi EAU-ELEC'!I36 -> 9742 | N37: ='Suivi EAU-ELEC'!K36 -> 3607 | O37: =L37+M37+N37 -> 17394 | Q37: =L37*0.6985+M37*0.9514+N37*1.3304 -> 16892.724 | V37: ='Suvi Gaz'!O31 -> 287.99289 | X37: =V37*7.8 -> 2246.3445
B38: 43675 | D38: 144 | E38: 252 | F38: ='Suivi EAU-ELEC'!E37 -> 140 | H38: =F38*8.79 -> 1230.6 | L38: ='Suivi EAU-ELEC'!G37 -> 4563 | M38: ='Suivi EAU-ELEC'!I37 -> 9132 | N38: ='Suivi EAU-ELEC'!K37 -> 3404 | O38: =L38+M38+N38 -> 17099 | Q38: =L38*0.6985+M38*0.9514+N38*1.3304 -> 16404.122 | V38: ='Suvi Gaz'!O32 -> 415.98973 | X38: =V38*7.8 -> 3244.7199
B39: 43676 | D39: 148 | E39: 247 | F39: ='Suivi EAU-ELEC'!E38 -> 184.8 | H39: =F39*8.79 -> 1624.392 | L39: ='Suivi EAU-ELEC'!G38 -> 5815 | M39: ='Suivi EAU-ELEC'!I38 -> 9234 | N39: ='Suivi EAU-ELEC'!K38 -> 3641 | O39: =L39+M39+N39 -> 18690 | Q39: =L39*0.6985+M39*0.9514+N39*1.3304 -> 17690.992 | V39: ='Suvi Gaz'!O33 -> 223.99447 | X39: =V39*7.8 -> 1747.1569
B40: 43677 | D40: 146 | E40: 261 | F40: ='Suivi EAU-ELEC'!E39 -> 161 | H40: =F40*8.79 -> 1415.19 | L40: ='Suivi EAU-ELEC'!G39 -> 5044 | M40: ='Suivi EAU-ELEC'!I39 -> 9803 | N40: ='Suivi EAU-ELEC'!K39 -> 3775 | O40: =L40+M40+N40 -> 18622 | Q40: =L40*0.6985+M40*0.9514+N40*1.3304 -> 17872.068 | V40: ='Suvi Gaz'!O34 -> 287.99289 | X40: =V40*7.8 -> 2246.3445
D41: =SUM(D10:D40) -> 4649 | E41: =SUM(E10:E40) -> 7621 | F41: =SUM(F10:F40) -> 5649 | H41: =SUM(H10:H40) -> 49654.71 | L41: =SUM(L10:L40) -> 148996 | M41: =SUM(M10:M40) -> 300008 | N41: =SUM(N10:N40) -> 115132 | O41: =SUM(O10:O40) -> 564136 | Q41: =SUM(Q10:Q40) -> 542672.93 | S41: =SUM(S10:S40) -> 0 | U41: =SUM(U10:U40) -> 0 | V41: =SUM(V10:V40) -> 11039.727 | X41: =SUM(X10:X40) -> 86109.874
A43: Désignation | H43: COUTS | I43: Consommations | L43: Consommations /DHs | N43: TOTAL Consommations /DHs
A44: ELECTRICITE / Kw/h | D44: creuse 81 | E44: creuse 81 | F44: creuse 81 | H44: 0.6985 | I44: =L41 -> 148996 | L44: =I44*H44 -> 104073.71 | N44: =L44+L45+L46 -> 542672.93
D45: pleine 82 | E45: pleine 82 | F45: pleine 82 | H45: 0.9514 | I45: =M41 -> 300008 | L45: =I45*H45 -> 285427.61
D46: pointe 83 | E46: pointe 83 | F46: pointe 83 | H46: 1.3304 | I46: =N41 -> 115132 | L46: =I46*H46 -> 153171.61
D47: REDEVANCE DE PUISSANCE | H47: 1000 | I47: 43.88167 | J47: 43.88167 | L47: =I47*H47 -> 43881.67 | N47: =L47 -> 43881.67
D48: DEPASSEMENT DE PUISSANCE | H48: 340 | I48: 65.822505 | J48: 65.822505 | L48: =I48*H48 -> 22379.652 | N48: =L48 -> 22379.652
D49: ENTRETIEN COMPTAGE | I49: 841 | J49: 841 | L49: =J49 -> 841 | N49: =L49 -> 841
D50: LOCATION COMPTAGE | I50: 1492 | J50: 1492 | L50: =J50 -> 1492 | N50: =L50 -> 1492
D51: TOTAL | N51: =N44+N47+N48+N49+N50 -> 611267.25
D52: UNIT KW PRICE | N52: =N51/O41 -> 1.0835459
A53: EAU HOTEL M3 | H53: 8.79 | I53: =F41 -> 5649 | L53: =I53*H53 -> 49654.71 | N53: =L53 -> 49654.71
A54: GAZ Kg | H54: 7.8 | I54: =V41 -> 11039.727 | L54: =I54*H54 -> 86109.874 | N54: =L54 -> 86109.874

Sheet Suvi Gaz
F1: suivi Gaz July 2019 | AA1: a
Q2: 803 | T2: 519 | W2: 800 | Z2: 802
B3: Relvé C1 | C3: cons C1 | D3: Relvé C2 | E3: cons C2 | F3: Relvé C3 | G3: cons C3 | H3: Relvé C4 | I3: cons C4 | J3: ∑ des relevés | K3: moyen general % | L3: con.j | M3: ∑ de volume en L | N3: cons./jen L | O3: cons./jen Kg | P3: cons./jen DH | Q3: livraison C1 | R3: %Avant | S3: % Après | T3: livraison C2 | U3: %Avant | V3: % Après | W3: livraison C3 | X3: %Avant | Y3: % Après | Z3: livraison C4 | AA3: %Avant | AB3: % Après | AC3: total livraison | AD3: moyen general % Avant L | AE3: moyen general % Aaprés L
A4: 43647 | B4: 45 | C4: =IF(AC4>0,((B4-R4)+(S4-B5)),IF(B5=0, ,(B4-B5))) -> 5 | D4: 49 | E4: =IF(AC4>0,((D4-U4)+(V4-D5)),IF(D5=0, ,(D4-D5))) -> 5 | F4: 49 | G4: =IF(AC4>0,((F4-X4)+(Y4-F5)),IF(F5=0, ,(F4-F5))) -> 3 | H4: 50 | I4: =IF(AC4>0,((H4-AA4)+(AB4-H5)),IF(H5=0, ,(H4-H5))) -> 4 | J4: =B4+D4+F4+H4 -> 193 | K4: =J4/4 -> 48.25 | L4: =IF(AC4>0,((K4-AD4)+(AE4-K5)),IF(K5=0, ,(K4-K5))) -> 4.25 | M4: =6049*4 -> 24196 | N4: =L4*M4/100 -> 1028.33 | O4: =N4*0.529 -> 543.98657 | P4: =O4*7.8 -> 4243.0952 | AC4: =Q4+T4+W4+Z4 -> 0 | AD4: =(R4+U4+X4+AA4)/4 -> 0 | AE4: =(S4+V4+Y4+AB4)/4 -> 0
A5: 43648 | B5: 40 | C5: =IF(AC5>0,((B5-R5)+(S5-B6)),IF(B6=0, ,(B5-B6))) -> 4 | D5: 44 | E5: =IF(AC5>0,((D5-U5)+(V5-D6)),IF(D6=0, ,(D5-D6))) -> 2 | F5: 46 | G5: =IF(AC5>0,((F5-X5)+(Y5-F6)),IF(F6=0, ,(F5-F6))) -> 1 | H5: 46 | I5: =IF(AC5>0,((H5-AA5)+(AB5-H6)),IF(H6=0, ,(H5-H6))) -> 1 | J5: =B5+D5+F5+H5 -> 176 | K5: =J5/4 -> 44 | L5: =IF(AC5>0,((K5-AD5)+(AE5-K6)),IF(K6=0, ,(K5-K6))) -> 2 | M5: =6049*4 -> 24196 | N5: =L5*M5/100 -> 483.92 | O5: =N5*0.529 -> 255.99368 | P5: =O5*7.8 -> 1996.7507 | Q5: 1889 | R5: 40 | S5: 68 | T5: 1900 | U5: 40 | V5: 64 | W5: 1911 | X5: 45 | Y5: 70 | Z5: 2003 | AA5: 45 | AB5: 70 | AC5: =Q5+T5+W5+Z5 -> 7703 | AD5: =(R5+U5+X5+AA5)/4 -> 42.5 | AE5: =(S5+V5+Y5+AB5)/4 -> 68
A6: 43649 | B6: 64 | C6: =IF(AC6>0,((B6-R6)+(S6-B7)),IF(B7=0, ,(B6-B7))) -> 4 | D6: 66 | E6: =IF(AC6:AC29>0,((D6-U6)+(V6-D7)),IF(D7=0, ,(D6-D7))) -> 5 | F6: 70 | G6: =IF(AC6>0,((F6-X6)+(Y6-F7)),IF(F7=0, ,(F6-F7))) -> 5 | H6: 70 | I6: =IF(AC6>0,((H6-AA6)+(AB6-H7)),IF(H7=0, ,(H6-H7))) -> 4 | J6: =B6+D6+F6+H6 -> 270 | K6: =J6/4 -> 67.5 | L6: =IF(AC6>0,((K6-AD6)+(AE6-K7)),IF(K7=0, ,(K6-K7))) -> 4.5 | M6: =6049*4 -> 24196 | N6: =L6*M6/100 -> 1088.82 | O6: =N6*0.529 -> 575.98578 | P6: =O6*7.8 -> 4492.6891 | AC6: =Q6+T6+W6+Z6 -> 0 | AD6: =(R6+U6+X6+AA6)/4 -> 0 | AE6: =(S6+V6+Y6+AB6)/4 -> 0
A7: 43650 | B7: 60 | C7: =IF(AC7>0,((B7-R7)+(S7-B8)),IF(B8=0, ,(B7-B8))) -> 4 | D7: 61 | E7: =IF(AC7:AC30>0,((D7-U7)+(V7-D8)),IF(D8=0, ,(D7-D8))) -> 2 | F7: 65 | G7: =IF(AC7>0,((F7-X7)+(Y7-F8)),IF(F8=0, ,(F7-F8))) -> 0 | H7: 66 | I7: =IF(AC7>0,((H7-AA7)+(AB7-H8)),IF(H8=0, ,(H7-H8))) -> 3 | J7: =B7+D7+F7+H7 -> 252 | K7: =J7/4 -> 63 | L7: =IF(AC7>0,((K7-AD7)+(AE7-K8)),IF(K8=0, ,(K7-K8))) -> 2.25 | M7: =6049*4 -> 24196 | N7: =L7*M7/100 -> 544.41 | O7: =N7*0.529 -> 287.99289 | P7: =O7*7.8 -> 2246.3445 | AC7: =Q7+T7+W7+Z7 -> 0 | AD7: =(R7+U7+X7+AA7)/4 -> 0 | AE7: =(S7+V7+Y7+AB7)/4 -> 0
A8: 43651 | B8: 56 | C8: =IF(AC8>0,((B8-R8)+(S8-B9)),IF(B9=0, ,(B8-B9))) -> 2 | D8: 59 | E8: =IF(AC8>0,((D8-U8)+(V8-D9)),IF(D9=0, ,(D8-D9))) -> 4 | F8: 65 | G8: =IF(AC8>0,((F8-X8)+(Y8-F9)),IF(F9=0, ,(F8-F9))) -> 5 | H8: 63 | I8: =IF(AC8>0,((H8-AA8)+(AB8-H9)),IF(H9=0, ,(H8-H9))) -> 0 | J8: =B8+D8+F8+H8 -> 243 | K8: =J8/4 -> 60.75 | L8: =IF(AC8>0,((K8-AD8)+(AE8-K9)),IF(K9=0, ,(K8-K9))) -> 2.75 | M8: =6049*4 -> 24196 | N8: =L8*M8/100 -> 665.39 | O8: =N8*0.529 -> 351.99131 | P8: =O8*7.8 -> 2745.5322 | Q8: 2475 | R8: 55 | S8: 85 | T8: 2655 | U8: 55 | V8: 85 | W8: 2239 | X8: 60 | Y8: 85 | Z8: 2039 | AA8: 63 | AB8: 85 | AC8: =Q8+T8+W8+Z8 -> 9408 | AD8: =(R8+U8+X8+AA8)/4 -> 58.25 | AE8: =(S8+V8+Y8+AB8)/4 -> 85
A9: 43652 | B9: 84 | C9: =IF(AC9>0,((B9-R9)+(S9-B10)),IF(B10=0, ,(B9-B10))) -> 4 | D9: 85 | E9: =IF(AC9>0,((D9-U9)+(V9-D10)),IF(D10=0, ,(D9-D10))) -> 2 | F9: 85 | G9: =IF(AC9>0,((F9-X9)+(Y9-F10)),IF(F10=0, ,(F9-F10))) -> 2 | H9: 85 | I9: =IF(AC9>0,((H9-AA9)+(AB9-H10)),IF(H10=0, ,(H9-H10))) -> 1 | J9: =B9+D9+F9+H9 -> 339 | K9: =J9/4 -> 84.75 | L9: =IF(AC9>0,((K9-AD9)+(AE9-K10)),IF(K10=0, ,(K9-K10))) -> 2.25 | M9: =6049*4 -> 24196 | N9: =L9*M9/100 -> 544.41 | O9: =N9*0.529 -> 287.99289 | P9: =O9*7.8 -> 2246.3445 | AC9: =Q9+T9+W9+Z9 -> 0 | AD9: =(R9+U9+X9+AA9)/4 -> 0 | AE9: =(S9+V9+Y9+AB9)/4 -> 0
A10: 43653 | B10: 80 | C10: =IF(AC10>0,((B10-R10)+(S10-B11)),IF(B11=0, ,(B10-B11))) -> 3 | D10: 83 | E10: =IF(AC10>0,((D10-U10)+(V10-D11)),IF(D11=0, ,(D10-D11))) -> 3 | F10: 83 | G10: =IF(AC10>0,((F10-X10)+(Y10-F11)),IF(F11=0, ,(F10-F11))) -> 3 | H10: 84 | I10: =IF(AC10>0,((H10-AA10)+(AB10-H11)),IF(H11=0, ,(H10-H11))) -> 4 | J10: =B10+D10+F10+H10 -> 330 | K10: =J10/4 -> 82.5 | L10: =IF(AC10>0,((K10-AD10)+(AE10-K11)),IF(K11=0, ,(K10-K11))) -> 3.25 | M10: =6049*4 -> 24196 | N10: =L10*M10/100 -> 786.37 | O10: =N10*0.529 -> 415.98973 | P10: =O10*7.8 -> 3244.7199 | AC10: =Q10+T10+W10+Z10 -> 0 | AD10: =(R10+U10+X10+AA10)/4 -> 0 | AE10: =(S10+V10+Y10+AB10)/4 -> 0
A11: 43654 | B11: 77 | C11: =IF(AC11>0,((B11-R11)+(S11-B12)),IF(B12=0, ,(B11-B12))) -> 2 | D11: 80 | E11: =IF(AC11>0,((D11-U11)+(V11-D12)),IF(D12=0, ,(D11-D12))) -> 4 | F11: 80 | G11: =IF(AC11>0,((F11-X11)+(Y11-F12)),IF(F12=0, ,(F11-F12))) -> 3 | H11: 80 | I11: =IF(AC11>0,((H11-AA11)+(AB11-H12)),IF(H12=0, ,(H11-H12))) -> 4 | J11: =B11+D11+F11+H11 -> 317 | K11: =J11/4 -> 79.25 | L11: =IF(AC11>0,((K11-AD11)+(AE11-K12)),IF(K12=0, ,(K11-K12))) -> 3.25 | M11: =6049*4 -> 24196 | N11: =L11*M11/100 -> 786.37 | O11: =N11*0.529 -> 415.98973 | P11: =O11*7.8 -> 3244.7199 | AC11: =Q11+T11+W11+Z11 -> 0 | AD11: =(R11+U11+X11+AA11)/4 -> 0 | AE11: =(S11+V11+Y11+AB11)/4 -> 0
A12: 43655 | B12: 75 | C12: =IF(AC12>0,((B12-R12)+(S12-B13)),IF(B13=0, ,(B12-B13))) -> 5 | D12: 76 | E12: =IF(AC12>0,((D12-U12)+(V12-D13)),IF(D13=0, ,(D12-D13))) -> 2 | F12: 77 | G12: =IF(AC12>0,((F12-X12)+(Y12-F13)),IF(F13=0, ,(F12-F13))) -> 2 | H12: 76 | I12: =IF(AC12>0,((H12-AA12)+(AB12-H13)),IF(H13=0, ,(H12-H13))) -> 1 | J12: =B12+D12+F12+H12 -> 304 | K12: =J12/4 -> 76 | L12: =IF(AC12>0,((K12-AD12)+(AE12-K13)),IF(K13=0, ,(K12-K13))) -> 2.5 | M12: =6049*4 -> 24196 | N12: =L12*M12/100 -> 604.9 | O12: =N12*0.529 -> 319.9921 | P12: =O12*7.8 -> 2495.9384 | AC12: =Q12+T12+W12+Z12 -> 0 | AD12: =(R12+U12+X12+AA12)/4 -> 0 | AE12: =(S12+V12+Y12+AB12)/4 -> 0
A13: 43656 | B13: 70 | C13: =IF(AC13>0,((B13-R13)+(S13-B14)),IF(B14=0, ,(B13-B14))) -> 2 | D13: 74 | E13: =IF(AC13>0,((D13-U13)+(V13-D14)),IF(D14=0, ,(D13-D14))) -> 4 | F13: 75 | G13: =IF(AC13>0,((F13-X13)+(Y13-F14)),IF(F14=0, ,(F13-F14))) -> 3 | H13: 75 | I13: =IF(AC13>0,((H13-AA13)+(AB13-H14)),IF(H14=0, ,(H13-H14))) -> 5 | J13: =B13+D13+F13+H13 -> 294 | K13: =J13/4 -> 73.5 | L13: =IF(AC13>0,((K13-AD13)+(AE13-K14)),IF(K14=0, ,(K13-K14))) -> 3.5 | M13: =6049*4 -> 24196 | N13: =L13*M13/100 -> 846.86 | O13: =N13*0.529 -> 447.98894 | P13: =O13*7.8 -> 3494.3137 | AC13: =Q13+T13+W13+Z13 -> 0 | AD13: =(R13+U13+X13+AA13)/4 -> 0 | AE13: =(S13+V13+Y13+AB13)/4 -> 0
A14: 43657 | B14: 68 | C14: =IF(AC14>0,((B14-R14)+(S14-B15)),IF(B15=0, ,(B14-B15))) -> 3 | D14: 70 | E14: =IF(AC14>0,((D14-U14)+(V14-D15)),IF(D15=0, ,(D14-D15))) -> 2 | F14: 72 | G14: =IF(AC14>0,((F14-X14)+(Y14-F15)),IF(F15=0, ,(F14-F15))) -> 2 | H14: 70 | I14: =IF(AC14>0,((H14-AA14)+(AB14-H15)),IF(H15=0, ,(H14-H15))) -> 0 | J14: =B14+D14+F14+H14 -> 280 | K14: =J14/4 -> 70 | L14: =IF(AC14>0,((K14-AD14)+(AE14-K15)),IF(K15=0, ,(K14-K15))) -> 1.75 | M14: =6049*4 -> 24196 | N14: =L14*M14/100 -> 423.43 | O14: =N14*0.529 -> 223.99447 | P14: =O14*7.8 -> 1747.1569 | AC14: =Q14+T14+W14+Z14 -> 0 | AD14: =(R14+U14+X14+AA14)/4 -> 0 | AE14: =(S14+V14+Y14+AB14)/4 -> 0
A15: 43658 | B15: 65 | C15: =IF(AC15>0,((B15-R15)+(S15-B16)),IF(B16=0, ,(B15-B16))) -> 5 | D15: 68 | E15: =IF(AC15>0,((D15-U15)+(V15-D16)),IF(D16=0, ,(D15-D16))) -> 5 | F15: 70 | G15: =IF(AC15>0,((F15-X15)+(Y15-F16)),IF(F16=0, ,(F15-F16))) -> 5 | H15: 70 | I15: =IF(AC15>0,((H15-AA15)+(AB15-H16)),IF(H16=0, ,(H15-H16))) -> 5 | J15: =B15+D15+F15+H15 -> 273 | K15: =J15/4 -> 68.25 | L15: =IF(AC15>0,((K15-AD15)+(AE15-K16)),IF(K16=0, ,(K15-K16))) -> 5 | M15: =6049*4 -> 24196 | N15: =L15*M15/100 -> 1209.8 | O15: =N15*0.529 -> 639.9842 | P15: =O15*7.8 -> 4991.8768 | AC15: =Q15+T15+W15+Z15 -> 0 | AD15: =(R15+U15+X15+AA15)/4 -> 0 | AE15: =(S15+V15+Y15+AB15)/4 -> 0
A16: 43659 | B16: 60 | C16: =IF(AC16>0,((B16-R16)+(S16-B17)),IF(B17=0, ,(B16-B17))) -> 6 | D16: 63 | E16: =IF(AC16>0,((D16-U16)+(V16-D17)),IF(D17=0, ,(D16-D17))) -> 3 | F16: 65 | G16: =IF(AC16>0,((F16-X16)+(Y16-F17)),IF(F17=0, ,(F16-F17))) -> 3 | H16: 65 | I16: =IF(AC16>0,((H16-AA16)+(AB16-H17)),IF(H17=0, ,(H16-H17))) -> 2 | J16: =B16+D16+F16+H16 -> 253 | K16: =J16/4 -> 63.25 | L16: =IF(AC16>0,((K16-AD16)+(AE16-K17)),IF(K17=0, ,(K16-K17))) -> 3.5 | M16: =6049*4 -> 24196 | N16: =L16*M16/100 -> 846.86 | O16: =N16*0.529 -> 447.98894 | P16: =O16*7.8 -> 3494.3137 | AC16: =Q16+T16+W16+Z16 -> 0 | AD16: =(R16+U16+X16+AA16)/4 -> 0 | AE16: =(S16+V16+Y16+AB16)/4 -> 0
A17: 43660 | B17: 54 | C17: =IF(AC17>0,((B17-R17)+(S17-B18)),IF(B18=0, ,(B17-B18))) -> 0 | D17: 60 | E17: =IF(AC17>0,((D17-U17)+(V17-D18)),IF(D18=0, ,(D17-D18))) -> 4 | F17: 62 | G17: =IF(AC17>0,((F17-X17)+(Y17-F18)),IF(F18=0, ,(F17-F18))) -> 2 | H17: 63 | I17: =IF(AC17>0,((H17-AA17)+(AB17-H18)),IF(H18=0, ,(H17-H18))) -> 3 | J17: =B17+D17+F17+H17 -> 239 | K17: =J17/4 -> 59.75 | L17: =IF(AC17>0,((K17-AD17)+(AE17-K18)),IF(K18=0, ,(K17-K18))) -> 2.25 | M17: =6049*4 -> 24196 | N17: =L17*M17/100 -> 544.41 | O17: =N17*0.529 -> 287.99289 | P17: =O17*7.8 -> 2246.3445 | AC17: =Q17+T17+W17+Z17 -> 0 | AD17: =(R17+U17+X17+AA17)/4 -> 0 | AE17: =(S17+V17+Y17+AB17)/4 -> 0
A18: 43661 | B18: 54 | C18: =IF(AC18>0,((B18-R18)+(S18-B19)),IF(B19=0, ,(B18-B19))) -> 3 | D18: 56 | E18: =IF(AC18>0,((D18-U18)+(V18-D19)),IF(D19=0, ,(D18-D19))) -> 2 | F18: 60 | G18: =IF(AC18>0,((F18-X18)+(Y18-F19)),IF(F19=0, ,(F18-F19))) -> 4 | H18: 60 | I18: =IF(AC18>0,((H18-AA18)+(AB18-H19)),IF(H19=0, ,(H18-H19))) -> 4 | J18: =B18+D18+F18+H18 -> 230 | K18: =J18/4 -> 57.5 | L18: =IF(AC18>0,((K18-AD18)+(AE18-K19)),IF(K19=0, ,(K18-K19))) -> 3.25 | M18: =6049*4 -> 24196 | N18: =L18*M18/100 -> 786.37 | O18: =N18*0.529 -> 415.98973 | P18: =O18*7.8 -> 3244.7199 | AC18: =Q18+T18+W18+Z18 -> 0 | AD18: =(R18+U18+X18+AA18)/4 -> 0 | AE18: =(S18+V18+Y18+AB18)/4 -> 0
A19: 43662 | B19: 51 | C19: =IF(AC19>0,((B19-R19)+(S19-B20)),IF(B20=0, ,(B19-B20))) -> 3 | D19: 54 | E19: =IF(AC19>0,((D19-U19)+(V19-D20)),IF(D20=0, ,(D19-D20))) -> 4 | F19: 56 | G19: =IF(AC19>0,((F19-X19)+(Y19-F20)),IF(F20=0, ,(F19-F20))) -> 2 | H19: 56 | I19: =IF(AC19>0,((H19-AA19)+(AB19-H20)),IF(H20=0, ,(H19-H20))) -> 2 | J19: =B19+D19+F19+H19 -> 217 | K19: =J19/4 -> 54.25 | L19: =IF(AC19>0,((K19-AD19)+(AE19-K20)),IF(K20=0, ,(K19-K20))) -> 2.75 | M19: =6049*4 -> 24196 | N19: =L19*M19/100 -> 665.39 | O19: =N19*0.529 -> 351.99131 | P19: =O19*7.8 -> 2745.5322 | AC19: =Q19+T19+W19+Z19 -> 0 | AD19: =(R19+U19+X19+AA19)/4 -> 0 | AE19: =(S19+V19+Y19+AB19)/4 -> 0
A20: 43663 | B20: 48 | C20: =IF(AC20>0,((B20-R20)+(S20-B21)),IF(B21=0, ,(B20-B21))) -> 6 | D20: 50 | E20: =IF(AC20>0,((D20-U20)+(V20-D21)),IF(D21=0, ,(D20-D21))) -> 6 | F20: 54 | G20: =IF(AC20>0,((F20-X20)+(Y20-F21)),IF(F21=0, ,(F20-F21))) -> 4 | H20: 54 | I20: =IF(AC20>0,((H20-AA20)+(AB20-H21)),IF(H21=0, ,(H20-H21))) -> 4 | J20: =B20+D20+F20+H20 -> 206 | K20: =J20/4 -> 51.5 | L20: =IF(AC20>0,((K20-AD20)+(AE20-K21)),IF(K21=0, ,(K20-K21))) -> 5 | M20: =6049*4 -> 24196 | N20: =L20*M20/100 -> 1209.8 | O20: =N20*0.529 -> 639.9842 | P20: =O20*7.8 -> 4991.8768 | Q20: 3233 | R20: 43 | S20: 85 | T20: 2917 | U20: 45 | V20: 85 | W20: 2860 | X20: 50 | Y20: 85 | Z20: 2790 | AA20: 50 | AB20: 85 | AC20: =Q20+T20+W20+Z20 -> 11800 | AD20: =(R20+U20+X20+AA20)/4 -> 47 | AE20: =(S20+V20+Y20+AB20)/4 -> 85
A21: 43664 | B21: 84 | C21: =IF(AC21>0,((B21-R21)+(S21-B22)),IF(B22=0, ,(B21-B22))) -> 4 | D21: 84 | E21: =IF(AC21>0,((D21-U21)+(V21-D22)),IF(D22=0, ,(D21-D22))) -> 4 | F21: 85 | G21: =IF(AC21>0,((F21-X21)+(Y21-F22)),IF(F22=0, ,(F21-F22))) -> 0 | H21: 85 | I21: =IF(AC21>0,((H21-AA21)+(AB21-H22)),IF(H22=0, ,(H21-H22))) -> 0 | J21: =B21+D21+F21+H21 -> 338 | K21: =J21/4 -> 84.5 | L21: =IF(AC21>0,((K21-AD21)+(AE21-K22)),IF(K22=0, ,(K21-K22))) -> 2 | M21: =6049*4 -> 24196 | N21: =L21*M21/100 -> 483.92 | O21: =N21*0.529 -> 255.99368 | P21: =O21*7.8 -> 1996.7507 | AC21: =Q21+T21+W21+Z21 -> 0 | AD21: =(R21+U21+X21+AA21)/4 -> 0 | AE21: =(S21+V21+Y21+AB21)/4 -> 0
A22: 43665 | B22: 80 | C22: =IF(AC22>0,((B22-R22)+(S22-B23)),IF(B23=0, ,(B22-B23))) -> 4 | D22: 80 | E22: =IF(AC22>0,((D22-U22)+(V22-D23)),IF(D23=0, ,(D22-D23))) -> 2 | F22: 85 | G22: =IF(AC22>0,((F22-X22)+(Y22-F23)),IF(F23=0, ,(F22-F23))) -> 5 | H22: 85 | I22: =IF(AC22>0,((H22-AA22)+(AB22-H23)),IF(H23=0, ,(H22-H23))) -> 5 | J22: =B22+D22+F22+H22 -> 330 | K22: =J22/4 -> 82.5 | L22: =IF(AC22>0,((K22-AD22)+(AE22-K23)),IF(K23=0, ,(K22-K23))) -> 4 | M22: =6049*4 -> 24196 | N22: =L22*M22/100 -> 967.84 | O22: =N22*0.529 -> 511.98736 | P22: =O22*7.8 -> 3993.5014 | AC22: =Q22+T22+W22+Z22 -> 0 | AD22: =(R22+U22+X22+AA22)/4 -> 0 | AE22: =(S22+V22+Y22+AB22)/4 -> 0
A23: 43666 | B23: 76 | C23: =IF(AC23>0,((B23-R23)+(S23-B24)),IF(B24=0, ,(B23-B24))) -> 1 | D23: 78 | E23: =IF(AC23>0,((D23-U23)+(V23-D24)),IF(D24=0, ,(D23-D24))) -> 3 | F23: 80 | G23: =IF(AC23>0,((F23-X23)+(Y23-F24)),IF(F24=0, ,(F23-F24))) -> 1 | H23: 80 | I23: =IF(AC23>0,((H23-AA23)+(AB23-H24)),IF(H24=0, ,(H23-H24))) -> 1 | J23: =B23+D23+F23+H23 -> 314 | K23: =J23/4 -> 78.5 | L23: =IF(AC23>0,((K23-AD23)+(AE23-K24)),IF(K24=0, ,(K23-K24))) -> 1.5 | M23: =6049*4 -> 24196 | N23: =L23*M23/100 -> 362.94 | O23: =N23*0.529 -> 191.99526 | P23: =O23*7.8 -> 1497.563 | AC23: =Q23+T23+W23+Z23 -> 0 | AD23: =(R23+U23+X23+AA23)/4 -> 0 | AE23: =(S23+V23+Y23+AB23)/4 -> 0
A24: 43667 | B24: 75 | C24: =IF(AC24>0,((B24-R24)+(S24-B25)),IF(B25=0, ,(B24-B25))) -> 1 | D24: 75 | E24: =IF(AC24>0,((D24-U24)+(V24-D25)),IF(D25=0, ,(D24-D25))) -> 2 | F24: 79 | G24: =IF(AC24>0,((F24-X24)+(Y24-F25)),IF(F25=0, ,(F24-F25))) -> 3 | H24: 79 | I24: =IF(AC24>0,((H24-AA24)+(AB24-H25)),IF(H25=0, ,(H24-H25))) -> 4 | J24: =B24+D24+F24+H24 -> 308 | K24: =J24/4 -> 77 | L24: =IF(AC24>0,((K24-AD24)+(AE24-K25)),IF(K25=0, ,(K24-K25))) -> 2.5 | M24: =6049*4 -> 24196 | N24: =L24*M24/100 -> 604.9 | O24: =N24*0.529 -> 319.9921 | P24: =O24*7.8 -> 2495.9384 | AC24: =Q24+T24+W24+Z24 -> 0 | AD24: =(R24+U24+X24+AA24)/4 -> 0 | AE24: =(S24+V24+Y24+AB24)/4 -> 0
A25: 43668 | B25: 74 | C25: =IF(AC25>0,((B25-R25)+(S25-B26)),IF(B26=0, ,(B25-B26))) -> 4 | D25: 73 | E25: =IF(AC25>0,((D25-U25)+(V25-D26)),IF(D26=0, ,(D25-D26))) -> 3 | F25: 76 | G25: =IF(AC25>0,((F25-X25)+(Y25-F26)),IF(F26=0, ,(F25-F26))) -> 1 | H25: 75 | I25: =IF(AC25>0,((H25-AA25)+(AB25-H26)),IF(H26=0, ,(H25-H26))) -> 0 | J25: =B25+D25+F25+H25 -> 298 | K25: =J25/4 -> 74.5 | L25: =IF(AC25>0,((K25-AD25)+(AE25-K26)),IF(K26=0, ,(K25-K26))) -> 2 | M25: =6049*4 -> 24196 | N25: =L25*M25/100 -> 483.92 | O25: =N25*0.529 -> 255.99368 | P25: =O25*7.8 -> 1996.7507 | AC25: =Q25+T25+W25+Z25 -> 0 | AD25: =(R25+U25+X25+AA25)/4 -> 0 | AE25: =(S25+V25+Y25+AB25)/4 -> 0
A26: 43669 | B26: 70 | C26: =IF(AC26>0,((B26-R26)+(S26-B27)),IF(B27=0, ,(B26-B27))) -> 1 | D26: 70 | E26: =IF(AC26>0,((D26-U26)+(V26-D27)),IF(D27=0, ,(D26-D27))) -> 1 | F26: 75 | G26: =IF(AC26>0,((F26-X26)+(Y26-F27)),IF(F27=0, ,(F26-F27))) -> 1 | H26: 75 | I26: =IF(AC26>0,((H26-AA26)+(AB26-H27)),IF(H27=0, ,(H26-H27))) -> 1 | J26: =B26+D26+F26+H26 -> 290 | K26: =J26/4 -> 72.5 | L26: =IF(AC26>0,((K26-AD26)+(AE26-K27)),IF(K27=0, ,(K26-K27))) -> 1 | M26: =6049*4 -> 24196 | N26: =L26*M26/100 -> 241.96 | O26: =N26*0.529 -> 127.99684 | P26: =O26*7.8 -> 998.37535 | AC26: =Q26+T26+W26+Z26 -> 0 | AD26: =(R26+U26+X26+AA26)/4 -> 0 | AE26: =(S26+V26+Y26+AB26)/4 -> 0
A27: 43670 | B27: 69 | C27: =IF(AC27>0,((B27-R27)+(S27-B28)),IF(B28=0, ,(B27-B28))) -> 3 | D27: 69 | E27: =IF(AC27>0,((D27-U27)+(V27-D28)),IF(D28=0, ,(D27-D28))) -> 2 | F27: 74 | G27: =IF(AC27>0,((F27-X27)+(Y27-F28)),IF(F28=0, ,(F27-F28))) -> 3 | H27: 74 | I27: =IF(AC27>0,((H27-AA27)+(AB27-H28)),IF(H28=0, ,(H27-H28))) -> 3 | J27: =B27+D27+F27+H27 -> 286 | K27: =J27/4 -> 71.5 | L27: =IF(AC27>0,((K27-AD27)+(AE27-K28)),IF(K28=0, ,(K27-K28))) -> 2.75 | M27: =6049*4 -> 24196 | N27: =L27*M27/100 -> 665.39 | O27: =N27*0.529 -> 351.99131 | P27: =O27*7.8 -> 2745.5322 | AC27: =Q27+T27+W27+Z27 -> 0 | AD27: =(R27+U27+X27+AA27)/4 -> 0 | AE27: =(S27+V27+Y27+AB27)/4 -> 0
A28: 43671 | B28: 66 | C28: =IF(AC28>0,((B28-R28)+(S28-B29)),IF(B29=0, ,(B28-B29))) -> 2 | D28: 67 | E28: =IF(AC28>0,((D28-U28)+(V28-D29)),IF(D29=0, ,(D28-D29))) -> 2 | F28: 71 | G28: =IF(AC28>0,((F28-X28)+(Y28-F29)),IF(F29=0, ,(F28-F29))) -> 1 | H28: 71 | I28: =IF(AC28>0,((H28-AA28)+(AB28-H29)),IF(H29=0, ,(H28-H29))) -> 1 | J28: =B28+D28+F28+H28 -> 275 | K28: =J28/4 -> 68.75 | L28: =IF(AC28>0,((K28-AD28)+(AE28-K29)),IF(K29=0, ,(K28-K29))) -> 1.5 | M28: =6049*4 -> 24196 | N28: =L28*M28/100 -> 362.94 | O28: =N28*0.529 -> 191.99526 | P28: =O28*7.8 -> 1497.563 | AC28: =Q28+T28+W28+Z28 -> 0 | AD28: =(R28+U28+X28+AA28)/4 -> 0 | AE28: =(S28+V28+Y28+AB28)/4 -> 0
A29: 43672 | B29: 64 | C29: =IF(AC29>0,((B29-R29)+(S29-B30)),IF(B30=0, ,(B29-B30))) -> 2 | D29: 65 | E29: =IF(AC29>0,((D29-U29)+(V29-D30)),IF(D30=0, ,(D29-D30))) -> 2 | F29: 70 | G29: =IF(AC29>0,((F29-X29)+(Y29-F30)),IF(F30=0, ,(F29-F30))) -> 2 | H29: 70 | I29: =IF(AC29>0,((H29-AA29)+(AB29-H30)),IF(H30=0, ,(H29-H30))) -> 2 | J29: =B29+D29+F29+H29 -> 269 | K29: =J29/4 -> 67.25 | L29: =IF(AC29>0,((K29-AD29)+(AE29-K30)),IF(K30=0, ,(K29-K30))) -> 2 | M29: =6049*4 -> 24196 | N29: =L29*M29/100 -> 483.92 | O29: =N29*0.529 -> 255.99368 | P29: =O29*7.8 -> 1996.7507 | AC29: =Q29+T29+W29+Z29 -> 0 | AD29: =(R29+U29+X29+AA29)/4 -> 0 | AE29: =(S29+V29+Y29+AB29)/4 -> 0
A30: 43673 | B30: 62 | C30: =IF(AC30>0,((B30-R30)+(S30-B31)),IF(B31=0, ,(B30-B31))) -> 4 | D30: 63 | E30: =IF(AC30>0,((D30-U30)+(V30-D31)),IF(D31=0, ,(D30-D31))) -> 4 | F30: 68 | G30: =IF(AC30>0,((F30-X30)+(Y30-F31)),IF(F31=0, ,(F30-F31))) -> 3 | H30: 68 | I30: =IF(AC30>0,((H30-AA30)+(AB30-H31)),IF(H31=0, ,(H30-H31))) -> 3 | J30: =B30+D30+F30+H30 -> 261 | K30: =J30/4 -> 65.25 | L30: =IF(AC30>0,((K30-AD30)+(AE30-K31)),IF(K31=0, ,(K30-K31))) -> 3.5 | M30: =6049*4 -> 24196 | N30: =L30*M30/100 -> 846.86 | O30: =N30*0.529 -> 447.98894 | P30: =O30*7.8 -> 3494.3137 | Q30: 1737 | R30: 60 | S30: 85 | T30: 1650 | U30: 61 | V30: 85 | W30: 1409 | X30: 65 | Y30: 85 | Z30: 1424 | AA30: 65 | AB30: 85 | AC30: =Q30+T30+W30+Z30 -> 6220 | AD30: =(R30+U30+X30+AA30)/4 -> 62.75 | AE30: =(S30+V30+Y30+AB30)/4 -> 85
A31: 43674 | B31: 83 | C31: =IF(AC31>0,((B31-R31)+(S31-B32)),IF(B32=0, ,(B31-B32))) -> 3 | D31: 83 | E31: =IF(AC31>0,((D31-U31)+(V31-D32)),IF(D32=0, ,(D31-D32))) -> 2 | F31: 85 | G31: =IF(AC31>0,((F31-X31)+(Y31-F32)),IF(F32=0, ,(F31-F32))) -> 3 | H31: 85 | I31: =IF(AC31>0,((H31-AA31)+(AB31-H32)),IF(H32=0, ,(H31-H32))) -> 1 | J31: =B31+D31+F31+H31 -> 336 | K31: =J31/4 -> 84 | L31: =IF(AC31>0,((K31-AD31)+(AE31-K32)),IF(K32=0, ,(K31-K32))) -> 2.25 | M31: =6049*4 -> 24196 | N31: =L31*M31/100 -> 544.41 | O31: =N31*0.529 -> 287.99289 | P31: =O31*7.8 -> 2246.3445 | AC31: =Q31+T31+W31+Z31 -> 0 | AD31: =(R31+U31+X31+AA31)/4 -> 0 | AE31: =(S31+V31+Y31+AB31)/4 -> 0
A32: 43675 | B32: 80 | C32: =IF(AC32>0,((B32-R32)+(S32-B33)),IF(B33=0, ,(B32-B33))) -> 4 | D32: 81 | E32: =IF(AC32>0,((D32-U32)+(V32-D33)),IF(D33=0, ,(D32-D33))) -> 3 | F32: 82 | G32: =IF(AC32>0,((F32-X32)+(Y32-F33)),IF(F33=0, ,(F32-F33))) -> 2 | H32: 84 | I32: =IF(AC32>0,((H32-AA32)+(AB32-H33)),IF(H33=0, ,(H32-H33))) -> 4 | J32: =B32+D32+F32+H32 -> 327 | K32: =J32/4 -> 81.75 | L32: =IF(AC32>0,((K32-AD32)+(AE32-K33)),IF(K33=0, ,(K32-K33))) -> 3.25 | M32: =6049*4 -> 24196 | N32: =L32*M32/100 -> 786.37 | O32: =N32*0.529 -> 415.98973 | P32: =O32*7.8 -> 3244.7199 | AC32: =Q32+T32+W32+Z32 -> 0 | AD32: =(R32+U32+X32+AA32)/4 -> 0 | AE32: =(S32+V32+Y32+AB32)/4 -> 0
A33: 43676 | B33: 76 | C33: =IF(AC33>0,((B33-R33)+(S33-B34)),IF(B34=0, ,(B33-B34))) -> 1 | D33: 78 | E33: =IF(AC33>0,((D33-U33)+(V33-D34)),IF(D34=0, ,(D33-D34))) -> 3 | F33: 80 | G33: =IF(AC33>0,((F33-X33)+(Y33-F34)),IF(F34=0, ,(F33-F34))) -> 1 | H33: 80 | I33: =IF(AC33>0,((H33-AA33)+(AB33-H34)),IF(H34=0, ,(H33-H34))) -> 2 | J33: =B33+D33+F33+H33 -> 314 | K33: =J33/4 -> 78.5 | L33: =IF(AC33>0,((K33-AD33)+(AE33-K34)),IF(K34=0, ,(K33-K34))) -> 1.75 | M33: =6049*4 -> 24196 | N33: =L33*M33/100 -> 423.43 | O33: =N33*0.529 -> 223.99447 | P33: =O33*7.8 -> 1747.1569 | AC33: =Q33+T33+W33+Z33 -> 0 | AD33: =(R33+U33+X33+AA33)/4 -> 0 | AE33: =(S33+V33+Y33+AB33)/4 -> 0
A34: 43677 | B34: 75 | C34: =IF(AC34>0,((B34-R34)+(S34-B35)),IF(B35=0, ,(B34-B35))) -> 2 | D34: 75 | E34: =IF(AC34>0,((D34-U34)+(V34-D35)),IF(D35=0, ,(D34-D35))) -> 1 | F34: 79 | G34: =IF(AC34>0,((F34-X34)+(Y34-F35)),IF(F35=0, ,(F34-F35))) -> 3 | H34: 78 | I34: =IF(AC34>0,((H34-AA34)+(AB34-H35)),IF(H35=0, ,(H34-H35))) -> 3 | J34: =B34+D34+F34+H34 -> 307 | K34: =J34/4 -> 76.75 | L34: =IF(AC34>0,((K34-AD34)+(AE34-K35)),IF(K35=0, ,(K34-K35))) -> 2.25 | M34: =6049*4 -> 24196 | N34: =L34*M34/100 -> 544.41 | O34: =N34*0.529 -> 287.99289 | P34: =O34*7.8 -> 2246.3445 | AC34: =Q34+T34+W34+Z34 -> 0 | AD34: =(R34+U34+X34+AA34)/4 -> 0 | AE34: =(S34+V34+Y34+AB34)/4 -> 0
A35: 43678 | B35: 73 | C35: =IF(AC35>0,((B35-R35)+(S35-B36)),IF(B36=0, ,(B35-B36))) -> 0 | D35: 74 | E35: =IF(AC35>0,((D35-U35)+(V35-D36)),IF(D36=0, ,(D35-D36))) -> 0 | F35: 76 | G35: =IF(AC35>0,((F35-X35)+(Y35-F36)),IF(F36=0, ,(F35-F36))) -> 0 | H35: 75 | I35: =IF(AC35>0,((H35-AA35)+(AB35-H36)),IF(H36=0, ,(H35-H36))) -> 0 | J35: =B35+D35+F35+H35 -> 298 | K35: =J35/4 -> 74.5 | L35: =IF(AC35>0,((K35-AD35)+(AE35-K36)),IF(K36=0, ,(K35-K36))) -> 0 | M35: =6049*4 -> 24196 | N35: =L35*M35/100 -> 0 | O35: =N35*0.529 -> 0 | P35: =O35*7.8 -> 0 | AC35: =Q35+T35+W35+Z35 -> 0 | AD35: =(R35+U35+X35+AA35)/4 -> 0 | AE35: =(S35+V35+Y35+AB35)/4 -> 0
C36: =IF(AC36>0,((B36-R36)+(S36-B37)),IF(B37=0, ,(B36-B37))) -> 0 | E36: =IF(AC36>0,((D36-U36)+(V36-D37)),IF(D37=0, ,(D36-D37))) -> 0 | G36: =IF(AC36>0,((F36-X36)+(Y36-F37)),IF(F37=0, ,(F36-F37))) -> 0 | I36: =IF(AC36>0,((H36-AA36)+(AB36-H37)),IF(H37=0, ,(H36-H37))) -> 0 | J36: =B36+D36+F36+H36 -> 0 | K36: =J36/4 -> 0 | L36: =IF(AC36>0,((K36-AD36)+(AE36-K37)),IF(K37=0, ,(K36-K37))) -> 0 | M36: =6049*4 -> 24196 | N36: =L36*M36/100 -> 0 | O36: =N36*0.529 -> 0 | P36: =O36*7.8 -> 0 | AC36: =Q36+T36+W36+Z36 -> 0 | AD36: =(R36+U36+X36+AA36)/4 -> 0 | AE36: =(S36+V36+Y36+AB36)/4 -> 0
C37: =IF(AC37>0,((B37-R37)+(S37-B38)),IF(B38=0, ,(B37-B38))) -> 0 | E37: =IF(AC37:AC60>0,((D37-U37)+(V37-D38)),IF(D38=0, ,(D37-D38))) -> 0 | G37: =IF(AC37>0,((F37-X37)+(Y37-F38)),IF(F38=0, ,(F37-F38))) -> 0 | I37: =IF(AC37>0,((H37-AA37)+(AB37-H38)),IF(H38=0, ,(H37-H38))) -> 0 | J37: =B37+D37+F37+H37 -> 0 | K37: =J37/4 -> 0 | L37: =IF(AC37>0,((K37-AD37)+(AE37-K38)),IF(K38=0, ,(K37-K38))) -> 0 | M37: =6049*4 -> 24196 | N37: =L37*M37/100 -> 0 | O37: =N37*0.529 -> 0 | P37: =O37*8 -> 0 | AC37: =Q37+T37+W37+Z37 -> 0 | AD37: =(R37+U37+X37+AA37)/4 -> 0 | AE37: =(S37+V37+Y37+AB37)/4 -> 0
C38: =IF(AC38>0,((B38-R38)+(S38-B39)),IF(B39=0, ,(B38-B39))) -> 0 | E38: =IF(AC38:AC61>0,((D38-U38)+(V38-D39)),IF(D39=0, ,(D38-D39))) -> 0 | G38: =IF(AC38>0,((F38-X38)+(Y38-F39)),IF(F39=0, ,(F38-F39))) -> 0 | I38: =IF(AC38>0,((H38-AA38)+(AB38-H39)),IF(H39=0, ,(H38-H39))) -> 0 | J38: =B38+D38+F38+H38 -> 0 | K38: =J38/4 -> 0 | L38: =IF(AC38>0,((K38-AD38)+(AE38-K39)),IF(K39=0, ,(K38-K39))) -> 0 | M38: =6049*4 -> 24196 | N38: =L38*M38/100 -> 0 | O38: =N38*0.53 -> 0 | P38: =O38*8 -> 0 | AC38: =Q38+T38+W38+Z38 -> 0 | AD38: =(R38+U38+X38+AA38)/4 -> 0 | AE38: =(S38+V38+Y38+AB38)/4 -> 0
C39: =IF(AC39>0,((B39-R39)+(S39-B40)),IF(B40=0, ,(B39-B40))) -> 0 | E39: =IF(AC39>0,((D39-U39)+(V39-D40)),IF(D40=0, ,(D39-D40))) -> 0 | G39: =IF(AC39>0,((F39-X39)+(Y39-F40)),IF(F40=0, ,(F39-F40))) -> 0 | I39: =IF(AC39>0,((H39-AA39)+(AB39-H40)),IF(H40=0, ,(H39-H40))) -> 0 | J39: =B39+D39+F39+H39 -> 0 | K39: =J39/4 -> 0 | L39: =IF(AC39>0,((K39-AD39)+(AE39-K40)),IF(K40=0, ,(K39-K40))) -> 0 | M39: =6049*4 -> 24196 | N39: =L39*M39/100 -> 0 | O39: =N39*0.53 -> 0 | P39: =O39*8 -> 0 | AC39: =Q39+T39+W39+Z39 -> 0 | AD39: =(R39+U39+X39+AA39)/4 -> 0 | AE39: =(S39+V39+Y39+AB39)/4 -> 0
C40: =IF(AC40>0,((B40-R40)+(S40-B41)),IF(B41=0, ,(B40-B41))) -> 0 | E40: =IF(AC40>0,((D40-U40)+(V40-D41)),IF(D41=0, ,(D40-D41))) -> 0 | G40: =IF(AC40>0,((F40-X40)+(Y40-F41)),IF(F41=0, ,(F40-F41))) -> 0 | I40: =IF(AC40>0,((H40-AA40)+(AB40-H41)),IF(H41=0, ,(H40-H41))) -> 0 | J40: =B40+D40+F40+H40 -> 0 | K40: =J40/4 -> 0 | L40: =IF(AC40>0,((K40-AD40)+(AE40-K41)),IF(K41=0, ,(K40-K41))) -> 0 | M40: =6049*4 -> 24196 | N40: =L40*M40/100 -> 0 | O40: =N40*0.53 -> 0 | P40: =O40*8 -> 0 | AC40: =Q40+T40+W40+Z40 -> 0 | AD40: =(R40+U40+X40+AA40)/4 -> 0 | AE40: =(S40+V40+Y40+AB40)/4 -> 0
...

Sheet Suivi EAU-ELEC
E1: Suivi Compteur d'Eau- électricité Lydec- July 2019 | J1: Département Engineering 2019
A7: Date/électriqie | B7: Incendie | D7: Eau m3 | F7: Electricité Kw/h
B8: Compteur | C8: Consommation | D8: Compteur | E8: Consommation | F8: Compteur H.Creuse | G8: Consommation H.Creuse | H8: Compteur H.Pleine | I8: Consommation H.Pleine | J8: Compteur H.Pointe | K8: Consommation H.Pointe
A9: 43647 | B9: 2375 | C9: 0 | D9: 34451.8 | E9: 319.8 | F9: 8385026 | G9: 4753 | H9: 14047255 | I9: 9058 | J9: 6272389 | K9: 3384
A10: 43648 | B10: 2375 | C10: =B10-B9 -> 0 | D10: 34621.5 | E10: =D10-D9 -> 169.7 | F10: 8389306 | G10: =F10-F9 -> 4280 | H10: 14055877 | I10: =H10-H9 -> 8622 | J10: 6275584 | K10: =J10-J9 -> 3195
A11: 43649 | B11: 2375 | C11: =B11-B10 -> 0 | D11: 34785.2 | E11: =D11-D10 -> 163.7 | F11: 8393519 | G11: =F11-F10 -> 4213 | H11: 14064533 | I11: =H11-H10 -> 8656 | J11: 6279017 | K11: =J11-J10 -> 3433
A12: 43650 | B12: 2375 | C12: =B12-B11 -> 0 | D12: 34979.5 | E12: =D12-D11 -> 194.3 | F12: 8397262 | G12: =F12-F11 -> 3743 | H12: 14074254 | I12: =H12-H11 -> 9721 | J12: 6282626 | K12: =J12-J11 -> 3609
A13: 43651 | B13: 2375 | C13: =B13-B12 -> 0 | D13: 35171 | E13: =D13-D12 -> 191.5 | F13: 8402272 | G13: =F13-F12 -> 5010 | H13: 14083559 | I13: =H13-H12 -> 9305 | J13: 6286160 | K13: =J13-J12 -> 3534
A14: 43652 | B14: 2375 | C14: =B14-B13 -> 0 | D14: 35356.9 | E14: =D14-D13 -> 185.9 | F14: 8406976 | G14: =F14-F13 -> 4704 | H14: 14093692 | I14: =H14-H13 -> 10133 | J14: 6289867 | K14: =J14-J13 -> 3707
A15: 43653 | B15: 2375 | C15: =B15-B14 -> 0 | D15: 35529.5 | E15: =D15-D14 -> 172.6 | F15: 8410965 | G15: =F15-F14 -> 3989 | H15: 14104130 | I15: =H15-H14 -> 10438 | J15: 6293228 | K15: =J15-J14 -> 3361
A16: 43654 | B16: 2375 | C16: =B16-B15 -> 0 | D16: 35681.1 | E16: =D16-D15 -> 151.6 | F16: 8415379 | G16: =F16-F15 -> 4414 | H16: 14114295 | I16: =H16-H15 -> 10165 | J16: 6296849 | K16: =J16-J15 -> 3621
A17: 43655 | B17: 2375 | C17: =B17-B16 -> 0 | D17: 35859 | E17: =D17-D16 -> 177.9 | F17: 8421191 | G17: =F17-F16 -> 5812 | H17: 14124668 | I17: =H17-H16 -> 10373 | J17: 6300698 | K17: =J17-J16 -> 3849
A18: 43656 | B18: 2375 | C18: =B18-B17 -> 0 | D18: 36051 | E18: =D18-D17 -> 192 | F18: 8426094 | G18: =F18-F17 -> 4903 | H18: 14134765 | I18: =H18-H17 -> 10097 | J18: 6304464 | K18: =J18-J17 -> 3766
A19: 43657 | B19: 2375 | C19: =B19-B18 -> 0 | D19: 36238 | E19: =D19-D18 -> 187 | F19: 8430878 | G19: =F19-F18 -> 4784 | H19: 14144111 | I19: =H19-H18 -> 9346 | J19: 6308347 | K19: =J19-J18 -> 3883
A20: 43658 | B20: 2375 | C20: =B20-B19 -> 0 | D20: 36420 | E20: =D20-D19 -> 182 | F20: 8436099 | G20: =F20-F19 -> 5221 | H20: 14154211 | I20: =H20-H19 -> 10100 | J20: 6312102 | K20: =J20-J19 -> 3755
A21: 43659 | B21: 2375 | C21: =B21-B20 -> 0 | D21: 36607 | E21: =D21-D20 -> 187 | F21: 8441611 | G21: =F21-F20 -> 5512 | H21: 14164446 | I21: =H21-H20 -> 10235 | J21: 6315977 | K21: =J21-J20 -> 3875
... A40: 43678 | B40: 2375 | C40: =B40-B39 -> 0 | D40: 39961 | E40: =D40-D39 -> 180 | F40: 8533950 | G40: =F40-F39 -> 4681 | H40: 14348108 | I40: =H40-H39 -> 9903 | J40: 6387956 | K40: =J40-J39 -> 3819

Sheet facture électricité
C1: Estimation de la consommation électrique Juillet 2019 | H1: Fiche technique
H3: DT fourseasons CBL
A7: N° de compteur | C7: Ancienne date de lecture | E7: Nouvelle date de lecture | F7: N de jours de consommation | G7: Heures pleines | H7: Heures creuses | I7: Heures de pointe
A8: 95670781 | C8: 43644 | E8: 43674 | F8: 30jours
A11: Type de comptage | C11: Puissance installée KVA | E11: Puissance souscrite KVA | G11: Puissance appelée KVA | I11: Dépassement de la puissance souscrite KVA
A12: 4T | C12: 3750 | E12: 1000 | G12: 1340
A16: Eléments de relève | C16: Nouvel Index | D16: Ancien Index | E16: Consommation | F16: Energie révaluée | G16: Consommation Compteur démarquant | I16: Energie à facturer
A17: HEURES PLEINE | C17: 14310036 | D17: 14017857 | E17: =MIN(C17-D17) -> 292179 | F17: =+E17 -> 292179 | I17: =+E17 -> 292179
A18: HEURES CREUSES | C18: 8511948 | D18: 8367617 | E18: =MIN(C18-D18) -> 144331 | F18: =+E18 -> 144331 | I18: =+E18 -> 144331
A19: HEURES DE POINTE | C19: 6373317 | D19: 6260526 | E19: =AVERAGE(C19-D19) -> 112791 | F19: =+E19 -> 112791 | I19: =+E19 -> 112791
A20: TOTAL | E20: =SUM(E17:E19) -> 549301
A23: Détail de la facture | D23: Quantité | E23: Prix unitaire | F23: Montant HT | G23: TVA | I23: Montant TTC
G24: Taux % | H24: Montant
A25: ENERGIE ACTIVE H. PLEINES | D25: =+E17 -> 292179 | E25: 0.9514 | F25: =PRODUCT(D25*E25) -> 277979.1 | G25: 14 | H25: =PRODUCT(0.14,F25) -> 38917.074 | I25: =SUM(H25,F25) -> 316896.17
A26: ENERGIE ACTIVE H. CREUSES | D26: =+E18 -> 144331 | E26: 0.6985 | F26: =PRODUCT(D26*E26) -> 100815.2 | G26: 14 | H26: =PRODUCT(0.14,F26) -> 14114.128 | I26: =SUM(H26,F26) -> 114929.33
A27: ENETGIE ACTIVE H. DE POINTE | D27: =+E19 -> 112791 | E27: 1.3304 | F27: =PRODUCT(D27*E27) -> 150057.15 | G27: 14 | H27: =PRODUCT(0.14,F27) -> 21008 | I27: =SUM(H27,F27) -> 171065.15
A28: REDEVANCE DE PUISSANCE | D28: 1000 | E28: 43.88167 | F28: =PRODUCT(D28,E28) -> 43881.67 | G28: 14 | H28: =PRODUCT(0.14,F28) -> 6143.4338 | I28: =SUM(H28,F28) -> 50025.104
A29: DEPASSEMENT DE PUISSANCE | D29: =G12-E12 -> 340 | E29: =E28*1.5 -> 65.822505 | F29: =PRODUCT(D29,E29) -> 22379.652 | G29: 14 | H29: =PRODUCT(0.14,F29) -> 3133.1512 | I29: =SUM(H29,F29) -> 25512.803
A30: ENTRETIEN COMPTAGE | F30: 841 | G30: 20 | H30: =PRODUCT(F30,0.2) -> 168.2 | I30: =SUM(H30,F30) -> 1009.2
A31: LOCATION COMPTAGE | F31: 1492 | G31: 7 | H31: =PRODUCT(F31,0.07) -> 104.44 | I31: =SUM(H31,F31) -> 1596.44
A32: Total | F32: =SUM(F25:F31) -> 597445.77 | I32: =SUM(I25:J31) -> 681034.2

Sheet Facture journalier D'élect
C1: Estimation de la consommation électrique July 2019 | H1: Fiche technique
H3: DT fourseasons CBL
A7: N° de compteur | C7: Ancienne date de lecture | E7: Nouvelle date de lecture | F7: N de jours de consommation | G7: Heures pleines | H7: Heures creuses | I7: Heures de pointe
A8: 95670781 | C8: 43662 | E8: 43663 | F8: 30jours
A11: Type de comptage | C11: Puissance installée KVA | E11: Puissance souscrite KVA | G11: Puissance appelée KVA | I11: Dépassement de la puissance souscrite KVA
A12: 4T | C12: 3750 | E12: 1000 | G12: 1359
A16: Eléments de relève | C16: Nouvel Index | D16: Ancien Index | E16: Consommation | F16: Energie révaluée | G16: Consommation Compteur démarquant | I16: Energie à facturer
A17: HEURES PLEINE | C17: 14203602 | D17: 14194385 | E17: =MIN(C17-D17) -> 9217 | F17: =+E17 -> 9217 | I17: =+E17 -> 9217
A18: HEURES CREUSES | C18: 8461312 | D18: 8456543 | E18: =MIN(C18-D18) -> 4769 | F18: =+E18 -> 4769 | I18: =+E18 -> 4769
A19: HEURES DE POINTE | C19: 6331806 | D19: 6328123 | E19: =AVERAGE(C19-D19) -> 3683 | F19: =+E19 -> 3683 | I19: =+E19 -> 3683
A20: TOTAL | E20: =SUM(E17:E19) -> 17669
A23: Détail de la facture | D23: Quantité | E23: Prix unitaire | F23: Montant HT | G23: TVA | I23: Montant TTC
G24: Taux % | H24: Montant
A25: ENERGIE ACTIVE H. PLEINES | D25: =+E17 -> 9217 | E25: 0.9514 | F25: =PRODUCT(D25*E25) -> 8769.0538 | G25: 14 | H25: =PRODUCT(0.14,F25) -> 1227.6675 | I25: =SUM(H25,F25) -> 9996.7213
A26: ENERGIE ACTIVE H. CREUSES | D26: =+E18 -> 4769 | E26: 0.6985 | F26: =PRODUCT(D26*E26) -> 3331.1465 | G26: 14 | H26: =PRODUCT(0.14,F26) -> 466.36051 | I26: =SUM(H26,F26) -> 3797.507
A27: ENETGIE ACTIVE H. DE POINTE | D27: =+E19 -> 3683 | E27: 1.3304 | F27: =PRODUCT(D27*E27) -> 4899.8632 | G27: 14 | H27: =PRODUCT(0.14,F27) -> 685.98085 | I27: =SUM(H27,F27) -> 5585.844
A28: REDEVANCE DE PUISSANCE | D28: 1000 | E28: 43.88167 | F28: =PRODUCT(D28,E28) -> 43881.67 | G28: 14 | H28: =PRODUCT(0.14,F28) -> 6143.4338 | I28: =SUM(H28,F28) -> 50025.104
A29: DEPASSEMENT DE PUISSANCE | D29: =G12-E12 -> 359 | E29: 48.97249 | F29: =PRODUCT(D29,E29) -> 17581.124 | G29: 14 | H29: =PRODUCT(0.14,F29) -> 2461.3573 | I29: =SUM(H29,F29) -> 20042.481
A30: ENTRETIEN COMPTAGE | F30: 841 | G30: 20 | H30: =PRODUCT(F30,0.2) -> 168.2 | I30: =SUM(H30,F30) -> 1009.2
A31: LOCATION COMPTAGE | F31: 1492 | G31: 7 | H31: =PRODUCT(F31,0.07) -> 104.44 | I31: =SUM(H31,F31) -> 1596.44
A32: Total | F32: =SUM(F25:F31) -> 80795.857 | I32: =SUM(I25:J31) -> 92053.297

Sheet facture d'eau
B1: Estimation de la consommation d'Eau Sanitaire July 2019 | F1: Fiche technique
F3: DT fourseasons CBL
A7: N° de compteur | B7: Type de relevé | C7: Ancien index | D7: Ancienne date de lecture | E7: Nouvel index | F7: Nouvelle date de lecture | G7: Consommation M3 | H7: N de jours de consommation
B8: RELEVEE | C8: 34451.8 | D8: 43647 | E8: 39961 | F8: 43678 | G8: =E8-C8 -> 5509.2
B10: Quantité | D10: Prix unitaire HT | F10: Montant HT
A11: Redevances Fixes | F11: 23
A12: Consommation eau
A13: Tranche unique | B13: =G8 -> 5509.2 | D13: 8.79 | F13: =PRODUCT(D13,B13) -> 48425.868
A14: Assainissement
A16: Tranche 1 | B16: 0 | D16: 0 | F16: =PRODUCT(D16,B16) -> 0
A17: Tranche 2 | B17: 0 | D17: 0 | F17: =PRODUCT(D17,B17) -> 0
A18: Tranche 3 | B18: 0 | D18: 0 | F18: =PRODUCT(D18,B18) -> 0
A19: Tranche 4 | B19: =G8 -> 5509.2 | D19: 2.61 | F19: =PRODUCT(D19,B19) -> 14379.012
A20: Total HT | F20: =SUM(F11+F13+F16+F17+F18+F19) -> 62827.88
A21: TVA 7% | F21: =PRODUCT(F20,0.07) -> 4397.9516
A22: Timbres Fiscaux | F22: 208.26
A23: Total Taxes | F23: =SUM(F21:H22) -> 4606.2116
A24: Net à payer | F24: =SUM(F20,F23) -> 67434.092

Sheet Facture journalier d'eau
B1: Estimation de la consommation d'Eau Sanitaire July 2019 | F1: Fiche technique
F3: DT fourseasons CBL
A7: N° de compteur | B7: Type de relevé | C7: Ancien index | D7: Ancienne date de lecture | E7: Nouvel index | F7: Nouvelle date de lecture | G7: Consommation M3 | H7: N de jours de consommation
B8: RELEVEE | C8: 36905.1 | D8: 43661 | E8: 37115.7 | F8: 43662 | G8: =E8-C8 -> 210.6
B10: Quantité | D10: Prix unitaire HT | F10: Montant HT
A11: Redevances Fixes | F11: 23
A12: Consommation eau
A13: Tranche unique | B13: =G8 -> 210.6 | D13: 8.5 | F13: =PRODUCT(D13,B13) -> 1790.1
A14: Assainissement
A16: Tranche 1 | B16: 0 | D16: 0 | F16: =PRODUCT(D16,B16) -> 0
A17: Tranche 2 | B17: 0 | D17: 0 | F17: =PRODUCT(D17,B17) -> 0
A18: Tranche 3 | B18: 0 | D18: 0 | F18: =PRODUCT(D18,B18) -> 0
A19: Tranche 4 | B19: 0 | D19: 0 | F19: 0
A20: Tranche 5 | B20: =G8 -> 210.6 | D20: 2.54 | F20: =PRODUCT(D20,B20) -> 534.924
A21: Total HT | F21: =SUM(F11+F13+F16+F17+F18+F20) -> 2348.024
A22: TVA 7% | F22: =PRODUCT(F21,0.07) -> 164.36168
A23: Timbres Fiscaux | F23: 208.26
A24: Total Taxes | F24: =SUM(F22:H23) -> 372.62168
A25: Net à payer | F25: =SUM(F21,F24) -> 2720.6457

Sheet facture incendie
B1: Estimation de la consommation d'Eau incendie July 2019 | F1: Fiche technique
F3: DT fourseasons CBL
A7: N° de compteur | B7: Type de relevé | C7: Ancien index | D7: Ancienne date de lecture | E7: Nouvel index | F7: Nouvelle date de lecture | G7: Consommation M3 | H7: N de jours de consommation
B8: RELEVEE | C8: 2375 | D8: 43647 | E8: 2375 | F8: 43678 | G8: =E8-C8 -> 0
B10: Quantité | D10: Prix unitaire HT | F10: Montant HT
A11: Redevances Fixes | F11: 15
A12: Consommation eau
A13: Tranche unique 1 | B13: =G8 -> 0 | D13: 16.48 | F13: =PRODUCT(D13,B13) -> 0
A14: Tranche unique 2
A15: Tranche unique 3
A16: Tranche unique 4
A17: Tranche unique 5
A18: Assainissement
A20: Tranche 1 | B20: 0 | D20: 0 | F20: =PRODUCT(D20,B20) -> 0
A21: Tranche 2 | B21: 0 | D21: 0 | F21: =PRODUCT(D21,B21) -> 0
A22: Tranche 3 | B22: 0 | D22: 0 | F22: =PRODUCT(D22,B22) -> 0
A23: Tranche 4 | B23: =G8 -> 0 | D23: 0 | F23: =PRODUCT(D23,B23) -> 0
A24: Tranche 5 | B24: 0 | D24: 2.54 | F24: =B24*D24 -> 0
A25: Total HT | F25: =SUM(F11+F13+F20+F21+F22+F23) -> 15
A26: TVA 7% | F26: 63.63
A27: Timbres Fiscaux | F27: 2.43
A28: Total Taxes | F28: =SUM(F26:H27) -> 66.06
A29: Net à payer | F29: =SUM(F25,F28) -> 81.06

Sheet cons annuel électr
C5: électricité en KW
C7: Janvier | D7: Février | E7: Mars | F7: avril | G7: Mai | H7: juin | I7: Juillet | J7: aout | K7: Septembre | L7: Octobre | M7: Novembre | N7: Décembre
B8: Année 2015 | L8: 544520 | M8: 561765 | N8: 546771
B9: Année 2016 | C9: 564170 | D9: 532072 | E9: 405239 | F9: 469130 | G9: 543877 | H9: 605744 | I9: 722083 | J9: 802210 | K9: 762933 | L9: 670848 | M9: 626451 | N9: 557392
B10: Année 2017 | C10: 520977 | D10: 541271 | E10: 508392 | F10: 659200 | G10: 705703 | H10: 784214 | I10: 823726 | J10: 913736 | K10: 831734 | L10: 794243 | M10: 688127 | N10: 577067
B11: Année 2018 | C11: 586355 | D11: 563735 | E11: 512313 | F11: 573440 | G11: 535115 | H11: 570139 | I11: 669302 | J11: 704714 | K11: 682717 | L11: 581239 | M11: 438561 | N11: 400672
B12: Année 2019 | C12: 388363 | D12: 407737 | E12: 392102 | F12: 454554 | G12: 448580 | H12: 535391 | I12: 549301
C13: électricité en DH HT
C15: Janvier | D15: Février | E15: Mars | F15: avril | G15: Mai | H15: juin | I15: Juillet | J15: aout | K15: Septembre | L15: Octobre | M15: Novembre | N15: Décembre
B16: Année 2015 | L16: 527344.76 | M16: 542887.95 | N16: 530789.1
B17: Année 2016 | C17: 577599.26 | D17: 549500.3 | E17: 437038.73 | F17: 498381.29 | G17: 567710.59 | H17: 626665.41 | I17: 732996.54 | J17: 807380.12 | K17: 765103.7 | L17: 674808.61 | M17: 636029.23 | N17: 575999.91
B18: Année 2017 | C18: 565777.06 | D18: 589465.87 | E18: 559348.97 | F18: 706566.83 | G18: 750048.77 | H18: 823657.04 | I18: 863911.21 | J18: 948371.74 | K18: 870086.49 | L18: 828237.33 | M18: 728226.36 | N18: 620794.43
B19: Année 2018 | C19: 629018.45 | D19: 609232.05 | E19: 564099.54 | F19: 625412.74 | G19: 591310.65 | H19: 627578.14 | I19: 723790.51 | J19: 756208.25 | K19: 734211.55 | L19: 634725.02 | M19: 492313.54 | N19: 430486.08
B20: Année 2019 | C20: 417767.5 | D20: 437511.45 | E20: 422948.91 | F20: 483026.43 | G20: 494466.66 | H20: 589026.66 | I20: 597445.77

Sheet cons annuel EAU  
C5: L'eau en M3
C7: Janvier | D7: Février | E7: Mars | F7: avril | G7: Mai | H7: juin | I7: Juillet | J7: aout | K7: Septembre | L7: Octobre | M7: Novembre | N7: Décembre
B8: Année 2015 | M8: 3298 | N8: 3866
B9: Année 2016 | C9: 4094 | D9: 3691 | E9: 3917 | F9: 4785 | G9: 5213 | H9: 4103 | I9: 5622 | J9: 6568 | K9: 4813 | L9: 6088 | M9: 4819 | N9: 5252
B10: Année 2017 | C10: 5132 | D10: 4589 | E10: 6190 | F10: 6170 | G10: 5980 | H10: 6097.8 | I10: 7050 | J10: 8050 | K10: 6678 | L10: 6859 | M10: 5960 | N10: 5210.1
B11: Année 2018 | C11: 5598.9 | D11: 5297 | E11: 5857 | F11: 6284 | G11: 5500 | H11: 5583.8 | I11: 6266.9 | J11: 6178.3 | K11: 6144.5 | L11: 6117.5 | M11: 5023 | N11: 4767.8
B12: Année 2019 | C12: 5044.8 | D12: 5061 | E12: 5504 | F12: 5372.3 | G12: 4507.3 | H12: 5269.2 | I12: 5509.2
C13: L'eau en DH HT
