Workbook

Sheet TOTAL
A1: Site Name | B1: Day | C1: Month | D1: Year | E1: Total Electricity Kwh | F1: Electricity Tariff ($/Kwh) | G1: LPG (Kg) | H1: LPG $/Kg | I1: Total Fuel Oil (Liters) | J1: Fuel Oil $/Liter | K1: Water Utility Supply (m3) m3 | L1: Water Utility Supply (m3) $/m3 | M1: Room Nights | N1: Food Covers | O1: Other fleets Petrol (Litres)
A2: Maldives at Landaa Giraavaru | B2: 1 | C2: 1 | D2: 2023 | E2: ='Submetering '!E2+'Submetering '!F2+'Submetering '!G2+'Submetering '!H2+'Submetering '!I2+'Submetering '!J2 -> 33144 | F2: 0.354 | G2: ='Maldives at LG Daily'!E5 -> 405 | H2: 1.24 | I2: ='Diesel consumption'!D5 -> 8380 | J2: 1.3 | K2: ='Maldives at LG Daily'!H5 -> 9389 | L2: 0 | M2: 96 | N2: ='Submetering '!BN2 -> 692 | O2: ='Diesel consumption'!H5+'Diesel consumption'!P5 -> 4200
A3: Maldives at Landaa Giraavaru | B3: 2 | C3: 1 | D3: 2023 | E3: ='Submetering '!E3+'Submetering '!F3+'Submetering '!G3+'Submetering '!H3+'Submetering '!I3+'Submetering '!J3 -> 32415 | F3: 0.354 | G3: ='Maldives at LG Daily'!E6 -> 270 | H3: 1.24 | I3: ='Diesel consumption'!D6 -> 8520 | J3: 1.3 | K3: ='Maldives at LG Daily'!H6 -> 9191 | L3: 0 | M3: 91 | N3: ='Submetering '!BN3 -> 701 | O3: ='Diesel consumption'!H6+'Diesel consumption'!P6 -> 1110
A4: Maldives at Landaa Giraavaru | B4: 3 | C4: 1 | D4: 2023 | E4: ='Submetering '!E4+'Submetering '!F4+'Submetering '!G4+'Submetering '!H4+'Submetering '!I4+'Submetering '!J4 -> 31874 | F4: 0.354 | G4: ='Maldives at LG Daily'!E7 -> 315 | H4: 1.24 | I4: ='Diesel consumption'!D7 -> 8110 | J4: 1.3 | K4: ='Maldives at LG Daily'!H7 -> 6813 | L4: 0 | M4: 91 | N4: ='Submetering '!BN4 -> 740 | O4: ='Diesel consumption'!H7+'Diesel consumption'!P7 -> 2200
A5: Maldives at Landaa Giraavaru | B5: 4 | C5: 1 | D5: 2023 | E5: ='Submetering '!E5+'Submetering '!F5+'Submetering '!G5+'Submetering '!H5+'Submetering '!I5+'Submetering '!J5 -> 31641 | F5: 0.354 | G5: ='Maldives at LG Daily'!E8 -> 270 | H5: 1.24 | I5: ='Diesel consumption'!D8 -> 8050 | J5: 1.3 | K5: ='Maldives at LG Daily'!H8 -> 10465 | L5: 0 | M5: 83 | N5: ='Submetering '!BN5 -> 647 | O5: ='Diesel consumption'!H8+'Diesel consumption'!P8 -> 260
A6: Maldives at Landaa Giraavaru | B6: 5 | C6: 1 | D6: 2023 | E6: ='Submetering '!E6+'Submetering '!F6+'Submetering '!G6+'Submetering '!H6+'Submetering '!I6+'Submetering '!J6 -> 31544 | F6: 0.354 | G6: ='Maldives at LG Daily'!E9 -> 360 | H6: 1.24 | I6: ='Diesel consumption'!D9 -> 8160 | J6: 1.3 | K6: ='Maldives at LG Daily'!H9 -> 9400 | L6: 0 | M6: 79 | N6: ='Submetering '!BN6 -> 639 | O6: ='Diesel consumption'!H9+'Diesel consumption'!P9 -> 3340
A7: Maldives at Landaa Giraavaru | B7: 6 | C7: 1 | D7: 2023 | E7: ='Submetering '!E7+'Submetering '!F7+'Submetering '!G7+'Submetering '!H7+'Submetering '!I7+'Submetering '!J7 -> 31798 | F7: 0.354 | G7: ='Maldives at LG Daily'!E10 -> 315 | H7: 1.24 | I7: ='Diesel consumption'!D10 -> 8160 | J7: 1.3 | K7: ='Maldives at LG Daily'!H10 -> 7536 | L7: 0 | M7: 69 | N7: ='Submetering '!BN7 -> 532 | O7: ='Diesel consumption'!H10+'Diesel consumption'!P10 -> 1750
A8: Maldives at Landaa Giraavaru | B8: 7 | C8: 1 | D8: 2023 | E8: ='Submetering '!E8+'Submetering '!F8+'Submetering '!G8+'Submetering '!H8+'Submetering '!I8+'Submetering '!J8 -> 30700 | F8: 0.354 | G8: ='Maldives at LG Daily'!E11 -> 270 | H8: 1.24 | I8: ='Diesel consumption'!D11 -> 7810 | J8: 1.3 | K8: ='Maldives at LG Daily'!H11 -> 8861 | L8: 0 | M8: 63 | N8: ='Submetering '!BN8 -> 539 | O8: ='Diesel consumption'!H11+'Diesel consumption'!P11 -> 140
A9: Maldives at Landaa Giraavaru | B9: 8 | C9: 1 | D9: 2023 | E9: ='Submetering '!E9+'Submetering '!F9+'Submetering '!G9+'Submetering '!H9+'Submetering '!I9+'Submetering '!J9 -> 29862 | F9: 0.354 | G9: ='Maldives at LG Daily'!E12 -> 315 | H9: 1.24 | I9: ='Diesel consumption'!D12 -> 7650 | J9: 1.3 | K9: ='Maldives at LG Daily'!H12 -> 7577 | L9: 0 | M9: 45 | N9: ='Submetering '!BN9 -> 334 | O9: ='Diesel consumption'!H12+'Diesel consumption'!P12 -> 1660
A10: Maldives at Landaa Giraavaru | B10: 9 | C10: 1 | D10: 2023 | E10: ='Submetering '!E10+'Submetering '!F10+'Submetering '!G10+'Submetering '!H10+'Submetering '!I10+'Submetering '!J10 -> 29322 | F10: 0.354 | G10: ='Maldives at LG Daily'!E13 -> 225 | H10: 1.24 | I10: ='Diesel consumption'!D13 -> 7300 | J10: 1.3 | K10: ='Maldives at LG Daily'!H13 -> 10197 | L10: 0 | M10: 44 | N10: ='Submetering '!BN10 -> 338 | O10: ='Diesel consumption'!H13+'Diesel consumption'!P13 -> 1640
A11: Maldives at Landaa Giraavaru | B11: 10 | C11: 1 | D11: 2023 | E11: ='Submetering '!E11+'Submetering '!F11+'Submetering '!G11+'Submetering '!H11+'Submetering '!I11+'Submetering '!J11 -> 28708 | F11: 0.354 | G11: ='Maldives at LG Daily'!E14 -> 270 | H11: 1.24 | I11: ='Diesel consumption'!D14 -> 7280 | J11: 1.3 | K11: ='Maldives at LG Daily'!H14 -> 6741 | L11: 0 | M11: 38 | N11: ='Submetering '!BN11 -> 285 | O11: ='Diesel consumption'!H14+'Diesel consumption'!P14 -> 1900
A12: Maldives at Landaa Giraavaru | B12: 11 | C12: 1 | D12: 2023 | E12: ='Submetering '!E12+'Submetering '!F12+'Submetering '!G12+'Submetering '!H12+'Submetering '!I12+'Submetering '!J12 -> 27709 | F12: 0.354 | G12: ='Maldives at LG Daily'!E15 -> 270 | H12: 1.24 | I12: ='Diesel consumption'!D15 -> 7340 | J12: 1.3 | K12: ='Maldives at LG Daily'!H15 -> 4793 | L12: 0 | M12: 42 | N12: ='Submetering '!BN12 -> 346 | O12: ='Diesel consumption'!H15+'Diesel consumption'!P15 -> 700
A13: Maldives at Landaa Giraavaru | B13: 12 | C13: 1 | D13: 2023 | E13: ='Submetering '!E13+'Submetering '!F13+'Submetering '!G13+'Submetering '!H13+'Submetering '!I13+'Submetering '!J13 -> 26452 | F13: 0.354 | G13: ='Maldives at LG Daily'!E16 -> 270 | H13: 1.24 | I13: ='Diesel consumption'!D16 -> 6740 | J13: 1.3 | K13: ='Maldives at LG Daily'!H16 -> 0 | L13: 0 | M13: 48 | N13: ='Submetering '!BN13 -> 372 | O13: ='Diesel consumption'!H16+'Diesel consumption'!P16 -> 1500
... A31: Maldives at Landaa Giraavaru | B31: 30 | C31: 1 | D31: 2023 | E31: ='Submetering '!E31+'Submetering '!F31+'Submetering '!G31+'Submetering '!H31+'Submetering '!I31+'Submetering '!J31 -> 26966 | F31: 0.354 | G31: ='Maldives at LG Daily'!E34 -> 315 | H31: 2.24 | I31: ='Diesel consumption'!D34 -> 6830 | J31: 1.3 | K31: ='Maldives at LG Daily'!H34 -> 14341 | L31: 1 | M31: 47 | N31: ='Submetering '!BN31 -> 302 | O31: ='Diesel consumption'!H34+'Diesel consumption'!P34 -> 2650
A32: Maldives at Landaa Giraavaru | B32: 31 | C32: 1 | D32: 2023 | E32: ='Submetering '!E32+'Submetering '!F32+'Submetering '!G32+'Submetering '!H32+'Submetering '!I32+'Submetering '!J32 -> 28139 | F32: 0.354 | G32: ='Maldives at LG Daily'!E35 -> 225 | H32: 1.24 | I32: ='Diesel consumption'!D35 -> 7010 | J32: 1.3 | K32: ='Maldives at LG Daily'!H36 -> 0 | L32: 0 | M32: 51 | N32: ='Submetering '!BN32 -> 317 | O32: ='Diesel consumption'!H35+'Diesel consumption'!P35 -> 2430
M33: =SUM(M2:M32) -> 1828 | N33: =SUM(N2:N32) -> 13333 | O33: =SUM(O2:O32) -> 64580

Sheet Submetering 
A1: Site Name | B1: Day | C1: Month | D1: Year | E1: Solar | F1: GENSET NO 1 | G1: GENSET NO 2 | H1: GENSET NO 3 | I1: GENSET NO 4 | J1: GENSET NO 5 | K1: Main BLU FEEDER PANEL 1 | L1: Main BLU FEEDER PANEL 2 | M1: Main POWER HOUSE FEEDER PANEL NO:3 | N1: Main Kitchen -7 | O1: Main Kitchen -10 | P1: Water treatment Plant | Q1: Sewage treatment Plant | R1: Laundry--8SSB (Machineries) | S1: Laundry-9 (HR/Tuck Shop Building) | T1: New staff accomodation (E0) | U1: Staff block-16(E2-E3) | V1: Staff Block Feeder-3(E4-E5) | W1: Management block-5 (M1 to M6) | X1: SNR STAFF BLOCK (PC Block) | Y1: BOAT DOCK FEEDER - 22 | Z1: RECEPTION Building Full (Finance/Reservation) | AA1: DIVE CENTER (Inc MDC and Recreation) | AB1: 301-307 | AC1: 308-314 | AD1: 315-320 | AE1: 401-407 | AF1: 408-414 | AG1: 415-420 | AH1: SPA - 1 | AI1: SPA - 2 | AJ1: BLU KITCHEN - 1 | AK1: BLU KITCHEN - 2 | AL1: AL BARAKATH | AM1: STAFF KITCHEN | AN1: R/O Plant A | AO1: R/O Plant B | AP1: R/O Plant C | AQ1: R/O Plant D | AR1: Laundry | AS1: Staff Block - E0 | AT1: Staff Block - E1 | AU1: Staff Block - E2 | AV1: Staff Block - E3 | AW1: Staff Block - E4 | AX1: Staff Block - E5 | AY1: Management Block | AZ1: PC Block | BA1: GM Bungalow | BB1: Boat Dock | BC1: Supply Jetty | BD1: Main Kitchen | BE1: Day Facility | BF1: Reception | BG1: Main Pool | BH1: Dive Center | BI1: Albarakthu | BJ1: Blu Resturant | BK1: Main Jetty | BL1: Landaa Estate | BM1: ROOM NIGHTS | BN1: Total Food Covers
A2: Maldives at Landaa Giraavaru | B2: 1 | C2: =TOTAL!C2 -> 1 | D2: =TOTAL!D2 -> 2023 | E2: ='SOLAR METER READING'!D9 -> 2990 | F2: ='Maldives at LG Daily'!G5 -> 6308 | G2: ='Maldives at LG Daily'!H5 -> 9389 | H2: ='Maldives at LG Daily'!I5 -> 5488 | I2: ='Maldives at LG Daily'!J5 -> 2984 | J2: ='Maldives at LG Daily'!K5 -> 5985 | K2: ='Maldives at LG Daily'!L5 -> 4416 | L2: ='Maldives at LG Daily'!M5 -> 4900 | M2: ='Maldives at LG Daily'!N5 -> 12450 | ... AM2: ='Maldives at LG Daily'!AN5 -> 1110 | AN2: ='Maldives at LG Daily'!AQ5 -> 243 | AO2: ='Maldives at LG Daily'!AR5 -> 73 | AP2: ='Maldives at LG Daily'!AS5 -> 0 | AQ2: ='Maldives at LG Daily'!AT5 -> 75 | AR2: ='Maldives at LG Daily'!AU5 -> 38 | AS2: ='Maldives at LG Daily'!AV5 -> 7 | AT2: ='Maldives at LG Daily'!AW5 -> 5 | AU2: ='Maldives at LG Daily'!AX5 -> 11 | ... BL2: ='Maldives at LG Daily'!BO5 -> 1 | BM2: ='Room Nights and Food Covers'!B5 -> 93.2 | BN2: ='Room Nights and Food Covers'!C5 -> 692
A3: Maldives at Landaa Giraavaru | B3: 2 | C3: =TOTAL!C3 -> 1 | D3: =TOTAL!D3 -> 2023 | E3: ='SOLAR METER READING'!D10 -> 3058 | F3: ='Maldives at LG Daily'!G6 -> 5796 | G3: ='Maldives at LG Daily'!H6 -> 9191 | H3: ='Maldives at LG Daily'!I6 -> 3869 | I3: ='Maldives at LG Daily'!J6 -> 4064 | J3: ='Maldives at LG Daily'!K6 -> 6437 | K3: ='Maldives at LG Daily'!L6 -> 4316 | L3: ='Maldives at LG Daily'!M6 -> 4766 | M3: ='Maldives at LG Daily'!N6 -> 12544 | ... AM3: ='Maldives at LG Daily'!AN6 -> 580 | AN3: ='Maldives at LG Daily'!AQ6 -> 216 | AO3: ='Maldives at LG Daily'!AR6 -> 91 | AP3: ='Maldives at LG Daily'!AS6 -> 0 | AQ3: ='Maldives at LG Daily'!AT6 -> 122 | AR3: ='Maldives at LG Daily'!AU6 -> 34 | AS3: ='Maldives at LG Daily'!AV6 -> 6 | AT3: ='Maldives at LG Daily'!AW6 -> 10 | AU3: ='Maldives at LG Daily'!AX6 -> 12 | ... BL3: ='Maldives at LG Daily'!BO6 -> 3 | BM3: ='Room Nights and Food Covers'!B6 -> 88.3 | BN3: ='Room Nights and Food Covers'!C6 -> 701
A4: Maldives at Landaa Giraavaru | B4: 3 | C4: =TOTAL!C4 -> 1 | D4: =TOTAL!D4 -> 2023 | E4: ='SOLAR METER READING'!D11 -> 2887 | F4: ='Maldives at LG Daily'!G7 -> 7321 | G4: ='Maldives at LG Daily'!H7 -> 6813 | H4: ='Maldives at LG Daily'!I7 -> 4139 | I4: ='Maldives at LG Daily'!J7 -> 3476 | J4: ='Maldives at LG Daily'!K7 -> 7238 | K4: ='Maldives at LG Daily'!L7 -> 4338 | L4: ='Maldives at LG Daily'!M7 -> 4664 | M4: ='Maldives at LG Daily'!N7 -> 12712 | ... AM4: ='Maldives at LG Daily'!AN7 -> 560 | AN4: ='Maldives at LG Daily'!AQ7 -> 195 | AO4: ='Maldives at LG Daily'!AR7 -> 85 | AP4: ='Maldives at LG Daily'!AS7 -> 0 | AQ4: ='Maldives at LG Daily'!AT7 -> 119 | AR4: ='Maldives at LG Daily'!AU7 -> 36 | AS4: ='Maldives at LG Daily'!AV7 -> 8 | AT4: ='Maldives at LG Daily'!AW7 -> 9 | AU4: ='Maldives at LG Daily'!AX7 -> 12 | ... BL4: ='Maldives at LG Daily'!BO7 -> 4 | BM4: ='Room Nights and Food Covers'!B7 -> 90.3 | BN4: ='Room Nights and Food Covers'!C7 -> 740
A5: Maldives at Landaa Giraavaru | B5: 4 | C5: =TOTAL!C5 -> 1 | D5: =TOTAL!D5 -> 2023 | E5: ='SOLAR METER READING'!D12 -> 3027 | F5: ='Maldives at LG Daily'!G8 -> 4960 | G5: ='Maldives at LG Daily'!H8 -> 10465 | H5: ='Maldives at LG Daily'!I8 -> 3888 | I5: ='Maldives at LG Daily'!J8 -> 3021 | J5: ='Maldives at LG Daily'!K8 -> 6280 | K5: ='Maldives at LG Daily'!L8 -> 4349 | L5: ='Maldives at LG Daily'!M8 -> 4661 | M5: ='Maldives at LG Daily'!N8 -> 11714 | ... AM5: ='Maldives at LG Daily'!AN8 -> 570 | AN5: ='Maldives at LG Daily'!AQ8 -> 187 | AO5: ='Maldives at LG Daily'!AR8 -> 15 | AP5: ='Maldives at LG Daily'!AS8 -> 179 | AQ5: ='Maldives at LG Daily'!AT8 -> 84 | AR5: ='Maldives at LG Daily'!AU8 -> 32 | AS5: ='Maldives at LG Daily'!AV8 -> 6 | AT5: ='Maldives at LG Daily'!AW8 -> 10 | AU5: ='Maldives at LG Daily'!AX8 -> 13 | ... BL5: ='Maldives at LG Daily'!BO8 -> 2 | BM5: ='Room Nights and Food Covers'!B8 -> 81.6 | BN5: ='Room Nights and Food Covers'!C8 -> 647
A6: Maldives at Landaa Giraavaru | B6: 5 | C6: =TOTAL!C6 -> 1 | D6: =TOTAL!D6 -> 2023 | E6: ='SOLAR METER READING'!D13 -> 2794 | F6: ='Maldives at LG Daily'!G9 -> 5580 | G6: ='Maldives at LG Daily'!H9 -> 9400 | H6: ='Maldives at LG Daily'!I9 -> 4621 | I6: ='Maldives at LG Daily'!J9 -> 1945 | J6: ='Maldives at LG Daily'!K9 -> 7204 | K6: ='Maldives at LG Daily'!L9 -> 4138 | L6: ='Maldives at LG Daily'!M9 -> 4769 | M6: ='Maldives at LG Daily'!N9 -> 12322 | ... AM6: ='Maldives at LG Daily'!AN9 -> 520 | AN6: ='Maldives at LG Daily'!AQ9 -> 180 | AO6: ='Maldives at LG Daily'!AR9 -> 67 | AP6: ='Maldives at LG Daily'!AS9 -> 166 | AQ6: ='Maldives at LG Daily'!AT9 -> 7 | AR6: ='Maldives at LG Daily'!AU9 -> 34 | AS6: ='Maldives at LG Daily'!AV9 -> 7 | AT6: ='Maldives at LG Daily'!AW9 -> 9 | AU6: ='Maldives at LG Daily'!AX9 -> 12 | ... BL6: ='Maldives at LG Daily'!BO9 -> 14 | BM6: ='Room Nights and Food Covers'!B9 -> 77.7 | BN6: ='Room Nights and Food Covers'!C9 -> 639
A7: Maldives at Landaa Giraavaru | B7: 6 | C7: =TOTAL!C7 -> 1 | D7: =TOTAL!D7 -> 2023 | E7: ='SOLAR METER READING'!D14 -> 2867 | F7: ='Maldives at LG Daily'!G10 -> 7411 | G7: ='Maldives at LG Daily'!H10 -> 7536 | H7: ='Maldives at LG Daily'!I10 -> 2796 | I7: ='Maldives at LG Daily'!J10 -> 3476 | J7: ='Maldives at LG Daily'!K10 -> 7712 | K7: ='Maldives at LG Daily'!L10 -> 4423 | L7: ='Maldives at LG Daily'!M10 -> 4621 | M7: ='Maldives at LG Daily'!N10 -> 12388 | ... AM7: ='Maldives at LG Daily'!AN10 -> 570 | AN7: ='Maldives at LG Daily'!AQ10 -> 89 | AO7: ='Maldives at LG Daily'!AR10 -> 42 | AP7: ='Maldives at LG Daily'!AS10 -> 182 | AQ7: ='Maldives at LG Daily'!AT10 -> 62 | AR7: ='Maldives at LG Daily'!AU10 -> 34 | AS7: ='Maldives at LG Daily'!AV10 -> 7 | AT7: ='Maldives at LG Daily'!AW10 -> 11 | AU7: ='Maldives at LG Daily'!AX10 -> 15 | ... BL7: ='Maldives at LG Daily'!BO10 -> 2 | BM7: ='Room Nights and Food Covers'!B10 -> 67 | BN7: ='Room Nights and Food Covers'!C10 -> 532
A8: Maldives at Landaa Giraavaru | B8: 7 | C8: =TOTAL!C8 -> 1 | D8: =TOTAL!D8 -> 2023 | E8: ='SOLAR METER READING'!D15 -> 2807 | F8: ='Maldives at LG Daily'!G11 -> 6511 | G8: ='Maldives at LG Daily'!H11 -> 8861 | H8: ='Maldives at LG Daily'!I11 -> 2573 | I8: ='Maldives at LG Daily'!J11 -> 2473 | J8: ='Maldives at LG Daily'!K11 -> 7475 | K8: ='Maldives at LG Daily'!L11 -> 4356 | L8: ='Maldives at LG Daily'!M11 -> 4463 | M8: ='Maldives at LG Daily'!N11 -> 12336 | ... AM8: ='Maldives at LG Daily'!AN11 -> 540 | AN8: ='Maldives at LG Daily'!AQ11 -> 153 | AO8: ='Maldives at LG Daily'!AR11 -> 53 | AP8: ='Maldives at LG Daily'!AS11 -> 101 | AQ8: ='Maldives at LG Daily'!AT11 -> 0 | AR8: ='Maldives at LG Daily'!AU11 -> 35 | AS8: ='Maldives at LG Daily'!AV11 -> 8 | AT8: ='Maldives at LG Daily'!AW11 -> 10 | AU8: ='Maldives at LG Daily'!AX11 -> 13 | ... BL8: ='Maldives at LG Daily'!BO11 -> 2 | BM8: ='Room Nights and Food Covers'!B11 -> 61.2 | BN8: ='Room Nights and Food Covers'!C11 -> 539
A9: Maldives at Landaa Giraavaru | B9: 8 | C9: =TOTAL!C9 -> 1 | D9: =TOTAL!D9 -> 2023 | E9: ='SOLAR METER READING'!D16 -> 2972 | F9: ='Maldives at LG Daily'!G12 -> 6893 | G9: ='Maldives at LG Daily'!H12 -> 7577 | H9: ='Maldives at LG Daily'!I12 -> 3036 | I9: ='Maldives at LG Daily'!J12 -> 2179 | J9: ='Maldives at LG Daily'!K12 -> 7205 | K9: ='Maldives at LG Daily'!L12 -> 4075 | L9: ='Maldives at LG Daily'!M12 -> 4494 | M9: ='Maldives at LG Daily'!N12 -> 11206 | ... AM9: ='Maldives at LG Daily'!AN12 -> 510 | AN9: ='Maldives at LG Daily'!AQ12 -> 169 | AO9: ='Maldives at LG Daily'!AR12 -> 10 | AP9: ='Maldives at LG Daily'!AS12 -> 125 | AQ9: ='Maldives at LG Daily'!AT12 -> 0 | AR9: ='Maldives at LG Daily'!AU12 -> 32 | AS9: ='Maldives at LG Daily'!AV12 -> 6 | AT9: ='Maldives at LG Daily'!AW12 -> 9 | AU9: ='Maldives at LG Daily'!AX12 -> 12 | ... BL9: ='Maldives at LG Daily'!BO12 -> 2 | BM9: ='Room Nights and Food Covers'!B12 -> 43.7 | BN9: ='Room Nights and Food Covers'!C12 -> 334
A10: Maldives at Landaa Giraavaru | B10: 9 | C10: =TOTAL!C10 -> 1 | D10: =TOTAL!D10 -> 2023 | E10: ='SOLAR METER READING'!D17 -> 2822 | F10: ='Maldives at LG Daily'!G13 -> 0 | G10: ='Maldives at LG Daily'!H13 -> 10197 | H10: ='Maldives at LG Daily'!I13 -> 7274 | I10: ='Maldives at LG Daily'!J13 -> 3110 | J10: ='Maldives at LG Daily'!K13 -> 5919 | K10: ='Maldives at LG Daily'!L13 -> 3970 | L10: ='Maldives at LG Daily'!M13 -> 4695 | M10: ='Maldives at LG Daily'!N13 -> 11415 | ... AM10: ='Maldives at LG Daily'!AN13 -> 560 | AN10: ='Maldives at LG Daily'!AQ13 -> 182 | AO10: ='Maldives at LG Daily'!AR13 -> 0 | AP10: ='Maldives at LG Daily'!AS13 -> 149 | AQ10: ='Maldives at LG Daily'!AT13 -> 0 | AR10: ='Maldives at LG Daily'!AU13 -> 31 | AS10: ='Maldives at LG Daily'!AV13 -> 6 | AT10: ='Maldives at LG Daily'!AW13 -> 10 | AU10: ='Maldives at LG Daily'!AX13 -> 11 | ... BL10: ='Maldives at LG Daily'!BO13 -> 3 | BM10: ='Room Nights and Food Covers'!B13 -> 42.7 | BN10: ='Room Nights and Food Covers'!C13 -> 338
A11: Maldives at Landaa Giraavaru | B11: 10 | C11: =TOTAL!C11 -> 1 | D11: =TOTAL!D11 -> 2023 | E11: ='SOLAR METER READING'!D18 -> 2734 | F11: ='Maldives at LG Daily'!G14 -> 7687 | G11: ='Maldives at LG Daily'!H14 -> 6741 | H11: ='Maldives at LG Daily'!I14 -> 15 | I11: ='Maldives at LG Daily'!J14 -> 3666 | J11: ='Maldives at LG Daily'!K14 -> 7865 | K11: ='Maldives at LG Daily'!L14 -> 3839 | L11: ='Maldives at LG Daily'!M14 -> 4138 | M11: ='Maldives at LG Daily'!N14 -> 11193 | ... AM11: ='Maldives at LG Daily'!AN14 -> 520 | AN11: ='Maldives at LG Daily'!AQ14 -> 181 | AO11: ='Maldives at LG Daily'!AR14 -> 0 | AP11: ='Maldives at LG Daily'!AS14 -> 125 | AQ11: ='Maldives at LG Daily'!AT14 -> 0 | AR11: ='Maldives at LG Daily'!AU14 -> 26 | AS11: ='Maldives at LG Daily'!AV14 -> 7 | AT11: ='Maldives at LG Daily'!AW14 -> 10 | AU11: ='Maldives at LG Daily'!AX14 -> 13 | ... BL11: ='Maldives at LG Daily'!BO14 -> 1 | BM11: ='Room Nights and Food Covers'!B14 -> 35 | BN11: ='Room Nights and Food Covers'!C14 -> 285
A12: Maldives at Landaa Giraavaru | B12: 11 | C12: =TOTAL!C12 -> 1 | D12: =TOTAL!D12 -> 2023 | E12: ='SOLAR METER READING'!D19 -> 2817 | F12: ='Maldives at LG Daily'!G15 -> 7264 | G12: ='Maldives at LG Daily'!H15 -> 4793 | H12: ='Maldives at LG Daily'!I15 -> 2625 | I12: ='Maldives at LG Daily'!J15 -> 4780 | J12: ='Maldives at LG Daily'!K15 -> 5430 | K12: ='Maldives at LG Daily'!L15 -> 3629 | L12: ='Maldives at LG Daily'!M15 -> 3859 | M12: ='Maldives at LG Daily'!N15 -> 10932 | ... AM12: ='Maldives at LG Daily'!AN15 -> 530 | AN12: ='Maldives at LG Daily'!AQ15 -> 175 | AO12: ='Maldives at LG Daily'!AR15 -> 31 | AP12: ='Maldives at LG Daily'!AS15 -> 132 | AQ12: ='Maldives at LG Daily'!AT15 -> 0 | AR12: ='Maldives at LG Daily'!AU15 -> 24 | AS12: ='Maldives at LG Daily'!AV15 -> 6 | AT12: ='Maldives at LG Daily'!AW15 -> 10 | AU12: ='Maldives at LG Daily'!AX15 -> 10 | ... BL12: ='Maldives at LG Daily'!BO15 -> 2 | BM12: ='Room Nights and Food Covers'!B15 -> 40.8 | BN12: ='Room Nights and Food Covers'!C15 -> 346
A13: Maldives at Landaa Giraavaru | B13: 12 | C13: =TOTAL!C13 -> 1 | D13: =TOTAL!D13 -> 2023 | E13: ='SOLAR METER READING'!D20 -> 2161 | F13: ='Maldives at LG Daily'!G16 -> 7040 | G13: ='Maldives at LG Daily'!H16 -> 0 | H13: ='Maldives at LG Daily'!I16 -> 3473 | I13: ='Maldives at LG Daily'!J16 -> 2892 | J13: ='Maldives at LG Daily'!K16 -> 10886 | K13: ='Maldives at LG Daily'!L16 -> 3458 | L13: ='Maldives at LG Daily'!M16 -> 3569 | M13: ='Maldives at LG Daily'!N16 -> 11155 | ... AM13: ='Maldives at LG Daily'!AN16 -> 520 | AN13: ='Maldives at LG Daily'!AQ16 -> 169 | AO13: ='Maldives at LG Daily'!AR16 -> 21 | AP13: ='Maldives at LG Daily'!AS16 -> 120 | AQ13: ='Maldives at LG Daily'!AT16 -> 0 | AR13: ='Maldives at LG Daily'!AU16 -> 28 | AS13: ='Maldives at LG Daily'!AV16 -> 5 | AT13: ='Maldives at LG Daily'!AW16 -> 10 | AU13: ='Maldives at LG Daily'!AX16 -> 11 | ... BL13: ='Maldives at LG Daily'!BO16 -> 8 | BM13: ='Room Nights and Food Covers'!B16 -> 46.6 | BN13: ='Room Nights and Food Covers'!C16 -> 372
... A32: Maldives at Landaa Giraavaru | B32: 31 | C32: =TOTAL!C32 -> 1 | D32: =TOTAL!D32 -> 2023 | E32: ='SOLAR METER READING'!D39 -> 2921 | F32: ='Maldives at LG Daily'!G35 -> 5489 | G32: ='Maldives at LG Daily'!H35 -> 9630 | H32: ='Maldives at LG Daily'!I35 -> 0 | I32: ='Maldives at LG Daily'!J35 -> 3232 | J32: ='Maldives at LG Daily'!K35 -> 6867 | K32: ='Maldives at LG Daily'!L35 -> 3801 | L32: ='Maldives at LG Daily'!M35 -> 4077 | M32: ='Maldives at LG Daily'!N35 -> 10874 | ... AM32: ='Maldives at LG Daily'!AN35 -> 530 | AN32: ='Maldives at LG Daily'!AQ35 -> 173 | AO32: ='Maldives at LG Daily'!AR35 -> 0 | AP32: ='Maldives at LG Daily'!AS35 -> 139 | AQ32: ='Maldives at LG Daily'!AT35 -> 0 | AR32: ='Maldives at LG Daily'!AU35 -> 28 | AS32: ='Maldives at LG Daily'!AV35 -> 6 | AT32: ='Maldives at LG Daily'!AW35 -> 10 | AU32: ='Maldives at LG Daily'!AX35 -> 11 | ... BL32: ='Maldives at LG Daily'!BO35 -> 0 | BM32: ='Room Nights and Food Covers'!B35 -> 49.5 | BN32: ='Room Nights and Food Covers'!C35 -> 317

Sheet Maldives at LG Daily
A2: Days | C2: Electricity Meter (KWh) | E2: Gas Kg | G2: GENSET NO 1 | H2: GENSET NO 2 | I2: GENSET NO 3 | J2: GENSET NO 4 | K2: GENSET NO 5 | L2: Main BLU FEEDER PANEL 1 | M2: Main BLU FEEDER PANEL 2 | N2: Main POWER HOUSE FEEDER PANEL NO:3 | O2: Main Kitchen -7 | P2: Main Kitchen -10 | Q2: Water treatment Plant | R2: Sewage treatment Plant | S2: Laundry--8SSB (Machineries) | T2: Laundry-9 (HR/Tuck Shop Building) | U2: New staff accomodation (E0) | V2: Staff block-16(E2-E3) | W2: Staff Block Feeder-3(E4-E5) | X2: Management block-5 (M1 to M6) | Y2: SNR STAFF BLOCK (PC Block) | Z2: BOAT DOCK FEEDER - 22 | AA2: RECEPTION Building Full (Finance/Reservation) | AB2: DIVE CENTER (Inc MDC and Recreation) | AC2: 301-307 | AD2: 308-314 | AE2: 315-320 | AF2: 401-407 | AG2: 408-414 | AH2: 415-420 | AI2: SPA - 1 | AJ2: SPA - 2 | AK2: BLU KITCHEN - 1 | AL2: BLU KITCHEN - 2 | AM2: AL BARAKATH | AN2: STAFF KITCHEN | AO2: Water m3 | AQ2: R/O Plant A | AR2: R/O Plant B | AS2: R/O Plant C | AT2: R/O Plant D | AU2: Laundry | AV2: Staff Block - E0 | AW2: Staff Block - E1 | AX2: Staff Block - E2 | AY2: Staff Block - E3 | AZ2: Staff Block - E4 | BA2: Staff Block - E5 | BB2: Management Block | BC2: PC Block | BD2: GM Bungalow | BE2: Boat Dock | BF2: Supply Jetty | BG2: Main Kitchen | BH2: Day Facility | BI2: Reception | BJ2: Main Pool | BK2: Dive Center | BL2: Albarakthu | BM2: Blu Resturant | BN2: Main Jetty | BO2: Landaa Estate
A3: Date | C3: Reading KWH | D3: Difference KWH | E3: Reading Kg | F3: Difference Kg | G3: KWh | H3: KWh | I3: KWh | J3: KWh | K3: KWh | L3: KWh | M3: KWh | N3: KWh | O3: KWh | P3: KWh | Q3: KWh | R3: KWh | S3: KWh | T3: KWh | U3: KWh | V3: KWh | W3: KWh | X3: KWh | Y3: KWh | Z3: KWh | AA3: KWh | AB3: KWh | AC3: KWh | AD3: KWh | AE3: KWh | AF3: KWh | AG3: KWh | AH3: KWh | AI3: KWh | AJ3: KWh | AK3: KWh | AL3: KWh | AM3: KWh | AN3: KWh | AO3: Reading m³ | AP3: Daily Consumption m³ | AQ3: Daily Consumption m³ | AR3: Daily Consumption m³ | AS3: Daily Consumption m³ | AT3: Daily Consumption m³ | AU3: Daily Consumption m³ | AV3: Daily Consumption m³ | AW3: Daily Consumption m³ | AX3: Daily Consumption m³ | AY3: Daily Consumption m³ | AZ3: Daily Consumption m³ | BA3: Daily Consumption m³ | BB3: Daily Consumption m³ | BC3: Daily Consumption m³ | BD3: Daily Consumption m³ | BE3: Daily Consumption m³ | BF3: Daily Consumption m³ | BG3: Daily Consumption m³ | BH3: Daily Consumption m³ | BI3: Daily Consumption m³ | BJ3: Daily Consumption m³ | BK3: Daily Consumption m³ | BL3: Daily Consumption m³ | BM3: Daily Consumption m³ | BN3: Daily Consumption m³ | BO3: Daily Consumption m³ | BP3: ROOM NIGHTS | BQ3: Total Food Covers
A4: 44926 | C4: 105508122 | E4: ='[1]Gas-2'!G5 -> 0 | F4: 90 | AO4: 1143399 | AP4: 318 | BP4: ='Room Nights and Food Covers'!B4 -> 0 | BQ4: ='Room Nights and Food Covers'!C4 -> 0
A5: =A4+1 -> 44927 | C5: =SUM('GENSET #1'!C10+'GENSET #2'!C10+'GENSET #3'!C10+'GENSET #4'!C10+'GENSET #5'!C10) -> 105538276 | D5: =IF((C5-C4<0), "0",C5-C4) -> 30154 | E5: ='Gas-2'!G6 -> 405 | F5: =IF((E5-E4<0), "0",E5-E4) -> 405 | G5: ='GENSET #1'!D10 -> 6308 | H5: ='GENSET #2'!D10 -> 9389 | I5: ='GENSET #3'!D10 -> 5488 | J5: ='GENSET #4'!D10 -> 2984 | K5: ='GENSET #5'!D10 -> 5985 | L5: ='FEEDER Consumption '!E5 -> 4416 | M5: ='FEEDER Consumption '!J5 -> 4900 | N5: ='FEEDER Consumption '!O5 -> 12450 | O5: ='FEEDER Consumption '!T5 -> 2500 | P5: ='FEEDER Consumption '!Y5 -> 3072 | Q5: ='FEEDER Consumption '!AD5 -> 2200 | R5: ='FEEDER Consumption '!AJ5 -> 484 | S5: ='FEEDER Consumption '!AO5 -> 700 | T5: ='FEEDER Consumption '!AT5 -> 2900 | U5: ='FEEDER Consumption '!AY5 -> 417 | V5: ='FEEDER Consumption '!BI5 -> 300 | W5: ='FEEDER Consumption '!BI5 -> 300 | X5: ='FEEDER Consumption '!BN5 -> 500 | Y5: ='FEEDER Consumption '!BS5 -> 200 | Z5: ='FEEDER Consumption '!BX5 -> 350 | AA5: ='FEEDER Consumption '!CC5 -> 1200 | AB5: ='FEEDER Consumption '!CH5 -> 430 | AC5: ='FEEDER Consumption '!CM5 -> 1100 | AD5: ='FEEDER Consumption '!CR5 -> 1090 | AE5: ='FEEDER Consumption '!DB5 -> 1100 | AF5: ='FEEDER Consumption '!DB5 -> 1100 | AG5: ='FEEDER Consumption '!DG5 -> 910 | AH5: ='FEEDER Consumption '!DL5 -> 730 | AI5: ='FEEDER Consumption '!DQ5 -> 390 | AJ5: ='FEEDER Consumption '!DV5 -> 150 | AK5: ='FEEDER Consumption '!EA5 -> 1030 | AL5: ='FEEDER Consumption '!EF5 -> 290 | AM5: ='FEEDER Consumption '!EK5 -> 720 | AN5: ='FEEDER Consumption '!EP5 -> 1110 | AO5: =SUM(WATER!C6,WATER!H6,WATER!M6,WATER!R6) -> 1154541 | AP5: =IF((AO5-AO4<0), "0",AO5-AO4) -> 11142 | AQ5: =WATER!D6 -> 243 | AR5: =WATER!I6 -> 73 | AS5: =WATER!N6 -> 0 | AT5: =WATER!S6 -> 75 | AU5: =WATER!AD6 -> 38 | AV5: =WATER!AI6 -> 7 | AW5: =WATER!AN6 -> 5 | AX5: =WATER!AS6 -> 11 | AY5: =WATER!AX6 -> 9 | AZ5: =WATER!BC6 -> 6 | BA5: =WATER!BH6 -> 8 | BB5: =WATER!BM6 -> 8 | BC5: =WATER!BR6 -> 4 | BD5: =WATER!BW6 -> 0 | BE5: =WATER!CB6 -> 3 | BF5: =WATER!CG6 -> 2 | BG5: =WATER!CL6 -> 33 | BH5: =WATER!CQ6 -> 7 | BI5: =WATER!CV6 -> 1 | BJ5: =WATER!DA6 -> 7 | BK5: =WATER!DF6 -> 3 | BL5: =WATER!DK6 -> 2 | BM5: =WATER!DP6 -> 19 | BN5: =WATER!DU6 -> 0 | BO5: =WATER!DZ6 -> 1 | BP5: ='Room Nights and Food Covers'!B5 -> 93.2 | BQ5: ='Room Nights and Food Covers'!C5 -> 692
A6: =A5+1 -> 44928 | C6: =SUM('GENSET #1'!C11+'GENSET #2'!C11+'GENSET #3'!C11+'GENSET #4'!C11+'GENSET #5'!C11) -> 105567633 | D6: =IF((C6-C5<0), "0",C6-C5) -> 29357 | E6: ='Gas-2'!G7 -> 270 | F6: =IF((E6-E5<0), "0",E6-E5) -> 0 | G6: ='GENSET #1'!D11 -> 5796 | H6: ='GENSET #2'!D11 -> 9191 | I6: ='GENSET #3'!D11 -> 3869 | J6: ='GENSET #4'!D11 -> 4064 | K6: ='GENSET #5'!D11 -> 6437 | L6: ='FEEDER Consumption '!E6 -> 4316 | M6: ='FEEDER Consumption '!J6 -> 4766 | N6: ='FEEDER Consumption '!O6 -> 12544 | O6: ='FEEDER Consumption '!T6 -> 2400 | P6: ='FEEDER Consumption '!Y6 -> 3068 | Q6: ='FEEDER Consumption '!AD6 -> 2400 | R6: ='FEEDER Consumption '!AJ6 -> 465 | S6: ='FEEDER Consumption '!AO6 -> 700 | T6: ='FEEDER Consumption '!AT6 -> 2800 | U6: ='FEEDER Consumption '!AY6 -> 438 | V6: ='FEEDER Consumption '!BI6 -> 300 | W6: ='FEEDER Consumption '!BI6 -> 300 | X6: ='FEEDER Consumption '!BN6 -> 600 | Y6: ='FEEDER Consumption '!BS6 -> 130 | Z6: ='FEEDER Consumption '!BX6 -> 360 | AA6: ='FEEDER Consumption '!CC6 -> 1200 | AB6: ='FEEDER Consumption '!CH6 -> 510 | AC6: ='FEEDER Consumption '!CM6 -> 1180 | AD6: ='FEEDER Consumption '!CR6 -> 1070 | AE6: ='FEEDER Consumption '!DB6 -> 1100 | AF6: ='FEEDER Consumption '!DB6 -> 1100 | AG6: ='FEEDER Consumption '!DG6 -> 880 | AH6: ='FEEDER Consumption '!DL6 -> 630 | AI6: ='FEEDER Consumption '!DQ6 -> 320 | AJ6: ='FEEDER Consumption '!DV6 -> 170 | AK6: ='FEEDER Consumption '!EA6 -> 1010 | AL6: ='FEEDER Consumption '!EF6 -> 310 | AM6: ='FEEDER Consumption '!EK6 -> 350 | AN6: ='FEEDER Consumption '!EP6 -> 580 | AO6: =SUM(WATER!C7,WATER!H7,WATER!M7,WATER!R7) -> 1154970 | AP6: =IF((AO6-AO5<0), "0",AO6-AO5) -> 429 | AQ6: =WATER!D7 -> 216 | AR6: =WATER!I7 -> 91 | AS6: =WATER!N7 -> 0 | AT6: =WATER!S7 -> 122 | AU6: =WATER!AD7 -> 34 | AV6: =WATER!AI7 -> 6 | AW6: =WATER!AN7 -> 10 | AX6: =WATER!AS7 -> 12 | AY6: =WATER!AX7 -> 9 | AZ6: =WATER!BC7 -> 7 | BA6: =WATER!BH7 -> 9 | BB6: =WATER!BM7 -> 10 | BC6: =WATER!BR7 -> 2 | BD6: =WATER!BW7 -> 0 | BE6: =WATER!CB7 -> 3 | BF6: =WATER!CG7 -> 4 | BG6: =WATER!CL7 -> 36 | BH6: =WATER!CQ7 -> 14 | BI6: =WATER!CV7 -> 2 | BJ6: =WATER!DA7 -> 4 | BK6: =WATER!DF7 -> 4 | BL6: =WATER!DK7 -> 6 | BM6: =WATER!DP7 -> 21 | BN6: =WATER!DU7 -> 7 | BO6: =WATER!DZ7 -> 3 | BP6: ='Room Nights and Food Covers'!B6 -> 88.3 | BQ6: ='Room Nights and Food Covers'!C6 -> 701
A7: =A6+1 -> 44929 | C7: =SUM('GENSET #1'!C12+'GENSET #2'!C12+'GENSET #3'!C12+'GENSET #4'!C12+'GENSET #5'!C12) -> 105596620 | D7: =IF((C7-C6<0), "0",C7-C6) -> 28987 | E7: ='Gas-2'!G8 -> 315 | F7: =IF((E7-E6<0), "0",E7-E6) -> 45 | G7: ='GENSET #1'!D12 -> 7321 | H7: ='GENSET #2'!D12 -> 6813 | I7: ='GENSET #3'!D12 -> 4139 | J7: ='GENSET #4'!D12 -> 3476 | K7: ='GENSET #5'!D12 -> 7238 | L7: ='FEEDER Consumption '!E7 -> 4338 | M7: ='FEEDER Consumption '!J7 -> 4664 | N7: ='FEEDER Consumption '!O7 -> 12712 | O7: ='FEEDER Consumption '!T7 -> 2500 | P7: ='FEEDER Consumption '!Y7 -> 3034 | Q7: ='FEEDER Consumption '!AD7 -> 2400 | R7: ='FEEDER Consumption '!AJ7 -> 484 | S7: ='FEEDER Consumption '!AO7 -> 600 | T7: ='FEEDER Consumption '!AT7 -> 2600 | U7: ='FEEDER Consumption '!AY7 -> 465 | V7: ='FEEDER Consumption '!BI7 -> 300 | W7: ='FEEDER Consumption '!BI7 -> 300 | X7: ='FEEDER Consumption '!BN7 -> 600 | Y7: ='FEEDER Consumption '!BS7 -> 150 | Z7: ='FEEDER Consumption '!BX7 -> 430 | AA7: ='FEEDER Consumption '!CC7 -> 1200 | AB7: ='FEEDER Consumption '!CH7 -> 510 | AC7: ='FEEDER Consumption '!CM7 -> 1150 | AD7: ='FEEDER Consumption '!CR7 -> 960 | AE7: ='FEEDER Consumption '!DB7 -> 1100 | AF7: ='FEEDER Consumption '!DB7 -> 1100 | AG7: ='FEEDER Consumption '!DG7 -> 800 | AH7: ='FEEDER Consumption '!DL7 -> 610 | AI7: ='FEEDER Consumption '!DQ7 -> 340 | AJ7: ='FEEDER Consumption '!DV7 -> 170 | AK7: ='FEEDER Consumption '!EA7 -> 1080 | AL7: ='FEEDER Consumption '!EF7 -> 330 | AM7: ='FEEDER Consumption '!EK7 -> 380 | AN7: ='FEEDER Consumption '!EP7 -> 560 | AO7: =SUM(WATER!C8,WATER!H8,WATER!M8,WATER!R8) -> 1155369 | AP7: =IF((AO7-AO6<0), "0",AO7-AO6) -> 399 | AQ7: =WATER!D8 -> 195 | AR7: =WATER!I8 -> 85 | AS7: =WATER!N8 -> 0 | AT7: =WATER!S8 -> 119 | AU7: =WATER!AD8 -> 36 | AV7: =WATER!AI8 -> 8 | AW7: =WATER!AN8 -> 9 | AX7: =WATER!AS8 -> 12 | AY7: =WATER!AX8 -> 10 | AZ7: =WATER!BC8 -> 6 | BA7: =WATER!BH8 -> 8 | BB7: =WATER!BM8 -> 9 | BC7: =WATER!BR8 -> 2 | BD7: =WATER!BW8 -> 0 | BE7: =WATER!CB8 -> 4 | BF7: =WATER!CG8 -> 0 | BG7: =WATER!CL8 -> 33 | BH7: =WATER!CQ8 -> 9 | BI7: =WATER!CV8 -> 1 | BJ7: =WATER!DA8 -> 7 | BK7: =WATER!DF8 -> 3 | BL7: =WATER!DK8 -> 5 | BM7: =WATER!DP8 -> 21 | BN7: =WATER!DU8 -> 5 | BO7: =WATER!DZ8 -> 4 | BP7: ='Room Nights and Food Covers'!B7 -> 90.3 | BQ7: ='Room Nights and Food Covers'!C7 -> 740
A8: =A7+1 -> 44930 | C8: =SUM('GENSET #1'!C13+'GENSET #2'!C13+'GENSET #3'!C13+'GENSET #4'!C13+'GENSET #5'!C13) -> 105625234 | D8: =IF((C8-C7<0), "0",C8-C7) -> 28614 | E8: ='Gas-2'!G9 -> 270 | F8: =IF((E8-E7<0), "0",E8-E7) -> 0 | G8: ='GENSET #1'!D13 -> 4960 | H8: ='GENSET #2'!D13 -> 10465 | I8: ='GENSET #3'!D13 -> 3888 | J8: ='GENSET #4'!D13 -> 3021 | K8: ='GENSET #5'!D13 -> 6280 | L8: ='FEEDER Consumption '!E8 -> 4349 | M8: ='FEEDER Consumption '!J8 -> 4661 | N8: ='FEEDER Consumption '!O8 -> 11714 | O8: ='FEEDER Consumption '!T8 -> 2300 | P8: ='FEEDER Consumption '!Y8 -> 2960 | Q8: ='FEEDER Consumption '!AD8 -> 2100 | R8: ='FEEDER Consumption '!AJ8 -> 504 | S8: ='FEEDER Consumption '!AO8 -> 800 | T8: ='FEEDER Consumption '!AT8 -> 2500 | U8: ='FEEDER Consumption '!AY8 -> 426 | V8: ='FEEDER Consumption '!BI8 -> 300 | W8: ='FEEDER Consumption '!BI8 -> 300 | X8: ='FEEDER Consumption '!BN8 -> 600 | Y8: ='FEEDER Consumption '!BS8 -> 120 | Z8: ='FEEDER Consumption '!BX8 -> 390 | AA8: ='FEEDER Consumption '!CC8 -> 1200 | AB8: ='FEEDER Consumption '!CH8 -> 470 | AC8: ='FEEDER Consumption '!CM8 -> 1160 | AD8: ='FEEDER Consumption '!CR8 -> 1060 | AE8: ='FEEDER Consumption '!DB8 -> 220 | AF8: ='FEEDER Consumption '!DB8 -> 220 | AG8: ='FEEDER Consumption '!DG8 -> 720 | AH8: ='FEEDER Consumption '!DL8 -> 610 | AI8: ='FEEDER Consumption '!DQ8 -> 370 | AJ8: ='FEEDER Consumption '!DV8 -> 140 | AK8: ='FEEDER Consumption '!EA8 -> 970 | AL8: ='FEEDER Consumption '!EF8 -> 290 | AM8: ='FEEDER Consumption '!EK8 -> 350 | AN8: ='FEEDER Consumption '!EP8 -> 570 | AO8: =SUM(WATER!C9,WATER!H9,WATER!M9,WATER!R9) -> 1155834 | AP8: =IF((AO8-AO7<0), "0",AO8-AO7) -> 465 | AQ8: =WATER!D9 -> 187 | AR8: =WATER!I9 -> 15 | AS8: =WATER!N9 -> 179 | AT8: =WATER!S9 -> 84 | AU8: =WATER!AD9 -> 32 | AV8: =WATER!AI9 -> 6 | AW8: =WATER!AN9 -> 10 | AX8: =WATER!AS9 -> 13 | AY8: =WATER!AX9 -> 10 | AZ8: =WATER!BC9 -> 8 | BA8: =WATER!BH9 -> 8 | BB8: =WATER!BM9 -> 9 | BC8: =WATER!BR9 -> 2 | BD8: =WATER!BW9 -> 0 | BE8: =WATER!CB9 -> 3 | BF8: =WATER!CG9 -> 2 | BG8: =WATER!CL9 -> 33 | BH8: =WATER!CQ9 -> 13 | BI8: =WATER!CV9 -> 1 | BJ8: =WATER!DA9 -> 16 | BK8: =WATER!DF9 -> 6 | BL8: =WATER!DK9 -> 3 | BM8: =WATER!DP9 -> 20 | BN8: =WATER!DU9 -> 2 | BO8: =WATER!DZ9 -> 2 | BP8: ='Room Nights and Food Covers'!B8 -> 81.6 | BQ8: ='Room Nights and Food Covers'!C8 -> 647
A9: =A8+1 -> 44931 | C9: =SUM('GENSET #1'!C14+'GENSET #2'!C14+'GENSET #3'!C14+'GENSET #4'!C14+'GENSET #5'!C14) -> 105653984 | D9: =IF((C9-C8<0), "0",C9-C8) -> 28750 | E9: ='Gas-2'!G10 -> 360 | F9: =IF((E9-E8<0), "0",E9-E8) -> 90 | G9: ='GENSET #1'!D14 -> 5580 | H9: ='GENSET #2'!D14 -> 9400 | I9: ='GENSET #3'!D14 -> 4621 | J9: ='GENSET #4'!D14 -> 1945 | K9: ='GENSET #5'!D14 -> 7204 | L9: ='FEEDER Consumption '!E9 -> 4138 | M9: ='FEEDER Consumption '!J9 -> 4769 | N9: ='FEEDER Consumption '!O9 -> 12322 | O9: ='FEEDER Consumption '!T9 -> 2500 | P9: ='FEEDER Consumption '!Y9 -> 3077 | Q9: ='FEEDER Consumption '!AD9 -> 1900 | R9: ='FEEDER Consumption '!AJ9 -> 494 | S9: ='FEEDER Consumption '!AO9 -> 700 | T9: ='FEEDER Consumption '!AT9 -> 2900 | U9: ='FEEDER Consumption '!AY9 -> 438 | V9: ='FEEDER Consumption '!BI9 -> 300 | W9: ='FEEDER Consumption '!BI9 -> 300 | X9: ='FEEDER Consumption '!BN9 -> 600 | Y9: ='FEEDER Consumption '!BS9 -> 130 | Z9: ='FEEDER Consumption '!BX9 -> 400 | AA9: ='FEEDER Consumption '!CC9 -> 1200 | AB9: ='FEEDER Consumption '!CH9 -> 480 | AC9: ='FEEDER Consumption '!CM9 -> 1200 | AD9: ='FEEDER Consumption '!CR9 -> 960 | AE9: ='FEEDER Consumption '!DB9 -> 1980 | AF9: ='FEEDER Consumption '!DB9 -> 1980 | AG9: ='FEEDER Consumption '!DG9 -> 680 | AH9: ='FEEDER Consumption '!DL9 -> 680 | AI9: ='FEEDER Consumption '!DQ9 -> 330 | AJ9: ='FEEDER Consumption '!DV9 -> 150 | AK9: ='FEEDER Consumption '!EA9 -> 1040 | AL9: ='FEEDER Consumption '!EF9 -> 320 | AM9: ='FEEDER Consumption '!EK9 -> 370 | AN9: ='FEEDER Consumption '!EP9 -> 520 | AO9: =SUM(WATER!C10,WATER!H10,WATER!M10,WATER!R10) -> 1156254 | AP9: =IF((AO9-AO8<0), "0",AO9-AO8) -> 420 | AQ9: =WATER!D10 -> 180 | AR9: =WATER!I10 -> 67 | AS9: =WATER!N10 -> 166 | AT9: =WATER!S10 -> 7 | AU9: =WATER!AD10 -> 34 | AV9: =WATER!AI10 -> 7 | AW9: =WATER!AN10 -> 9 | AX9: =WATER!AS10 -> 12 | AY9: =WATER!AX10 -> 9 | AZ9: =WATER!BC10 -> 6 | BA9: =WATER!BH10 -> 9 | BB9: =WATER!BM10 -> 9 | BC9: =WATER!BR10 -> 2 | BD9: =WATER!BW10 -> 0 | BE9: =WATER!CB10 -> 5 | BF9: =WATER!CG10 -> 3 | BG9: =WATER!CL10 -> 31 | BH9: =WATER!CQ10 -> 10 | BI9: =WATER!CV10 -> 1 | BJ9: =WATER!DA10 -> 6 | BK9: =WATER!DF10 -> 4 | BL9: =WATER!DK10 -> 6 | BM9: =WATER!DP10 -> 22 | BN9: =WATER!DU10 -> 5 | BO9: =WATER!DZ10 -> 14 | BP9: ='Room Nights and Food Covers'!B9 -> 77.7 | BQ9: ='Room Nights and Food Covers'!C9 -> 639
A10: =A9+1 -> 44932 | C10: =SUM('GENSET #1'!C15+'GENSET #2'!C15+'GENSET #3'!C15+'GENSET #4'!C15+'GENSET #5'!C15) -> 105682915 | D10: =IF((C10-C9<0), "0",C10-C9) -> 28931 | E10: ='Gas-2'!G11 -> 315 | F10: =IF((E10-E9<0), "0",E10-E9) -> 0 | G10: ='GENSET #1'!D15 -> 7411 | H10: ='GENSET #2'!D15 -> 7536 | I10: ='GENSET #3'!D15 -> 2796 | J10: ='GENSET #4'!D15 -> 3476 | K10: ='GENSET #5'!D15 -> 7712 | L10: ='FEEDER Consumption '!E10 -> 4423 | M10: ='FEEDER Consumption '!J10 -> 4621 | N10: ='FEEDER Consumption '!O10 -> 12388 | O10: ='FEEDER Consumption '!T10 -> 2300 | P10: ='FEEDER Consumption '!Y10 -> 3058 | Q10: ='FEEDER Consumption '!AD10 -> 2400 | R10: ='FEEDER Consumption '!AJ10 -> 472 | S10: ='FEEDER Consumption '!AO10 -> 700 | T10: ='FEEDER Consumption '!AT10 -> 2500 | U10: ='FEEDER Consumption '!AY10 -> 429 | V10: ='FEEDER Consumption '!BI10 -> 300 | W10: ='FEEDER Consumption '!BI10 -> 300 | X10: ='FEEDER Consumption '!BN10 -> 500 | Y10: ='FEEDER Consumption '!BS10 -> 110 | Z10: ='FEEDER Consumption '!BX10 -> 370 | AA10: ='FEEDER Consumption '!CC10 -> 1200 | AB10: ='FEEDER Consumption '!CH10 -> 510 | AC10: ='FEEDER Consumption '!CM10 -> 1120 | AD10: ='FEEDER Consumption '!CR10 -> 1020 | AE10: ='FEEDER Consumption '!DB10 -> 1100 | AF10: ='FEEDER Consumption '!DB10 -> 1100 | AG10: ='FEEDER Consumption '!DG10 -> 720 | AH10: ='FEEDER Consumption '!DL10 -> 550 | AI10: ='FEEDER Consumption '!DQ10 -> 350 | AJ10: ='FEEDER Consumption '!DV10 -> 160 | AK10: ='FEEDER Consumption '!EA10 -> 990 | AL10: ='FEEDER Consumption '!EF10 -> 320 | AM10: ='FEEDER Consumption '!EK10 -> 370 | AN10: ='FEEDER Consumption '!EP10 -> 570 | AO10: =SUM(WATER!C11,WATER!H11,WATER!M11,WATER!R11) -> 1156629 | AP10: =IF((AO10-AO9<0), "0",AO10-AO9) -> 375 | AQ10: =WATER!D11 -> 89 | AR10: =WATER!I11 -> 42 | AS10: =WATER!N11 -> 182 | AT10: =WATER!S11 -> 62 | AU10: =WATER!AD11 -> 34 | AV10: =WATER!AI11 -> 7 | AW10: =WATER!AN11 -> 11 | AX10: =WATER!AS11 -> 15 | AY10: =WATER!AX11 -> 11 | AZ10: =WATER!BC11 -> 8 | BA10: =WATER!BH11 -> 9 | BB10: =WATER!BM11 -> 9 | BC10: =WATER!BR11 -> 2 | BD10: =WATER!BW11 -> 0 | BE10: =WATER!CB11 -> 3 | BF10: =WATER!CG11 -> 0 | BG10: =WATER!CL11 -> 26 | BH10: =WATER!CQ11 -> 12 | BI10: =WATER!CV11 -> 0 | BJ10: =WATER!DA11 -> 6 | BK10: =WATER!DF11 -> 3 | BL10: =WATER!DK11 -> 3 | BM10: =WATER!DP11 -> 21 | BN10: =WATER!DU11 -> 3 | BO10: =WATER!DZ11 -> 2 | BP10: ='Room Nights and Food Covers'!B10 -> 67 | BQ10: ='Room Nights and Food Covers'!C10 -> 532
A11: =A10+1 -> 44933 | C11: =SUM('GENSET #1'!C16+'GENSET #2'!C16+'GENSET #3'!C16+'GENSET #4'!C16+'GENSET #5'!C16) -> 105710808 | D11: =IF((C11-C10<0), "0",C11-C10) -> 27893 | E11: ='Gas-2'!G12 -> 270 | F11: =IF((E11-E10<0), "0",E11-E10) -> 0 | G11: ='GENSET #1'!D16 -> 6511 | H11: ='GENSET #2'!D16 -> 8861 | I11: ='GENSET #3'!D16 -> 2573 | J11: ='GENSET #4'!D16 -> 2473 | K11: ='GENSET #5'!D16 -> 7475 | L11: ='FEEDER Consumption '!E11 -> 4356 | M11: ='FEEDER Consumption '!J11 -> 4463 | N11: ='FEEDER Consumption '!O11 -> 12336 | O11: ='FEEDER Consumption '!T11 -> 2400 | P11: ='FEEDER Consumption '!Y11 -> 2974 | Q11: ='FEEDER Consumption '!AD11 -> 2100 | R11: ='FEEDER Consumption '!AJ11 -> 447 | S11: ='FEEDER Consumption '!AO11 -> 800 | T11: ='FEEDER Consumption '!AT11 -> 2500 | U11: ='FEEDER Consumption '!AY11 -> 432 | V11: ='FEEDER Consumption '!BI11 -> 400 | W11: ='FEEDER Consumption '!BI11 -> 400 | X11: ='FEEDER Consumption '!BN11 -> 600 | Y11: ='FEEDER Consumption '!BS11 -> 130 | Z11: ='FEEDER Consumption '!BX11 -> 400 | AA11: ='FEEDER Consumption '!CC11 -> 1200 | AB11: ='FEEDER Consumption '!CH11 -> 470 | AC11: ='FEEDER Consumption '!CM11 -> 1260 | AD11: ='FEEDER Consumption '!CR11 -> 1030 | AE11: ='FEEDER Consumption '!DB11 -> 1300 | AF11: ='FEEDER Consumption '!DB11 -> 1300 | AG11: ='FEEDER Consumption '!DG11 -> 720 | AH11: ='FEEDER Consumption '!DL11 -> 550 | AI11: ='FEEDER Consumption '!DQ11 -> 350 | AJ11: ='FEEDER Consumption '!DV11 -> 140 | AK11: ='FEEDER Consumption '!EA11 -> 1070 | AL11: ='FEEDER Consumption '!EF11 -> 340 | AM11: ='FEEDER Consumption '!EK11 -> 480 | AN11: ='FEEDER Consumption '!EP11 -> 540 | AO11: =SUM(WATER!C12,WATER!H12,WATER!M12,WATER!R12) -> 1156936 | AP11: =IF((AO11-AO10<0), "0",AO11-AO10) -> 307 | AQ11: =WATER!D12 -> 153 | AR11: =WATER!I12 -> 53 | AS11: =WATER!N12 -> 101 | AT11: =WATER!S12 -> 0 | AU11: =WATER!AD12 -> 35 | AV11: =WATER!AI12 -> 8 | AW11: =WATER!AN12 -> 10 | AX11: =WATER!AS12 -> 13 | AY11: =WATER!AX12 -> 9 | AZ11: =WATER!BC12 -> 7 | BA11: =WATER!BH12 -> 9 | BB11: =WATER!BM12 -> 9 | BC11: =WATER!BR12 -> 1 | BD11: =WATER!BW12 -> 2 | BE11: =WATER!CB12 -> 2 | BF11: =WATER!CG12 -> 2 | BG11: =WATER!CL12 -> 27 | BH11: =WATER!CQ12 -> 6 | BI11: =WATER!CV12 -> 2 | BJ11: =WATER!DA12 -> 1 | BK11: =WATER!DF12 -> 4 | BL11: =WATER!DK12 -> 4 | BM11: =WATER!DP12 -> 19 | BN11: =WATER!DU12 -> 2 | BO11: =WATER!DZ12 -> 2 | BP11: ='Room Nights and Food Covers'!B11 -> 61.2 | BQ11: ='Room Nights and Food Covers'!C11 -> 539
A12: =A11+1 -> 44934 | C12: =SUM('GENSET #1'!C17+'GENSET #2'!C17+'GENSET #3'!C17+'GENSET #4'!C17+'GENSET #5'!C17) -> 105737698 | D12: =IF((C12-C11<0), "0",C12-C11) -> 26890 | E12: ='Gas-2'!G13 -> 315 | F12: =IF((E12-E11<0), "0",E12-E11) -> 45 | G12: ='GENSET #1'!D17 -> 6893 | H12: ='GENSET #2'!D17 -> 7577 | I12: ='GENSET #3'!D17 -> 3036 | J12: ='GENSET #4'!D17 -> 2179 | K12: ='GENSET #5'!D17 -> 7205 | L12: ='FEEDER Consumption '!E12 -> 4075 | M12: ='FEEDER Consumption '!J12 -> 4494 | N12: ='FEEDER Consumption '!O12 -> 11206 | O12: ='FEEDER Consumption '!T12 -> 2300 | P12: ='FEEDER Consumption '!Y12 -> 2843 | Q12: ='FEEDER Consumption '!AD12 -> 1600 | R12: ='FEEDER Consumption '!AJ12 -> 466 | S12: ='FEEDER Consumption '!AO12 -> 700 | T12: ='FEEDER Consumption '!AT12 -> 2300 | U12: ='FEEDER Consumption '!AY12 -> 448 | V12: ='FEEDER Consumption '!BI12 -> 300 | W12: ='FEEDER Consumption '!BI12 -> 300 | X12: ='FEEDER Consumption '!BN12 -> 600 | Y12: ='FEEDER Consumption '!BS12 -> 120 | Z12: ='FEEDER Consumption '!BX12 -> 410 | AA12: ='FEEDER Consumption '!CC12 -> 1200 | AB12: ='FEEDER Consumption '!CH12 -> 430 | AC12: ='FEEDER Consumption '!CM12 -> 1070 | AD12: ='FEEDER Consumption '!CR12 -> 840 | AE12: ='FEEDER Consumption '!DB12 -> 800 | AF12: ='FEEDER Consumption '!DB12 -> 800 | AG12: ='FEEDER Consumption '!DG12 -> 700 | AH12: ='FEEDER Consumption '!DL12 -> 510 | AI12: ='FEEDER Consumption '!DQ12 -> 330 | AJ12: ='FEEDER Consumption '!DV12 -> 120 | AK12: ='FEEDER Consumption '!EA12 -> 850 | AL12: ='FEEDER Consumption '!EF12 -> 300 | AM12: ='FEEDER Consumption '!EK12 -> 380 | AN12: ='FEEDER Consumption '!EP12 -> 510 | AO12: =SUM(WATER!C13,WATER!H13,WATER!M13,WATER!R13) -> 1157240 | AP12: =IF((AO12-AO11<0), "0",AO12-AO11) -> 304 | AQ12: =WATER!D13 -> 169 | AR12: =WATER!I13 -> 10 | AS12: =WATER!N13 -> 125 | AT12: =WATER!S13 -> 0 | AU12: =WATER!AD13 -> 32 | AV12: =WATER!AI13 -> 6 | AW12: =WATER!AN13 -> 9 | AX12: =WATER!AS13 -> 12 | AY12: =WATER!AX13 -> 10 | AZ12: =WATER!BC13 -> 7 | BA12: =WATER!BH13 -> 9 | BB12: =WATER!BM13 -> 9 | BC12: =WATER!BR13 -> 2 | BD12: =WATER!BW13 -> 0 | BE12: =WATER!CB13 -> 3 | BF12: =WATER!CG13 -> 1 | BG12: =WATER!CL13 -> 23 | BH12: =WATER!CQ13 -> 17 | BI12: =WATER!CV13 -> 1 | BJ12: =WATER!DA13 -> 1 | BK12: =WATER!DF13 -> 3 | BL12: =WATER!DK13 -> 4 | BM12: =WATER!DP13 -> 20 | BN12: =WATER!DU13 -> 4 | BO12: =WATER!DZ13 -> 2 | BP12: ='Room Nights and Food Covers'!B12 -> 43.7 | BQ12: ='Room Nights and Food Covers'!C12 -> 334
A13: =A12+1 -> 44935 | C13: =SUM('GENSET #1'!C18+'GENSET #2'!C18+'GENSET #3'!C18+'GENSET #4'!C18+'GENSET #5'!C18) -> 105764198 | D13: =IF((C13-C12<0), "0",C13-C12) -> 26500 | E13: ='Gas-2'!G14 -> 225 | F13: =IF((E13-E12<0), "0",E13-E12) -> 0 | G13: ='GENSET #1'!D18 -> 0 | H13: ='GENSET #2'!D18 -> 10197 | I13: ='GENSET #3'!D18 -> 7274 | J13: ='GENSET #4'!D18 -> 3110 | K13: ='GENSET #5'!D18 -> 5919 | L13: ='FEEDER Consumption '!E13 -> 3970 | M13: ='FEEDER Consumption '!J13 -> 4695 | N13: ='FEEDER Consumption '!O13 -> 11415 | O13: ='FEEDER Consumption '!T13 -> 2200 | P13: ='FEEDER Consumption '!Y13 -> 2966 | Q13: ='FEEDER Consumption '!AD13 -> 1600 | R13: ='FEEDER Consumption '!AJ13 -> 475 | S13: ='FEEDER Consumption '!AO13 -> 700 | T13: ='FEEDER Consumption '!AT13 -> 1900 | U13: ='FEEDER Consumption '!AY13 -> 472 | V13: ='FEEDER Consumption '!BI13 -> 200 | W13: ='FEEDER Consumption '!BI13 -> 200 | X13: ='FEEDER Consumption '!BN13 -> 600 | Y13: ='FEEDER Consumption '!BS13 -> 130 | Z13: ='FEEDER Consumption '!BX13 -> 430 | AA13: ='FEEDER Consumption '!CC13 -> 1200 | AB13: ='FEEDER Consumption '!CH13 -> 440 | AC13: ='FEEDER Consumption '!CM13 -> 1050 | AD13: ='FEEDER Consumption '!CR13 -> 1040 | AE13: ='FEEDER Consumption '!DB13 -> 1200 | AF13: ='FEEDER Consumption '!DB13 -> 1200 | AG13: ='FEEDER Consumption '!DG13 -> 760 | AH13: ='FEEDER Consumption '!DL13 -> 570 | AI13: ='FEEDER Consumption '!DQ13 -> 320 | AJ13: ='FEEDER Consumption '!DV13 -> 100 | AK13: ='FEEDER Consumption '!EA13 -> 920 | AL13: ='FEEDER Consumption '!EF13 -> 290 | AM13: ='FEEDER Consumption '!EK13 -> 360 | AN13: ='FEEDER Consumption '!EP13 -> 560 | AO13: =SUM(WATER!C14,WATER!H14,WATER!M14,WATER!R14) -> 1157571 | AP13: =IF((AO13-AO12<0), "0",AO13-AO12) -> 331 | AQ13: =WATER!D14 -> 182 | AR13: =WATER!I14 -> 0 | AS13: =WATER!N14 -> 149 | AT13: =WATER!S14 -> 0 | AU13: =WATER!AD14 -> 31 | AV13: =WATER!AI14 -> 6 | AW13: =WATER!AN14 -> 10 | AX13: =WATER!AS14 -> 11 | AY13: =WATER!AX14 -> 9 | AZ13: =WATER!BC14 -> 7 | BA13: =WATER!BH14 -> 9 | BB13: =WATER!BM14 -> 7 | BC13: =WATER!BR14 -> 2 | BD13: =WATER!BW14 -> 1 | BE13: =WATER!CB14 -> 5 | BF13: =WATER!CG14 -> 4 | BG13: =WATER!CL14 -> 24 | BH13: =WATER!CQ14 -> 8 | BI13: =WATER!CV14 -> 1 | BJ13: =WATER!DA14 -> 1 | BK13: =WATER!DF14 -> 3 | BL13: =WATER!DK14 -> 2 | BM13: =WATER!DP14 -> 10 | BN13: =WATER!DU14 -> 6 | BO13: =WATER!DZ14 -> 3 | BP13: ='Room Nights and Food Covers'!B13 -> 42.7 | BQ13: ='Room Nights and Food Covers'!C13 -> 338
A14: =A13+1 -> 44936 | C14: =SUM('GENSET #1'!C19+'GENSET #2'!C19+'GENSET #3'!C19+'GENSET #4'!C19+'GENSET #5'!C19) -> 105790172 | D14: =IF((C14-C13<0), "0",C14-C13) -> 25974 | E14: ='Gas-2'!G15 -> 270 | F14: =IF((E14-E13<0), "0",E14-E13) -> 45 | G14: ='GENSET #1'!D19 -> 7687 | H14: ='GENSET #2'!D19 -> 6741 | I14: ='GENSET #3'!D19 -> 15 | J14: ='GENSET #4'!D19 -> 3666 | K14: ='GENSET #5'!D19 -> 7865 | L14: ='FEEDER Consumption '!E14 -> 3839 | M14: ='FEEDER Consumption '!J14 -> 4138 | N14: ='FEEDER Consumption '!O14 -> 11193 | O14: ='FEEDER Consumption '!T14 -> 2100 | P14: ='FEEDER Consumption '!Y14 -> 2907 | Q14: ='FEEDER Consumption '!AD14 -> 1600 | R14: ='FEEDER Consumption '!AJ14 -> 466 | S14: ='FEEDER Consumption '!AO14 -> 800 | T14: ='FEEDER Consumption '!AT14 -> 1900 | U14: ='FEEDER Consumption '!AY14 -> 430 | V14: ='FEEDER Consumption '!BI14 -> 300 | W14: ='FEEDER Consumption '!BI14 -> 300 | X14: ='FEEDER Consumption '!BN14 -> 500 | Y14: ='FEEDER Consumption '!BS14 -> 130 | Z14: ='FEEDER Consumption '!BX14 -> 370 | AA14: ='FEEDER Consumption '!CC14 -> 1200 | AB14: ='FEEDER Consumption '!CH14 -> 410 | AC14: ='FEEDER Consumption '!CM14 -> 770 | AD14: ='FEEDER Consumption '!CR14 -> 990 | AE14: ='FEEDER Consumption '!DB14 -> 1000 | AF14: ='FEEDER Consumption '!DB14 -> 1000 | AG14: ='FEEDER Consumption '!DG14 -> 790 | AH14: ='FEEDER Consumption '!DL14 -> 580 | AI14: ='FEEDER Consumption '!DQ14 -> 320 | AJ14: ='FEEDER Consumption '!DV14 -> 140 | AK14: ='FEEDER Consumption '!EA14 -> 940 | AL14: ='FEEDER Consumption '!EF14 -> 300 | AM14: ='FEEDER Consumption '!EK14 -> 430 | AN14: ='FEEDER Consumption '!EP14 -> 520 | AO14: =SUM(WATER!C15,WATER!H15,WATER!M15,WATER!R15) -> 1157877 | AP14: =IF((AO14-AO13<0), "0",AO14-AO13) -> 306 | AQ14: =WATER!D15 -> 181 | AR14: =WATER!I15 -> 0 | AS14: =WATER!N15 -> 125 | AT14: =WATER!S15 -> 0 | AU14: =WATER!AD15 -> 26 | AV14: =WATER!AI15 -> 7 | AW14: =WATER!AN15 -> 10 | AX14: =WATER!AS15 -> 13 | AY14: =WATER!AX15 -> 7 | AZ14: =WATER!BC15 -> 6 | BA14: =WATER!BH15 -> 8 | BB14: =WATER!BM15 -> 7 | BC14: =WATER!BR15 -> 2 | BD14: =WATER!BW15 -> 1 | BE14: =WATER!CB15 -> 4 | BF14: =WATER!CG15 -> 1 | BG14: =WATER!CL15 -> 23 | BH14: =WATER!CQ15 -> 8 | BI14: =WATER!CV15 -> 1 | BJ14: =WATER!DA15 -> 0 | BK14: =WATER!DF15 -> 2 | BL14: =WATER!DK15 -> 2 | BM14: =WATER!DP15 -> 20 | BN14: =WATER!DU15 -> 2 | BO14: =WATER!DZ15 -> 1 | BP14: ='Room Nights and Food Covers'!B14 -> 35 | BQ14: ='Room Nights and Food Covers'!C14 -> 285
A15: =A14+1 -> 44937 | C15: =SUM('GENSET #1'!C20+'GENSET #2'!C20+'GENSET #3'!C20+'GENSET #4'!C20+'GENSET #5'!C20) -> 105815064 | D15: =IF((C15-C14<0), "0",C15-C14) -> 24892 | E15: ='Gas-2'!G16 -> 270 | F15: =IF((E15-E14<0), "0",E15-E14) -> 0 | G15: ='GENSET #1'!D20 -> 7264 | H15: ='GENSET #2'!D20 -> 4793 | I15: ='GENSET #3'!D20 -> 2625 | J15: ='GENSET #4'!D20 -> 4780 | K15: ='GENSET #5'!D20 -> 5430 | L15: ='FEEDER Consumption '!E15 -> 3629 | M15: ='FEEDER Consumption '!J15 -> 3859 | N15: ='FEEDER Consumption '!O15 -> 10932 | O15: ='FEEDER Consumption '!T15 -> 2200 | P15: ='FEEDER Consumption '!Y15 -> 2878 | Q15: ='FEEDER Consumption '!AD15 -> 1500 | R15: ='FEEDER Consumption '!AJ15 -> 425 | S15: ='FEEDER Consumption '!AO15 -> 700 | T15: ='FEEDER Consumption '!AT15 -> 2000 | U15: ='FEEDER Consumption '!AY15 -> 420 | V15: ='FEEDER Consumption '!BI15 -> 300 | W15: ='FEEDER Consumption '!BI15 -> 300 | X15: ='FEEDER Consumption '!BN15 -> 600 | Y15: ='FEEDER Consumption '!BS15 -> 120 | Z15: ='FEEDER Consumption '!BX15 -> 320 | AA15: ='FEEDER Consumption '!CC15 -> 1100 | AB15: ='FEEDER Consumption '!CH15 -> 430 | AC15: ='FEEDER Consumption '!CM15 -> 750 | AD15: ='FEEDER Consumption '!CR15 -> 960 | AE15: ='FEEDER Consumption '!DB15 -> 800 | AF15: ='FEEDER Consumption '!DB15 -> 800 | AG15: ='FEEDER Consumption '!DG15 -> 750 | AH15: ='FEEDER Consumption '!DL15 -> 610 | AI15: ='FEEDER Consumption '!DQ15 -> 290 | AJ15: ='FEEDER Consumption '!DV15 -> 110 | AK15: ='FEEDER Consumption '!EA15 -> 950 | AL15: ='FEEDER Consumption '!EF15 -> 300 | AM15: ='FEEDER Consumption '!EK15 -> 400 | AN15: ='FEEDER Consumption '!EP15 -> 530 | AO15: =SUM(WATER!C16,WATER!H16,WATER!M16,WATER!R16) -> 1158215 | AP15: =IF((AO15-AO14<0), "0",AO15-AO14) -> 338 | AQ15: =WATER!D16 -> 175 | AR15: =WATER!I16 -> 31 | AS15: =WATER!N16 -> 132 | AT15: =WATER!S16 -> 0 | AU15: =WATER!AD16 -> 24 | AV15: =WATER!AI16 -> 6 | AW15: =WATER!AN16 -> 10 | AX15: =WATER!AS16 -> 10 | AY15: =WATER!AX16 -> 9 | AZ15: =WATER!BC16 -> 7 | BA15: =WATER!BH16 -> 8 | BB15: =WATER!BM16 -> 9 | BC15: =WATER!BR16 -> 2 | BD15: =WATER!BW16 -> 1 | BE15: =WATER!CB16 -> 1 | BF15: =WATER!CG16 -> 1 | BG15: =WATER!CL16 -> 25 | BH15: =WATER!CQ16 -> 11 | BI15: =WATER!CV16 -> 1 | BJ15: =WATER!DA16 -> 1 | BK15: =WATER!DF16 -> 4 | BL15: =WATER!DK16 -> 4 | BM15: =WATER!DP16 -> 12 | BN15: =WATER!DU16 -> 1 | BO15: =WATER!DZ16 -> 2 | BP15: ='Room Nights and Food Covers'!B15 -> 40.8 | BQ15: ='Room Nights and Food Covers'!C15 -> 346
A16: =A15+1 -> 44938 | C16: =SUM('GENSET #1'!C21+'GENSET #2'!C21+'GENSET #3'!C21+'GENSET #4'!C21+'GENSET #5'!C21) -> 105839355 | D16: =IF((C16-C15<0), "0",C16-C15) -> 24291 | E16: ='Gas-2'!G17 -> 270 | F16: =IF((E16-E15<0), "0",E16-E15) -> 0 | G16: ='GENSET #1'!D21 -> 7040 | H16: ='GENSET #2'!D21 -> 0 | I16: ='GENSET #3'!D21 -> 3473 | J16: ='GENSET #4'!D21 -> 2892 | K16: ='GENSET #5'!D21 -> 10886 | L16: ='FEEDER Consumption '!E16 -> 3458 | M16: ='FEEDER Consumption '!J16 -> 3569 | N16: ='FEEDER Consumption '!O16 -> 11155 | O16: ='FEEDER Consumption '!T16 -> 2100 | P16: ='FEEDER Consumption '!Y16 -> 2820 | Q16: ='FEEDER Consumption '!AD16 -> 1700 | R16: ='FEEDER Consumption '!AJ16 -> 481 | S16: ='FEEDER Consumption '!AO16 -> 600 | T16: ='FEEDER Consumption '!AT16 -> 1900 | U16: ='FEEDER Consumption '!AY16 -> 358 | V16: ='FEEDER Consumption '!BI16 -> 300 | W16: ='FEEDER Consumption '!BI16 -> 300 | X16: ='FEEDER Consumption '!BN16 -> 500 | Y16: ='FEEDER Consumption '!BS16 -> 100 | Z16: ='FEEDER Consumption '!BX16 -> 400 | AA16: ='FEEDER Consumption '!CC16 -> 1200 | AB16: ='FEEDER Consumption '!CH16 -> 480 | AC16: ='FEEDER Consumption '!CM16 -> 670 | AD16: ='FEEDER Consumption '!CR16 -> 770 | AE16: ='FEEDER Consumption '!DB16 -> 700 | AF16: ='FEEDER Consumption '!DB16 -> 700 | AG16: ='FEEDER Consumption '!DG16 -> 610 | AH16: ='FEEDER Consumption '!DL16 -> 520 | AI16: ='FEEDER Consumption '!DQ16 -> 310 | AJ16: ='FEEDER Consumption '!DV16 -> 120 | AK16: ='FEEDER Consumption '!EA16 -> 870 | AL16: ='FEEDER Consumption '!EF16 -> 260 | AM16: ='FEEDER Consumption '!EK16 -> 330 | AN16: ='FEEDER Consumption '!EP16 -> 520 | AO16: =SUM(WATER!C17,WATER!H17,WATER!M17,WATER!R17) -> 1158525 | AP16: =IF((AO16-AO15<0), "0",AO16-AO15) -> 310 | AQ16: =WATER!D17 -> 169 | AR16: =WATER!I17 -> 21 | AS16: =WATER!N17 -> 120 | AT16: =WATER!S17 -> 0 | AU16: =WATER!AD17 -> 28 | AV16: =WATER!AI17 -> 5 | AW16: =WATER!AN17 -> 10 | AX16: =WATER!AS17 -> 11 | AY16: =WATER!AX17 -> 8 | AZ16: =WATER!BC17 -> 7 | BA16: =WATER!BH17 -> 8 | BB16: =WATER!BM17 -> 7 | BC16: =WATER!BR17 -> 2 | BD16: =WATER!BW17 -> 1 | BE16: =WATER!CB17 -> 5 | BF16: =WATER!CG17 -> 3 | BG16: =WATER!CL17 -> 30 | BH16: =WATER!CQ17 -> 10 | BI16: =WATER!CV17 -> 4 | BJ16: =WATER!DA17 -> 0 | BK16: =WATER!DF17 -> 2 | BL16: =WATER!DK17 -> 3 | BM16: =WATER!DP17 -> 13 | BN16: =WATER!DU17 -> 4 | BO16: =WATER!DZ17 -> 8 | BP16: ='Room Nights and Food Covers'!B16 -> 46.6 | BQ16: ='Room Nights and Food Covers'!C16 -> 372
... A35: =A34+1 -> 44957 | C35: =SUM('GENSET #1'!C40+'GENSET #2'!C40+'GENSET #3'!C40+'GENSET #4'!C40+'GENSET #5'!C40) -> 106322316 | D35: =IF((C35-C34<0), "0",C35-C34) -> 25218 | E35: ='Gas-2'!G36 -> 225 | F35: =IF((E35-E34<0), "0",E35-E34) -> 0 | G35: ='GENSET #1'!D40 -> 5489 | H35: ='GENSET #2'!D40 -> 9630 | I35: ='GENSET #3'!D40 -> 0 | J35: ='GENSET #4'!D40 -> 3232 | K35: ='GENSET #5'!D40 -> 6867 | L35: ='FEEDER Consumption '!E35 -> 3801 | M35: ='FEEDER Consumption '!J35 -> 4077 | N35: ='FEEDER Consumption '!O35 -> 10874 | O35: ='FEEDER Consumption '!T35 -> 2100 | P35: ='FEEDER Consumption '!Y35 -> 2922 | Q35: ='FEEDER Consumption '!AD35 -> 1700 | R35: ='FEEDER Consumption '!AJ35 -> 512 | S35: ='FEEDER Consumption '!AO35 -> 700 | T35: ='FEEDER Consumption '!AT35 -> 1600 | U35: ='FEEDER Consumption '!AY35 -> 357 | V35: ='FEEDER Consumption '!BI35 -> 300 | W35: ='FEEDER Consumption '!BI35 -> 300 | X35: ='FEEDER Consumption '!BN35 -> 500 | Y35: ='FEEDER Consumption '!BS35 -> 110 | Z35: ='FEEDER Consumption '!BX35 -> 310 | AA35: ='FEEDER Consumption '!CC35 -> 1100 | AB35: ='FEEDER Consumption '!CH35 -> 430 | AC35: ='FEEDER Consumption '!CM35 -> 910 | AD35: ='FEEDER Consumption '!CR35 -> 950 | AE35: ='FEEDER Consumption '!DB35 -> 900 | AF35: ='FEEDER Consumption '!DB35 -> 900 | AG35: ='FEEDER Consumption '!DG35 -> 800 | AH35: ='FEEDER Consumption '!DL35 -> 570 | AI35: ='FEEDER Consumption '!DQ35 -> 340 | AJ35: ='FEEDER Consumption '!DV35 -> 120 | AK35: ='FEEDER Consumption '!EA35 -> 1000 | AL35: ='FEEDER Consumption '!EF35 -> 270 | AM35: ='FEEDER Consumption '!EK35 -> 380 | AN35: ='FEEDER Consumption '!EP35 -> 530 | AO35: =SUM(WATER!C36,WATER!H36,WATER!M36,WATER!R36) -> 917575 | AP35: =IF((AO35-AO34<0), "0",AO35-AO34) -> 312 | AQ35: =WATER!D36 -> 173 | AR35: =WATER!I36 -> 0 | AS35: =WATER!N36 -> 139 | AT35: =WATER!S36 -> 0 | AU35: =WATER!AD36 -> 28 | AV35: =WATER!AI36 -> 6 | AW35: =WATER!AN36 -> 10 | AX35: =WATER!AS36 -> 11 | AY35: =WATER!AX36 -> 7 | AZ35: =WATER!BC36 -> 6 | BA35: =WATER!BH36 -> 9 | BB35: =WATER!BM36 -> 7 | BC35: =WATER!BR36 -> 1 | BD35: =WATER!BW36 -> 0 | BE35: =WATER!CB36 -> 4 | BF35: =WATER!CG36 -> 2 | BG35: =WATER!CL36 -> 29 | BH35: =WATER!CQ36 -> 9 | BI35: =WATER!CV36 -> 0 | BJ35: =WATER!DA36 -> 1 | BK35: =WATER!DF36 -> 3 | BL35: =WATER!DK36 -> 2 | BM35: =WATER!DP36 -> 17 | BN35: =WATER!DU36 -> 3 | BO35: =WATER!DZ36 -> 0 | BP35: ='Room Nights and Food Covers'!B35 -> 49.5 | BQ35: ='Room Nights and Food Covers'!C35 -> 317

Sheet Finance and DOE
A4: Daily Utility Report
A5: 44927
A7: DAY | B7: Occupancy | C7: No. of Guests | D7: Genset (Kwh) | E7: Solar (Kwh) | F7: Total (Kwh) | G7: Water Consumption ( m3) | H7: Gas Consumption (kg) | I7: Genset Diesel Consumption (Liters) | J7: Boats Diesel Consumption (Liters) | K7: Boats Petrol Consumption (Liters)
A8: 1 | B8: =TOTAL!M2 -> 96 | C8: ='Room Nights and Food Covers'!D4 -> 0 | D8: =SUM('GENSET #1:GENSET #5'!D10) -> 30154 | E8: ='SOLAR METER READING'!D9 -> 2990 | F8: =E8+D8 -> 33144 | G8: =WATER!V6 -> 391 | H8: ='Gas-2'!G6 -> 405 | I8: ='Diesel consumption'!D5 -> 8380 | J8: ='Diesel consumption'!H5 -> 4200 | K8: ='Diesel consumption'!P5 -> 0
A9: 2 | B9: =TOTAL!M3 -> 91 | C9: ='Room Nights and Food Covers'!D5 -> 258 | D9: =SUM('GENSET #1:GENSET #5'!D11) -> 29357 | E9: ='SOLAR METER READING'!D10 -> 3058 | F9: =E9+D9 -> 32415 | G9: =WATER!V7 -> 429 | H9: ='Gas-2'!G7 -> 270 | I9: ='Diesel consumption'!D6 -> 8520 | J9: ='Diesel consumption'!H6 -> 1110 | K9: ='Diesel consumption'!P6 -> 0
A10: 3 | B10: =TOTAL!M4 -> 91 | C10: ='Room Nights and Food Covers'!D6 -> 246 | D10: =SUM('GENSET #1:GENSET #5'!D12) -> 28987 | E10: ='SOLAR METER READING'!D11 -> 2887 | F10: =E10+D10 -> 31874 | G10: =WATER!V8 -> 399 | H10: ='Gas-2'!G8 -> 315 | I10: ='Diesel consumption'!D7 -> 8110 | J10: ='Diesel consumption'!H7 -> 2200 | K10: ='Diesel consumption'!P7 -> 0
A11: 4 | B11: =TOTAL!M5 -> 83 | C11: ='Room Nights and Food Covers'!D7 -> 253 | D11: =SUM('GENSET #1:GENSET #5'!D13) -> 28614 | E11: ='SOLAR METER READING'!D12 -> 3027 | F11: =E11+D11 -> 31641 | G11: =WATER!V9 -> 465 | H11: ='Gas-2'!G9 -> 270 | I11: ='Diesel consumption'!D8 -> 8050 | J11: ='Diesel consumption'!H8 -> 260 | K11: ='Diesel consumption'!P8 -> 0
A12: 5 | B12: =TOTAL!M6 -> 79 | C12: ='Room Nights and Food Covers'!D8 -> 232 | D12: =SUM('GENSET #1:GENSET #5'!D14) -> 28750 | E12: ='SOLAR METER READING'!D13 -> 2794 | F12: =E12+D12 -> 31544 | G12: =WATER!V10 -> 420 | H12: ='Gas-2'!G10 -> 360 | I12: ='Diesel consumption'!D9 -> 8160 | J12: ='Diesel consumption'!H9 -> 3340 | K12: ='Diesel consumption'!P9 -> 0
A13: 6 | B13: =TOTAL!M7 -> 69 | C13: ='Room Nights and Food Covers'!D9 -> 219 | D13: =SUM('GENSET #1:GENSET #5'!D15) -> 28931 | E13: ='SOLAR METER READING'!D14 -> 2867 | F13: =E13+D13 -> 31798 | G13: =WATER!V11 -> 375 | H13: ='Gas-2'!G11 -> 315 | I13: ='Diesel consumption'!D10 -> 8160 | J13: ='Diesel consumption'!H10 -> 1750 | K13: ='Diesel consumption'!P10 -> 0
A14: 7 | B14: =TOTAL!M8 -> 63 | C14: ='Room Nights and Food Covers'!D10 -> 189 | D14: =SUM('GENSET #1:GENSET #5'!D16) -> 27893 | E14: ='SOLAR METER READING'!D15 -> 2807 | F14: =E14+D14 -> 30700 | G14: =WATER!V12 -> 307 | H14: ='Gas-2'!G12 -> 270 | I14: ='Diesel consumption'!D11 -> 7810 | J14: ='Diesel consumption'!H11 -> 140 | K14: ='Diesel consumption'!P11 -> 0
A15: 8 | B15: =TOTAL!M9 -> 45 | C15: ='Room Nights and Food Covers'!D11 -> 174 | D15: =SUM('GENSET #1:GENSET #5'!D17) -> 26890 | E15: ='SOLAR METER READING'!D16 -> 2972 | F15: =E15+D15 -> 29862 | G15: =WATER!V13 -> 304 | H15: ='Gas-2'!G13 -> 315 | I15: ='Diesel consumption'!D12 -> 7650 | J15: ='Diesel consumption'!H12 -> 1660 | K15: ='Diesel consumption'!P12 -> 0
A16: 9 | B16: =TOTAL!M10 -> 44 | C16: ='Room Nights and Food Covers'!D12 -> 135 | D16: =SUM('GENSET #1:GENSET #5'!D18) -> 26500 | E16: ='SOLAR METER READING'!D17 -> 2822 | F16: =E16+D16 -> 29322 | G16: =WATER!V14 -> 331 | H16: ='Gas-2'!G14 -> 225 | I16: ='Diesel consumption'!D13 -> 7300 | J16: ='Diesel consumption'!H13 -> 1640 | K16: ='Diesel consumption'!P13 -> 0
A17: 10 | B17: =TOTAL!M11 -> 38 | C17: ='Room Nights and Food Covers'!D13 -> 127 | D17: =SUM('GENSET #1:GENSET #5'!D19) -> 25974 | E17: ='SOLAR METER READING'!D18 -> 2734 | F17: =E17+D17 -> 28708 | G17: =WATER!V15 -> 306 | H17: ='Gas-2'!G15 -> 270 | I17: ='Diesel consumption'!D14 -> 7280 | J17: ='Diesel consumption'!H14 -> 1900 | K17: ='Diesel consumption'!P14 -> 0
