Workbook

Sheet TOTAL
A1: Site Name | B1: Day | C1: Month | D1: Year | E1: Total Electricity Kwh | F1: Electricity Tariff ($/Kwh) | G1: LPG (Kg) | H1: LPG $/Kg | I1: Water Utility Supply (m3) m3 | J1: Water Utility Supply (m3) $/m3 | K1: Irrigation Water (m3) m3 | L1: Irrigation water $/m3 | M1: Room Nights | N1: Total Guests
A2: Dubai at Jumeirah Beach | B2: 1 | C2: 4 | D2: 2022 | E2: =Submetering!M2+Submetering!N2+Submetering!O2+Submetering!P2+Submetering!Q2+Submetering!R2+Submetering!S2+Submetering!T2+Submetering!U2+Submetering!V2 -> 42337.68 | F2: 0.44448 | G2: =SUM(Submetering!Z2:AB2,Submetering!AD2:AI2) -> 852.39 | H2: =2.32/0.52 -> 4.4615385 | I2: =Submetering!G2 -> 691 | J2: 13.83 | K2: =Submetering!I2 -> 137 | L2: 1.2 | M2: =Submetering!E2 -> 199.08 | N2: =Submetering!F2 -> 380
A3: Dubai at Jumeirah Beach | B3: =B2+1 -> 2 | C3: 4 | D3: 2022 | E3: =Submetering!M3+Submetering!N3+Submetering!O3+Submetering!P3+Submetering!Q3+Submetering!R3+Submetering!S3+Submetering!T3+Submetering!U3+Submetering!V3 -> 44432.64 | F3: 0.44448 | G3: =SUM(Submetering!Z3:AB3,Submetering!AD3:AI3) -> 644.49 | H3: =2.32/0.52 -> 4.4615385 | I3: =Submetering!G3 -> 754 | J3: 13.83 | K3: =Submetering!I3 -> 328 | L3: 1.2 | M3: =Submetering!E3 -> 180.12 | N3: =Submetering!F3 -> 365
A4: Dubai at Jumeirah Beach | B4: =B3+1 -> 3 | C4: 4 | D4: 2022 | E4: =Submetering!M4+Submetering!N4+Submetering!O4+Submetering!P4+Submetering!Q4+Submetering!R4+Submetering!S4+Submetering!T4+Submetering!U4+Submetering!V4 -> 43068.48 | F4: 0.44448 | G4: =SUM(Submetering!Z4:AB4,Submetering!AD4:AI4) -> 678.51 | H4: =2.32/0.52 -> 4.4615385 | I4: =Submetering!G4 -> 709 | J4: 13.83 | K4: =Submetering!I4 -> 330 | L4: 1.2 | M4: =Submetering!E4 -> 173.01 | N4: =Submetering!F4 -> 389
A5: Dubai at Jumeirah Beach | B5: =B4+1 -> 4 | C5: 4 | D5: 2022 | E5: =Submetering!M5+Submetering!N5+Submetering!O5+Submetering!P5+Submetering!Q5+Submetering!R5+Submetering!S5+Submetering!T5+Submetering!U5+Submetering!V5 -> 42678.72 | F5: 0.44448 | G5: =SUM(Submetering!Z5:AB5,Submetering!AD5:AI5) -> 680.4 | H5: =2.32/0.52 -> 4.4615385 | I5: =Submetering!G5 -> 782 | J5: 13.83 | K5: =Submetering!I5 -> 319 | L5: 1.2 | M5: =Submetering!E5 -> 173.01 | N5: =Submetering!F5 -> 334
A6: Dubai at Jumeirah Beach | B6: =B5+1 -> 5 | C6: 4 | D6: 2022 | E6: =Submetering!M6+Submetering!N6+Submetering!O6+Submetering!P6+Submetering!Q6+Submetering!R6+Submetering!S6+Submetering!T6+Submetering!U6+Submetering!V6 -> 44432.64 | F6: 0.44448 | G6: =SUM(Submetering!Z6:AB6,Submetering!AD6:AI6) -> 570.78 | H6: =2.32/0.52 -> 4.4615385 | I6: =Submetering!G6 -> 668 | J6: 13.83 | K6: =Submetering!I6 -> 323 | L6: 1.2 | M6: =Submetering!E6 -> 175.38 | N6: =Submetering!F6 -> 331
A7: Dubai at Jumeirah Beach | B7: =B6+1 -> 6 | C7: 4 | D7: 2022 | E7: =Submetering!M7+Submetering!N7+Submetering!O7+Submetering!P7+Submetering!Q7+Submetering!R7+Submetering!S7+Submetering!T7+Submetering!U7+Submetering!V7 -> 44042.88 | F7: 0.44448 | G7: =SUM(Submetering!Z7:AB7,Submetering!AD7:AI7) -> 561.33 | H7: =2.32/0.52 -> 4.4615385 | I7: =Submetering!G7 -> 709 | J7: 13.83 | K7: =Submetering!I7 -> 336 | L7: 1.2 | M7: =Submetering!E7 -> 168.27 | N7: =Submetering!F7 -> 346
A8: Dubai at Jumeirah Beach | B8: =B7+1 -> 7 | C8: 4 | D8: 2022 | E8: =Submetering!M8+Submetering!N8+Submetering!O8+Submetering!P8+Submetering!Q8+Submetering!R8+Submetering!S8+Submetering!T8+Submetering!U8+Submetering!V8 -> 42824.88 | F8: 0.44448 | G8: =SUM(Submetering!Z8:AB8,Submetering!AD8:AI8) -> 557.55 | H8: =2.32/0.52 -> 4.4615385 | I8: =Submetering!G8 -> 704 | J8: 13.83 | K8: =Submetering!I8 -> 310 | L8: 1.2 | M8: =Submetering!E8 -> 170.64 | N8: =Submetering!F8 -> 345
A9: Dubai at Jumeirah Beach | B9: =B8+1 -> 8 | C9: 4 | D9: 2022 | E9: =Submetering!M9+Submetering!N9+Submetering!O9+Submetering!P9+Submetering!Q9+Submetering!R9+Submetering!S9+Submetering!T9+Submetering!U9+Submetering!V9 -> 45601.92 | F9: 0.44448 | G9: =SUM(Submetering!Z9:AB9,Submetering!AD9:AI9) -> 585.9 | H9: =2.32/0.52 -> 4.4615385 | I9: =Submetering!G9 -> 790 | J9: 13.83 | K9: =Submetering!I9 -> 338 | L9: 1.2 | M9: =Submetering!E9 -> 177.75 | N9: =Submetering!F9 -> 367
A10: Dubai at Jumeirah Beach | B10: =B9+1 -> 9 | C10: 4 | D10: 2022 | E10: =Submetering!M10+Submetering!N10+Submetering!O10+Submetering!P10+Submetering!Q10+Submetering!R10+Submetering!S10+Submetering!T10+Submetering!U10+Submetering!V10 -> 43360.8 | F10: 0.44448 | G10: =SUM(Submetering!Z10:AB10,Submetering!AD10:AI10) -> 693.63 | H10: =2.32/0.52 -> 4.4615385 | I10: =Submetering!G10 -> 734 | J10: 13.83 | K10: =Submetering!I10 -> 313 | L10: 1.2 | M10: =Submetering!E10 -> 189.6 | N10: =Submetering!F10 -> 405
A11: Dubai at Jumeirah Beach | B11: =B10+1 -> 10 | C11: 4 | D11: 2022 | E11: =Submetering!M11+Submetering!N11+Submetering!O11+Submetering!P11+Submetering!Q11+Submetering!R11+Submetering!S11+Submetering!T11+Submetering!U11+Submetering!V11 -> 44432.64 | F11: 0.44448 | G11: =SUM(Submetering!Z11:AB11,Submetering!AD11:AI11) -> 824.04 | H11: =2.32/0.52 -> 4.4615385 | I11: =Submetering!G11 -> 712 | J11: 13.83 | K11: =Submetering!I11 -> 320 | L11: 1.2 | M11: =Submetering!E11 -> 206.19 | N11: =Submetering!F11 -> 446
A12: Dubai at Jumeirah Beach | B12: =B11+1 -> 11 | C12: 4 | D12: 2022 | E12: =Submetering!M12+Submetering!N12+Submetering!O12+Submetering!P12+Submetering!Q12+Submetering!R12+Submetering!S12+Submetering!T12+Submetering!U12+Submetering!V12 -> 44237.76 | F12: 0.44448 | G12: =SUM(Submetering!Z12:AB12,Submetering!AD12:AI12) -> 725.76 | H12: =2.32/0.52 -> 4.4615385 | I12: =Submetering!G12 -> 741 | J12: 13.83 | K12: =Submetering!I12 -> 322 | L12: 1.2 | M12: =Submetering!E12 -> 201.45 | N12: =Submetering!F12 -> 417
A13: Dubai at Jumeirah Beach | B13: =B12+1 -> 12 | C13: 4 | D13: 2022 | E13: =Submetering!M13+Submetering!N13+Submetering!O13+Submetering!P13+Submetering!Q13+Submetering!R13+Submetering!S13+Submetering!T13+Submetering!U13+Submetering!V13 -> 44335.2 | F13: 0.44448 | G13: =SUM(Submetering!Z13:AB13,Submetering!AD13:AI13) -> 680.4 | H13: =2.32/0.52 -> 4.4615385 | I13: =Submetering!G13 -> 822 | J13: 13.83 | K13: =Submetering!I13 -> 326 | L13: 1.2 | M13: =Submetering!E13 -> 201.45 | N13: =Submetering!F13 -> 424
A14: Dubai at Jumeirah Beach | B14: =B13+1 -> 13 | C14: 4 | D14: 2022 | E14: =Submetering!M14+Submetering!N14+Submetering!O14+Submetering!P14+Submetering!Q14+Submetering!R14+Submetering!S14+Submetering!T14+Submetering!U14+Submetering!V14 -> 44189.04 | F14: 0.44448 | G14: =SUM(Submetering!Z14:AB14,Submetering!AD14:AI14) -> 674.73 | H14: =2.32/0.52 -> 4.4615385 | I14: =Submetering!G14 -> 706 | J14: 13.83 | K14: =Submetering!I14 -> 330 | L14: 1.2 | M14: =Submetering!E14 -> 203.82 | N14: =Submetering!F14 -> 424
... A31: Dubai at Jumeirah Beach | B31: =B30+1 -> 30 | C31: 4 | D31: 2022 | E31: =Submetering!M31+Submetering!N31+Submetering!O31+Submetering!P31+Submetering!Q31+Submetering!R31+Submetering!S31+Submetering!T31+Submetering!U31+Submetering!V31 -> 46576.32 | F31: 0.44448 | G31: =SUM(Submetering!Z31:AB31,Submetering!AD31:AI31) -> 616.14 | H31: =2.32/0.52 -> 4.4615385 | I31: =Submetering!G31 -> 767 | J31: 13.83 | K31: =Submetering!I31 -> 302 | L31: 1.2 | M31: =Submetering!E31 -> 173.01 | N31: =Submetering!F31 -> 341

Sheet Submetering
A1: Site Name | B1: Day | C1: Month | D1: Year | E1: Room Nights | F1: Total Guests | G1: Potable Water -IG (m3) | H1: Resort Water (m3) | I1: Tse Water (m3) | J1: Irrigation (m3) | K1: Cooling Tower Water (m3) | L1: Cooling Tower Blowdown (m3) | M1: EMDB-1 All Pumps (KWh) | N1: EMDB-2 Elevators (KWh) | O1: MDB-1 Chiller #1 (KWh) | P1: MDB-2 Chiller #2 (KWh) | Q1: MDB-3 Chiller #3(KWh) | R1: MDB-4 North Riser (KWh) | S1: MDB-5 North Riser (KWh) | T1: MDB-6 Main Kitchen (KWh) | U1: MDB-7 South Riser (KWh) | V1: MDB-8 F&B (KWh) | W1: Chiller 1 (Kwh cooling) | X1: Chiller 2 (Kwh cooling) | Y1: Chiller 3 (Kwh cooling) | Z1: Steam Boiler LPG (Kg) | AA1: Solar Hot Water Boiler LPG (Kg) | AB1: Low Temp Hot Water Boiler LPG (Kg) | AC1: Steam Boiler Steam (Kg) | AD1: Ird Kitchen (Kg) | AE1: Suq Kitchen (Kg) | AF1: Bakery Kitchen (Kg) | AG1: Shai Saloon Kitchen (kg) | AH1: Banquet Kitchen (Kg) | AI1: Sea Fu Kitchen (Kg) | AJ1: Jean George Cold Water (m³) | AK1: Jean George Hot Water (m³) | AL1: Coya Cold Water (m³) | AM1: Coya Hot Water (m³) | AN1: Nusrat Cold Water (m³) | AO1: Nusrat Hot Water (m³) | AP1: Provocateur Cold Water (m³) | AQ1: Provocateur Hot Water (m³) | AR1: Scalini Cold Water (m³) | AS1: Scalini Hot Water (m³) | AT1: F&B V Irrigation (m³) | AU1: MDB Coya (KWh) | AV1: MDB Jean Georges (KWh) | AW1: MDB Nusrat(KWh) | AX1: SMDB Provocateur (KWh) | AY1: SMDB Scalini (KWh) | AZ1: Common ESMDB (KWh) | BA1: Chilled Water Coya (Kwh) | BB1: Chilled Water Coya Cold Room (Kwh) | BC1: Chilled Water Jean Georges (Kwh) | BD1: Chilled Water Nusrat (Kwh) | BE1: Chilled Water Provocateur A (Kwh) | BF1: Chilled Water Provocateur B (Kwh) | BG1: Coya LPG (Kg) | BH1: Nusrat LPG (Kg) | BI1: Jean Georges LPG (Kg) | BJ1: Provocateur LPG (Kg) | BK1: Scalini LPG (Kg)
A2: Dubai at Jumeirah Beach | B2: 1 | C2: 4 | D2: 2022 | E2: =237*0.84 -> 199.08 | F2: =335+45 -> 380 | G2: ='DJB Daily Readings'!C10-'DJB Daily Readings'!C9 -> 691 | H2: ='DJB Daily Readings'!F10-'DJB Daily Readings'!F9 -> 441 | I2: ='DJB Daily Readings'!K10-'DJB Daily Readings'!K9 -> 137 | J2: ='DJB Daily Readings'!K10-'DJB Daily Readings'!K9 -> 137 | K2: ='DJB Daily Readings'!O10-'DJB Daily Readings'!O9 -> 107.68 | L2: ='DJB Daily Readings'!R10-'DJB Daily Readings'!R9 -> 7 | M2: ='DJB Daily Readings'!U10-'DJB Daily Readings'!U9 -> 2046.24 | N2: ='DJB Daily Readings'!X10-'DJB Daily Readings'!X9 -> 4823.28 | O2: ='DJB Daily Readings'!AA10-'DJB Daily Readings'!AA9 -> 341.04 | P2: ='DJB Daily Readings'!AD10-'DJB Daily Readings'!AD9 -> 10962 | Q2: ='DJB Daily Readings'!AG10-'DJB Daily Readings'!AG9 -> 779.52 | R2: ='DJB Daily Readings'!AJ10-'DJB Daily Readings'!AJ9 -> 5456.64 | S2: ='DJB Daily Readings'!AM10-'DJB Daily Readings'!AM9 -> 4336.08 | T2: ='DJB Daily Readings'!AP10-'DJB Daily Readings'!AP9 -> 4677.12 | U2: ='DJB Daily Readings'!AS10-'DJB Daily Readings'!AS9 -> 3069.36 | V2: ='DJB Daily Readings'!AV10-'DJB Daily Readings'!AV9 -> 5846.4 | W2: ='DJB Daily Readings'!AZ10-'DJB Daily Readings'!AZ9 -> 0 | X2: ='DJB Daily Readings'!BC10-'DJB Daily Readings'!BC9 -> 61400 | Y2: ='DJB Daily Readings'!BF10-'DJB Daily Readings'!BF9 -> 0 | Z2: =('DJB Daily Readings'!CK10-'DJB Daily Readings'!CK9)*1.89 -> 198.45 | AA2: =('DJB Daily Readings'!CN10-'DJB Daily Readings'!CN9)*1.89 -> 221.13 | AB2: =('DJB Daily Readings'!CQ10-'DJB Daily Readings'!CQ9)*1.89 -> 266.49 | AC2: ='DJB Daily Readings'!CT10-'DJB Daily Readings'!CT9 -> 228 | AD2: =('DJB Daily Readings'!BY10-'DJB Daily Readings'!BY9)*1.89 -> 39.69 | AE2: =('DJB Daily Readings'!CA10-'DJB Daily Readings'!CA9)*1.89 -> 35.91 | AF2: =('DJB Daily Readings'!CC10-'DJB Daily Readings'!CC9)*1.89 -> 11.34 | AG2: =('DJB Daily Readings'!CE10-'DJB Daily Readings'!CE9)*1.89 -> 13.23 | AH2: =('DJB Daily Readings'!CG10-'DJB Daily Readings'!CG9)*1.89 -> 22.68 | AI2: =('DJB Daily Readings'!CI10-'DJB Daily Readings'!CI9)*1.89 -> 43.47 | AJ2: ='DJB Daily Readings'!CY10-'DJB Daily Readings'!CY9 -> 6 | AK2: ='DJB Daily Readings'!CW10-'DJB Daily Readings'!CW9 -> 8 | AL2: ='DJB Daily Readings'!DC10-'DJB Daily Readings'!DC9 -> 13 | AM2: ='DJB Daily Readings'!DA10-'DJB Daily Readings'!DA9 -> 16 | AN2: ='DJB Daily Readings'!DG10-'DJB Daily Readings'!DG9 -> 7 | AO2: ='DJB Daily Readings'!DE10-'DJB Daily Readings'!DE9 -> 10 | AP2: ='DJB Daily Readings'!DK10-'DJB Daily Readings'!DK9 -> 8 | AQ2: ='DJB Daily Readings'!DI10-'DJB Daily Readings'!DI9 -> 11 | AR2: ='DJB Daily Readings'!DO10-'DJB Daily Readings'!DO9 -> 7 | AS2: ='DJB Daily Readings'!DM10-'DJB Daily Readings'!DM9 -> 3 | AT2: ='DJB Daily Readings'!DQ10-'DJB Daily Readings'!DQ9 -> 9 | AU2: ='DJB Daily Readings'!DT10-'DJB Daily Readings'!DT9 -> 9.2 | AW2: ='DJB Daily Readings'!DX10-'DJB Daily Readings'!DX9 -> 6.5 | AX2: ='DJB Daily Readings'!DZ10-'DJB Daily Readings'!DZ9 -> 8.7 | AY2: ='DJB Daily Readings'!EB10-'DJB Daily Readings'!EB9 -> 707 | AZ2: ='DJB Daily Readings'!ED10-'DJB Daily Readings'!ED9 -> 154.7 | BA2: ='DJB Daily Readings'!EG10-'DJB Daily Readings'!EG9 -> 4000 | BB2: ='DJB Daily Readings'!EI10-'DJB Daily Readings'!EI9 -> 230 | BC2: ='DJB Daily Readings'!EQ10-'DJB Daily Readings'!EQ9 -> 4200 | BD2: ='DJB Daily Readings'!EK10-'DJB Daily Readings'!EK9 -> 1900 | BE2: ='DJB Daily Readings'!EM10-'DJB Daily Readings'!EM9 -> 500 | BF2: ='DJB Daily Readings'!EO10-'DJB Daily Readings'!EO9 -> 610 | BG2: =('DJB Daily Readings'!ET10-'DJB Daily Readings'!ET9)*1.89 -> 32.13 | BH2: =('DJB Daily Readings'!EV10-'DJB Daily Readings'!EV9)*1.89 -> 24.57 | BI2: =('DJB Daily Readings'!EZ10-'DJB Daily Readings'!EZ9)*1.89 -> 22.68 | BJ2: =('DJB Daily Readings'!EX10-'DJB Daily Readings'!EX9)*1.89 -> 18.9 | BK2: =('DJB Daily Readings'!FB10-'DJB Daily Readings'!FB9)*1.89 -> 56.7
A3: Dubai at Jumeirah Beach | B3: =B2+1 -> 2 | C3: 4 | D3: 2022 | E3: =237*0.76 -> 180.12 | F3: =317+48 -> 365 | G3: ='DJB Daily Readings'!C11-'DJB Daily Readings'!C10 -> 754 | H3: ='DJB Daily Readings'!F11-'DJB Daily Readings'!F10 -> 436 | I3: ='DJB Daily Readings'!K11-'DJB Daily Readings'!K10 -> 328 | J3: ='DJB Daily Readings'!K11-'DJB Daily Readings'!K10 -> 328 | K3: ='DJB Daily Readings'!O11-'DJB Daily Readings'!O10 -> 126.81 | L3: ='DJB Daily Readings'!R11-'DJB Daily Readings'!R10 -> 12 | M3: ='DJB Daily Readings'!U11-'DJB Daily Readings'!U10 -> 2777.04 | N3: ='DJB Daily Readings'!X11-'DJB Daily Readings'!X10 -> 4677.12 | O3: ='DJB Daily Readings'!AA11-'DJB Daily Readings'!AA10 -> 876.96 | P3: ='DJB Daily Readings'!AD11-'DJB Daily Readings'!AD10 -> 779.52 | Q3: ='DJB Daily Readings'!AG11-'DJB Daily Readings'!AG10 -> 11790.24 | R3: ='DJB Daily Readings'!AJ11-'DJB Daily Readings'!AJ10 -> 5748.96 | S3: ='DJB Daily Readings'!AM11-'DJB Daily Readings'!AM10 -> 4189.92 | T3: ='DJB Daily Readings'!AP11-'DJB Daily Readings'!AP10 -> 4969.44 | U3: ='DJB Daily Readings'!AS11-'DJB Daily Readings'!AS10 -> 2825.76 | V3: ='DJB Daily Readings'!AV11-'DJB Daily Readings'!AV10 -> 5797.68 | W3: ='DJB Daily Readings'!AZ11-'DJB Daily Readings'!AZ10 -> 0 | X3: ='DJB Daily Readings'!BC11-'DJB Daily Readings'!BC10 -> 2300 | Y3: ='DJB Daily Readings'!BF11-'DJB Daily Readings'!BF10 -> 64100 | Z3: =('DJB Daily Readings'!CK11-'DJB Daily Readings'!CK10)*1.89 -> 204.12 | AA3: =('DJB Daily Readings'!CN11-'DJB Daily Readings'!CN10)*1.89 -> 198.45 | AB3: =('DJB Daily Readings'!CQ11-'DJB Daily Readings'!CQ10)*1.89 -> 83.16 | AC3: ='DJB Daily Readings'!CT11-'DJB Daily Readings'!CT10 -> 252 | AD3: =('DJB Daily Readings'!BY11-'DJB Daily Readings'!BY10)*1.89 -> 37.8 | AE3: =('DJB Daily Readings'!CA11-'DJB Daily Readings'!CA10)*1.89 -> 35.91 | AF3: =('DJB Daily Readings'!CC11-'DJB Daily Readings'!CC10)*1.89 -> 7.56 | AG3: =('DJB Daily Readings'!CE11-'DJB Daily Readings'!CE10)*1.89 -> 11.34 | AH3: =('DJB Daily Readings'!CG11-'DJB Daily Readings'!CG10)*1.89 -> 17.01 | AI3: =('DJB Daily Readings'!CI11-'DJB Daily Readings'!CI10)*1.89 -> 49.14 | AJ3: ='DJB Daily Readings'!CY11-'DJB Daily Readings'!CY10 -> 6 | AK3: ='DJB Daily Readings'!CW11-'DJB Daily Readings'!CW10 -> 6 | AL3: ='DJB Daily Readings'!DC11-'DJB Daily Readings'!DC10 -> 13 | AM3: ='DJB Daily Readings'!DA11-'DJB Daily Readings'!DA10 -> 16 | AN3: ='DJB Daily Readings'!DG11-'DJB Daily Readings'!DG10 -> 7 | AO3: ='DJB Daily Readings'!DE11-'DJB Daily Readings'!DE10 -> 10 | AP3: ='DJB Daily Readings'!DK11-'DJB Daily Readings'!DK10 -> 8 | AQ3: ='DJB Daily Readings'!DI11-'DJB Daily Readings'!DI10 -> 11 | AR3: ='DJB Daily Readings'!DO11-'DJB Daily Readings'!DO10 -> 7 | AS3: ='DJB Daily Readings'!DM11-'DJB Daily Readings'!DM10 -> 4 | AT3: ='DJB Daily Readings'!DQ11-'DJB Daily Readings'!DQ10 -> 18 | AU3: ='DJB Daily Readings'!DT11-'DJB Daily Readings'!DT10 -> 9.4 | AW3: ='DJB Daily Readings'!DX11-'DJB Daily Readings'!DX10 -> 6.3 | AX3: ='DJB Daily Readings'!DZ11-'DJB Daily Readings'!DZ10 -> 9.9 | AY3: ='DJB Daily Readings'!EB11-'DJB Daily Readings'!EB10 -> 672 | AZ3: ='DJB Daily Readings'!ED11-'DJB Daily Readings'!ED10 -> 158.2 | BA3: ='DJB Daily Readings'!EG11-'DJB Daily Readings'!EG10 -> 4800 | BB3: ='DJB Daily Readings'!EI11-'DJB Daily Readings'!EI10 -> 250 | BC3: ='DJB Daily Readings'!EQ11-'DJB Daily Readings'!EQ10 -> 5400 | BD3: ='DJB Daily Readings'!EK11-'DJB Daily Readings'!EK10 -> 2200 | BE3: ='DJB Daily Readings'!EM11-'DJB Daily Readings'!EM10 -> 800 | BF3: ='DJB Daily Readings'!EO11-'DJB Daily Readings'!EO10 -> 320 | BG3: =('DJB Daily Readings'!ET11-'DJB Daily Readings'!ET10)*1.89 -> 35.91 | BH3: =('DJB Daily Readings'!EV11-'DJB Daily Readings'!EV10)*1.89 -> 20.79 | BI3: =('DJB Daily Readings'!EZ11-'DJB Daily Readings'!EZ10)*1.89 -> 22.68 | BJ3: =('DJB Daily Readings'!EX11-'DJB Daily Readings'!EX10)*1.89 -> 24.57 | BK3: =('DJB Daily Readings'!FB11-'DJB Daily Readings'!FB10)*1.89 -> 51.03
A4: Dubai at Jumeirah Beach | B4: =B3+1 -> 3 | C4: 4 | D4: 2022 | E4: =237*0.73 -> 173.01 | F4: =333+56 -> 389 | G4: ='DJB Daily Readings'!C12-'DJB Daily Readings'!C11 -> 709 | H4: ='DJB Daily Readings'!F12-'DJB Daily Readings'!F11 -> 369 | I4: ='DJB Daily Readings'!K12-'DJB Daily Readings'!K11 -> 330 | J4: ='DJB Daily Readings'!K12-'DJB Daily Readings'!K11 -> 330 | K4: ='DJB Daily Readings'!O12-'DJB Daily Readings'!O11 -> 118.14 | L4: ='DJB Daily Readings'!R12-'DJB Daily Readings'!R11 -> 15 | M4: ='DJB Daily Readings'!U12-'DJB Daily Readings'!U11 -> 2777.04 | N4: ='DJB Daily Readings'!X12-'DJB Daily Readings'!X11 -> 4725.84 | O4: ='DJB Daily Readings'!AA12-'DJB Daily Readings'!AA11 -> 876.96 | P4: ='DJB Daily Readings'!AD12-'DJB Daily Readings'!AD11 -> 389.76 | Q4: ='DJB Daily Readings'!AG12-'DJB Daily Readings'!AG11 -> 11546.64 | R4: ='DJB Daily Readings'!AJ12-'DJB Daily Readings'!AJ11 -> 5602.8 | S4: ='DJB Daily Readings'!AM12-'DJB Daily Readings'!AM11 -> 4336.08 | T4: ='DJB Daily Readings'!AP12-'DJB Daily Readings'!AP11 -> 4677.12 | U4: ='DJB Daily Readings'!AS12-'DJB Daily Readings'!AS11 -> 2825.76 | V4: ='DJB Daily Readings'!AV12-'DJB Daily Readings'!AV11 -> 5310.48 | W4: ='DJB Daily Readings'!AZ12-'DJB Daily Readings'!AZ11 -> 0 | X4: ='DJB Daily Readings'!BC12-'DJB Daily Readings'!BC11 -> 0 | Y4: ='DJB Daily Readings'!BF12-'DJB Daily Readings'!BF11 -> 65300 | Z4: =('DJB Daily Readings'!CK12-'DJB Daily Readings'!CK11)*1.89 -> 207.9 | AA4: =('DJB Daily Readings'!CN12-'DJB Daily Readings'!CN11)*1.89 -> 206.01 | AB4: =('DJB Daily Readings'!CQ12-'DJB Daily Readings'!CQ11)*1.89 -> 105.84 | AC4: ='DJB Daily Readings'!CT12-'DJB Daily Readings'!CT11 -> 256 | AD4: =('DJB Daily Readings'!BY12-'DJB Daily Readings'!BY11)*1.89 -> 32.13 | AE4: =('DJB Daily Readings'!CA12-'DJB Daily Readings'!CA11)*1.89 -> 34.02 | AF4: =('DJB Daily Readings'!CC12-'DJB Daily Readings'!CC11)*1.89 -> 9.45 | AG4: =('DJB Daily Readings'!CE12-'DJB Daily Readings'!CE11)*1.89 -> 13.23 | AH4: =('DJB Daily Readings'!CG12-'DJB Daily Readings'!CG11)*1.89 -> 24.57 | AI4: =('DJB Daily Readings'!CI12-'DJB Daily Readings'!CI11)*1.89 -> 45.36 | AJ4: ='DJB Daily Readings'!CY12-'DJB Daily Readings'!CY11 -> 2 | AK4: ='DJB Daily Readings'!CW12-'DJB Daily Readings'!CW11 -> 2 | AL4: ='DJB Daily Readings'!DC12-'DJB Daily Readings'!DC11 -> 15 | AM4: ='DJB Daily Readings'!DA12-'DJB Daily Readings'!DA11 -> 18 | AN4: ='DJB Daily Readings'!DG12-'DJB Daily Readings'!DG11 -> 6 | AO4: ='DJB Daily Readings'!DE12-'DJB Daily Readings'!DE11 -> 4 | AP4: ='DJB Daily Readings'!DK12-'DJB Daily Readings'!DK11 -> 6 | AQ4: ='DJB Daily Readings'!DI12-'DJB Daily Readings'!DI11 -> 12 | AR4: ='DJB Daily Readings'!DO12-'DJB Daily Readings'!DO11 -> 1 | AS4: ='DJB Daily Readings'!DM12-'DJB Daily Readings'!DM11 -> 3 | AT4: ='DJB Daily Readings'!DQ12-'DJB Daily Readings'!DQ11 -> 17 | AU4: ='DJB Daily Readings'!DT12-'DJB Daily Readings'!DT11 -> 8.4 | AW4: ='DJB Daily Readings'!DX12-'DJB Daily Readings'!DX11 -> 6 | AX4: ='DJB Daily Readings'!DZ12-'DJB Daily Readings'!DZ11 -> 8.9 | AY4: ='DJB Daily Readings'!EB12-'DJB Daily Readings'!EB11 -> 652 | AZ4: ='DJB Daily Readings'!ED12-'DJB Daily Readings'!ED11 -> 146.2 | BA4: ='DJB Daily Readings'!EG12-'DJB Daily Readings'!EG11 -> 4200 | BB4: ='DJB Daily Readings'!EI12-'DJB Daily Readings'!EI11 -> 220 | BC4: ='DJB Daily Readings'!EQ12-'DJB Daily Readings'!EQ11 -> 4900 | BD4: ='DJB Daily Readings'!EK12-'DJB Daily Readings'!EK11 -> 2000 | BE4: ='DJB Daily Readings'!EM12-'DJB Daily Readings'!EM11 -> 600 | BF4: ='DJB Daily Readings'!EO12-'DJB Daily Readings'!EO11 -> 990 | BG4: =('DJB Daily Readings'!ET12-'DJB Daily Readings'!ET11)*1.89 -> 28.35 | BH4: =('DJB Daily Readings'!EV12-'DJB Daily Readings'!EV11)*1.89 -> 17.01 | BI4: =('DJB Daily Readings'!EZ12-'DJB Daily Readings'!EZ11)*1.89 -> 13.23 | BJ4: =('DJB Daily Readings'!EX12-'DJB Daily Readings'!EX11)*1.89 -> 24.57 | BK4: =('DJB Daily Readings'!FB12-'DJB Daily Readings'!FB11)*1.89 -> 39.69
A5: Dubai at Jumeirah Beach | B5: =B4+1 -> 4 | C5: 4 | D5: 2022 | E5: =237*0.73 -> 173.01 | F5: =276+58 -> 334 | G5: ='DJB Daily Readings'!C13-'DJB Daily Readings'!C12 -> 782 | H5: ='DJB Daily Readings'!F13-'DJB Daily Readings'!F12 -> 351 | I5: ='DJB Daily Readings'!K13-'DJB Daily Readings'!K12 -> 319 | J5: ='DJB Daily Readings'!K13-'DJB Daily Readings'!K12 -> 319 | K5: ='DJB Daily Readings'!O13-'DJB Daily Readings'!O12 -> 122.58 | L5: ='DJB Daily Readings'!R13-'DJB Daily Readings'!R12 -> 8 | M5: ='DJB Daily Readings'!U13-'DJB Daily Readings'!U12 -> 2728.32 | N5: ='DJB Daily Readings'!X13-'DJB Daily Readings'!X12 -> 4774.56 | O5: ='DJB Daily Readings'!AA13-'DJB Daily Readings'!AA12 -> 828.24 | P5: ='DJB Daily Readings'!AD13-'DJB Daily Readings'!AD12 -> 438.48 | Q5: ='DJB Daily Readings'!AG13-'DJB Daily Readings'!AG12 -> 11692.8 | R5: ='DJB Daily Readings'!AJ13-'DJB Daily Readings'!AJ12 -> 5651.52 | S5: ='DJB Daily Readings'!AM13-'DJB Daily Readings'!AM12 -> 4141.2 | T5: ='DJB Daily Readings'!AP13-'DJB Daily Readings'!AP12 -> 4482.24 | U5: ='DJB Daily Readings'!AS13-'DJB Daily Readings'!AS12 -> 2679.6 | V5: ='DJB Daily Readings'!AV13-'DJB Daily Readings'!AV12 -> 5261.76 | W5: ='DJB Daily Readings'!AZ13-'DJB Daily Readings'!AZ12 -> 0 | X5: ='DJB Daily Readings'!BC13-'DJB Daily Readings'!BC12 -> 0 | Y5: ='DJB Daily Readings'!BF13-'DJB Daily Readings'!BF12 -> 63500 | Z5: =('DJB Daily Readings'!CK13-'DJB Daily Readings'!CK12)*1.89 -> 207.9 | AA5: =('DJB Daily Readings'!CN13-'DJB Daily Readings'!CN12)*1.89 -> 192.78 | AB5: =('DJB Daily Readings'!CQ13-'DJB Daily Readings'!CQ12)*1.89 -> 128.52 | AC5: ='DJB Daily Readings'!CT13-'DJB Daily Readings'!CT12 -> 256 | AD5: =('DJB Daily Readings'!BY13-'DJB Daily Readings'!BY12)*1.89 -> 28.35 | AE5: =('DJB Daily Readings'!CA13-'DJB Daily Readings'!CA12)*1.89 -> 35.91 | AF5: =('DJB Daily Readings'!CC13-'DJB Daily Readings'!CC12)*1.89 -> 7.56 | AG5: =('DJB Daily Readings'!CE13-'DJB Daily Readings'!CE12)*1.89 -> 17.01 | AH5: =('DJB Daily Readings'!CG13-'DJB Daily Readings'!CG12)*1.89 -> 15.12 | AI5: =('DJB Daily Readings'!CI13-'DJB Daily Readings'!CI12)*1.89 -> 47.25 | AJ5: ='DJB Daily Readings'!CY13-'DJB Daily Readings'!CY12 -> 3 | AK5: ='DJB Daily Readings'!CW13-'DJB Daily Readings'!CW12 -> 3 | AL5: ='DJB Daily Readings'!DC13-'DJB Daily Readings'!DC12 -> 14 | AM5: ='DJB Daily Readings'!DA13-'DJB Daily Readings'!DA12 -> 14 | AN5: ='DJB Daily Readings'!DG13-'DJB Daily Readings'!DG12 -> 6 | AO5: ='DJB Daily Readings'!DE13-'DJB Daily Readings'!DE12 -> 8 | AP5: ='DJB Daily Readings'!DK13-'DJB Daily Readings'!DK12 -> 3 | AQ5: ='DJB Daily Readings'!DI13-'DJB Daily Readings'!DI12 -> 8 | AR5: ='DJB Daily Readings'!DO13-'DJB Daily Readings'!DO12 -> 5 | AS5: ='DJB Daily Readings'!DM13-'DJB Daily Readings'!DM12 -> 3 | AT5: ='DJB Daily Readings'!DQ13-'DJB Daily Readings'!DQ12 -> 18 | AU5: ='DJB Daily Readings'!DT13-'DJB Daily Readings'!DT12 -> 8.2 | AW5: ='DJB Daily Readings'!DX13-'DJB Daily Readings'!DX12 -> 6.2 | AX5: ='DJB Daily Readings'!DZ13-'DJB Daily Readings'!DZ12 -> 8.6 | AY5: ='DJB Daily Readings'!EB13-'DJB Daily Readings'!EB12 -> 670 | AZ5: ='DJB Daily Readings'!ED13-'DJB Daily Readings'!ED12 -> 148 | BA5: ='DJB Daily Readings'!EG13-'DJB Daily Readings'!EG12 -> 4500 | BB5: ='DJB Daily Readings'!EI13-'DJB Daily Readings'!EI12 -> 230 | BC5: ='DJB Daily Readings'!EQ13-'DJB Daily Readings'!EQ12 -> 4800 | BD5: ='DJB Daily Readings'!EK13-'DJB Daily Readings'!EK12 -> 2200 | BE5: ='DJB Daily Readings'!EM13-'DJB Daily Readings'!EM12 -> 400 | BF5: ='DJB Daily Readings'!EO13-'DJB Daily Readings'!EO12 -> 630 | BG5: =('DJB Daily Readings'!ET13-'DJB Daily Readings'!ET12)*1.89 -> 26.46 | BH5: =('DJB Daily Readings'!EV13-'DJB Daily Readings'!EV12)*1.89 -> 18.9 | BI5: =('DJB Daily Readings'!EZ13-'DJB Daily Readings'!EZ12)*1.89 -> 18.9 | BJ5: =('DJB Daily Readings'!EX13-'DJB Daily Readings'!EX12)*1.89 -> 15.12 | BK5: =('DJB Daily Readings'!FB13-'DJB Daily Readings'!FB12)*1.89 -> 43.47
A6: Dubai at Jumeirah Beach | B6: =B5+1 -> 5 | C6: 4 | D6: 2022 | E6: =237*0.74 -> 175.38 | F6: =271+60 -> 331 | G6: ='DJB Daily Readings'!C14-'DJB Daily Readings'!C13 -> 668 | H6: ='DJB Daily Readings'!F14-'DJB Daily Readings'!F13 -> 354 | I6: ='DJB Daily Readings'!K14-'DJB Daily Readings'!K13 -> 323 | J6: ='DJB Daily Readings'!K14-'DJB Daily Readings'!K13 -> 323 | K6: ='DJB Daily Readings'!O14-'DJB Daily Readings'!O13 -> 128.65 | L6: ='DJB Daily Readings'!R14-'DJB Daily Readings'!R13 -> 0 | M6: ='DJB Daily Readings'!U14-'DJB Daily Readings'!U13 -> 2971.92 | N6: ='DJB Daily Readings'!X14-'DJB Daily Readings'!X13 -> 4774.56 | O6: ='DJB Daily Readings'!AA14-'DJB Daily Readings'!AA13 -> 974.4 | P6: ='DJB Daily Readings'!AD14-'DJB Daily Readings'!AD13 -> 535.92 | Q6: ='DJB Daily Readings'!AG14-'DJB Daily Readings'!AG13 -> 12618.48 | R6: ='DJB Daily Readings'!AJ14-'DJB Daily Readings'!AJ13 -> 5700.24 | S6: ='DJB Daily Readings'!AM14-'DJB Daily Readings'!AM13 -> 4336.08 | T6: ='DJB Daily Readings'!AP14-'DJB Daily Readings'!AP13 -> 4336.08 | U6: ='DJB Daily Readings'!AS14-'DJB Daily Readings'!AS13 -> 2728.32 | V6: ='DJB Daily Readings'!AV14-'DJB Daily Readings'!AV13 -> 5456.64 | W6: ='DJB Daily Readings'!AZ14-'DJB Daily Readings'!AZ13 -> 0 | X6: ='DJB Daily Readings'!BC14-'DJB Daily Readings'!BC13 -> 0 | Y6: ='DJB Daily Readings'!BF14-'DJB Daily Readings'!BF13 -> 67200 | Z6: =('DJB Daily Readings'!CK14-'DJB Daily Readings'!CK13)*1.89 -> 206.01 | AA6: =('DJB Daily Readings'!CN14-'DJB Daily Readings'!CN13)*1.89 -> 192.78 | AB6: =('DJB Daily Readings'!CQ14-'DJB Daily Readings'!CQ13)*1.89 -> 0 | AC6: ='DJB Daily Readings'!CT14-'DJB Daily Readings'!CT13 -> 251 | AD6: =('DJB Daily Readings'!BY14-'DJB Daily Readings'!BY13)*1.89 -> 39.69 | AE6: =('DJB Daily Readings'!CA14-'DJB Daily Readings'!CA13)*1.89 -> 32.13 | AF6: =('DJB Daily Readings'!CC14-'DJB Daily Readings'!CC13)*1.89 -> 11.34 | AG6: =('DJB Daily Readings'!CE14-'DJB Daily Readings'!CE13)*1.89 -> 15.12 | AH6: =('DJB Daily Readings'!CG14-'DJB Daily Readings'!CG13)*1.89 -> 22.68 | AI6: =('DJB Daily Readings'!CI14-'DJB Daily Readings'!CI13)*1.89 -> 51.03 | AJ6: ='DJB Daily Readings'!CY14-'DJB Daily Readings'!CY13 -> 2 | AK6: ='DJB Daily Readings'!CW14-'DJB Daily Readings'!CW13 -> 4 | AL6: ='DJB Daily Readings'!DC14-'DJB Daily Readings'!DC13 -> 13 | AM6: ='DJB Daily Readings'!DA14-'DJB Daily Readings'!DA13 -> 14 | AN6: ='DJB Daily Readings'!DG14-'DJB Daily Readings'!DG13 -> 7 | AO6: ='DJB Daily Readings'!DE14-'DJB Daily Readings'!DE13 -> 8 | AP6: ='DJB Daily Readings'!DK14-'DJB Daily Readings'!DK13 -> 5 | AQ6: ='DJB Daily Readings'!DI14-'DJB Daily Readings'!DI13 -> 8 | AR6: ='DJB Daily Readings'!DO14-'DJB Daily Readings'!DO13 -> 5 | AS6: ='DJB Daily Readings'!DM14-'DJB Daily Readings'!DM13 -> 2 | AT6: ='DJB Daily Readings'!DQ14-'DJB Daily Readings'!DQ13 -> 18 | AU6: ='DJB Daily Readings'!DT14-'DJB Daily Readings'!DT13 -> 8.5 | AW6: ='DJB Daily Readings'!DX14-'DJB Daily Readings'!DX13 -> 6.3 | AX6: ='DJB Daily Readings'!DZ14-'DJB Daily Readings'!DZ13 -> 8.7 | AY6: ='DJB Daily Readings'!EB14-'DJB Daily Readings'!EB13 -> 667 | AZ6: ='DJB Daily Readings'!ED14-'DJB Daily Readings'!ED13 -> 153.1 | BA6: ='DJB Daily Readings'!EG14-'DJB Daily Readings'!EG13 -> 4700 | BB6: ='DJB Daily Readings'!EI14-'DJB Daily Readings'!EI13 -> 240 | BC6: ='DJB Daily Readings'!EQ14-'DJB Daily Readings'!EQ13 -> 4600 | BD6: ='DJB Daily Readings'!EK14-'DJB Daily Readings'!EK13 -> 2200 | BE6: ='DJB Daily Readings'!EM14-'DJB Daily Readings'!EM13 -> 300 | BF6: ='DJB Daily Readings'!EO14-'DJB Daily Readings'!EO13 -> 640 | BG6: =('DJB Daily Readings'!ET14-'DJB Daily Readings'!ET13)*1.89 -> 30.24 | BH6: =('DJB Daily Readings'!EV14-'DJB Daily Readings'!EV13)*1.89 -> 18.9 | BI6: =('DJB Daily Readings'!EZ14-'DJB Daily Readings'!EZ13)*1.89 -> 11.34 | BJ6: =('DJB Daily Readings'!EX14-'DJB Daily Readings'!EX13)*1.89 -> 15.12 | BK6: =('DJB Daily Readings'!FB14-'DJB Daily Readings'!FB13)*1.89 -> 47.25
A7: Dubai at Jumeirah Beach | B7: =B6+1 -> 6 | C7: 4 | D7: 2022 | E7: =237*0.71 -> 168.27 | F7: =283+63 -> 346 | G7: ='DJB Daily Readings'!C15-'DJB Daily Readings'!C14 -> 709 | H7: ='DJB Daily Readings'!F15-'DJB Daily Readings'!F14 -> 354 | I7: ='DJB Daily Readings'!K15-'DJB Daily Readings'!K14 -> 336 | J7: ='DJB Daily Readings'!K15-'DJB Daily Readings'!K14 -> 336 | K7: ='DJB Daily Readings'!O15-'DJB Daily Readings'!O14 -> 126.41 | L7: ='DJB Daily Readings'!R15-'DJB Daily Readings'!R14 -> 0 | M7: ='DJB Daily Readings'!U15-'DJB Daily Readings'!U14 -> 4043.76 | N7: ='DJB Daily Readings'!X15-'DJB Daily Readings'!X14 -> 4969.44 | O7: ='DJB Daily Readings'!AA15-'DJB Daily Readings'!AA14 -> 876.96 | P7: ='DJB Daily Readings'!AD15-'DJB Daily Readings'!AD14 -> 487.2 | Q7: ='DJB Daily Readings'!AG15-'DJB Daily Readings'!AG14 -> 10620.96 | R7: ='DJB Daily Readings'!AJ15-'DJB Daily Readings'!AJ14 -> 5895.12 | S7: ='DJB Daily Readings'!AM15-'DJB Daily Readings'!AM14 -> 4384.8 | T7: ='DJB Daily Readings'!AP15-'DJB Daily Readings'!AP14 -> 4677.12 | U7: ='DJB Daily Readings'!AS15-'DJB Daily Readings'!AS14 -> 2728.32 | V7: ='DJB Daily Readings'!AV15-'DJB Daily Readings'!AV14 -> 5359.2 | W7: ='DJB Daily Readings'!AZ15-'DJB Daily Readings'!AZ14 -> 0 | X7: ='DJB Daily Readings'!BC15-'DJB Daily Readings'!BC14 -> 0 | Y7: ='DJB Daily Readings'!BF15-'DJB Daily Readings'!BF14 -> 63000 | Z7: =('DJB Daily Readings'!CK15-'DJB Daily Readings'!CK14)*1.89 -> 207.9 | AA7: =('DJB Daily Readings'!CN15-'DJB Daily Readings'!CN14)*1.89 -> 185.22 | AB7: =('DJB Daily Readings'!CQ15-'DJB Daily Readings'!CQ14)*1.89 -> 0 | AC7: ='DJB Daily Readings'!CT15-'DJB Daily Readings'!CT14 -> 256 | AD7: =('DJB Daily Readings'!BY15-'DJB Daily Readings'!BY14)*1.89 -> 39.69 | AE7: =('DJB Daily Readings'!CA15-'DJB Daily Readings'!CA14)*1.89 -> 35.91 | AF7: =('DJB Daily Readings'!CC15-'DJB Daily Readings'!CC14)*1.89 -> 11.34 | AG7: =('DJB Daily Readings'!CE15-'DJB Daily Readings'!CE14)*1.89 -> 13.23 | AH7: =('DJB Daily Readings'!CG15-'DJB Daily Readings'!CG14)*1.89 -> 18.9 | AI7: =('DJB Daily Readings'!CI15-'DJB Daily Readings'!CI14)*1.89 -> 49.14 | AJ7: ='DJB Daily Readings'!CY15-'DJB Daily Readings'!CY14 -> 2 | AK7: ='DJB Daily Readings'!CW15-'DJB Daily Readings'!CW14 -> 4 | AL7: ='DJB Daily Readings'!DC15-'DJB Daily Readings'!DC14 -> 11 | AM7: ='DJB Daily Readings'!DA15-'DJB Daily Readings'!DA14 -> 15 | AN7: ='DJB Daily Readings'!DG15-'DJB Daily Readings'!DG14 -> 7 | AO7: ='DJB Daily Readings'!DE15-'DJB Daily Readings'!DE14 -> 9 | AP7: ='DJB Daily Readings'!DK15-'DJB Daily Readings'!DK14 -> 6 | AQ7: ='DJB Daily Readings'!DI15-'DJB Daily Readings'!DI14 -> 9 | AR7: ='DJB Daily Readings'!DO15-'DJB Daily Readings'!DO14 -> 6 | AS7: ='DJB Daily Readings'!DM15-'DJB Daily Readings'!DM14 -> 3 | AT7: ='DJB Daily Readings'!DQ15-'DJB Daily Readings'!DQ14 -> 18 | AU7: ='DJB Daily Readings'!DT15-'DJB Daily Readings'!DT14 -> 8.7 | AW7: ='DJB Daily Readings'!DX15-'DJB Daily Readings'!DX14 -> 6.2 | AX7: ='DJB Daily Readings'!DZ15-'DJB Daily Readings'!DZ14 -> 8.8 | AY7: ='DJB Daily Readings'!EB15-'DJB Daily Readings'!EB14 -> 708 | AZ7: ='DJB Daily Readings'!ED15-'DJB Daily Readings'!ED14 -> 155.8 | BA7: ='DJB Daily Readings'!EG15-'DJB Daily Readings'!EG14 -> 4500 | BB7: ='DJB Daily Readings'!EI15-'DJB Daily Readings'!EI14 -> 240 | BC7: ='DJB Daily Readings'!EQ15-'DJB Daily Readings'!EQ14 -> 4000 | BD7: ='DJB Daily Readings'!EK15-'DJB Daily Readings'!EK14 -> 2100 | BE7: ='DJB Daily Readings'!EM15-'DJB Daily Readings'!EM14 -> 300 | BF7: ='DJB Daily Readings'!EO15-'DJB Daily Readings'!EO14 -> 640 | BG7: =('DJB Daily Readings'!ET15-'DJB Daily Readings'!ET14)*1.89 -> 26.46 | BH7: =('DJB Daily Readings'!EV15-'DJB Daily Readings'!EV14)*1.89 -> 20.79 | BI7: =('DJB Daily Readings'!EZ15-'DJB Daily Readings'!EZ14)*1.89 -> 15.12 | BJ7: =('DJB Daily Readings'!EX15-'DJB Daily Readings'!EX14)*1.89 -> 15.12 | BK7: =('DJB Daily Readings'!FB15-'DJB Daily Readings'!FB14)*1.89 -> 45.36
A8: Dubai at Jumeirah Beach | B8: =B7+1 -> 7 | C8: 4 | D8: 2022 | E8: =237*0.72 -> 170.64 | F8: =273+72 -> 345 | G8: ='DJB Daily Readings'!C16-'DJB Daily Readings'!C15 -> 704 | H8: ='DJB Daily Readings'!F16-'DJB Daily Readings'!F15 -> 351 | I8: ='DJB Daily Readings'!K16-'DJB Daily Readings'!K15 -> 310 | J8: ='DJB Daily Readings'!K16-'DJB Daily Readings'!K15 -> 310 | K8: ='DJB Daily Readings'!O16-'DJB Daily Readings'!O15 -> 126.3 | L8: ='DJB Daily Readings'!R16-'DJB Daily Readings'!R15 -> 0 | M8: ='DJB Daily Readings'!U16-'DJB Daily Readings'!U15 -> 4141.2 | N8: ='DJB Daily Readings'!X16-'DJB Daily Readings'!X15 -> 4677.12 | O8: ='DJB Daily Readings'!AA16-'DJB Daily Readings'!AA15 -> 1023.12 | P8: ='DJB Daily Readings'!AD16-'DJB Daily Readings'!AD15 -> 389.76 | Q8: ='DJB Daily Readings'!AG16-'DJB Daily Readings'!AG15 -> 10133.76 | R8: ='DJB Daily Readings'!AJ16-'DJB Daily Readings'!AJ15 -> 5700.24 | S8: ='DJB Daily Readings'!AM16-'DJB Daily Readings'!AM15 -> 4384.8 | T8: ='DJB Daily Readings'!AP16-'DJB Daily Readings'!AP15 -> 4482.24 | U8: ='DJB Daily Readings'!AS16-'DJB Daily Readings'!AS15 -> 2582.16 | V8: ='DJB Daily Readings'!AV16-'DJB Daily Readings'!AV15 -> 5310.48 | W8: ='DJB Daily Readings'!AZ16-'DJB Daily Readings'!AZ15 -> 0 | X8: ='DJB Daily Readings'!BC16-'DJB Daily Readings'!BC15 -> 0 | Y8: ='DJB Daily Readings'!BF16-'DJB Daily Readings'!BF15 -> 61800 | Z8: =('DJB Daily Readings'!CK16-'DJB Daily Readings'!CK15)*1.89 -> 202.23 | AA8: =('DJB Daily Readings'!CN16-'DJB Daily Readings'!CN15)*1.89 -> 189 | AB8: =('DJB Daily Readings'!CQ16-'DJB Daily Readings'!CQ15)*1.89 -> 0 | AC8: ='DJB Daily Readings'!CT16-'DJB Daily Readings'!CT15 -> 248 | AD8: =('DJB Daily Readings'!BY16-'DJB Daily Readings'!BY15)*1.89 -> 41.58 | AE8: =('DJB Daily Readings'!CA16-'DJB Daily Readings'!CA15)*1.89 -> 35.91 | AF8: =('DJB Daily Readings'!CC16-'DJB Daily Readings'!CC15)*1.89 -> 9.45 | AG8: =('DJB Daily Readings'!CE16-'DJB Daily Readings'!CE15)*1.89 -> 13.23 | AH8: =('DJB Daily Readings'!CG16-'DJB Daily Readings'!CG15)*1.89 -> 17.01 | AI8: =('DJB Daily Readings'!CI16-'DJB Daily Readings'!CI15)*1.89 -> 49.14 | AJ8: ='DJB Daily Readings'!CY16-'DJB Daily Readings'!CY15 -> 3 | AK8: ='DJB Daily Readings'!CW16-'DJB Daily Readings'!CW15 -> 4 | AL8: ='DJB Daily Readings'!DC16-'DJB Daily Readings'!DC15 -> 14 | AM8: ='DJB Daily Readings'!DA16-'DJB Daily Readings'!DA15 -> 13 | AN8: ='DJB Daily Readings'!DG16-'DJB Daily Readings'!DG15 -> 6 | AO8: ='DJB Daily Readings'!DE16-'DJB Daily Readings'!DE15 -> 7 | AP8: ='DJB Daily Readings'!DK16-'DJB Daily Readings'!DK15 -> 4 | AQ8: ='DJB Daily Readings'!DI16-'DJB Daily Readings'!DI15 -> 10 | AR8: ='DJB Daily Readings'!DO16-'DJB Daily Readings'!DO15 -> 6 | AS8: ='DJB Daily Readings'!DM16-'DJB Daily Readings'!DM15 -> 3 | AT8: ='DJB Daily Readings'!DQ16-'DJB Daily Readings'!DQ15 -> 18 | AU8: ='DJB Daily Readings'!DT16-'DJB Daily Readings'!DT15 -> 8.6 | AW8: ='DJB Daily Readings'!DX16-'DJB Daily Readings'!DX15 -> 6 | AX8: ='DJB Daily Readings'!DZ16-'DJB Daily Readings'!DZ15 -> 8.5 | AY8: ='DJB Daily Readings'!EB16-'DJB Daily Readings'!EB15 -> 683 | AZ8: ='DJB Daily Readings'!ED16-'DJB Daily Readings'!ED15 -> 151.5 | BA8: ='DJB Daily Readings'!EG16-'DJB Daily Readings'!EG15 -> 4000 | BB8: ='DJB Daily Readings'!EI16-'DJB Daily Readings'!EI15 -> 230 | BC8: ='DJB Daily Readings'!EQ16-'DJB Daily Readings'!EQ15 -> 4700 | BD8: ='DJB Daily Readings'!EK16-'DJB Daily Readings'!EK15 -> 2100 | BE8: ='DJB Daily Readings'!EM16-'DJB Daily Readings'!EM15 -> 300 | BF8: ='DJB Daily Readings'!EO16-'DJB Daily Readings'!EO15 -> 620 | BG8: =('DJB Daily Readings'!ET16-'DJB Daily Readings'!ET15)*1.89 -> 26.46 | BH8: =('DJB Daily Readings'!EV16-'DJB Daily Readings'!EV15)*1.89 -> 18.9 | BI8: =('DJB Daily Readings'!EZ16-'DJB Daily Readings'!EZ15)*1.89 -> 17.01 | BJ8: =('DJB Daily Readings'!EX16-'DJB Daily Readings'!EX15)*1.89 -> 17.01 | BK8: =('DJB Daily Readings'!FB16-'DJB Daily Readings'!FB15)*1.89 -> 47.25
A9: Dubai at Jumeirah Beach | B9: =B8+1 -> 8 | C9: 4 | D9: 2022 | E9: =237*0.75 -> 177.75 | F9: =280+87 -> 367 | G9: ='DJB Daily Readings'!C17-'DJB Daily Readings'!C16 -> 790 | H9: ='DJB Daily Readings'!F17-'DJB Daily Readings'!F16 -> 416 | I9: ='DJB Daily Readings'!K17-'DJB Daily Readings'!K16 -> 338 | J9: ='DJB Daily Readings'!K17-'DJB Daily Readings'!K16 -> 338 | K9: ='DJB Daily Readings'!O17-'DJB Daily Readings'!O16 -> 134.12 | L9: ='DJB Daily Readings'!R17-'DJB Daily Readings'!R16 -> 0 | M9: ='DJB Daily Readings'!U17-'DJB Daily Readings'!U16 -> 4287.36 | N9: ='DJB Daily Readings'!X17-'DJB Daily Readings'!X16 -> 4920.72 | O9: ='DJB Daily Readings'!AA17-'DJB Daily Readings'!AA16 -> 925.68 | P9: ='DJB Daily Readings'!AD17-'DJB Daily Readings'!AD16 -> 389.76 | Q9: ='DJB Daily Readings'!AG17-'DJB Daily Readings'!AG16 -> 11595.36 | R9: ='DJB Daily Readings'!AJ17-'DJB Daily Readings'!AJ16 -> 5992.56 | S9: ='DJB Daily Readings'!AM17-'DJB Daily Readings'!AM16 -> 4482.24 | T9: ='DJB Daily Readings'!AP17-'DJB Daily Readings'!AP16 -> 4677.12 | U9: ='DJB Daily Readings'!AS17-'DJB Daily Readings'!AS16 -> 2874.48 | V9: ='DJB Daily Readings'!AV17-'DJB Daily Readings'!AV16 -> 5456.64 | W9: ='DJB Daily Readings'!AZ17-'DJB Daily Readings'!AZ16 -> 0 | X9: ='DJB Daily Readings'!BC17-'DJB Daily Readings'!BC16 -> 0 | Y9: ='DJB Daily Readings'!BF17-'DJB Daily Readings'!BF16 -> 62900 | Z9: =('DJB Daily Readings'!CK17-'DJB Daily Readings'!CK16)*1.89 -> 204.12 | AA9: =('DJB Daily Readings'!CN17-'DJB Daily Readings'!CN16)*1.89 -> 202.23 | AB9: =('DJB Daily Readings'!CQ17-'DJB Daily Readings'!CQ16)*1.89 -> 0 | AC9: ='DJB Daily Readings'!CT17-'DJB Daily Readings'!CT16 -> 249 | AD9: =('DJB Daily Readings'!BY17-'DJB Daily Readings'!BY16)*1.89 -> 43.47 | AE9: =('DJB Daily Readings'!CA17-'DJB Daily Readings'!CA16)*1.89 -> 39.69 | AF9: =('DJB Daily Readings'!CC17-'DJB Daily Readings'!CC16)*1.89 -> 7.56 | AG9: =('DJB Daily Readings'!CE17-'DJB Daily Readings'!CE16)*1.89 -> 13.23 | AH9: =('DJB Daily Readings'!CG17-'DJB Daily Readings'!CG16)*1.89 -> 24.57 | AI9: =('DJB Daily Readings'!CI17-'DJB Daily Readings'!CI16)*1.89 -> 51.03 | AJ9: ='DJB Daily Readings'!CY17-'DJB Daily Readings'!CY16 -> 8 | AK9: ='DJB Daily Readings'!CW17-'DJB Daily Readings'!CW16 -> 6 | AL9: ='DJB Daily Readings'!DC17-'DJB Daily Readings'!DC16 -> 15 | AM9: ='DJB Daily Readings'!DA17-'DJB Daily Readings'!DA16 -> 15 | AN9: ='DJB Daily Readings'!DG17-'DJB Daily Readings'!DG16 -> 10 | AO9: ='DJB Daily Readings'!DE17-'DJB Daily Readings'!DE16 -> 10 | AP9: ='DJB Daily Readings'!DK17-'DJB Daily Readings'!DK16 -> 0 | AQ9: ='DJB Daily Readings'!DI17-'DJB Daily Readings'!DI16 -> 13 | AR9: ='DJB Daily Readings'!DO17-'DJB Daily Readings'!DO16 -> 4 | AS9: ='DJB Daily Readings'!DM17-'DJB Daily Readings'!DM16 -> 4 | AT9: ='DJB Daily Readings'!DQ17-'DJB Daily Readings'!DQ16 -> 18 | AU9: ='DJB Daily Readings'!DT17-'DJB Daily Readings'!DT16 -> 9 | AW9: ='DJB Daily Readings'!DX17-'DJB Daily Readings'!DX16 -> 6.1 | AX9: ='DJB Daily Readings'!DZ17-'DJB Daily Readings'!DZ16 -> 8.6 | AY9: ='DJB Daily Readings'!EB17-'DJB Daily Readings'!EB16 -> 720 | AZ9: ='DJB Daily Readings'!ED17-'DJB Daily Readings'!ED16 -> 155.7 | BA9: ='DJB Daily Readings'!EG17-'DJB Daily Readings'!EG16 -> 4000 | BB9: ='DJB Daily Readings'!EI17-'DJB Daily Readings'!EI16 -> 230 | BC9: ='DJB Daily Readings'!EQ17-'DJB Daily Readings'!EQ16 -> 4600 | BD9: ='DJB Daily Readings'!EK17-'DJB Daily Readings'!EK16 -> 2000 | BE9: ='DJB Daily Readings'!EM17-'DJB Daily Readings'!EM16 -> 200 | BF9: ='DJB Daily Readings'!EO17-'DJB Daily Readings'!EO16 -> 630 | BG9: =('DJB Daily Readings'!ET17-'DJB Daily Readings'!ET16)*1.89 -> 26.46 | BH9: =('DJB Daily Readings'!EV17-'DJB Daily Readings'!EV16)*1.89 -> 20.79 | BI9: =('DJB Daily Readings'!EZ17-'DJB Daily Readings'!EZ16)*1.89 -> 17.01 | BJ9: =('DJB Daily Readings'!EX17-'DJB Daily Readings'!EX16)*1.89 -> 17.01 | BK9: =('DJB Daily Readings'!FB17-'DJB Daily Readings'!FB16)*1.89 -> 49.14
A10: Dubai at Jumeirah Beach | B10: =B9+1 -> 9 | C10: 4 | D10: 2022 | E10: =237*0.8 -> 189.6 | F10: =315+90 -> 405 | G10: ='DJB Daily Readings'!C18-'DJB Daily Readings'!C17 -> 734 | H10: ='DJB Daily Readings'!F18-'DJB Daily Readings'!F17 -> 394 | I10: ='DJB Daily Readings'!K18-'DJB Daily Readings'!K17 -> 313 | J10: ='DJB Daily Readings'!K18-'DJB Daily Readings'!K17 -> 313 | K10: ='DJB Daily Readings'!O18-'DJB Daily Readings'!O17 -> 128.36 | M10: ='DJB Daily Readings'!U18-'DJB Daily Readings'!U17 -> 2143.68 | N10: ='DJB Daily Readings'!X18-'DJB Daily Readings'!X17 -> 4920.72 | O10: ='DJB Daily Readings'!AA18-'DJB Daily Readings'!AA17 -> 97.44 | P10: ='DJB Daily Readings'!AD18-'DJB Daily Readings'!AD17 -> 12764.64 | Q10: ='DJB Daily Readings'!AG18-'DJB Daily Readings'!AG17 -> 341.04 | R10: ='DJB Daily Readings'!AJ18-'DJB Daily Readings'!AJ17 -> 5748.96 | S10: ='DJB Daily Readings'!AM18-'DJB Daily Readings'!AM17 -> 4336.08 | T10: ='DJB Daily Readings'!AP18-'DJB Daily Readings'!AP17 -> 4725.84 | U10: ='DJB Daily Readings'!AS18-'DJB Daily Readings'!AS17 -> 2533.44 | V10: ='DJB Daily Readings'!AV18-'DJB Daily Readings'!AV17 -> 5748.96 | W10: ='DJB Daily Readings'!AZ18-'DJB Daily Readings'!AZ17 -> 0 | X10: ='DJB Daily Readings'!BC18-'DJB Daily Readings'!BC17 -> 63600 | Y10: ='DJB Daily Readings'!BF18-'DJB Daily Readings'!BF17 -> 2400 | Z10: =('DJB Daily Readings'!CK18-'DJB Daily Readings'!CK17)*1.89 -> 200.34 | AA10: =('DJB Daily Readings'!CN18-'DJB Daily Readings'!CN17)*1.89 -> 198.45 | AB10: =('DJB Daily Readings'!CQ18-'DJB Daily Readings'!CQ17)*1.89 -> 120.96 | AC10: ='DJB Daily Readings'!CT18-'DJB Daily Readings'!CT17 -> 243 | AD10: =('DJB Daily Readings'!BY18-'DJB Daily Readings'!BY17)*1.89 -> 41.58 | AE10: =('DJB Daily Readings'!CA18-'DJB Daily Readings'!CA17)*1.89 -> 37.8 | AF10: =('DJB Daily Readings'!CC18-'DJB Daily Readings'!CC17)*1.89 -> 7.56 | AG10: =('DJB Daily Readings'!CE18-'DJB Daily Readings'!CE17)*1.89 -> 15.12 | AH10: =('DJB Daily Readings'!CG18-'DJB Daily Readings'!CG17)*1.89 -> 20.79 | AI10: =('DJB Daily Readings'!CI18-'DJB Daily Readings'!CI17)*1.89 -> 51.03 | AJ10: ='DJB Daily Readings'!CY18-'DJB Daily Readings'!CY17 -> 3 | AK10: ='DJB Daily Readings'!CW18-'DJB Daily Readings'!CW17 -> 6 | AL10: ='DJB Daily Readings'!DC18-'DJB Daily Readings'!DC17 -> 12 | AM10: ='DJB Daily Readings'!DA18-'DJB Daily Readings'!DA17 -> 15 | AN10: ='DJB Daily Readings'!DG18-'DJB Daily Readings'!DG17 -> 10 | AO10: ='DJB Daily Readings'!DE18-'DJB Daily Readings'!DE17 -> 10 | AP10: ='DJB Daily Readings'!DK18-'DJB Daily Readings'!DK17 -> 4 | AQ10: ='DJB Daily Readings'!DI18-'DJB Daily Readings'!DI17 -> 12 | AR10: ='DJB Daily Readings'!DO18-'DJB Daily Readings'!DO17 -> 4 | AS10: ='DJB Daily Readings'!DM18-'DJB Daily Readings'!DM17 -> 8 | AT10: ='DJB Daily Readings'!DQ18-'DJB Daily Readings'!DQ17 -> 19 | AU10: ='DJB Daily Readings'!DT18-'DJB Daily Readings'!DT17 -> 9.4 | AW10: ='DJB Daily Readings'!DX18-'DJB Daily Readings'!DX17 -> 6.5 | AX10: ='DJB Daily Readings'!DZ18-'DJB Daily Readings'!DZ17 -> 9.8 | AY10: ='DJB Daily Readings'!EB18-'DJB Daily Readings'!EB17 -> 779 | AZ10: ='DJB Daily Readings'!ED18-'DJB Daily Readings'!ED17 -> 158.2 | BA10: ='DJB Daily Readings'!EG18-'DJB Daily Readings'!EG17 -> 4000 | BB10: ='DJB Daily Readings'!EI18-'DJB Daily Readings'!EI17 -> 230 | BC10: ='DJB Daily Readings'!EQ18-'DJB Daily Readings'!EQ17 -> 4700 | BD10: ='DJB Daily Readings'!EK18-'DJB Daily Readings'!EK17 -> 2100 | BE10: ='DJB Daily Readings'!EM18-'DJB Daily Readings'!EM17 -> 800 | BF10: ='DJB Daily Readings'!EO18-'DJB Daily Readings'!EO17 -> 630 | BG10: =('DJB Daily Readings'!ET18-'DJB Daily Readings'!ET17)*1.89 -> 32.13 | BH10: =('DJB Daily Readings'!EV18-'DJB Daily Readings'!EV17)*1.89 -> 20.79 | BI10: =('DJB Daily Readings'!EZ18-'DJB Daily Readings'!EZ17)*1.89 -> 17.01 | BJ10: =('DJB Daily Readings'!EX18-'DJB Daily Readings'!EX17)*1.89 -> 24.57 | BK10: =('DJB Daily Readings'!FB18-'DJB Daily Readings'!FB17)*1.89 -> 47.25
A11: Dubai at Jumeirah Beach | B11: =B10+1 -> 10 | C11: 4 | D11: 2022 | E11: =237*0.87 -> 206.19 | F11: =340+106 -> 446 | G11: ='DJB Daily Readings'!C19-'DJB Daily Readings'!C18 -> 712 | H11: ='DJB Daily Readings'!F19-'DJB Daily Readings'!F18 -> 398 | I11: ='DJB Daily Readings'!K19-'DJB Daily Readings'!K18 -> 320 | J11: ='DJB Daily Readings'!K19-'DJB Daily Readings'!K18 -> 320 | K11: ='DJB Daily Readings'!O19-'DJB Daily Readings'!O18 -> 127.67 | L11: ='DJB Daily Readings'!R19-'DJB Daily Readings'!R18 -> 22 | M11: ='DJB Daily Readings'!U19-'DJB Daily Readings'!U18 -> 2192.4 | N11: ='DJB Daily Readings'!X19-'DJB Daily Readings'!X18 -> 4969.44 | O11: ='DJB Daily Readings'!AA19-'DJB Daily Readings'!AA18 -> 97.44 | P11: ='DJB Daily Readings'!AD19-'DJB Daily Readings'!AD18 -> 12131.28 | Q11: ='DJB Daily Readings'!AG19-'DJB Daily Readings'!AG18 -> 1120.56 | R11: ='DJB Daily Readings'!AJ19-'DJB Daily Readings'!AJ18 -> 5992.56 | S11: ='DJB Daily Readings'!AM19-'DJB Daily Readings'!AM18 -> 4823.28 | T11: ='DJB Daily Readings'!AP19-'DJB Daily Readings'!AP18 -> 4725.84 | U11: ='DJB Daily Readings'!AS19-'DJB Daily Readings'!AS18 -> 2777.04 | V11: ='DJB Daily Readings'!AV19-'DJB Daily Readings'!AV18 -> 5602.8 | W11: ='DJB Daily Readings'!AZ19-'DJB Daily Readings'!AZ18 -> 0 | X11: ='DJB Daily Readings'!BC19-'DJB Daily Readings'!BC18 -> 63700 | Y11: ='DJB Daily Readings'!BF19-'DJB Daily Readings'!BF18 -> 0 | Z11: =('DJB Daily Readings'!CK19-'DJB Daily Readings'!CK18)*1.89 -> 215.46 | AA11: =('DJB Daily Readings'!CN19-'DJB Daily Readings'!CN18)*1.89 -> 196.56 | AB11: =('DJB Daily Readings'!CQ19-'DJB Daily Readings'!CQ18)*1.89 -> 249.48 | AC11: ='DJB Daily Readings'!CT19-'DJB Daily Readings'!CT18 -> 253 | AD11: =('DJB Daily Readings'!BY19-'DJB Daily Readings'!BY18)*1.89 -> 43.47 | AE11: =('DJB Daily Readings'!CA19-'DJB Daily Readings'!CA18)*1.89 -> 37.8 | AF11: =('DJB Daily Readings'!CC19-'DJB Daily Readings'!CC18)*1.89 -> 9.45 | AG11: =('DJB Daily Readings'!CE19-'DJB Daily Readings'!CE18)*1.89 -> 11.34 | AH11: =('DJB Daily Readings'!CG19-'DJB Daily Readings'!CG18)*1.89 -> 9.45 | AI11: =('DJB Daily Readings'!CI19-'DJB Daily Readings'!CI18)*1.89 -> 51.03 | AJ11: ='DJB Daily Readings'!CY19-'DJB Daily Readings'!CY18 -> 4 | AK11: ='DJB Daily Readings'!CW19-'DJB Daily Readings'!CW18 -> 3 | AL11: ='DJB Daily Readings'!DC19-'DJB Daily Readings'!DC18 -> 12 | AM11: ='DJB Daily Readings'!DA19-'DJB Daily Readings'!DA18 -> 17 | AN11: ='DJB Daily Readings'!DG19-'DJB Daily Readings'!DG18 -> 3 | AO11: ='DJB Daily Readings'!DE19-'DJB Daily Readings'!DE18 -> 7 | AP11: ='DJB Daily Readings'!DK19-'DJB Daily Readings'!DK18 -> 10 | AQ11: ='DJB Daily Readings'!DI19-'DJB Daily Readings'!DI18 -> 16 | AR11: ='DJB Daily Readings'!DO19-'DJB Daily Readings'!DO18 -> 6 | AS11: ='DJB Daily Readings'!DM19-'DJB Daily Readings'!DM18 -> 0 | AT11: ='DJB Daily Readings'!DQ19-'DJB Daily Readings'!DQ18 -> 20 | AU11: ='DJB Daily Readings'!DT19-'DJB Daily Readings'!DT18 -> 8.5 | AW11: ='DJB Daily Readings'!DX19-'DJB Daily Readings'!DX18 -> 6 | AX11: ='DJB Daily Readings'!DZ19-'DJB Daily Readings'!DZ18 -> 9.2 | AY11: ='DJB Daily Readings'!EB19-'DJB Daily Readings'!EB18 -> 678 | AZ11: ='DJB Daily Readings'!ED19-'DJB Daily Readings'!ED18 -> 144.9 | BA11: ='DJB Daily Readings'!EG19-'DJB Daily Readings'!EG18 -> 3800 | BB11: ='DJB Daily Readings'!EI19-'DJB Daily Readings'!EI18 -> 230 | BC11: ='DJB Daily Readings'!EQ19-'DJB Daily Readings'!EQ18 -> 4500 | BD11: ='DJB Daily Readings'!EK19-'DJB Daily Readings'!EK18 -> 2000 | BE11: ='DJB Daily Readings'!EM19-'DJB Daily Readings'!EM18 -> 500 | BF11: ='DJB Daily Readings'!EO19-'DJB Daily Readings'!EO18 -> 630 | BG11: =('DJB Daily Readings'!ET19-'DJB Daily Readings'!ET18)*1.89 -> 24.57 | BH11: =('DJB Daily Readings'!EV19-'DJB Daily Readings'!EV18)*1.89 -> 20.79 | BI11: =('DJB Daily Readings'!EZ19-'DJB Daily Readings'!EZ18)*1.89 -> 17.01 | BJ11: =('DJB Daily Readings'!EX19-'DJB Daily Readings'!EX18)*1.89 -> 24.57 | BK11: =('DJB Daily Readings'!FB19-'DJB Daily Readings'!FB18)*1.89 -> 41.58
A12: Dubai at Jumeirah Beach | B12: =B11+1 -> 11 | C12: 4 | D12: 2022 | E12: =237*0.85 -> 201.45 | F12: =329+88 -> 417 | G12: ='DJB Daily Readings'!C20-'DJB Daily Readings'!C19 -> 741 | H12: ='DJB Daily Readings'!F20-'DJB Daily Readings'!F19 -> 366 | I12: ='DJB Daily Readings'!K20-'DJB Daily Readings'!K19 -> 322 | J12: ='DJB Daily Readings'!K20-'DJB Daily Readings'!K19 -> 322 | K12: ='DJB Daily Readings'!O20-'DJB Daily Readings'!O19 -> 137.93 | L12: ='DJB Daily Readings'!R20-'DJB Daily Readings'!R19 -> 25 | M12: ='DJB Daily Readings'!U20-'DJB Daily Readings'!U19 -> 2094.96 | N12: ='DJB Daily Readings'!X20-'DJB Daily Readings'!X19 -> 4677.12 | O12: ='DJB Daily Readings'!AA20-'DJB Daily Readings'!AA19 -> 97.44 | P12: ='DJB Daily Readings'!AD20-'DJB Daily Readings'!AD19 -> 13739.04 | Q12: ='DJB Daily Readings'!AG20-'DJB Daily Readings'!AG19 -> 1364.16 | R12: ='DJB Daily Readings'!AJ20-'DJB Daily Readings'!AJ19 -> 5554.08 | S12: ='DJB Daily Readings'!AM20-'DJB Daily Readings'!AM19 -> 4189.92 | T12: ='DJB Daily Readings'!AP20-'DJB Daily Readings'!AP19 -> 4482.24 | U12: ='DJB Daily Readings'!AS20-'DJB Daily Readings'!AS19 -> 2630.88 | V12: ='DJB Daily Readings'!AV20-'DJB Daily Readings'!AV19 -> 5407.92 | W12: ='DJB Daily Readings'!AZ20-'DJB Daily Readings'!AZ19 -> 0 | X12: ='DJB Daily Readings'!BC20-'DJB Daily Readings'!BC19 -> 72400 | Y12: ='DJB Daily Readings'!BF20-'DJB Daily Readings'!BF19 -> 0 | Z12: =('DJB Daily Readings'!CK20-'DJB Daily Readings'!CK19)*1.89 -> 200.34 | AA12: =('DJB Daily Readings'!CN20-'DJB Daily Readings'!CN19)*1.89 -> 183.33 | AB12: =('DJB Daily Readings'!CQ20-'DJB Daily Readings'!CQ19)*1.89 -> 175.77 | AC12: ='DJB Daily Readings'!CT20-'DJB Daily Readings'!CT19 -> 244 | AD12: =('DJB Daily Readings'!BY20-'DJB Daily Readings'!BY19)*1.89 -> 41.58 | AE12: =('DJB Daily Readings'!CA20-'DJB Daily Readings'!CA19)*1.89 -> 35.91 | AF12: =('DJB Daily Readings'!CC20-'DJB Daily Readings'!CC19)*1.89 -> 11.34 | AG12: =('DJB Daily Readings'!CE20-'DJB Daily Readings'!CE19)*1.89 -> 13.23 | AH12: =('DJB Daily Readings'!CG20-'DJB Daily Readings'!CG19)*1.89 -> 17.01 | AI12: =('DJB Daily Readings'!CI20-'DJB Daily Readings'!CI19)*1.89 -> 47.25 | AJ12: ='DJB Daily Readings'!CY20-'DJB Daily Readings'!CY19 -> 2 | AK12: ='DJB Daily Readings'!CW20-'DJB Daily Readings'!CW19 -> 3 | AL12: ='DJB Daily Readings'!DC20-'DJB Daily Readings'!DC19 -> 14 | AM12: ='DJB Daily Readings'!DA20-'DJB Daily Readings'!DA19 -> 15 | AN12: ='DJB Daily Readings'!DG20-'DJB Daily Readings'!DG19 -> 8 | AO12: ='DJB Daily Readings'!DE20-'DJB Daily Readings'!DE19 -> 8 | AP12: ='DJB Daily Readings'!DK20-'DJB Daily Readings'!DK19 -> 3 | AQ12: ='DJB Daily Readings'!DI20-'DJB Daily Readings'!DI19 -> 11 | AR12: ='DJB Daily Readings'!DO20-'DJB Daily Readings'!DO19 -> 5 | AS12: ='DJB Daily Readings'!DM20-'DJB Daily Readings'!DM19 -> 4 | AT12: ='DJB Daily Readings'!DQ20-'DJB Daily Readings'!DQ19 -> 19 | AU12: ='DJB Daily Readings'!DT20-'DJB Daily Readings'!DT19 -> 8.4 | AW12: ='DJB Daily Readings'!DX20-'DJB Daily Readings'!DX19 -> 6.8 | AX12: ='DJB Daily Readings'!DZ20-'DJB Daily Readings'!DZ19 -> 7.9 | AY12: ='DJB Daily Readings'!EB20-'DJB Daily Readings'!EB19 -> 683 | AZ12: ='DJB Daily Readings'!ED20-'DJB Daily Readings'!ED19 -> 146.8 | BA12: ='DJB Daily Readings'!EG20-'DJB Daily Readings'!EG19 -> 4400 | BB12: ='DJB Daily Readings'!EI20-'DJB Daily Readings'!EI19 -> 250 | BC12: ='DJB Daily Readings'!EQ20-'DJB Daily Readings'!EQ19 -> 5600 | BD12: ='DJB Daily Readings'!EK20-'DJB Daily Readings'!EK19 -> 2300 | BE12: ='DJB Daily Readings'!EM20-'DJB Daily Readings'!EM19 -> 800 | BF12: ='DJB Daily Readings'!EO20-'DJB Daily Readings'!EO19 -> 630 | BG12: =('DJB Daily Readings'!ET20-'DJB Daily Readings'!ET19)*1.89 -> 26.46 | BH12: =('DJB Daily Readings'!EV20-'DJB Daily Readings'!EV19)*1.89 -> 22.68 | BI12: =('DJB Daily Readings'!EZ20-'DJB Daily Readings'!EZ19)*1.89 -> 17.01 | BJ12: =('DJB Daily Readings'!EX20-'DJB Daily Readings'!EX19)*1.89 -> 15.12 | BK12: =('DJB Daily Readings'!FB20-'DJB Daily Readings'!FB19)*1.89 -> 49.14
A13: Dubai at Jumeirah Beach | B13: =B12+1 -> 12 | C13: 4 | D13: 2022 | E13: =237*0.85 -> 201.45 | F13: =336+88 -> 424 | G13: ='DJB Daily Readings'!C21-'DJB Daily Readings'!C20 -> 822 | H13: ='DJB Daily Readings'!F21-'DJB Daily Readings'!F20 -> 414 | I13: ='DJB Daily Readings'!K21-'DJB Daily Readings'!K20 -> 326 | J13: ='DJB Daily Readings'!K21-'DJB Daily Readings'!K20 -> 326 | K13: ='DJB Daily Readings'!O21-'DJB Daily Readings'!O20 -> 143.72 | L13: ='DJB Daily Readings'!R21-'DJB Daily Readings'!R20 -> 19 | M13: ='DJB Daily Readings'!U21-'DJB Daily Readings'!U20 -> 2436 | N13: ='DJB Daily Readings'!X21-'DJB Daily Readings'!X20 -> 4774.56 | O13: ='DJB Daily Readings'!AA21-'DJB Daily Readings'!AA20 -> 194.88 | P13: ='DJB Daily Readings'!AD21-'DJB Daily Readings'!AD20 -> 10669.68 | Q13: ='DJB Daily Readings'!AG21-'DJB Daily Readings'!AG20 -> 3215.52 | R13: ='DJB Daily Readings'!AJ21-'DJB Daily Readings'!AJ20 -> 5846.4 | S13: ='DJB Daily Readings'!AM21-'DJB Daily Readings'!AM20 -> 4482.24 | T13: ='DJB Daily Readings'!AP21-'DJB Daily Readings'!AP20 -> 4530.96 | U13: ='DJB Daily Readings'!AS21-'DJB Daily Readings'!AS20 -> 2825.76 | V13: ='DJB Daily Readings'!AV21-'DJB Daily Readings'!AV20 -> 5359.2 | W13: ='DJB Daily Readings'!AZ21-'DJB Daily Readings'!AZ20 -> 0 | X13: ='DJB Daily Readings'!BC21-'DJB Daily Readings'!BC20 -> 52800 | Y13: ='DJB Daily Readings'!BF21-'DJB Daily Readings'!BF20 -> 14000 | Z13: =('DJB Daily Readings'!CK21-'DJB Daily Readings'!CK20)*1.89 -> 206.01 | AA13: =('DJB Daily Readings'!CN21-'DJB Daily Readings'!CN20)*1.89 -> 147.42 | AB13: =('DJB Daily Readings'!CQ21-'DJB Daily Readings'!CQ20)*1.89 -> 149.31 | AC13: ='DJB Daily Readings'!CT21-'DJB Daily Readings'!CT20 -> 250 | AD13: =('DJB Daily Readings'!BY21-'DJB Daily Readings'!BY20)*1.89 -> 37.8 | AE13: =('DJB Daily Readings'!CA21-'DJB Daily Readings'!CA20)*1.89 -> 37.8 | AF13: =('DJB Daily Readings'!CC21-'DJB Daily Readings'!CC20)*1.89 -> 11.34 | AG13: =('DJB Daily Readings'!CE21-'DJB Daily Readings'!CE20)*1.89 -> 15.12 | AH13: =('DJB Daily Readings'!CG21-'DJB Daily Readings'!CG20)*1.89 -> 22.68 | AI13: =('DJB Daily Readings'!CI21-'DJB Daily Readings'!CI20)*1.89 -> 52.92 | AJ13: ='DJB Daily Readings'!CY21-'DJB Daily Readings'!CY20 -> 2 | AK13: ='DJB Daily Readings'!CW21-'DJB Daily Readings'!CW20 -> 5 | AL13: ='DJB Daily Readings'!DC21-'DJB Daily Readings'!DC20 -> 14 | AM13: ='DJB Daily Readings'!DA21-'DJB Daily Readings'!DA20 -> 17 | AN13: ='DJB Daily Readings'!DG21-'DJB Daily Readings'!DG20 -> 7 | AO13: ='DJB Daily Readings'!DE21-'DJB Daily Readings'!DE20 -> 10 | AP13: ='DJB Daily Readings'!DK21-'DJB Daily Readings'!DK20 -> 4 | AQ13: ='DJB Daily Readings'!DI21-'DJB Daily Readings'!DI20 -> 10 | AR13: ='DJB Daily Readings'!DO21-'DJB Daily Readings'!DO20 -> 5 | AS13: ='DJB Daily Readings'!DM21-'DJB Daily Readings'!DM20 -> 4 | AT13: ='DJB Daily Readings'!DQ21-'DJB Daily Readings'!DQ20 -> 20 | AU13: ='DJB Daily Readings'!DT21-'DJB Daily Readings'!DT20 -> 8.8 | AW13: ='DJB Daily Readings'!DX21-'DJB Daily Readings'!DX20 -> 6.7 | AX13: ='DJB Daily Readings'!DZ21-'DJB Daily Readings'!DZ20 -> 7.2 | AY13: ='DJB Daily Readings'!EB21-'DJB Daily Readings'!EB20 -> 642 | AZ13: ='DJB Daily Readings'!ED21-'DJB Daily Readings'!ED20 -> 151.8 | BA13: ='DJB Daily Readings'!EG21-'DJB Daily Readings'!EG20 -> 4100 | BB13: ='DJB Daily Readings'!EI21-'DJB Daily Readings'!EI20 -> 240 | BC13: ='DJB Daily Readings'!EQ21-'DJB Daily Readings'!EQ20 -> 5300 | BD13: ='DJB Daily Readings'!EK21-'DJB Daily Readings'!EK20 -> 2200 | BE13: ='DJB Daily Readings'!EM21-'DJB Daily Readings'!EM20 -> 600 | BF13: ='DJB Daily Readings'!EO21-'DJB Daily Readings'!EO20 -> 650 | BG13: =('DJB Daily Readings'!ET21-'DJB Daily Readings'!ET20)*1.89 -> 30.24 | BH13: =('DJB Daily Readings'!EV21-'DJB Daily Readings'!EV20)*1.89 -> 24.57 | BI13: =('DJB Daily Readings'!EZ21-'DJB Daily Readings'!EZ20)*1.89 -> 22.68 | BJ13: =('DJB Daily Readings'!EX21-'DJB Daily Readings'!EX20)*1.89 -> 18.9 | BK13: =('DJB Daily Readings'!FB21-'DJB Daily Readings'!FB20)*1.89 -> 49.14
