Workbook

Sheet TOTAL
A1: Site Name | B1: Day | C1: Month | D1: Year | E1: Total Electricity Kwh | F1: Electricity Tariff ($/Kwh) | G1: Water Utility Supply (m3) m3 | H1: Water Utility Supply (m3) $/m3 | I1: Room Nights | J1: Total Guests | K1: Cooling Degree Day
A2: Doha | B2: 1 | C2: 2 | D2: 2023 | E2: =0.75*INDEX('13 - Electrical Readings'!$H$8:$H$987,1+(2*(ROWS(A$1:A1)-1)))+INDEX('13 - Electrical Readings'!$Q$8:$Q$987,1+(2*(ROWS(A$1:A1)-1))) -> 51826.75 | F2: 0.041 | G2: =0.75*INDEX('9 - Water Readings'!$F$8:$F$985,1+(2*(ROWS(A$1:A1)-1)))+INDEX('9 - Water Readings'!$M$8:$M$985,1+(2*(ROWS(A$1:A1)-1))) -> 587.25 | H2: 1.5571913 | I2: ='Submetering '!AA2 -> 132 | J2: ='Submetering '!AB2 -> 398 | K2: ='Submetering '!AC2 -> 1.2
A3: Doha | B3: =B2+1 -> 2 | C3: 2 | D3: 2023 | E3: =0.75*INDEX('13 - Electrical Readings'!$H$8:$H$987,1+(2*(ROWS(A$1:A2)-1)))+INDEX('13 - Electrical Readings'!$Q$8:$Q$987,1+(2*(ROWS(A$1:A2)-1))) -> 49183.5 | F3: 0.041 | G3: =0.75*INDEX('9 - Water Readings'!$F$8:$F$985,1+(2*(ROWS(A$1:A2)-1)))+INDEX('9 - Water Readings'!$M$8:$M$985,1+(2*(ROWS(A$1:A2)-1))) -> 638 | H3: 1.5571913 | I3: ='Submetering '!AA3 -> 156 | J3: ='Submetering '!AB3 -> 570 | K3: ='Submetering '!AC3 -> 1.3
A4: Doha | B4: =B3+1 -> 3 | C4: 2 | D4: 2023 | E4: =0.75*INDEX('13 - Electrical Readings'!$H$8:$H$987,1+(2*(ROWS(A$1:A3)-1)))+INDEX('13 - Electrical Readings'!$Q$8:$Q$987,1+(2*(ROWS(A$1:A3)-1))) -> 50817 | F4: 0.041 | G4: =0.75*INDEX('9 - Water Readings'!$F$8:$F$985,1+(2*(ROWS(A$1:A3)-1)))+INDEX('9 - Water Readings'!$M$8:$M$985,1+(2*(ROWS(A$1:A3)-1))) -> 618 | H4: 1.5571913 | I4: ='Submetering '!AA4 -> 138 | J4: ='Submetering '!AB4 -> 498 | K4: ='Submetering '!AC4 -> 0.8
A5: Doha | B5: =B4+1 -> 4 | C5: 2 | D5: 2023 | E5: =0.75*INDEX('13 - Electrical Readings'!$H$8:$H$987,1+(2*(ROWS(A$1:A4)-1)))+INDEX('13 - Electrical Readings'!$Q$8:$Q$987,1+(2*(ROWS(A$1:A4)-1))) -> 50496.25 | F5: 0.041 | G5: =0.75*INDEX('9 - Water Readings'!$F$8:$F$985,1+(2*(ROWS(A$1:A4)-1)))+INDEX('9 - Water Readings'!$M$8:$M$985,1+(2*(ROWS(A$1:A4)-1))) -> 608 | H5: 1.5571913 | I5: ='Submetering '!AA5 -> 104 | J5: ='Submetering '!AB5 -> 320 | K5: ='Submetering '!AC5 -> 0.1
A6: Doha | B6: =B5+1 -> 5 | C6: 2 | D6: 2023 | E6: =0.75*INDEX('13 - Electrical Readings'!$H$8:$H$987,1+(2*(ROWS(A$1:A5)-1)))+INDEX('13 - Electrical Readings'!$Q$8:$Q$987,1+(2*(ROWS(A$1:A5)-1))) -> 49944.5 | F6: 0.041 | G6: =0.75*INDEX('9 - Water Readings'!$F$8:$F$985,1+(2*(ROWS(A$1:A5)-1)))+INDEX('9 - Water Readings'!$M$8:$M$985,1+(2*(ROWS(A$1:A5)-1))) -> 545 | H6: 1.5571913 | I6: ='Submetering '!AA6 -> 99 | J6: ='Submetering '!AB6 -> 262 | K6: ='Submetering '!AC6 -> 0.3
A7: Doha | B7: =B6+1 -> 6 | C7: 2 | D7: 2023 | E7: =0.75*INDEX('13 - Electrical Readings'!$H$8:$H$987,1+(2*(ROWS(A$1:A6)-1)))+INDEX('13 - Electrical Readings'!$Q$8:$Q$987,1+(2*(ROWS(A$1:A6)-1))) -> 54081.75 | F7: 0.041 | G7: =0.75*INDEX('9 - Water Readings'!$F$8:$F$985,1+(2*(ROWS(A$1:A6)-1)))+INDEX('9 - Water Readings'!$M$8:$M$985,1+(2*(ROWS(A$1:A6)-1))) -> 578 | H7: 1.5571913 | I7: ='Submetering '!AA7 -> 127 | J7: ='Submetering '!AB7 -> 310 | K7: ='Submetering '!AC7 -> 0.6
A8: Doha | B8: =B7+1 -> 7 | C8: 2 | D8: 2023 | E8: =0.75*INDEX('13 - Electrical Readings'!$H$8:$H$987,1+(2*(ROWS(A$1:A7)-1)))+INDEX('13 - Electrical Readings'!$Q$8:$Q$987,1+(2*(ROWS(A$1:A7)-1))) -> 55491 | F8: 0.041 | G8: =0.75*INDEX('9 - Water Readings'!$F$8:$F$985,1+(2*(ROWS(A$1:A7)-1)))+INDEX('9 - Water Readings'!$M$8:$M$985,1+(2*(ROWS(A$1:A7)-1))) -> 573 | H8: 1.5571913 | I8: ='Submetering '!AA8 -> 116 | J8: ='Submetering '!AB8 -> 294 | K8: ='Submetering '!AC8 -> 3
A9: Doha | B9: =B8+1 -> 8 | C9: 2 | D9: 2023 | E9: =0.75*INDEX('13 - Electrical Readings'!$H$8:$H$987,1+(2*(ROWS(A$1:A8)-1)))+INDEX('13 - Electrical Readings'!$Q$8:$Q$987,1+(2*(ROWS(A$1:A8)-1))) -> 55782.25 | F9: 0.041 | G9: =0.75*INDEX('9 - Water Readings'!$F$8:$F$985,1+(2*(ROWS(A$1:A8)-1)))+INDEX('9 - Water Readings'!$M$8:$M$985,1+(2*(ROWS(A$1:A8)-1))) -> 596.5 | H9: 1.5571913 | I9: ='Submetering '!AA9 -> 113 | J9: ='Submetering '!AB9 -> 350 | K9: ='Submetering '!AC9 -> 0.9
A10: Doha | B10: =B9+1 -> 9 | C10: 2 | D10: 2023 | E10: =0.75*INDEX('13 - Electrical Readings'!$H$8:$H$987,1+(2*(ROWS(A$1:A9)-1)))+INDEX('13 - Electrical Readings'!$Q$8:$Q$987,1+(2*(ROWS(A$1:A9)-1))) -> 50646.5 | F10: 0.041 | G10: =0.75*INDEX('9 - Water Readings'!$F$8:$F$985,1+(2*(ROWS(A$1:A9)-1)))+INDEX('9 - Water Readings'!$M$8:$M$985,1+(2*(ROWS(A$1:A9)-1))) -> 647 | H10: 1.5571913 | I10: ='Submetering '!AA10 -> 122 | J10: ='Submetering '!AB10 -> 448 | K10: ='Submetering '!AC10 -> 0.3
A11: Doha | B11: =B10+1 -> 10 | C11: 2 | D11: 2023 | E11: =0.75*INDEX('13 - Electrical Readings'!$H$8:$H$987,1+(2*(ROWS(A$1:A10)-1)))+INDEX('13 - Electrical Readings'!$Q$8:$Q$987,1+(2*(ROWS(A$1:A10)-1))) -> 50357.75 | F11: 0.041 | G11: =0.75*INDEX('9 - Water Readings'!$F$8:$F$985,1+(2*(ROWS(A$1:A10)-1)))+INDEX('9 - Water Readings'!$M$8:$M$985,1+(2*(ROWS(A$1:A10)-1))) -> 645 | H11: 1.5571913 | I11: ='Submetering '!AA11 -> 127 | J11: ='Submetering '!AB11 -> 522 | K11: ='Submetering '!AC11 -> 0
A12: Doha | B12: =B11+1 -> 11 | C12: 2 | D12: 2023 | E12: =0.75*INDEX('13 - Electrical Readings'!$H$8:$H$987,1+(2*(ROWS(A$1:A11)-1)))+INDEX('13 - Electrical Readings'!$Q$8:$Q$987,1+(2*(ROWS(A$1:A11)-1))) -> 49644.5 | F12: 0.041 | G12: =0.75*INDEX('9 - Water Readings'!$F$8:$F$985,1+(2*(ROWS(A$1:A11)-1)))+INDEX('9 - Water Readings'!$M$8:$M$985,1+(2*(ROWS(A$1:A11)-1))) -> 594 | H12: 1.5571913 | I12: ='Submetering '!AA12 -> 173 | J12: ='Submetering '!AB12 -> 626 | K12: ='Submetering '!AC12 -> 0.3
A13: Doha | B13: =B12+1 -> 12 | C13: 2 | D13: 2023 | E13: =0.75*INDEX('13 - Electrical Readings'!$H$8:$H$987,1+(2*(ROWS(A$1:A12)-1)))+INDEX('13 - Electrical Readings'!$Q$8:$Q$987,1+(2*(ROWS(A$1:A12)-1))) -> 51794 | F13: 0.041 | G13: =0.75*INDEX('9 - Water Readings'!$F$8:$F$985,1+(2*(ROWS(A$1:A12)-1)))+INDEX('9 - Water Readings'!$M$8:$M$985,1+(2*(ROWS(A$1:A12)-1))) -> 627 | H13: 1.5571913 | I13: ='Submetering '!AA13 -> 184 | J13: ='Submetering '!AB13 -> 616 | K13: ='Submetering '!AC13 -> 0.5
A14: Doha | B14: =B13+1 -> 13 | C14: 2 | D14: 2023 | E14: =0.75*INDEX('13 - Electrical Readings'!$H$8:$H$987,1+(2*(ROWS(A$1:A13)-1)))+INDEX('13 - Electrical Readings'!$Q$8:$Q$987,1+(2*(ROWS(A$1:A13)-1))) -> 53028 | F14: 0.041 | G14: =0.75*INDEX('9 - Water Readings'!$F$8:$F$985,1+(2*(ROWS(A$1:A13)-1)))+INDEX('9 - Water Readings'!$M$8:$M$985,1+(2*(ROWS(A$1:A13)-1))) -> 621 | H14: 1.5571913 | I14: ='Submetering '!AA14 -> 139 | J14: ='Submetering '!AB14 -> 474 | K14: ='Submetering '!AC14 -> 2.2
... A29: Doha | B29: =B28+1 -> 28 | C29: 2 | D29: 2023 | E29: =0.75*INDEX('13 - Electrical Readings'!$H$8:$H$987,1+(2*(ROWS(A$1:A28)-1)))+INDEX('13 - Electrical Readings'!$Q$8:$Q$987,1+(2*(ROWS(A$1:A28)-1))) -> 58405.25 | F29: 0.041 | G29: =0.75*INDEX('9 - Water Readings'!$F$8:$F$985,1+(2*(ROWS(A$1:A28)-1)))+INDEX('9 - Water Readings'!$M$8:$M$985,1+(2*(ROWS(A$1:A28)-1))) -> 648 | H29: 1.5571913 | I29: ='Submetering '!AA29 -> 217 | J29: ='Submetering '!AB29 -> 672 | K29: ='Submetering '!AC29 -> 3.5
E30: =SUM(E2:E29) -> 1499234.8 | G30: =SUM(G2:G29) -> 17683.25 | I30: =SUM(I2:I29) -> 4532 | J30: =SUM(J2:J29) -> 14402 | K30: =SUM(K2:K29) -> 39.9

Sheet Submetering 
A1: Site Name | B1: Day | C1: Month | D1: Year | E1: CP Chillers 157691 (KWh) | F1: CP Chillers 157692 (KWh) | G1: CP Chillers 157693 (KWh) | H1: CP Chillers 157694 (KWh) | I1: CP Chillers 167609 (KWh) | J1: Town House 166443 (KWh) | K1: Hotel 157687 (KWh) | L1: Hotel 157688 (KWh) | M1: Hotel 157689 (KWh) | N1: Hotel 157690 (KWh) | O1: SPA (KWh) | P1: Marina (KWh) | Q1: Nobu (KWh) | R1: CP F/F (m3) | S1: CP Chillers (m3) | T1: CP Parking (m3) | U1: Town House (m3) | V1: Spa B (m3) | W1: Spa A (m3) | X1: CW Hotel A (m3) | Y1: CCW Hotel B (m3) | Z1: Marina (m3) | AA1: Room Nights | AB1: Total Guests | AC1: Cooling Degree Day
A2: Doha | B2: 1 | C2: 2 | D2: 2023 | E2: =INDEX('13 - Electrical Readings'!$C$8:$C$953,1+(2*(ROWS(A$1:A1)-1))) -> 2525 | F2: =INDEX('13 - Electrical Readings'!$D$6:$D$953,1+(2*(ROWS(A$1:A2)-1))) -> 637 | G2: =INDEX('13 - Electrical Readings'!$E$6:$E$953,1+(2*(ROWS(A$1:A2)-1))) -> 10391 | H2: =INDEX('13 - Electrical Readings'!$F$6:$F$953,1+(2*(ROWS(A$1:A2)-1))) -> 2308 | I2: =INDEX('13 - Electrical Readings'!$G$6:$G$953,1+(2*(ROWS(A$1:A2)-1))) -> 408 | J2: =INDEX('13 - Electrical Readings'!$I$6:$I$953,1+(2*(ROWS(A$1:A2)-1))) -> 1695 | K2: =INDEX('13 - Electrical Readings'!$J$6:$J$953,1+(2*(ROWS(B$1:B2)-1))) -> 9514 | L2: =INDEX('13 - Electrical Readings'!$K$6:$K$953,1+(2*(ROWS(C$1:C2)-1))) -> 3890 | M2: =INDEX('13 - Electrical Readings'!$L$6:$L$953,1+(2*(ROWS(D$1:D2)-1))) -> 5051 | N2: =INDEX('13 - Electrical Readings'!$M$6:$M$953,1+(2*(ROWS(E$1:E2)-1))) -> 8916 | O2: =INDEX('13 - Electrical Readings'!$N$6:$N$953,1+(2*(ROWS(E$1:E2)-1))) -> 6937 | P2: =INDEX('13 - Electrical Readings'!$O$6:$O$953,1+(2*(ROWS(E$1:E2)-1))) -> 952 | Q2: =INDEX('13 - Electrical Readings'!$P$6:$P$953,1+(2*(ROWS(E$1:E2)-1))) -> 2670 | R2: =INDEX('9 - Water Readings'!$C$8:$C$955,1+(2*(ROWS(A$1:A1)-1))) -> 3 | S2: =INDEX('9 - Water Readings'!$D$8:$D$954,1+(2*(ROWS(A$1:A1)-1))) -> 0 | T2: =INDEX('9 - Water Readings'!$E$8:$E$955,1+(2*(ROWS(A$1:A1)-1))) -> 0 | U2: =INDEX('9 - Water Readings'!$G$8:$G$954,1+(2*(ROWS(A$1:A1)-1))) -> 142 | V2: =INDEX('9 - Water Readings'!$H$8:$H$955,1+(2*(ROWS(A$1:A1)-1))) -> 17 | W2: =INDEX('9 - Water Readings'!$I$8:$I$955,1+(2*(ROWS(A$1:A1)-1))) -> 73 | X2: =INDEX('9 - Water Readings'!$J$8:$J$955,1+(2*(ROWS(A$1:A1)-1))) -> 292 | Y2: =INDEX('9 - Water Readings'!$K$8:$K$955,1+(2*(ROWS(A$1:A1)-1))) -> 34 | Z2: =INDEX('9 - Water Readings'!$L$8:$L$955,1+(2*(ROWS(A$1:A1)-1))) -> 27 | AA2: ='9 - Water Readings'!Q7 -> 132 | AB2: ='9 - Water Readings'!R7 -> 398 | AC2: ='9 - Water Readings'!S7 -> 1.2
A3: Doha | B3: =B2+1 -> 2 | C3: 2 | D3: 2023 | E3: =INDEX('13 - Electrical Readings'!$C$8:$C$953,1+(2*(ROWS(A$1:A2)-1))) -> 0 | F3: =INDEX('13 - Electrical Readings'!$D$6:$D$953,1+(2*(ROWS(A$1:A3)-1))) -> 922 | G3: =INDEX('13 - Electrical Readings'!$E$6:$E$953,1+(2*(ROWS(A$1:A3)-1))) -> 5287 | H3: =INDEX('13 - Electrical Readings'!$F$6:$F$953,1+(2*(ROWS(A$1:A3)-1))) -> 8553 | I3: =INDEX('13 - Electrical Readings'!$G$6:$G$953,1+(2*(ROWS(A$1:A3)-1))) -> 12 | J3: =INDEX('13 - Electrical Readings'!$I$6:$I$953,1+(2*(ROWS(A$1:A3)-1))) -> 1695 | K3: =INDEX('13 - Electrical Readings'!$J$6:$J$953,1+(2*(ROWS(B$1:B3)-1))) -> 9200 | L3: =INDEX('13 - Electrical Readings'!$K$6:$K$953,1+(2*(ROWS(C$1:C3)-1))) -> 3785 | M3: =INDEX('13 - Electrical Readings'!$L$6:$L$953,1+(2*(ROWS(D$1:D3)-1))) -> 4710 | N3: =INDEX('13 - Electrical Readings'!$M$6:$M$953,1+(2*(ROWS(E$1:E3)-1))) -> 7932 | O3: =INDEX('13 - Electrical Readings'!$N$6:$N$953,1+(2*(ROWS(E$1:E3)-1))) -> 7124 | P3: =INDEX('13 - Electrical Readings'!$O$6:$O$953,1+(2*(ROWS(E$1:E3)-1))) -> 987 | Q3: =INDEX('13 - Electrical Readings'!$P$6:$P$953,1+(2*(ROWS(E$1:E3)-1))) -> 2670 | R3: =INDEX('9 - Water Readings'!$C$8:$C$955,1+(2*(ROWS(A$1:A2)-1))) -> 0 | S3: =INDEX('9 - Water Readings'!$D$8:$D$954,1+(2*(ROWS(A$1:A2)-1))) -> 0 | T3: =INDEX('9 - Water Readings'!$E$8:$E$955,1+(2*(ROWS(A$1:A2)-1))) -> 0 | U3: =INDEX('9 - Water Readings'!$G$8:$G$954,1+(2*(ROWS(A$1:A2)-1))) -> 135 | V3: =INDEX('9 - Water Readings'!$H$8:$H$955,1+(2*(ROWS(A$1:A2)-1))) -> 17 | W3: =INDEX('9 - Water Readings'!$I$8:$I$955,1+(2*(ROWS(A$1:A2)-1))) -> 89 | X3: =INDEX('9 - Water Readings'!$J$8:$J$955,1+(2*(ROWS(A$1:A2)-1))) -> 310 | Y3: =INDEX('9 - Water Readings'!$K$8:$K$955,1+(2*(ROWS(A$1:A2)-1))) -> 56 | Z3: =INDEX('9 - Water Readings'!$L$8:$L$955,1+(2*(ROWS(A$1:A2)-1))) -> 31 | AA3: ='9 - Water Readings'!Q8 -> 156 | AB3: ='9 - Water Readings'!R8 -> 570 | AC3: ='9 - Water Readings'!S8 -> 1.3
A4: Doha | B4: =B3+1 -> 3 | C4: 2 | D4: 2023 | E4: =INDEX('13 - Electrical Readings'!$C$8:$C$953,1+(2*(ROWS(A$1:A3)-1))) -> 0 | F4: =INDEX('13 - Electrical Readings'!$D$6:$D$953,1+(2*(ROWS(A$1:A4)-1))) -> 907 | G4: =INDEX('13 - Electrical Readings'!$E$6:$E$953,1+(2*(ROWS(A$1:A4)-1))) -> 2065 | H4: =INDEX('13 - Electrical Readings'!$F$6:$F$953,1+(2*(ROWS(A$1:A4)-1))) -> 11150 | I4: =INDEX('13 - Electrical Readings'!$G$6:$G$953,1+(2*(ROWS(A$1:A4)-1))) -> 14 | J4: =INDEX('13 - Electrical Readings'!$I$6:$I$953,1+(2*(ROWS(A$1:A4)-1))) -> 1726 | K4: =INDEX('13 - Electrical Readings'!$J$6:$J$953,1+(2*(ROWS(B$1:B4)-1))) -> 9602 | L4: =INDEX('13 - Electrical Readings'!$K$6:$K$953,1+(2*(ROWS(C$1:C4)-1))) -> 3886 | M4: =INDEX('13 - Electrical Readings'!$L$6:$L$953,1+(2*(ROWS(D$1:D4)-1))) -> 4808 | N4: =INDEX('13 - Electrical Readings'!$M$6:$M$953,1+(2*(ROWS(E$1:E4)-1))) -> 9219 | O4: =INDEX('13 - Electrical Readings'!$N$6:$N$953,1+(2*(ROWS(E$1:E4)-1))) -> 7024 | P4: =INDEX('13 - Electrical Readings'!$O$6:$O$953,1+(2*(ROWS(E$1:E4)-1))) -> 1070 | Q4: =INDEX('13 - Electrical Readings'!$P$6:$P$953,1+(2*(ROWS(E$1:E4)-1))) -> 2880 | R4: =INDEX('9 - Water Readings'!$C$8:$C$955,1+(2*(ROWS(A$1:A3)-1))) -> 0 | S4: =INDEX('9 - Water Readings'!$D$8:$D$954,1+(2*(ROWS(A$1:A3)-1))) -> 0 | T4: =INDEX('9 - Water Readings'!$E$8:$E$955,1+(2*(ROWS(A$1:A3)-1))) -> 0 | U4: =INDEX('9 - Water Readings'!$G$8:$G$954,1+(2*(ROWS(A$1:A3)-1))) -> 133 | V4: =INDEX('9 - Water Readings'!$H$8:$H$955,1+(2*(ROWS(A$1:A3)-1))) -> 17 | W4: =INDEX('9 - Water Readings'!$I$8:$I$955,1+(2*(ROWS(A$1:A3)-1))) -> 78 | X4: =INDEX('9 - Water Readings'!$J$8:$J$955,1+(2*(ROWS(A$1:A3)-1))) -> 317 | Y4: =INDEX('9 - Water Readings'!$K$8:$K$955,1+(2*(ROWS(A$1:A3)-1))) -> 49 | Z4: =INDEX('9 - Water Readings'!$L$8:$L$955,1+(2*(ROWS(A$1:A3)-1))) -> 24 | AA4: ='9 - Water Readings'!Q9 -> 138 | AB4: ='9 - Water Readings'!R9 -> 498 | AC4: ='9 - Water Readings'!S9 -> 0.8
A5: Doha | B5: =B4+1 -> 4 | C5: 2 | D5: 2023 | E5: =INDEX('13 - Electrical Readings'!$C$8:$C$953,1+(2*(ROWS(A$1:A4)-1))) -> 1762 | F5: =INDEX('13 - Electrical Readings'!$D$6:$D$953,1+(2*(ROWS(A$1:A5)-1))) -> 851 | G5: =INDEX('13 - Electrical Readings'!$E$6:$E$953,1+(2*(ROWS(A$1:A5)-1))) -> 2138 | H5: =INDEX('13 - Electrical Readings'!$F$6:$F$953,1+(2*(ROWS(A$1:A5)-1))) -> 3817 | I5: =INDEX('13 - Electrical Readings'!$G$6:$G$953,1+(2*(ROWS(A$1:A5)-1))) -> 7755 | J5: =INDEX('13 - Electrical Readings'!$I$6:$I$953,1+(2*(ROWS(A$1:A5)-1))) -> 1711 | K5: =INDEX('13 - Electrical Readings'!$J$6:$J$953,1+(2*(ROWS(B$1:B5)-1))) -> 8779 | L5: =INDEX('13 - Electrical Readings'!$K$6:$K$953,1+(2*(ROWS(C$1:C5)-1))) -> 3482 | M5: =INDEX('13 - Electrical Readings'!$L$6:$L$953,1+(2*(ROWS(D$1:D5)-1))) -> 4748 | N5: =INDEX('13 - Electrical Readings'!$M$6:$M$953,1+(2*(ROWS(E$1:E5)-1))) -> 8980 | O5: =INDEX('13 - Electrical Readings'!$N$6:$N$953,1+(2*(ROWS(E$1:E5)-1))) -> 6893 | P5: =INDEX('13 - Electrical Readings'!$O$6:$O$953,1+(2*(ROWS(E$1:E5)-1))) -> 901 | Q5: =INDEX('13 - Electrical Readings'!$P$6:$P$953,1+(2*(ROWS(E$1:E5)-1))) -> 2760 | R5: =INDEX('9 - Water Readings'!$C$8:$C$955,1+(2*(ROWS(A$1:A4)-1))) -> 0 | S5: =INDEX('9 - Water Readings'!$D$8:$D$954,1+(2*(ROWS(A$1:A4)-1))) -> 0 | T5: =INDEX('9 - Water Readings'!$E$8:$E$955,1+(2*(ROWS(A$1:A4)-1))) -> 0 | U5: =INDEX('9 - Water Readings'!$G$8:$G$954,1+(2*(ROWS(A$1:A4)-1))) -> 137 | V5: =INDEX('9 - Water Readings'!$H$8:$H$955,1+(2*(ROWS(A$1:A4)-1))) -> 17 | W5: =INDEX('9 - Water Readings'!$I$8:$I$955,1+(2*(ROWS(A$1:A4)-1))) -> 81 | X5: =INDEX('9 - Water Readings'!$J$8:$J$955,1+(2*(ROWS(A$1:A4)-1))) -> 298 | Y5: =INDEX('9 - Water Readings'!$K$8:$K$955,1+(2*(ROWS(A$1:A4)-1))) -> 46 | Z5: =INDEX('9 - Water Readings'!$L$8:$L$955,1+(2*(ROWS(A$1:A4)-1))) -> 29 | AA5: ='9 - Water Readings'!Q10 -> 104 | AB5: ='9 - Water Readings'!R10 -> 320 | AC5: ='9 - Water Readings'!S10 -> 0.1
A6: Doha | B6: =B5+1 -> 5 | C6: 2 | D6: 2023 | E6: =INDEX('13 - Electrical Readings'!$C$8:$C$953,1+(2*(ROWS(A$1:A5)-1))) -> 5339 | F6: =INDEX('13 - Electrical Readings'!$D$6:$D$953,1+(2*(ROWS(A$1:A6)-1))) -> 822 | G6: =INDEX('13 - Electrical Readings'!$E$6:$E$953,1+(2*(ROWS(A$1:A6)-1))) -> 2235 | H6: =INDEX('13 - Electrical Readings'!$F$6:$F$953,1+(2*(ROWS(A$1:A6)-1))) -> 1840 | I6: =INDEX('13 - Electrical Readings'!$G$6:$G$953,1+(2*(ROWS(A$1:A6)-1))) -> 7362 | J6: =INDEX('13 - Electrical Readings'!$I$6:$I$953,1+(2*(ROWS(A$1:A6)-1))) -> 1617 | K6: =INDEX('13 - Electrical Readings'!$J$6:$J$953,1+(2*(ROWS(B$1:B6)-1))) -> 8937 | L6: =INDEX('13 - Electrical Readings'!$K$6:$K$953,1+(2*(ROWS(C$1:C6)-1))) -> 3447 | M6: =INDEX('13 - Electrical Readings'!$L$6:$L$953,1+(2*(ROWS(D$1:D6)-1))) -> 4663 | N6: =INDEX('13 - Electrical Readings'!$M$6:$M$953,1+(2*(ROWS(E$1:E6)-1))) -> 8578 | O6: =INDEX('13 - Electrical Readings'!$N$6:$N$953,1+(2*(ROWS(E$1:E6)-1))) -> 6638 | P6: =INDEX('13 - Electrical Readings'!$O$6:$O$953,1+(2*(ROWS(E$1:E6)-1))) -> 886 | Q6: =INDEX('13 - Electrical Readings'!$P$6:$P$953,1+(2*(ROWS(E$1:E6)-1))) -> 1980 | R6: =INDEX('9 - Water Readings'!$C$8:$C$955,1+(2*(ROWS(A$1:A5)-1))) -> 0 | S6: =INDEX('9 - Water Readings'!$D$8:$D$954,1+(2*(ROWS(A$1:A5)-1))) -> 0 | T6: =INDEX('9 - Water Readings'!$E$8:$E$955,1+(2*(ROWS(A$1:A5)-1))) -> 0 | U6: =INDEX('9 - Water Readings'!$G$8:$G$954,1+(2*(ROWS(A$1:A5)-1))) -> 136 | V6: =INDEX('9 - Water Readings'!$H$8:$H$955,1+(2*(ROWS(A$1:A5)-1))) -> 15 | W6: =INDEX('9 - Water Readings'!$I$8:$I$955,1+(2*(ROWS(A$1:A5)-1))) -> 66 | X6: =INDEX('9 - Water Readings'!$J$8:$J$955,1+(2*(ROWS(A$1:A5)-1))) -> 272 | Y6: =INDEX('9 - Water Readings'!$K$8:$K$955,1+(2*(ROWS(A$1:A5)-1))) -> 38 | Z6: =INDEX('9 - Water Readings'!$L$8:$L$955,1+(2*(ROWS(A$1:A5)-1))) -> 18 | AA6: ='9 - Water Readings'!Q11 -> 99 | AB6: ='9 - Water Readings'!R11 -> 262 | AC6: ='9 - Water Readings'!S11 -> 0.3
A7: Doha | B7: =B6+1 -> 6 | C7: 2 | D7: 2023 | E7: =INDEX('13 - Electrical Readings'!$C$8:$C$953,1+(2*(ROWS(A$1:A6)-1))) -> 14715 | F7: =INDEX('13 - Electrical Readings'!$D$6:$D$953,1+(2*(ROWS(A$1:A7)-1))) -> 874 | G7: =INDEX('13 - Electrical Readings'!$E$6:$E$953,1+(2*(ROWS(A$1:A7)-1))) -> 2369 | H7: =INDEX('13 - Electrical Readings'!$F$6:$F$953,1+(2*(ROWS(A$1:A7)-1))) -> 2266 | I7: =INDEX('13 - Electrical Readings'!$G$6:$G$953,1+(2*(ROWS(A$1:A7)-1))) -> 13 | J7: =INDEX('13 - Electrical Readings'!$I$6:$I$953,1+(2*(ROWS(A$1:A7)-1))) -> 1636 | K7: =INDEX('13 - Electrical Readings'!$J$6:$J$953,1+(2*(ROWS(B$1:B7)-1))) -> 9421 | L7: =INDEX('13 - Electrical Readings'!$K$6:$K$953,1+(2*(ROWS(C$1:C7)-1))) -> 3593 | M7: =INDEX('13 - Electrical Readings'!$L$6:$L$953,1+(2*(ROWS(D$1:D7)-1))) -> 4866 | N7: =INDEX('13 - Electrical Readings'!$M$6:$M$953,1+(2*(ROWS(E$1:E7)-1))) -> 8940 | O7: =INDEX('13 - Electrical Readings'!$N$6:$N$953,1+(2*(ROWS(E$1:E7)-1))) -> 7047 | P7: =INDEX('13 - Electrical Readings'!$O$6:$O$953,1+(2*(ROWS(E$1:E7)-1))) -> 931 | Q7: =INDEX('13 - Electrical Readings'!$P$6:$P$953,1+(2*(ROWS(E$1:E7)-1))) -> 2470 | R7: =INDEX('9 - Water Readings'!$C$8:$C$955,1+(2*(ROWS(A$1:A6)-1))) -> 0 | S7: =INDEX('9 - Water Readings'!$D$8:$D$954,1+(2*(ROWS(A$1:A6)-1))) -> 0 | T7: =INDEX('9 - Water Readings'!$E$8:$E$955,1+(2*(ROWS(A$1:A6)-1))) -> 0 | U7: =INDEX('9 - Water Readings'!$G$8:$G$954,1+(2*(ROWS(A$1:A6)-1))) -> 138 | V7: =INDEX('9 - Water Readings'!$H$8:$H$955,1+(2*(ROWS(A$1:A6)-1))) -> 15 | W7: =INDEX('9 - Water Readings'!$I$8:$I$955,1+(2*(ROWS(A$1:A6)-1))) -> 75 | X7: =INDEX('9 - Water Readings'!$J$8:$J$955,1+(2*(ROWS(A$1:A6)-1))) -> 287 | Y7: =INDEX('9 - Water Readings'!$K$8:$K$955,1+(2*(ROWS(A$1:A6)-1))) -> 37 | Z7: =INDEX('9 - Water Readings'!$L$8:$L$955,1+(2*(ROWS(A$1:A6)-1))) -> 26 | AA7: ='9 - Water Readings'!Q12 -> 127 | AB7: ='9 - Water Readings'!R12 -> 310 | AC7: ='9 - Water Readings'!S12 -> 0.6
A8: Doha | B8: =B7+1 -> 7 | C8: 2 | D8: 2023 | E8: =INDEX('13 - Electrical Readings'!$C$8:$C$953,1+(2*(ROWS(A$1:A7)-1))) -> 15726 | F8: =INDEX('13 - Electrical Readings'!$D$6:$D$953,1+(2*(ROWS(A$1:A8)-1))) -> 816 | G8: =INDEX('13 - Electrical Readings'!$E$6:$E$953,1+(2*(ROWS(A$1:A8)-1))) -> 2304 | H8: =INDEX('13 - Electrical Readings'!$F$6:$F$953,1+(2*(ROWS(A$1:A8)-1))) -> 2460 | I8: =INDEX('13 - Electrical Readings'!$G$6:$G$953,1+(2*(ROWS(A$1:A8)-1))) -> 14 | J8: =INDEX('13 - Electrical Readings'!$I$6:$I$953,1+(2*(ROWS(A$1:A8)-1))) -> 1604 | K8: =INDEX('13 - Electrical Readings'!$J$6:$J$953,1+(2*(ROWS(B$1:B8)-1))) -> 9390 | L8: =INDEX('13 - Electrical Readings'!$K$6:$K$953,1+(2*(ROWS(C$1:C8)-1))) -> 3441 | M8: =INDEX('13 - Electrical Readings'!$L$6:$L$953,1+(2*(ROWS(D$1:D8)-1))) -> 4909 | N8: =INDEX('13 - Electrical Readings'!$M$6:$M$953,1+(2*(ROWS(E$1:E8)-1))) -> 9181 | O8: =INDEX('13 - Electrical Readings'!$N$6:$N$953,1+(2*(ROWS(E$1:E8)-1))) -> 7325 | P8: =INDEX('13 - Electrical Readings'!$O$6:$O$953,1+(2*(ROWS(E$1:E8)-1))) -> 1011 | Q8: =INDEX('13 - Electrical Readings'!$P$6:$P$953,1+(2*(ROWS(E$1:E8)-1))) -> 2640 | R8: =INDEX('9 - Water Readings'!$C$8:$C$955,1+(2*(ROWS(A$1:A7)-1))) -> 0 | S8: =INDEX('9 - Water Readings'!$D$8:$D$954,1+(2*(ROWS(A$1:A7)-1))) -> 8 | T8: =INDEX('9 - Water Readings'!$E$8:$E$955,1+(2*(ROWS(A$1:A7)-1))) -> 0 | U8: =INDEX('9 - Water Readings'!$G$8:$G$954,1+(2*(ROWS(A$1:A7)-1))) -> 136 | V8: =INDEX('9 - Water Readings'!$H$8:$H$955,1+(2*(ROWS(A$1:A7)-1))) -> 15 | W8: =INDEX('9 - Water Readings'!$I$8:$I$955,1+(2*(ROWS(A$1:A7)-1))) -> 80 | X8: =INDEX('9 - Water Readings'!$J$8:$J$955,1+(2*(ROWS(A$1:A7)-1))) -> 273 | Y8: =INDEX('9 - Water Readings'!$K$8:$K$955,1+(2*(ROWS(A$1:A7)-1))) -> 36 | Z8: =INDEX('9 - Water Readings'!$L$8:$L$955,1+(2*(ROWS(A$1:A7)-1))) -> 27 | AA8: ='9 - Water Readings'!Q13 -> 116 | AB8: ='9 - Water Readings'!R13 -> 294 | AC8: ='9 - Water Readings'!S13 -> 3
A9: Doha | B9: =B8+1 -> 8 | C9: 2 | D9: 2023 | E9: =INDEX('13 - Electrical Readings'!$C$8:$C$953,1+(2*(ROWS(A$1:A8)-1))) -> 8882 | F9: =INDEX('13 - Electrical Readings'!$D$6:$D$953,1+(2*(ROWS(A$1:A9)-1))) -> 864 | G9: =INDEX('13 - Electrical Readings'!$E$6:$E$953,1+(2*(ROWS(A$1:A9)-1))) -> 2384 | H9: =INDEX('13 - Electrical Readings'!$F$6:$F$953,1+(2*(ROWS(A$1:A9)-1))) -> 2389 | I9: =INDEX('13 - Electrical Readings'!$G$6:$G$953,1+(2*(ROWS(A$1:A9)-1))) -> 5708 | J9: =INDEX('13 - Electrical Readings'!$I$6:$I$953,1+(2*(ROWS(A$1:A9)-1))) -> 1696 | K9: =INDEX('13 - Electrical Readings'!$J$6:$J$953,1+(2*(ROWS(B$1:B9)-1))) -> 9702 | L9: =INDEX('13 - Electrical Readings'!$K$6:$K$953,1+(2*(ROWS(C$1:C9)-1))) -> 3809 | M9: =INDEX('13 - Electrical Readings'!$L$6:$L$953,1+(2*(ROWS(D$1:D9)-1))) -> 5213 | N9: =INDEX('13 - Electrical Readings'!$M$6:$M$953,1+(2*(ROWS(E$1:E9)-1))) -> 9263 | O9: =INDEX('13 - Electrical Readings'!$N$6:$N$953,1+(2*(ROWS(E$1:E9)-1))) -> 7219 | P9: =INDEX('13 - Electrical Readings'!$O$6:$O$953,1+(2*(ROWS(E$1:E9)-1))) -> 1000 | Q9: =INDEX('13 - Electrical Readings'!$P$6:$P$953,1+(2*(ROWS(E$1:E9)-1))) -> 2710 | R9: =INDEX('9 - Water Readings'!$C$8:$C$955,1+(2*(ROWS(A$1:A8)-1))) -> 0 | S9: =INDEX('9 - Water Readings'!$D$8:$D$954,1+(2*(ROWS(A$1:A8)-1))) -> 2 | T9: =INDEX('9 - Water Readings'!$E$8:$E$955,1+(2*(ROWS(A$1:A8)-1))) -> 0 | U9: =INDEX('9 - Water Readings'!$G$8:$G$954,1+(2*(ROWS(A$1:A8)-1))) -> 136 | V9: =INDEX('9 - Water Readings'!$H$8:$H$955,1+(2*(ROWS(A$1:A8)-1))) -> 15 | W9: =INDEX('9 - Water Readings'!$I$8:$I$955,1+(2*(ROWS(A$1:A8)-1))) -> 81 | X9: =INDEX('9 - Water Readings'!$J$8:$J$955,1+(2*(ROWS(A$1:A8)-1))) -> 298 | Y9: =INDEX('9 - Water Readings'!$K$8:$K$955,1+(2*(ROWS(A$1:A8)-1))) -> 39 | Z9: =INDEX('9 - Water Readings'!$L$8:$L$955,1+(2*(ROWS(A$1:A8)-1))) -> 26 | AA9: ='9 - Water Readings'!Q14 -> 113 | AB9: ='9 - Water Readings'!R14 -> 350 | AC9: ='9 - Water Readings'!S14 -> 0.9
A10: Doha | B10: =B9+1 -> 9 | C10: 2 | D10: 2023 | E10: =INDEX('13 - Electrical Readings'!$C$8:$C$953,1+(2*(ROWS(A$1:A9)-1))) -> 8 | F10: =INDEX('13 - Electrical Readings'!$D$6:$D$953,1+(2*(ROWS(A$1:A10)-1))) -> 860 | G10: =INDEX('13 - Electrical Readings'!$E$6:$E$953,1+(2*(ROWS(A$1:A10)-1))) -> 4368 | H10: =INDEX('13 - Electrical Readings'!$F$6:$F$953,1+(2*(ROWS(A$1:A10)-1))) -> 4847 | I10: =INDEX('13 - Electrical Readings'!$G$6:$G$953,1+(2*(ROWS(A$1:A10)-1))) -> 4663 | J10: =INDEX('13 - Electrical Readings'!$I$6:$I$953,1+(2*(ROWS(A$1:A10)-1))) -> 1703 | K10: =INDEX('13 - Electrical Readings'!$J$6:$J$953,1+(2*(ROWS(B$1:B10)-1))) -> 9519 | L10: =INDEX('13 - Electrical Readings'!$K$6:$K$953,1+(2*(ROWS(C$1:C10)-1))) -> 3757 | M10: =INDEX('13 - Electrical Readings'!$L$6:$L$953,1+(2*(ROWS(D$1:D10)-1))) -> 5290 | N10: =INDEX('13 - Electrical Readings'!$M$6:$M$953,1+(2*(ROWS(E$1:E10)-1))) -> 8629 | O10: =INDEX('13 - Electrical Readings'!$N$6:$N$953,1+(2*(ROWS(E$1:E10)-1))) -> 7021 | P10: =INDEX('13 - Electrical Readings'!$O$6:$O$953,1+(2*(ROWS(E$1:E10)-1))) -> 948 | Q10: =INDEX('13 - Electrical Readings'!$P$6:$P$953,1+(2*(ROWS(E$1:E10)-1))) -> 2720 | R10: =INDEX('9 - Water Readings'!$C$8:$C$955,1+(2*(ROWS(A$1:A9)-1))) -> 0 | S10: =INDEX('9 - Water Readings'!$D$8:$D$954,1+(2*(ROWS(A$1:A9)-1))) -> 0 | T10: =INDEX('9 - Water Readings'!$E$8:$E$955,1+(2*(ROWS(A$1:A9)-1))) -> 0 | U10: =INDEX('9 - Water Readings'!$G$8:$G$954,1+(2*(ROWS(A$1:A9)-1))) -> 142 | V10: =INDEX('9 - Water Readings'!$H$8:$H$955,1+(2*(ROWS(A$1:A9)-1))) -> 18 | W10: =INDEX('9 - Water Readings'!$I$8:$I$955,1+(2*(ROWS(A$1:A9)-1))) -> 87 | X10: =INDEX('9 - Water Readings'!$J$8:$J$955,1+(2*(ROWS(A$1:A9)-1))) -> 329 | Y10: =INDEX('9 - Water Readings'!$K$8:$K$955,1+(2*(ROWS(A$1:A9)-1))) -> 47 | Z10: =INDEX('9 - Water Readings'!$L$8:$L$955,1+(2*(ROWS(A$1:A9)-1))) -> 24 | AA10: ='9 - Water Readings'!Q15 -> 122 | AB10: ='9 - Water Readings'!R15 -> 448 | AC10: ='9 - Water Readings'!S15 -> 0.3
A11: Doha | B11: =B10+1 -> 10 | C11: 2 | D11: 2023 | E11: =INDEX('13 - Electrical Readings'!$C$8:$C$953,1+(2*(ROWS(A$1:A10)-1))) -> 9 | F11: =INDEX('13 - Electrical Readings'!$D$6:$D$953,1+(2*(ROWS(A$1:A11)-1))) -> 843 | G11: =INDEX('13 - Electrical Readings'!$E$6:$E$953,1+(2*(ROWS(A$1:A11)-1))) -> 2317 | H11: =INDEX('13 - Electrical Readings'!$F$6:$F$953,1+(2*(ROWS(A$1:A11)-1))) -> 9666 | I11: =INDEX('13 - Electrical Readings'!$G$6:$G$953,1+(2*(ROWS(A$1:A11)-1))) -> 14 | J11: =INDEX('13 - Electrical Readings'!$I$6:$I$953,1+(2*(ROWS(A$1:A11)-1))) -> 1692 | K11: =INDEX('13 - Electrical Readings'!$J$6:$J$953,1+(2*(ROWS(B$1:B11)-1))) -> 9785 | L11: =INDEX('13 - Electrical Readings'!$K$6:$K$953,1+(2*(ROWS(C$1:C11)-1))) -> 3871 | M11: =INDEX('13 - Electrical Readings'!$L$6:$L$953,1+(2*(ROWS(D$1:D11)-1))) -> 5392 | N11: =INDEX('13 - Electrical Readings'!$M$6:$M$953,1+(2*(ROWS(E$1:E11)-1))) -> 9206 | O11: =INDEX('13 - Electrical Readings'!$N$6:$N$953,1+(2*(ROWS(E$1:E11)-1))) -> 6866 | P11: =INDEX('13 - Electrical Readings'!$O$6:$O$953,1+(2*(ROWS(E$1:E11)-1))) -> 969 | Q11: =INDEX('13 - Electrical Readings'!$P$6:$P$953,1+(2*(ROWS(E$1:E11)-1))) -> 2940 | R11: =INDEX('9 - Water Readings'!$C$8:$C$955,1+(2*(ROWS(A$1:A10)-1))) -> 0 | S11: =INDEX('9 - Water Readings'!$D$8:$D$954,1+(2*(ROWS(A$1:A10)-1))) -> 0 | T11: =INDEX('9 - Water Readings'!$E$8:$E$955,1+(2*(ROWS(A$1:A10)-1))) -> 0 | U11: =INDEX('9 - Water Readings'!$G$8:$G$954,1+(2*(ROWS(A$1:A10)-1))) -> 144 | V11: =INDEX('9 - Water Readings'!$H$8:$H$955,1+(2*(ROWS(A$1:A10)-1))) -> 13 | W11: =INDEX('9 - Water Readings'!$I$8:$I$955,1+(2*(ROWS(A$1:A10)-1))) -> 89 | X11: =INDEX('9 - Water Readings'!$J$8:$J$955,1+(2*(ROWS(A$1:A10)-1))) -> 323 | Y11: =INDEX('9 - Water Readings'!$K$8:$K$955,1+(2*(ROWS(A$1:A10)-1))) -> 50 | Z11: =INDEX('9 - Water Readings'!$L$8:$L$955,1+(2*(ROWS(A$1:A10)-1))) -> 26 | AA11: ='9 - Water Readings'!Q16 -> 127 | AB11: ='9 - Water Readings'!R16 -> 522 | AC11: ='9 - Water Readings'!S16 -> 0
A12: Doha | B12: =B11+1 -> 11 | C12: 2 | D12: 2023 | E12: =INDEX('13 - Electrical Readings'!$C$8:$C$953,1+(2*(ROWS(A$1:A11)-1))) -> 9 | F12: =INDEX('13 - Electrical Readings'!$D$6:$D$953,1+(2*(ROWS(A$1:A12)-1))) -> 867 | G12: =INDEX('13 - Electrical Readings'!$E$6:$E$953,1+(2*(ROWS(A$1:A12)-1))) -> 2341 | H12: =INDEX('13 - Electrical Readings'!$F$6:$F$953,1+(2*(ROWS(A$1:A12)-1))) -> 11139 | I12: =INDEX('13 - Electrical Readings'!$G$6:$G$953,1+(2*(ROWS(A$1:A12)-1))) -> 14 | J12: =INDEX('13 - Electrical Readings'!$I$6:$I$953,1+(2*(ROWS(A$1:A12)-1))) -> 1683 | K12: =INDEX('13 - Electrical Readings'!$J$6:$J$953,1+(2*(ROWS(B$1:B12)-1))) -> 8784 | L12: =INDEX('13 - Electrical Readings'!$K$6:$K$953,1+(2*(ROWS(C$1:C12)-1))) -> 3942 | M12: =INDEX('13 - Electrical Readings'!$L$6:$L$953,1+(2*(ROWS(D$1:D12)-1))) -> 4908 | N12: =INDEX('13 - Electrical Readings'!$M$6:$M$953,1+(2*(ROWS(E$1:E12)-1))) -> 9408 | O12: =INDEX('13 - Electrical Readings'!$N$6:$N$953,1+(2*(ROWS(E$1:E12)-1))) -> 6735 | P12: =INDEX('13 - Electrical Readings'!$O$6:$O$953,1+(2*(ROWS(E$1:E12)-1))) -> 837 | Q12: =INDEX('13 - Electrical Readings'!$P$6:$P$953,1+(2*(ROWS(E$1:E12)-1))) -> 2570 | R12: =INDEX('9 - Water Readings'!$C$8:$C$955,1+(2*(ROWS(A$1:A11)-1))) -> 0 | S12: =INDEX('9 - Water Readings'!$D$8:$D$954,1+(2*(ROWS(A$1:A11)-1))) -> 0 | T12: =INDEX('9 - Water Readings'!$E$8:$E$955,1+(2*(ROWS(A$1:A11)-1))) -> 0 | U12: =INDEX('9 - Water Readings'!$G$8:$G$954,1+(2*(ROWS(A$1:A11)-1))) -> 137 | V12: =INDEX('9 - Water Readings'!$H$8:$H$955,1+(2*(ROWS(A$1:A11)-1))) -> 17 | W12: =INDEX('9 - Water Readings'!$I$8:$I$955,1+(2*(ROWS(A$1:A11)-1))) -> 79 | X12: =INDEX('9 - Water Readings'!$J$8:$J$955,1+(2*(ROWS(A$1:A11)-1))) -> 286 | Y12: =INDEX('9 - Water Readings'!$K$8:$K$955,1+(2*(ROWS(A$1:A11)-1))) -> 50 | Z12: =INDEX('9 - Water Readings'!$L$8:$L$955,1+(2*(ROWS(A$1:A11)-1))) -> 25 | AA12: ='9 - Water Readings'!Q17 -> 173 | AB12: ='9 - Water Readings'!R17 -> 626 | AC12: ='9 - Water Readings'!S17 -> 0.3
A13: Doha | B13: =B12+1 -> 12 | C13: 2 | D13: 2023 | E13: =INDEX('13 - Electrical Readings'!$C$8:$C$953,1+(2*(ROWS(A$1:A12)-1))) -> 9 | F13: =INDEX('13 - Electrical Readings'!$D$6:$D$953,1+(2*(ROWS(A$1:A13)-1))) -> 854 | G13: =INDEX('13 - Electrical Readings'!$E$6:$E$953,1+(2*(ROWS(A$1:A13)-1))) -> 2341 | H13: =INDEX('13 - Electrical Readings'!$F$6:$F$953,1+(2*(ROWS(A$1:A13)-1))) -> 11909 | I13: =INDEX('13 - Electrical Readings'!$G$6:$G$953,1+(2*(ROWS(A$1:A13)-1))) -> 19 | J13: =INDEX('13 - Electrical Readings'!$I$6:$I$953,1+(2*(ROWS(A$1:A13)-1))) -> 1650 | K13: =INDEX('13 - Electrical Readings'!$J$6:$J$953,1+(2*(ROWS(B$1:B13)-1))) -> 9764 | L13: =INDEX('13 - Electrical Readings'!$K$6:$K$953,1+(2*(ROWS(C$1:C13)-1))) -> 3965 | M13: =INDEX('13 - Electrical Readings'!$L$6:$L$953,1+(2*(ROWS(D$1:D13)-1))) -> 5068 | N13: =INDEX('13 - Electrical Readings'!$M$6:$M$953,1+(2*(ROWS(E$1:E13)-1))) -> 9838 | O13: =INDEX('13 - Electrical Readings'!$N$6:$N$953,1+(2*(ROWS(E$1:E13)-1))) -> 7076 | P13: =INDEX('13 - Electrical Readings'!$O$6:$O$953,1+(2*(ROWS(E$1:E13)-1))) -> 914 | Q13: =INDEX('13 - Electrical Readings'!$P$6:$P$953,1+(2*(ROWS(E$1:E13)-1))) -> 2170 | R13: =INDEX('9 - Water Readings'!$C$8:$C$955,1+(2*(ROWS(A$1:A12)-1))) -> 0 | S13: =INDEX('9 - Water Readings'!$D$8:$D$954,1+(2*(ROWS(A$1:A12)-1))) -> 0 | T13: =INDEX('9 - Water Readings'!$E$8:$E$955,1+(2*(ROWS(A$1:A12)-1))) -> 0 | U13: =INDEX('9 - Water Readings'!$G$8:$G$954,1+(2*(ROWS(A$1:A12)-1))) -> 139 | V13: =INDEX('9 - Water Readings'!$H$8:$H$955,1+(2*(ROWS(A$1:A12)-1))) -> 15 | W13: =INDEX('9 - Water Readings'!$I$8:$I$955,1+(2*(ROWS(A$1:A12)-1))) -> 73 | X13: =INDEX('9 - Water Readings'!$J$8:$J$955,1+(2*(ROWS(A$1:A12)-1))) -> 322 | Y13: =INDEX('9 - Water Readings'!$K$8:$K$955,1+(2*(ROWS(A$1:A12)-1))) -> 51 | Z13: =INDEX('9 - Water Readings'!$L$8:$L$955,1+(2*(ROWS(A$1:A12)-1))) -> 27 | AA13: ='9 - Water Readings'!Q18 -> 184 | AB13: ='9 - Water Readings'!R18 -> 616 | AC13: ='9 - Water Readings'!S18 -> 0.5
A14: Doha | B14: =B13+1 -> 13 | C14: 2 | D14: 2023 | E14: =INDEX('13 - Electrical Readings'!$C$8:$C$953,1+(2*(ROWS(A$1:A13)-1))) -> 3 | F14: =INDEX('13 - Electrical Readings'!$D$6:$D$953,1+(2*(ROWS(A$1:A14)-1))) -> 872 | G14: =INDEX('13 - Electrical Readings'!$E$6:$E$953,1+(2*(ROWS(A$1:A14)-1))) -> 2362 | H14: =INDEX('13 - Electrical Readings'!$F$6:$F$953,1+(2*(ROWS(A$1:A14)-1))) -> 13097 | I14: =INDEX('13 - Electrical Readings'!$G$6:$G$953,1+(2*(ROWS(A$1:A14)-1))) -> 14 | J14: =INDEX('13 - Electrical Readings'!$I$6:$I$953,1+(2*(ROWS(A$1:A14)-1))) -> 1604 | K14: =INDEX('13 - Electrical Readings'!$J$6:$J$953,1+(2*(ROWS(B$1:B14)-1))) -> 9864 | L14: =INDEX('13 - Electrical Readings'!$K$6:$K$953,1+(2*(ROWS(C$1:C14)-1))) -> 3993 | M14: =INDEX('13 - Electrical Readings'!$L$6:$L$953,1+(2*(ROWS(D$1:D14)-1))) -> 4918 | N14: =INDEX('13 - Electrical Readings'!$M$6:$M$953,1+(2*(ROWS(E$1:E14)-1))) -> 9541 | O14: =INDEX('13 - Electrical Readings'!$N$6:$N$953,1+(2*(ROWS(E$1:E14)-1))) -> 7224 | P14: =INDEX('13 - Electrical Readings'!$O$6:$O$953,1+(2*(ROWS(E$1:E14)-1))) -> 973 | Q14: =INDEX('13 - Electrical Readings'!$P$6:$P$953,1+(2*(ROWS(E$1:E14)-1))) -> 2650 | R14: =INDEX('9 - Water Readings'!$C$8:$C$955,1+(2*(ROWS(A$1:A13)-1))) -> 0 | S14: =INDEX('9 - Water Readings'!$D$8:$D$954,1+(2*(ROWS(A$1:A13)-1))) -> 0 | T14: =INDEX('9 - Water Readings'!$E$8:$E$955,1+(2*(ROWS(A$1:A13)-1))) -> 0 | U14: =INDEX('9 - Water Readings'!$G$8:$G$954,1+(2*(ROWS(A$1:A13)-1))) -> 137 | V14: =INDEX('9 - Water Readings'!$H$8:$H$955,1+(2*(ROWS(A$1:A13)-1))) -> 15 | W14: =INDEX('9 - Water Readings'!$I$8:$I$955,1+(2*(ROWS(A$1:A13)-1))) -> 82 | X14: =INDEX('9 - Water Readings'!$J$8:$J$955,1+(2*(ROWS(A$1:A13)-1))) -> 313 | Y14: =INDEX('9 - Water Readings'!$K$8:$K$955,1+(2*(ROWS(A$1:A13)-1))) -> 49 | Z14: =INDEX('9 - Water Readings'!$L$8:$L$955,1+(2*(ROWS(A$1:A13)-1))) -> 25 | AA14: ='9 - Water Readings'!Q19 -> 139 | AB14: ='9 - Water Readings'!R19 -> 474 | AC14: ='9 - Water Readings'!S19 -> 2.2
... A29: Doha | B29: =B28+1 -> 28 | C29: 2 | D29: 2023 | E29: =INDEX('13 - Electrical Readings'!$C$8:$C$953,1+(2*(ROWS(A$1:A28)-1))) -> 3834 | F29: =INDEX('13 - Electrical Readings'!$D$6:$D$953,1+(2*(ROWS(A$1:A29)-1))) -> 901 | G29: =INDEX('13 - Electrical Readings'!$E$6:$E$953,1+(2*(ROWS(A$1:A29)-1))) -> 2433 | H29: =INDEX('13 - Electrical Readings'!$F$6:$F$953,1+(2*(ROWS(A$1:A29)-1))) -> 2618 | I29: =INDEX('13 - Electrical Readings'!$G$6:$G$953,1+(2*(ROWS(A$1:A29)-1))) -> 12541 | J29: =INDEX('13 - Electrical Readings'!$I$6:$I$953,1+(2*(ROWS(A$1:A29)-1))) -> 1672 | K29: =INDEX('13 - Electrical Readings'!$J$6:$J$953,1+(2*(ROWS(B$1:B29)-1))) -> 9981 | L29: =INDEX('13 - Electrical Readings'!$K$6:$K$953,1+(2*(ROWS(C$1:C29)-1))) -> 4199 | M29: =INDEX('13 - Electrical Readings'!$L$6:$L$953,1+(2*(ROWS(D$1:D29)-1))) -> 4954 | N29: =INDEX('13 - Electrical Readings'!$M$6:$M$953,1+(2*(ROWS(E$1:E29)-1))) -> 9258 | O29: =INDEX('13 - Electrical Readings'!$N$6:$N$953,1+(2*(ROWS(E$1:E29)-1))) -> 7380 | P29: =INDEX('13 - Electrical Readings'!$O$6:$O$953,1+(2*(ROWS(E$1:E29)-1))) -> 1416 | Q29: =INDEX('13 - Electrical Readings'!$P$6:$P$953,1+(2*(ROWS(E$1:E29)-1))) -> 2800 | R29: =INDEX('9 - Water Readings'!$C$8:$C$955,1+(2*(ROWS(A$1:A28)-1))) -> 0 | S29: =INDEX('9 - Water Readings'!$D$8:$D$954,1+(2*(ROWS(A$1:A28)-1))) -> 0 | T29: =INDEX('9 - Water Readings'!$E$8:$E$955,1+(2*(ROWS(A$1:A28)-1))) -> 0 | U29: =INDEX('9 - Water Readings'!$G$8:$G$954,1+(2*(ROWS(A$1:A28)-1))) -> 144 | V29: =INDEX('9 - Water Readings'!$H$8:$H$955,1+(2*(ROWS(A$1:A28)-1))) -> 18 | W29: =INDEX('9 - Water Readings'!$I$8:$I$955,1+(2*(ROWS(A$1:A28)-1))) -> 90 | X29: =INDEX('9 - Water Readings'!$J$8:$J$955,1+(2*(ROWS(A$1:A28)-1))) -> 324 | Y29: =INDEX('9 - Water Readings'!$K$8:$K$955,1+(2*(ROWS(A$1:A28)-1))) -> 51 | Z29: =INDEX('9 - Water Readings'!$L$8:$L$955,1+(2*(ROWS(A$1:A28)-1))) -> 21 | AA29: ='9 - Water Readings'!Q34 -> 217 | AB29: ='9 - Water Readings'!R34 -> 672 | AC29: ='9 - Water Readings'!S34 -> 3.5
E30: =SUM(E2:E29) -> 180483 | F30: =SUM(F2:F29) -> 24390 | G30: =SUM(G2:G29) -> 90292 | H30: =SUM(H2:H29) -> 140552 | I30: =SUM(I2:I29) -> 67440 | J30: =SUM(J2:J29) -> 46792 | K30: =SUM(K2:K29) -> 267089 | L30: =SUM(L2:L29) -> 113044 | ... AC30: =SUM(AC2:AC29) -> 39.9

Sheet 13 - Electrical Readings
F2: Central Plant Engineering
F3: Daily Electrical Meter Readings | N3: Month: FEBRUARY 2023
B5: Date | C5: CP Chillers | D5: CP Chillers | E5: CP Chillers | F5: CP Chillers | G5: CP Chillers | H5: CP Total kWh | I5: Town House | J5: Hotel | K5: Hotel | L5: Hotel | M5: Hotel | N5: Spa | O5: Marina | P5: Nobu | Q5: Hotel Total kWh | R5: Grand Total kWh
C6: 157691 | D6: 157692 | E6: 157693 | F6: 157694 | G6: 167609 | I6: 166443 | J6: 157687 | K6: 157688 | L6: 157689 | M6: 157690 | N6: 174390 | O6: 173992 | P6: 1180004
B7: 1 | C7: 22955455 | D7: 16510829 | E7: 29416830 | F7: 29032681 | G7: 17434212 | I7: 6567884 | J7: 28831997 | K7: 9617832 | L7: 14245942 | M7: 22001477 | N7: 27304344 | O7: 8841346 | P7: 8045320
B8: Consumption | C8: =C7-22952930 -> 2525 | D8: =D7-16510192 -> 637 | E8: =E7-29406439 -> 10391 | F8: =F7-29030373 -> 2308 | G8: =G7-17433804 -> 408 | H8: =G8+F8+E8+D8+C8 -> 16269 | I8: =I7-6566189 -> 1695 | J8: =J7-28822483 -> 9514 | K8: =K7-9613942 -> 3890 | L8: =L7-14240891 -> 5051 | M8: =M7-21992561 -> 8916 | N8: =N7-27297407 -> 6937 | O8: =O7-8840394 -> 952 | P8: =P7-8042650 -> 2670 | Q8: =P8+O8+N8+M8+L8+K8+J8+I8 -> 39625 | R8: =Q8+H8 -> 55894
B9: 2 | C9: 22955455 | D9: 16511751 | E9: 29422117 | F9: 29041234 | G9: 17434224 | I9: 6569579 | J9: 28841197 | K9: 9621617 | L9: 14250652 | M9: 22009409 | N9: 27311468 | O9: 8842333 | P9: 8047990
B10: Consumption | C10: =C9-C7 -> 0 | D10: =D9-D7 -> 922 | E10: =E9-E7 -> 5287 | F10: =F9-F7 -> 8553 | G10: =G9-G7 -> 12 | H10: =G10+F10+E10+D10+C10 -> 14774 | I10: =I9-I7 -> 1695 | J10: =J9-J7 -> 9200 | K10: =K9-K7 -> 3785 | L10: =L9-L7 -> 4710 | M10: =M9-M7 -> 7932 | N10: =N9-N7 -> 7124 | O10: =O9-O7 -> 987 | P10: =P9-P7 -> 2670 | Q10: =P10+O10+N10+M10+L10+K10+J10+I10 -> 38103 | R10: =Q10+H10 -> 52877
B11: 3 | C11: 22955455 | D11: 16512658 | E11: 29424182 | F11: 29052384 | G11: 17434238 | I11: 6571305 | J11: 28850799 | K11: 9625503 | L11: 14255460 | M11: 22018628 | N11: 27318492 | O11: 8843403 | P11: 8050870
B12: Consumption | C12: =C11-C9 -> 0 | D12: =D11-D9 -> 907 | E12: =E11-E9 -> 2065 | F12: =F11-F9 -> 11150 | G12: =G11-G9 -> 14 | H12: =G12+F12+E12+D12+C12 -> 14136 | I12: =I11-I9 -> 1726 | J12: =J11-J9 -> 9602 | K12: =K11-K9 -> 3886 | L12: =L11-L9 -> 4808 | M12: =M11-M9 -> 9219 | N12: =N11-N9 -> 7024 | O12: =O11-O9 -> 1070 | P12: =P11-P9 -> 2880 | Q12: =P12+O12+N12+M12+L12+K12+J12+I12 -> 40215 | R12: =Q12+H12 -> 54351
B13: 4 | C13: 22957217 | D13: 16513509 | E13: 29426320 | F13: 29056201 | G13: 17441993 | I13: 6573016 | J13: 28859578 | K13: 9628985 | L13: 14260208 | M13: 22027608 | N13: 27325385 | O13: 8844304 | P13: 8053630
B14: Consumption | C14: =C13-C11 -> 1762 | D14: =D13-D11 -> 851 | E14: =E13-E11 -> 2138 | F14: =F13-F11 -> 3817 | G14: =G13-G11 -> 7755 | H14: =G14+F14+E14+D14+C14 -> 16323 | I14: =I13-I11 -> 1711 | J14: =J13-J11 -> 8779 | K14: =K13-K11 -> 3482 | L14: =L13-L11 -> 4748 | M14: =M13-M11 -> 8980 | N14: =N13-N11 -> 6893 | O14: =O13-O11 -> 901 | P14: =P13-P11 -> 2760 | Q14: =P14+O14+N14+M14+L14+K14+J14+I14 -> 38254 | R14: =Q14+H14 -> 54577
B15: 5 | C15: 22962556 | D15: 16514331 | E15: 29428555 | F15: 29058041 | G15: 17449355 | I15: 6574633 | J15: 28868515 | K15: 9632432 | L15: 14264871 | M15: 22036186 | N15: 27332023 | O15: 8845190 | P15: 8055610
B16: Consumption | C16: =C15-C13 -> 5339 | D16: =D15-D13 -> 822 | E16: =E15-E13 -> 2235 | F16: =F15-F13 -> 1840 | G16: =G15-G13 -> 7362 | H16: =G16+F16+E16+D16+C16 -> 17598 | I16: =I15-I13 -> 1617 | J16: =J15-J13 -> 8937 | K16: =K15-K13 -> 3447 | L16: =L15-L13 -> 4663 | M16: =M15-M13 -> 8578 | N16: =N15-N13 -> 6638 | O16: =O15-O13 -> 886 | P16: =P15-P13 -> 1980 | Q16: =P16+O16+N16+M16+L16+K16+J16+I16 -> 36746 | R16: =Q16+H16 -> 54344
B17: 6 | C17: 22977271 | D17: 16515205 | E17: 29430924 | F17: 29060307 | G17: 17449368 | I17: 6576269 | J17: 28877936 | K17: 9636025 | L17: 14269737 | M17: 22045126 | N17: 27339070 | O17: 8846121 | P17: 8058080
B18: Consumption | C18: =C17-C15 -> 14715 | D18: =D17-D15 -> 874 | E18: =E17-E15 -> 2369 | F18: =F17-F15 -> 2266 | G18: =G17-G15 -> 13 | H18: =G18+F18+E18+D18+C18 -> 20237 | I18: =I17-I15 -> 1636 | J18: =J17-J15 -> 9421 | K18: =K17-K15 -> 3593 | L18: =L17-L15 -> 4866 | M18: =M17-M15 -> 8940 | N18: =N17-N15 -> 7047 | O18: =O17-O15 -> 931 | P18: =P17-P15 -> 2470 | Q18: =P18+O18+N18+M18+L18+K18+J18+I18 -> 38904 | R18: =Q18+H18 -> 59141
B19: 7 | C19: 22992997 | D19: 16516021 | E19: 29433228 | F19: 29062767 | G19: 17449382 | I19: 6577873 | J19: 28887326 | K19: 9639466 | L19: 14274646 | M19: 22054307 | N19: 27346395 | O19: 8847132 | P19: 8060720
B20: Consumption | C20: =C19-C17 -> 15726 | D20: =D19-D17 -> 816 | E20: =E19-E17 -> 2304 | F20: =F19-F17 -> 2460 | G20: =G19-G17 -> 14 | H20: =G20+F20+E20+D20+C20 -> 21320 | I20: =I19-I17 -> 1604 | J20: =J19-J17 -> 9390 | K20: =K19-K17 -> 3441 | L20: =L19-L17 -> 4909 | M20: =M19-M17 -> 9181 | N20: =N19-N17 -> 7325 | O20: =O19-O17 -> 1011 | P20: =P19-P17 -> 2640 | Q20: =P20+O20+N20+M20+L20+K20+J20+I20 -> 39501 | R20: =Q20+H20 -> 60821
B21: 8 | C21: 23001879 | D21: 16516885 | E21: 29435612 | F21: 29065156 | G21: 17455090 | I21: 6579569 | J21: 28897028 | K21: 9643275 | L21: 14279859 | M21: 22063570 | N21: 27353614 | O21: 8848132 | P21: 8063430
B22: Consumption | C22: =C21-C19 -> 8882 | D22: =D21-D19 -> 864 | E22: =E21-E19 -> 2384 | F22: =F21-F19 -> 2389 | G22: =G21-G19 -> 5708 | H22: =G22+F22+E22+D22+C22 -> 20227 | I22: =I21-I19 -> 1696 | J22: =J21-J19 -> 9702 | K22: =K21-K19 -> 3809 | L22: =L21-L19 -> 5213 | M22: =M21-M19 -> 9263 | N22: =N21-N19 -> 7219 | O22: =O21-O19 -> 1000 | P22: =P21-P19 -> 2710 | Q22: =P22+O22+N22+M22+L22+K22+J22+I22 -> 40612 | R22: =Q22+H22 -> 60839
B23: 9 | C23: 23001887 | D23: 16517745 | E23: 29439980 | F23: 29070003 | G23: 17459753 | I23: 6581272 | J23: 28906547 | K23: 9647032 | L23: 14285149 | M23: 22072199 | N23: 27360635 | O23: 8849080 | P23: 8066150
B24: Consumption | C24: =C23-C21 -> 8 | D24: =D23-D21 -> 860 | E24: =E23-E21 -> 4368 | F24: =F23-F21 -> 4847 | G24: =G23-G21 -> 4663 | H24: =G24+F24+E24+D24+C24 -> 14746 | I24: =I23-I21 -> 1703 | J24: =J23-J21 -> 9519 | K24: =K23-K21 -> 3757 | L24: =L23-L21 -> 5290 | M24: =M23-M21 -> 8629 | N24: =N23-N21 -> 7021 | O24: =O23-O21 -> 948 | P24: =P23-P21 -> 2720 | Q24: =P24+O24+N24+M24+L24+K24+J24+I24 -> 39587 | R24: =Q24+H24 -> 54333
B25: 10 | C25: 23001896 | D25: 16518588 | E25: 29442297 | F25: 29079669 | G25: 17459767 | I25: 6582964 | J25: 28916332 | K25: 9650903 | L25: 14290541 | M25: 22081405 | N25: 27367501 | O25: 8850049 | P25: 8069090
B26: Consumption | C26: =C25-C23 -> 9 | D26: =D25-D23 -> 843 | E26: =E25-E23 -> 2317 | F26: =F25-F23 -> 9666 | G26: =G25-G23 -> 14 | H26: =G26+F26+E26+D26+C26 -> 12849 | I26: =I25-I23 -> 1692 | J26: =J25-J23 -> 9785 | K26: =K25-K23 -> 3871 | L26: =L25-L23 -> 5392 | M26: =M25-M23 -> 9206 | N26: =N25-N23 -> 6866 | O26: =O25-O23 -> 969 | P26: =P25-P23 -> 2940 | Q26: =P26+O26+N26+M26+L26+K26+J26+I26 -> 40721 | R26: =Q26+H26 -> 53570
B27: 11 | C27: 23001905 | D27: 16519455 | E27: 29444638 | F27: 29090808 | G27: 17459781 | I27: 6584647 | J27: 28925116 | K27: 9654845 | L27: 14295449 | M27: 22090813 | N27: 27374236 | O27: 8850886 | P27: 8071660
B28: Consumption | C28: =C27-C25 -> 9 | D28: =D27-D25 -> 867 | E28: =E27-E25 -> 2341 | F28: =F27-F25 -> 11139 | G28: =G27-G25 -> 14 | H28: =G28+F28+E28+D28+C28 -> 14370 | I28: =I27-I25 -> 1683 | J28: =J27-J25 -> 8784 | K28: =K27-K25 -> 3942 | L28: =L27-L25 -> 4908 | M28: =M27-M25 -> 9408 | N28: =N27-N25 -> 6735 | O28: =O27-O25 -> 837 | P28: =P27-P25 -> 2570 | Q28: =P28+O28+N28+M28+L28+K28+J28+I28 -> 38867 | R28: =Q28+H28 -> 53237
B29: 12 | C29: 23001914 | D29: 16520309 | E29: 29446979 | F29: 29102717 | G29: 17459800 | I29: 6586297 | J29: 28934880 | K29: 9658810 | L29: 14300517 | M29: 22100651 | N29: 27381312 | O29: 8851800 | P29: 8073830
B30: Consumption | C30: =C29-C27 -> 9 | D30: =D29-D27 -> 854 | E30: =E29-E27 -> 2341 | F30: =F29-F27 -> 11909 | G30: =G29-G27 -> 19 | H30: =G30+F30+E30+D30+C30 -> 15132 | I30: =I29-I27 -> 1650 | J30: =J29-J27 -> 9764 | K30: =K29-K27 -> 3965 | L30: =L29-L27 -> 5068 | M30: =M29-M27 -> 9838 | N30: =N29-N27 -> 7076 | O30: =O29-O27 -> 914 | P30: =P29-P27 -> 2170 | Q30: =P30+O30+N30+M30+L30+K30+J30+I30 -> 40445 | R30: =Q30+H30 -> 55577
B31: 13 | C31: 23001917 | D31: 16521181 | E31: 29449341 | F31: 29115814 | G31: 17459814 | I31: 6587901 | J31: 28944744 | K31: 9662803 | L31: 14305435 | M31: 22110192 | N31: 27388536 | O31: 8852773 | P31: 8076480
B32: Consumption | C32: =C31-C29 -> 3 | D32: =D31-D29 -> 872 | E32: =E31-E29 -> 2362 | F32: =F31-F29 -> 13097 | G32: =G31-G29 -> 14 | H32: =G32+F32+E32+D32+C32 -> 16348 | I32: =I31-I29 -> 1604 | J32: =J31-J29 -> 9864 | K32: =K31-K29 -> 3993 | L32: =L31-L29 -> 4918 | M32: =M31-M29 -> 9541 | N32: =N31-N29 -> 7224 | O32: =O31-O29 -> 973 | P32: =P31-P29 -> 2650 | Q32: =P32+O32+N32+M32+L32+K32+J32+I32 -> 40767 | R32: =Q32+H32 -> 57115
B33: 14 | C33: 23001924 | D33: 16522051 | E33: 29451709 | F33: 29129686 | G33: 17459832 | I33: 6589527 | J33: 28954716 | K33: 9666852 | L33: 14310341 | M33: 22119403 | N33: 27396005 | O33: 8853775 | P33: 8079270
B34: Consumption | C34: =C33-C31 -> 7 | D34: =D33-D31 -> 870 | E34: =E33-E31 -> 2368 | F34: =F33-F31 -> 13872 | G34: =G33-G31 -> 18 | H34: =G34+F34+E34+D34+C34 -> 17135 | I34: =I33-I31 -> 1626 | J34: =J33-J31 -> 9972 | K34: =K33-K31 -> 4049 | L34: =L33-L31 -> 4906 | M34: =M33-M31 -> 9211 | N34: =N33-N31 -> 7469 | O34: =O33-O31 -> 1002 | P34: =P33-P31 -> 2790 | Q34: =P34+O34+N34+M34+L34+K34+J34+I34 -> 41025 | R34: =Q34+H34 -> 58160
B35: 15 | C35: 23001927 | D35: 16522920 | E35: 29457246 | F35: 29139762 | G35: 17459846 | I35: 6591268 | J35: 28965132 | K35: 9671109 | L35: 14315725 | M35: 22129144 | N35: 27403790 | O35: 8854899 | P35: 8082170
B36: Consumption | C36: =C35-C33 -> 3 | D36: =D35-D33 -> 869 | E36: =E35-E33 -> 5537 | F36: =F35-F33 -> 10076 | G36: =G35-G33 -> 14 | H36: =G36+F36+E36+D36+C36 -> 16499 | I36: =I35-I33 -> 1741 | J36: =J35-J33 -> 10416 | K36: =K35-K33 -> 4257 | L36: =L35-L33 -> 5384 | M36: =M35-M33 -> 9741 | N36: =N35-N33 -> 7785 | O36: =O35-O33 -> 1124 | P36: =P35-P33 -> 2900 | Q36: =P36+O36+N36+M36+L36+K36+J36+I36 -> 43348 | R36: =Q36+H36 -> 59847
B37: 16 | C37: 23003149 | D37: 16523809 | E37: 29468129 | F37: 29142361 | G37: 17459861 | I37: 6592876 | J37: 28974643 | K37: 9675198 | L37: 14320628 | M37: 22138742 | N37: 27410863 | O37: 8855824 | P37: 8084740
B38: Consumption | C38: =C37-C35 -> 1222 | D38: =D37-D35 -> 889 | E38: =E37-E35 -> 10883 | F38: =F37-F35 -> 2599 | G38: =G37-G35 -> 15 | H38: =G38+F38+E38+D38+C38 -> 15608 | I38: =I37-I35 -> 1608 | J38: =J37-J35 -> 9511 | K38: =K37-K35 -> 4089 | L38: =L37-L35 -> 4903 | M38: =M37-M35 -> 9598 | N38: =N37-N35 -> 7073 | O38: =O37-O35 -> 925 | P38: =P37-P35 -> 2570 | Q38: =P38+O38+N38+M38+L38+K38+J38+I38 -> 40277 | R38: =Q38+H38 -> 55885
B39: 17 | C39: 23016010 | D39: 16524675 | E39: 29470493 | F39: 29144546 | G39: 17459878 | I39: 6594528 | J39: 28984380 | K39: 9679729 | L39: 14325828 | M39: 22147762 | N39: 27417716 | O39: 8856705 | P39: 8087690
B40: Consumption | C40: =C39-C37 -> 12861 | D40: =D39-D37 -> 866 | E40: =E39-E37 -> 2364 | F40: =F39-F37 -> 2185 | G40: =G39-G37 -> 17 | H40: =G40+F40+E40+D40+C40 -> 18293 | I40: =I39-I37 -> 1652 | J40: =J39-J37 -> 9737 | K40: =K39-K37 -> 4531 | L40: =L39-L37 -> 5200 | M40: =M39-M37 -> 9020 | N40: =N39-N37 -> 6853 | O40: =O39-O37 -> 881 | P40: =P39-P37 -> 2950 | Q40: =P40+O40+N40+M40+L40+K40+J40+I40 -> 40824 | R40: =Q40+H40 -> 59117
B41: 18 | C41: 23027998 | D41: 16525527 | E41: 29472852 | F41: 29146646 | G41: 17459893 | I41: 6596288 | J41: 28993491 | K41: 9684063 | L41: 14331047 | M41: 22156776 | N41: 27424810 | O41: 8857520 | P41: 8090420
B42: Consumption | C42: =C41-C39 -> 11988 | D42: =D41-D39 -> 852 | E42: =E41-E39 -> 2359 | F42: =F41-F39 -> 2100 | G42: =G41-G39 -> 15 | H42: =G42+F42+E42+D42+C42 -> 17314 | I42: =I41-I39 -> 1760 | J42: =J41-J39 -> 9111 | K42: =K41-K39 -> 4334 | L42: =L41-L39 -> 5219 | M42: =M41-M39 -> 9014 | N42: =N41-N39 -> 7094 | O42: =O41-O39 -> 815 | P42: =P41-P39 -> 2730 | Q42: =P42+O42+N42+M42+L42+K42+J42+I42 -> 40077 | R42: =Q42+H42 -> 57391
...

Sheet 9 - Water Readings
F2: Central Plant Engineering
F3: Daily Water Meter Readings | M3: Month: FEBRUARY 2023
B5: Date | C5: CP F/F | D5: CP Chillers | E5: CP Parking | F5: CP Total M3 | G5: Town House | H5: Spa B | I5: Spa A | J5: CW Hotel A | K5: CCW Hotel B | L5: Marina | M5: Hotel Total M3 | N5: Grand Total M3 | P5: Day | Q5: Room Nights | R5: Total Guests | S5: Cooling Degree Day
C6: 130465 | D6: 130460 | E6: 130461 | G6: 130464 | H6: 130456 | I6: 130457 | J6: 130458 | K6: 130459 | L6: 130466 | T6: Following Meter is not working
B7: 1 | C7: 8347 | D7: 532 | E7: 46762 | G7: 300323 | H7: 168777 | I7: 187023 | J7: 29116 | K7: 640468 | L7: 6745 | P7: 1 | Q7: 132 | R7: 398 | S7: 1.2 | T7: 130461 | U7: CP Parking
B8: Consumption | C8: =C7-8344 -> 3 | D8: =D7-532 -> 0 | E8: =E7-46762 -> 0 | F8: =E8+D8+C8 -> 3 | G8: =G7-300181 -> 142 | H8: =H7-168760 -> 17 | I8: =I7-186950 -> 73 | J8: =J7-28824 -> 292 | K8: =K7-640434 -> 34 | L8: =L7-6718 -> 27 | M8: =L8+K8+J8+I8+H8+G8 -> 585 | N8: =M8+F8 -> 588 | P8: 2 | Q8: 156 | R8: 570 | S8: 1.3
B9: 2 | C9: 8347 | D9: 532 | E9: 46762 | G9: 300458 | H9: 168794 | I9: 187112 | J9: 29426 | K9: 640524 | L9: 6776 | P9: 3 | Q9: 138 | R9: 498 | S9: 0.8
B10: Consumption | C10: =C9-C7 -> 0 | D10: =D9-D7 -> 0 | E10: =E9-E7 -> 0 | F10: =E10+D10+C10 -> 0 | G10: =G9-G7 -> 135 | H10: =H9-H7 -> 17 | I10: =I9-I7 -> 89 | J10: =J9-J7 -> 310 | K10: =K9-K7 -> 56 | L10: =L9-L7 -> 31 | M10: =L10+K10+J10+I10+H10+G10 -> 638 | N10: =M10+F10 -> 638 | P10: 4 | Q10: 104 | R10: 320 | S10: 0.1
B11: 3 | C11: 8347 | D11: 532 | E11: 46762 | G11: 300591 | H11: 168811 | I11: 187190 | J11: 29743 | K11: 640573 | L11: 6800 | P11: 5 | Q11: 99 | R11: 262 | S11: 0.3
B12: Consumption | C12: =C11-C9 -> 0 | D12: =D11-D9 -> 0 | E12: =E11-E9 -> 0 | F12: =E12+D12+C12 -> 0 | G12: =G11-G9 -> 133 | H12: =H11-H9 -> 17 | I12: =I11-I9 -> 78 | J12: =J11-J9 -> 317 | K12: =K11-K9 -> 49 | L12: =L11-L9 -> 24 | M12: =L12+K12+J12+I12+H12+G12 -> 618 | N12: =M12+F12 -> 618 | P12: 6 | Q12: 127 | R12: 310 | S12: 0.6
B13: 4 | C13: 8347 | D13: 532 | E13: 46762 | G13: 300728 | H13: 168828 | I13: 187271 | J13: 30041 | K13: 640619 | L13: 6829 | P13: 7 | Q13: 116 | R13: 294 | S13: 3
B14: Consumption | C14: =C13-C11 -> 0 | D14: =D13-D11 -> 0 | E14: =E13-E11 -> 0 | F14: =E14+D14+C14 -> 0 | G14: =G13-G11 -> 137 | H14: =H13-H11 -> 17 | I14: =I13-I11 -> 81 | J14: =J13-J11 -> 298 | K14: =K13-K11 -> 46 | L14: =L13-L11 -> 29 | M14: =L14+K14+J14+I14+H14+G14 -> 608 | N14: =M14+F14 -> 608 | P14: 8 | Q14: 113 | R14: 350 | S14: 0.9
B15: 5 | C15: 8347 | D15: 532 | E15: 46762 | G15: 300864 | H15: 168843 | I15: 187337 | J15: 30313 | K15: 640657 | L15: 6847 | P15: 9 | Q15: 122 | R15: 448 | S15: 0.3
B16: Consumption | C16: =C15-C13 -> 0 | D16: =D15-D13 -> 0 | E16: =E15-E13 -> 0 | F16: =E16+D16+C16 -> 0 | G16: =G15-G13 -> 136 | H16: =H15-H13 -> 15 | I16: =I15-I13 -> 66 | J16: =J15-J13 -> 272 | K16: =K15-K13 -> 38 | L16: =L15-L13 -> 18 | M16: =L16+K16+J16+I16+H16+G16 -> 545 | N16: =M16+F16 -> 545 | P16: 10 | Q16: 127 | R16: 522 | S16: 0
B17: 6 | C17: 8347 | D17: 532 | E17: 46762 | G17: 301002 | H17: 168858 | I17: 187412 | J17: 30600 | K17: 640694 | L17: 6873 | P17: 11 | Q17: 173 | R17: 626 | S17: 0.3
B18: Consumption | C18: =C17-C15 -> 0 | D18: =D17-D15 -> 0 | E18: =E17-E15 -> 0 | F18: =E18+D18+C18 -> 0 | G18: =G17-G15 -> 138 | H18: =H17-H15 -> 15 | I18: =I17-I15 -> 75 | J18: =J17-J15 -> 287 | K18: =K17-K15 -> 37 | L18: =L17-L15 -> 26 | M18: =L18+K18+J18+I18+H18+G18 -> 578 | N18: =M18+F18 -> 578 | P18: 12 | Q18: 184 | R18: 616 | S18: 0.5
B19: 7 | C19: 8347 | D19: 540 | E19: 46762 | G19: 301138 | H19: 168873 | I19: 187492 | J19: 30873 | K19: 640730 | L19: 6900 | P19: 13 | Q19: 139 | R19: 474 | S19: 2.2
B20: Consumption | C20: =C19-C17 -> 0 | D20: =D19-D17 -> 8 | E20: =E19-E17 -> 0 | F20: =E20+D20+C20 -> 8 | G20: =G19-G17 -> 136 | H20: =H19-H17 -> 15 | I20: =I19-I17 -> 80 | J20: =J19-J17 -> 273 | K20: =K19-K17 -> 36 | L20: =L19-L17 -> 27 | M20: =L20+K20+J20+I20+H20+G20 -> 567 | N20: =M20+F20 -> 575 | P20: 14 | Q20: 150 | R20: 486 | S20: 2.2
B21: 8 | C21: 8347 | D21: 542 | E21: 46762 | G21: 301274 | H21: 168888 | I21: 187573 | J21: 31171 | K21: 640769 | L21: 6926 | P21: 15 | Q21: 127 | R21: 438 | S21: 2.8
B22: Consumption | C22: =C21-C19 -> 0 | D22: =D21-D19 -> 2 | E22: =E21-E19 -> 0 | F22: =E22+D22+C22 -> 2 | G22: =G21-G19 -> 136 | H22: =H21-H19 -> 15 | I22: =I21-I19 -> 81 | J22: =J21-J19 -> 298 | K22: =K21-K19 -> 39 | L22: =L21-L19 -> 26 | M22: =L22+K22+J22+I22+H22+G22 -> 595 | N22: =M22+F22 -> 597 | P22: 16 | Q22: 163 | R22: 590 | S22: 0.8
B23: 9 | C23: 8347 | D23: 542 | E23: 46762 | G23: 301416 | H23: 168906 | I23: 187660 | J23: 31500 | K23: 640816 | L23: 6950 | P23: 17 | Q23: 128 | R23: 476 | S23: 0.3
B24: Consumption | C24: =C23-C21 -> 0 | D24: =D23-D21 -> 0 | E24: =E23-E21 -> 0 | F24: =E24+D24+C24 -> 0 | G24: =G23-G21 -> 142 | H24: =H23-H21 -> 18 | I24: =I23-I21 -> 87 | J24: =J23-J21 -> 329 | K24: =K23-K21 -> 47 | L24: =L23-L21 -> 24 | M24: =L24+K24+J24+I24+H24+G24 -> 647 | N24: =M24+F24 -> 647 | P24: 18 | Q24: 140 | R24: 414 | S24: 0
B25: 10 | C25: 8347 | D25: 542 | E25: 46762 | G25: 301560 | H25: 168919 | I25: 187749 | J25: 31823 | K25: 640866 | L25: 6976 | P25: 19 | Q25: 213 | R25: 506 | S25: 0.3
B26: Consumption | C26: =C25-C23 -> 0 | D26: =D25-D23 -> 0 | E26: =E25-E23 -> 0 | F26: =E26+D26+C26 -> 0 | G26: =G25-G23 -> 144 | H26: =H25-H23 -> 13 | I26: =I25-I23 -> 89 | J26: =J25-J23 -> 323 | K26: =K25-K23 -> 50 | L26: =L25-L23 -> 26 | M26: =L26+K26+J26+I26+H26+G26 -> 645 | N26: =M26+F26 -> 645 | P26: 20 | Q26: 209 | R26: 494 | S26: 0.5
B27: 11 | C27: 8347 | D27: 542 | E27: 46762 | G27: 301697 | H27: 168936 | I27: 187828 | J27: 32109 | K27: 640916 | L27: 7001 | P27: 21 | Q27: 205 | R27: 542 | S27: 1.3
B28: Consumption | C28: =C27-C25 -> 0 | D28: =D27-D25 -> 0 | E28: =E27-E25 -> 0 | F28: =E28+D28+C28 -> 0 | G28: =G27-G25 -> 137 | H28: =H27-H25 -> 17 | I28: =I27-I25 -> 79 | J28: =J27-J25 -> 286 | K28: =K27-K25 -> 50 | L28: =L27-L25 -> 25 | M28: =L28+K28+J28+I28+H28+G28 -> 594 | N28: =M28+F28 -> 594 | P28: 22 | Q28: 164 | R28: 538 | S28: 1.9
B29: 12 | C29: 8347 | D29: 542 | E29: 46762 | G29: 301836 | H29: 168951 | I29: 187901 | J29: 32431 | K29: 640967 | L29: 7028 | P29: 23 | Q29: 205 | R29: 736 | S29: 2.7
B30: Consumption | C30: =C29-C27 -> 0 | D30: =D29-D27 -> 0 | E30: =E29-E27 -> 0 | F30: =E30+D30+C30 -> 0 | G30: =G29-G27 -> 139 | H30: =H29-H27 -> 15 | I30: =I29-I27 -> 73 | J30: =J29-J27 -> 322 | K30: =K29-K27 -> 51 | L30: =L29-L27 -> 27 | M30: =L30+K30+J30+I30+H30+G30 -> 627 | N30: =M30+F30 -> 627 | P30: 24 | Q30: 224 | R30: 764 | S30: 2.7
B31: 13 | C31: 8347 | D31: 542 | E31: 46762 | G31: 301973 | H31: 168966 | I31: 187983 | J31: 32744 | K31: 641016 | L31: 7053 | P31: 25 | Q31: 221 | R31: 674 | S31: 3
B32: Consumption | C32: =C31-C29 -> 0 | D32: =D31-D29 -> 0 | E32: =E31-E29 -> 0 | F32: =E32+D32+C32 -> 0 | G32: =G31-G29 -> 137 | H32: =H31-H29 -> 15 | I32: =I31-I29 -> 82 | J32: =J31-J29 -> 313 | K32: =K31-K29 -> 49 | L32: =L31-L29 -> 25 | M32: =L32+K32+J32+I32+H32+G32 -> 621 | N32: =M32+F32 -> 621 | P32: 26 | Q32: 221 | R32: 702 | S32: 3.2
B33: 14 | C33: 8347 | D33: 542 | E33: 46762 | G33: 302114 | H33: 168983 | I33: 188074 | J33: 33075 | K33: 641062 | L33: 7073 | P33: 27 | Q33: 215 | R33: 682 | S33: 3.2
B34: Consumption | C34: =C33-C31 -> 0 | D34: =D33-D31 -> 0 | E34: =E33-E31 -> 0 | F34: =E34+D34+C34 -> 0 | G34: =G33-G31 -> 141 | H34: =H33-H31 -> 17 | I34: =I33-I31 -> 91 | J34: =J33-J31 -> 331 | K34: =K33-K31 -> 46 | L34: =L33-L31 -> 20 | M34: =L34+K34+J34+I34+H34+G34 -> 646 | N34: =M34+F34 -> 646 | P34: 28 | Q34: 217 | R34: 672 | S34: 3.5
B35: 15 | C35: 8359 | D35: 542 | E35: 46762 | G35: 302260 | H35: 168998 | I35: 188173 | J35: 33408 | K35: 641109 | L35: 7108
B36: Consumption | C36: =C35-C33 -> 12 | D36: =D35-D33 -> 0 | E36: =E35-E33 -> 0 | F36: =E36+D36+C36 -> 12 | G36: =G35-G33 -> 146 | H36: =H35-H33 -> 15 | I36: =I35-I33 -> 99 | J36: =J35-J33 -> 333 | K36: =K35-K33 -> 47 | L36: =L35-L33 -> 35 | M36: =L36+K36+J36+I36+H36+G36 -> 675 | N36: =M36+F36 -> 687
B37: 16 | C37: 8359 | D37: 542 | E37: 46762 | G37: 302390 | H37: 169014 | I37: 188173 | J37: 33781 | K37: 641159 | L37: 7142
B38: Consumption | C38: =C37-C35 -> 0 | D38: =D37-D35 -> 0 | E38: =E37-E35 -> 0 | F38: =E38+D38+C38 -> 0 | G38: =G37-G35 -> 130 | H38: =H37-H35 -> 16 | I38: =I37-I35 -> 0 | J38: =J37-J35 -> 373 | K38: =K37-K35 -> 50 | L38: =L37-L35 -> 34 | M38: =L38+K38+J38+I38+H38+G38 -> 603 | N38: =M38+F38 -> 603
B39: 17 | C39: 8359 | D39: 542 | E39: 46762 | G39: 302526 | H39: 169029 | I39: 188339 | J39: 34111 | K39: 641215 | L39: 7159
B40: Consumption | C40: =C39-C37 -> 0 | D40: =D39-D37 -> 0 | E40: =E39-E37 -> 0 | F40: =E40+D40+C40 -> 0 | G40: =G39-G37 -> 136 | H40: =H39-H37 -> 15 | I40: =I39-I37 -> 166 | J40: =J39-J37 -> 330 | K40: =K39-K37 -> 56 | L40: =L39-L37 -> 17 | M40: =L40+K40+J40+I40+H40+G40 -> 720 | N40: =M40+F40 -> 720
B41: 18 | C41: 8359 | D41: 542 | E41: 46762 | G41: 302671 | H41: 169044 | I41: 188429 | J41: 34439 | K41: 641260 | L41: 7183
B42: Consumption | C42: =C41-C39 -> 0 | D42: =D41-D39 -> 0 | E42: =E41-E39 -> 0 | F42: =E42+D42+C42 -> 0 | G42: =G41-G39 -> 145 | H42: =H41-H39 -> 15 | I42: =I41-I39 -> 90 | J42: =J41-J39 -> 328 | K42: =K41-K39 -> 45 | L42: =L41-L39 -> 24 | M42: =L42+K42+J42+I42+H42+G42 -> 647 | N42: =M42+F42 -> 647
...

Sheet LPG
D2: Central Plant Engineering
D3: Daily LPG Meter Readings
D4: Month: FEBRUARY 2023
B5: Date | C5: COMMON LPG READING/M3 | D5: NOBU/M3 | E5: LPG Total
C6: HOTEL+NOBU
B7: 1 | C7: 337246 | D7: 2386
B8: Consumption | C8: =C7-336708 -> 538 | D8: =D7-2366 -> 20 | E8: =C8 -> 538
B9: 2 | C9: 337755 | D9: 2406
B10: Consumption | C10: =C9-C7 -> 509 | D10: =D9-D7 -> 20 | E10: =C10 -> 509
B11: 3 | C11: 338313 | D11: 2433
B12: Consumption | C12: =C11-C9 -> 558 | D12: =D11-D9 -> 27 | E12: =C12 -> 558
B13: 4 | C13: 338864 | D13: 2451
B14: Consumption | C14: =C13-C11 -> 551 | D14: =D13-D11 -> 18 | E14: =C14 -> 551
B15: 5 | C15: 339378 | D15: 2456
B16: Consumption | C16: =C15-C13 -> 514 | D16: =D15-D13 -> 5 | E16: =C16 -> 514
B17: 6 | C17: 339883 | D17: 2475
B18: Consumption | C18: =C17-C15 -> 505 | D18: =D17-D15 -> 19 | E18: =C18 -> 505
B19: 7 | C19: 340468 | D19: 2495
B20: Consumption | C20: =C19-C17 -> 585 | D20: =D19-D17 -> 20 | E20: =C20 -> 585
B21: 8 | C21: 340988 | D21: 2514
B22: Consumption | C22: =C21-C19 -> 520 | D22: =D21-D19 -> 19 | E22: =C22 -> 520
B23: 9 | C23: 341632 | D23: 2535
B24: Consumption | C24: =C23-C21 -> 644 | D24: =D23-D21 -> 21 | E24: =C24 -> 644
B25: 10 | C25: 342258 | D25: 2566
B26: Consumption | C26: =C25-C23 -> 626 | D26: =D25-D23 -> 31 | E26: =C26 -> 626
B27: 11 | C27: 342781 | D27: 2586
B28: Consumption | C28: =C27-C25 -> 523 | D28: =D27-D25 -> 20 | E28: =C28 -> 523
B29: 12 | C29: 343383 | D29: 2588
B30: Consumption | C30: =C29-C27 -> 602 | D30: =D29-D27 -> 2 | E30: =C30 -> 602
B31: 13 | C31: 343965 | D31: 2609
B32: Consumption | C32: =C31-C29 -> 582 | D32: =D31-D29 -> 21 | E32: =C32 -> 582
B33: 14 | C33: 344452 | D33: 2634
B34: Consumption | C34: =C33-C31 -> 487 | D34: =D33-D31 -> 25 | E34: =C34 -> 487
B35: 15 | C35: 345128 | D35: 2657
B36: Consumption | C36: =C35-C33 -> 676 | D36: =D35-D33 -> 23 | E36: =C36 -> 676
B37: 16 | C37: 345729 | D37: 2677
B38: Consumption | C38: =C37-C35 -> 601 | D38: =D37-D35 -> 20 | E38: =C38 -> 601
B39: 17 | C39: 346354 | D39: 2706
B40: Consumption | C40: =C39-C37 -> 625 | D40: =D39-D37 -> 29 | E40: =C40 -> 625
B41: 18 | C41: 346953 | D41: 2730
...
