Workbook

Sheet TOTAL
A1: Site Name | B1: Day | C1: Month | D1: Year | E1: Total Electricity Kwh | F1: Electricity Tariff ($/Kwh) | G1: Total Fuel Oil (Liter) | H1: Fuel Oil $/Liter | I1: LPG (Kg) | J1: LPG $/Kg | K1: Water Utility Supply (m3) m3 | L1: Water Utility Supply (m3) $/m3 | M1: Room Night | N1: Food Cover
A2: Langkawi | B2: 1 | C2: 2 | D2: 2023 | E2: ='B16'!L4+'B16 ext'!L4+'B17'!L4 -> 18496 | F2: =('B16'!J4+'B16 ext'!J4+'B17'!J4)/TOTAL!E2 -> 0.24903357 | G2: ='Diesel Reading '!H4 -> 297.7 | H2: ='Diesel Reading '!I4/'Diesel Reading '!H4 -> 2.84 | I2: 161.78 | J2: 6.76 | K2: ='Water Reading'!L4 -> 12 | L2: ='Water Reading'!I4/'Water Reading'!H4 -> 1.35 | M2: 54
A3: Langkawi | B3: =B2+1 -> 2 | C3: 2 | D3: 2023 | E3: ='B16'!L5+'B16 ext'!L5+'B17'!L5 -> 16981 | F3: =('B16'!J5+'B16 ext'!J5+'B17'!J5)/TOTAL!E3 -> 0.25395024 | G3: ='Diesel Reading '!H5 -> 246.8 | H3: ='Diesel Reading '!I5/'Diesel Reading '!H5 -> 2.84 | I3: 161.78 | J3: 6.76 | K3: ='Water Reading'!L5 -> 21 | L3: ='Water Reading'!I5/'Water Reading'!H5 -> 1.35 | M3: 55
A4: Langkawi | B4: =B3+1 -> 3 | C4: 2 | D4: 2023 | E4: ='B16'!L6+'B16 ext'!L6+'B17'!L6 -> 19372 | F4: =('B16'!J6+'B16 ext'!J6+'B17'!J6)/TOTAL!E4 -> 0.25273808 | G4: ='Diesel Reading '!H6 -> 297.1 | H4: ='Diesel Reading '!I6/'Diesel Reading '!H6 -> 2.84 | I4: 161.78 | J4: 6.76 | K4: ='Water Reading'!L6 -> 25 | L4: ='Water Reading'!I6/'Water Reading'!H6 -> 1.35 | M4: 66
A5: Langkawi | B5: =B4+1 -> 4 | C5: 2 | D5: 2023 | E5: ='B16'!L7+'B16 ext'!L7+'B17'!L7 -> 19613 | F5: =('B16'!J7+'B16 ext'!J7+'B17'!J7)/TOTAL!E5 -> 0.24966247 | G5: ='Diesel Reading '!H7 -> 278.8 | H5: ='Diesel Reading '!I7/'Diesel Reading '!H7 -> 2.84 | I5: 161.78 | J5: 6.76 | K5: ='Water Reading'!L7 -> 32 | L5: ='Water Reading'!I7/'Water Reading'!H7 -> 1.35 | M5: 68
A6: Langkawi | B6: =B5+1 -> 5 | C6: 2 | D6: 2023 | E6: ='B16'!L8+'B16 ext'!L8+'B17'!L8 -> 19699 | F6: =('B16'!J8+'B16 ext'!J8+'B17'!J8)/TOTAL!E6 -> 0.24693918 | G6: ='Diesel Reading '!H8 -> 259 | H6: ='Diesel Reading '!I8/'Diesel Reading '!H8 -> 2.84 | I6: 161.78 | J6: 6.76 | K6: ='Water Reading'!L8 -> 29 | L6: ='Water Reading'!I8/'Water Reading'!H8 -> 1.35 | M6: 51
A7: Langkawi | B7: =B6+1 -> 6 | C7: 2 | D7: 2023 | E7: ='B16'!L9+'B16 ext'!L9+'B17'!L9 -> 19251 | F7: =('B16'!J9+'B16 ext'!J9+'B17'!J9)/TOTAL!E7 -> 0.25043494 | G7: ='Diesel Reading '!H10 -> 379.6 | H7: ='Diesel Reading '!I10/'Diesel Reading '!H10 -> 2.84 | I7: 161.78 | J7: 6.76 | K7: ='Water Reading'!L9 -> 37 | L7: ='Water Reading'!I9/'Water Reading'!H9 -> 1.35 | M7: 38
A8: Langkawi | B8: =B7+1 -> 7 | C8: 2 | D8: 2023 | E8: ='B16'!L10+'B16 ext'!L10+'B17'!L10 -> 23440 | F8: =('B16'!J10+'B16 ext'!J10+'B17'!J10)/TOTAL!E8 -> 0.23638784 | G8: ='Diesel Reading '!H11 -> 386 | H8: ='Diesel Reading '!I11/'Diesel Reading '!H11 -> 2.84 | I8: 161.78 | J8: 6.76 | K8: ='Water Reading'!L10 -> 41 | L8: ='Water Reading'!I10/'Water Reading'!H10 -> 1.35 | M8: 35
A9: Langkawi | B9: =B8+1 -> 8 | C9: 2 | D9: 2023 | E9: ='B16'!L11+'B16 ext'!L11+'B17'!L11 -> 18471 | F9: =('B16'!J11+'B16 ext'!J11+'B17'!J11)/TOTAL!E9 -> 0.25185334 | G9: ='Diesel Reading '!H12 -> 412.4 | H9: ='Diesel Reading '!I12/'Diesel Reading '!H12 -> 2.84 | I9: 161.78 | J9: 6.76 | K9: ='Water Reading'!L11 -> 37 | L9: ='Water Reading'!I11/'Water Reading'!H11 -> 1.35 | M9: 37
A10: Langkawi | B10: =B9+1 -> 9 | C10: 2 | D10: 2023 | E10: ='B16'!L12+'B16 ext'!L12+'B17'!L12 -> 16052 | F10: =('B16'!J12+'B16 ext'!J12+'B17'!J12)/TOTAL!E10 -> 0.26780812 | G10: ='Diesel Reading '!H13 -> 398.2 | H10: ='Diesel Reading '!I13/'Diesel Reading '!H13 -> 2.84 | I10: 161.78 | J10: 6.76 | K10: ='Water Reading'!L12 -> 28 | L10: ='Water Reading'!I12/'Water Reading'!H12 -> 1.35 | M10: 38
A11: Langkawi | B11: =B10+1 -> 10 | C11: 2 | D11: 2023 | E11: ='B16'!L13+'B16 ext'!L13+'B17'!L13 -> 20948 | F11: =('B16'!J13+'B16 ext'!J13+'B17'!J13)/TOTAL!E11 -> 0.24899527 | G11: ='Diesel Reading '!H14 -> 360.6 | H11: ='Diesel Reading '!I14/'Diesel Reading '!H14 -> 2.84 | I11: 161.78 | J11: 6.76 | K11: ='Water Reading'!L13 -> 21 | L11: ='Water Reading'!I13/'Water Reading'!H13 -> 1.35 | M11: 46
A12: Langkawi | B12: =B11+1 -> 11 | C12: 2 | D12: 2023 | E12: ='B16'!L14+'B16 ext'!L14+'B17'!L14 -> 18081 | F12: =('B16'!J14+'B16 ext'!J14+'B17'!J14)/TOTAL!E12 -> 0.24578795 | G12: ='Diesel Reading '!H15 -> 380.6 | H12: ='Diesel Reading '!I15/'Diesel Reading '!H15 -> 2.84 | I12: 161.78 | J12: 6.76 | K12: ='Water Reading'!L14 -> 47 | L12: ='Water Reading'!I14/'Water Reading'!H14 -> 1.35 | M12: 46
A13: Langkawi | B13: =B12+1 -> 12 | C13: 2 | D13: 2023 | E13: ='B16'!L15+'B16 ext'!L15+'B17'!L15 -> 25897 | F13: =('B16'!J15+'B16 ext'!J15+'B17'!J15)/TOTAL!E13 -> 0.24287477 | G13: ='Diesel Reading '!H16 -> 413.1 | H13: ='Diesel Reading '!I16/'Diesel Reading '!H16 -> 2.84 | I13: 161.78 | J13: 6.76 | K13: ='Water Reading'!L15 -> 8 | L13: ='Water Reading'!I15/'Water Reading'!H15 -> 1.35 | M13: 47
A14: Langkawi | B14: =B13+1 -> 13 | C14: 2 | D14: 2023 | E14: ='B16'!L16+'B16 ext'!L16+'B17'!L16 -> 20239 | F14: =('B16'!J16+'B16 ext'!J16+'B17'!J16)/TOTAL!E14 -> 0.25060695 | G14: ='Diesel Reading '!H17 -> 503.9 | H14: ='Diesel Reading '!I17/'Diesel Reading '!H17 -> 2.84 | I14: 161.78 | J14: 6.76 | K14: ='Water Reading'!L16 -> 20 | L14: ='Water Reading'!I16/'Water Reading'!H16 -> 1.35 | M14: 48
A15: Langkawi | B15: =B14+1 -> 14 | C15: 2 | D15: 2023 | E15: ='B16'!L17+'B16 ext'!L17+'B17'!L17 -> 20796 | F15: =('B16'!J17+'B16 ext'!J17+'B17'!J17)/TOTAL!E15 -> 0.24844331 | G15: ='Diesel Reading '!H18 -> 437.5 | H15: ='Diesel Reading '!I18/'Diesel Reading '!H18 -> 2.84 | I15: 161.78 | J15: 6.76 | K15: ='Water Reading'!L17 -> 23 | L15: ='Water Reading'!I17/'Water Reading'!H17 -> 1.35 | M15: 46
A16: Langkawi | B16: =B15+1 -> 15 | C16: 2 | D16: 2023 | E16: ='B16'!L18+'B16 ext'!L18+'B17'!L18 -> 19487 | F16: =('B16'!J18+'B16 ext'!J18+'B17'!J18)/TOTAL!E16 -> 0.24989306 | G16: ='Diesel Reading '!H19 -> 420.2 | H16: ='Diesel Reading '!I19/'Diesel Reading '!H19 -> 2.84 | I16: 161.78 | J16: 6.76 | K16: ='Water Reading'!L18 -> 137 | L16: ='Water Reading'!I18/'Water Reading'!H18 -> 1.35 | M16: 49
A17: Langkawi | B17: =B16+1 -> 16 | C17: 2 | D17: 2023 | E17: ='B16'!L19+'B16 ext'!L19+'B17'!L19 -> 16999 | F17: =('B16'!J19+'B16 ext'!J19+'B17'!J19)/TOTAL!E17 -> 0.26835184 | G17: ='Diesel Reading '!H20 -> 499.8 | H17: ='Diesel Reading '!I20/'Diesel Reading '!H20 -> 2.84 | I17: 161.78 | J17: 6.76 | K17: ='Water Reading'!L19 -> 96 | L17: ='Water Reading'!I19/'Water Reading'!H19 -> 1.35 | M17: 53
A18: Langkawi | B18: =B17+1 -> 17 | C18: 2 | D18: 2023 | E18: ='B16'!L20+'B16 ext'!L20+'B17'!L20 -> 21664 | F18: =('B16'!J20+'B16 ext'!J20+'B17'!J20)/TOTAL!E18 -> 0.24840399 | G18: ='Diesel Reading '!H21 -> 543.8 | H18: ='Diesel Reading '!I21/'Diesel Reading '!H21 -> 2.84 | I18: 161.78 | J18: 6.76 | K18: ='Water Reading'!L20 -> 75 | L18: ='Water Reading'!I20/'Water Reading'!H20 -> 1.35 | M18: 73
A19: Langkawi | B19: =B18+1 -> 18 | C19: 2 | D19: 2023 | E19: ='B16'!L21+'B16 ext'!L21+'B17'!L21 -> 21187 | F19: =('B16'!J21+'B16 ext'!J21+'B17'!J21)/TOTAL!E19 -> 0.24686813 | G19: ='Diesel Reading '!H22 -> 445 | H19: ='Diesel Reading '!I22/'Diesel Reading '!H22 -> 2.84 | I19: 161.78 | J19: 6.76 | K19: ='Water Reading'!L21 -> 0 | L19: 1.35 | M19: 74
A20: Langkawi | B20: =B19+1 -> 19 | C20: 2 | D20: 2023 | E20: ='B16'!L22+'B16 ext'!L22+'B17'!L22 -> 19272 | F20: =('B16'!J22+'B16 ext'!J22+'B17'!J22)/TOTAL!E20 -> 0.25627008 | G20: ='Diesel Reading '!H23 -> 487.5 | H20: ='Diesel Reading '!I23/'Diesel Reading '!H23 -> 2.84 | I20: 161.78 | J20: 6.76 | K20: ='Water Reading'!L22 -> 27 | L20: ='Water Reading'!I22/'Water Reading'!H22 -> 1.35 | M20: 52
A21: Langkawi | B21: =B20+1 -> 20 | C21: 2 | D21: 2023 | E21: ='B16'!L23+'B16 ext'!L23+'B17'!L23 -> 20686 | F21: =('B16'!J23+'B16 ext'!J23+'B17'!J23)/TOTAL!E21 -> 0.25049739 | G21: ='Diesel Reading '!H24 -> 465.1 | H21: ='Diesel Reading '!I24/'Diesel Reading '!H24 -> 2.84 | I21: 161.78 | J21: 6.76 | K21: ='Water Reading'!L23 -> 21 | L21: ='Water Reading'!I23/'Water Reading'!H23 -> 1.35 | M21: 51
A22: Langkawi | B22: =B21+1 -> 21 | C22: 2 | D22: 2023 | E22: ='B16'!L24+'B16 ext'!L24+'B17'!L24 -> 20538 | F22: =('B16'!J24+'B16 ext'!J24+'B17'!J24)/TOTAL!E22 -> 0.25066491 | G22: ='Diesel Reading '!H25 -> 450.5 | H22: ='Diesel Reading '!I25/'Diesel Reading '!H25 -> 2.84 | I22: 161.78 | J22: 6.76 | K22: ='Water Reading'!L24 -> 21 | L22: ='Water Reading'!I24/'Water Reading'!H24 -> 1.35 | M22: 56
A23: Langkawi | B23: =B22+1 -> 22 | C23: 2 | D23: 2023 | E23: ='B16'!L25+'B16 ext'!L25+'B17'!L25 -> 24036 | F23: =('B16'!J25+'B16 ext'!J25+'B17'!J25)/TOTAL!E23 -> 0.23717349 | G23: ='Diesel Reading '!H26 -> 407.4 | H23: ='Diesel Reading '!I26/'Diesel Reading '!H26 -> 2.84 | I23: 161.78 | J23: 6.76 | K23: ='Water Reading'!L25 -> 26 | L23: ='Water Reading'!I25/'Water Reading'!H25 -> 1.35 | M23: 53
A24: Langkawi | B24: =B23+1 -> 23 | C24: 2 | D24: 2023 | E24: ='B16'!L26+'B16 ext'!L26+'B17'!L26 -> 16293 | F24: =('B16'!J26+'B16 ext'!J26+'B17'!J26)/TOTAL!E24 -> 0.2710499 | G24: ='Diesel Reading '!H27 -> 405.7 | H24: ='Diesel Reading '!I27/'Diesel Reading '!H27 -> 2.84 | I24: 161.78 | J24: 6.76 | K24: ='Water Reading'!L26 -> 33 | L24: ='Water Reading'!I26/'Water Reading'!H26 -> 1.35 | M24: 45
A25: Langkawi | B25: =B24+1 -> 24 | C25: 2 | D25: 2023 | E25: ='B16'!L27+'B16 ext'!L27+'B17'!L27 -> 20695 | F25: =('B16'!J27+'B16 ext'!J27+'B17'!J27)/TOTAL!E25 -> 0.24636226 | G25: ='Diesel Reading '!H28 -> 445.1 | H25: ='Diesel Reading '!I28/'Diesel Reading '!H28 -> 2.84 | I25: 161.78 | J25: 6.76 | K25: ='Water Reading'!L27 -> 30 | L25: ='Water Reading'!I27/'Water Reading'!H27 -> 1.35 | M25: 51
A26: Langkawi | B26: =B25+1 -> 25 | C26: 2 | D26: 2023 | E26: ='B16'!L28+'B16 ext'!L28+'B17'!L28 -> 19017 | F26: =('B16'!J28+'B16 ext'!J28+'B17'!J28)/TOTAL!E26 -> 0.25162455 | G26: ='Diesel Reading '!H29 -> 375.3 | H26: ='Diesel Reading '!I29/'Diesel Reading '!H29 -> 2.84 | I26: 161.78 | J26: 6.76 | K26: ='Water Reading'!L28 -> 20 | L26: ='Water Reading'!I28/'Water Reading'!H28 -> 1.35 | M26: 53
A27: Langkawi | B27: =B26+1 -> 26 | C27: 2 | D27: 2023 | E27: ='B16'!L29+'B16 ext'!L29+'B17'!L29 -> 19481 | F27: =('B16'!J29+'B16 ext'!J29+'B17'!J29)/TOTAL!E27 -> 0.25141404 | G27: ='Diesel Reading '!H30 -> 390.8 | H27: ='Diesel Reading '!I30/'Diesel Reading '!H30 -> 2.84 | I27: 161.78 | J27: 6.76 | K27: ='Water Reading'!L29 -> 28 | L27: ='Water Reading'!I29/'Water Reading'!H29 -> 1.35 | M27: 33
A28: Langkawi | B28: =B27+1 -> 27 | C28: 2 | D28: 2023 | E28: ='B16'!L30+'B16 ext'!L30+'B17'!L30 -> 19690 | F28: =('B16'!J30+'B16 ext'!J30+'B17'!J30)/TOTAL!E28 -> 0.24789005 | G28: ='Diesel Reading '!H31 -> 390.1 | H28: ='Diesel Reading '!I31/'Diesel Reading '!H31 -> 2.84 | I28: 161.78 | J28: 6.76 | K28: ='Water Reading'!L30 -> 24 | L28: ='Water Reading'!I30/'Water Reading'!H30 -> 1.35 | M28: 39
A29: Langkawi | B29: =B28+1 -> 28 | C29: 2 | D29: 2023 | E29: ='B16'!L31+'B16 ext'!L31+'B17'!L31 -> 10715 | F29: 0.25 | G29: 380 | H29: 2.84 | I29: 161.78 | J29: 6.76 | K29: ='Water Reading'!L31 -> 29 | L29: 1.35 | M29: 42

Sheet B16
A1: Daily Electricity Consumption
B2: Meter Reading (kWh) | C2: Consumption (kWh) | D2: Meter Reading (kWh) | E2: Consumption (kWh) | F2: MD (kW) | G2: Occupancy | H2: Weather | I2: Total Consumption | J2: Cost
B3: (Peak) | C3: (Peak) | D3: (Off Peak) | E3: (Off Peak) | F3: (Peak) | G3: % | I3: Daily (KWh) | J3: Daily (RM)
A4: 44958 | B4: 5441 | C4: =IF(B5-B4 < 0,0,B5-B4) -> 5639 | D4: 2952 | E4: =IF(D5-D4 < 0,0,D5-D4) -> 3120 | F4: 446 | G4: 0.59 | H4: Fair | I4: =+E4+C4 -> 8759 | J4: =(C4*0.288)+(E4*0.177) -> 2176.272 | L4: =C4+E4 -> 8759
A5: 44959 | B5: 11080 | C5: =IF(B6-B5 < 0,0,B6-B5) -> 5403 | D5: 6072 | E5: =IF(D6-D5 < 0,0,D6-D5) -> 2577 | F5: 458 | G5: 0.6 | H5: Fair | I5: =+E5+C5 -> 7980 | J5: =(C5*0.288)+(E5*0.177) -> 2012.193 | L5: =C5+E5 -> 7980
A6: 44960 | B6: 16483 | C6: =IF(B7-B6 < 0,0,B7-B6) -> 6059 | D6: 8649 | E6: =IF(D7-D6 < 0,0,D7-D6) -> 3000 | F6: 458 | G6: 0.72 | H6: Isolate Rain | I6: =+E6+C6 -> 9059 | J6: =(C6*0.288)+(E6*0.177) -> 2275.992 | L6: =C6+E6 -> 9059
A7: 44961 | B7: 22542 | C7: =IF(B8-B7 < 0,0,B8-B7) -> 5782 | D7: 11649 | E7: =IF(D8-D7 < 0,0,D8-D7) -> 3297 | F7: 526 | G7: 0.74 | H7: Fair | I7: =+E7+C7 -> 9079 | J7: =(C7*0.288)+(E7*0.177) -> 2248.785 | L7: =C7+E7 -> 9079
A8: 44962 | B8: 28324 | C8: =IF(B9-B8 < 0,0,B9-B8) -> 5438 | D8: 14946 | E8: =IF(D9-D8 < 0,0,D9-D8) -> 3401 | F8: 526 | G8: 0.55 | H8: Fair | I8: =+E8+C8 -> 8839 | J8: =(C8*0.288)+(E8*0.177) -> 2168.121 | L8: =C8+E8 -> 8839
A9: 44963 | B9: 33762 | C9: =IF(B10-B9 < 0,0,B10-B9) -> 5803 | D9: 18347 | E9: =IF(D10-D9 < 0,0,D10-D9) -> 3100 | F9: 526 | G9: 0.41 | H9: Fair | I9: =+E9+C9 -> 8903 | J9: =(C9*0.288)+(E9*0.177) -> 2219.964 | L9: =C9+E9 -> 8903
A10: 44964 | B10: 39565 | C10: =IF(B11-B10 < 0,0,B11-B10) -> 5749 | D10: 21447 | E10: =IF(D11-D10 < 0,0,D11-D10) -> 5903 | F10: 526 | G10: 0.38 | H10: Fair | I10: =+E10+C10 -> 11652 | J10: =(C10*0.288)+(E10*0.177) -> 2700.543 | L10: =C10+E10 -> 11652
A11: 44965 | B11: 45314 | C11: =IF(B12-B11 < 0,0,B12-B11) -> 5673 | D11: 27350 | E11: =IF(D12-D11 < 0,0,D12-D11) -> 2909 | F11: 526 | G11: 0.4 | H11: Fair | I11: =+E11+C11 -> 8582 | J11: =(C11*0.288)+(E11*0.177) -> 2148.717 | L11: =C11+E11 -> 8582
A12: 44966 | B12: 50987 | C12: =IF(B13-B12 < 0,0,B13-B12) -> 5565 | D12: 30259 | E12: =IF(D13-D12 < 0,0,D13-D12) -> 504 | F12: 526 | G12: 0.41 | H12: Fair | I12: =+E12+C12 -> 6069 | J12: =(C12*0.288)+(E12*0.177) -> 1691.928 | L12: =C12+E12 -> 6069
A13: 44967 | B13: 56552 | C13: =IF(B14-B13 < 0,0,B14-B13) -> 5824 | D13: 30763 | E13: =IF(D14-D13 < 0,0,D14-D13) -> 3141 | F13: 526 | G13: 0.5 | H13: Fair | I13: =+E13+C13 -> 8965 | J13: =(C13*0.288)+(E13*0.177) -> 2233.269 | L13: =C13+E13 -> 8965
A14: 44968 | B14: 62376 | C14: =IF(B15-B14 < 0,0,B15-B14) -> 3792 | D14: 33904 | E14: =IF(D15-D14 < 0,0,D15-D14) -> 3097 | F14: 526 | G14: 0.5 | H14: Fair | I14: =+E14+C14 -> 6889 | J14: =(C14*0.288)+(E14*0.177) -> 1640.265 | L14: =C14+E14 -> 6889
A15: 44969 | B15: 66168 | C15: =IF(B16-B15 < 0,0,B16-B15) -> 7942 | D15: 37001 | E15: =IF(D16-D15 < 0,0,D16-D15) -> 5930 | F15: 526 | G15: 0.51 | H15: Fair | I15: =+E15+C15 -> 13872 | J15: =(C15*0.288)+(E15*0.177) -> 3336.906 | L15: =C15+E15 -> 13872
... A24: 44978 | B24: 122490 | C24: =IF(B25-B24 < 0,0,B25-B24) -> 5922 | D24: 67034 | E24: =IF(D25-D24 < 0,0,D25-D24) -> 3054 | F24: 564 | G24: 0.61 | H24: Fair | I24: =+E24+C24 -> 8976 | J24: =(C24*0.288)+(E24*0.177) -> 2246.094 | L24: =C24+E24 -> 8976
A25: 44979 | B25: 128412 | C25: =IF(B26-B25 < 0,0,B26-B25) -> 5788 | D25: 70088 | E25: =IF(D26-D25 < 0,0,D26-D25) -> 5861 | F25: 564 | G25: 0.58 | H25: Fair | I25: =+E25+C25 -> 11649 | J25: =(C25*0.288)+(E25*0.177) -> 2704.341 | L25: =C25+E25 -> 11649 | P25: 2188
A26: 44980 | B26: 134200 | C26: =IF(B27-B26 < 0,0,B27-B26) -> 6184 | D26: 75949 | E26: =IF(D27-D26 < 0,0,D27-D26) -> 236 | F26: 570 | G26: 0.49 | H26: Fair | I26: =+E26+C26 -> 6420 | J26: =(C26*0.288)+(E26*0.177) -> 1822.764 | L26: =C26+E26 -> 6420
A27: 44981 | B27: 140384 | C27: =IF(B28-B27 < 0,0,B28-B27) -> 5667 | D27: 76185 | E27: =IF(D28-D27 < 0,0,D28-D27) -> 3530 | F27: 564 | G27: 0.55 | H27: Fair | I27: =+E27+C27 -> 9197 | J27: =(C27*0.288)+(E27*0.177) -> 2256.906 | L27: =C27+E27 -> 9197
A28: 44982 | B28: 146051 | C28: =IF(B29-B28 < 0,0,B29-B28) -> 5619 | D28: 79715 | E28: =IF(D29-D28 < 0,0,D29-D28) -> 3047 | F28: 564 | G28: 0.58 | H28: Fair | I28: =+E28+C28 -> 8666 | J28: =(C28*0.288)+(E28*0.177) -> 2157.591 | L28: =C28+E28 -> 8666
A29: 44983 | B29: 151670 | C29: =IF(B30-B29 < 0,0,B30-B29) -> 5757 | D29: 82762 | E29: =IF(D30-D29 < 0,0,D30-D29) -> 2904 | F29: 564 | G29: 0.36 | H29: Fair | I29: =+E29+C29 -> 8661 | J29: =(C29*0.288)+(E29*0.177) -> 2172.024 | L29: =C29+E29 -> 8661
A30: 44984 | B30: 157427 | C30: =IF(B31-B30 < 0,0,B31-B30) -> 5509 | D30: 85666 | E30: =IF(D31-D30 < 0,0,D31-D30) -> 3299 | F30: 564 | G30: 0.42 | H30: Fair | I30: =+E30+C30 -> 8808 | J30: =(C30*0.288)+(E30*0.177) -> 2170.515 | L30: =C30+E30 -> 8808
A31: 44985 | B31: 162936 | C31: 3133 | D31: 88965 | E31: 2188 | F31: 564 | G31: 0.46 | H31: Fair | I31: =+E31+C31 -> 5321 | J31: =(C31*0.288)+(E31*0.177) -> 1289.58 | L31: =C31+E31 -> 5321
A32: Total | C32: =SUM(C4:C31) -> 160628 | E32: =SUM(E4:E31) -> 88201 | F32: =MAX(F4:F31) -> 570 | I32: =+E32+C32 -> 248829 | J32: =(C32*0.288)+(E32*0.177) -> 61872.441
A33: =COUNT(A4:A31) -> 28 | C33: =COUNTIF(C4:C31,">0") -> 28
A35: PLEASE MAKE SURE TO KEY IN THE OCCUPANCY AND WEATHER FOR THE DAY!

Sheet B16 ext
A1: Daily Electricity Consumption
B2: Meter Reading (kWh) | C2: Consumption (kWh) | D2: Meter Reading (kWh) | E2: Consumption (kWh) | F2: MD (kW) | G2: Occupancy | H2: Weather | I2: Total Consumption | J2: Cost
B3: (Peak) | C3: (Peak) | D3: (Off Peak) | E3: (Off Peak) | F3: (Peak) | G3: % | I3: Daily (KWh) | J3: Daily (RM)
A4: 44958 | B4: 2500 | C4: =IF(B5-B4 < 0,0,B5-B4) -> 2355 | D4: 817 | E4: =IF(D5-D4 < 0,0,D5-D4) -> 887 | F4: 228 | G4: 0.59 | H4: Fair | I4: =+E4+C4 -> 3242 | J4: =(C4*0.288)+(E4*0.177) -> 835.239 | L4: =C4+E4 -> 3242
A5: 44959 | B5: 4855 | C5: =IF(B6-B5 < 0,0,B6-B5) -> 2390 | D5: 1704 | E5: =IF(D6-D5 < 0,0,D6-D5) -> 623 | F5: 228 | G5: 0.6 | H5: Fair | I5: =+E5+C5 -> 3013 | J5: =(C5*0.288)+(E5*0.177) -> 798.591 | L5: =C5+E5 -> 3013
A6: 44960 | B6: 7245 | C6: =IF(B7-B6 < 0,0,B7-B6) -> 2521 | D6: 2327 | E6: =IF(D7-D6 < 0,0,D7-D6) -> 769 | F6: 228 | G6: 0.72 | H6: Isolate Rain | I6: =+E6+C6 -> 3290 | J6: =(C6*0.288)+(E6*0.177) -> 862.161 | L6: =C6+E6 -> 3290
A7: 44961 | B7: 9766 | C7: =IF(B8-B7 < 0,0,B8-B7) -> 2390 | D7: 3096 | E7: =IF(D8-D7 < 0,0,D8-D7) -> 762 | F7: 228 | G7: 0.74 | H7: Fair | I7: =+E7+C7 -> 3152 | J7: =(C7*0.288)+(E7*0.177) -> 823.194 | L7: =C7+E7 -> 3152
A8: 44962 | B8: 12156 | C8: =IF(B9-B8 < 0,0,B9-B8) -> 2294 | D8: 3858 | E8: =IF(D9-D8 < 0,0,D9-D8) -> 889 | F8: 228 | G8: 0.55 | H8: Fair | I8: =+E8+C8 -> 3183 | J8: =(C8*0.288)+(E8*0.177) -> 818.025 | L8: =C8+E8 -> 3183
A9: 44963 | B9: 14450 | C9: =IF(B10-B9 < 0,0,B10-B9) -> 2334 | D9: 4747 | E9: =IF(D10-D9 < 0,0,D10-D9) -> 780 | F9: 228 | G9: 0.41 | H9: Fair | I9: =+E9+C9 -> 3114 | J9: =(C9*0.288)+(E9*0.177) -> 810.252 | L9: =C9+E9 -> 3114
A10: 44964 | B10: 16784 | C10: =IF(B11-B10 < 0,0,B11-B10) -> 2373 | D10: 5527 | E10: =IF(D11-D10 < 0,0,D11-D10) -> 1489 | F10: 228 | G10: 0.38 | H10: Fair | I10: =+E10+C10 -> 3862 | J10: =(C10*0.288)+(E10*0.177) -> 946.977 | L10: =C10+E10 -> 3862
A11: 44965 | B11: 19157 | C11: =IF(B12-B11 < 0,0,B12-B11) -> 2354 | D11: 7016 | E11: =IF(D12-D11 < 0,0,D12-D11) -> 785 | F11: 228 | G11: 0.4 | H11: Fair | I11: =+E11+C11 -> 3139 | J11: =(C11*0.288)+(E11*0.177) -> 816.897 | L11: =C11+E11 -> 3139
A12: 44966 | B12: 21511 | C12: =IF(B13-B12 < 0,0,B13-B12) -> 2409 | D12: 7801 | E12: =IF(D13-D12 < 0,0,D13-D12) -> 118 | F12: 228 | G12: 0.41 | H12: Fair | I12: =+E12+C12 -> 2527 | J12: =(C12*0.288)+(E12*0.177) -> 714.678 | L12: =C12+E12 -> 2527
A13: 44967 | B13: 23920 | C13: =IF(B14-B13 < 0,0,B14-B13) -> 2464 | D13: 7919 | E13: =IF(D14-D13 < 0,0,D14-D13) -> 870 | F13: 228 | G13: 0.5 | H13: Fair | I13: =+E13+C13 -> 3334 | J13: =(C13*0.288)+(E13*0.177) -> 863.622 | L13: =C13+E13 -> 3334
A14: 44968 | B14: 26384 | C14: =IF(B15-B14 < 0,0,B15-B14) -> 2465 | D14: 8789 | E14: =IF(D15-D14 < 0,0,D15-D14) -> 743 | F14: 228 | G14: 0.5 | H14: Fair | I14: =+E14+C14 -> 3208 | J14: =(C14*0.288)+(E14*0.177) -> 841.431 | L14: =C14+E14 -> 3208
A15: 44969 | B15: 28849 | C15: =IF(B16-B15 < 0,0,B16-B15) -> 2427 | D15: 9532 | E15: =IF(D16-D15 < 0,0,D16-D15) -> 1499 | F15: 228 | G15: 0.51 | H15: Fair | I15: =+E15+C15 -> 3926 | J15: =(C15*0.288)+(E15*0.177) -> 964.299 | L15: =C15+E15 -> 3926
... A31: 44985 | B31: 69196 | C31: =IF(B32-B31 < 0,0,B32-B31) -> 2137 | D31: 23207 | E31: =IF(D32-D31 < 0,0,D32-D31) -> 0 | F31: 256 | G31: 0.46 | H31: Fair | I31: =+E31+C31 -> 2137 | J31: =(C31*0.288)+(E31*0.177) -> 615.456 | L31: =C31+E31 -> 2137
B32: 71333 | C32: =IF(B33-B32 < 0,0,B33-B32) -> 0 | E32: =IF(D33-D32 < 0,0,D33-D32) -> 0 | I32: =+E32+C32 -> 0 | J32: =(C32*0.288)+(E32*0.177) -> 0 | L32: =C32+E32 -> 0
C33: =IF(B34-B33 < 0,0,B34-B33) -> 0 | E33: =IF(D34-D33 < 0,0,D34-D33) -> 0 | I33: =+E33+C33 -> 0 | J33: =(C33*0.288)+(E33*0.177) -> 0 | L33: =C33+E33 -> 0
C34: =IF(B35-B34 < 0,0,B35-B34) -> 0 | E34: 0 | I34: =+E34+C34 -> 0 | J34: =(C34*0.288)+(E34*0.177) -> 0 | L34: =C34+E34 -> 0
I35: =+E35+C35 -> 0 | J35: =(C35*0.288)+(E35*0.177) -> 0
C36: =SUM(C4:C35) -> 68833 | E36: =SUM(E4:E35) -> 22390 | F36: =MAX(F4:F34) -> 257 | I36: =+E36+C36 -> 91223 | J36: =(C36*0.288)+(E36*0.177) -> 23786.934
A37: =COUNT(A4:A34) -> 28 | H37: f
H38: Rain
A39: PLEASE MAKE SURE TO KEY IN THE OCCUPANCY AND WEATHER FOR THE DAY! | H39: Hot
H40: Cloudy

Sheet B17
A1: Daily Electricity Consumption
B2: Meter Reading (kWh) | C2: Consumption (kWh) | D2: Meter Reading (kWh) | E2: Consumption (kWh) | F2: MD (kW) | G2: Occupancy | H2: Weather | I2: Total Consumption | J2: Cost
B3: (Peak) | C3: (Peak) | E3: (Off Peak) | F3: (Peak) | G3: % | I3: Daily (KWh) | J3: Daily (RM)
A4: 44958 | B4: 4178 | C4: =IF(B5-B4 < 0,0,B5-B4) -> 4009 | D4: 2404 | E4: =IF(D5-D4 < 0,0,D5-D4) -> 2486 | F4: 344 | G4: 0.59 | H4: Fair | I4: =+E4+C4 -> 6495 | J4: =(C4*0.288)+(E4*0.177) -> 1594.614 | L4: =C4+E4 -> 6495
A5: 44959 | B5: 8187 | C5: =IF(B6-B5 < 0,0,B6-B5) -> 3979 | D5: 4890 | E5: =IF(D6-D5 < 0,0,D6-D5) -> 2009 | F5: 344 | G5: 0.6 | H5: Fair | I5: =+E5+C5 -> 5988 | J5: =(C5*0.288)+(E5*0.177) -> 1501.545 | L5: =C5+E5 -> 5988
A6: 44960 | B6: 12166 | C6: =IF(B7-B6 < 0,0,B7-B6) -> 4638 | D6: 6899 | E6: =IF(D7-D6 < 0,0,D7-D6) -> 2385 | F6: 344 | G6: 0.72 | H6: Isolate Rain | I6: =+E6+C6 -> 7023 | J6: =(C6*0.288)+(E6*0.177) -> 1757.889 | L6: =C6+E6 -> 7023
A7: 44961 | B7: 16804 | C7: =IF(B8-B7 < 0,0,B8-B7) -> 4667 | D7: 9284 | E7: =IF(D8-D7 < 0,0,D8-D7) -> 2715 | F7: 383 | G7: 0.74 | H7: Fair | I7: =+E7+C7 -> 7382 | J7: =(C7*0.288)+(E7*0.177) -> 1824.651 | L7: =C7+E7 -> 7382
A8: 44962 | B8: 21471 | C8: =IF(B9-B8 < 0,0,B9-B8) -> 4680 | D8: 11999 | E8: =IF(D9-D8 < 0,0,D9-D8) -> 2997 | F8: 383 | G8: 0.55 | H8: Fair | I8: =+E8+C8 -> 7677 | J8: =(C8*0.288)+(E8*0.177) -> 1878.309 | L8: =C8+E8 -> 7677
A9: 44963 | B9: 26151 | C9: =IF(B10-B9 < 0,0,B10-B9) -> 4599 | D9: 14996 | E9: =IF(D10-D9 < 0,0,D10-D9) -> 2635 | F9: 383 | G9: 0.41 | H9: Fair | I9: =+E9+C9 -> 7234 | J9: =(C9*0.288)+(E9*0.177) -> 1790.907 | L9: =C9+E9 -> 7234
A10: 44964 | B10: 30750 | C10: =IF(B11-B10 < 0,0,B11-B10) -> 4419 | D10: 17631 | E10: =IF(D11-D10 < 0,0,D11-D10) -> 3507 | F10: 404 | G10: 0.38 | H10: Fair | I10: =+E10+C10 -> 7926 | J10: =(C10*0.288)+(E10*0.177) -> 1893.411 | L10: =C10+E10 -> 7926
A11: 44965 | B11: 35169 | C11: =IF(B12-B11 < 0,0,B12-B11) -> 4429 | D11: 21138 | E11: =IF(D12-D11 < 0,0,D12-D11) -> 2321 | F11: 404 | G11: 0.4 | H11: Fair | I11: =+E11+C11 -> 6750 | J11: =(C11*0.288)+(E11*0.177) -> 1686.369 | L11: =C11+E11 -> 6750
A12: 44966 | B12: 39598 | C12: =IF(B13-B12 < 0,0,B13-B12) -> 5158 | D12: 23459 | E12: =IF(D13-D12 < 0,0,D13-D12) -> 2298 | F12: 404 | G12: 0.41 | H12: Fair | I12: =+E12+C12 -> 7456 | J12: =(C12*0.288)+(E12*0.177) -> 1892.25 | L12: =C12+E12 -> 7456
A13: 44967 | B13: 44756 | C13: =IF(B14-B13 < 0,0,B14-B13) -> 5299 | D13: 25757 | E13: =IF(D14-D13 < 0,0,D14-D13) -> 3350 | F13: 444 | G13: 0.5 | H13: Fair | I13: =+E13+C13 -> 8649 | J13: =(C13*0.288)+(E13*0.177) -> 2119.062 | L13: =C13+E13 -> 8649
A14: 44968 | B14: 50055 | C14: =IF(B15-B14 < 0,0,B15-B14) -> 4948 | D14: 29107 | E14: =IF(D15-D14 < 0,0,D15-D14) -> 3036 | F14: 444 | G14: 0.5 | H14: Fair | I14: =+E14+C14 -> 7984 | J14: =(C14*0.288)+(E14*0.177) -> 1962.396 | L14: =C14+E14 -> 7984
A15: 44969 | B15: 55003 | C15: =IF(B16-B15 < 0,0,B16-B15) -> 5000 | D15: 32143 | E15: =IF(D16-D15 < 0,0,D16-D15) -> 3099 | F15: 444 | G15: 0.51 | H15: Fair | I15: =+E15+C15 -> 8099 | J15: =(C15*0.288)+(E15*0.177) -> 1988.523 | L15: =C15+E15 -> 8099
... A31: 44985 | B31: 133399 | C31: =IF(B32-B31 < 0,0,B32-B31) -> 3257 | D31: 76970 | E31: =IF(D32-D31 < 0,0,D32-D31) -> 0 | F31: 444 | G31: 0.46 | H31: Fair | I31: =+E31+C31 -> 3257 | J31: =(C31*0.288)+(E31*0.177) -> 938.016 | L31: =C31+E31 -> 3257
B32: 136656 | C32: =IF(B33-B32 < 0,0,B33-B32) -> 0 | E32: =IF(D33-D32 < 0,0,D33-D32) -> 0 | I32: =+E32+C32 -> 0 | J32: =(C32*0.288)+(E32*0.177) -> 0 | L32: =C32+E32 -> 0
C33: =IF(B34-B33 < 0,0,B34-B33) -> 0 | E33: =IF(D34-D33 < 0,0,D34-D33) -> 0 | I33: =+E33+C33 -> 0 | J33: =(C33*0.288)+(E33*0.177) -> 0 | L33: =C33+E33 -> 0
C34: =IF(B35-B34 < 0,0,B35-B34) -> 0 | E34: =IF(D35-D34 < 0,0,D35-D34) -> 0 | I34: =+E34+C34 -> 0 | J34: =(C34*0.288)+(E34*0.177) -> 0 | L34: =C34+E34 -> 0
I35: =+E35+C35 -> 0 | J35: =(C35*0.288)+(E35*0.177) -> 0
C36: =SUM(C4:C35) -> 132478 | E36: =SUM(E4:E35) -> 74566 | F36: =MAX(F4:F34) -> 444 | I36: =+E36+C36 -> 207044 | J36: =(C36*0.288)+(E36*0.177) -> 51351.846
A37: =COUNT(A4:A34) -> 28
H38: Rain
A39: PLEASE MAKE SURE TO KEY IN THE OCCUPANCY AND WEATHER FOR THE DAY! | H39: Hot
H40: Cloudy

Sheet Water Reading
A1: Daily Water Consumption
B2: Meter Reading (Main) | C2: Consumption | D2: Meter Reading Landscape | E2: Consumption | F2: Occupancy | G2: Weather | H2: Total Consumption | I2: Cost | J2: Remarks
B3: (m3) | C3: (m3) | D3: (m3) | E3: (m3) | F3: % | H3: (m3) | I3: Daily (RM)
A4: 44958 | B4: 526007 | C4: =IF(B5-B4<0,0,B5-B4) -> 0 | D4: 4236 | E4: =IF(D5-D4<0,0,D5-D4) -> 12 | F4: 0.59 | G4: Fair | H4: =+E4+C4 -> 12 | I4: =(C4*1.35)+(E4*1.35) -> 16.2 | L4: =C4+E4 -> 12
A5: 44959 | B5: 526007 | C5: =IF(B6-B5<0,0,B6-B5) -> 1 | D5: 4248 | E5: =IF(D6-D5<0,0,D6-D5) -> 20 | F5: 0.6 | G5: Fair | H5: =+E5+C5 -> 21 | I5: =(C5*1.35)+(E5*1.35) -> 28.35 | L5: =C5+E5 -> 21
A6: 44960 | B6: 526008 | C6: =IF(B7-B6<0,0,B7-B6) -> 2 | D6: 4268 | E6: =IF(D7-D6<0,0,D7-D6) -> 23 | F6: 0.72 | G6: Isolate Rain | H6: =+E6+C6 -> 25 | I6: =(C6*1.35)+(E6*1.35) -> 33.75 | L6: =C6+E6 -> 25
A7: 44961 | B7: 526010 | C7: =IF(B8-B7<0,0,B8-B7) -> 10 | D7: 4291 | E7: =IF(D8-D7<0,0,D8-D7) -> 22 | F7: 0.74 | G7: Fair | H7: =+E7+C7 -> 32 | I7: =(C7*1.35)+(E7*1.35) -> 43.2 | L7: =C7+E7 -> 32
A8: 44962 | B8: 526020 | C8: =IF(B9-B8<0,0,B9-B8) -> 0 | D8: 4313 | E8: =IF(D9-D8<0,0,D9-D8) -> 29 | F8: 0.55 | G8: Fair | H8: =+E8+C8 -> 29 | I8: =(C8*1.35)+(E8*1.35) -> 39.15 | L8: =C8+E8 -> 29
A9: 44963 | B9: 526020 | C9: =IF(B10-B9<0,0,B10-B9) -> 0 | D9: 4342 | E9: =IF(D10-D9<0,0,D10-D9) -> 37 | F9: 0.41 | G9: Fair | H9: =+E9+C9 -> 37 | I9: =(C9*1.35)+(E9*1.35) -> 49.95 | L9: =C9+E9 -> 37
A10: 44964 | B10: 526020 | C10: =IF(B11-B10<0,0,B11-B10) -> 0 | D10: 4379 | E10: =IF(D11-D10<0,0,D11-D10) -> 41 | F10: 0.38 | G10: Fair | H10: =+E10+C10 -> 41 | I10: =(C10*1.35)+(E10*1.35) -> 55.35 | L10: =C10+E10 -> 41
A11: 44965 | B11: 526020 | C11: =IF(B12-B11<0,0,B12-B11) -> 0 | D11: 4420 | E11: =IF(D12-D11<0,0,D12-D11) -> 37 | F11: 0.4 | G11: Fair | H11: =+E11+C11 -> 37 | I11: =(C11*1.35)+(E11*1.35) -> 49.95 | L11: =C11+E11 -> 37
A12: 44966 | B12: 526020 | C12: =IF(B13-B12<0,0,B13-B12) -> 0 | D12: 4457 | E12: =IF(D13-D12<0,0,D13-D12) -> 28 | F12: 0.41 | G12: Fair | H12: =+E12+C12 -> 28 | I12: =(C12*1.35)+(E12*1.35) -> 37.8 | L12: =C12+E12 -> 28
A13: 44967 | B13: 526020 | C13: =IF(B14-B13<0,0,B14-B13) -> 0 | D13: 4485 | E13: =IF(D14-D13<0,0,D14-D13) -> 21 | F13: 0.5 | G13: Fair | H13: =+E13+C13 -> 21 | I13: =(C13*1.35)+(E13*1.35) -> 28.35 | L13: =C13+E13 -> 21
A14: 44968 | B14: 526020 | C14: =IF(B15-B14<0,0,B15-B14) -> 6 | D14: 4506 | E14: =IF(D15-D14<0,0,D15-D14) -> 41 | F14: 0.5 | G14: Fair | H14: =+E14+C14 -> 47 | I14: =(C14*1.35)+(E14*1.35) -> 63.45 | L14: =C14+E14 -> 47
A15: 44969 | B15: 526026 | C15: =IF(B16-B15<0,0,B16-B15) -> 4 | D15: 4547 | E15: =IF(D16-D15<0,0,D16-D15) -> 4 | F15: 0.51 | G15: Fair | H15: =+E15+C15 -> 8 | I15: =(C15*1.35)+(E15*1.35) -> 10.8 | L15: =C15+E15 -> 8
... A30: 44984 | B30: 526222 | C30: =IF(B31-B30<0,0,B31-B30) -> 0 | D30: 4916 | E30: =IF(D31-D30<0,0,D31-D30) -> 24 | F30: 0.42 | G30: Fair | H30: =+E30+C30 -> 24 | I30: =(C30*1.35)+(E30*1.35) -> 32.4 | L30: =C30+E30 -> 24
A31: 44985 | B31: 526222 | C31: 5 | D31: 4940 | E31: 24 | F31: 0.46 | G31: Fair | H31: =+E31+C31 -> 29 | I31: =(C31*1.35)+(E31*1.35) -> 39.15 | L31: =C31+E31 -> 29
C32: =IF(B33-B32<0,0,B33-B32) -> 0 | E32: =IF(D33-D32<0,0,D33-D32) -> 0 | H32: =+E32+C32 -> 0 | I32: =(C32*1.35)+(E32*1.35) -> 0 | L32: =C32+E32 -> 0
C33: =IF(B34-B33<0,0,B34-B33) -> 0 | E33: =IF(D34-D33<0,0,D34-D33) -> 0 | H33: =+E33+C33 -> 0 | I33: =(C33*1.35)+(E33*1.35) -> 0 | L33: =C33+E33 -> 0
C34: =IF(B35-B34<0,0,B35-B34) -> 0 | E34: =IF(D35-D34<0,0,D35-D34) -> 0 | H34: =+E34+C34 -> 0 | I34: =(C34*1.35)+(E34*1.35) -> 0 | L34: =C34+E34 -> 0
C35: =SUM(C4:C34) -> 220 | E35: =SUM(E4:E34) -> 728 | H35: =SUM(H4:H34) -> 948 | I35: =SUM(I4:I34) -> 1279.8
A38: PLEASE MAKE SURE TO KEY IN THE OCCUPANCY AND WEATHER FOR THE DAY!

Sheet Diesel Reading 
A1: Daily Diesel Consumption
B2: BOILER | C2: TIME | D2: TIME | E2: TOTAL | F2: Meter Reading | G2: Meter Reading | H2: Consumption | I2: Cost | J2: Diesel in/Litre | N2: MAIN METER READING
B3: NO | C3: START | D3: STOP | E3: HRS | F3: START | G3: STOP | H3: (L) | I3: Daily (RM) | N3: Date | O3: Before | P3: After | Q3: Total Usage | R3: Balance Litre
A4: 44958 | B4: 2 | C4: 8.3 | D4: 20 | E4: =D4-C4 -> 11.7 | F4: 1633681.7 | G4: 1633979.4 | H4: =G4-F4 -> 297.7 | I4: =(H4*[1]Summary!$C$6) -> 845.468 | J4: 2136.2 | K4: CF Last Month | N4: 44958 | O4: 66475.8 | P4: 66925.4 | Q4: =P4-O4 -> 449.6 | R4: 2853.4 | S4: CF Last Month
A5: 44959 | B5: 2 | C5: 8.3 | D5: 20 | E5: =D5-C5 -> 11.7 | F5: 1633979.4 | G5: 1634226.2 | H5: =G5-F5 -> 246.8 | I5: =(H5*[1]Summary!$C$6) -> 700.912 | N5: 44959 | O5: 66925.4 | Q5: =P5-O5 -> -66925.4
A6: 44960 | B6: 2 | C6: 8.3 | D6: 20 | E6: =D6-C6 -> 11.7 | F6: 1634226.2 | G6: 1634523.3 | H6: =G6-F6 -> 297.1 | I6: =(H6*[1]Summary!$C$6) -> 843.764 | J6: 5460 | K6: Diesel In | N6: 44960 | P6: 67842.6 | Q6: =P6-O6 -> 67842.6 | R6: 5460 | S6: Diesel In
A7: 44961 | B7: 2 | C7: 8.3 | D7: 20 | E7: =D7-C7 -> 11.7 | F7: 1634523.3 | G7: 1634802.1 | H7: =G7-F7 -> 278.8 | I7: =(H7*[1]Summary!$C$6) -> 791.792 | N7: 44961 | O7: 67842.6 | P7: 68292.5 | Q7: =P7-O7 -> 449.9
A8: 44962 | B8: 2 | C8: 8.3 | D8: 20 | E8: =D8-C8 -> 11.7 | F8: 1634802.1 | G8: 1635061.1 | H8: =G8-F8 -> 259 | I8: =(H8*[1]Summary!$C$6) -> 735.56 | N8: 44962 | O8: 68292.5 | P8: 68711.2 | Q8: =P8-O8 -> 418.7
A9: 44963 | B9: 1 | C9: 8.3 | D9: 18 | E9: =D9-C9 -> 9.7 | F9: 1750426.1 | G9: 1750655.9 | H9: =G9-F9 -> 229.8 | I9: =(H9*[1]Summary!$C$6) -> 652.632 | N9: 44963 | O9: 68711.2 | P9: 69157.3 | Q9: =P9-O9 -> 446.1
A10: 44964 | B10: 2 | C10: 8.3 | D10: 18 | E10: =D10-C10 -> 9.7 | F10: 1635159.2 | G10: 1635538.8 | H10: =G10-F10 -> 379.6 | I10: =(H10*[1]Summary!$C$6) -> 1078.064 | N10: 44964 | O10: 69157.3 | P10: 69568 | Q10: =P10-O10 -> 410.7
A11: 44965 | B11: 1 | C11: 8.3 | D11: 18 | E11: =D11-C11 -> 9.7 | F11: 1750655.9 | G11: 1751041.9 | H11: =G11-F11 -> 386 | I11: =(H11*[1]Summary!$C$6) -> 1096.24 | N11: 44965 | O11: 69568 | P11: 69568 | Q11: =P11-O11 -> 0
A12: 44966 | B12: 1 | C12: 8.3 | D12: 18 | E12: =D12-C12 -> 9.7 | F12: 1751041.9 | G12: 1751454.3 | H12: =G12-F12 -> 412.4 | I12: =(H12*[1]Summary!$C$6) -> 1171.216 | N12: 44966 | Q12: =P12-O12 -> 0
A13: 44967 | B13: 1 | C13: 8.3 | D13: 18 | E13: =D13-C13 -> 9.7 | F13: 1751454.3 | G13: 1751852.5 | H13: =G13-F13 -> 398.2 | I13: =(H13*[1]Summary!$C$6) -> 1130.888 | N13: 44967 | Q13: =P13-O13 -> 0
A14: 44968 | B14: 2 | C14: 8.4 | D14: 18 | E14: =D14-C14 -> 9.6 | F14: 1635538.7 | G14: 1635899.3 | H14: =G14-F14 -> 360.6 | I14: =(H14*[1]Summary!$C$6) -> 1024.104 | N14: 44968 | O14: 69568 | P14: 70729.9 | Q14: =P14-O14 -> 1161.9
A15: 44969 | B15: 1 | C15: 8.4 | D15: 18 | E15: =D15-C15 -> 9.6 | F15: 1751852.5 | G15: 1752233.1 | H15: =G15-F15 -> 380.6 | I15: =(H15*[1]Summary!$C$6) -> 1080.904 | N15: 44969 | O15: 70729.9 | P15: 71129.1 | Q15: =P15-O15 -> 399.2
A16: 44970 | B16: 2 | C16: 8.3 | D16: 20 | E16: =D16-C16 -> 11.7 | F16: 1635899.3 | G16: 1636312.4 | H16: =G16-F16 -> 413.1 | I16: =(H16*[1]Summary!$C$6) -> 1173.204 | N16: 44970 | O16: 71129.1 | P16: 71486.6 | Q16: =P16-O16 -> 357.5
A17: 44971 | B17: 1 | C17: 8.3 | D17: 20 | E17: =D17-C17 -> 11.7 | F17: 1752233.1 | G17: 1752737 | H17: =G17-F17 -> 503.9 | I17: =(H17*[1]Summary!$C$6) -> 1431.076 | N17: 44971 | O17: 71486.6 | P17: 71957.9 | Q17: =P17-O17 -> 471.3
A18: 44972 | B18: 2 | C18: 8.3 | D18: 20 | E18: =D18-C18 -> 11.7 | F18: 1636312.3 | G18: 1636749.8 | H18: =G18-F18 -> 437.5 | I18: =(H18*[1]Summary!$C$6) -> 1242.5 | J18: 5460 | N18: 44972 | O18: 71957.9 | P18: 72443.8 | Q18: =P18-O18 -> 485.9 | R18: 5460
A19: 44973 | B19: 2 | C19: 8.3 | D19: 20 | E19: =D19-C19 -> 11.7 | F19: 1636749.8 | G19: 1637170 | H19: =G19-F19 -> 420.2 | I19: =(H19*[1]Summary!$C$6) -> 1193.368 | N19: 44973 | Q19: =P19-O19 -> 0
A20: 44974 | B20: 2 | C20: 8.3 | D20: 20 | E20: =D20-C20 -> 11.7 | F20: 1637170 | G20: 1637669.8 | H20: =G20-F20 -> 499.8 | I20: =(H20*[1]Summary!$C$6) -> 1419.432 | N20: 44974 | O20: 72443.8 | P20: 73944.3 | Q20: =P20-O20 -> 1500.5
A21: 44975 | B21: 1 | C21: 8.3 | D21: 22.5 | E21: =D21-C21 -> 14.2 | F21: 1752737 | G21: 1753280.8 | H21: =G21-F21 -> 543.8 | I21: =(H21*[1]Summary!$C$6) -> 1544.392 | N21: 44975 | O21: 73944.3 | P21: 74477.7 | Q21: =P21-O21 -> 533.4
A22: 44976 | B22: 2 | C22: 8.3 | D22: 18 | E22: =D22-C22 -> 9.7 | F22: 1637669.8 | G22: 1638114.8 | H22: =G22-F22 -> 445 | I22: =(H22*[1]Summary!$C$6) -> 1263.8 | N22: 44976 | O22: 74477.7 | P22: 75039.1 | Q22: =P22-O22 -> 561.4
A23: 44977 | B23: 1 | C23: 8.3 | D23: 20 | E23: =D23-C23 -> 11.7 | F23: 1753280.8 | G23: 1753768.3 | H23: =G23-F23 -> 487.5 | I23: =(H23*[1]Summary!$C$6) -> 1384.5 | N23: 44977 | O23: 75039.1 | P23: 75430.3 | Q23: =P23-O23 -> 391.2
A24: 44978 | B24: 2 | C24: 8.3 | D24: 20 | E24: =D24-C24 -> 11.7 | F24: 1638114.8 | G24: 1638579.9 | H24: =G24-F24 -> 465.1 | I24: =(H24*[1]Summary!$C$6) -> 1320.884 | N24: 44978 | O24: 75430.3 | P24: 75931 | Q24: =P24-O24 -> 500.7
A25: 44979 | B25: 1 | C25: 8.3 | D25: 20 | E25: =D25-C25 -> 11.7 | F25: 1753768.3 | G25: 1754218.8 | H25: =G25-F25 -> 450.5 | I25: =(H25*[1]Summary!$C$6) -> 1279.42 | J25: -100 | K25: Watersport | N25: 44979 | O25: 75931 | P25: 76367 | Q25: =P25-O25 -> 436
A26: 44980 | B26: 2 | C26: 8.3 | D26: 19 | E26: =D26-C26 -> 10.7 | F26: 1638579.9 | G26: 1638987.3 | H26: =G26-F26 -> 407.4 | I26: =(H26*[1]Summary!$C$6) -> 1157.016 | N26: 44980 | O26: 75931 | P26: 76367 | Q26: =P26-O26 -> 436
A27: 44981 | B27: 2 | C27: 8.3 | D27: 20 | E27: =D27-C27 -> 11.7 | F27: 1638987.3 | G27: 1639393 | H27: =G27-F27 -> 405.7 | I27: =(H27*[1]Summary!$C$6) -> 1152.188 | N27: 44981 | Q27: =P27-O27 -> 0
A28: 44982 | B28: 1 | C28: 8.3 | D28: 20 | E28: =D28-C28 -> 11.7 | F28: 1754218.8 | G28: 1754663.9 | H28: =G28-F28 -> 445.1 | I28: =(H28*[1]Summary!$C$6) -> 1264.084 | N28: 44982 | O28: 76367 | P28: 77254.9 | Q28: =P28-O28 -> 887.9
A29: 44983 | B29: 2 | C29: 8.3 | D29: 18 | E29: =D29-C29 -> 9.7 | F29: 1639393 | G29: 1639768.3 | H29: =G29-F29 -> 375.3 | I29: =(H29*[1]Summary!$C$6) -> 1065.852 | N29: 44983 | O29: 77254.9 | P29: 77701 | Q29: =P29-O29 -> 446.1
A30: 44984 | B30: 1 | C30: 8.3 | D30: 18 | E30: =D30-C30 -> 9.7 | F30: 1754663.9 | G30: 1755054.7 | H30: =G30-F30 -> 390.8 | I30: =(H30*[1]Summary!$C$6) -> 1109.872 | N30: 44984 | O30: 77701 | P30: 78118.2 | Q30: =P30-O30 -> 417.2
A31: 44985 | B31: 2 | C31: 8.3 | D31: 18 | E31: =D31-C31 -> 9.7 | F31: 1639768.3 | G31: 1640158.4 | H31: =G31-F31 -> 390.1 | I31: =(H31*[1]Summary!$C$6) -> 1107.884 | N31: 44985 | O31: 78118.2 | P31: 78356.8 | Q31: =P31-O31 -> 238.6
E32: =D32-C32 -> 0 | H32: =G32-F32 -> 0 | I32: =(H32*[1]Summary!$C$6) -> 0 | Q32: =P32-O32 -> 0
E33: =D33-C33 -> 0 | H33: =G33-F33 -> 0 | I33: =(H33*[1]Summary!$C$6) -> 0 | Q33: =P33-O33 -> 0
E34: =D34-C34 -> 0 | H34: =G34-F34 -> 0 | I34: =(H34*[1]Summary!$C$6) -> 0 | Q34: =P34-O34 -> 0
E35: =D35-C35 -> 0 | H35: =G35-F35 -> 0 | I35: =(H35*[1]Summary!$C$6) -> 0 | Q35: =P35-O35 -> 0
A36: Total | H36: =SUM(H4:H35) -> 11007.4 | I36: =SUM(I4:I35) -> 31261.016 | J36: =SUM(J4:J35)-H36 -> 1948.8 | K36: Balance (Litre) | P36: Total Usage | Q36: =SUM(Q4:Q35) -> 12317 | R36: =SUM(R4:R35)-Q36 -> 1456.4
A57: Date : 01/1/2023
B58: Outside tank
C59: length : 452 cm
C60: Diameter : 196 cm
...
