Workbook

Sheet Sheet1
A1: Site Name | B1: Month | C1: Year | D1: Total (per Unit) mixed glass | E1: Total cost mixed glass | F1: Total (per Unit) liquid food waste | G1: Total cost liquid food waste | H1: Total (per Unit) kitchen grease | I1: Total cost kitchen grease | J1: Total (per Unit) liquid hazardous waste | K1: Total cost liquid hazardous waste | L1: Total (per Unit) batteries | M1: Total cost batteries | N1: Total (per Unit) mixed metals | O1: Total cost mixed metals | P1: Total (per Unit) food waste | Q1: Total cost food waste | R1: Total (per Unit) general municipal solid waste | S1: Total cost general municipal solid waste
A2: Seychelles | B2: 1 | C2: 2023 | D2: 0 | E2: 0 | F2: ='Insert in SCR'!F5 -> 675 | G2: ='Insert in SCR'!G5 -> 0 | H2: ='Insert in SCR'!H5 -> 0 | I2: ='Insert in SCR'!I5/13.68 -> 0 | J2: ='Insert in SCR'!J5 -> 0 | K2: ='Insert in SCR'!K5/13.68 -> 0 | L2: 0 | M2: ='Insert in SCR'!M5/13.68 -> 0 | N2: 0 | O2: 0 | P2: ='Insert in SCR'!P5 -> 2853 | Q2: ='Insert in SCR'!Q5/13.68 -> 0 | R2: ='Insert in SCR'!R5 -> 0 | S2: ='Insert in SCR'!S5/13.68 -> 0 | U2: =SUM(D2,F2,H2,J2,L2,N2,P2,R2) -> 3528
A3: Seychelles | B3: 2 | C3: 2023 | D3: 0 | E3: 0 | F3: 425 | G3: ='Insert in SCR'!G6 -> 0 | H3: ='Insert in SCR'!H6 -> 0 | I3: ='Insert in SCR'!I6/13.68 -> 0 | J3: ='Insert in SCR'!J6 -> 0 | K3: ='Insert in SCR'!K6/13.68 -> 0 | L3: 1023 | M3: ='Insert in SCR'!M6/13.68 -> 0 | N3: 0 | O3: 0 | P3: 2311 | Q3: ='Insert in SCR'!Q6/13.68 -> 0 | R3: ='Insert in SCR'!R6 -> 0 | S3: ='Insert in SCR'!S6/13.68 -> 0 | U3: =SUM(D3,F3,H3,J3,L3,N3,P3,R3) -> 3759
A4: Seychelles | B4: 3 | C4: 2023 | D4: 0 | E4: 0 | F4: ='Insert in SCR'!F7 -> 0 | G4: ='Insert in SCR'!G7 -> 0 | H4: ='Insert in SCR'!H7 -> 0 | I4: ='Insert in SCR'!I7/13.68 -> 0 | J4: ='Insert in SCR'!J7 -> 0 | K4: ='Insert in SCR'!K7/13.68 -> 0 | L4: 660 | M4: ='Insert in SCR'!M7/13.68 -> 0 | N4: 0 | O4: 0 | P4: ='Insert in SCR'!P7 -> 0 | Q4: ='Insert in SCR'!Q7/13.68 -> 0 | R4: ='Insert in SCR'!R7 -> 0 | S4: ='Insert in SCR'!S7/13.68 -> 0 | U4: =SUM(D4,F4,H4,J4,L4,N4,P4,R4) -> 660
A5: Seychelles | B5: 4 | C5: 2023 | D5: 0 | E5: 0 | F5: ='Insert in SCR'!F8 -> 0 | G5: ='Insert in SCR'!G8 -> 0 | H5: ='Insert in SCR'!H8 -> 0 | I5: ='Insert in SCR'!I8/13.68 -> 0 | J5: ='Insert in SCR'!J8 -> 0 | K5: ='Insert in SCR'!K8/13.68 -> 0 | L5: 1650 | M5: ='Insert in SCR'!M8/13.68 -> 0 | N5: 0 | O5: 0 | P5: ='Insert in SCR'!P8 -> 0 | Q5: ='Insert in SCR'!Q8/13.68 -> 0 | R5: ='Insert in SCR'!R8 -> 0 | S5: ='Insert in SCR'!S8/13.68 -> 0 | U5: =SUM(D5,F5,H5,J5,L5,N5,P5,R5) -> 1650
A6: Seychelles | B6: 5 | C6: 2023 | D6: 0 | E6: 0 | F6: ='Insert in SCR'!F9 -> 0 | G6: ='Insert in SCR'!G9 -> 0 | H6: ='Insert in SCR'!H9 -> 0 | I6: ='Insert in SCR'!I9/13.68 -> 0 | J6: ='Insert in SCR'!J9 -> 0 | K6: ='Insert in SCR'!K9/13.68 -> 0 | L6: 2178 | M6: ='Insert in SCR'!M9/13.68 -> 0 | N6: 0 | O6: 0 | P6: ='Insert in SCR'!P9 -> 0 | Q6: ='Insert in SCR'!Q9/13.68 -> 0 | R6: ='Insert in SCR'!R9 -> 0 | S6: ='Insert in SCR'!S9/13.68 -> 0 | U6: =SUM(D6,F6,H6,J6,L6,N6,P6,R6) -> 2178
A7: Seychelles | B7: 6 | C7: 2023 | D7: 0 | E7: 0 | F7: ='Insert in SCR'!F10 -> 0 | G7: ='Insert in SCR'!G10 -> 0 | H7: ='Insert in SCR'!H10 -> 0 | I7: ='Insert in SCR'!I10/13.68 -> 0 | J7: ='Insert in SCR'!J10 -> 0 | K7: ='Insert in SCR'!K10/13.68 -> 0 | L7: 4420 | M7: ='Insert in SCR'!M10/13.68 -> 0 | N7: 0 | O7: 0 | P7: ='Insert in SCR'!P10 -> 0 | Q7: ='Insert in SCR'!Q10/13.68 -> 0 | R7: ='Insert in SCR'!R10 -> 0 | S7: ='Insert in SCR'!S10/13.68 -> 0 | U7: =SUM(D7,F7,H7,J7,L7,N7,P7,R7) -> 4420
A8: Seychelles | B8: 7 | C8: 2023 | D8: 0 | E8: 0 | F8: ='Insert in SCR'!F11 -> 0 | G8: ='Insert in SCR'!G11 -> 0 | H8: ='Insert in SCR'!H11 -> 0 | I8: ='Insert in SCR'!I11/13.68 -> 0 | J8: ='Insert in SCR'!J11 -> 0 | K8: ='Insert in SCR'!K11/13.68 -> 0 | L8: 1452 | M8: ='Insert in SCR'!M11/13.68 -> 0 | N8: 0 | O8: 0 | P8: ='Insert in SCR'!P11 -> 0 | Q8: ='Insert in SCR'!Q11/13.68 -> 0 | R8: ='Insert in SCR'!R11 -> 0 | S8: ='Insert in SCR'!S11/13.68 -> 0 | U8: =SUM(D8,F8,H8,J8,L8,N8,P8,R8) -> 1452
A9: Seychelles | B9: 8 | C9: 2023 | D9: 0 | E9: 0 | F9: ='Insert in SCR'!F12 -> 0 | G9: ='Insert in SCR'!G12 -> 0 | H9: ='Insert in SCR'!H12 -> 0 | I9: ='Insert in SCR'!I12/13.68 -> 0 | J9: ='Insert in SCR'!J12 -> 0 | K9: ='Insert in SCR'!K12/13.68 -> 0 | L9: 1320 | M9: ='Insert in SCR'!M12/13.68 -> 0 | N9: 0 | O9: 0 | P9: ='Insert in SCR'!P12 -> 0 | Q9: ='Insert in SCR'!Q12/13.68 -> 0 | R9: ='Insert in SCR'!R12 -> 0 | S9: ='Insert in SCR'!S12/13.68 -> 0 | U9: =SUM(D9,F9,H9,J9,L9,N9,P9,R9) -> 1320
A10: Seychelles | B10: 9 | C10: 2023 | D10: 0 | E10: 0 | F10: ='Insert in SCR'!F13 -> 0 | G10: ='Insert in SCR'!G13 -> 0 | H10: ='Insert in SCR'!H13 -> 0 | I10: ='Insert in SCR'!I13/13.68 -> 0 | J10: ='Insert in SCR'!J13 -> 0 | K10: ='Insert in SCR'!K13/13.68 -> 0 | L10: 0 | M10: ='Insert in SCR'!M13/13.68 -> 0 | N10: 0 | O10: 0 | P10: ='Insert in SCR'!P13 -> 0 | Q10: ='Insert in SCR'!Q13/13.68 -> 0 | R10: ='Insert in SCR'!R13 -> 0 | S10: ='Insert in SCR'!S13/13.68 -> 0 | U10: =SUM(D10,F10,H10,J10,L10,N10,P10,R10) -> 0
A11: Seychelles | B11: 10 | C11: 2023 | D11: 1360 | E11: 0 | F11: ='Insert in SCR'!F14 -> 0 | G11: ='Insert in SCR'!G14 -> 0 | H11: ='Insert in SCR'!H14 -> 0 | I11: ='Insert in SCR'!I14/13.68 -> 0 | J11: ='Insert in SCR'!J14 -> 0 | K11: ='Insert in SCR'!K14/13.68 -> 0 | L11: 0 | M11: ='Insert in SCR'!M14/13.68 -> 0 | N11: 0 | O11: 0 | P11: ='Insert in SCR'!P14 -> 0 | Q11: ='Insert in SCR'!Q14/13.68 -> 0 | R11: ='Insert in SCR'!R14 -> 0 | S11: ='Insert in SCR'!S14/13.68 -> 0 | U11: =SUM(D11,F11,H11,J11,L11,N11,P11,R11) -> 1360
A12: Seychelles | B12: 11 | C12: 2023 | F12: ='Insert in SCR'!F15 -> 0 | G12: ='Insert in SCR'!G15 -> 0 | H12: ='Insert in SCR'!H15 -> 0 | I12: ='Insert in SCR'!I15/13.68 -> 0 | J12: ='Insert in SCR'!J15 -> 0 | K12: ='Insert in SCR'!K15/13.68 -> 0 | L12: 0 | M12: ='Insert in SCR'!M15/13.68 -> 0 | N12: 0 | O12: 0 | P12: ='Insert in SCR'!P15 -> 0 | Q12: ='Insert in SCR'!Q15/13.68 -> 0 | R12: ='Insert in SCR'!R15 -> 0 | S12: ='Insert in SCR'!S15/13.68 -> 0 | U12: =SUM(D12,F12,H12,J12,L12,N12,P12,R12) -> 0
A13: Seychelles | B13: 12 | C13: 2023 | F13: 500 | G13: 0 | H13: ='Insert in SCR'!H16 -> 0 | I13: ='Insert in SCR'!I16/13.68 -> 0 | J13: 2680 | K13: ='Insert in SCR'!K16/13.68 -> 0 | L13: 0 | M13: ='Insert in SCR'!M16/13.68 -> 0 | N13: 0 | O13: 0 | P13: 2583 | Q13: ='Insert in SCR'!Q16/13.68 -> 0 | R13: ='Insert in SCR'!R16 -> 0 | S13: ='Insert in SCR'!S16/13.68 -> 0 | U13: =SUM(D13,F13,H13,J13,L13,N13,P13,R13) -> 5763
A15: Assigned Team member | D15: Collected by third party for recycling, not going landfill | F15: Collected third party, getting to scr value | H15: Collected by Wastea, data from Birthstreet invoice | J15: Collected by LWMA, data from Birthstreet invoice | L15: Collected by third party scrap meter licence, getting scr65 value per battery | N15: Clemance to weight and share data | P15: Collected by third party (animal farm). Clemence to share data | R15: Collected by Wastea, data from Birthstreet invoice. (Skip + Compactor)
K18: Total (per Unit) batteries | L18: Weight
K19: Trojan battery 145 | L19: 33
K20: Trojan battery 875 | L20: 29

Sheet Insert in SCR
D2: Step 3-IN SEYCHELLES RUPEE
A4: Site Name | B4: Month | C4: Year | D4: Total (per Unit) mixed glass | E4: Total cost mixed glass | F4: Total (per Unit) liquid food waste | G4: Total cost liquid food waste | H4: Total (per Unit) kitchen grease | I4: Total cost kitchen grease | J4: Total (per Unit) liquid hazardous waste | K4: Total cost liquid hazardous waste | L4: Total (per Unit) batteries | M4: Total cost batteries (scr65) | N4: Total (per Unit) mixed metals | O4: Total cost mixed metals | P4: Total (per Unit) food waste | Q4: Total cost food waste | R4: Total (per Unit) general municipal solid waste | S4: Total cost general municipal solid waste
A5: Seychelles | B5: 1 | C5: 2023 | F5: 675 | G5: 0 | P5: 2853 | Q5: 0
A6: Seychelles | B6: 2 | C6: 2023 | G6: 0 | Q6: 0
A7: Seychelles | B7: 3 | C7: 2023 | G7: 0 | Q7: 0
A8: Seychelles | B8: 4 | C8: 2023 | G8: 0 | Q8: 0
A9: Seychelles | B9: 5 | C9: 2023 | G9: 0 | Q9: 0
A10: Seychelles | B10: 6 | C10: 2023 | G10: 0 | Q10: 0
A11: Seychelles | B11: 7 | C11: 2023 | G11: 0 | Q11: 0
A12: Seychelles | B12: 8 | C12: 2023 | G12: 0 | Q12: 0
A13: Seychelles | B13: 9 | C13: 2023 | G13: 0 | Q13: 0
A14: Seychelles | B14: 10 | C14: 2023 | G14: 0 | Q14: 0
A15: Seychelles | B15: 11 | C15: 2023 | G15: 0 | Q15: 0
A16: Seychelles | B16: 12 | C16: 2023 | Q16: 0
F17: OIL WASTE | H17: GREASE TRAP | J17: ENGINE OIL | L17: BATTERIES | N17: SCRAP METAL | P17: FOOD WASTE | R17: COMPACTOR+WOOD SKIP

Sheet Calculation Foodwaste
C3: Outlet | D3: Bin per day | F3: % | H3: Jan | J3: Feb | N3: Mar | P3: Apr | R3: May | T3: Jun | V3: Jul | X3: Aug | Z3: Sep | AA3: Oct | AB3: Nov | AC3: Dec
B4: 1 | C4: Kannel | D4: 5 | E4: =D4*100/D11 -> #DIV/0! | F4: 0.17 | H4: =D21*F4 -> 677.28 | I4: =F21*E21 -> 6772.8 | J4: =D22*E21 -> 600.78 | K4: =F22*E21 -> 6007.8 | N4: =D23*E21 -> 681.02 | O4: =F23*E21 -> 6810.2 | P4: =D24*E21 -> 820.335 | Q4: =F24*E21 -> 5468.9 | R4: =D25*E21 -> 1012.35 | S4: =F25*E21 -> 6749 | T4: =D26*E21 -> 996.5655 | U4: =F26*E21 -> 6643.6 | V4: =D27*F4 -> 5.0388 | W4: =V4*1000 -> 5038.8 | X4: =D28*F4 -> 8.7023 | Y4: =X4*1000 -> 8702.3
B5: 2 | C5: Zez | D5: 4 | E5: =D5*100/D11 -> #DIV/0! | F5: 0.13 | H5: =D22*F5 -> 459.42 | I5: =F21*E22 -> 5179.2 | J5: =D22*E22 -> 459.42 | K5: =F22*E22 -> 4594.2 | N5: =D23*E22 -> 520.78 | O5: =F23*E22 -> 5207.8 | P5: =D24*E22 -> 627.315 | Q5: =F24*E22 -> 4182.1 | R5: =D25*E22 -> 774.15 | S5: =F25*E22 -> 5161 | T5: =D26*E22 -> 762.0795 | U5: =F26*E22 -> 5080.4 | V5: =D27*F5 -> 3.8532 | W5: =V5*1000 -> 3853.2 | X5: =D28*F5 -> 6.6547 | Y5: =X5*1000 -> 6654.7
B6: 3 | C6: IVD | D6: 5 | E6: =D6*100/D11 -> #DIV/0! | F6: 0.17 | H6: 677.28 | I6: =F21*E23 -> 6772.8 | J6: =D22*E23 -> 600.78 | K6: =F22*E23 -> 6007.8 | N6: =D23*E23 -> 681.02 | O6: =F23*E23 -> 6810.2 | P6: =D24*E23 -> 820.335 | Q6: =F24*E23 -> 5468.9 | R6: =D25*E23 -> 1012.35 | S6: =F25*E23 -> 6749 | T6: =D26*E23 -> 996.5655 | U6: =F26*E23 -> 6643.6 | V6: 5.0388 | W6: =V6*1000 -> 5038.8 | X6: =D28*F6 -> 8.7023 | Y6: =X6*1000 -> 8702.3
B7: 4 | C7: Buther | D7: 2 | E7: =D7*100/D11 -> #DIV/0! | F7: 0.07 | H7: =D21*F7 -> 278.88 | I7: =F21*E24 -> 2788.8 | J7: =D22*E24 -> 247.38 | K7: =F22*E24 -> 2473.8 | N7: =D23*E24 -> 280.42 | O7: =F23*E24 -> 2804.2 | P7: =D24*E24 -> 337.785 | Q7: =F24*E24 -> 2251.9 | R7: =D25*E24 -> 416.85 | S7: =F25*E24 -> 2779 | T7: =D26*E24 -> 410.3505 | U7: =F26*E24 -> 2735.6 | V7: =D27*F7 -> 2.0748 | W7: =V7*1000 -> 2074.8 | X7: =D28*F7 -> 3.5833 | Y7: =X7*1000 -> 3583.3
B8: 5 | C8: Sitronel | D8: 4 | E8: =D8*100/D11 -> #DIV/0! | F8: 0.13 | H8: 459.42 | I8: =F21*E25 -> 5179.2 | J8: =D22*E25 -> 459.42 | K8: =F22*E25 -> 4594.2 | N8: =D23*E25 -> 520.78 | O8: =F23*E25 -> 5207.8 | P8: =D24*E25 -> 627.315 | Q8: =F24*E25 -> 4182.1 | R8: =D25*E25 -> 774.15 | S8: =F25*E25 -> 5161 | T8: =D26*E25 -> 762.0795 | U8: =F26*E25 -> 5080.4 | V8: =D27*F8 -> 3.8532 | W8: =V8*1000 -> 3853.2 | X8: =D28*F8 -> 6.6547 | Y8: =X8*1000 -> 6654.7
B9: 6 | C9: E-housing | D9: 10 | E9: =D9*100/D11 -> #DIV/0! | F9: 0.33 | H9: =SUM(H4:H8) -> 2552.28 | I9: =SUM(I4:I8) -> 26692.8 | J9: =SUM(J4:J8) -> 2367.78 | K9: =SUM(K4:K8) -> 23677.8 | N9: =SUM(N4:N8) -> 2684.02 | O9: =SUM(O4:O8) -> 26840.2 | P9: =SUM(P4:P8) -> 3233.085 | Q9: =SUM(Q4:Q8) -> 21553.9 | R9: =SUM(R4:R8) -> 3989.85 | S9: =SUM(S4:S8) -> 26599 | T9: =SUM(T4:T8) -> 3927.6405 | U9: =SUM(U4:U8) -> 26183.6 | ... W9: =SUM(W4:W8) -> 19858.8
B10: 7 | C10: Residence | D10: 0 | E10: =D10*100/D11 -> #DIV/0!
C11: KG | G11: jan | H11: 2552.28 | I11: 26692.8 | J11: 28070 | K11: 4142.5 | V11: =SUM(V4:V10) -> 39.7176 | W11: =SUM(W4:W10) -> 39717.6 | X11: =SUM(X4:X10) -> 34.2973 | Y11: =SUM(Y4:Y10) -> 34297.3
B12: 1 | C12: Kannel | G12: feb | H12: 2367.68 | I12: 23677.8 | J12: 35820 | K12: 3582 | V12: =E27*F4 -> 755.82 | X12: =E28*F4 -> 1305.345
B13: 2 | C13: Zez | G13: mar | H13: 2684.02 | I13: 26840.2 | J13: 26600 | K13: 2510.5 | V13: =E27*F5 -> 577.98 | X13: =E28*F5 -> 998.205
B14: 3 | C14: IVD | G14: apr | H14: 3233.09 | I14: 21553.9 | J14: 19560 | K14: 2780.5 | V14: =E27*F6 -> 755.82 | X14: =E28*F6 -> 1305.345
B15: 4 | C15: Buther | G15: may | H15: 3989.85 | I15: 26599 | J15: 12920 | K15: 1833 | V15: =E27*F7 -> 311.22 | X15: =E28*F7 -> 537.495
B16: 5 | C16: Sitronel | G16: jun | H16: 3927.64 | I16: 26183.6 | J16: 20380 | K16: 2967.75 | V16: =E27*F8 -> 577.98 | X16: =E28*F8 -> 998.205
B17: 6 | C17: E-housing | G17: jul | I17: 19852.8 | J17: 16870 | K17: 3031.5
B18: 7 | C18: Residence | G18: aug | J18: 8910 | K18: 1869.5
H19: =SUM(H12:H16) -> 16202.28 | J19: =SUM(J12:J16) -> 115280 | N19: =SUM(N12:N16) -> 0 | P19: =SUM(P12:P16) -> 0 | R19: =SUM(R12:R16) -> 0 | T19: =SUM(T12:T16) -> 0 | V19: =SUM(V12:V16) -> 2978.82 | W19: =SUM(W12:W16) -> 0 | X19: =SUM(X12:X16) -> 5144.595
B21: 2022 | C21: January | D21: 3984 | E21: 0.17 | F21: 39840
B22: 2022 | C22: February | D22: 3534 | E22: 0.13 | F22: 35340
B23: 2022 | C23: March | D23: 4006 | E23: 0.17 | F23: 40060
B24: 2022 | C24: April | D24: 4825.5 | E24: 0.07 | F24: 32170
B25: 2022 | C25: May | D25: 5955 | E25: 0.13 | F25: 39700
B26: 2022 | C26: June | D26: 5862.15 | F26: 39080
B27: 2022 | C27: July | D27: 29.64 | E27: 4446
B28: 2022 | C28: August | D28: 51.19 | E28: 7678.5
B29: 2022 | C29: September
B30: 2022 | C30: October
B31: 2022 | C31: November
B32: 2022 | C32: December
C37: Step2- Information gathered from Step1 to insert on "Insert in SCR sheet" | N37: Step1- Information gathered from Birthstreet POs
C38: Grease Trap (Kitchen Outlets) | F38: Compactor (STP) | I38: Skip (BOH) | N38: Grease Trap | O38: September | Q38: October | S38: November | U38: December
C39: Tonnes | D39: Convert in Kg | E39: Total price SCR | F39: Tonnes | G39: Convert in Kg | H39: Total price SCR | I39: Tonnes | J39: Convert in Kg | K39: Total price SCR | L39: Total Kg of Compactor + Skip | M39: Total Price of Compactor + Skip | N39: No. of Request | O39: Tonnes | P39: Total price SCR | Q39: Tonnes | R39: Total price SCR | S39: Tonnes | T39: Total price | U39: Tonnes | V39: Total price
A40: 2022 | B40: January | C40: 28.07 | D40: =C40*1000 -> 28070 | E40: 4142.5 | F40: 39.84 | G40: =F40*1000 -> 39840 | H40: 3984 | I40: 5.41 | J40: =I40*1000 -> 5410 | K40: 541 | L40: =G40+J40 -> 45250 | M40: =H40+K40 -> 4525 | N40: 1 | O40: 1.07 | P40: 160.5 | Q40: 5.37 | R40: 805.5
A41: 2022 | B41: February | C41: 35.82 | D41: =C41*1000 -> 35820 | E41: 3582 | F41: 35.34 | G41: =F41*1000 -> 35340 | H41: 3534 | I41: 6.53 | J41: =I41*1000 -> 6530 | K41: 653 | L41: =G41+J41 -> 41870 | M41: =H41+K41 -> 4187 | N41: 2 | O41: 1.07 | P41: 160.5 | Q41: 1.86 | R41: 279
A42: 2022 | B42: March | C42: 26.6 | D42: =C42*1000 -> 26600 | E42: 2510.5 | F42: 40.06 | G42: =F42*1000 -> 40060 | H42: 4006 | I42: 8.37 | J42: =I42*1000 -> 8370 | K42: 837 | L42: =G42+J42 -> 48430 | M42: =H42+K42 -> 4843 | N42: 3 | O42: 1.1 | P42: 165 | Q42: 1.34 | R42: 201
A43: 2022 | B43: April | C43: 19.56 | D43: =C43*1000 -> 19560 | E43: 2780.5 | F43: 32.17 | G43: =F43*1000 -> 32170 | H43: 4825.5 | I43: 7.65 | J43: =I43*1000 -> 7650 | K43: 1147.5 | L43: =G43+J43 -> 39820 | M43: =H43+K43 -> 5973 | N43: 4 | O43: 5.78 | P43: 867 | Q43: 1.28 | R43: 192
A44: 2022 | B44: May | C44: 12.92 | D44: =C44*1000 -> 12920 | E44: 1833 | F44: 39.7 | G44: =F44*1000 -> 39700 | H44: 5955 | I44: 11.33 | J44: =I44*1000 -> 11330 | K44: 1699.5 | L44: =G44+J44 -> 51030 | M44: =H44+K44 -> 7654.5 | N44: 5 | O44: 5.77 | P44: 865.5 | Q44: 5.56 | R44: 834
A45: 2022 | B45: June | C45: 20.38 | D45: =C45*1000 -> 20380 | E45: 2967.75 | F45: 39.08 | G45: =F45*1000 -> 39080 | H45: 5862.15 | I45: 8.49 | J45: =I45*1000 -> 8490 | K45: 1273.5 | L45: =G45+J45 -> 47570 | M45: =H45+K45 -> 7135.65 | N45: 6 | O45: 1.03 | P45: 154.5 | Q45: 1.4 | R45: 210
A46: 2022 | B46: July | C46: 16.87 | D46: =C46*1000 -> 16870 | E46: 3031.5 | F46: 29.64 | G46: =F46*1000 -> 29640 | H46: 4446 | I46: 10.98 | J46: =I46*1000 -> 10980 | K46: 17667 | L46: =G46+J46 -> 40620 | M46: =H46+K46 -> 22113 | N46: 7 | O46: 1.1 | P46: 165 | Q46: 1.43 | R46: 214.5
A47: 2022 | B47: August | C47: 8.91 | D47: =C47*1000 -> 8910 | E47: 1869.5 | F47: 51.19 | G47: =F47*1000 -> 51190 | H47: 7678.5 | I47: 7.69 | J47: =I47*1000 -> 7690 | K47: 13403.5 | L47: =G47+J47 -> 58880 | M47: =H47+K47 -> 21082 | N47: 8 | O47: 0.84 | P47: 63 | Q47: 0.51 | R47: 38.25
...
