Workbook

Sheet TOTAL
A1: Site Name | B1: Day | C1: Month | D1: Year | E1: Total Electricity Kwh | F1: Electricity Tariff ($/Kwh) | G1: Natual Gas (m3) | H1: Natural Gas $/m3 | I1: Water Utility Supply (m3) m3 | J1: Water Utility Supply (m3) $/m3 | K1: Room Nights | L1: Total Guests | M1: Utilities day cost dh
A2: Mumbai | B2: 1 | C2: 2 | D2: 2023 | E2: =(IF('Daily HLP'!H4>0,'Daily HLP'!H4,0)) -> 22366 | F2: 10 | G2: =(IF('Daily HLP'!L4>0,'Daily HLP'!L4,0)) -> 1161.285 | H2: 66 | I2: =(IF('Daily HLP'!O4>0,'Daily HLP'!O4,0)) -> 222 | J2: 100 | K2: =Occupancy!G2 -> 161 | L2: =Occupancy!F2 -> 451 | M2: =E2*F2+G2*H2+#REF!*#REF!+I2*J2 -> #REF!
A3: Mumbai | B3: =B2+1 -> 2 | C3: 2 | D3: 2023 | E3: =(IF('Daily HLP'!H5>0,'Daily HLP'!H5,0)) -> 22458 | F3: 10 | G3: =(IF('Daily HLP'!L5>0,'Daily HLP'!L5,0)) -> 1083 | H3: 66 | I3: =(IF('Daily HLP'!O5>0,'Daily HLP'!O5,0)) -> 249 | J3: 100 | K3: =Occupancy!G3 -> 152 | L3: =Occupancy!F3 -> 351 | M3: =E3*F3+G3*H3+#REF!*#REF!+I3*J3 -> #REF!
A4: Mumbai | B4: =B3+1 -> 3 | C4: 2 | D4: 2023 | E4: =(IF('Daily HLP'!H6>0,'Daily HLP'!H6,0)) -> 23549.31 | F4: 10 | G4: =(IF('Daily HLP'!L6>0,'Daily HLP'!L6,0)) -> 1112 | H4: 66 | I4: =(IF('Daily HLP'!O6>0,'Daily HLP'!O6,0)) -> 277 | J4: 100 | K4: =Occupancy!G4 -> 176 | L4: =Occupancy!F4 -> 369 | M4: =E4*F4+G4*H4+#REF!*#REF!+I4*J4 -> #REF!
A5: Mumbai | B5: =B4+1 -> 4 | C5: 2 | D5: 2023 | E5: =(IF('Daily HLP'!H7>0,'Daily HLP'!H7,0)) -> 22365.69 | F5: 10 | G5: =(IF('Daily HLP'!L7>0,'Daily HLP'!L7,0)) -> 1150 | H5: 66 | I5: =(IF('Daily HLP'!O7>0,'Daily HLP'!O7,0)) -> 265 | J5: 100 | K5: =Occupancy!G5 -> 179 | L5: =Occupancy!F5 -> 455 | M5: =E5*F5+G5*H5+#REF!*#REF!+I5*J5 -> #REF!
A6: Mumbai | B6: =B5+1 -> 5 | C6: 2 | D6: 2023 | E6: =(IF('Daily HLP'!H8>0,'Daily HLP'!H8,0)) -> 23051.87 | F6: 10 | G6: =(IF('Daily HLP'!L8>0,'Daily HLP'!L8,0)) -> 1134.2 | H6: 66 | I6: =(IF('Daily HLP'!O8>0,'Daily HLP'!O8,0)) -> 302 | J6: 100 | K6: =Occupancy!G6 -> 174 | L6: =Occupancy!F6 -> 482 | M6: =E6*F6+G6*H6+#REF!*#REF!+I6*J6 -> #REF!
A7: Mumbai | B7: =B6+1 -> 6 | C7: 2 | D7: 2023 | E7: =(IF('Daily HLP'!H9>0,'Daily HLP'!H9,0)) -> 23696.13 | F7: 10 | G7: =(IF('Daily HLP'!L9>0,'Daily HLP'!L9,0)) -> 1087.8 | H7: 66 | I7: =(IF('Daily HLP'!O9>0,'Daily HLP'!O9,0)) -> 311 | J7: 100 | K7: =Occupancy!G7 -> 167 | L7: =Occupancy!F7 -> 551 | M7: =E7*F7+G7*H7+#REF!*#REF!+I7*J7 -> #REF!
A8: Mumbai | B8: =B7+1 -> 7 | C8: 2 | D8: 2023 | E8: =(IF('Daily HLP'!H10>0,'Daily HLP'!H10,0)) -> 23753 | F8: 10 | G8: =(IF('Daily HLP'!L10>0,'Daily HLP'!L10,0)) -> 1130 | H8: 66 | I8: =(IF('Daily HLP'!O10>0,'Daily HLP'!O10,0)) -> 220 | J8: 100 | K8: =Occupancy!G8 -> 161 | L8: =Occupancy!F8 -> 658 | M8: =E8*F8+G8*H8+#REF!*#REF!+I8*J8 -> #REF!
A9: Mumbai | B9: =B8+1 -> 8 | C9: 2 | D9: 2023 | E9: =(IF('Daily HLP'!H11>0,'Daily HLP'!H11,0)) -> 23272 | F9: 10 | G9: =(IF('Daily HLP'!L11>0,'Daily HLP'!L11,0)) -> 1248 | H9: 66 | I9: =(IF('Daily HLP'!O11>0,'Daily HLP'!O11,0)) -> 415 | J9: 100 | K9: =Occupancy!G9 -> 145 | L9: =Occupancy!F9 -> 542 | M9: =E9*F9+G9*H9+#REF!*#REF!+I9*J9 -> #REF!
A10: Mumbai | B10: =B9+1 -> 9 | C10: 2 | D10: 2023 | E10: =(IF('Daily HLP'!H12>0,'Daily HLP'!H12,0)) -> 22239.42 | F10: 10 | G10: =(IF('Daily HLP'!L12>0,'Daily HLP'!L12,0)) -> 1162.76 | H10: 66 | I10: =(IF('Daily HLP'!O12>0,'Daily HLP'!O12,0)) -> 105 | J10: 100 | K10: =Occupancy!G10 -> 161 | L10: =Occupancy!F10 -> 398 | M10: =E10*F10+G10*H10+#REF!*#REF!+I10*J10 -> #REF!
A11: Mumbai | B11: =B10+1 -> 10 | C11: 2 | D11: 2023 | E11: =(IF('Daily HLP'!H13>0,'Daily HLP'!H13,0)) -> 22634.09 | F11: 10 | G11: =(IF('Daily HLP'!L13>0,'Daily HLP'!L13,0)) -> 1074.82 | H11: 66 | I11: =(IF('Daily HLP'!O13>0,'Daily HLP'!O13,0)) -> 47 | J11: 100 | K11: =Occupancy!G11 -> 158 | L11: =Occupancy!F11 -> 474 | M11: =E11*F11+G11*H11+#REF!*#REF!+I11*J11 -> #REF!
A12: Mumbai | B12: =B11+1 -> 11 | C12: 2 | D12: 2023 | E12: =(IF('Daily HLP'!H14>0,'Daily HLP'!H14,0)) -> 21484.03 | F12: 10 | G12: =(IF('Daily HLP'!L14>0,'Daily HLP'!L14,0)) -> 1066.42 | H12: 66 | I12: =(IF('Daily HLP'!O14>0,'Daily HLP'!O14,0)) -> 54 | J12: 100 | K12: =Occupancy!G12 -> 164 | L12: =Occupancy!F12 -> 0 | M12: =E12*F12+G12*H12+#REF!*#REF!+I12*J12 -> #REF!
A13: Mumbai | B13: =B12+1 -> 12 | C13: 2 | D13: 2023 | E13: =(IF('Daily HLP'!H15>0,'Daily HLP'!H15,0)) -> 20559.38 | F13: 10 | G13: =(IF('Daily HLP'!L15>0,'Daily HLP'!L15,0)) -> 741.61 | H13: 66 | I13: =(IF('Daily HLP'!O15>0,'Daily HLP'!O15,0)) -> 57 | J13: 100 | K13: =Occupancy!G13 -> 164 | L13: =Occupancy!F13 -> 0 | M13: =E13*F13+G13*H13+#REF!*#REF!+I13*J13 -> #REF!
A14: Mumbai | B14: =B13+1 -> 13 | C14: 2 | D14: 2023 | E14: =(IF('Daily HLP'!H16>0,'Daily HLP'!H16,0)) -> 21408.77 | F14: 10 | G14: =(IF('Daily HLP'!L16>0,'Daily HLP'!L16,0)) -> 738.4136 | H14: 66 | I14: =(IF('Daily HLP'!O16>0,'Daily HLP'!O16,0)) -> 64 | J14: 100 | K14: =Occupancy!G14 -> 167 | L14: =Occupancy!F14 -> 0 | M14: =E14*F14+G14*H14+#REF!*#REF!+I14*J14 -> #REF!
... A29: Mumbai | B29: =B28+1 -> 28 | C29: 2 | D29: 2023 | E29: =(IF('Daily HLP'!H31>0,'Daily HLP'!H31,0)) -> 22679.05 | F29: 10 | G29: =(IF('Daily HLP'!L31>0,'Daily HLP'!L31,0)) -> 1186 | H29: 66 | I29: =(IF('Daily HLP'!O31>0,'Daily HLP'!O31,0)) -> 202 | J29: 100 | K29: =Occupancy!G29 -> 0 | L29: =Occupancy!F29 -> 0 | M29: =E29*F29+G29*H29+#REF!*#REF!+I29*J29 -> #REF!
A30: Mumbai | B30: =B29+1 -> 29 | C30: 2 | D30: 2023 | K30: =Occupancy!G30 -> 0 | L30: =Occupancy!F30 -> 0 | M30: =E30*F30+G30*H30+#REF!*#REF!+I30*J30 -> #REF!
A31: Mumbai | B31: =B30+1 -> 30 | C31: 2 | D31: 2023 | K31: =Occupancy!G31 -> 0 | L31: =Occupancy!F31 -> 0 | M31: =E31*F31+G31*H31+#REF!*#REF!+I31*J31 -> #REF!
A32: Mumbai | B32: =B31+1 -> 31 | C32: 2 | D32: 2023 | K32: =Occupancy!G32 -> 0 | L32: =Occupancy!F32 -> 0

Sheet Submetering
A1: Site Name | B1: Day | C1: Month | D1: Year | E1: ='Section Load'!F4 -> HVAC | F1: ='Section Load'!G4 -> Fire & Emergency PP | G1: ='Section Load'!H4 -> Main PP | H1: ='Section Load'!I4 -> Lighting PP | I1: ='Section Load'!J4 -> CH-1+ CH2+CH3+CH4 | J1: ='Section Load'!K4 -> Chilled water Pump | K1: ='Section Load'!L4 -> Ball Room-1 | L1: ='Section Load'!M4 -> Ball Room-2 | ... AL1: ='Section Load'!AM4 -> Cooling Tower | AM1: R.o.plant | AN1: STP Water Prod | AO1: Domestic Zone-1 | AP1: Domestic Zone-2 | AQ1: Domestic Zone-3 | AR1: Flush Zone -1 | AS1: Flush Zone -2 | AT1: Flush Zone -3 | AU1: Swimming pool | AV1: B2 Laundry | AW1: Boiler Feed Water | AX1: cooling tower filling water | AY1: STP flush(new water meter) | AZ1: Garden Water Pump | BA1: Flush Zone 2 pump meter | BB1: Flush Zone 3 Pump Meter (wtp transfer ) | BC1: Flush Tanker-Zone-1 | BD1: Total Domestic Water (Tanker (R.O) +BMC) | BE1: Total Domestic Consumption | BF1: Total STP Consumption | BG1: ='Section Load'!AN4 -> MGL | BH1: ='Section Load'!AO4 -> HWG | BI1: ='Section Load'!AP4 -> Prato | BJ1: ='Section Load'!AQ4 -> BR-1 | BK1: ='Section Load'!AR4 -> SanQi IND | BL1: ='Section Load'!AS4 -> SanQi JPN | BM1: ='Section Load'!AT4 -> Boiler
A2: Mumbai | B2: 1 | C2: 2 | D2: 2023 | E2: =(IF('Section Load'!F5>0,'Section Load'!F5,0)) -> 3155 | F2: =(IF('Section Load'!G5>0,'Section Load'!G5,0)) -> 1493.44 | G2: =(IF('Section Load'!H5>0,'Section Load'!H5,0)) -> 2665 | H2: =(IF('Section Load'!I5>0,'Section Load'!I5,0)) -> 2949 | I2: =(IF('Section Load'!J5>0,'Section Load'!J5,0)) -> 5272.36 | J2: =(IF('Section Load'!K5>0,'Section Load'!K5,0)) -> 2516 | K2: =(IF('Section Load'!L5>0,'Section Load'!L5,0)) -> 1254 | L2: =(IF('Section Load'!M5>0,'Section Load'!M5,0)) -> 1049 | ... AL2: =(IF('Section Load'!AM5>0,'Section Load'!AM5,0)) -> 507 | AM2: =(IF('Water Report'!$D$7>0,'Water Report'!$D$7,0)) -> 119 | AN2: =(IF('Water Report'!$D$8>0,'Water Report'!$D$8,0)) -> 143 | AO2: =(IF('Water Report'!$D$9>0,'Water Report'!$D$9,0)) -> 129 | AP2: =(IF('Water Report'!$D$10>0,'Water Report'!$D$10,0)) -> 29 | AQ2: =(IF('Water Report'!$D$11>0,'Water Report'!$D$11,0)) -> 7 | AR2: =(IF('Water Report'!$D$13>0,'Water Report'!$D$13,0)) -> 15 | AS2: =(IF('Water Report'!$D$14>0,'Water Report'!$D$14,0)) -> 5 | AT2: =(IF('Water Report'!$D$15>0,'Water Report'!$D$15,0)) -> 8 | AU2: =(IF('Water Report'!$D$17>0,'Water Report'!$D$17,0)) -> 0 | AV2: =(IF('Water Report'!$D$18>0,'Water Report'!$D$18,0)) -> 11 | AW2: =(IF('Water Report'!$D$19>0,'Water Report'!$D$19,0)) -> 14 | AX2: =(IF('Water Report'!$D$21>0,'Water Report'!$D$21,0)) -> 154 | AY2: =(IF('Water Report'!$D$22>0,'Water Report'!$D$22,0)) -> 0 | AZ2: =(IF('Water Report'!$D$23>0,'Water Report'!$D$23,0)) -> 7 | BA2: =(IF('Water Report'!$D$14>0,'Water Report'!$D$14,0)) -> 5 | BB2: =(IF('Water Report'!$D$15>0,'Water Report'!$D$15,0)) -> 8 | BC2: =(IF('Water Report'!$D$13>0,'Water Report'!$D$13,0)) -> 15 | BD2: =(IF('Water Report'!$D$24>0,'Water Report'!$D$24,0)) -> 222 | BE2: =(IF('Water Report'!$D$25>0,'Water Report'!$D$25,0)) -> 178 | BF2: =(IF('Water Report'!$D$27>0,'Water Report'!$D$27,0)) -> 176 | BG2: =(IF('Section Load'!AN5>0,'Section Load'!AN5,0)) -> 1161.285 | BH2: =(IF('Section Load'!AO5>0,'Section Load'!AO5,0)) -> 370 | BI2: =(IF('Section Load'!AP5>0,'Section Load'!AP5,0)) -> 0 | BJ2: =(IF('Section Load'!AQ5>0,'Section Load'!AQ5,0)) -> 129 | BK2: =(IF('Section Load'!AR5>0,'Section Load'!AR5,0)) -> 51 | BL2: =(IF('Section Load'!AS5>0,'Section Load'!AS5,0)) -> 0 | BM2: =(IF('Section Load'!AT5>0,'Section Load'!AT5,0)) -> 611.285
A3: Mumbai | B3: =B2+1 -> 2 | C3: 2 | D3: 2023 | E3: =(IF('Section Load'!F6>0,'Section Load'!F6,0)) -> 3052.71 | F3: =(IF('Section Load'!G6>0,'Section Load'!G6,0)) -> 1444.96 | G3: =(IF('Section Load'!H6>0,'Section Load'!H6,0)) -> 2647.57 | H3: =(IF('Section Load'!I6>0,'Section Load'!I6,0)) -> 2798.19 | I3: =(IF('Section Load'!J6>0,'Section Load'!J6,0)) -> 4638.19 | J3: =(IF('Section Load'!K6>0,'Section Load'!K6,0)) -> 2483.99 | K3: =(IF('Section Load'!L6>0,'Section Load'!L6,0)) -> 1293.39 | L3: =(IF('Section Load'!M6>0,'Section Load'!M6,0)) -> 1009 | ... AL3: =(IF('Section Load'!AM6>0,'Section Load'!AM6,0)) -> 582 | AM3: =(IF('Water Report'!$E$7>0,'Water Report'!$E$7,0)) -> 129 | AN3: =(IF('Water Report'!$E$8>0,'Water Report'!$E$8,0)) -> 74 | AO3: =(IF('Water Report'!$E$9>0,'Water Report'!$E$9,0)) -> 142 | AP3: =(IF('Water Report'!$E$10>0,'Water Report'!$E$10,0)) -> 15 | AQ3: =(IF('Water Report'!$E$11>0,'Water Report'!$E$11,0)) -> 16 | AR3: =(IF('Water Report'!$E$13>0,'Water Report'!$E$13,0)) -> 15 | AS3: =(IF('Water Report'!$E$14>0,'Water Report'!$E$14,0)) -> 6 | AT3: =(IF('Water Report'!$E$15>0,'Water Report'!$E$15,0)) -> 7 | AU3: =(IF('Water Report'!$E$17>0,'Water Report'!$E$17,0)) -> 2 | AV3: =(IF('Water Report'!$E$18>0,'Water Report'!$E$18,0)) -> 9 | AW3: =(IF('Water Report'!$E$19>0,'Water Report'!$E$19,0)) -> 12 | AX3: =(IF('Water Report'!$E$21>0,'Water Report'!$E$21,0)) -> 116 | AY3: =(IF('Water Report'!$E$22>0,'Water Report'!$E$22,0)) -> 0 | AZ3: =(IF('Water Report'!$E$23>0,'Water Report'!$E$23,0)) -> 3 | BA3: =(IF('Water Report'!$E$14>0,'Water Report'!$E$14,0)) -> 6 | BB3: =(IF('Water Report'!$E$15>0,'Water Report'!$E$15,0)) -> 7 | BC3: =(IF('Water Report'!$E$13>0,'Water Report'!$E$13,0)) -> 15 | BD3: =(IF('Water Report'!$E$24>0,'Water Report'!$E$24,0)) -> 249 | BE3: =(IF('Water Report'!$E$25>0,'Water Report'!$E$25,0)) -> 186 | BF3: =(IF('Water Report'!$E$27>0,'Water Report'!$E$27,0)) -> 134 | BG3: =(IF('Section Load'!AN6>0,'Section Load'!AN6,0)) -> 1083 | BH3: =(IF('Section Load'!AO6>0,'Section Load'!AO6,0)) -> 293 | BI3: =(IF('Section Load'!AP6>0,'Section Load'!AP6,0)) -> 0 | BJ3: =(IF('Section Load'!AQ6>0,'Section Load'!AQ6,0)) -> 111 | BK3: =(IF('Section Load'!AR6>0,'Section Load'!AR6,0)) -> 43 | BL3: =(IF('Section Load'!AS6>0,'Section Load'!AS6,0)) -> 0 | BM3: =(IF('Section Load'!AT6>0,'Section Load'!AT6,0)) -> 636
A4: Mumbai | B4: =B3+1 -> 3 | C4: 2 | D4: 2023 | E4: =(IF('Section Load'!F7>0,'Section Load'!F7,0)) -> 2999.29 | F4: =(IF('Section Load'!G7>0,'Section Load'!G7,0)) -> 1455.03 | G4: =(IF('Section Load'!H7>0,'Section Load'!H7,0)) -> 2822.43 | H4: =(IF('Section Load'!I7>0,'Section Load'!I7,0)) -> 2880.23 | I4: =(IF('Section Load'!J7>0,'Section Load'!J7,0)) -> 3321 | J4: =(IF('Section Load'!K7>0,'Section Load'!K7,0)) -> 2638.01 | K4: =(IF('Section Load'!L7>0,'Section Load'!L7,0)) -> 1949.68 | L4: =(IF('Section Load'!M7>0,'Section Load'!M7,0)) -> 1123.9 | ... AL4: =(IF('Section Load'!AM7>0,'Section Load'!AM7,0)) -> 504 | AM4: =(IF('Water Report'!$F$7>0,'Water Report'!$F$7,0)) -> 129.3 | AN4: =(IF('Water Report'!$F$8>0,'Water Report'!$F$8,0)) -> 74 | AO4: =(IF('Water Report'!$F$9>0,'Water Report'!$G$9,0)) -> 145 | AP4: =(IF('Water Report'!$F$10>0,'Water Report'!$F$10,0)) -> 17 | AQ4: =(IF('Water Report'!$F$11>0,'Water Report'!$F$11,0)) -> 30 | AR4: =(IF('Water Report'!$F$13>0,'Water Report'!$F$13,0)) -> 20 | AS4: =(IF('Water Report'!$F$14>0,'Water Report'!$F$14,0)) -> 4 | AT4: =(IF('Water Report'!$F$15>0,'Water Report'!$F$15,0)) -> 9 | AU4: =(IF('Water Report'!$F$17>0,'Water Report'!$F$17,0)) -> 2 | AV4: =(IF('Water Report'!$F$18>0,'Water Report'!$F$18,0)) -> 14 | AW4: =(IF('Water Report'!$F$19>0,'Water Report'!$F$19,0)) -> 11 | AX4: =(IF('Water Report'!$F$21>0,'Water Report'!$F$21,0)) -> 121 | AY4: =(IF('Water Report'!$F$22>0,'Water Report'!$F$22,0)) -> 0 | AZ4: =(IF('Water Report'!$F$23>0,'Water Report'!$F$23,0)) -> 6 | BA4: =(IF('Water Report'!$F$14>0,'Water Report'!$F$14,0)) -> 4 | BB4: =(IF('Water Report'!$F$15>0,'Water Report'!$F$15,0)) -> 9 | BC4: =(IF('Water Report'!$F$13>0,'Water Report'!$F$13,0)) -> 20 | BD4: =(IF('Water Report'!$F$24>0,'Water Report'!$F$24,0)) -> 277 | BE4: =(IF('Water Report'!$F$25>0,'Water Report'!$F$25,0)) -> 200 | BF4: =(IF('Water Report'!$F$27>0,'Water Report'!$F$27,0)) -> 147 | BG4: =(IF('Section Load'!AN7>0,'Section Load'!AN7,0)) -> 1112 | BH4: =(IF('Section Load'!AO7>0,'Section Load'!AO7,0)) -> 304 | BI4: =(IF('Section Load'!AP7>0,'Section Load'!AP7,0)) -> 0 | BJ4: =(IF('Section Load'!AQ7>0,'Section Load'!AQ7,0)) -> 101 | BK4: =(IF('Section Load'!AR7>0,'Section Load'!AR7,0)) -> 49 | BL4: =(IF('Section Load'!AS7>0,'Section Load'!AS7,0)) -> 0 | BM4: =(IF('Section Load'!AT7>0,'Section Load'!AT7,0)) -> 658
A5: Mumbai | B5: =B4+1 -> 4 | C5: 2 | D5: 2023 | E5: =(IF('Section Load'!F8>0,'Section Load'!F8,0)) -> 2937 | F5: =(IF('Section Load'!G8>0,'Section Load'!G8,0)) -> 1470.57 | G5: =(IF('Section Load'!H8>0,'Section Load'!H8,0)) -> 2762 | H5: =(IF('Section Load'!I8>0,'Section Load'!I8,0)) -> 2818.34 | I5: =(IF('Section Load'!J8>0,'Section Load'!J8,0)) -> 3150.57 | J5: =(IF('Section Load'!K8>0,'Section Load'!K8,0)) -> 2585 | K5: =(IF('Section Load'!L8>0,'Section Load'!L8,0)) -> 1188.93 | L5: =(IF('Section Load'!M8>0,'Section Load'!M8,0)) -> 925.1 | ... AL5: =(IF('Section Load'!AM8>0,'Section Load'!AM8,0)) -> 467 | AM5: =(IF('Water Report'!$G$7>0,'Water Report'!$F$7,0)) -> 129.3 | AN5: =(IF('Water Report'!$G$8>0,'Water Report'!$F$8,0)) -> 74 | AO5: =(IF('Water Report'!$G$9>0,'Water Report'!$H$9,0)) -> 114 | AP5: =(IF('Water Report'!$G$10>0,'Water Report'!$G$10,0)) -> 18 | AQ5: =(IF('Water Report'!$G$11>0,'Water Report'!$G$11,0)) -> 30 | AR5: =(IF('Water Report'!$G$13>0,'Water Report'!$G$13,0)) -> 32 | AS5: =(IF('Water Report'!$G$14>0,'Water Report'!$G$14,0)) -> 3 | AT5: =(IF('Water Report'!$G$15>0,'Water Report'!$G$15,0)) -> 5 | AU5: =(IF('Water Report'!$G$17>0,'Water Report'!$G$17,0)) -> 2 | AV5: =(IF('Water Report'!$G$18>0,'Water Report'!$G$18,0)) -> 9 | AW5: =(IF('Water Report'!$G$19>0,'Water Report'!$G$19,0)) -> 4 | AX5: =(IF('Water Report'!$G$21>0,'Water Report'!$G$21,0)) -> 143 | AY5: =(IF('Water Report'!$G$22>0,'Water Report'!$G$22,0)) -> 0 | AZ5: =(IF('Water Report'!$G$23>0,'Water Report'!$G$23,0)) -> 10 | BA5: =(IF('Water Report'!$G$14>0,'Water Report'!$G$14,0)) -> 3 | BB5: =(IF('Water Report'!$G$15>0,'Water Report'!$G$15,0)) -> 5 | BC5: =(IF('Water Report'!$G$13>0,'Water Report'!$G$13,0)) -> 32 | BD5: =(IF('Water Report'!$G$24>0,'Water Report'!$G$24,0)) -> 265 | BE5: =(IF('Water Report'!$G$25>0,'Water Report'!$G$25,0)) -> 201 | BF5: =(IF('Water Report'!$G$27>0,'Water Report'!$G$27,0)) -> 185 | BG5: =(IF('Section Load'!AN8>0,'Section Load'!AN8,0)) -> 1150 | BH5: =(IF('Section Load'!AO8>0,'Section Load'!AO8,0)) -> 305 | BI5: =(IF('Section Load'!AP8>0,'Section Load'!AP8,0)) -> 0 | BJ5: =(IF('Section Load'!AQ8>0,'Section Load'!AQ8,0)) -> 116 | BK5: =(IF('Section Load'!AR8>0,'Section Load'!AR8,0)) -> 54 | BL5: =(IF('Section Load'!AS8>0,'Section Load'!AS8,0)) -> 0 | BM5: =(IF('Section Load'!AT8>0,'Section Load'!AT8,0)) -> 675
A6: Mumbai | B6: =B5+1 -> 5 | C6: 2 | D6: 2023 | E6: =(IF('Section Load'!F9>0,'Section Load'!F9,0)) -> 3086.83 | F6: =(IF('Section Load'!G9>0,'Section Load'!G9,0)) -> 1511 | G6: =(IF('Section Load'!H9>0,'Section Load'!H9,0)) -> 2739.43 | H6: =(IF('Section Load'!I9>0,'Section Load'!I9,0)) -> 2837.21 | I6: =(IF('Section Load'!J9>0,'Section Load'!J9,0)) -> 3609.84 | J6: =(IF('Section Load'!K9>0,'Section Load'!K9,0)) -> 2660 | K6: =(IF('Section Load'!L9>0,'Section Load'!L9,0)) -> 1129.36 | L6: =(IF('Section Load'!M9>0,'Section Load'!M9,0)) -> 1036.59 | ... AL6: =(IF('Section Load'!AM9>0,'Section Load'!AM9,0)) -> 483 | AM6: =(IF('Water Report'!$H$7>0,'Water Report'!$H$7,0)) -> 124 | AN6: =(IF('Water Report'!$H$8>0,'Water Report'!$H$8,0)) -> 66 | AO6: =(IF('Water Report'!$H$9>0,'Water Report'!$H$9,0)) -> 114 | AP6: =(IF('Water Report'!$H$10>0,'Water Report'!$H$10,0)) -> 22 | AQ6: =(IF('Water Report'!$H$11>0,'Water Report'!$H$11,0)) -> 26 | AR6: =(IF('Water Report'!$H$13>0,'Water Report'!$H$13,0)) -> 20 | AS6: =(IF('Water Report'!$H$14>0,'Water Report'!$H$14,0)) -> 2 | AT6: =(IF('Water Report'!$H$15>0,'Water Report'!$H$15,0)) -> 7 | AU6: =(IF('Water Report'!$H$17>0,'Water Report'!$H$17,0)) -> 0 | AV6: =(IF('Water Report'!$H$18>0,'Water Report'!$H$18,0)) -> 11 | AW6: =(IF('Water Report'!$H$19>0,'Water Report'!$H$19,0)) -> 28 | AX6: =(IF('Water Report'!$H$21>0,'Water Report'!$H$21,0)) -> 61 | AY6: =(IF('Water Report'!$H$22>0,'Water Report'!$H$22,0)) -> 0 | AZ6: =(IF('Water Report'!$H$23>0,'Water Report'!$H$23,0)) -> 0 | BA6: =(IF('Water Report'!$H$14>0,'Water Report'!$H$14,0)) -> 2 | BB6: =(IF('Water Report'!$H$15>0,'Water Report'!$H$15,0)) -> 7 | BC6: =(IF('Water Report'!$H$13>0,'Water Report'!$H$13,0)) -> 20 | BD6: =(IF('Water Report'!$H$24>0,'Water Report'!$H$24,0)) -> 302 | BE6: =(IF('Water Report'!$H$25>0,'Water Report'!$H$25,0)) -> 171 | BF6: =(IF('Water Report'!$H$27>0,'Water Report'!$H$27,0)) -> 81 | BG6: =(IF('Section Load'!AN9>0,'Section Load'!AN9,0)) -> 1134.2 | BH6: =(IF('Section Load'!AO9>0,'Section Load'!AO9,0)) -> 342 | BI6: =(IF('Section Load'!AP9>0,'Section Load'!AP9,0)) -> 0 | BJ6: =(IF('Section Load'!AQ9>0,'Section Load'!AQ9,0)) -> 109 | BK6: =(IF('Section Load'!AR9>0,'Section Load'!AR9,0)) -> 56 | BL6: =(IF('Section Load'!AS9>0,'Section Load'!AS9,0)) -> 0.5 | BM6: =(IF('Section Load'!AT9>0,'Section Load'!AT9,0)) -> 626.7
A7: Mumbai | B7: =B6+1 -> 6 | C7: 2 | D7: 2023 | E7: =(IF('Section Load'!F10>0,'Section Load'!F10,0)) -> 3158.17 | F7: =(IF('Section Load'!G10>0,'Section Load'!G10,0)) -> 1555 | G7: =(IF('Section Load'!H10>0,'Section Load'!H10,0)) -> 2717.57 | H7: =(IF('Section Load'!I10>0,'Section Load'!I10,0)) -> 2829 | I7: =(IF('Section Load'!J10>0,'Section Load'!J10,0)) -> 3625.49 | J7: =(IF('Section Load'!K10>0,'Section Load'!K10,0)) -> 2664 | K7: =(IF('Section Load'!L10>0,'Section Load'!L10,0)) -> 1416.64 | L7: =(IF('Section Load'!M10>0,'Section Load'!M10,0)) -> 1112.41 | ... AL7: =(IF('Section Load'!AM10>0,'Section Load'!AM10,0)) -> 442 | AM7: =(IF('Water Report'!$I$7>0,'Water Report'!$I$7,0)) -> 111 | AN7: =(IF('Water Report'!$I$8>0,'Water Report'!$I$8,0)) -> 88 | AO7: =(IF('Water Report'!$I$9>0,'Water Report'!$I$9,0)) -> 135 | AP7: =(IF('Water Report'!$I$10>0,'Water Report'!$I$10,0)) -> 27 | AQ7: =(IF('Water Report'!$I$11>0,'Water Report'!$I$11,0)) -> 19 | AR7: =(IF('Water Report'!$I$13>0,'Water Report'!$I$13,0)) -> 30 | AS7: =(IF('Water Report'!$I$14>0,'Water Report'!$I$14,0)) -> 4 | AT7: =(IF('Water Report'!$I$15>0,'Water Report'!$I$15,0)) -> 4 | AU7: =(IF('Water Report'!$I$17>0,'Water Report'!$I$17,0)) -> 0 | AV7: =(IF('Water Report'!$I$18>0,'Water Report'!$I$18,0)) -> 11 | AW7: =(IF('Water Report'!$I$19>0,'Water Report'!$I$19,0)) -> 14 | AX7: =(IF('Water Report'!$I$21>0,'Water Report'!$I$21,0)) -> 118 | AY7: =(IF('Water Report'!$I$22>0,'Water Report'!$I$22,0)) -> 0 | AZ7: =(IF('Water Report'!$I$23>0,'Water Report'!$I$23,0)) -> 9 | BA7: =(IF('Water Report'!$I$14>0,'Water Report'!$I$14,0)) -> 4 | BB7: =(IF('Water Report'!$I$15>0,'Water Report'!$I$15,0)) -> 4 | BC7: =(IF('Water Report'!$I$13>0,'Water Report'!$I$13,0)) -> 30 | BD7: =(IF('Water Report'!$I$24>0,'Water Report'!$I$24,0)) -> 311 | BE7: =(IF('Water Report'!$I$25>0,'Water Report'!$I$25,0)) -> 189 | BF7: =(IF('Water Report'!$I$27>0,'Water Report'!$I$27,0)) -> 157 | BG7: =(IF('Section Load'!AN10>0,'Section Load'!AN10,0)) -> 1087.8 | BH7: =(IF('Section Load'!AO10>0,'Section Load'!AO10,0)) -> 318 | BI7: =(IF('Section Load'!AP10>0,'Section Load'!AP10,0)) -> 0 | BJ7: =(IF('Section Load'!AQ10>0,'Section Load'!AQ10,0)) -> 114 | BK7: =(IF('Section Load'!AR10>0,'Section Load'!AR10,0)) -> 55 | BL7: =(IF('Section Load'!AS10>0,'Section Load'!AS10,0)) -> 0 | BM7: =(IF('Section Load'!AT10>0,'Section Load'!AT10,0)) -> 600.8
A8: Mumbai | B8: =B7+1 -> 7 | C8: 2 | D8: 2023 | E8: =(IF('Section Load'!F11>0,'Section Load'!F11,0)) -> 3302 | F8: =(IF('Section Load'!G11>0,'Section Load'!G11,0)) -> 1488 | G8: =(IF('Section Load'!H11>0,'Section Load'!H11,0)) -> 2729 | H8: =(IF('Section Load'!I11>0,'Section Load'!I11,0)) -> 2806 | I8: =(IF('Section Load'!J11>0,'Section Load'!J11,0)) -> 3472 | J8: =(IF('Section Load'!K11>0,'Section Load'!K11,0)) -> 2678 | K8: =(IF('Section Load'!L11>0,'Section Load'!L11,0)) -> 1524 | L8: =(IF('Section Load'!M11>0,'Section Load'!M11,0)) -> 1116 | ... AL8: =(IF('Section Load'!AM11>0,'Section Load'!AM11,0)) -> 600 | AM8: =(IF('Water Report'!$J$7>0,'Water Report'!$J$7,0)) -> 147 | AN8: =(IF('Water Report'!$J$8>0,'Water Report'!$J$8,0)) -> 94 | AO8: =(IF('Water Report'!$J$9>0,'Water Report'!$J$9,0)) -> 140 | AP8: =(IF('Water Report'!$J$10>0,'Water Report'!$J$10,0)) -> 22 | AQ8: =(IF('Water Report'!$J$11>0,'Water Report'!$J$11,0)) -> 20 | AR8: =(IF('Water Report'!$J$13>0,'Water Report'!$J$13,0)) -> 21 | AS8: =(IF('Water Report'!$J$14>0,'Water Report'!$J$14,0)) -> 2 | AT8: =(IF('Water Report'!$J$15>0,'Water Report'!$J$15,0)) -> 8 | AU8: =(IF('Water Report'!$J$17>0,'Water Report'!$J$17,0)) -> 1 | AV8: =(IF('Water Report'!$J$18>0,'Water Report'!$J$18,0)) -> 10 | AW8: =(IF('Water Report'!$J$19>0,'Water Report'!$J$19,0)) -> 14 | AX8: =(IF('Water Report'!$J$21>0,'Water Report'!$J$21,0)) -> 92 | AY8: =(IF('Water Report'!$J$22>0,'Water Report'!$J$22,0)) -> 0 | AZ8: =(IF('Water Report'!$J$23>0,'Water Report'!$J$23,0)) -> 4 | BA8: =(IF('Water Report'!$J$14>0,'Water Report'!$J$14,0)) -> 2 | BB8: =(IF('Water Report'!$J$15>0,'Water Report'!$J$15,0)) -> 8 | BC8: =(IF('Water Report'!$J$13>0,'Water Report'!$J$13,0)) -> 21 | BD8: =(IF('Water Report'!$J$24>0,'Water Report'!$J$24,0)) -> 220 | BE8: =(IF('Water Report'!$J$25>0,'Water Report'!$J$25,0)) -> 192 | BF8: =(IF('Water Report'!$J$27>0,'Water Report'!$J$27,0)) -> 117 | BG8: =(IF('Section Load'!AN11>0,'Section Load'!AN11,0)) -> 1130 | BH8: =(IF('Section Load'!AO11>0,'Section Load'!AO11,0)) -> 320 | BI8: =(IF('Section Load'!AP11>0,'Section Load'!AP11,0)) -> 0 | BJ8: =(IF('Section Load'!AQ11>0,'Section Load'!AQ11,0)) -> 116 | BK8: =(IF('Section Load'!AR11>0,'Section Load'!AR11,0)) -> 47 | BL8: =(IF('Section Load'!AS11>0,'Section Load'!AS11,0)) -> 0 | BM8: =(IF('Section Load'!AT11>0,'Section Load'!AT11,0)) -> 647
A9: Mumbai | B9: =B8+1 -> 8 | C9: 2 | D9: 2023 | E9: =(IF('Section Load'!F12>0,'Section Load'!F12,0)) -> 3250.79 | F9: =(IF('Section Load'!G12>0,'Section Load'!G12,0)) -> 1465 | G9: =(IF('Section Load'!H12>0,'Section Load'!H12,0)) -> 2794 | H9: =(IF('Section Load'!I12>0,'Section Load'!I12,0)) -> 2838 | I9: =(IF('Section Load'!J12>0,'Section Load'!J12,0)) -> 3412 | J9: =(IF('Section Load'!K12>0,'Section Load'!K12,0)) -> 2448 | K9: =(IF('Section Load'!L12>0,'Section Load'!L12,0)) -> 1565 | L9: =(IF('Section Load'!M12>0,'Section Load'!M12,0)) -> 946 | ... AL9: =(IF('Section Load'!AM12>0,'Section Load'!AM12,0)) -> 723 | AM9: =(IF('Water Report'!$K$7>0,'Water Report'!$K$7,0)) -> 156 | AN9: =(IF('Water Report'!$K$8>0,'Water Report'!$K$8,0)) -> 1 | AO9: =(IF('Water Report'!$K$9>0,'Water Report'!$K$9,0)) -> 137 | AP9: =(IF('Water Report'!$K$10>0,'Water Report'!$K$10,0)) -> 10 | AQ9: =(IF('Water Report'!$K$11>0,'Water Report'!$K$11,0)) -> 24 | AR9: =(IF('Water Report'!$K$13>0,'Water Report'!$K$13,0)) -> 24 | AS9: =(IF('Water Report'!$K$14>0,'Water Report'!$K$14,0)) -> 9 | AT9: =(IF('Water Report'!$K$15>0,'Water Report'!$K$15,0)) -> 9 | AU9: =(IF('Water Report'!$K$17>0,'Water Report'!$K$17,0)) -> 0 | AV9: =(IF('Water Report'!$K$18>0,'Water Report'!$K$18,0)) -> 13 | AW9: =(IF('Water Report'!$K$19>0,'Water Report'!$K$19,0)) -> 15 | AX9: =(IF('Water Report'!$K$21>0,'Water Report'!$K$21,0)) -> 88 | AY9: =(IF('Water Report'!$K$22>0,'Water Report'!$K$22,0)) -> 0 | AZ9: =(IF('Water Report'!$K$23>0,'Water Report'!$K$23,0)) -> 0 | BA9: =(IF('Water Report'!$K$14>0,'Water Report'!$K$14,0)) -> 9 | BB9: =(IF('Water Report'!$K$15>0,'Water Report'!$K$15,0)) -> 9 | BC9: =(IF('Water Report'!$K$13>0,'Water Report'!$K$13,0)) -> 24 | BD9: =(IF('Water Report'!$K$24>0,'Water Report'!$K$24,0)) -> 415 | BE9: =(IF('Water Report'!$K$25>0,'Water Report'!$K$25,0)) -> 189 | BF9: =(IF('Water Report'!$K$27>0,'Water Report'!$K$27,0)) -> 112 | BG9: =(IF('Section Load'!AN12>0,'Section Load'!AN12,0)) -> 1248 | BH9: =(IF('Section Load'!AO12>0,'Section Load'!AO12,0)) -> 344 | BI9: =(IF('Section Load'!AP12>0,'Section Load'!AP12,0)) -> 0.2 | BJ9: =(IF('Section Load'!AQ12>0,'Section Load'!AQ12,0)) -> 125 | BK9: =(IF('Section Load'!AR12>0,'Section Load'!AR12,0)) -> 57 | BL9: =(IF('Section Load'!AS12>0,'Section Load'!AS12,0)) -> 0 | BM9: =(IF('Section Load'!AT12>0,'Section Load'!AT12,0)) -> 721.8
A10: Mumbai | B10: =B9+1 -> 9 | C10: 2 | D10: 2023 | E10: =(IF('Section Load'!F13>0,'Section Load'!F13,0)) -> 3086.27 | F10: =(IF('Section Load'!G13>0,'Section Load'!G13,0)) -> 1388.59 | G10: =(IF('Section Load'!H13>0,'Section Load'!H13,0)) -> 2435.86 | H10: =(IF('Section Load'!I13>0,'Section Load'!I13,0)) -> 2782.34 | I10: =(IF('Section Load'!J13>0,'Section Load'!J13,0)) -> 3380.17 | J10: =(IF('Section Load'!K13>0,'Section Load'!K13,0)) -> 2617.79 | K10: =(IF('Section Load'!L13>0,'Section Load'!L13,0)) -> 1214.71 | L10: =(IF('Section Load'!M13>0,'Section Load'!M13,0)) -> 987.55 | ... AL10: =(IF('Section Load'!AM13>0,'Section Load'!AM13,0)) -> 544 | AM10: =(IF('Water Report'!$L$7>0,'Water Report'!$L$7,0)) -> 9 | AN10: =(IF('Water Report'!$L$8>0,'Water Report'!$L$8,0)) -> 45 | AO10: =(IF('Water Report'!$L$9>0,'Water Report'!$L$9,0)) -> 131 | AP10: =(IF('Water Report'!$L$10>0,'Water Report'!$L$10,0)) -> 6 | AQ10: =(IF('Water Report'!$L$11>0,'Water Report'!$L$11,0)) -> 22 | AR10: =(IF('Water Report'!$L$13>0,'Water Report'!$L$13,0)) -> 10 | AS10: =(IF('Water Report'!$L$14>0,'Water Report'!$L$14,0)) -> 3 | AT10: =(IF('Water Report'!$L$15>0,'Water Report'!$L$15,0)) -> 7 | AU10: =(IF('Water Report'!$L$17>0,'Water Report'!$L$17,0)) -> 3 | AV10: =(IF('Water Report'!$L$18>0,'Water Report'!$L$18,0)) -> 11 | AW10: =(IF('Water Report'!$L$19>0,'Water Report'!$L$19,0)) -> 17 | AX10: =(IF('Water Report'!$L$21>0,'Water Report'!$L$21,0)) -> 93 | AY10: =(IF('Water Report'!$L$22>0,'Water Report'!$L$22,0)) -> 0 | AZ10: =(IF('Water Report'!$L$23>0,'Water Report'!$L$23,0)) -> 5 | BA10: =(IF('Water Report'!$L$14>0,'Water Report'!$L$14,0)) -> 3 | BB10: =(IF('Water Report'!$L$15>0,'Water Report'!$L$15,0)) -> 7 | BC10: =(IF('Water Report'!$L$13>0,'Water Report'!$L$13,0)) -> 10 | BD10: =(IF('Water Report'!$L$24>0,'Water Report'!$L$24,0)) -> 105 | BE10: =(IF('Water Report'!$L$25>0,'Water Report'!$L$25,0)) -> 169 | BF10: =(IF('Water Report'!$L$27>0,'Water Report'!$L$27,0)) -> 108 | BG10: =(IF('Section Load'!AN13>0,'Section Load'!AN13,0)) -> 1162.76 | BH10: =(IF('Section Load'!AO13>0,'Section Load'!AO13,0)) -> 305.61 | BI10: =(IF('Section Load'!AP13>0,'Section Load'!AP13,0)) -> 0 | BJ10: =(IF('Section Load'!AQ13>0,'Section Load'!AQ13,0)) -> 84 | BK10: =(IF('Section Load'!AR13>0,'Section Load'!AR13,0)) -> 42 | BL10: =(IF('Section Load'!AS13>0,'Section Load'!AS13,0)) -> 0 | BM10: =(IF('Section Load'!AT13>0,'Section Load'!AT13,0)) -> 731.35
A11: Mumbai | B11: =B10+1 -> 10 | C11: 2 | D11: 2023 | E11: =(IF('Section Load'!F14>0,'Section Load'!F14,0)) -> 3098.94 | F11: =(IF('Section Load'!G14>0,'Section Load'!G14,0)) -> 1391.41 | G11: =(IF('Section Load'!H14>0,'Section Load'!H14,0)) -> 2439.57 | H11: =(IF('Section Load'!I14>0,'Section Load'!I14,0)) -> 2862.66 | I11: =(IF('Section Load'!J14>0,'Section Load'!J14,0)) -> 3491.04 | J11: =(IF('Section Load'!K14>0,'Section Load'!K14,0)) -> 2611.81 | K11: =(IF('Section Load'!L14>0,'Section Load'!L14,0)) -> 1246.29 | L11: =(IF('Section Load'!M14>0,'Section Load'!M14,0)) -> 1005.45 | ... AL11: =(IF('Section Load'!AM14>0,'Section Load'!AM14,0)) -> 506 | AM11: =(IF('Water Report'!$M$7>0,'Water Report'!$M$7,0)) -> 0 | AN11: =(IF('Water Report'!$M$8>0,'Water Report'!$M$8,0)) -> 93 | AO11: =(IF('Water Report'!$M$9>0,'Water Report'!$M$9,0)) -> 114 | AP11: =(IF('Water Report'!$M$10>0,'Water Report'!$M$10,0)) -> 9 | AQ11: =(IF('Water Report'!$M$11>0,'Water Report'!$M$11,0)) -> 22 | AR11: =(IF('Water Report'!$M$13>0,'Water Report'!$M$13,0)) -> 10 | AS11: =(IF('Water Report'!$M$14>0,'Water Report'!$M$14,0)) -> 6 | AT11: =(IF('Water Report'!$M$15>0,'Water Report'!$M$15,0)) -> 6 | AU11: =(IF('Water Report'!$M$17>0,'Water Report'!$M$17,0)) -> 2 | AV11: =(IF('Water Report'!$M$18>0,'Water Report'!$M$18,0)) -> 10 | AW11: =(IF('Water Report'!$M$19>0,'Water Report'!$M$19,0)) -> 13 | AX11: =(IF('Water Report'!$M$21>0,'Water Report'!$M$21,0)) -> 92 | AY11: =(IF('Water Report'!$M$22>0,'Water Report'!$M$22,0)) -> 0 | AZ11: =(IF('Water Report'!$M$23>0,'Water Report'!$M$23,0)) -> 1 | BA11: =(IF('Water Report'!$M$14>0,'Water Report'!$M$14,0)) -> 6 | BB11: =(IF('Water Report'!$M$15>0,'Water Report'!$M$15,0)) -> 6 | BC11: =(IF('Water Report'!$M$13>0,'Water Report'!$M$13,0)) -> 10 | BD11: =(IF('Water Report'!$M$24>0,'Water Report'!$M$24,0)) -> 47 | BE11: =(IF('Water Report'!$M$25>0,'Water Report'!$M$25,0)) -> 157 | BF11: =(IF('Water Report'!$M$27>0,'Water Report'!$M$27,0)) -> 103 | BG11: =(IF('Section Load'!AN14>0,'Section Load'!AN14,0)) -> 1074.82 | BH11: =(IF('Section Load'!AO14>0,'Section Load'!AO14,0)) -> 311.39 | BI11: =(IF('Section Load'!AP14>0,'Section Load'!AP14,0)) -> 0 | BJ11: =(IF('Section Load'!AQ14>0,'Section Load'!AQ14,0)) -> 100 | BK11: =(IF('Section Load'!AR14>0,'Section Load'!AR14,0)) -> 47 | BL11: =(IF('Section Load'!AS14>0,'Section Load'!AS14,0)) -> 0 | BM11: =(IF('Section Load'!AT14>0,'Section Load'!AT14,0)) -> 616.43
A12: Mumbai | B12: =B11+1 -> 11 | C12: 2 | D12: 2023 | E12: =(IF('Section Load'!F15>0,'Section Load'!F15,0)) -> 3210.46 | F12: =(IF('Section Load'!G15>0,'Section Load'!G15,0)) -> 1366.19 | G12: =(IF('Section Load'!H15>0,'Section Load'!H15,0)) -> 2416.75 | H12: =(IF('Section Load'!I15>0,'Section Load'!I15,0)) -> 2794.22 | I12: =(IF('Section Load'!J15>0,'Section Load'!J15,0)) -> 2718.21 | J12: =(IF('Section Load'!K15>0,'Section Load'!K15,0)) -> 2619.87 | K12: =(IF('Section Load'!L15>0,'Section Load'!L15,0)) -> 1156.95 | L12: =(IF('Section Load'!M15>0,'Section Load'!M15,0)) -> 1010.47 | ... AL12: =(IF('Section Load'!AM15>0,'Section Load'!AM15,0)) -> 860 | AM12: =(IF('Water Report'!$N$7>0,'Water Report'!$N$7,0)) -> 0 | AN12: =(IF('Water Report'!$N$8>0,'Water Report'!$N$8,0)) -> 132 | AO12: =(IF('Water Report'!$N$9>0,'Water Report'!$N$9,0)) -> 106 | AP12: =(IF('Water Report'!$N$10>0,'Water Report'!$N$10,0)) -> 10 | AQ12: =(IF('Water Report'!$N$11>0,'Water Report'!$N$11,0)) -> 36 | AR12: =(IF('Water Report'!$N$13>0,'Water Report'!$N$13,0)) -> 8 | AS12: =(IF('Water Report'!$N$14>0,'Water Report'!$N$14,0)) -> 3 | AT12: =(IF('Water Report'!$N$15>0,'Water Report'!$N$15,0)) -> 6 | AU12: =(IF('Water Report'!$N$17>0,'Water Report'!$N$17,0)) -> 2 | AV12: =(IF('Water Report'!$N$18>0,'Water Report'!$N$18,0)) -> 11 | AW12: =(IF('Water Report'!$N$19>0,'Water Report'!$N$19,0)) -> 12 | AX12: =(IF('Water Report'!$N$21>0,'Water Report'!$N$21,0)) -> 109 | AY12: =(IF('Water Report'!$N$22>0,'Water Report'!$N$22,0)) -> 0 | AZ12: =(IF('Water Report'!$N$23>0,'Water Report'!$N$23,0)) -> 2 | BA12: =(IF('Water Report'!$N$14>0,'Water Report'!$N$14,0)) -> 3 | BB12: =(IF('Water Report'!$N$15>0,'Water Report'!$N$15,0)) -> 6 | BC12: =(IF('Water Report'!$N$13>0,'Water Report'!$N$13,0)) -> 8 | BD12: =(IF('Water Report'!$N$24>0,'Water Report'!$N$24,0)) -> 54 | BE12: =(IF('Water Report'!$N$25>0,'Water Report'!$N$25,0)) -> 161 | BF12: =(IF('Water Report'!$N$27>0,'Water Report'!$N$27,0)) -> 119 | BG12: =(IF('Section Load'!AN15>0,'Section Load'!AN15,0)) -> 1066.42 | BH12: =(IF('Section Load'!AO15>0,'Section Load'!AO15,0)) -> 295.92 | BI12: =(IF('Section Load'!AP15>0,'Section Load'!AP15,0)) -> 0 | BJ12: =(IF('Section Load'!AQ15>0,'Section Load'!AQ15,0)) -> 131 | BK12: =(IF('Section Load'!AR15>0,'Section Load'!AR15,0)) -> 49 | BL12: =(IF('Section Load'!AS15>0,'Section Load'!AS15,0)) -> 0 | BM12: =(IF('Section Load'!AT15>0,'Section Load'!AT15,0)) -> 590.5
A13: Mumbai | B13: =B12+1 -> 12 | C13: 2 | D13: 2023 | E13: =(IF('Section Load'!F16>0,'Section Load'!F16,0)) -> 3075.2 | F13: =(IF('Section Load'!G16>0,'Section Load'!G16,0)) -> 1336.16 | G13: =(IF('Section Load'!H16>0,'Section Load'!H16,0)) -> 2375.52 | H13: =(IF('Section Load'!I16>0,'Section Load'!I16,0)) -> 2793.6 | I13: =(IF('Section Load'!J16>0,'Section Load'!J16,0)) -> 2806.04 | J13: =(IF('Section Load'!K16>0,'Section Load'!K16,0)) -> 2614.24 | K13: =(IF('Section Load'!L16>0,'Section Load'!L16,0)) -> 1137.48 | L13: =(IF('Section Load'!M16>0,'Section Load'!M16,0)) -> 734.44 | ... AL13: =(IF('Section Load'!AM16>0,'Section Load'!AM16,0)) -> 699 | AM13: =(IF('Water Report'!$O$7>0,'Water Report'!$O$7,0)) -> 0 | AN13: =(IF('Water Report'!$O$8>0,'Water Report'!$O$8,0)) -> 116 | AO13: =(IF('Water Report'!$O$9>0,'Water Report'!$O$9,0)) -> 101 | AP13: =(IF('Water Report'!$O$10>0,'Water Report'!$O$10,0)) -> 9 | AQ13: =(IF('Water Report'!$O$11>0,'Water Report'!$O$11,0)) -> 35 | AR13: =(IF('Water Report'!$O$13>0,'Water Report'!$O$13,0)) -> 13 | AS13: =(IF('Water Report'!$O$14>0,'Water Report'!$O$14,0)) -> 4 | AT13: =(IF('Water Report'!$O$15>0,'Water Report'!$O$15,0)) -> 6 | AU13: =(IF('Water Report'!$O$17>0,'Water Report'!$O$17,0)) -> 0 | AV13: =(IF('Water Report'!$O$18>0,'Water Report'!$O$18,0)) -> 0 | AW13: =(IF('Water Report'!$O$19>0,'Water Report'!$O$19,0)) -> 9 | AX13: =(IF('Water Report'!$O$21>0,'Water Report'!$O$21,0)) -> 92 | AY13: =(IF('Water Report'!$O$22>0,'Water Report'!$O$22,0)) -> 0 | AZ13: =(IF('Water Report'!$O$23>0,'Water Report'!$O$23,0)) -> 0 | BA13: =(IF('Water Report'!$O$14>0,'Water Report'!$O$14,0)) -> 4 | BB13: =(IF('Water Report'!$O$15>0,'Water Report'!$O$15,0)) -> 6 | BC13: =(IF('Water Report'!$O$13>0,'Water Report'!$O$13,0)) -> 13 | BD13: =(IF('Water Report'!$O$24>0,'Water Report'!$O$24,0)) -> 57 | BE13: =(IF('Water Report'!$O$25>0,'Water Report'!$O$25,0)) -> 155 | BF13: =(IF('Water Report'!$O$27>0,'Water Report'!$O$27,0)) -> 105 | BG13: =(IF('Section Load'!AN16>0,'Section Load'!AN16,0)) -> 741.61 | BH13: =(IF('Section Load'!AO16>0,'Section Load'!AO16,0)) -> 286.08 | BI13: =(IF('Section Load'!AP16>0,'Section Load'!AP16,0)) -> 0.2 | BJ13: =(IF('Section Load'!AQ16>0,'Section Load'!AQ16,0)) -> 112 | BK13: =(IF('Section Load'!AR16>0,'Section Load'!AR16,0)) -> 58 | BL13: =(IF('Section Load'!AS16>0,'Section Load'!AS16,0)) -> 0 | BM13: =(IF('Section Load'!AT16>0,'Section Load'!AT16,0)) -> 285.33
A14: Mumbai | B14: =B13+1 -> 13 | C14: 2 | D14: 2023 | E14: =(IF('Section Load'!F17>0,'Section Load'!F17,0)) -> 2867.61 | F14: =(IF('Section Load'!G17>0,'Section Load'!G17,0)) -> 1353.65 | G14: =(IF('Section Load'!H17>0,'Section Load'!H17,0)) -> 2302.16 | H14: =(IF('Section Load'!I17>0,'Section Load'!I17,0)) -> 2751.41 | I14: =(IF('Section Load'!J17>0,'Section Load'!J17,0)) -> 3416.84 | J14: =(IF('Section Load'!K17>0,'Section Load'!K17,0)) -> 2558.96 | K14: =(IF('Section Load'!L17>0,'Section Load'!L17,0)) -> 1562.52 | L14: =(IF('Section Load'!M17>0,'Section Load'!M17,0)) -> 807.09 | ... AL14: =(IF('Section Load'!AM17>0,'Section Load'!AM17,0)) -> 536 | AM14: =(IF('Water Report'!$P$7>0,'Water Report'!$P$7,0)) -> 0 | AN14: =(IF('Water Report'!$P$8>0,'Water Report'!$P$8,0)) -> 91 | AO14: =(IF('Water Report'!$P$9>0,'Water Report'!$P$9,0)) -> 83 | AP14: =(IF('Water Report'!$P$10>0,'Water Report'!$P$10,0)) -> 9 | AQ14: =(IF('Water Report'!$P$11>0,'Water Report'!$P$11,0)) -> 32 | AR14: =(IF('Water Report'!$P$13>0,'Water Report'!$P$13,0)) -> 9 | AS14: =(IF('Water Report'!$P$14>0,'Water Report'!$P$14,0)) -> 7 | AT14: =(IF('Water Report'!$P$15>0,'Water Report'!$P$15,0)) -> 11 | AU14: =(IF('Water Report'!$P$17>0,'Water Report'!$P$17,0)) -> 4 | AV14: =(IF('Water Report'!$P$18>0,'Water Report'!$P$18,0)) -> 0 | AW14: =(IF('Water Report'!$P$19>0,'Water Report'!$P$19,0)) -> 9 | AX14: =(IF('Water Report'!$P$21>0,'Water Report'!$P$21,0)) -> 78 | AY14: =(IF('Water Report'!$P$22>0,'Water Report'!$P$22,0)) -> 0 | AZ14: =(IF('Water Report'!$P$23>0,'Water Report'!$P$23,0)) -> 0 | BA14: =(IF('Water Report'!$P$14>0,'Water Report'!$P$14,0)) -> 7 | BB14: =(IF('Water Report'!$P$15>0,'Water Report'!$P$15,0)) -> 11 | BC14: =(IF('Water Report'!$P$13>0,'Water Report'!$P$13,0)) -> 9 | BD14: =(IF('Water Report'!$P$24>0,'Water Report'!$P$24,0)) -> 64 | BE14: =(IF('Water Report'!$P$25>0,'Water Report'!$P$25,0)) -> 142 | BF14: =(IF('Water Report'!$P$27>0,'Water Report'!$P$27,0)) -> 87 | BG14: =(IF('Section Load'!AN17>0,'Section Load'!AN17,0)) -> 738.4136 | BH14: =(IF('Section Load'!AO17>0,'Section Load'!AO17,0)) -> 299 | BI14: =(IF('Section Load'!AP17>0,'Section Load'!AP17,0)) -> 0 | BJ14: =(IF('Section Load'!AQ17>0,'Section Load'!AQ17,0)) -> 105 | BK14: =(IF('Section Load'!AR17>0,'Section Load'!AR17,0)) -> 48 | BL14: =(IF('Section Load'!AS17>0,'Section Load'!AS17,0)) -> 0 | BM14: =(IF('Section Load'!AT17>0,'Section Load'!AT17,0)) -> 286.8136
A15: Mumbai | B15: =B14+1 -> 14 | C15: 2 | D15: 2023 | E15: =(IF('Section Load'!F18>0,'Section Load'!F18,0)) -> 3173.73 | F15: =(IF('Section Load'!G18>0,'Section Load'!G18,0)) -> 1369.75 | G15: =(IF('Section Load'!H18>0,'Section Load'!H18,0)) -> 2361.49 | H15: =(IF('Section Load'!I18>0,'Section Load'!I18,0)) -> 2759.55 | I15: =(IF('Section Load'!J18>0,'Section Load'!J18,0)) -> 3541.01 | J15: =(IF('Section Load'!K18>0,'Section Load'!K18,0)) -> 2594.08 | K15: =(IF('Section Load'!L18>0,'Section Load'!L18,0)) -> 1637.72 | L15: =(IF('Section Load'!M18>0,'Section Load'!M18,0)) -> 948.87 | ... AL15: =(IF('Section Load'!AM18>0,'Section Load'!AM18,0)) -> 588 | AM15: =(IF('Water Report'!$Q$7>0,'Water Report'!$Q$7,0)) -> 0 | AN15: =(IF('Water Report'!$Q$8>0,'Water Report'!$Q$8,0)) -> 102 | AO15: =(IF('Water Report'!$Q$9>0,'Water Report'!$Q$9,0)) -> 99 | AP15: =(IF('Water Report'!$Q$10>0,'Water Report'!$Q$10,0)) -> 12 | AQ15: =(IF('Water Report'!$Q$11>0,'Water Report'!$Q$11,0)) -> 40 | AR15: =(IF('Water Report'!$Q$13>0,'Water Report'!$Q$13,0)) -> 11 | AS15: =(IF('Water Report'!$Q$14>0,'Water Report'!$Q$14,0)) -> 4 | AT15: =(IF('Water Report'!$Q$15>0,'Water Report'!$Q$15,0)) -> 6 | AU15: =(IF('Water Report'!$Q$17>0,'Water Report'!$Q$17,0)) -> 0 | AV15: =(IF('Water Report'!$Q$18>0,'Water Report'!$Q$18,0)) -> 0 | AW15: =(IF('Water Report'!$Q$19>0,'Water Report'!$Q$19,0)) -> 9 | AX15: =(IF('Water Report'!$Q$21>0,'Water Report'!$Q$21,0)) -> 45 | AY15: =(IF('Water Report'!$Q$22>0,'Water Report'!$Q$22,0)) -> 0 | AZ15: =(IF('Water Report'!$Q$23>0,'Water Report'!$Q$23,0)) -> 0 | BA15: =(IF('Water Report'!$Q$14>0,'Water Report'!$Q$14,0)) -> 4 | BB15: =(IF('Water Report'!$Q$15>0,'Water Report'!$Q$15,0)) -> 6 | BC15: =(IF('Water Report'!$Q$13>0,'Water Report'!$Q$13,0)) -> 11 | BD15: =(IF('Water Report'!$Q$24>0,'Water Report'!$Q$24,0)) -> 174 | BE15: =(IF('Water Report'!$Q$25>0,'Water Report'!$Q$25,0)) -> 161 | BF15: =(IF('Water Report'!$Q$27>0,'Water Report'!$Q$27,0)) -> 56 | BG15: =(IF('Section Load'!AN18>0,'Section Load'!AN18,0)) -> 823.9764 | BH15: =(IF('Section Load'!AO18>0,'Section Load'!AO18,0)) -> 286 | BI15: =(IF('Section Load'!AP18>0,'Section Load'!AP18,0)) -> 0 | BJ15: =(IF('Section Load'!AQ18>0,'Section Load'!AQ18,0)) -> 113 | BK15: =(IF('Section Load'!AR18>0,'Section Load'!AR18,0)) -> 64 | BL15: =(IF('Section Load'!AS18>0,'Section Load'!AS18,0)) -> 0 | BM15: =(IF('Section Load'!AT18>0,'Section Load'!AT18,0)) -> 360.9764
A16: Mumbai | B16: =B15+1 -> 15 | C16: 2 | D16: 2023 | E16: =(IF('Section Load'!F19>0,'Section Load'!F19,0)) -> 3189.83 | F16: =(IF('Section Load'!G19>0,'Section Load'!G19,0)) -> 1354.69 | G16: =(IF('Section Load'!H19>0,'Section Load'!H19,0)) -> 2676.24 | H16: =(IF('Section Load'!I19>0,'Section Load'!I19,0)) -> 2852.25 | I16: =(IF('Section Load'!J19>0,'Section Load'!J19,0)) -> 3568.97 | J16: =(IF('Section Load'!K19>0,'Section Load'!K19,0)) -> 2608.25 | K16: =(IF('Section Load'!L19>0,'Section Load'!L19,0)) -> 1526.33 | L16: =(IF('Section Load'!M19>0,'Section Load'!M19,0)) -> 1252 | ... AL16: =(IF('Section Load'!AM19>0,'Section Load'!AM19,0)) -> 724 | AM16: =(IF('Water Report'!$R$7>0,'Water Report'!$R$7,0)) -> 52 | AN16: =(IF('Water Report'!$R$8>0,'Water Report'!$R$8,0)) -> 89 | AO16: =(IF('Water Report'!$R$9>0,'Water Report'!$R$9,0)) -> 145 | AP16: =(IF('Water Report'!$R$10>0,'Water Report'!$R$10,0)) -> 9 | AQ16: =(IF('Water Report'!$R$11>0,'Water Report'!$R$11,0)) -> 16 | AR16: =(IF('Water Report'!$R$13>0,'Water Report'!$R$13,0)) -> 17 | AS16: =(IF('Water Report'!$R$14>0,'Water Report'!$R$14,0)) -> 9 | AT16: =(IF('Water Report'!$R$15>0,'Water Report'!$R$15,0)) -> 7 | AU16: =(IF('Water Report'!$R$17>0,'Water Report'!$R$17,0)) -> 0 | AV16: =(IF('Water Report'!$R$18>0,'Water Report'!$R$18,0)) -> 11 | AW16: =(IF('Water Report'!$R$19>0,'Water Report'!$R$19,0)) -> 15 | AX16: =(IF('Water Report'!$R$21>0,'Water Report'!$R$21,0)) -> 159 | AY16: =(IF('Water Report'!$R$22>0,'Water Report'!$R$22,0)) -> 0 | AZ16: =(IF('Water Report'!$R$23>0,'Water Report'!$R$23,0)) -> 13 | BA16: =(IF('Water Report'!$R$14>0,'Water Report'!$R$14,0)) -> 9 | BB16: =(IF('Water Report'!$R$15>0,'Water Report'!$R$15,0)) -> 7 | BC16: =(IF('Water Report'!$R$13>0,'Water Report'!$R$13,0)) -> 17 | BD16: =(IF('Water Report'!$R$24>0,'Water Report'!$R$24,0)) -> 308 | BE16: =(IF('Water Report'!$R$25>0,'Water Report'!$R$25,0)) -> 186 | BF16: =(IF('Water Report'!$R$27>0,'Water Report'!$R$27,0)) -> 189 | BG16: =(IF('Section Load'!AN19>0,'Section Load'!AN19,0)) -> 1071 | BH16: =(IF('Section Load'!AO19>0,'Section Load'!AO19,0)) -> 326.71 | BI16: =(IF('Section Load'!AP19>0,'Section Load'!AP19,0)) -> 0.2 | BJ16: =(IF('Section Load'!AQ19>0,'Section Load'!AQ19,0)) -> 122 | BK16: =(IF('Section Load'!AR19>0,'Section Load'!AR19,0)) -> 49 | BL16: =(IF('Section Load'!AS19>0,'Section Load'!AS19,0)) -> 0 | BM16: =(IF('Section Load'!AT19>0,'Section Load'!AT19,0)) -> 573.09
A17: Mumbai | B17: =B16+1 -> 16 | C17: 2 | D17: 2023 | E17: =(IF('Section Load'!F20>0,'Section Load'!F20,0)) -> 3462.71 | F17: =(IF('Section Load'!G20>0,'Section Load'!G20,0)) -> 1415.63 | G17: =(IF('Section Load'!H20>0,'Section Load'!H20,0)) -> 2706.91 | H17: =(IF('Section Load'!I20>0,'Section Load'!I20,0)) -> 2907.11 | I17: =(IF('Section Load'!J20>0,'Section Load'!J20,0)) -> 3528.06 | J17: =(IF('Section Load'!K20>0,'Section Load'!K20,0)) -> 2706.15 | K17: =(IF('Section Load'!L20>0,'Section Load'!L20,0)) -> 1797.55 | L17: =(IF('Section Load'!M20>0,'Section Load'!M20,0)) -> 1219.84 | ... AL17: =(IF('Section Load'!AM20>0,'Section Load'!AM20,0)) -> 775 | AM17: =(IF('Water Report'!$S$7>0,'Water Report'!$S$7,0)) -> 85 | AN17: =(IF('Water Report'!$S$8>0,'Water Report'!$S$8,0)) -> 127 | AO17: =(IF('Water Report'!$S$9>0,'Water Report'!$S$9,0)) -> 132 | AP17: =(IF('Water Report'!$S$10>0,'Water Report'!$D$10,0)) -> 29 | AQ17: =(IF('Water Report'!$S$11>0,'Water Report'!$D$11,0)) -> 7 | AR17: =(IF('Water Report'!$S$13>0,'Water Report'!$D$13,0)) -> 15 | AS17: =(IF('Water Report'!$S$14>0,'Water Report'!$D$14,0)) -> 5 | AT17: =(IF('Water Report'!$S$15>0,'Water Report'!$D$15,0)) -> 8 | AU17: =(IF('Water Report'!$S$17>0,'Water Report'!$D$17,0)) -> 0 | AV17: =(IF('Water Report'!$S$18>0,'Water Report'!$D$18,0)) -> 11 | AW17: =(IF('Water Report'!$S$19>0,'Water Report'!$D$19,0)) -> 14 | AX17: =(IF('Water Report'!$S$21>0,'Water Report'!$D$21,0)) -> 154 | AY17: =(IF('Water Report'!$S$22>0,'Water Report'!$D$22,0)) -> 0 | AZ17: =(IF('Water Report'!$S$23>0,'Water Report'!$D$23,0)) -> 7 | BA17: =(IF('Water Report'!$S$14>0,'Water Report'!$D$14,0)) -> 5 | BB17: =(IF('Water Report'!$S$15>0,'Water Report'!$D$15,0)) -> 8 | BC17: =(IF('Water Report'!$S$13>0,'Water Report'!$D$13,0)) -> 15 | BD17: =(IF('Water Report'!$S$24>0,'Water Report'!$D$24,0)) -> 222 | BE17: =(IF('Water Report'!$S$25>0,'Water Report'!$D$25,0)) -> 178 | BF17: =(IF('Water Report'!$S$27>0,'Water Report'!$D$27,0)) -> 176 | BG17: =(IF('Section Load'!AN20>0,'Section Load'!AN20,0)) -> 1110 | BH17: =(IF('Section Load'!AO20>0,'Section Load'!AO20,0)) -> 318.64 | BI17: =(IF('Section Load'!AP20>0,'Section Load'!AP20,0)) -> 0 | BJ17: =(IF('Section Load'!AQ20>0,'Section Load'!AQ20,0)) -> 154 | BK17: =(IF('Section Load'!AR20>0,'Section Load'!AR20,0)) -> 56.6 | BL17: =(IF('Section Load'!AS20>0,'Section Load'!AS20,0)) -> 0 | BM17: =(IF('Section Load'!AT20>0,'Section Load'!AT20,0)) -> 580.76
A18: Mumbai | B18: =B17+1 -> 17 | C18: 2 | D18: 2023 | E18: =(IF('Section Load'!F21>0,'Section Load'!F21,0)) -> 3505.49 | F18: =(IF('Section Load'!G21>0,'Section Load'!G21,0)) -> 1531.37 | G18: =(IF('Section Load'!H21>0,'Section Load'!H21,0)) -> 2781.93 | H18: =(IF('Section Load'!I21>0,'Section Load'!I21,0)) -> 2889.44 | I18: =(IF('Section Load'!J21>0,'Section Load'!J21,0)) -> 4460.8 | J18: =(IF('Section Load'!K21>0,'Section Load'!K21,0)) -> 2772.85 | K18: =(IF('Section Load'!L21>0,'Section Load'!L21,0)) -> 1798.45 | L18: =(IF('Section Load'!M21>0,'Section Load'!M21,0)) -> 1213.29 | ... AL18: =(IF('Section Load'!AM21>0,'Section Load'!AM21,0)) -> 880 | AM18: =(IF('Water Report'!$T$7>0,'Water Report'!$T$7,0)) -> 144 | AN18: =(IF('Water Report'!$T$8>0,'Water Report'!$T$8,0)) -> 76 | AO18: =(IF('Water Report'!$T$9>0,'Water Report'!$T$9,0)) -> 133 | AP18: =(IF('Water Report'!$T$10>0,'Water Report'!$T$10,0)) -> 13 | AQ18: =(IF('Water Report'!$T$11>0,'Water Report'!$T$11,0)) -> 22 | AR18: =(IF('Water Report'!$T$13>0,'Water Report'!$T$13,0)) -> 28 | AS18: =(IF('Water Report'!$T$14>0,'Water Report'!$T$14,0)) -> 4 | AT18: =(IF('Water Report'!$T$15>0,'Water Report'!$T$15,0)) -> 13 | AU18: =(IF('Water Report'!$T$17>0,'Water Report'!$T$17,0)) -> 0 | AV18: =(IF('Water Report'!$T$18>0,'Water Report'!$T$18,0)) -> 13 | AW18: =(IF('Water Report'!$T$19>0,'Water Report'!$T$19,0)) -> 12 | AX18: =(IF('Water Report'!$T$21>0,'Water Report'!$T$21,0)) -> 136 | AY18: =(IF('Water Report'!$T$22>0,'Water Report'!$T$22,0)) -> 0 | AZ18: =(IF('Water Report'!$T$23>0,'Water Report'!$T$23,0)) -> 7 | BA18: =(IF('Water Report'!$T$14>0,'Water Report'!$T$14,0)) -> 4 | BB18: =(IF('Water Report'!$T$15>0,'Water Report'!$T$15,0)) -> 13 | BC18: =(IF('Water Report'!$T$13>0,'Water Report'!$T$13,0)) -> 28 | BD18: =(IF('Water Report'!$T$24>0,'Water Report'!$T$24,0)) -> 279 | BE18: =(IF('Water Report'!$T$25>0,'Water Report'!$T$25,0)) -> 185 | BF18: =(IF('Water Report'!$T$27>0,'Water Report'!$T$27,0)) -> 171 | BG18: =(IF('Section Load'!AN21>0,'Section Load'!AN21,0)) -> 1229 | BH18: =(IF('Section Load'!AO21>0,'Section Load'!AO21,0)) -> 305.65 | BI18: =(IF('Section Load'!AP21>0,'Section Load'!AP21,0)) -> 0 | BJ18: =(IF('Section Load'!AQ21>0,'Section Load'!AQ21,0)) -> 148 | BK18: =(IF('Section Load'!AR21>0,'Section Load'!AR21,0)) -> 61.4 | BL18: =(IF('Section Load'!AS21>0,'Section Load'!AS21,0)) -> 0 | BM18: =(IF('Section Load'!AT21>0,'Section Load'!AT21,0)) -> 713.95
A19: Mumbai | B19: =B18+1 -> 18 | C19: 2 | D19: 2023 | E19: =(IF('Section Load'!F22>0,'Section Load'!F22,0)) -> 3468.35 | F19: =(IF('Section Load'!G22>0,'Section Load'!G22,0)) -> 1258.549 | G19: =(IF('Section Load'!H22>0,'Section Load'!H22,0)) -> 2661.73 | H19: =(IF('Section Load'!I22>0,'Section Load'!I22,0)) -> 2879.49 | I19: =(IF('Section Load'!J22>0,'Section Load'!J22,0)) -> 3962.77 | J19: =(IF('Section Load'!K22>0,'Section Load'!K22,0)) -> 2447.1 | K19: =(IF('Section Load'!L22>0,'Section Load'!L22,0)) -> 1837.19 | L19: =(IF('Section Load'!M22>0,'Section Load'!M22,0)) -> 1264.91 | ... AL19: =(IF('Section Load'!AM22>0,'Section Load'!AM22,0)) -> 0 | AM19: =(IF('Water Report'!$U$7>0,'Water Report'!$U$7,0)) -> 92 | AN19: =(IF('Water Report'!$U$8>0,'Water Report'!$U$8,0)) -> 90 | AO19: =(IF('Water Report'!$U$9>0,'Water Report'!$U$9,0)) -> 162 | AP19: =(IF('Water Report'!$U$10>0,'Water Report'!$U$10,0)) -> 10 | AQ19: =(IF('Water Report'!$U$11>0,'Water Report'!$U$11,0)) -> 28 | AR19: =(IF('Water Report'!$U$13>0,'Water Report'!$U$13,0)) -> 30 | AS19: =(IF('Water Report'!$U$14>0,'Water Report'!$U$14,0)) -> 4 | AT19: =(IF('Water Report'!$U$15>0,'Water Report'!$U$15,0)) -> 7 | AU19: =(IF('Water Report'!$U$17>0,'Water Report'!$U$17,0)) -> 1 | AV19: =(IF('Water Report'!$U$18>0,'Water Report'!$U$18,0)) -> 10 | AW19: =(IF('Water Report'!$U$19>0,'Water Report'!$U$19,0)) -> 17 | AX19: =(IF('Water Report'!$U$21>0,'Water Report'!$U$21,0)) -> 114 | AY19: =(IF('Water Report'!$U$22>0,'Water Report'!$U$22,0)) -> 0 | AZ19: =(IF('Water Report'!$U$23>0,'Water Report'!$U$23,0)) -> 8 | BA19: =(IF('Water Report'!$U$14>0,'Water Report'!$U$14,0)) -> 4 | BB19: =(IF('Water Report'!$U$15>0,'Water Report'!$U$15,0)) -> 7 | BC19: =(IF('Water Report'!$U$13>0,'Water Report'!$U$13,0)) -> 30 | BD19: =(IF('Water Report'!$U$24>0,'Water Report'!$U$24,0)) -> 235 | BE19: =(IF('Water Report'!$U$25>0,'Water Report'!$U$25,0)) -> 211 | BF19: =(IF('Water Report'!$U$27>0,'Water Report'!$U$27,0)) -> 152 | BG19: =(IF('Section Load'!AN22>0,'Section Load'!AN22,0)) -> 1250 | BH19: =(IF('Section Load'!AO22>0,'Section Load'!AO22,0)) -> 307.56 | BI19: =(IF('Section Load'!AP22>0,'Section Load'!AP22,0)) -> 0 | BJ19: =(IF('Section Load'!AQ22>0,'Section Load'!AQ22,0)) -> 57 | BK19: =(IF('Section Load'!AR22>0,'Section Load'!AR22,0)) -> 60.8 | BL19: =(IF('Section Load'!AS22>0,'Section Load'!AS22,0)) -> 0 | BM19: =(IF('Section Load'!AT22>0,'Section Load'!AT22,0)) -> 824.64
A20: Mumbai | B20: =B19+1 -> 19 | C20: 2 | D20: 2023 | E20: =(IF('Section Load'!F23>0,'Section Load'!F23,0)) -> 3305.19 | F20: =(IF('Section Load'!G23>0,'Section Load'!G23,0)) -> 1356.481 | G20: =(IF('Section Load'!H23>0,'Section Load'!H23,0)) -> 2578.5 | H20: =(IF('Section Load'!I23>0,'Section Load'!I23,0)) -> 2894.43 | I20: =(IF('Section Load'!J23>0,'Section Load'!J23,0)) -> 4257.44 | J20: =(IF('Section Load'!K23>0,'Section Load'!K23,0)) -> 2367.8 | K20: =(IF('Section Load'!L23>0,'Section Load'!L23,0)) -> 1450.4 | L20: =(IF('Section Load'!M23>0,'Section Load'!M23,0)) -> 1068.64 | ... AL20: =(IF('Section Load'!AM23>0,'Section Load'!AM23,0)) -> 0 | AM20: =(IF('Water Report'!$V$7>0,'Water Report'!$V$7,0)) -> 74 | AN20: =(IF('Water Report'!$V$8>0,'Water Report'!$V$8,0)) -> 110 | AO20: =(IF('Water Report'!$V$9>0,'Water Report'!$V$9,0)) -> 108 | AP20: =(IF('Water Report'!$V$10>0,'Water Report'!$V$10,0)) -> 12 | AQ20: =(IF('Water Report'!$V$11>0,'Water Report'!$V$11,0)) -> 20 | AR20: =(IF('Water Report'!$V$13>0,'Water Report'!$V$13,0)) -> 22 | AS20: =(IF('Water Report'!$V$14>0,'Water Report'!$V$14,0)) -> 3 | AT20: =(IF('Water Report'!$V$15>0,'Water Report'!$V$15,0)) -> 5 | AU20: =(IF('Water Report'!$V$17>0,'Water Report'!$V$17,0)) -> 1 | AV20: =(IF('Water Report'!$V$18>0,'Water Report'!$V$18,0)) -> 15 | AW20: =(IF('Water Report'!$V$19>0,'Water Report'!$V$19,0)) -> 15 | AX20: =(IF('Water Report'!$V$21>0,'Water Report'!$V$21,0)) -> 99 | AY20: =(IF('Water Report'!$V$22>0,'Water Report'!$V$22,0)) -> 0 | AZ20: =(IF('Water Report'!$V$23>0,'Water Report'!$V$23,0)) -> 0 | BA20: =(IF('Water Report'!$V$14>0,'Water Report'!$V$14,0)) -> 3 | BB20: =(IF('Water Report'!$V$15>0,'Water Report'!$V$15,0)) -> 5 | BC20: =(IF('Water Report'!$V$13>0,'Water Report'!$V$13,0)) -> 22 | BD20: =(IF('Water Report'!$V$24>0,'Water Report'!$V$24,0)) -> 239 | BE20: =(IF('Water Report'!$V$25>0,'Water Report'!$V$25,0)) -> 148 | BF20: =(IF('Water Report'!$V$27>0,'Water Report'!$V$27,0)) -> 121 | BG20: =(IF('Section Load'!AN23>0,'Section Load'!AN23,0)) -> 1250 | BH20: =(IF('Section Load'!AO23>0,'Section Load'!AO23,0)) -> 305.51 | BI20: =(IF('Section Load'!AP23>0,'Section Load'!AP23,0)) -> 0 | BJ20: =(IF('Section Load'!AQ23>0,'Section Load'!AQ23,0)) -> 216 | BK20: =(IF('Section Load'!AR23>0,'Section Load'!AR23,0)) -> 54.2 | BL20: =(IF('Section Load'!AS23>0,'Section Load'!AS23,0)) -> 0 | BM20: =(IF('Section Load'!AT23>0,'Section Load'!AT23,0)) -> 674.29
A21: Mumbai | B21: =B20+1 -> 20 | C21: 2 | D21: 2023 | E21: =(IF('Section Load'!F24>0,'Section Load'!F24,0)) -> 3448.43 | F21: =(IF('Section Load'!G24>0,'Section Load'!G24,0)) -> 1472.53 | G21: =(IF('Section Load'!H24>0,'Section Load'!H24,0)) -> 2652.77 | H21: =(IF('Section Load'!I24>0,'Section Load'!I24,0)) -> 3029.5 | I21: =(IF('Section Load'!J24>0,'Section Load'!J24,0)) -> 3986.37 | J21: =(IF('Section Load'!K24>0,'Section Load'!K24,0)) -> 2442.1 | K21: =(IF('Section Load'!L24>0,'Section Load'!L24,0)) -> 1719.41 | L21: =(IF('Section Load'!M24>0,'Section Load'!M24,0)) -> 1063.45 | ... AL21: =(IF('Section Load'!AM24>0,'Section Load'!AM24,0)) -> 0 | AM21: =(IF('Water Report'!$W$7>0,'Water Report'!$W$7,0)) -> 56 | AN21: =(IF('Water Report'!$W$8>0,'Water Report'!$W$8,0)) -> 97 | AO21: =(IF('Water Report'!$W$9>0,'Water Report'!$W$9,0)) -> 137 | AP21: =(IF('Water Report'!$W$10>0,'Water Report'!$W$10,0)) -> 13 | AQ21: =(IF('Water Report'!$W$11>0,'Water Report'!$W$11,0)) -> 16 | AR21: =(IF('Water Report'!$W$13>0,'Water Report'!$W$13,0)) -> 21 | AS21: =(IF('Water Report'!$W$14>0,'Water Report'!$W$14,0)) -> 12 | AT21: =(IF('Water Report'!$W$15>0,'Water Report'!$W$15,0)) -> 5 | AU21: =(IF('Water Report'!$W$17>0,'Water Report'!$W$17,0)) -> 0 | AV21: =(IF('Water Report'!$W$18>0,'Water Report'!$W$18,0)) -> 14 | AW21: =(IF('Water Report'!$W$19>0,'Water Report'!$W$19,0)) -> 17 | AX21: =(IF('Water Report'!$W$21>0,'Water Report'!$W$21,0)) -> 115 | AY21: =(IF('Water Report'!$W$22>0,'Water Report'!$W$22,0)) -> 0 | AZ21: =(IF('Water Report'!$W$23>0,'Water Report'!$W$23,0)) -> 6 | BA21: =(IF('Water Report'!$W$14>0,'Water Report'!$W$14,0)) -> 12 | BB21: =(IF('Water Report'!$W$15>0,'Water Report'!$W$15,0)) -> 5 | BC21: =(IF('Water Report'!$W$13>0,'Water Report'!$W$13,0)) -> 21 | BD21: =(IF('Water Report'!$W$24>0,'Water Report'!$W$24,0)) -> 235 | BE21: =(IF('Water Report'!$W$25>0,'Water Report'!$W$25,0)) -> 183 | BF21: =(IF('Water Report'!$W$27>0,'Water Report'!$W$27,0)) -> 142 | BG21: =(IF('Section Load'!AN24>0,'Section Load'!AN24,0)) -> 1237 | BH21: =(IF('Section Load'!AO24>0,'Section Load'!AO24,0)) -> 303.93 | BI21: =(IF('Section Load'!AP24>0,'Section Load'!AP24,0)) -> 0 | BJ21: =(IF('Section Load'!AQ24>0,'Section Load'!AQ24,0)) -> 149 | BK21: =(IF('Section Load'!AR24>0,'Section Load'!AR24,0)) -> 53 | BL21: =(IF('Section Load'!AS24>0,'Section Load'!AS24,0)) -> 0 | BM21: =(IF('Section Load'!AT24>0,'Section Load'!AT24,0)) -> 731.07
A22: Mumbai | B22: =B21+1 -> 21 | C22: 2 | D22: 2023 | E22: =(IF('Section Load'!F25>0,'Section Load'!F25,0)) -> 3405 | F22: =(IF('Section Load'!G25>0,'Section Load'!G25,0)) -> 1453 | G22: =(IF('Section Load'!H25>0,'Section Load'!H25,0)) -> 2677.57 | H22: =(IF('Section Load'!I25>0,'Section Load'!I25,0)) -> 2880 | I22: =(IF('Section Load'!J25>0,'Section Load'!J25,0)) -> 4981 | J22: =(IF('Section Load'!K25>0,'Section Load'!K25,0)) -> 2656 | K22: =(IF('Section Load'!L25>0,'Section Load'!L25,0)) -> 1622 | L22: =(IF('Section Load'!M25>0,'Section Load'!M25,0)) -> 1103 | ... AL22: =(IF('Section Load'!AM25>0,'Section Load'!AM25,0)) -> 0 | AM22: =(IF('Water Report'!$X$7>0,'Water Report'!$X$7,0)) -> 52 | AN22: =(IF('Water Report'!$X$8>0,'Water Report'!$X$8,0)) -> 104 | AO22: =(IF('Water Report'!$X$9>0,'Water Report'!$X$9,0)) -> 138 | AP22: =(IF('Water Report'!$X$10>0,'Water Report'!$X$10,0)) -> 17 | AQ22: =(IF('Water Report'!$X$11>0,'Water Report'!$X$11,0)) -> 20 | AR22: =(IF('Water Report'!$X$13>0,'Water Report'!$X$13,0)) -> 38 | AS22: =(IF('Water Report'!$X$14>0,'Water Report'!$X$14,0)) -> 3 | AT22: =(IF('Water Report'!$X$15>0,'Water Report'!$X$15,0)) -> 6 | AU22: =(IF('Water Report'!$X$17>0,'Water Report'!$X$17,0)) -> 0 | AV22: =(IF('Water Report'!$X$18>0,'Water Report'!$X$18,0)) -> 13 | AW22: =(IF('Water Report'!$X$19>0,'Water Report'!$X$19,0)) -> 17 | AX22: =(IF('Water Report'!$X$21>0,'Water Report'!$X$21,0)) -> 115 | AY22: =(IF('Water Report'!$X$22>0,'Water Report'!$X$22,0)) -> 0 | AZ22: =(IF('Water Report'!$X$23>0,'Water Report'!$X$23,0)) -> 7 | BA22: =(IF('Water Report'!$X$14>0,'Water Report'!$X$14,0)) -> 3 | BB22: =(IF('Water Report'!$X$15>0,'Water Report'!$X$15,0)) -> 6 | BC22: =(IF('Water Report'!$X$13>0,'Water Report'!$X$13,0)) -> 38 | BD22: =(IF('Water Report'!$X$24>0,'Water Report'!$X$24,0)) -> 258 | BE22: =(IF('Water Report'!$X$25>0,'Water Report'!$X$25,0)) -> 184 | BF22: =(IF('Water Report'!$X$27>0,'Water Report'!$X$27,0)) -> 160 | BG22: =(IF('Section Load'!AN25>0,'Section Load'!AN25,0)) -> 1216 | BH22: =(IF('Section Load'!AO25>0,'Section Load'!AO25,0)) -> 291 | BI22: =(IF('Section Load'!AP25>0,'Section Load'!AP25,0)) -> 0 | BJ22: =(IF('Section Load'!AQ25>0,'Section Load'!AQ25,0)) -> 127 | BK22: =(IF('Section Load'!AR25>0,'Section Load'!AR25,0)) -> 59 | BL22: =(IF('Section Load'!AS25>0,'Section Load'!AS25,0)) -> 0 | BM22: =(IF('Section Load'!AT25>0,'Section Load'!AT25,0)) -> 739
