Workbook

Sheet TOTAL
A1: Site Name | B1: Day | C1: Month | D1: Year | E1: Total Electricity Kwh | F1: Electricity Tariff ($/Kwh) | G1: Natual Gas (m3) | H1: Natural Gas $/m3 | I1: Water Utility Supply (m3) m3 | J1: Water Utility Supply (m3) $/m3 | K1: Room Nights | L1: Total Guests
A2: Milan | B2: 1 | C2: 8 | D2: 2022 | E2: ='Hotel Data'!X5 -> 17604 | F2: 0.7331 | G2: =INT('Hotel Data'!E5) -> 215 | H2: 1.8705 | I2: =INT('Hotel Data'!K5) -> 373 | J2: 0.7838 | K2: 81 | L2: 149
A3: Milan | B3: =B2+1 -> 2 | C3: 8 | D3: 2022 | E3: ='Hotel Data'!X6 -> 17671 | F3: 0.7331 | G3: =INT('Hotel Data'!E6) -> 198 | H3: 1.8705 | I3: =INT('Hotel Data'!K6) -> 317 | J3: 0.7838 | K3: 85 | L3: 159
A4: Milan | B4: =B3+1 -> 3 | C4: 8 | D4: 2022 | E4: ='Hotel Data'!X7 -> 17843 | F4: 0.7331 | G4: =INT('Hotel Data'!E7) -> 227 | H4: 1.8705 | I4: =INT('Hotel Data'!K7) -> 349 | J4: 0.7838 | K4: 93 | L4: 179
A5: Milan | B5: =B4+1 -> 4 | C5: 8 | D5: 2022 | E5: ='Hotel Data'!X8 -> 17936 | F5: 0.7331 | G5: =INT('Hotel Data'!E8) -> 201 | H5: 1.8705 | I5: =INT('Hotel Data'!K8) -> 344 | J5: 0.7838 | K5: 109 | L5: 206
A6: Milan | B6: =B5+1 -> 5 | C6: 8 | D6: 2022 | E6: ='Hotel Data'!X9 -> 18419 | F6: 0.7331 | G6: =INT('Hotel Data'!E9) -> 275 | H6: 1.8705 | I6: =INT('Hotel Data'!K9) -> 360 | J6: 0.7838 | K6: 78 | L6: 150
A7: Milan | B7: =B6+1 -> 6 | C7: 8 | D7: 2022 | E7: ='Hotel Data'!X10 -> 18829 | F7: 0.7331 | G7: =INT('Hotel Data'!E10) -> 153 | H7: 1.8705 | I7: =INT('Hotel Data'!K10) -> 348 | J7: 0.7838 | K7: 75 | L7: 146
A8: Milan | B8: =B7+1 -> 7 | C8: 8 | D8: 2022 | E8: ='Hotel Data'!X11 -> 17584 | F8: 0.7331 | G8: =INT('Hotel Data'!E11) -> 193 | H8: 1.8705 | I8: =INT('Hotel Data'!K11) -> 294 | J8: 0.7838 | K8: 80 | L8: 133
A9: Milan | B9: =B8+1 -> 8 | C9: 8 | D9: 2022 | E9: ='Hotel Data'!X12 -> 17554 | F9: 0.7331 | G9: =INT('Hotel Data'!E12) -> 226 | H9: 1.8705 | I9: =INT('Hotel Data'!K12) -> 311 | J9: 0.7838 | K9: 109 | L9: 159
A10: Milan | B10: =B9+1 -> 9 | C10: 8 | D10: 2022 | E10: ='Hotel Data'!X13 -> 17815 | F10: 0.7331 | G10: =INT('Hotel Data'!E13) -> 201 | H10: 1.8705 | I10: =INT('Hotel Data'!K13) -> 321 | J10: 0.7838 | K10: 97 | L10: 139
A11: Milan | B11: =B10+1 -> 10 | C11: 8 | D11: 2022 | E11: ='Hotel Data'!X14 -> 17502 | F11: 0.7331 | G11: =INT('Hotel Data'!E14) -> 198 | H11: 1.8705 | I11: =INT('Hotel Data'!K14) -> 335 | J11: 0.7838 | K11: 96 | L11: 144
A12: Milan | B12: =B11+1 -> 11 | C12: 8 | D12: 2022 | E12: ='Hotel Data'!X15 -> 17114 | F12: 0.7331 | G12: =INT('Hotel Data'!E15) -> 201 | H12: 1.8705 | I12: =INT('Hotel Data'!K15) -> 320 | J12: 0.7838 | K12: 105 | L12: 164
A13: Milan | B13: =B12+1 -> 12 | C13: 8 | D13: 2022 | E13: ='Hotel Data'!X16 -> 16839 | F13: 0.7331 | G13: =INT('Hotel Data'!E16) -> 209 | H13: 1.8705 | I13: =INT('Hotel Data'!K16) -> 301 | J13: 0.7838 | K13: 82 | L13: 153
A14: Milan | B14: =B13+1 -> 13 | C14: 8 | D14: 2022 | E14: ='Hotel Data'!X17 -> 16332 | F14: 0.7331 | G14: =INT('Hotel Data'!E17) -> 208 | H14: 1.8705 | I14: =INT('Hotel Data'!K17) -> 256 | J14: 0.7838 | K14: 67 | L14: 139
... A32: Milan | B32: =B31+1 -> 31 | C32: 8 | D32: 2022 | E32: ='Hotel Data'!X35 -> 15399 | F32: 0.7331 | G32: =INT('Hotel Data'!E35) -> 298 | H32: 1.8705 | I32: =INT('Hotel Data'!K35) -> 222 | J32: 0.7838 | K32: 84 | L32: 150

Sheet Submetering 
A1: Site Name | B1: Day | C1: Month | D1: Year | E1: GAS RISCALD.(m3) | F1: GAS CUCINA (m3) | G1: H2O CONDIZION.ADD (m3) | H1: REINT. H2O ADD (m3) | I1: H2O ADD F CUC P (m3) | J1: H2O SANIT. CALDA (m3) | K1: ENEL CUC.PRINC. P (KWh) | L1: ENEL CUC.PRINC. N. (KWh) | M1: ENEL CUC.PREP. (KWh) | N1: ENEL CUC.VERANDA (KWh) | O1: ENEL LAVANDERIA (KWh) | P1: Room Nights
A3: Milan | B3: 1 | C3: 8 | D3: 2022 | E3: ='Hotel Data'!E5 -> 215 | F3: ='Hotel Data'!G5 -> 0 | G3: ='Hotel Data'!O5 -> 82 | H3: ='Hotel Data'!Q5 -> 117 | I3: ='Hotel Data'!S5 -> 0 | J3: ='Hotel Data'!U5 -> 149 | K3: ='Hotel Data'!AD5 -> 344 | L3: ='Hotel Data'!AG5 -> 1130 | M3: ='Hotel Data'!AJ5 -> 152 | N3: ='Hotel Data'!AN5 -> 507 | O3: ='Hotel Data'!AR5 -> 296
A4: Milan | B4: =B3+1 -> 2 | C4: 8 | D4: 2022 | E4: ='Hotel Data'!E6 -> 198 | F4: ='Hotel Data'!G6 -> 0 | G4: ='Hotel Data'!O6 -> 69 | H4: ='Hotel Data'!Q6 -> 100 | I4: ='Hotel Data'!S6 -> 0 | J4: ='Hotel Data'!U6 -> 122 | K4: ='Hotel Data'!AD6 -> 333 | L4: ='Hotel Data'!AG6 -> 1160 | M4: ='Hotel Data'!AJ6 -> 160 | N4: ='Hotel Data'!AN6 -> 458 | O4: ='Hotel Data'!AR6 -> 280
A5: Milan | B5: =B4+1 -> 3 | C5: 8 | D5: 2022 | E5: ='Hotel Data'!E7 -> 227 | F5: ='Hotel Data'!G7 -> 0 | G5: ='Hotel Data'!O7 -> 90 | H5: ='Hotel Data'!Q7 -> 98 | I5: ='Hotel Data'!S7 -> 0 | J5: ='Hotel Data'!U7 -> 121 | K5: ='Hotel Data'!AD7 -> 336 | L5: ='Hotel Data'!AG7 -> 1191 | M5: ='Hotel Data'!AJ7 -> 192 | N5: ='Hotel Data'!AN7 -> 442 | O5: ='Hotel Data'!AR7 -> 264
A6: Milan | B6: =B5+1 -> 4 | C6: 8 | D6: 2022 | E6: ='Hotel Data'!E8 -> 201 | F6: ='Hotel Data'!G8 -> 1 | G6: ='Hotel Data'!O8 -> 92 | H6: ='Hotel Data'!Q8 -> 96 | I6: ='Hotel Data'!S8 -> 0 | J6: ='Hotel Data'!U8 -> 124 | K6: ='Hotel Data'!AD8 -> 365 | L6: ='Hotel Data'!AG8 -> 1098 | M6: ='Hotel Data'!AJ8 -> 160 | N6: ='Hotel Data'!AN8 -> 426 | O6: ='Hotel Data'!AR8 -> 280
A7: Milan | B7: =B6+1 -> 5 | C7: 8 | D7: 2022 | E7: ='Hotel Data'!E9 -> 275 | F7: ='Hotel Data'!G9 -> 0 | G7: ='Hotel Data'!O9 -> 93 | H7: ='Hotel Data'!Q9 -> 96 | I7: ='Hotel Data'!S9 -> 0 | J7: ='Hotel Data'!U9 -> 127 | K7: ='Hotel Data'!AD9 -> 330 | L7: ='Hotel Data'!AG9 -> 1178 | M7: ='Hotel Data'!AJ9 -> 168 | N7: ='Hotel Data'!AN9 -> 472 | O7: ='Hotel Data'!AR9 -> 280
A8: Milan | B8: =B7+1 -> 6 | C8: 8 | D8: 2022 | E8: ='Hotel Data'!E10 -> 153 | F8: ='Hotel Data'!G10 -> 0 | G8: ='Hotel Data'!O10 -> 95 | H8: ='Hotel Data'!Q10 -> 93 | I8: ='Hotel Data'!S10 -> 0 | J8: ='Hotel Data'!U10 -> 120 | K8: ='Hotel Data'!AD10 -> 348 | L8: ='Hotel Data'!AG10 -> 1239 | M8: ='Hotel Data'!AJ10 -> 144 | N8: ='Hotel Data'!AN10 -> 471 | O8: ='Hotel Data'!AR10 -> 264
A9: Milan | B9: =B8+1 -> 7 | C9: 8 | D9: 2022 | E9: ='Hotel Data'!E11 -> 193 | F9: ='Hotel Data'!G11 -> 0 | G9: ='Hotel Data'!O11 -> 78 | H9: ='Hotel Data'!Q11 -> 90 | I9: ='Hotel Data'!S11 -> 0 | J9: ='Hotel Data'!U11 -> 118 | K9: ='Hotel Data'!AD11 -> 351 | L9: ='Hotel Data'!AG11 -> 1083 | M9: ='Hotel Data'!AJ11 -> 136 | N9: ='Hotel Data'!AN11 -> 488 | O9: ='Hotel Data'!AR11 -> 256
A10: Milan | B10: =B9+1 -> 8 | C10: 8 | D10: 2022 | E10: ='Hotel Data'!E12 -> 226 | F10: ='Hotel Data'!G12 -> 0 | G10: ='Hotel Data'!O12 -> 77 | H10: ='Hotel Data'!Q12 -> 93 | I10: ='Hotel Data'!S12 -> 0 | J10: ='Hotel Data'!U12 -> 120 | K10: ='Hotel Data'!AD12 -> 347 | L10: ='Hotel Data'!AG12 -> 1123 | M10: ='Hotel Data'!AJ12 -> 152 | N10: ='Hotel Data'!AN12 -> 485 | O10: ='Hotel Data'!AR12 -> 272
A11: Milan | B11: =B10+1 -> 9 | C11: 8 | D11: 2022 | E11: ='Hotel Data'!E13 -> 201 | F11: ='Hotel Data'!G13 -> 1 | G11: ='Hotel Data'!O13 -> 82 | H11: ='Hotel Data'!Q13 -> 88 | I11: ='Hotel Data'!S13 -> 0 | J11: ='Hotel Data'!U13 -> 117 | K11: ='Hotel Data'!AD13 -> 340 | L11: ='Hotel Data'!AG13 -> 1184 | M11: ='Hotel Data'!AJ13 -> 168 | N11: ='Hotel Data'!AN13 -> 458 | O11: ='Hotel Data'!AR13 -> 248
A12: Milan | B12: =B11+1 -> 10 | C12: 8 | D12: 2022 | E12: ='Hotel Data'!E14 -> 198 | F12: ='Hotel Data'!G14 -> 1 | G12: ='Hotel Data'!O14 -> 80 | H12: ='Hotel Data'!Q14 -> 93 | I12: ='Hotel Data'!S14 -> 0 | J12: ='Hotel Data'!U14 -> 125 | K12: ='Hotel Data'!AD14 -> 366 | L12: ='Hotel Data'!AG14 -> 1302 | M12: ='Hotel Data'!AJ14 -> 144 | N12: ='Hotel Data'!AN14 -> 467 | O12: ='Hotel Data'!AR14 -> 296
A13: Milan | B13: =B12+1 -> 11 | C13: 8 | D13: 2022 | E13: ='Hotel Data'!E15 -> 201 | F13: ='Hotel Data'!G15 -> 0 | G13: ='Hotel Data'!O15 -> 79 | H13: ='Hotel Data'!Q15 -> 93 | I13: ='Hotel Data'!S15 -> 0 | J13: ='Hotel Data'!U15 -> 123 | K13: ='Hotel Data'!AD15 -> 337 | L13: ='Hotel Data'!AG15 -> 1231 | M13: ='Hotel Data'!AJ15 -> 136 | N13: ='Hotel Data'!AN15 -> 437 | O13: ='Hotel Data'!AR15 -> 312
A14: Milan | B14: =B13+1 -> 12 | C14: 8 | D14: 2022 | E14: ='Hotel Data'!E16 -> 209 | F14: ='Hotel Data'!G16 -> 0 | G14: ='Hotel Data'!O16 -> 70 | H14: ='Hotel Data'!Q16 -> 79 | I14: ='Hotel Data'!S16 -> 0 | J14: ='Hotel Data'!U16 -> 107 | K14: ='Hotel Data'!AD16 -> 366 | L14: ='Hotel Data'!AG16 -> 1228 | M14: ='Hotel Data'!AJ16 -> 168 | N14: ='Hotel Data'!AN16 -> 452 | O14: ='Hotel Data'!AR16 -> 256
A15: Milan | B15: =B14+1 -> 13 | C15: 8 | D15: 2022 | E15: ='Hotel Data'!E17 -> 208 | F15: ='Hotel Data'!G17 -> 0 | G15: ='Hotel Data'!O17 -> 63 | H15: ='Hotel Data'!Q17 -> 53 | I15: ='Hotel Data'!S17 -> 0 | J15: ='Hotel Data'!U17 -> 77 | K15: ='Hotel Data'!AD17 -> 339 | L15: ='Hotel Data'!AG17 -> 1182 | M15: ='Hotel Data'!AJ17 -> 168 | N15: ='Hotel Data'!AN17 -> 466 | O15: ='Hotel Data'!AR17 -> 240
... A33: Milan | B33: =B32+1 -> 31 | C33: 8 | D33: 2022 | E33: ='Hotel Data'!E35 -> 298 | F33: ='Hotel Data'!G35 -> 2 | G33: ='Hotel Data'!O35 -> 58 | H33: ='Hotel Data'!Q35 -> 48 | I33: ='Hotel Data'!S35 -> 0 | J33: ='Hotel Data'!U35 -> 62 | K33: ='Hotel Data'!AD35 -> 340 | L33: ='Hotel Data'!AG35 -> 1035 | M33: ='Hotel Data'!AJ35 -> 128 | N33: ='Hotel Data'!AN35 -> 449 | O33: ='Hotel Data'!AR35 -> 224

Sheet Hotel Data
D1: GAS RISCALD. | F1: GAS CUCINA | H1: H2O GENERALE | N1: H2O CONDIZION.ADD | P1: REINT. H2O ADD | R1: H2O ADD F CUC P | T1: H2O SANIT. CALDA | V1: ENEL ATTIVA | Y1: ENEL REATT. | AB1: ENEL CUC.PRINC. P | AE1: ENEL CUC.PRINC. N. | AH1: ENEL CUC.PREP. | AL1: ENEL CUC.VERANDA | AP1: ENEL LAVANDERIA | AS1: TEMPER.GG. | AU1: n°Ric | AV1: Ricarica auto el. | AW1: lt/ G | AZ1: GAS RISCALD | BA1: GAS CUCINA | BB1: ACQUA GENER. | BC1: ACQUA CONDIZ. | BD1: ENERGIA | BE1: Proiezione BA | BF1: ENEL CUC.PRINC | BG1: ENEL CUC.PREP | BH1: ENEL CUC.VER | BI1: ENEL LAVAND
A3: GG | B3: ORA | C3: NOTE | D3: LETTURA MC | E3: DIFF. G | F3: LETTURA MC | G3: DIFF. G | H3: LETTURA MC | I3: DIFF. G | J3: lett. BA | K3: DIFF. G | L3: GUESTS | M3: mcxcl | N3: LETTURA MC | O3: DIFF. G | P3: LETTURA MC | Q3: DIFF. G | R3: LETTURA MC | S3: DIFF. G | T3: LETTURA MC | U3: DIFF. G | V3: LET. KWH*2200 | W3: DIFF. G | X3: Consumo Ba | Y3: LET.KWT | Z3: DIFF. G | AA3: Consumo Ba | AB3: LET. KWH | AC3: DIFF. G | AD3: Consumo Ba | AE3: LET. KWH | AF3: DIFF. G | AG3: Consumo Ba | AH3: LET. KWH*80 | AI3: DIFF. G | AJ3: Consumo Ba | AK3: COVERS | AL3: LET. KWH | AM3: DIFF. G | AN3: Consumo Ba | AO3: COVERS | AP3: LET. KWH*80 | AQ3: DIFF. G | AR3: Consumo Ba | AS3: MIN | AT3: MAX | AU3: KW/h
D4: 323766 | F4: ='[1]July '!F35 -> 7050 | H4: 84957 | J4: 600015 | N4: 11078 | P4: 94582 | R4: 36 | T4: 197834 | V4: 4998.44 | Y4: 956.38 | AB4: 1746536 | AE4: 5152419 | AH4: 34068 | AL4: 202543 | AP4: 46711 | AV4: ='[1]July '!AV35 -> 0 | AZ4: =D39 -> 7000 | BA4: =F39 -> 50 | BB4: =H39 -> 5200 | BC4: =N39 -> 6500 | BD4: 550000 | BE4: =BD4 -> 550000 | BG4: 9439 | BH4: 13443 | BI4: 11344
A5: 1 | B5: 00:00 | D5: 323981 | E5: =IF(ISBLANK(D5),0,D5-D4) -> 215 | F5: 7050 | G5: =IF(ISBLANK(F5),0,F5-F4) -> 0 | H5: 85344 | I5: =IF(ISBLANK(H5),0,H5-H4) -> 387 | J5: 600388 | K5: =IF(ISBLANK(J5),0,J5-J4) -> 373 | M5: =I5/L5 -> #DIV/0! | N5: 11160 | O5: =IF(ISBLANK(N5),0,N5-N4) -> 82 | P5: 94699 | Q5: =IF(ISBLANK(P5),0,P5-P4) -> 117 | R5: 36 | S5: 0 | T5: 197983 | U5: =IF(ISBLANK(T5),0,T5-T4) -> 149 | X5: 17604 | AA5: 2790 | AC5: =IF(ISBLANK(AB5),0,SUM(AB5-AB4)) -> 0 | AD5: 344 | AF5: =IF(ISBLANK(AE5),0,SUM(AE5-AE4)) -> 0 | AG5: 1130 | AI5: =IF(ISBLANK(AH5),0,SUM(AH5-AH4)*80) -> 0 | AJ5: 152 | AM5: =IF(ISBLANK(AL5),0,AL5-AL4) -> 0 | AN5: 507 | AQ5: =IF(ISBLANK(AP5),0,SUM(AP5-AP4)*80) -> 0 | AR5: 296 | AS5: 21 | AT5: 36 | AW5: =IF(ISBLANK(AV6),0,AV6-AV5) -> 0 | AY5: 1 | AZ5: =IF(D5<>0,(+D5-D$10)/A5*31,0) -> -32674 | BA5: =IF(F5<>0,(+F5-F$10)/$A5*31,0) -> -31 | BB5: =IF(H5<>0,(+H5-H$10)/$A5*31,0) -> -55273 | BC5: =IF(N5<>0,(+N5-N$10)/$A5*31,0) -> -13609 | BD5: =IF(V5<>0,(+V5-V$10)*2200/$A5*31,0) -> 0 | BE5: =IF(X5<>0,AVERAGE(X5:X$11)*31,) -> 557495.14 | BF5: =IF(AD5+AG5<>0,AVERAGE(AD5:AD$11)*31+AVERAGE(AG5:AG$11)*31,) -> 46438 | BG5: =IF(AJ5<>0,AVERAGE(AJ5:AJ$11)*31,) -> 4924.5714 | BH5: =IF(AN5<>0,AVERAGE(AN5:AN$11)*31,) -> 14454.857 | BI5: =IF(AR5<>0,AVERAGE(AR5:AR$11)*31,) -> 8502.8571
A6: =1+A5 -> 2 | B6: 00:00 | D6: 324179 | E6: =IF(ISBLANK(D6),0,D6-D5) -> 198 | F6: 7050 | G6: =IF(ISBLANK(F6),0,F6-F5) -> 0 | H6: 85673 | I6: =IF(ISBLANK(H6),0,H6-H5) -> 329 | J6: 600705 | K6: =IF(ISBLANK(J6),0,J6-J5) -> 317 | M6: =I6/L6 -> #DIV/0! | N6: 11229 | O6: =IF(ISBLANK(N6),0,N6-N5) -> 69 | P6: 94799 | Q6: =IF(ISBLANK(P6),0,P6-P5) -> 100 | R6: 36 | S6: =IF(ISBLANK(R6),0,R6-R5) -> 0 | T6: 198105 | U6: =IF(ISBLANK(T6),0,T6-T5) -> 122 | X6: 17671 | AA6: 2992 | AC6: =IF(ISBLANK(AB6),0,SUM(AB6-AB5)) -> 0 | AD6: 333 | AF6: =IF(ISBLANK(AE6),0,SUM(AE6-AE5)) -> 0 | AG6: 1160 | AI6: =IF(ISBLANK(AH6),0,SUM(AH6-AH5)*80) -> 0 | AJ6: 160 | AM6: =IF(ISBLANK(AL6),0,AL6-AL5) -> 0 | AN6: 458 | AQ6: =IF(ISBLANK(AP6),0,SUM(AP6-AP5)*80) -> 0 | AR6: 280 | AS6: 22 | AT6: 34 | AW6: =IF(ISBLANK(AV7),0,AV7-AV6) -> 0 | AY6: =1+AY5 -> 2 | AZ6: =IF(D6<>0,(+D6-D$10)/A6*31,0) -> -13268 | BA6: =IF(F6<>0,(+F6-F$10)/$A6*31,0) -> -15.5 | BB6: =IF(H6<>0,(+H6-H$10)/$A6*31,0) -> -22537 | BC6: =IF(N6<>0,(+N6-N$10)/$A6*31,0) -> -5735 | BD6: =IF(V6<>0,(+V6-V$10)*2200/$A6*31,0) -> 0 | BE6: =IF(X6<>0,AVERAGE(X6:X$11)*31,) -> 559457 | BF6: =IF(AD6+AG6<>0,AVERAGE(AD6:AD$11)*31+AVERAGE(AG6:AG$11)*31,) -> 46562 | BG6: =IF(AJ6<>0,AVERAGE(AJ6:AJ$11)*31,) -> 4960 | BH6: =IF(AN6<>0,AVERAGE(AN6:AN$11)*31,) -> 14244.5 | BI6: =IF(AR6<>0,AVERAGE(AR6:AR$11)*31,) -> 8390.6667
A7: =1+A6 -> 3 | B7: 00:00 | D7: 324406 | E7: =IF(ISBLANK(D7),0,D7-D6) -> 227 | F7: 7050 | G7: =IF(ISBLANK(F7),0,F7-F6) -> 0 | H7: 86035 | I7: =IF(ISBLANK(H7),0,H7-H6) -> 362 | J7: 601054 | K7: =IF(ISBLANK(J7),0,J7-J6) -> 349 | M7: =I7/L7 -> #DIV/0! | N7: 11319 | O7: =IF(ISBLANK(N7),0,N7-N6) -> 90 | P7: 94897 | Q7: =IF(ISBLANK(P7),0,P7-P6) -> 98 | R7: 36 | S7: =IF(ISBLANK(R7),0,R7-R6) -> 0 | T7: 198226 | U7: =IF(ISBLANK(T7),0,T7-T6) -> 121 | X7: 17843 | AA7: 2833 | AC7: =IF(ISBLANK(AB7),0,SUM(AB7-AB6)) -> 0 | AD7: 336 | AF7: =IF(ISBLANK(AE7),0,SUM(AE7-AE6)) -> 0 | AG7: 1191 | AI7: =IF(ISBLANK(AH7),0,SUM(AH7-AH6)*80) -> 0 | AJ7: 192 | AM7: =IF(ISBLANK(AL7),0,AL7-AL6) -> 0 | AN7: 442 | AQ7: =IF(ISBLANK(AP7),0,SUM(AP7-AP6)*80) -> 0 | AR7: 264 | AS7: 22 | AT7: 34 | AW7: =IF(ISBLANK(AV8),0,AV8-AV7) -> 0 | AY7: =1+AY6 -> 3 | AZ7: =IF(D7<>0,(+D7-D$10)/A7*31,0) -> -6499.6667 | BA7: =IF(F7<>0,(+F7-F$10)/$A7*31,0) -> -10.333333 | BB7: =IF(H7<>0,(+H7-H$10)/$A7*31,0) -> -11284 | BC7: =IF(N7<>0,(+N7-N$10)/$A7*31,0) -> -2893.3333 | BD7: =IF(V7<>0,(+V7-V$10)*2200/$A7*31,0) -> 0 | BE7: =IF(X7<>0,AVERAGE(X7:X$11)*31,) -> 561788.2 | BF7: =IF(AD7+AG7<>0,AVERAGE(AD7:AD$11)*31+AVERAGE(AG7:AG$11)*31,) -> 46617.8 | BG7: =IF(AJ7<>0,AVERAGE(AJ7:AJ$11)*31,) -> 4960 | BH7: =IF(AN7<>0,AVERAGE(AN7:AN$11)*31,) -> 14253.8 | BI7: =IF(AR7<>0,AVERAGE(AR7:AR$11)*31,) -> 8332.8
A8: =1+A7 -> 4 | B8: 00:00 | D8: 324607 | E8: =IF(ISBLANK(D8),0,D8-D7) -> 201 | F8: 7051 | G8: =IF(ISBLANK(F8),0,F8-F7) -> 1 | H8: 86392 | I8: =IF(ISBLANK(H8),0,H8-H7) -> 357 | J8: 601398 | K8: =IF(ISBLANK(J8),0,J8-J7) -> 344 | M8: =I8/L8 -> #DIV/0! | N8: 11411 | O8: =IF(ISBLANK(N8),0,N8-N7) -> 92 | P8: 94993 | Q8: =IF(ISBLANK(P8),0,P8-P7) -> 96 | R8: 36 | S8: =IF(ISBLANK(R8),0,R8-R7) -> 0 | T8: 198350 | U8: =IF(ISBLANK(T8),0,T8-T7) -> 124 | X8: 17936 | AA8: 2848 | AC8: =IF(ISBLANK(AB8),0,SUM(AB8-AB7)) -> 0 | AD8: 365 | AF8: =IF(ISBLANK(AE8),0,SUM(AE8-AE7)) -> 0 | AG8: 1098 | AI8: =IF(ISBLANK(AH8),0,SUM(AH8-AH7)*80) -> 0 | AJ8: 160 | AM8: =IF(ISBLANK(AL8),0,AL8-AL7) -> 0 | AN8: 426 | AQ8: =IF(ISBLANK(AP8),0,SUM(AP8-AP7)*80) -> 0 | AR8: 280 | AS8: 26 | AT8: 36 | AW8: =IF(ISBLANK(AV9),0,AV9-AV8) -> 0 | AY8: =1+AY7 -> 4 | AZ8: =IF(D8<>0,(+D8-D$10)/A8*31,0) -> -3317 | BA8: =IF(F8<>0,(+F8-F$10)/$A8*31,0) -> 0 | BB8: =IF(H8<>0,(+H8-H$10)/$A8*31,0) -> -5696.25 | BC8: =IF(N8<>0,(+N8-N$10)/$A8*31,0) -> -1457 | BD8: =IF(V8<>0,(+V8-V$10)*2200/$A8*31,0) -> 0 | BE8: =IF(X8<>0,AVERAGE(X8:X$11)*31,) -> 563952 | BF8: =IF(AD8+AG8<>0,AVERAGE(AD8:AD$11)*31+AVERAGE(AG8:AG$11)*31,) -> 46438 | BG8: =IF(AJ8<>0,AVERAGE(AJ8:AJ$11)*31,) -> 4712 | BH8: =IF(AN8<>0,AVERAGE(AN8:AN$11)*31,) -> 14391.75 | BI8: =IF(AR8<>0,AVERAGE(AR8:AR$11)*31,) -> 8370
A9: =1+A8 -> 5 | B9: 00:00 | D9: 324882 | E9: =IF(ISBLANK(D9),0,D9-D8) -> 275 | F9: 7051 | G9: =IF(ISBLANK(F9),0,F9-F8) -> 0 | H9: 86766 | I9: =IF(ISBLANK(H9),0,H9-H8) -> 374 | J9: 601758 | K9: =IF(ISBLANK(J9),0,J9-J8) -> 360 | M9: =I9/L9 -> #DIV/0! | N9: 11504 | O9: =IF(ISBLANK(N9),0,N9-N8) -> 93 | P9: 95089 | Q9: =IF(ISBLANK(P9),0,P9-P8) -> 96 | R9: 36 | S9: =IF(ISBLANK(R9),0,R9-R8) -> 0 | T9: 198477 | U9: =IF(ISBLANK(T9),0,T9-T8) -> 127 | X9: 18419 | AA9: 3146 | AC9: =IF(ISBLANK(AB9),0,SUM(AB9-AB8)) -> 0 | AD9: 330 | AF9: =IF(ISBLANK(AE9),0,SUM(AE9-AE8)) -> 0 | AG9: 1178 | AI9: =IF(ISBLANK(AH9),0,SUM(AH9-AH8)*80) -> 0 | AJ9: 168 | AM9: =IF(ISBLANK(AL9),0,AL9-AL8) -> 0 | AN9: 472 | AQ9: =IF(ISBLANK(AP9),0,SUM(AP9-AP8)*80) -> 0 | AR9: 280 | AS9: 27 | AT9: 37 | AW9: =IF(ISBLANK(AV10),0,AV10-AV9) -> 0 | AY9: =1+AY8 -> 5 | AZ9: =IF(D9<>0,(+D9-D$10)/A9*31,0) -> -948.6 | BA9: =IF(F9<>0,(+F9-F$10)/$A9*31,0) -> 0 | BB9: =IF(H9<>0,(+H9-H$10)/$A9*31,0) -> -2238.2 | BC9: =IF(N9<>0,(+N9-N$10)/$A9*31,0) -> -589 | BD9: =IF(V9<>0,(+V9-V$10)*2200/$A9*31,0) -> 0 | BE9: =IF(X9<>0,AVERAGE(X9:X$11)*31,) -> 566597.33 | BF9: =IF(AD9+AG9<>0,AVERAGE(AD9:AD$11)*31+AVERAGE(AG9:AG$11)*31,) -> 46799.667 | BG9: =IF(AJ9<>0,AVERAGE(AJ9:AJ$11)*31,) -> 4629.3333 | BH9: =IF(AN9<>0,AVERAGE(AN9:AN$11)*31,) -> 14787 | BI9: =IF(AR9<>0,AVERAGE(AR9:AR$11)*31,) -> 8266.6667
A10: =1+A9 -> 6 | B10: 00:00 | D10: 325035 | E10: =IF(ISBLANK(D10),0,D10-D9) -> 153 | F10: 7051 | G10: =IF(ISBLANK(F10),0,F10-F9) -> 0 | H10: 87127 | I10: =IF(ISBLANK(H10),0,H10-H9) -> 361 | J10: 602106 | K10: =IF(ISBLANK(J10),0,J10-J9) -> 348 | M10: =I10/L10 -> #DIV/0! | N10: 11599 | O10: =IF(ISBLANK(N10),0,N10-N9) -> 95 | P10: 95182 | Q10: =IF(ISBLANK(P10),0,P10-P9) -> 93 | R10: 36 | S10: =IF(ISBLANK(R10),0,R10-R9) -> 0 | T10: 198597 | U10: =IF(ISBLANK(T10),0,T10-T9) -> 120 | X10: 18829 | AA10: 3246 | AC10: =IF(ISBLANK(AB10),0,SUM(AB10-AB9)) -> 0 | AD10: 348 | AF10: =IF(ISBLANK(AE10),0,SUM(AE10-AE9)) -> 0 | AG10: 1239 | AI10: =IF(ISBLANK(AH10),0,SUM(AH10-AH9)*80) -> 0 | AJ10: 144 | AM10: =IF(ISBLANK(AL10),0,AL10-AL9) -> 0 | AN10: 471 | AQ10: =IF(ISBLANK(AP10),0,SUM(AP10-AP9)*80) -> 0 | AR10: 264 | AS10: 26 | AT10: 36 | AW10: =IF(ISBLANK(AV11),0,AV11-AV10) -> 0 | AY10: =1+AY9 -> 6 | AZ10: =IF(D10<>0,(+D10-D$10)/A10*31,0) -> 0 | BA10: =IF(F10<>0,(+F10-F$10)/$A10*31,0) -> 0 | BB10: =IF(H10<>0,(+H10-H$10)/$A10*31,0) -> 0 | BC10: =IF(N10<>0,(+N10-N$10)/$A10*31,0) -> 0 | BD10: =IF(V10<>0,(+V10-V$10)*2200/$A10*31,0) -> 0 | BE10: =IF(X10<>0,AVERAGE(X10:X$11)*31,) -> 564401.5 | BF10: =IF(AD10+AG10<>0,AVERAGE(AD10:AD$11)*31+AVERAGE(AG10:AG$11)*31,) -> 46825.5 | BG10: =IF(AJ10<>0,AVERAGE(AJ10:AJ$11)*31,) -> 4340 | BH10: =IF(AN10<>0,AVERAGE(AN10:AN$11)*31,) -> 14864.5 | BI10: =IF(AR10<>0,AVERAGE(AR10:AR$11)*31,) -> 8060
A11: =1+A10 -> 7 | B11: 00:00 | D11: 325228 | E11: =IF(ISBLANK(D11),0,D11-D10) -> 193 | F11: 7051 | G11: =IF(ISBLANK(F11),0,F11-F10) -> 0 | H11: 87432 | I11: =IF(ISBLANK(H11),0,H11-H10) -> 305 | J11: 602400 | K11: =IF(ISBLANK(J11),0,J11-J10) -> 294 | M11: =I11/L11 -> #DIV/0! | N11: 11677 | O11: =IF(ISBLANK(N11),0,N11-N10) -> 78 | P11: 95272 | Q11: =IF(ISBLANK(P11),0,P11-P10) -> 90 | R11: 36 | S11: =IF(ISBLANK(R11),0,R11-R10) -> 0 | T11: 198715 | U11: =IF(ISBLANK(T11),0,T11-T10) -> 118 | X11: 17584 | AA11: 2790 | AC11: =IF(ISBLANK(AB11),0,SUM(AB11-AB10)) -> 0 | AD11: 351 | AF11: =IF(ISBLANK(AE11),0,SUM(AE11-AE10)) -> 0 | AG11: 1083 | AI11: =IF(ISBLANK(AH11),0,SUM(AH11-AH10)*80) -> 0 | AJ11: 136 | AM11: =IF(ISBLANK(AL11),0,AL11-AL10) -> 0 | AN11: 488 | AQ11: =IF(ISBLANK(AP11),0,SUM(AP11-AP10)*80) -> 0 | AR11: 256 | AS11: 22 | AT11: 32 | AW11: =IF(ISBLANK(AV12),0,AV12-AV11) -> 0 | AY11: =1+AY10 -> 7 | AZ11: =IF(D11<>0,(+D11-D$10)/A11*31,0) -> 854.71429 | BA11: =IF(F11<>0,(+F11-F$10)/$A11*31,0) -> 0 | BB11: =IF(H11<>0,(+H11-H$10)/$A11*31,0) -> 1350.7143 | BC11: =IF(N11<>0,(+N11-N$10)/$A11*31,0) -> 345.42857 | BD11: =IF(V11<>0,(+V11-V$10)*2200/$A11*31,0) -> 0 | BE11: =IF(X11<>0,AVERAGE(X$11:X11)*31,) -> 545104 | BF11: =IF(AD11+AG11<>0,AVERAGE(AD$11:AD11)*31+AVERAGE(AG$11:AG11)*31,) -> 44454 | BG11: =IF(AJ11<>0,AVERAGE(AJ$11:AJ11)*31,) -> 4216 | BH11: =IF(AN11<>0,AVERAGE(AN$11:AN11)*31,) -> 15128 | BI11: =IF(AR11<>0,AVERAGE(AR$11:AR11)*31,) -> 7936
A12: =1+A11 -> 8 | B12: 00:00 | D12: 325454 | E12: =IF(ISBLANK(D12),0,D12-D11) -> 226 | F12: 7051 | G12: =IF(ISBLANK(F12),0,F12-F11) -> 0 | H12: 87755 | I12: =IF(ISBLANK(H12),0,H12-H11) -> 323 | J12: 602711 | K12: =IF(ISBLANK(J12),0,J12-J11) -> 311 | M12: =I12/L12 -> #DIV/0! | N12: 11754 | O12: =IF(ISBLANK(N12),0,N12-N11) -> 77 | P12: 95365 | Q12: =IF(ISBLANK(P12),0,P12-P11) -> 93 | R12: 36 | S12: =IF(ISBLANK(R12),0,R12-R11) -> 0 | T12: 198835 | U12: =IF(ISBLANK(T12),0,T12-T11) -> 120 | X12: 17554 | AA12: 2792 | AC12: =IF(ISBLANK(AB12),0,SUM(AB12-AB11)) -> 0 | AD12: 347 | AF12: =IF(ISBLANK(AE12),0,SUM(AE12-AE11)) -> 0 | AG12: 1123 | AI12: =IF(ISBLANK(AH12),0,SUM(AH12-AH11)*80) -> 0 | AJ12: 152 | AM12: =IF(ISBLANK(AL12),0,AL12-AL11) -> 0 | AN12: 485 | AQ12: =IF(ISBLANK(AP12),0,SUM(AP12-AP11)*80) -> 0 | AR12: 272 | AS12: 21 | AT12: 31 | AW12: =IF(ISBLANK(AV13),0,AV13-AV12) -> 0 | AY12: =1+AY11 -> 8 | AZ12: =IF(D12<>0,(+D12-D$10)/A12*31,0) -> 1623.625 | BA12: =IF(F12<>0,(+F12-F$10)/$A12*31,0) -> 0 | BB12: =IF(H12<>0,(+H12-H$10)/$A12*31,0) -> 2433.5 | BC12: =IF(N12<>0,(+N12-N$10)/$A12*31,0) -> 600.625 | BD12: =IF(V12<>0,(+V12-V$10)*2200/$A12*31,0) -> 0 | BE12: =IF(X12<>0,AVERAGE(X$11:X12)*31,) -> 544639 | BF12: =IF(AD12+AG12<>0,AVERAGE(AD$11:AD12)*31+AVERAGE(AG$11:AG12)*31,) -> 45012 | BG12: =IF(AJ12<>0,AVERAGE(AJ$11:AJ12)*31,) -> 4464 | BH12: =IF(AN12<>0,AVERAGE(AN$11:AN12)*31,) -> 15081.5 | BI12: =IF(AR12<>0,AVERAGE(AR$11:AR12)*31,) -> 8184
A13: 9 | B13: 00:00 | D13: 325655 | E13: =IF(ISBLANK(D13),0,D13-D12) -> 201 | F13: 7052 | G13: =IF(ISBLANK(F13),0,F13-F12) -> 1 | H13: 88089 | I13: =IF(ISBLANK(H13),0,H13-H12) -> 334 | J13: 603032 | K13: =IF(ISBLANK(J13),0,J13-J12) -> 321 | M13: =I13/L13 -> #DIV/0! | N13: 11836 | O13: =IF(ISBLANK(N13),0,N13-N12) -> 82 | P13: 95453 | Q13: =IF(ISBLANK(P13),0,P13-P12) -> 88 | R13: 36 | S13: =IF(ISBLANK(R13),0,R13-R12) -> 0 | T13: 198952 | U13: =IF(ISBLANK(T13),0,T13-T12) -> 117 | X13: 17815 | AA13: 3087 | AC13: =IF(ISBLANK(AB13),0,SUM(AB13-AB12)) -> 0 | AD13: 340 | AF13: =IF(ISBLANK(AE13),0,SUM(AE13-AE12)) -> 0 | AG13: 1184 | AI13: =IF(ISBLANK(AH13),0,SUM(AH13-AH12)*80) -> 0 | AJ13: 168 | AM13: =IF(ISBLANK(AL13),0,AL13-AL12) -> 0 | AN13: 458 | AQ13: =IF(ISBLANK(AP13),0,SUM(AP13-AP12)*80) -> 0 | AR13: 248 | AS13: 22 | AT13: 30 | AW13: =IF(ISBLANK(AV14),0,AV14-AV13) -> 0 | AY13: =1+AY12 -> 9 | AZ13: =IF(D13<>0,(+D13-D$10)/A13*31,0) -> 2135.5556 | BA13: =IF(F13<>0,(+F13-F$10)/$A13*31,0) -> 3.4444444 | BB13: =IF(H13<>0,(+H13-H$10)/$A13*31,0) -> 3313.5556 | BC13: =IF(N13<>0,(+N13-N$10)/$A13*31,0) -> 816.33333 | BD13: =IF(V13<>0,(+V13-V$10)*2200/$A13*31,0) -> 0 | BE13: =IF(X13<>0,AVERAGE(X$11:X13)*31,) -> 547181 | BF13: =IF(AD13+AG13<>0,AVERAGE(AD$11:AD13)*31+AVERAGE(AG$11:AG13)*31,) -> 45756 | BG13: =IF(AJ13<>0,AVERAGE(AJ$11:AJ13)*31,) -> 4712 | BH13: =IF(AN13<>0,AVERAGE(AN$11:AN13)*31,) -> 14787 | BI13: =IF(AR13<>0,AVERAGE(AR$11:AR13)*31,) -> 8018.6667
A14: =1+A13 -> 10 | B14: 00:00 | D14: 325853 | E14: =IF(ISBLANK(D14),0,D14-D13) -> 198 | F14: 7053 | G14: =IF(ISBLANK(F14),0,F14-F13) -> 1 | H14: 88436 | I14: =IF(ISBLANK(H14),0,H14-H13) -> 347 | J14: 603367 | K14: =IF(ISBLANK(J14),0,J14-J13) -> 335 | M14: =I14/L14 -> #DIV/0! | N14: 11916 | O14: =IF(ISBLANK(N14),0,N14-N13) -> 80 | P14: 95546 | Q14: =IF(ISBLANK(P14),0,P14-P13) -> 93 | R14: 36 | S14: =IF(ISBLANK(R14),0,R14-R13) -> 0 | T14: 199077 | U14: =IF(ISBLANK(T14),0,T14-T13) -> 125 | V14: 5082.428 | X14: 17502 | Y14: 971.22 | AA14: 2729 | AB14: 1749999 | AC14: =IF(ISBLANK(AB14),0,SUM(AB14-AB13)) -> 1749999 | AD14: 366 | AE14: 5164121 | AF14: =IF(ISBLANK(AE14),0,SUM(AE14-AE13)) -> 5164121 | AG14: 1302 | AH14: 34087 | AI14: =IF(ISBLANK(AH14),0,SUM(AH14-AH13)*80) -> 2726960 | AJ14: 144 | AL14: 207219 | AM14: =IF(ISBLANK(AL14),0,AL14-AL13) -> 207219 | AN14: 467 | AP14: 46746 | AQ14: =IF(ISBLANK(AP14),0,SUM(AP14-AP13)*80) -> 3739680 | AR14: 296 | AS14: 22 | AT14: 32 | AW14: =IF(ISBLANK(AV15),0,AV15-AV14) -> 0 | AY14: =1+AY13 -> 10 | AZ14: =IF(D14<>0,(+D14-D$10)/A14*31,0) -> 2535.8 | BA14: =IF(F14<>0,(+F14-F$10)/$A14*31,0) -> 6.2 | BB14: =IF(H14<>0,(+H14-H$10)/$A14*31,0) -> 4057.9 | BC14: =IF(N14<>0,(+N14-N$10)/$A14*31,0) -> 982.7 | BD14: =IF(V14<>0,(+V14-V$10)*2200/$A14*31,0) -> 34662159 | BE14: =IF(X14<>0,AVERAGE(X$11:X14)*31,) -> 546026.25 | BF14: =IF(AD14+AG14<>0,AVERAGE(AD$11:AD14)*31+AVERAGE(AG$11:AG14)*31,) -> 47244 | BG14: =IF(AJ14<>0,AVERAGE(AJ$11:AJ14)*31,) -> 4650 | BH14: =IF(AN14<>0,AVERAGE(AN$11:AN14)*31,) -> 14709.5 | BI14: =IF(AR14<>0,AVERAGE(AR$11:AR14)*31,) -> 8308
A15: =1+A14 -> 11 | B15: 00:00 | D15: 326054 | E15: =IF(ISBLANK(D15),0,D15-D14) -> 201 | F15: 7053 | G15: =IF(ISBLANK(F15),0,F15-F14) -> 0 | H15: 88769 | I15: =IF(ISBLANK(H15),0,H15-H14) -> 333 | J15: 603687 | K15: =IF(ISBLANK(J15),0,J15-J14) -> 320 | M15: =I15/L15 -> #DIV/0! | N15: 11995 | O15: =IF(ISBLANK(N15),0,N15-N14) -> 79 | P15: 95639 | Q15: =IF(ISBLANK(P15),0,P15-P14) -> 93 | R15: 36 | S15: =IF(ISBLANK(R15),0,R15-R14) -> 0 | T15: 199200 | U15: =IF(ISBLANK(T15),0,T15-T14) -> 123 | X15: 17114 | AA15: 2832 | AC15: =IF(ISBLANK(AB15),0,SUM(AB15-AB14)) -> 0 | AD15: 337 | AF15: =IF(ISBLANK(AE15),0,SUM(AE15-AE14)) -> 0 | AG15: 1231 | AI15: =IF(ISBLANK(AH15),0,SUM(AH15-AH14)*80) -> 0 | AJ15: 136 | AM15: =IF(ISBLANK(AL15),0,AL15-AL14) -> 0 | AN15: 437 | AQ15: =IF(ISBLANK(AP15),0,SUM(AP15-AP14)*80) -> 0 | AR15: 312 | AS15: 22 | AT15: 32 | AW15: =IF(ISBLANK(AV16),0,AV16-AV15) -> 0 | AY15: 11 | AZ15: =IF(D15<>0,(+D15-D$10)/A15*31,0) -> 2871.7273 | BA15: =IF(F15<>0,(+F15-F$10)/$A15*31,0) -> 5.6363636 | BB15: =IF(H15<>0,(+H15-H$10)/$A15*31,0) -> 4627.4545 | BC15: =IF(N15<>0,(+N15-N$10)/$A15*31,0) -> 1116 | BD15: =IF(V15<>0,(+V15-V$10)*2200/$A15*31,0) -> 0 | BE15: =IF(X15<>0,AVERAGE(X$11:X15)*31,) -> 542927.8 | BF15: =IF(AD15+AG15<>0,AVERAGE(AD$11:AD15)*31+AVERAGE(AG$11:AG15)*31,) -> 47516.8 | BG15: =IF(AJ15<>0,AVERAGE(AJ$11:AJ15)*31,) -> 4563.2 | BH15: =IF(AN15<>0,AVERAGE(AN$11:AN15)*31,) -> 14477 | BI15: =IF(AR15<>0,AVERAGE(AR$11:AR15)*31,) -> 8580.8
A16: =1+A15 -> 12 | B16: 00:00 | D16: 326263 | E16: =IF(ISBLANK(D16),0,D16-D15) -> 209 | F16: 7053 | G16: =IF(ISBLANK(F16),0,F16-F15) -> 0 | H16: 89082 | I16: =IF(ISBLANK(H16),0,H16-H15) -> 313 | J16: 603988 | K16: =IF(ISBLANK(J16),0,J16-J15) -> 301 | M16: =I16/L16 -> #DIV/0! | N16: 12065 | O16: =IF(ISBLANK(N16),0,N16-N15) -> 70 | P16: 95718 | Q16: =IF(ISBLANK(P16),0,P16-P15) -> 79 | R16: 36 | S16: =IF(ISBLANK(R16),0,R16-R15) -> 0 | T16: 199307 | U16: =IF(ISBLANK(T16),0,T16-T15) -> 107 | X16: 16839 | AA16: 3041 | AC16: =IF(ISBLANK(AB16),0,SUM(AB16-AB15)) -> 0 | AD16: 366 | AF16: =IF(ISBLANK(AE16),0,SUM(AE16-AE15)) -> 0 | AG16: 1228 | AI16: =IF(ISBLANK(AH16),0,SUM(AH16-AH15)*80) -> 0 | AJ16: 168 | AM16: =IF(ISBLANK(AL16),0,AL16-AL15) -> 0 | AN16: 452 | AQ16: =IF(ISBLANK(AP16),0,SUM(AP16-AP15)*80) -> 0 | AR16: 256 | AS16: 19 | AT16: 31 | AW16: =IF(ISBLANK(AV17),0,AV17-AV16) -> 0 | AY16: =1+AY15 -> 12 | AZ16: =IF(D16<>0,(+D16-D$10)/A16*31,0) -> 3172.3333 | BA16: =IF(F16<>0,(+F16-F$10)/$A16*31,0) -> 5.1666667 | BB16: =IF(H16<>0,(+H16-H$10)/$A16*31,0) -> 5050.4167 | BC16: =IF(N16<>0,(+N16-N$10)/$A16*31,0) -> 1203.8333 | BD16: =IF(V16<>0,(+V16-V$10)*2200/$A16*31,0) -> 0 | BE16: =IF(X16<>0,AVERAGE(X$11:X16)*31,) -> 539441.33 | BF16: =IF(AD16+AG16<>0,AVERAGE(AD$11:AD16)*31+AVERAGE(AG$11:AG16)*31,) -> 47833 | BG16: =IF(AJ16<>0,AVERAGE(AJ$11:AJ16)*31,) -> 4670.6667 | BH16: =IF(AN16<>0,AVERAGE(AN$11:AN16)*31,) -> 14399.5 | BI16: =IF(AR16<>0,AVERAGE(AR$11:AR16)*31,) -> 8473.3333
A17: 13 | B17: 00:00 | D17: 326471 | E17: =IF(ISBLANK(D17),0,D17-D16) -> 208 | F17: 7053 | G17: =IF(ISBLANK(F17),0,F17-F16) -> 0 | H17: 89347 | I17: =IF(ISBLANK(H17),0,H17-H16) -> 265 | J17: 604244 | K17: =IF(ISBLANK(J17),0,J17-J16) -> 256 | M17: =I17/L17 -> #DIV/0! | N17: 12128 | O17: =IF(ISBLANK(N17),0,N17-N16) -> 63 | P17: 95771 | Q17: =IF(ISBLANK(P17),0,P17-P16) -> 53 | R17: 36 | S17: =IF(ISBLANK(R17),0,R17-R16) -> 0 | T17: 199384 | U17: =IF(ISBLANK(T17),0,T17-T16) -> 77 | X17: 16332 | AA17: 2935 | AC17: =IF(ISBLANK(AB17),0,SUM(AB17-AB16)) -> 0 | AD17: 339 | AF17: =IF(ISBLANK(AE17),0,SUM(AE17-AE16)) -> 0 | AG17: 1182 | AI17: =IF(ISBLANK(AH17),0,SUM(AH17-AH16)*80) -> 0 | AJ17: 168 | AM17: =IF(ISBLANK(AL17),0,AL17-AL16) -> 0 | AN17: 466 | AQ17: =IF(ISBLANK(AP17),0,SUM(AP17-AP16)*80) -> 0 | AR17: 240 | AS17: 18 | AT17: 31 | AW17: =IF(ISBLANK(AV18),0,AV18-AV17) -> 0 | AY17: =1+AY16 -> 13 | AZ17: =IF(D17<>0,(+D17-D$10)/A17*31,0) -> 3424.3077 | BA17: =IF(F17<>0,(+F17-F$10)/$A17*31,0) -> 4.7692308 | BB17: =IF(H17<>0,(+H17-H$10)/$A17*31,0) -> 5293.8462 | BC17: =IF(N17<>0,(+N17-N$10)/$A17*31,0) -> 1261.4615 | BD17: =IF(V17<>0,(+V17-V$10)*2200/$A17*31,0) -> 0 | BE17: =IF(X17<>0,AVERAGE(X$11:X17)*31,) -> 534705.71 | BF17: =IF(AD17+AG17<>0,AVERAGE(AD$11:AD17)*31+AVERAGE(AG$11:AG17)*31,) -> 47735.571 | BG17: =IF(AJ17<>0,AVERAGE(AJ$11:AJ17)*31,) -> 4747.4286 | BH17: =IF(AN17<>0,AVERAGE(AN$11:AN17)*31,) -> 14406.143 | BI17: =IF(AR17<>0,AVERAGE(AR$11:AR17)*31,) -> 8325.7143
A18: =1+A17 -> 14 | B18: 00:00 | D18: 326681 | E18: =IF(ISBLANK(D18),0,D18-D17) -> 210 | F18: 7054 | G18: =IF(ISBLANK(F18),0,F18-F17) -> 1 | H18: 89611 | I18: =IF(ISBLANK(H18),0,H18-H17) -> 264 | J18: 604497 | K18: =IF(ISBLANK(J18),0,J18-J17) -> 253 | M18: =I18/L18 -> #DIV/0! | N18: 12194 | O18: =IF(ISBLANK(N18),0,N18-N17) -> 66 | P18: 95820 | Q18: =IF(ISBLANK(P18),0,P18-P17) -> 49 | R18: 36 | S18: =IF(ISBLANK(R18),0,R18-R17) -> 0 | T18: 199460 | U18: =IF(ISBLANK(T18),0,T18-T17) -> 76 | X18: 16365 | AA18: 2890 | AC18: =IF(ISBLANK(AB18),0,SUM(AB18-AB17)) -> 0 | AD18: 349 | AF18: =IF(ISBLANK(AE18),0,SUM(AE18-AE17)) -> 0 | AG18: 1135 | AI18: =IF(ISBLANK(AH18),0,SUM(AH18-AH17)*80) -> 0 | AJ18: 168 | AM18: =IF(ISBLANK(AL18),0,AL18-AL17) -> 0 | AN18: 464 | AQ18: =IF(ISBLANK(AP18),0,SUM(AP18-AP17)*80) -> 0 | AR18: 240 | AS18: 19 | AT18: 31 | AW18: =IF(ISBLANK(AV19),0,AV19-AV18) -> 0 | AY18: =1+AY17 -> 14 | AZ18: =IF(D18<>0,(+D18-D$10)/A18*31,0) -> 3644.7143 | BA18: =IF(F18<>0,(+F18-F$10)/$A18*31,0) -> 6.6428571 | BB18: =IF(H18<>0,(+H18-H$10)/$A18*31,0) -> 5500.2857 | BC18: =IF(N18<>0,(+N18-N$10)/$A18*31,0) -> 1317.5 | BD18: =IF(V18<>0,(+V18-V$10)*2200/$A18*31,0) -> 0 | BE18: =IF(X18<>0,AVERAGE(X$11:X18)*31,) -> 531281.88 | BF18: =IF(AD18+AG18<>0,AVERAGE(AD$11:AD18)*31+AVERAGE(AG$11:AG18)*31,) -> 47519.125 | BG18: =IF(AJ18<>0,AVERAGE(AJ$11:AJ18)*31,) -> 4805 | BH18: =IF(AN18<>0,AVERAGE(AN$11:AN18)*31,) -> 14403.375 | BI18: =IF(AR18<>0,AVERAGE(AR$11:AR18)*31,) -> 8215
A19: =1+A18 -> 15 | B19: 00:00 | D19: 326885 | E19: =IF(ISBLANK(D19),0,D19-D18) -> 204 | F19: 7054 | G19: =IF(ISBLANK(F19),0,F19-F18) -> 0 | H19: 89886 | I19: =IF(ISBLANK(H19),0,H19-H18) -> 275 | J19: 604761 | K19: =IF(ISBLANK(J19),0,J19-J18) -> 264 | M19: =I19/L19 -> #DIV/0! | N19: 12264 | O19: =IF(ISBLANK(N19),0,N19-N18) -> 70 | P19: 95867 | Q19: =IF(ISBLANK(P19),0,P19-P18) -> 47 | R19: 36 | S19: =IF(ISBLANK(R19),0,R19-R18) -> 0 | T19: 199530 | U19: =IF(ISBLANK(T19),0,T19-T18) -> 70 | X19: 16925 | AA19: 2987 | AC19: =IF(ISBLANK(AB19),0,SUM(AB19-AB18)) -> 0 | AD19: 345 | AF19: =IF(ISBLANK(AE19),0,SUM(AE19-AE18)) -> 0 | AG19: 1056 | AI19: =IF(ISBLANK(AH19),0,SUM(AH19-AH18)*80) -> 0 | AJ19: 152 | AM19: =IF(ISBLANK(AL19),0,AL19-AL18) -> 0 | AN19: 486 | AQ19: =IF(ISBLANK(AP19),0,SUM(AP19-AP18)*80) -> 0 | AR19: 240 | AS19: 21 | AT19: 32 | AW19: =IF(ISBLANK(AV20),0,AV20-AV19) -> 0 | AY19: =1+AY18 -> 15 | AZ19: =IF(D19<>0,(+D19-D$10)/A19*31,0) -> 3823.3333 | BA19: =IF(F19<>0,(+F19-F$10)/$A19*31,0) -> 6.2 | BB19: =IF(H19<>0,(+H19-H$10)/$A19*31,0) -> 5701.9333 | BC19: =IF(N19<>0,(+N19-N$10)/$A19*31,0) -> 1374.3333 | BD19: =IF(V19<>0,(+V19-V$10)*2200/$A19*31,0) -> 0 | BE19: =IF(X19<>0,AVERAGE(X$11:X19)*31,) -> 530547.78 | BF19: =IF(AD19+AG19<>0,AVERAGE(AD$11:AD19)*31+AVERAGE(AG$11:AG19)*31,) -> 47064.889 | BG19: =IF(AJ19<>0,AVERAGE(AJ$11:AJ19)*31,) -> 4794.6667 | BH19: =IF(AN19<>0,AVERAGE(AN$11:AN19)*31,) -> 14477 | BI19: =IF(AR19<>0,AVERAGE(AR$11:AR19)*31,) -> 8128.8889
A20: =1+A19 -> 16 | B20: 00:00 | D20: 327085 | E20: =IF(ISBLANK(D20),0,D20-D19) -> 200 | F20: 7054 | G20: =IF(ISBLANK(F20),0,F20-F19) -> 0 | H20: 90165 | I20: =IF(ISBLANK(H20),0,H20-H19) -> 279 | J20: 605030 | K20: =IF(ISBLANK(J20),0,J20-J19) -> 269 | M20: =I20/L20 -> #DIV/0! | N20: 12338 | O20: =IF(ISBLANK(N20),0,N20-N19) -> 74 | P20: 95917 | Q20: =IF(ISBLANK(P20),0,P20-P19) -> 50 | R20: 37 | S20: =IF(ISBLANK(R20),0,R20-R19) -> 1 | T20: 199603 | U20: =IF(ISBLANK(T20),0,T20-T19) -> 73 | X20: 17480 | AA20: 3064 | AC20: =IF(ISBLANK(AB20),0,SUM(AB20-AB19)) -> 0 | AD20: 359 | AF20: =IF(ISBLANK(AE20),0,SUM(AE20-AE19)) -> 0 | AG20: 1136 | AI20: =IF(ISBLANK(AH20),0,SUM(AH20-AH19)*80) -> 0 | AJ20: 168 | AM20: =IF(ISBLANK(AL20),0,AL20-AL19) -> 0 | AN20: 466 | AQ20: =IF(ISBLANK(AP20),0,SUM(AP20-AP19)*80) -> 0 | AR20: 256 | AS20: 24 | AT20: 33 | AW20: =IF(ISBLANK(AV21),0,AV21-AV20) -> 0 | AY20: =1+AY19 -> 16 | AZ20: =IF(D20<>0,(+D20-D$10)/A20*31,0) -> 3971.875 | BA20: =IF(F20<>0,(+F20-F$10)/$A20*31,0) -> 5.8125 | BB20: =IF(H20<>0,(+H20-H$10)/$A20*31,0) -> 5886.125 | BC20: =IF(N20<>0,(+N20-N$10)/$A20*31,0) -> 1431.8125 | BD20: =IF(V20<>0,(+V20-V$10)*2200/$A20*31,0) -> 0 | BE20: =IF(X20<>0,AVERAGE(X$11:X20)*31,) -> 531681 | BF20: =IF(AD20+AG20<>0,AVERAGE(AD$11:AD20)*31+AVERAGE(AG$11:AG20)*31,) -> 46992.9 | BG20: =IF(AJ20<>0,AVERAGE(AJ$11:AJ20)*31,) -> 4836 | BH20: =IF(AN20<>0,AVERAGE(AN$11:AN20)*31,) -> 14473.9 | BI20: =IF(AR20<>0,AVERAGE(AR$11:AR20)*31,) -> 8109.6
A21: =1+A20 -> 17 | B21: 00:00 | D21: 327293 | E21: =IF(ISBLANK(D21),0,D21-D20) -> 208 | F21: 7054 | G21: =IF(ISBLANK(F21),0,F21-F20) -> 0 | H21: 90452 | I21: =IF(ISBLANK(H21),0,H21-H20) -> 287 | J21: 605306 | K21: =IF(ISBLANK(J21),0,J21-J20) -> 276 | M21: =I21/L21 -> #DIV/0! | N21: 12412 | O21: =IF(ISBLANK(N21),0,N21-N20) -> 74 | P21: 95963 | Q21: =IF(ISBLANK(P21),0,P21-P20) -> 46 | R21: 37 | S21: =IF(ISBLANK(R21),0,R21-R20) -> 0 | T21: 199680 | U21: =IF(ISBLANK(T21),0,T21-T20) -> 77 | X21: 17943 | AA21: 2921 | AC21: =IF(ISBLANK(AB21),0,SUM(AB21-AB20)) -> 0 | AD21: 359 | AF21: =IF(ISBLANK(AE21),0,SUM(AE21-AE20)) -> 0 | AG21: 1149 | AI21: =IF(ISBLANK(AH21),0,SUM(AH21-AH20)*80) -> 0 | AJ21: 176 | AM21: =IF(ISBLANK(AL21),0,AL21-AL20) -> 0 | AN21: 484 | AQ21: =IF(ISBLANK(AP21),0,SUM(AP21-AP20)*80) -> 0 | AR21: 280 | AS21: 22 | AT21: 30 | AW21: =IF(ISBLANK(AV22),0,AV22-AV21) -> 0 | AY21: =1+AY20 -> 17 | AZ21: =IF(D21<>0,(+D21-D$10)/A21*31,0) -> 4117.5294 | BA21: =IF(F21<>0,(+F21-F$10)/$A21*31,0) -> 5.4705882 | BB21: =IF(H21<>0,(+H21-H$10)/$A21*31,0) -> 6063.2353 | BC21: =IF(N21<>0,(+N21-N$10)/$A21*31,0) -> 1482.5294 | BD21: =IF(V21<>0,(+V21-V$10)*2200/$A21*31,0) -> 0 | BE21: =IF(X21<>0,AVERAGE(X$11:X21)*31,) -> 533913 | BF21: =IF(AD21+AG21<>0,AVERAGE(AD$11:AD21)*31+AVERAGE(AG$11:AG21)*31,) -> 46970.636 | BG21: =IF(AJ21<>0,AVERAGE(AJ$11:AJ21)*31,) -> 4892.3636 | BH21: =IF(AN21<>0,AVERAGE(AN$11:AN21)*31,) -> 14522.091 | BI21: =IF(AR21<>0,AVERAGE(AR$11:AR21)*31,) -> 8161.4545
A22: =1+A21 -> 18 | B22: 00:00 | D22: 327504 | E22: =IF(ISBLANK(D22),0,D22-D21) -> 211 | F22: 7054 | G22: =IF(ISBLANK(F22),0,F22-F21) -> 0 | H22: 90710 | I22: =IF(ISBLANK(H22),0,H22-H21) -> 258 | J22: 605555 | K22: =IF(ISBLANK(J22),0,J22-J21) -> 249 | M22: =I22/L22 -> #DIV/0! | N22: 12468 | O22: =IF(ISBLANK(N22),0,N22-N21) -> 56 | P22: 96011 | Q22: =IF(ISBLANK(P22),0,P22-P21) -> 48 | R22: 37 | S22: =IF(ISBLANK(R22),0,R22-R21) -> 0 | T22: 199755 | U22: =IF(ISBLANK(T22),0,T22-T21) -> 75 | X22: 16790 | AA22: 2907 | AC22: =IF(ISBLANK(AB22),0,SUM(AB22-AB21)) -> 0 | AD22: 335 | AF22: =IF(ISBLANK(AE22),0,SUM(AE22-AE21)) -> 0 | AG22: 1048 | AI22: =IF(ISBLANK(AH22),0,SUM(AH22-AH21)*80) -> 0 | AJ22: 176 | AM22: =IF(ISBLANK(AL22),0,AL22-AL21) -> 0 | AN22: 465 | AQ22: =IF(ISBLANK(AP22),0,SUM(AP22-AP21)*80) -> 0 | AR22: 256 | AS22: 20 | AT22: 24 | AW22: =IF(ISBLANK(AV23),0,AV23-AV22) -> 0 | AY22: =1+AY21 -> 18 | AZ22: =IF(D22<>0,(+D22-D$10)/A22*31,0) -> 4252.1667 | BA22: =IF(F22<>0,(+F22-F$10)/$A22*31,0) -> 5.1666667 | BB22: =IF(H22<>0,(+H22-H$10)/$A22*31,0) -> 6170.7222 | BC22: =IF(N22<>0,(+N22-N$10)/$A22*31,0) -> 1496.6111 | BD22: =IF(V22<>0,(+V22-V$10)*2200/$A22*31,0) -> 0 | BE22: =IF(X22<>0,AVERAGE(X$11:X22)*31,) -> 532794.42 | BF22: =IF(AD22+AG22<>0,AVERAGE(AD$11:AD22)*31+AVERAGE(AG$11:AG22)*31,) -> 46629.167 | BG22: =IF(AJ22<>0,AVERAGE(AJ$11:AJ22)*31,) -> 4939.3333 | BH22: =IF(AN22<>0,AVERAGE(AN$11:AN22)*31,) -> 14513.167 | BI22: =IF(AR22<>0,AVERAGE(AR$11:AR22)*31,) -> 8142.6667
A23: =1+A22 -> 19 | B23: 00:00 | D23: 327716 | E23: =IF(ISBLANK(D23),0,D23-D22) -> 212 | F23: 7054 | G23: =IF(ISBLANK(F23),0,F23-F22) -> 0 | H23: 90970 | I23: =IF(ISBLANK(H23),0,H23-H22) -> 260 | J23: 605805 | K23: =IF(ISBLANK(J23),0,J23-J22) -> 250 | M23: =I23/L23 -> #DIV/0! | N23: 12525 | O23: =IF(ISBLANK(N23),0,N23-N22) -> 57 | P23: 96050 | Q23: =IF(ISBLANK(P23),0,P23-P22) -> 39 | R23: 37 | S23: =IF(ISBLANK(R23),0,R23-R22) -> 0 | T23: 199822 | U23: =IF(ISBLANK(T23),0,T23-T22) -> 67 | X23: 16328 | AA23: 2800 | AC23: =IF(ISBLANK(AB23),0,SUM(AB23-AB22)) -> 0 | AD23: 335 | AF23: =IF(ISBLANK(AE23),0,SUM(AE23-AE22)) -> 0 | AG23: 1236 | AI23: =IF(ISBLANK(AH23),0,SUM(AH23-AH22)*80) -> 0 | AJ23: 160 | AM23: =IF(ISBLANK(AL23),0,AL23-AL22) -> 0 | AN23: 481 | AQ23: =IF(ISBLANK(AP23),0,SUM(AP23-AP22)*80) -> 0 | AR23: 248 | AS23: 19 | AT23: 29 | AW23: =IF(ISBLANK(AV24),0,AV24-AV23) -> 0 | AY23: =1+AY22 -> 19 | AZ23: =IF(D23<>0,(+D23-D$10)/A23*31,0) -> 4374.2632 | BA23: =IF(F23<>0,(+F23-F$10)/$A23*31,0) -> 4.8947368 | BB23: =IF(H23<>0,(+H23-H$10)/$A23*31,0) -> 6270.1579 | BC23: =IF(N23<>0,(+N23-N$10)/$A23*31,0) -> 1510.8421 | BD23: =IF(V23<>0,(+V23-V$10)*2200/$A23*31,0) -> 0 | BE23: =IF(X23<>0,AVERAGE(X$11:X23)*31,) -> 530746.23 | BF23: =IF(AD23+AG23<>0,AVERAGE(AD$11:AD23)*31+AVERAGE(AG$11:AG23)*31,) -> 46788.538 | BG23: =IF(AJ23<>0,AVERAGE(AJ$11:AJ23)*31,) -> 4940.9231 | BH23: =IF(AN23<>0,AVERAGE(AN$11:AN23)*31,) -> 14543.769 | BI23: =IF(AR23<>0,AVERAGE(AR$11:AR23)*31,) -> 8107.6923
A24: =1+A23 -> 20 | B24: 00:00 | D24: 327914 | E24: =IF(ISBLANK(D24),0,D24-D23) -> 198 | F24: 7054 | G24: =IF(ISBLANK(F24),0,F24-F23) -> 0 | H24: 91231 | I24: =IF(ISBLANK(H24),0,H24-H23) -> 261 | J24: 606055 | K24: =IF(ISBLANK(J24),0,J24-J23) -> 250 | M24: =I24/L24 -> #DIV/0! | N24: 12593 | O24: =IF(ISBLANK(N24),0,N24-N23) -> 68 | P24: 96087 | Q24: =IF(ISBLANK(P24),0,P24-P23) -> 37 | R24: 37 | S24: =IF(ISBLANK(R24),0,R24-R23) -> 0 | T24: 199883 | U24: =IF(ISBLANK(T24),0,T24-T23) -> 61 | V24: 5160.093 | X24: 16363 | Y24: 985.582 | AA24: 2890 | AB24: 1753455 | AC24: =IF(ISBLANK(AB24),0,SUM(AB24-AB23)) -> 1753455 | AD24: 336 | AE24: 5176762 | AF24: =IF(ISBLANK(AE24),0,SUM(AE24-AE23)) -> 5176762 | AG24: 1087 | AH24: 34091 | AI24: =IF(ISBLANK(AH24),0,SUM(AH24-AH23)*80) -> 2727280 | AJ24: 168 | AL24: 211894 | AM24: =IF(ISBLANK(AL24),0,AL24-AL23) -> 211894 | AN24: 476 | AP24: 48777 | AQ24: =IF(ISBLANK(AP24),0,SUM(AP24-AP23)*80) -> 3902160 | AR24: 224 | AS24: 20 | AT24: 33 | AW24: =IF(ISBLANK(AV25),0,AV25-AV24) -> 0 | AY24: =1+AY23 -> 20 | AZ24: =IF(D24<>0,(+D24-D$10)/A24*31,0) -> 4462.45 | BA24: =IF(F24<>0,(+F24-F$10)/$A24*31,0) -> 4.65 | BB24: =IF(H24<>0,(+H24-H$10)/$A24*31,0) -> 6361.2 | BC24: =IF(N24<>0,(+N24-N$10)/$A24*31,0) -> 1540.7 | BD24: =IF(V24<>0,(+V24-V$10)*2200/$A24*31,0) -> 17595917 | BE24: =IF(X24<>0,AVERAGE(X$11:X24)*31,) -> 529068.14 | BF24: =IF(AD24+AG24<>0,AVERAGE(AD$11:AD24)*31+AVERAGE(AG$11:AG24)*31,) -> 46597.429 | BG24: =IF(AJ24<>0,AVERAGE(AJ$11:AJ24)*31,) -> 4960 | BH24: =IF(AN24<>0,AVERAGE(AN$11:AN24)*31,) -> 14558.929 | BI24: =IF(AR24<>0,AVERAGE(AR$11:AR24)*31,) -> 8024.5714
A25: =1+A24 -> 21 | B25: 00:00 | D25: 328114 | E25: =IF(ISBLANK(D25),0,D25-D24) -> 200 | F25: 7054 | G25: =IF(ISBLANK(F25),0,F25-F24) -> 0 | H25: 91492 | I25: =IF(ISBLANK(H25),0,H25-H24) -> 261 | J25: 606307 | K25: =IF(ISBLANK(J25),0,J25-J24) -> 252 | M25: =I25/L25 -> #DIV/0! | N25: 12662 | O25: =IF(ISBLANK(N25),0,N25-N24) -> 69 | P25: 96125 | Q25: =IF(ISBLANK(P25),0,P25-P24) -> 38 | R25: 37 | S25: =IF(ISBLANK(R25),0,R25-R24) -> 0 | T25: 199947 | U25: =IF(ISBLANK(T25),0,T25-T24) -> 64 | X25: 16162 | AA25: 2887 | AC25: =IF(ISBLANK(AB25),0,SUM(AB25-AB24)) -> 0 | AD25: 327 | AF25: =IF(ISBLANK(AE25),0,SUM(AE25-AE24)) -> 0 | AG25: 894 | AI25: =IF(ISBLANK(AH25),0,SUM(AH25-AH24)*80) -> 0 | AJ25: 264 | AM25: =IF(ISBLANK(AL25),0,AL25-AL24) -> 0 | AN25: 473 | AQ25: =IF(ISBLANK(AP25),0,SUM(AP25-AP24)*80) -> 0 | AR25: 272 | AS25: 19 | AT25: 32 | AW25: =IF(ISBLANK(AV26),0,AV26-AV25) -> 0 | AY25: =1+AY24 -> 21 | AZ25: =IF(D25<>0,(+D25-D$10)/A25*31,0) -> 4545.1905 | BA25: =IF(F25<>0,(+F25-F$10)/$A25*31,0) -> 4.4285714 | BB25: =IF(H25<>0,(+H25-H$10)/$A25*31,0) -> 6443.5714 | BC25: =IF(N25<>0,(+N25-N$10)/$A25*31,0) -> 1569.1905 | BD25: =IF(V25<>0,(+V25-V$10)*2200/$A25*31,0) -> 0 | BE25: =IF(X25<>0,AVERAGE(X$11:X25)*31,) -> 527198.4 | BF25: =IF(AD25+AG25<>0,AVERAGE(AD$11:AD25)*31+AVERAGE(AG$11:AG25)*31,) -> 46014.333 | BG25: =IF(AJ25<>0,AVERAGE(AJ$11:AJ25)*31,) -> 5174.9333 | BH25: =IF(AN25<>0,AVERAGE(AN$11:AN25)*31,) -> 14565.867 | BI25: =IF(AR25<>0,AVERAGE(AR$11:AR25)*31,) -> 8051.7333
A26: =1+A25 -> 22 | B26: 00:00 | D26: 328328 | E26: =IF(ISBLANK(D26),0,D26-D25) -> 214 | F26: 7054.24 | G26: =IF(ISBLANK(F26),0,F26-F25) -> 0.24 | H26: 91771 | I26: =IF(ISBLANK(H26),0,H26-H25) -> 279 | J26: 606576 | K26: =IF(ISBLANK(J26),0,J26-J25) -> 269 | M26: =I26/L26 -> #DIV/0! | N26: 12721 | O26: =IF(ISBLANK(N26),0,N26-N25) -> 59 | P26: 96164 | Q26: =IF(ISBLANK(P26),0,P26-P25) -> 39 | R26: 37 | S26: =IF(ISBLANK(R26),0,R26-R25) -> 0 | T26: 200005 | U26: =IF(ISBLANK(T26),0,T26-T25) -> 58 | X26: 16685 | AA26: 2650 | AC26: =IF(ISBLANK(AB26),0,SUM(AB26-AB25)) -> 0 | AD26: 337 | AF26: =IF(ISBLANK(AE26),0,SUM(AE26-AE25)) -> 0 | AG26: 1038 | AI26: =IF(ISBLANK(AH26),0,SUM(AH26-AH25)*80) -> 0 | AJ26: 264 | AM26: =IF(ISBLANK(AL26),0,AL26-AL25) -> 0 | AN26: 467 | AQ26: =IF(ISBLANK(AP26),0,SUM(AP26-AP25)*80) -> 0 | AR26: 264 | AS26: 22 | AT26: 33 | AW26: =IF(ISBLANK(AV27),0,AV27-AV26) -> 0 | AY26: =1+AY25 -> 22 | AZ26: =IF(D26<>0,(+D26-D$10)/A26*31,0) -> 4640.1364 | BA26: =IF(F26<>0,(+F26-F$10)/$A26*31,0) -> 4.5654545 | BB26: =IF(H26<>0,(+H26-H$10)/$A26*31,0) -> 6543.8182 | BC26: =IF(N26<>0,(+N26-N$10)/$A26*31,0) -> 1581 | BD26: =IF(V26<>0,(+V26-V$10)*2200/$A26*31,0) -> 0 | BE26: =IF(X26<>0,AVERAGE(X$11:X26)*31,) -> 526575.69 | BF26: =IF(AD26+AG26<>0,AVERAGE(AD$11:AD26)*31+AVERAGE(AG$11:AG26)*31,) -> 45802.5 | BG26: =IF(AJ26<>0,AVERAGE(AJ$11:AJ26)*31,) -> 5363 | BH26: =IF(AN26<>0,AVERAGE(AN$11:AN26)*31,) -> 14560.312 | BI26: =IF(AR26<>0,AVERAGE(AR$11:AR26)*31,) -> 8060
A27: =1+A26 -> 23 | B27: 00:00 | D27: 328571 | E27: =IF(ISBLANK(D27),0,D27-D26) -> 243 | F27: 7054 | G27: =IF(ISBLANK(F27),0,F27-F26) -> -0.24 | H27: 92024 | I27: =IF(ISBLANK(H27),0,H27-H26) -> 253 | J27: 606819 | K27: =IF(ISBLANK(J27),0,J27-J26) -> 243 | M27: =I27/L27 -> #DIV/0! | N27: 12796 | O27: =IF(ISBLANK(N27),0,N27-N26) -> 75 | P27: 96208 | Q27: =IF(ISBLANK(P27),0,P27-P26) -> 44 | R27: 37 | S27: =IF(ISBLANK(R27),0,R27-R26) -> 0 | T27: 200071 | U27: =IF(ISBLANK(T27),0,T27-T26) -> 66 | X27: 16609 | AA27: 2802 | AC27: =IF(ISBLANK(AB27),0,SUM(AB27-AB26)) -> 0 | AD27: 376 | AF27: =IF(ISBLANK(AE27),0,SUM(AE27-AE26)) -> 0 | AG27: 1138 | AI27: =IF(ISBLANK(AH27),0,SUM(AH27-AH26)*80) -> 0 | AJ27: 160 | AM27: =IF(ISBLANK(AL27),0,AL27-AL26) -> 0 | AN27: 485 | AQ27: =IF(ISBLANK(AP27),0,SUM(AP27-AP26)*80) -> 0 | AR27: 184 | AS27: 24 | AT27: 33 | AW27: =IF(ISBLANK(AV29),0,AV29-AV27) -> 0 | AY27: =1+AY26 -> 23 | AZ27: =IF(D27<>0,(+D27-D$10)/A27*31,0) -> 4765.913 | BA27: =IF(F27<>0,(+F27-F$10)/$A27*31,0) -> 4.0434783 | BB27: =IF(H27<>0,(+H27-H$10)/$A27*31,0) -> 6600.3043 | BC27: =IF(N27<>0,(+N27-N$10)/$A27*31,0) -> 1613.3478 | BD27: =IF(V27<>0,(+V27-V$10)*2200/$A27*31,0) -> 0 | BE27: =IF(X27<>0,AVERAGE(X$11:X27)*31,) -> 525887.65 | BF27: =IF(AD27+AG27<>0,AVERAGE(AD$11:AD27)*31+AVERAGE(AG$11:AG27)*31,) -> 45869.059 | BG27: =IF(AJ27<>0,AVERAGE(AJ$11:AJ27)*31,) -> 5339.2941 | BH27: =IF(AN27<>0,AVERAGE(AN$11:AN27)*31,) -> 14588.235 | BI27: =IF(AR27<>0,AVERAGE(AR$11:AR27)*31,) -> 7921.4118
A28: 24 | B28: 34 | D28: 328721 | E28: =IF(ISBLANK(D28),0,D28-D27) -> 150 | F28: 7054 | G28: =IF(ISBLANK(F28),0,F28-F27) -> 0 | H28: 92281 | I28: =IF(ISBLANK(H28),0,H28-H27) -> 257 | J28: 607067 | K28: =IF(ISBLANK(J28),0,J28-J27) -> 248 | M28: #DIV/0! | N28: 12871 | O28: =IF(ISBLANK(N28),0,N28-N27) -> 75 | P28: 96255 | Q28: =IF(ISBLANK(P28),0,P28-P27) -> 47 | R28: 37 | S28: =IF(ISBLANK(R28),0,R28-R27) -> 0 | T28: 200141 | U28: =IF(ISBLANK(T28),0,T28-T27) -> 70 | X28: 16395 | AA28: 2322 | AC28: 0 | AD28: 345 | AF28: 0 | AG28: 1155 | AI28: 0 | AJ28: 168 | AM28: 0 | AN28: 500 | AQ28: 0 | AR28: 208 | AS28: 24 | AT28: 33 | AW28: 0 | AY28: 24 | AZ28: =IF(D28<>0,(+D28-D$10)/A28*31,0) -> 4761.0833 | BA28: =IF(F28<>0,(+F28-F$10)/$A28*31,0) -> 3.875 | BB28: =IF(H28<>0,(+H28-H$10)/$A28*31,0) -> 6657.25 | BC28: =IF(N28<>0,(+N28-N$10)/$A28*31,0) -> 1643 | BD28: 0 | BE28: 0 | BF28: 0 | BG28: 0 | BH28: 0 | BI28: 0
A29: 25 | B29: 34 | C29: GF4 comp. B fermo | D29: 328945 | E29: =IF(ISBLANK(D29),0,D29-D28) -> 224 | F29: 7054 | G29: =IF(ISBLANK(F29),0,F29-F28) -> 0 | H29: 92544 | I29: =IF(ISBLANK(H29),0,H29-H28) -> 263 | J29: 607319 | K29: =IF(ISBLANK(J29),0,J29-J28) -> 252 | M29: =I29/L29 -> #DIV/0! | N29: 12937 | O29: =IF(ISBLANK(N29),0,N29-N28) -> 66 | P29: 96289 | Q29: =IF(ISBLANK(P29),0,P29-P27) -> 81 | R29: 37 | S29: =IF(ISBLANK(R29),0,R29-R28) -> 0 | T29: 200199 | U29: =IF(ISBLANK(T29),0,T29-T28) -> 58 | X29: 16513 | AA29: 2722 | AC29: =IF(ISBLANK(AB29),0,SUM(AB29-AB27)) -> 0 | AD29: 355 | AF29: =IF(ISBLANK(AE29),0,SUM(AE29-AE27)) -> 0 | AG29: 1130 | AI29: =IF(ISBLANK(AH29),0,SUM(AH29-AH27)*80) -> 0 | AJ29: 160 | AM29: =IF(ISBLANK(AL29),0,AL29-AL27) -> 0 | AN29: 469 | AQ29: =IF(ISBLANK(AP29),0,SUM(AP29-AP27)*80) -> 0 | AR29: 232 | AS29: 23 | AT29: 31 | AW29: =IF(ISBLANK(AV30),0,AV30-AV29) -> 0 | AY29: =1+AY27 -> 24 | AZ29: =IF(D29<>0,(+D29-D$10)/A29*31,0) -> 4848.4 | BA29: =IF(F29<>0,(+F29-F$10)/$A29*31,0) -> 3.72 | BB29: =IF(H29<>0,(+H29-H$10)/$A29*31,0) -> 6717.08 | BC29: =IF(N29<>0,(+N29-N$10)/$A29*31,0) -> 1659.12 | BD29: =IF(V29<>0,(+V29-V$10)*2200/$A29*31,0) -> 0 | BE29: =IF(X29<>0,AVERAGE(X$11:X29)*31,) -> 524223.05 | BF29: =IF(AD29+AG29<>0,AVERAGE(AD$11:AD29)*31+AVERAGE(AG$11:AG29)*31,) -> 45911 | BG29: =IF(AJ29<>0,AVERAGE(AJ$11:AJ29)*31,) -> 5312.4211 | BH29: =IF(AN29<>0,AVERAGE(AN$11:AN29)*31,) -> 14633.632 | BI29: =IF(AR29<>0,AVERAGE(AR$11:AR29)*31,) -> 7805.4737
A30: =1+A29 -> 26 | B30: 00:00 | C30: UTA meet off | D30: 329206 | E30: =IF(ISBLANK(D30),0,D30-D29) -> 261 | F30: 7054 | G30: =IF(ISBLANK(F30),0,F30-F29) -> 0 | H30: 92818 | I30: =IF(ISBLANK(H30),0,H30-H29) -> 274 | J30: 607583 | K30: =IF(ISBLANK(J30),0,J30-J29) -> 264 | M30: =I30/L30 -> #DIV/0! | N30: 13007 | O30: =IF(ISBLANK(N30),0,N30-N29) -> 70 | P30: 96328 | Q30: =IF(ISBLANK(P30),0,P30-P29) -> 39 | R30: 37 | S30: =IF(ISBLANK(R30),0,R30-R29) -> 0 | T30: 200261 | U30: =IF(ISBLANK(T30),0,T30-T29) -> 62 | X30: 16586 | AA30: 2815 | AC30: =IF(ISBLANK(AB30),0,SUM(AB30-AB29)) -> 0 | AD30: 324 | AF30: =IF(ISBLANK(AE30),0,SUM(AE30-AE29)) -> 0 | AG30: 1121 | AI30: =IF(ISBLANK(AH30),0,SUM(AH30-AH29)*80) -> 0 | AJ30: 160 | AM30: =IF(ISBLANK(AL30),0,AL30-AL29) -> 0 | AN30: 443 | AQ30: =IF(ISBLANK(AP30),0,SUM(AP30-AP29)*80) -> 0 | AR30: 272 | AS30: 24 | AT30: 33 | AW30: =IF(ISBLANK(AV31),0,AV31-AV30) -> 0 | AY30: =1+AY29 -> 25 | AZ30: =IF(D30<>0,(+D30-D$10)/A30*31,0) -> 4973.1154 | BA30: =IF(F30<>0,(+F30-F$10)/$A30*31,0) -> 3.5769231 | BB30: =IF(H30<>0,(+H30-H$10)/$A30*31,0) -> 6785.4231 | BC30: =IF(N30<>0,(+N30-N$10)/$A30*31,0) -> 1678.7692 | BD30: =IF(V30<>0,(+V30-V$10)*2200/$A30*31,0) -> 0 | BE30: =IF(X30<>0,AVERAGE(X$11:X30)*31,) -> 523720.2 | BF30: =IF(AD30+AG30<>0,AVERAGE(AD$11:AD30)*31+AVERAGE(AG$11:AG30)*31,) -> 45855.2 | BG30: =IF(AJ30<>0,AVERAGE(AJ$11:AJ30)*31,) -> 5294.8 | BH30: =IF(AN30<>0,AVERAGE(AN$11:AN30)*31,) -> 14588.6 | BI30: =IF(AR30<>0,AVERAGE(AR$11:AR30)*31,) -> 7836.8
A31: =1+A30 -> 27 | B31: 00:00 | C31: " " | D31: 329484 | E31: =IF(ISBLANK(D31),0,D31-D30) -> 278 | F31: 7054 | G31: =IF(ISBLANK(F31),0,F31-F30) -> 0 | H31: 93115 | I31: =IF(ISBLANK(H31),0,H31-H30) -> 297 | J31: 607868 | K31: =IF(ISBLANK(J31),0,J31-J30) -> 285 | M31: =I31/L31 -> #DIV/0! | N31: 13081 | O31: =IF(ISBLANK(N31),0,N31-N30) -> 74 | P31: 96373 | Q31: =IF(ISBLANK(P31),0,P31-P30) -> 45 | R31: 37 | S31: =IF(ISBLANK(R31),0,R31-R30) -> 0 | T31: 200342 | U31: =IF(ISBLANK(T31),0,T31-T30) -> 81 | X31: 16516 | AA31: 2740 | AC31: =IF(ISBLANK(AB31),0,SUM(AB31-AB30)) -> 0 | AD31: 339 | AF31: =IF(ISBLANK(AE31),0,SUM(AE31-AE30)) -> 0 | AG31: 1152 | AI31: =IF(ISBLANK(AH31),0,SUM(AH31-AH30)*80) -> 0 | AJ31: 192 | AM31: =IF(ISBLANK(AL31),0,AL31-AL30) -> 0 | AN31: 488 | AQ31: =IF(ISBLANK(AP31),0,SUM(AP31-AP30)*80) -> 0 | AR31: 288 | AS31: 20 | AT31: 31 | AW31: =IF(ISBLANK(AV32),0,AV32-AV31) -> 0 | AY31: =1+AY30 -> 26 | AZ31: =IF(D31<>0,(+D31-D$10)/A31*31,0) -> 5108.1111 | BA31: =IF(F31<>0,(+F31-F$10)/$A31*31,0) -> 3.4444444 | BB31: =IF(H31<>0,(+H31-H$10)/$A31*31,0) -> 6875.1111 | BC31: =IF(N31<>0,(+N31-N$10)/$A31*31,0) -> 1701.5556 | BD31: =IF(V31<>0,(+V31-V$10)*2200/$A31*31,0) -> 0 | BE31: =IF(X31<>0,AVERAGE(X$11:X31)*31,) -> 523161.9 | BF31: =IF(AD31+AG31<>0,AVERAGE(AD$11:AD31)*31+AVERAGE(AG$11:AG31)*31,) -> 45872.619 | BG31: =IF(AJ31<>0,AVERAGE(AJ$11:AJ31)*31,) -> 5326.0952 | BH31: =IF(AN31<>0,AVERAGE(AN$11:AN31)*31,) -> 14614.286 | BI31: =IF(AR31<>0,AVERAGE(AR$11:AR31)*31,) -> 7888.7619
A32: =1+A31 -> 28 | B32: 00:00 | C32: " " | D32: 329751 | E32: =IF(ISBLANK(D32),0,D32-D31) -> 267 | F32: 7054 | G32: =IF(ISBLANK(F32),0,F32-F31) -> 0 | H32: 93385 | I32: =IF(ISBLANK(H32),0,H32-H31) -> 270 | J32: 608128 | K32: =IF(ISBLANK(J32),0,J32-J31) -> 260 | M32: =I32/L32 -> #DIV/0! | N32: 13143 | O32: =IF(ISBLANK(N32),0,N32-N31) -> 62 | P32: 96416 | Q32: =IF(ISBLANK(P32),0,P32-P31) -> 43 | R32: 37 | S32: =IF(ISBLANK(R32),0,R32-R31) -> 0 | T32: 200415 | U32: =IF(ISBLANK(T32),0,T32-T31) -> 73 | X32: 16279 | AA32: 3146 | AC32: =IF(ISBLANK(AB32),0,SUM(AB32-AB31)) -> 0 | AD32: 336 | AF32: =IF(ISBLANK(AE32),0,SUM(AE32-AE31)) -> 0 | AG32: 1105 | AI32: =IF(ISBLANK(AH32),0,SUM(AH32-AH31)*80) -> 0 | AJ32: 168 | AM32: =IF(ISBLANK(AL32),0,AL32-AL31) -> 0 | AN32: 500 | AQ32: =IF(ISBLANK(AP32),0,SUM(AP32-AP31)*80) -> 0 | AR32: 264 | AS32: 20 | AT32: 31 | AW32: =IF(ISBLANK(AV33),0,AV33-AV32) -> 0 | AY32: =1+AY31 -> 27 | AZ32: =IF(D32<>0,(+D32-D$10)/A32*31,0) -> 5221.2857 | BA32: =IF(F32<>0,(+F32-F$10)/$A32*31,0) -> 3.3214286 | BB32: =IF(H32<>0,(+H32-H$10)/$A32*31,0) -> 6928.5 | BC32: =IF(N32<>0,(+N32-N$10)/$A32*31,0) -> 1709.4286 | BD32: =IF(V32<>0,(+V32-V$10)*2200/$A32*31,0) -> 0 | BE32: =IF(X32<>0,AVERAGE(X$11:X32)*31,) -> 522320.41 | BF32: =IF(AD32+AG32<>0,AVERAGE(AD$11:AD32)*31+AVERAGE(AG$11:AG32)*31,) -> 45818 | BG32: =IF(AJ32<>0,AVERAGE(AJ$11:AJ32)*31,) -> 5320.7273 | BH32: =IF(AN32<>0,AVERAGE(AN$11:AN32)*31,) -> 14654.545 | BI32: =IF(AR32<>0,AVERAGE(AR$11:AR32)*31,) -> 7902.1818
A33: 29 | B33: 00:00 | D33: 330028 | E33: =IF(ISBLANK(D33),0,D33-D32) -> 277 | F33: 7054 | G33: =IF(ISBLANK(F33),0,F33-F32) -> 0 | H33: 93671 | I33: =IF(ISBLANK(H33),0,H33-H32) -> 286 | J33: 608403 | K33: =IF(ISBLANK(J33),0,J33-J32) -> 275 | M33: =I33/L33 -> #DIV/0! | N33: 13217 | O33: =IF(ISBLANK(N33),0,N33-N32) -> 74 | P33: 96462 | Q33: =IF(ISBLANK(P33),0,P33-P32) -> 46 | R33: 37 | S33: =IF(ISBLANK(R33),0,R33-R32) -> 0 | T33: 200487 | U33: =IF(ISBLANK(T33),0,T33-T32) -> 72 | X33: 17255 | AA33: 3064 | AC33: =IF(ISBLANK(AB33),0,SUM(AB33-AB32)) -> 0 | AD33: 339 | AF33: =IF(ISBLANK(AE33),0,SUM(AE33-AE32)) -> 0 | AG33: 1083 | AI33: =IF(ISBLANK(AH33),0,SUM(AH33-AH32)*80) -> 0 | AJ33: 144 | AM33: =IF(ISBLANK(AL33),0,AL33-AL32) -> 0 | AN33: 466 | AQ33: =IF(ISBLANK(AP33),0,SUM(AP33-AP32)*80) -> 0 | AR33: 208 | AS33: 20 | AT33: 31 | AW33: =IF(ISBLANK(AV34),0,AV34-AV33) -> 0 | AY33: 28 | AZ33: =IF(D33<>0,(+D33-D$10)/A33*31,0) -> 5337.3448 | BA33: =IF(F33<>0,(+F33-F$10)/$A33*31,0) -> 3.2068966 | BB33: =IF(H33<>0,(+H33-H$10)/$A33*31,0) -> 6995.3103 | BC33: =IF(N33<>0,(+N33-N$10)/$A33*31,0) -> 1729.5862 | BD33: =IF(V33<>0,(+V33-V$10)*2200/$A33*31,0) -> 0 | BE33: =IF(X33<>0,AVERAGE(X$11:X33)*31,) -> 522867.57 | BF33: =IF(AD33+AG33<>0,AVERAGE(AD$11:AD33)*31+AVERAGE(AG$11:AG33)*31,) -> 45742.522 | BG33: =IF(AJ33<>0,AVERAGE(AJ$11:AJ33)*31,) -> 5283.4783 | BH33: =IF(AN33<>0,AVERAGE(AN$11:AN33)*31,) -> 14645.478 | BI33: =IF(AR33<>0,AVERAGE(AR$11:AR33)*31,) -> 7838.9565
A34: 30 | B34: 00:00 | D34: 330267 | E34: =IF(ISBLANK(D34),0,D34-D33) -> 239 | F34: 7054 | G34: =IF(ISBLANK(F34),0,F34-F33) -> 0 | H34: 93951 | I34: =IF(ISBLANK(H34),0,H34-H33) -> 280 | J34: 608681 | K34: =IF(ISBLANK(J34),0,J34-J33) -> 278 | M34: =I34/L34 -> #DIV/0! | N34: 13284 | O34: =IF(ISBLANK(N34),0,N34-N33) -> 67 | P34: 96501 | Q34: =IF(ISBLANK(P34),0,P34-P33) -> 39 | R34: 37 | S34: =IF(ISBLANK(R34),0,R34-R33) -> 0 | T34: 200558 | U34: =IF(ISBLANK(T34),0,T34-T33) -> 71 | X34: 17422 | AA34: 3019 | AC34: =IF(ISBLANK(AB34),0,SUM(AB34-AB33)) -> 0 | AD34: 350 | AF34: =IF(ISBLANK(AE34),0,SUM(AE34-AE33)) -> 0 | AG34: 1079 | AI34: =IF(ISBLANK(AH34),0,SUM(AH34-AH33)*80) -> 0 | AJ34: 160 | AM34: =IF(ISBLANK(AL34),0,AL34-AL33) -> 0 | AN34: 493 | AQ34: =IF(ISBLANK(AP34),0,SUM(AP34-AP33)*80) -> 0 | AR34: 248 | AS34: 20 | AT34: 30 | AW34: =IF(ISBLANK(AV35),0,AV35-AV34) -> 0 | AY34: =1+AY33 -> 29 | AZ34: =IF(D34<>0,(+D34-D$10)/A34*31,0) -> 5406.4 | BA34: =IF(F34<>0,(+F34-F$10)/$A34*31,0) -> 3.1 | BB34: =IF(H34<>0,(+H34-H$10)/$A34*31,0) -> 7051.4667 | BC34: =IF(N34<>0,(+N34-N$10)/$A34*31,0) -> 1741.1667 | BD34: =IF(V34<>0,(+V34-V$10)*2200/$A34*31,0) -> 0 | BE34: =IF(X34<>0,AVERAGE(X$11:X34)*31,) -> 523584.83 | BF34: =IF(AD34+AG34<>0,AVERAGE(AD$11:AD34)*31+AVERAGE(AG$11:AG34)*31,) -> 45682.375 | BG34: =IF(AJ34<>0,AVERAGE(AJ$11:AJ34)*31,) -> 5270 | BH34: =IF(AN34<>0,AVERAGE(AN$11:AN34)*31,) -> 14672.042 | BI34: =IF(AR34<>0,AVERAGE(AR$11:AR34)*31,) -> 7832.6667
A35: 31 | B35: 00:00 | D35: 330565 | E35: =IF(ISBLANK(D35),0,D35-D34) -> 298 | F35: 7056 | G35: =IF(ISBLANK(F35),0,F35-F34) -> 2 | H35: 94191 | I35: =IF(ISBLANK(H35),0,H35-H34) -> 240 | J35: 608903 | K35: =IF(ISBLANK(J35),0,J35-J34) -> 222 | M35: =I35/L35 -> #DIV/0! | N35: 13342 | O35: =IF(ISBLANK(N35),0,N35-N34) -> 58 | P35: 96549 | Q35: =IF(ISBLANK(P35),0,P35-P34) -> 48 | R35: 37 | S35: =IF(ISBLANK(R35),0,R35-R34) -> 0 | T35: 200620 | U35: =IF(ISBLANK(T35),0,T35-T34) -> 62 | V35: 5243.8 | X35: 15399 | Y35: 1001.05 | AA35: 2200 | AB35: 1757227 | AC35: =IF(ISBLANK(AB35),0,SUM(AB35-AB34)) -> 1757227 | AD35: 340 | AE35: 5187529 | AF35: =IF(ISBLANK(AE35),0,SUM(AE35-AE34)) -> 5187529 | AG35: 1035 | AH35: 34098 | AI35: =IF(ISBLANK(AH35),0,SUM(AH35-AH34)*80) -> 2727840 | AJ35: 128 | AL35: 217127 | AM35: =IF(ISBLANK(AL35),0,AL35-AL34) -> 217127 | AN35: 449 | AP35: 46810 | AQ35: =IF(ISBLANK(AP35),0,SUM(AP35-AP34)*80) -> 3744800 | AR35: 224 | AS35: 19 | AT35: 29 | AW35: =IF(ISBLANK(AV36),0,AV36-AV35) -> 0 | AX35: 1 | AY35: =1+AY34 -> 30 | AZ35: =IF(D35<>0,(+D35-D$10)/A35*31,0) -> 5530 | BA35: =IF(F35<>0,(+F35-F$10)/$A35*31,0) -> 5 | BB35: =IF(H35<>0,(+H35-H$10)/$A35*31,0) -> 7064 | BC35: =IF(N35<>0,(+N35-N$10)/$A35*31,0) -> 1743 | BD35: =IF(V35<>0,(+V35-V$10)*2200/$A35*31,0) -> 11536360 | BE35: =IF(X35<>0,AVERAGE(X$11:X35)*31,) -> 521736.2 | BF35: =IF(AD35+AG35<>0,AVERAGE(AD$11:AD35)*31+AVERAGE(AG$11:AG35)*31,) -> 45560.08 | BG35: =IF(AJ35<>0,AVERAGE(AJ$11:AJ35)*31,) -> 5217.92 | BH35: =IF(AN35<>0,AVERAGE(AN$11:AN35)*31,) -> 14641.92 | BI35: =IF(AR35<>0,AVERAGE(AR$11:AR35)*31,) -> 7797.12
A36: TOTALE | D36: =D35-D4 -> 6799 | F36: =F35-F4 -> 6 | H36: =H35-H4 -> 9234 | N36: =N35-N4 -> 2264 | P36: =P35-P5 -> 1850 | R36: =R35-R5 -> 1 | T36: =T35-T5 -> 2637 | V36: =SUM(+V35-V4)*2200 -> 539792 | X36: =SUM(X4:X35) -> 529057 | Y36: =Y35-Y4 -> 44.67 | AA36: =SUM(AA4:AA35) -> 88887 | AB36: =SUM(+AB35-AB4) -> 10691 | AD36: =SUM(AD4:AD35) -> 10688 | AE36: =SUM(+AE35-AE4) -> 35110 | AG36: =SUM(AG4:AG35) -> 35106 | AH36: =SUM(+AH35-AH4)*80 -> 2400 | AJ36: =SUM(AJ4:AJ35) -> 5184 | AL36: =SUM(+AL35-AL4) -> 14584 | AN36: =SUM(AN4:AN35) -> 14584 | AP36: =SUM(+AP35-AP4)*80 -> 7920 | AR36: =SUM(AR4:AR35) -> 7952 | AS36: =AVERAGE(AS5:AS35) -> 21.612903 | AT36: =AVERAGE(AT5:AT35) -> 31.967742 | AY36: 31
A37: CONSUMI | AB37: =AD36+AG36 -> 45794 | AJ37: =AB37+AJ36 -> 50978 | AS37: MEDIA
A39: BUDGET | D39: 7000 | F39: 50 | H39: 5200 | N39: 6500 | V39: 550000
A40: RIMECO 15 | D40: 6838 | F40: 107 | H40: 5501 | N40: 1281 | V40: 557339
A41: RIMECO 16 | D41: 10312 | F41: 91 | H41: 6541 | N41: 974 | V41: 517912
A42: RIMECO 17 | D42: 4814 | F42: 63 | H42: 5713 | N42: 933 | V42: 567068
...
