Workbook

Sheet Submetering
A1: Site Name | B1: Day | C1: Month | D1: Year | E1: ATS1 Kwh | F1: ATS2 Kwh | G1: ATS3 Kwh | H1: ATS4 Kwh | I1: ATS5 Kwh | J1: Guest (m3) | K1: Kitchen & Laundry (m3) | L1: Room Nights
A2: Beirut | B2: 1 | C2: 2 | D2: 2023 | E2: =ELEC!M4 -> 978 | F2: =ELEC!K4 -> 708 | G2: =ELEC!I4 -> 444 | H2: =ELEC!E4 -> 1020 | I2: =ELEC!G4 -> 314 | J2: =WATER!Y6 -> 0 | K2: =WATER!AJ6 -> 0 | L2: =ELEC!B4 -> 0
A3: Beirut | B3: =B2+1 -> 2 | C3: 2 | D3: 2023 | E3: =ELEC!M5 -> 852 | F3: =ELEC!K5 -> 898 | G3: =ELEC!I5 -> 410 | H3: =ELEC!E5 -> 640 | I3: =ELEC!G5 -> 265 | J3: =WATER!Y7 -> 0 | K3: =WATER!AJ7 -> 0 | L3: =ELEC!B5 -> 0
A4: Beirut | B4: =B3+1 -> 3 | C4: 2 | D4: 2023 | E4: =ELEC!M6 -> 0 | F4: =ELEC!K6 -> 0 | G4: =ELEC!I6 -> 0 | H4: =ELEC!E6 -> 0 | I4: =ELEC!G6 -> 0 | J4: =WATER!Y8 -> 0 | K4: =WATER!AJ8 -> 0 | L4: =ELEC!B6 -> 0
A5: Beirut | B5: =B4+1 -> 4 | C5: 2 | D5: 2023 | E5: =ELEC!M7 -> 0 | F5: =ELEC!K7 -> 0 | G5: =ELEC!I7 -> 0 | H5: =ELEC!E7 -> 0 | I5: =ELEC!G7 -> 0 | J5: =WATER!Y9 -> 0 | K5: =WATER!AJ9 -> 0 | L5: =ELEC!B7 -> 0
A6: Beirut | B6: =B5+1 -> 5 | C6: 2 | D6: 2023 | E6: =ELEC!M8 -> 890 | F6: =ELEC!K8 -> 806 | G6: =ELEC!I8 -> 470 | H6: =ELEC!E8 -> 760 | I6: =ELEC!G8 -> 335 | J6: =WATER!Y10 -> 0 | K6: =WATER!AJ10 -> 0 | L6: =ELEC!B8 -> 0
A7: Beirut | B7: =B6+1 -> 6 | C7: 2 | D7: 2023 | E7: =ELEC!M9 -> 890 | F7: =ELEC!K9 -> 810 | G7: =ELEC!I9 -> 462 | H7: =ELEC!E9 -> 780 | I7: =ELEC!G9 -> 356 | J7: =WATER!Y11 -> 0 | K7: =WATER!AJ11 -> 0 | L7: =ELEC!B9 -> 0
A8: Beirut | B8: =B7+1 -> 7 | C8: 2 | D8: 2023 | E8: =ELEC!M10 -> 1112 | F8: =ELEC!K10 -> 1048 | G8: =ELEC!I10 -> 450 | H8: =ELEC!E10 -> 750 | I8: =ELEC!G10 -> 352 | J8: =WATER!Y12 -> 0 | K8: =WATER!AJ12 -> 0 | L8: =ELEC!B10 -> 0
A9: Beirut | B9: =B8+1 -> 8 | C9: 2 | D9: 2023 | E9: =ELEC!M11 -> 872 | F9: =ELEC!K11 -> 874 | G9: =ELEC!I11 -> 384 | H9: =ELEC!E11 -> 1010 | I9: =ELEC!G11 -> 298 | J9: =WATER!Y13 -> 0 | K9: =WATER!AJ13 -> 0 | L9: =ELEC!B11 -> 0
A10: Beirut | B10: =B9+1 -> 9 | C10: 2 | D10: 2023 | E10: =ELEC!M12 -> 0 | F10: =ELEC!K12 -> 0 | G10: =ELEC!I12 -> 0 | H10: =ELEC!E12 -> 0 | I10: =ELEC!G12 -> 0 | J10: =WATER!Y14 -> 0 | K10: =WATER!AJ14 -> 0 | L10: =ELEC!B12 -> 0
A11: Beirut | B11: =B10+1 -> 10 | C11: 2 | D11: 2023 | E11: =ELEC!M13 -> 0 | F11: =ELEC!K13 -> 0 | G11: =ELEC!I13 -> 0 | H11: =ELEC!E13 -> 0 | I11: =ELEC!G13 -> 0 | J11: =WATER!Y15 -> 0 | K11: =WATER!AJ15 -> 0 | L11: =ELEC!B13 -> 0
A12: Beirut | B12: =B11+1 -> 11 | C12: 2 | D12: 2023 | E12: =ELEC!M14 -> 0 | F12: =ELEC!K14 -> 0 | G12: =ELEC!I14 -> 0 | H12: =ELEC!E14 -> 0 | I12: =ELEC!G14 -> 0 | J12: =WATER!Y16 -> 0 | K12: =WATER!AJ16 -> 0 | L12: =ELEC!B14 -> 0
A13: Beirut | B13: =B12+1 -> 12 | C13: 2 | D13: 2023 | E13: =ELEC!M15 -> 820 | F13: =ELEC!K15 -> 680 | G13: =ELEC!I15 -> 408 | H13: =ELEC!E15 -> 800 | I13: =ELEC!G15 -> 295 | J13: =WATER!Y17 -> 0 | K13: =WATER!AJ17 -> 0 | L13: =ELEC!B15 -> 0
A14: Beirut | B14: =B13+1 -> 13 | C14: 2 | D14: 2023 | E14: =ELEC!M16 -> 866 | F14: =ELEC!K16 -> 780 | G14: =ELEC!I16 -> 464 | H14: =ELEC!E16 -> 710 | I14: =ELEC!G16 -> 405 | J14: =WATER!Y18 -> 0 | K14: =WATER!AJ18 -> -57 | L14: =ELEC!B16 -> 0
... A29: Beirut | B29: =B28+1 -> 28 | C29: 2 | D29: 2023 | E29: =ELEC!M31 -> 0 | F29: =ELEC!K31 -> 0 | G29: =ELEC!I31 -> 0 | H29: =ELEC!E31 -> 0 | I29: =ELEC!G31 -> 0 | J29: =WATER!Y33 -> 0 | K29: =WATER!AJ33 -> 0 | L29: =ELEC!B31 -> 0
A30: Beirut
A31: Beirut
A32: Beirut
D45: .

Sheet Total
A1: Site Name | B1: Day | C1: Month | D1: Year | E1: Total Electricity Kwh | F1: Electricity Tariff ($/Kwh) | G1: Total Fuel Oil (Liter) | H1: Fuel Oil $/Liter | I1: LPG (Kg) | J1: LPG $/Kg | K1: Water Utility Supply (m3) m3 | L1: Water Utility Supply (m3) $/m3 | M1: Irrigation Water (m3) m3 | N1: Irrigation water $/m3 | O1: Room Nights
A2: Beirut | B2: 1 | C2: 2 | D2: 2023 | E2: =ELEC!N4 -> 3464 | F2: =SUM('EDl log'!T4) -> 0.4893128 | G2: =-tanks!AW6 -> 49 | H2: =tanks!AV6 -> 0.915 | I2: =('B5'!AU4)*0.51 -> 0 | J2: ='B5'!AX4/0.51 -> 1.5686275 | K2: =WATER!I6 -> 0 | L2: =SUM(WATER!J6) -> 0 | M2: =WATER!Q6 -> 0 | N2: 0.6 | O2: =ELEC!B4 -> 0
A3: Beirut | B3: =B2+1 -> 2 | C3: 2 | D3: 2023 | E3: =ELEC!N5 -> 3065 | F3: =SUM('EDl log'!T5) -> 0.24657687 | G3: =-tanks!AW7 -> 548 | H3: =tanks!AV7 -> 0.915 | I3: =('B5'!AU5)*0.51 -> 0 | J3: ='B5'!AX5/0.51 -> 1.5686275 | K3: =WATER!I7 -> 0 | L3: =SUM(WATER!J7) -> 0 | M3: =WATER!Q7 -> 0 | N3: 0.6 | O3: =ELEC!B5 -> 0
A4: Beirut | B4: =B3+1 -> 3 | C4: 2 | D4: 2023 | E4: =ELEC!N6 -> 0 | F4: =SUM('EDl log'!T6) -> 0 | G4: =-tanks!AW8 -> 0.6 | H4: =tanks!AV8 -> 0.915 | I4: =('B5'!AU6)*0.51 -> 0 | J4: ='B5'!AX6/0.51 -> 1.5686275 | K4: =WATER!I8 -> 0 | L4: =SUM(WATER!J8) -> 0 | M4: =WATER!Q8 -> 0 | N4: 0.6 | O4: =ELEC!B6 -> 0
A5: Beirut | B5: =B4+1 -> 4 | C5: 2 | D5: 2023 | E5: =ELEC!N7 -> 0 | F5: =SUM('EDl log'!T7) -> 0 | G5: =-tanks!AW9 -> 0 | H5: =tanks!AV9 -> 0.915 | I5: =('B5'!AU7)*0.51 -> 0 | J5: ='B5'!AX7/0.51 -> 1.5686275 | K5: =WATER!I9 -> 0 | L5: =SUM(WATER!J9) -> 0 | M5: =WATER!Q9 -> 0 | N5: 0.6 | O5: =ELEC!B7 -> 0
A6: Beirut | B6: =B5+1 -> 5 | C6: 2 | D6: 2023 | E6: =ELEC!N8 -> 3261 | F6: =SUM('EDl log'!T8) -> 0.32284671 | G6: =-tanks!AW10 -> 203 | H6: =tanks!AV10 -> 0.915 | I6: =('B5'!AU8)*0.51 -> 0 | J6: ='B5'!AX8/0.51 -> 1.5686275 | K6: =WATER!I10 -> 0 | L6: =SUM(WATER!J10) -> 0 | M6: =WATER!Q10 -> 0 | N6: 0.6 | O6: =ELEC!B8 -> 0
A7: Beirut | B7: =B6+1 -> 6 | C7: 2 | D7: 2023 | E7: =ELEC!N9 -> 3298 | F7: =SUM('EDl log'!T9) -> 0.37908156 | G7: =-tanks!AW11 -> 280.4 | H7: =tanks!AV11 -> 0.915 | I7: =('B5'!AU9)*0.51 -> 0 | J7: ='B5'!AX9/0.51 -> 1.5686275 | K7: =WATER!I11 -> 0 | L7: =SUM(WATER!J11) -> 0 | M7: =WATER!Q11 -> 0 | N7: 0.6 | O7: =ELEC!B9 -> 0
A8: Beirut | B8: =B7+1 -> 7 | C8: 2 | D8: 2023 | E8: =ELEC!N10 -> 3712 | F8: =SUM('EDl log'!T10) -> 0.34130236 | G8: =-tanks!AW12 -> 191 | H8: =tanks!AV12 -> 0.915 | I8: =('B5'!AU10)*0.51 -> 0 | J8: ='B5'!AX10/0.51 -> 1.5686275 | K8: =WATER!I12 -> 0 | L8: =SUM(WATER!J12) -> 0 | M8: =WATER!Q12 -> 0 | N8: 0.6 | O8: =ELEC!B10 -> 0
A9: Beirut | B9: =B8+1 -> 8 | C9: 2 | D9: 2023 | E9: =ELEC!N11 -> 3438 | F9: =SUM('EDl log'!T11) -> 0.026149855 | G9: =-tanks!AW13 -> 321 | H9: =tanks!AV13 -> 0.868 | I9: =('B5'!AU11)*0.51 -> 0 | J9: ='B5'!AX11/0.51 -> 1.5686275 | K9: =WATER!I13 -> 7 | L9: =SUM(WATER!J13) -> 38.265306 | M9: =WATER!Q13 -> 0 | N9: 0.6 | O9: =ELEC!B11 -> 0
A10: Beirut | B10: =B9+1 -> 9 | C10: 2 | D10: 2023 | E10: =ELEC!N12 -> 0 | F10: =SUM('EDl log'!T12) -> 0 | G10: =-tanks!AW14 -> 0 | H10: =tanks!AV14 -> 0.868 | I10: =('B5'!AU12)*0.51 -> 0 | J10: ='B5'!AX12/0.51 -> 1.5686275 | K10: =WATER!I14 -> 0 | L10: =SUM(WATER!J14) -> 0 | M10: =WATER!Q14 -> 0 | N10: 0.6 | O10: =ELEC!B12 -> 0
A11: Beirut | B11: =B10+1 -> 10 | C11: 2 | D11: 2023 | E11: =ELEC!N13 -> 0 | F11: =SUM('EDl log'!T13) -> 0 | G11: =-tanks!AW15 -> 0 | H11: =tanks!AV15 -> 0.868 | I11: =('B5'!AU13)*0.51 -> 0 | J11: ='B5'!AX13/0.51 -> 1.5686275 | K11: =WATER!I15 -> 0 | L11: =SUM(WATER!J15) -> 0 | M11: =WATER!Q15 -> 0 | N11: 0.6 | O11: =ELEC!B13 -> 0
A12: Beirut | B12: =B11+1 -> 11 | C12: 2 | D12: 2023 | E12: =ELEC!N14 -> 0 | F12: =SUM('EDl log'!T14) -> 0 | G12: =-tanks!AW16 -> 0 | H12: =tanks!AV16 -> 0.868 | I12: =('B5'!AU14)*0.51 -> 0 | J12: ='B5'!AX14/0.51 -> 1.5686275 | K12: =WATER!I16 -> 0 | L12: =SUM(WATER!J16) -> 0 | M12: =WATER!Q16 -> 0 | N12: 0.6 | O12: =ELEC!B14 -> 0
A13: Beirut | B13: =B12+1 -> 12 | C13: 2 | D13: 2023 | E13: =ELEC!N15 -> 3003 | F13: =SUM('EDl log'!T15) -> 0.31436542 | G13: =-tanks!AW17 -> 636 | H13: =tanks!AV17 -> 0.868 | I13: =('B5'!AU15)*0.51 -> 0 | J13: ='B5'!AX15/0.51 -> 1.5686275 | K13: =WATER!I17 -> 368 | L13: =SUM(WATER!J17) -> 0.72787267 | M13: =WATER!Q17 -> 0 | N13: 0.6 | O13: =ELEC!B15 -> 0
A14: Beirut | B14: =B13+1 -> 13 | C14: 2 | D14: 2023 | E14: =ELEC!N16 -> 3225 | F14: =SUM('EDl log'!T16) -> 0.265666 | G14: =-tanks!AW18 -> 124 | H14: =tanks!AV18 -> 0.868 | I14: =('B5'!AU16)*0.51 -> 0 | J14: ='B5'!AX16/0.51 -> 1.5686275 | K14: =WATER!I18 -> 0 | L14: =SUM(WATER!J18) -> 0 | M14: =WATER!Q18 -> 0 | N14: 0.6 | O14: =ELEC!B16 -> 0
... A29: Beirut | B29: =B28+1 -> 28 | C29: 2 | D29: 2023 | E29: =ELEC!N31 -> 0 | F29: =SUM('EDl log'!T31) -> 0 | G29: =-tanks!AW33 -> 0 | H29: =tanks!AV33 -> 0.88 | I29: =('B5'!AU31)*0.51 -> 0 | J29: ='B5'!AX31/0.51 -> 1.5686275 | K29: =WATER!I33 -> 0 | L29: =SUM(WATER!J33) -> 0 | M29: =WATER!Q33 -> 0 | N29: 0.6 | O29: =ELEC!B31 -> 0
A30: Beirut
A31: Beirut
A32: Beirut

Sheet ELEC
A2: OOC | B2: Room OCC | D2: MDB3 | E2: MDB3/day | F2: EMDB2 | G2: EMDB2/day | H2: EMDB1 | I2: EMDB1/day | J2: MDB2 | K2: mdb2/day | L2: MDB1 | M2: MDB1/Day | N2: Total KWH | O2: KWH/Rooc | P2: Gen MHW | Q2: Gen/Day KWH | R2: EDL KWH | S2: CH1 RH | T2: RH | U2: C1h1 power | V2: CH1 Con KWH | W2: CH2 RH | X2: RH | Y2: Ch2 power | Z2: CH2 Con KWH | AA2: CH3 RH | AB2: RH | AC2: Ch3 power | AD2: CH3 Con KWH | AE2: RH total | AF2: KWH total | AG2: AVG chiller KW/Hr
A3: =[1]ELEC!$A$34 -> 0 | B3: =[1]ELEC!$B$34 -> 0 | C3: 44957 | D3: 436570 | E3: =[2]ELEC!E34 -> 2020 | F3: 4195798 | G3: =[2]ELEC!G34 -> 292 | H3: 18114990 | I3: =[2]ELEC!I34 -> 540 | J3: 29912234 | K3: =[2]ELEC!K34 -> 1060 | L3: 24731876 | M3: =[2]ELEC!M34 -> 1094 | N3: =[2]ELEC!N34 -> 5006 | O3: =[2]ELEC!O34 -> 0 | P3: 19768.966 | Q3: =[2]ELEC!Q34 -> 5066 | R3: =[2]ELEC!R34 -> -60 | S3: =[2]ELEC!S34 -> 10175 | T3: =[2]ELEC!T34 -> 0 | U3: =[2]ELEC!U34 -> 429166 | V3: =[2]ELEC!V34 -> 0 | W3: =[2]ELEC!W34 -> 33502 | X3: =[2]ELEC!X34 -> 0 | ... AG3: =[2]ELEC!AG34 -> 0
A4: ='General information '!F5 -> 0 | B4: =SUM(230*A4) -> 0 | C4: =C3+1 -> 44958 | D4: 437590 | E4: =D4-D3 -> 1020 | F4: 4196112 | G4: =F4-F3 -> 314 | H4: 18115434 | I4: =H4-H3 -> 444 | J4: 29912942 | K4: =J4-J3 -> 708 | L4: 24732854 | M4: =L4-L3 -> 978 | N4: =M4+K4+I4+G4+E4 -> 3464 | O4: =IF(B4>0,N4/B4,0) -> 0 | P4: 19772.488 | Q4: =(P4-P3)*1000 -> 3522 | R4: =+N4-Q4 -> -58 | S4: =S3 -> 10175 | T4: =S4-S3 -> 0 | U4: =U3 -> 429166 | V4: =U4-U3 -> 0 | W4: =W3 -> 33502 | X4: =W4-W3 -> 0 | Y4: =Y3 -> 1001284 | Z4: =Y4-Y3 -> 0 | AA4: =AA3 -> 36804 | AB4: =AA4-AA3 -> 0 | AC4: =AC3 -> 1173391 | AD4: =AC4-AC3 -> 0 | AE4: =AB4+X4+T4 -> 0 | AF4: =V4+Z4+AD4 -> 0 | AG4: =IF(AE4>0,AF4/AE4,0) -> 0
A5: ='General information '!F6 -> 0 | B5: =SUM(230*A5) -> 0 | C5: =C4+1 -> 44959 | D5: 438230 | E5: =D5-D4 -> 640 | F5: 4196377 | G5: =F5-F4 -> 265 | H5: 18115844 | I5: =H5-H4 -> 410 | J5: 29913840 | K5: =J5-J4 -> 898 | L5: 24733706 | M5: =L5-L4 -> 852 | N5: =M5+K5+I5+G5+E5 -> 3065 | O5: =IF(B5>0,N5/B5,0) -> 0 | P5: 19775.337 | Q5: =(P5-P4)*1000 -> 2849 | R5: =+N5-Q5 -> 216 | S5: =S4 -> 10175 | T5: =S5-S4 -> 0 | U5: =U4 -> 429166 | V5: =U5-U4 -> 0 | W5: =W4 -> 33502 | X5: =W5-W4 -> 0 | Y5: =Y4 -> 1001284 | Z5: =Y5-Y4 -> 0 | AA5: =AA4 -> 36804 | AB5: =AA5-AA4 -> 0 | AC5: =AC4 -> 1173391 | AD5: =AC5-AC4 -> 0 | AE5: =AB5+X5+T5 -> 0 | AF5: =V5+Z5+AD5 -> 0 | AG5: =IF(AE5>0,AF5/AE5,0) -> 0
A6: ='General information '!F7 -> 0 | B6: =SUM(230*A6) -> 0 | C6: =C5+1 -> 44960 | D6: 438230 | E6: =D6-D5 -> 0 | F6: 4196377 | G6: =F6-F5 -> 0 | H6: 18115844 | I6: =H6-H5 -> 0 | J6: 29913840 | K6: =J6-J5 -> 0 | L6: 24733706 | M6: =L6-L5 -> 0 | N6: =M6+K6+I6+G6+E6 -> 0 | O6: =IF(B6>0,N6/B6,0) -> 0 | P6: 19775.337 | Q6: =(P6-P5)*1000 -> 0 | R6: =+N6-Q6 -> 0 | S6: =S5 -> 10175 | T6: =S6-S5 -> 0 | U6: =U5 -> 429166 | V6: =U6-U5 -> 0 | W6: =W5 -> 33502 | X6: =W6-W5 -> 0 | Y6: =Y5 -> 1001284 | Z6: =Y6-Y5 -> 0 | AA6: =AA5 -> 36804 | AB6: =AA6-AA5 -> 0 | AC6: =AC5 -> 1173391 | AD6: =AC6-AC5 -> 0 | AE6: =AB6+X6+T6 -> 0 | AF6: =V6+Z6+AD6 -> 0 | AG6: =IF(AE6>0,AF6/AE6,0) -> 0
A7: ='General information '!F8 -> 0 | B7: =SUM(230*A7) -> 0 | C7: =C6+1 -> 44961 | D7: =D6 -> 438230 | E7: =D7-D6 -> 0 | F7: =F6 -> 4196377 | G7: =F7-F6 -> 0 | H7: =H6 -> 18115844 | I7: =H7-H6 -> 0 | J7: =J6 -> 29913840 | K7: =J7-J6 -> 0 | L7: =L6 -> 24733706 | M7: =L7-L6 -> 0 | N7: =M7+K7+I7+G7+E7 -> 0 | O7: =IF(B7>0,N7/B7,0) -> 0 | P7: =P6 -> 19775.337 | Q7: =(P7-P6)*1000 -> 0 | R7: =+N7-Q7 -> 0 | S7: =S6 -> 10175 | T7: =S7-S6 -> 0 | U7: =U6 -> 429166 | V7: =U7-U6 -> 0 | W7: =W6 -> 33502 | X7: =W7-W6 -> 0 | Y7: =Y6 -> 1001284 | Z7: =Y7-Y6 -> 0 | AA7: =AA6 -> 36804 | AB7: =AA7-AA6 -> 0 | AC7: =AC6 -> 1173391 | AD7: =AC7-AC6 -> 0 | AE7: =AB7+X7+T7 -> 0 | AF7: =V7+Z7+AD7 -> 0 | AG7: =IF(AE7>0,AF7/AE7,0) -> 0
A8: ='General information '!F9 -> 0 | B8: =SUM(230*A8) -> 0 | C8: =C7+1 -> 44962 | D8: 438990 | E8: =D8-D7 -> 760 | F8: 4196712 | G8: =F8-F7 -> 335 | H8: 18116314 | I8: =H8-H7 -> 470 | J8: 29914646 | K8: =J8-J7 -> 806 | L8: 24734596 | M8: =L8-L7 -> 890 | N8: =M8+K8+I8+G8+E8 -> 3261 | O8: =IF(B8>0,N8/B8,0) -> 0 | P8: 19778.14 | Q8: =(P8-P7)*1000 -> 2803 | R8: =+N8-Q8 -> 458 | S8: =S7 -> 10175 | T8: =S8-S7 -> 0 | U8: =U7 -> 429166 | V8: =U8-U7 -> 0 | W8: =W7 -> 33502 | X8: =W8-W7 -> 0 | Y8: =Y7 -> 1001284 | Z8: =Y8-Y7 -> 0 | AA8: =AA7 -> 36804 | AB8: =AA8-AA7 -> 0 | AC8: =AC7 -> 1173391 | AD8: =AC8-AC7 -> 0 | AE8: =AB8+X8+T8 -> 0 | AF8: =V8+Z8+AD8 -> 0 | AG8: =IF(AE8>0,AF8/AE8,0) -> 0
A9: ='General information '!F10 -> 0 | B9: =SUM(230*A9) -> 0 | C9: =C8+1 -> 44963 | D9: 439770 | E9: =D9-D8 -> 780 | F9: 4197068 | G9: =F9-F8 -> 356 | H9: 18116776 | I9: =H9-H8 -> 462 | J9: 29915456 | K9: =J9-J8 -> 810 | L9: 24735486 | M9: =L9-L8 -> 890 | N9: =M9+K9+I9+G9+E9 -> 3298 | O9: =IF(B9>0,N9/B9,0) -> 0 | P9: 19781.484 | Q9: =(P9-P8)*1000 -> 3344 | R9: =+N9-Q9 -> -46 | S9: =S8 -> 10175 | T9: =S9-S8 -> 0 | U9: =U8 -> 429166 | V9: =U9-U8 -> 0 | W9: =W8 -> 33502 | X9: =W9-W8 -> 0 | Y9: =Y8 -> 1001284 | Z9: =Y9-Y8 -> 0 | AA9: =AA8 -> 36804 | AB9: =AA9-AA8 -> 0 | AC9: =AC8 -> 1173391 | AD9: =AC9-AC8 -> 0 | AE9: =AB9+X9+T9 -> 0 | AF9: =V9+Z9+AD9 -> 0 | AG9: =IF(AE9>0,AF9/AE9,0) -> 0
A10: ='General information '!F11 -> 0 | B10: =SUM(230*A10) -> 0 | C10: =C9+1 -> 44964 | D10: 440520 | E10: =D10-D9 -> 750 | F10: 4197420 | G10: =F10-F9 -> 352 | H10: 18117226 | I10: =H10-H9 -> 450 | J10: 29916504 | K10: =J10-J9 -> 1048 | L10: 24736598 | M10: =L10-L9 -> 1112 | N10: =M10+K10+I10+G10+E10 -> 3712 | O10: =IF(B10>0,N10/B10,0) -> 0 | P10: 19785.276 | Q10: =(P10-P9)*1000 -> 3792 | R10: =+N10-Q10 -> -80 | S10: =S9 -> 10175 | T10: =S10-S9 -> 0 | U10: =U9 -> 429166 | V10: =U10-U9 -> 0 | W10: =W9 -> 33502 | X10: =W10-W9 -> 0 | Y10: =Y9 -> 1001284 | Z10: =Y10-Y9 -> 0 | AA10: =AA9 -> 36804 | AB10: =AA10-AA9 -> 0 | AC10: =AC9 -> 1173391 | AD10: =AC10-AC9 -> 0 | AE10: =AB10+X10+T10 -> 0 | AF10: =V10+Z10+AD10 -> 0 | AG10: =IF(AE10>0,AF10/AE10,0) -> 0
A11: ='General information '!F12 -> 0 | B11: =SUM(230*A11) -> 0 | C11: =C10+1 -> 44965 | D11: 441530 | E11: =D11-D10 -> 1010 | F11: 4197718 | G11: =F11-F10 -> 298 | H11: 18117610 | I11: =H11-H10 -> 384 | J11: 29917378 | K11: =J11-J10 -> 874 | L11: 24737470 | M11: =L11-L10 -> 872 | N11: =M11+K11+I11+G11+E11 -> 3438 | O11: =IF(B11>0,N11/B11,0) -> 0 | P11: 19788.774 | Q11: =(P11-P10)*1000 -> 3498 | R11: =N11-Q11 -> -60 | S11: =S10 -> 10175 | T11: =S11-S10 -> 0 | U11: =U10 -> 429166 | V11: =U11-U10 -> 0 | W11: =W10 -> 33502 | X11: =W11-W10 -> 0 | Y11: =Y10 -> 1001284 | Z11: =Y11-Y10 -> 0 | AA11: =AA10 -> 36804 | AB11: =AA11-AA10 -> 0 | AC11: =AC10 -> 1173391 | AD11: =AC11-AC10 -> 0 | AE11: =AB11+X11+T11 -> 0 | AF11: =V11+Z11+AD11 -> 0 | AG11: =IF(AE11>0,AF11/AE11,0) -> 0
A12: ='General information '!F13 -> 0 | B12: =SUM(230*A12) -> 0 | C12: =C11+1 -> 44966 | D12: =D11 -> 441530 | E12: =D12-D11 -> 0 | F12: =F11 -> 4197718 | G12: =F12-F11 -> 0 | H12: =H11 -> 18117610 | I12: =H12-H11 -> 0 | J12: =J11 -> 29917378 | K12: =J12-J11 -> 0 | L12: =L11 -> 24737470 | M12: =L12-L11 -> 0 | N12: =M12+K12+I12+G12+E12 -> 0 | O12: =IF(B12>0,N12/B12,0) -> 0 | P12: =P11 -> 19788.774 | Q12: =(P12-P11)*1000 -> 0 | R12: =N12-Q12 -> 0 | S12: =S11 -> 10175 | T12: =S12-S11 -> 0 | U12: =U11 -> 429166 | V12: =U12-U11 -> 0 | W12: =W11 -> 33502 | X12: =W12-W11 -> 0 | Y12: =Y11 -> 1001284 | Z12: =Y12-Y11 -> 0 | AA12: =AA11 -> 36804 | AB12: =AA12-AA11 -> 0 | AC12: =AC11 -> 1173391 | AD12: =AC12-AC11 -> 0 | AE12: =AB12+X12+T12 -> 0 | AF12: =V12+Z12+AD12 -> 0 | AG12: =IF(AE12>0,AF12/AE12,0) -> 0
A13: ='General information '!F14 -> 0 | B13: =SUM(230*A13) -> 0 | C13: =C12+1 -> 44967 | D13: =D12 -> 441530 | E13: =D13-D12 -> 0 | F13: =F12 -> 4197718 | G13: =F13-F12 -> 0 | H13: =H12 -> 18117610 | I13: =H13-H12 -> 0 | J13: =J12 -> 29917378 | K13: =J13-J12 -> 0 | L13: =L12 -> 24737470 | M13: =L13-L12 -> 0 | N13: =M13+K13+I13+G13+E13 -> 0 | O13: =IF(B13>0,N13/B13,0) -> 0 | P13: =P12 -> 19788.774 | Q13: =(P13-P12)*1000 -> 0 | R13: =N13-Q13 -> 0 | S13: =S12 -> 10175 | T13: =S13-S12 -> 0 | U13: =U12 -> 429166 | V13: =U13-U12 -> 0 | W13: =W12 -> 33502 | X13: =W13-W12 -> 0 | Y13: =Y12 -> 1001284 | Z13: =Y13-Y12 -> 0 | AA13: =AA12 -> 36804 | AB13: =AA13-AA12 -> 0 | AC13: =AC12 -> 1173391 | AD13: =AC13-AC12 -> 0 | AE13: =AB13+X13+T13 -> 0 | AF13: =V13+Z13+AD13 -> 0 | AG13: =IF(AE13>0,AF13/AE13,0) -> 0
A14: ='General information '!F15 -> 0 | B14: =SUM(230*A14) -> 0 | C14: =C13+1 -> 44968 | D14: =D13 -> 441530 | E14: =D14-D13 -> 0 | F14: =F13 -> 4197718 | G14: =F14-F13 -> 0 | H14: =H13 -> 18117610 | I14: =H14-H13 -> 0 | J14: =J13 -> 29917378 | K14: =J14-J13 -> 0 | L14: =L13 -> 24737470 | M14: =L14-L13 -> 0 | N14: =M14+K14+I14+G14+E14 -> 0 | O14: =IF(B14>0,N14/B14,0) -> 0 | P14: =P13 -> 19788.774 | Q14: =(P14-P13)*1000 -> 0 | R14: =N14-Q14 -> 0 | S14: =S13 -> 10175 | T14: =S14-S13 -> 0 | U14: =U13 -> 429166 | V14: =U14-U13 -> 0 | W14: =W13 -> 33502 | X14: =W14-W13 -> 0 | Y14: =Y13 -> 1001284 | Z14: =Y14-Y13 -> 0 | AA14: =AA13 -> 36804 | AB14: =AA14-AA13 -> 0 | AC14: =AC13 -> 1173391 | AD14: =AC14-AC13 -> 0 | AE14: =AB14+X14+T14 -> 0 | AF14: =V14+Z14+AD14 -> 0 | AG14: =IF(AE14>0,AF14/AE14,0) -> 0
A15: ='General information '!F16 -> 0 | B15: =SUM(230*A15) -> 0 | C15: =C14+1 -> 44969 | D15: 442330 | E15: =D15-D14 -> 800 | F15: 4198013 | G15: =F15-F14 -> 295 | H15: 18118018 | I15: =H15-H14 -> 408 | J15: 29918058 | K15: =J15-J14 -> 680 | L15: 24738290 | M15: =L15-L14 -> 820 | N15: =M15+K15+I15+G15+E15 -> 3003 | O15: =IF(B15>0,N15/B15,0) -> 0 | P15: 19791.026 | Q15: =(P15-P14)*1000 -> 2252 | R15: =N15-Q15 -> 751 | S15: =S14 -> 10175 | T15: =S15-S14 -> 0 | U15: =U14 -> 429166 | V15: =U15-U14 -> 0 | W15: =W14 -> 33502 | X15: =W15-W14 -> 0 | Y15: =Y14 -> 1001284 | Z15: =Y15-Y14 -> 0 | AA15: =AA14 -> 36804 | AB15: =AA15-AA14 -> 0 | AC15: =AC14 -> 1173391 | AD15: =AC15-AC14 -> 0 | AE15: =AB15+X15+T15 -> 0 | AF15: =V15+Z15+AD15 -> 0 | AG15: =IF(AE15>0,AF15/AE15,0) -> 0
A16: ='General information '!F17 -> 0 | B16: =SUM(230*A16) -> 0 | C16: =C15+1 -> 44970 | D16: 443040 | E16: =D16-D15 -> 710 | F16: 4198418 | G16: =F16-F15 -> 405 | H16: 18118482 | I16: =H16-H15 -> 464 | J16: 29918838 | K16: =J16-J15 -> 780 | L16: 24739156 | M16: =L16-L15 -> 866 | N16: =M16+K16+I16+G16+E16 -> 3225 | O16: =IF(B16>0,N16/B16,0) -> 0 | P16: 19793.798 | Q16: =(P16-P15)*1000 -> 2772 | R16: =N16-Q16 -> 453 | S16: =S15 -> 10175 | T16: =S16-S15 -> 0 | U16: =U15 -> 429166 | V16: =U16-U15 -> 0 | W16: =W15 -> 33502 | X16: =W16-W15 -> 0 | Y16: =Y15 -> 1001284 | Z16: =Y16-Y15 -> 0 | AA16: =AA15 -> 36804 | AB16: =AA16-AA15 -> 0 | AC16: =AC15 -> 1173391 | AD16: =AC16-AC15 -> 0 | AE16: =AB16+X16+T16 -> 0 | AF16: =V16+Z16+AD16 -> 0 | AG16: =IF(AE16>0,AF16/AE16,0) -> 0
A17: ='General information '!F18 -> 0 | B17: =SUM(230*A17) -> 0 | C17: =C16+1 -> 44971 | D17: 443700 | E17: =D17-D16 -> 660 | F17: 4198782 | G17: =F17-F16 -> 364 | H17: 18118866 | I17: =H17-H16 -> 384 | J17: 29919532 | K17: =J17-J16 -> 694 | L17: 24739842 | M17: =L17-L16 -> 686 | N17: =M17+K17+I17+G17+E17 -> 2788 | O17: =IF(B17>0,N17/B17,0) -> 0 | P17: 19796.117 | Q17: =(P17-P16)*1000 -> 2319 | R17: =N17-Q17 -> 469 | S17: =S16 -> 10175 | T17: =S17-S16 -> 0 | U17: =U16 -> 429166 | V17: =U17-U16 -> 0 | W17: 33503 | X17: =W17-W16 -> 1 | Y17: 1001544 | Z17: =Y17-Y16 -> 260 | AA17: =AA16 -> 36804 | AB17: =AA17-AA16 -> 0 | AC17: =AC16 -> 1173391 | AD17: =AC17-AC16 -> 0 | AE17: =AB17+X17+T17 -> 1 | AF17: =V17+Z17+AD17 -> 260 | AG17: =IF(AE17>0,AF17/AE17,0) -> 260
A18: ='General information '!F19 -> 0 | B18: =SUM(230*A18) -> 0 | C18: =C17+1 -> 44972 | D18: 444300 | E18: =D18-D17 -> 600 | F18: 4199089 | G18: =F18-F17 -> 307 | H18: 18119198 | I18: =H18-H17 -> 332 | J18: 29920082 | K18: =J18-J17 -> 550 | L18: 24740358 | M18: =L18-L17 -> 516 | N18: =M18+K18+I18+G18+E18 -> 2305 | O18: =IF(B18>0,N18/B18,0) -> 0 | P18: 19797.964 | Q18: =(P18-P17)*1000 -> 1847 | R18: =N18-Q18 -> 458 | S18: =S17 -> 10175 | T18: =S18-S17 -> 0 | U18: =U17 -> 429166 | V18: =U18-U17 -> 0 | W18: =W17 -> 33503 | X18: =W18-W17 -> 0 | Y18: =Y17 -> 1001544 | Z18: =Y18-Y17 -> 0 | AA18: =AA17 -> 36804 | AB18: =AA18-AA17 -> 0 | AC18: =AC17 -> 1173391 | AD18: =AC18-AC17 -> 0 | AE18: =AB18+X18+T18 -> 0 | AF18: =V18+Z18+AD18 -> 0 | AG18: =IF(AE18>0,AF18/AE18,0) -> 0
A19: ='General information '!F20 -> 0 | B19: =SUM(230*A19) -> 0 | C19: =C18+1 -> 44973 | D19: 444960 | E19: =D19-D18 -> 660 | F19: 4199434 | G19: =F19-F18 -> 345 | H19: 18119606 | I19: =H19-H18 -> 408 | J19: 29920778 | K19: =J19-J18 -> 696 | L19: 24741038 | M19: =L19-L18 -> 680 | N19: =M19+K19+I19+G19+E19 -> 2789 | O19: =IF(B19>0,N19/B19,0) -> 0 | P19: 19800.593 | Q19: =(P19-P18)*1000 -> 2629 | R19: =N19-Q19 -> 160 | S19: =S18 -> 10175 | T19: =S19-S18 -> 0 | U19: =U18 -> 429166 | V19: =U19-U18 -> 0 | W19: =W18 -> 33503 | X19: =W19-W18 -> 0 | Y19: =Y18 -> 1001544 | Z19: =Y19-Y18 -> 0 | AA19: =AA18 -> 36804 | AB19: =AA19-AA18 -> 0 | AC19: =AC18 -> 1173391 | AD19: =AC19-AC18 -> 0 | AE19: =AB19+X19+T19 -> 0 | AF19: =V19+Z19+AD19 -> 0 | AG19: =IF(AE19>0,AF19/AE19,0) -> 0
A20: ='General information '!F21 -> 0 | B20: =SUM(230*A20) -> 0 | C20: =C19+1 -> 44974 | D20: 444960 | E20: =D20-D19 -> 0 | F20: 4199434 | G20: =F20-F19 -> 0 | H20: 18119606 | I20: =H20-H19 -> 0 | J20: 29920778 | K20: =J20-J19 -> 0 | L20: 24741038 | M20: =L20-L19 -> 0 | N20: =M20+K20+I20+G20+E20 -> 0 | O20: =IF(B20>0,N20/B20,0) -> 0 | P20: 19800.593 | Q20: =(P20-P19)*1000 -> 0 | R20: =N20-Q20 -> 0 | S20: =S19 -> 10175 | T20: =S20-S19 -> 0 | U20: =U19 -> 429166 | V20: =U20-U19 -> 0 | W20: =W19 -> 33503 | X20: =W20-W19 -> 0 | Y20: =Y19 -> 1001544 | Z20: =Y20-Y19 -> 0 | AA20: =AA19 -> 36804 | AB20: =AA20-AA19 -> 0 | AC20: =AC19 -> 1173391 | AD20: =AC20-AC19 -> 0 | AE20: =AB20+X20+T20 -> 0 | AF20: =V20+Z20+AD20 -> 0 | AG20: =IF(AE20>0,AF20/AE20,0) -> 0
A21: ='General information '!F22 -> 0 | B21: =SUM(230*A21) -> 0 | C21: =C20+1 -> 44975 | D21: 444960 | E21: =D21-D20 -> 0 | F21: 4199434 | G21: =F21-F20 -> 0 | H21: =H20 -> 18119606 | I21: =H21-H20 -> 0 | J21: =J20 -> 29920778 | K21: =J21-J20 -> 0 | L21: 24741038 | M21: =L21-L20 -> 0 | N21: =M21+K21+I21+G21+E21 -> 0 | O21: =IF(B21>0,N21/B21,0) -> 0 | P21: =P20 -> 19800.593 | Q21: =(P21-P20)*1000 -> 0 | R21: =N21-Q21 -> 0 | S21: =S20 -> 10175 | T21: =S21-S20 -> 0 | U21: =U20 -> 429166 | V21: =U21-U20 -> 0 | W21: =W20 -> 33503 | X21: =W21-W20 -> 0 | Y21: =Y20 -> 1001544 | Z21: =Y21-Y20 -> 0 | AA21: =AA20 -> 36804 | AB21: =AA21-AA20 -> 0 | AC21: =AC20 -> 1173391 | AD21: =AC21-AC20 -> 0 | AE21: =AB21+X21+T21 -> 0 | AF21: =V21+Z21+AD21 -> 0 | AG21: =IF(AE21>0,AF21/AE21,0) -> 0
A22: ='General information '!F23 -> 0 | B22: =SUM(230*A22) -> 0 | C22: =C21+1 -> 44976 | D22: 445550 | E22: =D22-D21 -> 590 | F22: 4199765 | G22: =F22-F21 -> 331 | H22: 18120036 | I22: =H22-H21 -> 430 | J22: 29921452 | K22: =J22-J21 -> 674 | L22: 24741812 | M22: =L22-L21 -> 774 | N22: =M22+K22+I22+G22+E22 -> 2799 | O22: =IF(B22>0,N22/B22,0) -> 0 | P22: 19802.984 | Q22: =(P22-P21)*1000 -> 2391 | R22: =N22-Q22 -> 408 | S22: =S21 -> 10175 | T22: =S22-S21 -> 0 | U22: =U21 -> 429166 | V22: =U22-U21 -> 0 | W22: =W21 -> 33503 | X22: =W22-W21 -> 0 | Y22: =Y21 -> 1001544 | Z22: =Y22-Y21 -> 0 | AA22: =AA21 -> 36804 | AB22: =AA22-AA21 -> 0 | AC22: =AC21 -> 1173391 | AD22: =AC22-AC21 -> 0 | AE22: =AB22+X22+T22 -> 0 | AF22: =V22+Z22+AD22 -> 0 | AG22: =IF(AE22>0,AF22/AE22,0) -> 0
A23: ='General information '!F24 -> 0 | B23: =SUM(230*A23) -> 0 | C23: =C22+1 -> 44977 | D23: 446070 | E23: =D23-D22 -> 520 | F23: 4200073 | G23: =F23-F22 -> 308 | H23: 18120444 | I23: =H23-H22 -> 408 | J23: 29922190 | K23: =J23-J22 -> 738 | L23: 24742606 | M23: =L23-L22 -> 794 | N23: =M23+K23+I23+G23+E23 -> 2768 | O23: =IF(B23>0,N23/B23,0) -> 0 | P23: 19805.325 | Q23: =(P23-P22)*1000 -> 2341 | R23: =N23-Q23 -> 427 | S23: =S22 -> 10175 | T23: =S23-S22 -> 0 | U23: =U22 -> 429166 | V23: =U23-U22 -> 0 | W23: =W22 -> 33503 | X23: =W23-W22 -> 0 | Y23: =Y22 -> 1001544 | Z23: =Y23-Y22 -> 0 | AA23: =AA22 -> 36804 | AB23: =AA23-AA22 -> 0 | AC23: =AC22 -> 1173391 | AD23: =AC23-AC22 -> 0 | AE23: =AB23+X23+T23 -> 0 | AF23: =V23+Z23+AD23 -> 0 | AG23: =IF(AE23>0,AF23/AE23,0) -> 0
A24: ='General information '!F25 -> 0 | B24: =SUM(230*A24) -> 0 | C24: =C23+1 -> 44978 | D24: 446660 | E24: =D24-D23 -> 590 | F24: 4200383 | G24: =F24-F23 -> 310 | H24: 18120838 | I24: =H24-H23 -> 394 | J24: 29922894 | K24: =J24-J23 -> 704 | L24: 24743290 | M24: =L24-L23 -> 684 | N24: =M24+K24+I24+G24+E24 -> 2682 | O24: =IF(B24>0,N24/B24,0) -> 0 | P24: 19808 | Q24: =(P24-P23)*1000 -> 2675 | R24: =N24-Q24 -> 7 | S24: =S23 -> 10175 | T24: =S24-S23 -> 0 | U24: =U23 -> 429166 | V24: =U24-U23 -> 0 | W24: =W23 -> 33503 | X24: =W24-W23 -> 0 | Y24: =Y23 -> 1001544 | Z24: =Y24-Y23 -> 0 | AA24: =AA23 -> 36804 | AB24: =AA24-AA23 -> 0 | AC24: =AC23 -> 1173391 | AD24: =AC24-AC23 -> 0 | AE24: =AB24+X24+T24 -> 0 | AF24: =V24+Z24+AD24 -> 0 | AG24: =IF(AE24>0,AF24/AE24,0) -> 0
A25: ='General information '!F26 -> 0 | B25: =SUM(230*A25) -> 0 | C25: =C24+1 -> 44979 | D25: 447160 | E25: =D25-D24 -> 500 | F25: 4200688 | G25: =F25-F24 -> 305 | H25: 18121232 | I25: =H25-H24 -> 394 | J25: 29923556 | K25: =J25-J24 -> 662 | L25: 24743950 | M25: =L25-L24 -> 660 | N25: =M25+K25+I25+G25+E25 -> 2521 | O25: =IF(B25>0,N25/B25,0) -> 0 | P25: 19810.14 | Q25: =(P25-P24)*1000 -> 2140 | R25: =N25-Q25 -> 381 | S25: =S24 -> 10175 | T25: =S25-S24 -> 0 | U25: =U24 -> 429166 | V25: =U25-U24 -> 0 | W25: =W24 -> 33503 | X25: =W25-W24 -> 0 | Y25: =Y24 -> 1001544 | Z25: =Y25-Y24 -> 0 | AA25: =AA24 -> 36804 | AB25: =AA25-AA24 -> 0 | AC25: =AC24 -> 1173391 | AD25: =AC25-AC24 -> 0 | AE25: =AB25+X25+T25 -> 0 | AF25: =V25+Z25+AD25 -> 0 | AG25: =IF(AE25>0,AF25/AE25,0) -> 0
A26: ='General information '!F27 -> 0 | B26: =SUM(230*A26) -> 0 | C26: =C25+1 -> 44980 | D26: 447720 | E26: =D26-D25 -> 560 | F26: 4201030 | G26: =F26-F25 -> 342 | H26: 18121674 | I26: =H26-H25 -> 442 | J26: 29924350 | K26: =J26-J25 -> 794 | L26: 24744706 | M26: =L26-L25 -> 756 | N26: =M26+K26+I26+G26+E26 -> 2894 | O26: =IF(B26>0,N26/B26,0) -> 0 | P26: 19812.964 | Q26: =(P26-P25)*1000 -> 2824 | R26: =N26-Q26 -> 70 | S26: =S25 -> 10175 | T26: =S26-S25 -> 0 | U26: =U25 -> 429166 | V26: =U26-U25 -> 0 | W26: =W25 -> 33503 | X26: =W26-W25 -> 0 | Y26: =Y25 -> 1001544 | Z26: =Y26-Y25 -> 0 | AA26: =AA25 -> 36804 | AB26: =AA26-AA25 -> 0 | AC26: =AC25 -> 1173391 | AD26: =AC26-AC25 -> 0 | AE26: =AB26+X26+T26 -> 0 | AF26: =V26+Z26+AD26 -> 0 | AG26: =IF(AE26>0,AF26/AE26,0) -> 0
A27: ='General information '!F28 -> 0 | B27: =SUM(230*A27) -> 0 | C27: =C26+1 -> 44981 | D27: =D26 -> 447720 | E27: =D27-D26 -> 0 | F27: =F26 -> 4201030 | G27: =F27-F26 -> 0 | H27: =H26 -> 18121674 | I27: =H27-H26 -> 0 | J27: =J26 -> 29924350 | K27: =J27-J26 -> 0 | L27: =L26 -> 24744706 | M27: =L27-L26 -> 0 | N27: =M27+K27+I27+G27+E27 -> 0 | O27: =IF(B27>0,N27/B27,0) -> 0 | P27: =P26 -> 19812.964 | Q27: =(P27-P26)*1000 -> 0 | R27: =N27-Q27 -> 0 | S27: =S26 -> 10175 | T27: =S27-S26 -> 0 | U27: =U26 -> 429166 | V27: =U27-U26 -> 0 | W27: =W26 -> 33503 | X27: =W27-W26 -> 0 | Y27: =Y26 -> 1001544 | Z27: =Y27-Y26 -> 0 | AA27: =AA26 -> 36804 | AB27: =AA27-AA26 -> 0 | AC27: =AC26 -> 1173391 | AD27: =AC27-AC26 -> 0 | AE27: =AB27+X27+T27 -> 0 | AF27: =V27+Z27+AD27 -> 0 | AG27: =IF(AE27>0,AF27/AE27,0) -> 0
A28: ='General information '!F29 -> 0 | B28: =SUM(230*A28) -> 0 | C28: =C27+1 -> 44982 | D28: =D27 -> 447720 | E28: =D28-D27 -> 0 | F28: =F27 -> 4201030 | G28: =F28-F27 -> 0 | H28: =H27 -> 18121674 | I28: =H28-H27 -> 0 | J28: =J27 -> 29924350 | K28: =J28-J27 -> 0 | L28: =L27 -> 24744706 | M28: =L28-L27 -> 0 | N28: =M28+K28+I28+G28+E28 -> 0 | O28: =IF(B28>0,N28/B28,0) -> 0 | P28: =P27 -> 19812.964 | Q28: =(P28-P27)*1000 -> 0 | R28: =N28-Q28 -> 0 | S28: =S27 -> 10175 | T28: =S28-S27 -> 0 | U28: =U27 -> 429166 | V28: =U28-U27 -> 0 | W28: =W27 -> 33503 | X28: =W28-W27 -> 0 | Y28: =Y27 -> 1001544 | Z28: =Y28-Y27 -> 0 | AA28: =AA27 -> 36804 | AB28: =AA28-AA27 -> 0 | AC28: =AC27 -> 1173391 | AD28: =AC28-AC27 -> 0 | AE28: =AB28+X28+T28 -> 0 | AF28: =V28+Z28+AD28 -> 0 | AG28: =IF(AE28>0,AF28/AE28,0) -> 0
A29: ='General information '!F30 -> 0 | B29: =SUM(230*A29) -> 0 | C29: =C28+1 -> 44983 | D29: 448240 | E29: =D29-D28 -> 520 | F29: 4201386 | G29: =F29-F28 -> 356 | H29: 18122118 | I29: =H29-H28 -> 444 | J29: 29925106 | K29: =J29-J28 -> 756 | L29: 24745510 | M29: =L29-L28 -> 804 | N29: =M29+K29+I29+G29+E29 -> 2880 | O29: =IF(B29>0,N29/B29,0) -> 0 | P29: 19815.371 | Q29: =(P29-P28)*1000 -> 2407 | R29: =N29-Q29 -> 473 | S29: =S28 -> 10175 | T29: =S29-S28 -> 0 | U29: =U28 -> 429166 | V29: =U29-U28 -> 0 | W29: =W28 -> 33503 | X29: =W29-W28 -> 0 | Y29: =Y28 -> 1001544 | Z29: =Y29-Y28 -> 0 | AA29: =AA28 -> 36804 | AB29: =AA29-AA28 -> 0 | AC29: =AC28 -> 1173391 | AD29: =AC29-AC28 -> 0 | AE29: =AB29+X29+T29 -> 0 | AF29: =V29+Z29+AD29 -> 0 | AG29: =IF(AE29>0,AF29/AE29,0) -> 0
A30: ='General information '!F31 -> 0 | B30: =SUM(230*A30) -> 0 | C30: =C29+1 -> 44984 | D30: 449010 | E30: =D30-D29 -> 770 | F30: 4201728 | G30: =F30-F29 -> 342 | H30: 18122546 | I30: =H30-H29 -> 428 | J30: 29925752 | K30: =J30-J29 -> 646 | L30: 24746262 | M30: =L30-L29 -> 752 | N30: =M30+K30+I30+G30+E30 -> 2938 | O30: =IF(B30>0,N30/B30,0) -> 0 | P30: 19817.695 | Q30: =(P30-P29)*1000 -> 2324 | R30: =N30-Q30 -> 614 | S30: =S29 -> 10175 | T30: =S30-S29 -> 0 | U30: =U29 -> 429166 | V30: =U30-U29 -> 0 | W30: =W29 -> 33503 | X30: =W30-W29 -> 0 | Y30: =Y29 -> 1001544 | Z30: =Y30-Y29 -> 0 | AA30: =AA29 -> 36804 | AB30: =AA30-AA29 -> 0 | AC30: =AC29 -> 1173391 | AD30: =AC30-AC29 -> 0 | AE30: =AB30+X30+T30 -> 0 | AF30: =V30+Z30+AD30 -> 0 | AG30: =IF(AE30>0,AF30/AE30,0) -> 0
A31: ='General information '!F32 -> 0 | B31: =SUM(230*A31) -> 0 | C31: =C30+1 -> 44985 | D31: =D30 -> 449010 | E31: =D31-D30 -> 0 | F31: =F30 -> 4201728 | G31: =F31-F30 -> 0 | H31: =H30 -> 18122546 | I31: =H31-H30 -> 0 | J31: =J30 -> 29925752 | K31: =J31-J30 -> 0 | L31: =L30 -> 24746262 | M31: =L31-L30 -> 0 | N31: =M31+K31+I31+G31+E31 -> 0 | O31: =IF(B31>0,N31/B31,0) -> 0 | P31: =P30 -> 19817.695 | Q31: =(P31-P30)*1000 -> 0 | R31: =N31-Q31 -> 0 | S31: =S30 -> 10175 | T31: =S31-S30 -> 0 | U31: =U30 -> 429166 | V31: =U31-U30 -> 0 | W31: =W30 -> 33503 | X31: =W31-W30 -> 0 | Y31: =Y30 -> 1001544 | Z31: =Y31-Y30 -> 0 | AA31: =AA30 -> 36804 | AB31: =AA31-AA30 -> 0 | AC31: =AC30 -> 1173391 | AD31: =AC31-AC30 -> 0 | AE31: =AB31+X31+T31 -> 0 | AF31: =V31+Z31+AD31 -> 0 | AG31: =IF(AE31>0,AF31/AE31,0) -> 0
A32: ='General information '!F33 -> 0 | B32: =SUM(230*A32) -> 0 | C32: =C31+1 -> 44986 | D32: =D31 -> 449010 | E32: =D32-D31 -> 0 | F32: =F31 -> 4201728 | G32: =F32-F31 -> 0 | H32: =H31 -> 18122546 | I32: =H32-H31 -> 0 | J32: =J31 -> 29925752 | K32: =J32-J31 -> 0 | L32: =L31 -> 24746262 | M32: =L32-L31 -> 0 | N32: =M32+K32+I32+G32+E32 -> 0 | O32: =IF(B32>0,N32/B32,0) -> 0 | P32: =P31 -> 19817.695 | Q32: =(P32-P31)*1000 -> 0 | R32: =N32-Q32 -> 0 | S32: =S31 -> 10175 | T32: =S32-S31 -> 0 | U32: =U31 -> 429166 | V32: =U32-U31 -> 0 | W32: =W31 -> 33503 | X32: =W32-W31 -> 0 | Y32: =Y31 -> 1001544 | Z32: =Y32-Y31 -> 0 | AA32: =AA31 -> 36804 | AB32: =AA32-AA31 -> 0 | AC32: =AC31 -> 1173391 | AD32: =AC32-AC31 -> 0 | AE32: =AB32+X32+T32 -> 0 | AF32: =V32+Z32+AD32 -> 0 | AG32: =IF(AE32>0,AF32/AE32,0) -> 0
A33: ='General information '!F34 -> 0 | B33: =SUM(230*A33) -> 0
A34: ='General information '!F35 -> 0 | B34: =SUM(230*A34) -> 0

Sheet B5
F1: Boiler A | J1: =#REF! -> #REF! | K1: Boiler B | P1: Boiler C | V1: Boiler | X1: SteamA | AC1: SteamB | AH1: Steam | AI1: Boiler & steam | AL1: Total Boiler Runing H | AM1: Total Steam Runing H | AN1: GAS1 % | AO1: GAS1/L | AP1: GAS2% | AQ1: Gas2/L | AR1: GAS3% | AS1: GAS3/L | AU1: Gas Cons | AV1: Delivery | AW1: Cost/L
B2: Level Tank Gen | C2: Level tank Boiler | D2: Daily Cons Bo. | E2: Boiler litter | F2: Boiler A | G2: Run Hr a | H2: Boiler A fuel | I2: Daily consumption | J2: AVG | K2: index Run H | L2: Run Hrb | M2: Boiler B Fuel | O2: Daily consumption | P2: Boiler C | S2: Run C | U2: Total RH | V2: Total Fuel | X2: SteamA | Y2: Run SA | Z2: Steam A Conter | AA2: Liters | AC2: SteamB | AD2: Run SteamB | AE2: Steam B Conter | AF2: SB Litters | AG2: Avg | AH2: Total Fuel | AI2: Total Fuel
S3: 0
A4: =ELEC!C3 -> 44957 | B4: 236 | C4: =[2]B5!C35 -> 241 | D4: =[2]B5!D35 -> 5.5 | E4: =[2]B5!E35 -> 46.09 | F4: =[2]B5!F35 -> 2382 | G4: =[2]B5!G35 -> 1 | H4: =[2]B5!H35 -> 54048 | I4: =[2]B5!I35 -> 53 | J4: =[2]B5!J35 -> 53 | ... L4: =[2]B5!L35 -> 0 | M4: 185690 | N4: =[2]B5!N35 -> 63 | O4: =[2]B5!O35 -> 2251 | P4: =[2]B5!P35 -> 2254 | Q4: =[2]B5!Q35 -> 188186 | R4: =[2]B5!R35 -> 128 | S4: =[2]B5!S35 -> 2 | T4: =[2]B5!T35 -> 0 | U4: =[2]B5!U35 -> 3 | ... AB4: =[2]B5!AB35 -> 0 | AC4: 1966 | AD4: =[2]B5!AD35 -> 0 | AE4: 368122 | AF4: =[2]B5!AF35 -> 0 | AG4: =[2]B5!AG35 -> 0 | AH4: =[2]B5!AH35 -> 0 | AI4: =[2]B5!AI35 -> 244 | AJ4: =[2]B5!AJ35 -> 244 | AK4: =[2]B5!AK35 -> 0 | AL4: =[2]B5!AL35 -> 3 | AM4: =[2]B5!AM35 -> 0 | ... AX4: =[2]B5!AX35 -> 0.8
A5: =ELEC!C4 -> 44958 | B5: 230 | C5: 236 | D5: =C4-C5 -> 5 | E5: =D5*8.38 -> 41.9 | F5: =F4 -> 2382 | G5: =F5-F4 -> 0 | H5: =H4 -> 54048 | I5: =SUM(H5-H4) -> 0 | J5: =IF(G5>0,I5/G5,0) -> 0 | K5: =K4 -> 2490 | L5: =K5-K4 -> 0 | M5: 185739 | N5: =M5-M4 -> 49 | O5: =O4 -> 2251 | P5: =P4 -> 2254 | Q5: =Q4 -> 188186 | R5: =Q5-Q4 -> 0 | S5: =SUM(P5-P4) -> 0 | T5: =SUM(S5*$T$2) -> 0 | U5: =SUM(G5+L5+S5) -> 0 | V5: =R5+N5+I5:I5 -> 49 | W5: =SUM(V5/U5) -> #DIV/0! | X5: =X4 -> 2498 | Y5: =X5-X4 -> 0 | Z5: =Z4 -> 141480 | AA5: =Z5-Z4 -> 0 | AB5: =SUM(Y5*$AB$2) -> 0 | AC5: 1966 | AD5: =AC5-AC4 -> 0 | AE5: 368122 | AF5: =AE5-AE4 -> 0 | AG5: =IF(AD5>0,AF5/AD5,0) -> 0 | AH5: =AF5+AA5 -> 0 | AI5: =SUM(AH5+V5) -> 49 | AJ5: =-tanks!AW7 -> 548 | AK5: =SUM(AJ5-AI5) -> 499 | AL5: =S5+L5+G5 -> 0 | AM5: =Y5+AD5 -> 0 | AN5: =AN4 -> 65 | AO5: =(AN5/100)*3000 -> 1950 | AP5: =AP4 -> 35 | AQ5: =(AP5/100)*3000 -> 1050 | AR5: =AR4 -> 73 | AS5: =(AR5/100)*3000 -> 2190 | AT5: =SUM(AO5+AQ5+AS5) -> 5190 | AU5: =AT4-AT5+AV5 -> 0 | AX5: =IF(AV5>0,AW5,AX4) -> 0.8
A6: =ELEC!C5 -> 44959 | B6: 226 | C6: 232 | D6: =C5-C6 -> 4 | E6: =D6*8.38 -> 33.52 | F6: 2382 | G6: =F6-F5 -> 0 | H6: 54054 | I6: =SUM(H6-H5) -> 6 | J6: =IF(G6>0,I6/G6,0) -> 0 | K6: =K5 -> 2490 | L6: =K6-K5 -> 0 | M6: 185739 | N6: =M6-M5 -> 0 | O6: =O5 -> 2251 | P6: 2258 | Q6: 188538 | R6: =Q6-Q5 -> 352 | S6: =SUM(P6-P5) -> 4 | T6: =SUM(S6*$T$2) -> 0 | U6: =SUM(G6+L6+S6) -> 4 | V6: =R6+N6+I6:I6 -> 358 | W6: =SUM(V6/U6) -> 89.5 | X6: =X5 -> 2498 | Y6: =X6-X5 -> 0 | Z6: =Z5 -> 141480 | AA6: =Z6-Z5 -> 0 | AB6: =SUM(Y6*$AB$2) -> 0 | AC6: 1968 | AD6: =AC6-AC5 -> 2 | AE6: 368312 | AF6: =AE6-AE5 -> 190 | AG6: =IF(AD6>0,AF6/AD6,0) -> 95 | AH6: =AF6+AA6 -> 190 | AI6: =SUM(AH6+V6) -> 548 | AJ6: =-tanks!AW8 -> 0.6 | AK6: =SUM(AJ6-AI6) -> -547.4 | AL6: =S6+L6+G6 -> 4 | AM6: =Y6+AD6 -> 2 | AN6: =AN5 -> 65 | AO6: =(AN6/100)*3000 -> 1950 | AP6: =AP5 -> 35 | AQ6: =(AP6/100)*3000 -> 1050 | AR6: =AR5 -> 73 | AS6: =(AR6/100)*3000 -> 2190 | AT6: =SUM(AO6+AQ6+AS6) -> 5190 | AU6: =AT5-AT6+AV6 -> 0 | AX6: =IF(AV6>0,AW6,AX5) -> 0.8
A7: =ELEC!C6 -> 44960 | B7: 226 | C7: 232 | D7: =C6-C7 -> 0 | E7: =D7*8.38 -> 0 | F7: 2382 | G7: =F7-F6 -> 0 | H7: 54054 | I7: =SUM(H7-H6) -> 0 | J7: =IF(G7>0,I7/G7,0) -> 0 | K7: 2490 | L7: =K7-K6 -> 0 | M7: 185739 | N7: =M7-M6 -> 0 | O7: =O6 -> 2251 | P7: 2258 | Q7: 188538 | R7: =Q7-Q6 -> 0 | S7: =SUM(P7-P6) -> 0 | T7: =SUM(S7*$T$2) -> 0 | U7: =SUM(G7+L7+S7) -> 0 | V7: =R7+N7+I7:I7 -> 0 | W7: =SUM(V7/U7) -> #DIV/0! | X7: =X6 -> 2498 | Y7: =X7-X6 -> 0 | Z7: =Z6 -> 141480 | AA7: =Z7-Z6 -> 0 | AB7: =SUM(Y7*$AB$2) -> 0 | AC7: =AC6 -> 1968 | AD7: =AC7-AC6 -> 0 | AE7: 368312.6 | AF7: =AE7-AE6 -> 0.6 | AG7: =IF(AD7>0,AF7/AD7,0) -> 0 | AH7: =AF7+AA7 -> 0.6 | AI7: =SUM(AH7+V7) -> 0.6 | AJ7: =-tanks!AW9 -> 0 | AK7: =SUM(AJ7-AI7) -> -0.6 | AL7: =S7+L7+G7 -> 0 | AM7: =Y7+AD7 -> 0 | AN7: =AN6 -> 65 | AO7: =(AN7/100)*3000 -> 1950 | AP7: =AP6 -> 35 | AQ7: =(AP7/100)*3000 -> 1050 | AR7: =AR6 -> 73 | AS7: =(AR7/100)*3000 -> 2190 | AT7: =SUM(AO7+AQ7+AS7) -> 5190 | AU7: =AT6-AT7+AV7 -> 0 | AX7: =IF(AV7>0,AW7,AX6) -> 0.8
A8: =ELEC!C7 -> 44961 | B8: =B7 -> 226 | C8: =C7 -> 232 | D8: =C7-C8 -> 0 | E8: =D8*8.38 -> 0 | F8: =F7 -> 2382 | G8: =F8-F7 -> 0 | H8: =H7 -> 54054 | I8: =SUM(H8-H7) -> 0 | J8: =IF(G8>0,I8/G8,0) -> 0 | K8: =K7 -> 2490 | L8: =K8-K7 -> 0 | M8: =M7 -> 185739 | N8: =M8-M7 -> 0 | O8: =O7 -> 2251 | P8: =P7 -> 2258 | Q8: =Q7 -> 188538 | R8: =Q8-Q7 -> 0 | S8: =SUM(P8-P7) -> 0 | T8: =SUM(S8*$T$2) -> 0 | U8: =SUM(G8+L8+S8) -> 0 | V8: =R8+N8+I8:I8 -> 0 | W8: =SUM(V8/U8) -> #DIV/0! | X8: =X7 -> 2498 | Y8: =X8-X7 -> 0 | Z8: =Z7 -> 141480 | AA8: =Z8-Z7 -> 0 | AB8: =SUM(Y8*$AB$2) -> 0 | AC8: =AC7 -> 1968 | AD8: =AC8-AC7 -> 0 | AE8: =AE7 -> 368312.6 | AF8: =AE8-AE7 -> 0 | AG8: =IF(AD8>0,AF8/AD8,0) -> 0 | AH8: =AF8+AA8 -> 0 | AI8: =SUM(AH8+V8) -> 0 | AJ8: =-tanks!AW10 -> 203 | AK8: =SUM(AJ8-AI8) -> 203 | AL8: =S8+L8+G8 -> 0 | AM8: =Y8+AD8 -> 0 | AN8: =AN7 -> 65 | AO8: =(AN8/100)*3000 -> 1950 | AP8: =AP7 -> 35 | AQ8: =(AP8/100)*3000 -> 1050 | AR8: =AR7 -> 73 | AS8: =(AR8/100)*3000 -> 2190 | AT8: =SUM(AO8+AQ8+AS8) -> 5190 | AU8: =AT7-AT8+AV8 -> 0 | AX8: =IF(AV8>0,AW8,AX7) -> 0.8
A9: =ELEC!C8 -> 44962 | B9: 222 | C9: 228 | D9: =C8-C9 -> 4 | E9: =D9*8.38 -> 33.52 | F9: =F8 -> 2382 | G9: =F9-F8 -> 0 | H9: =H8 -> 54054 | I9: =SUM(H9-H8) -> 0 | J9: =IF(G9>0,I9/G9,0) -> 0 | K9: =K8 -> 2490 | L9: =K9-K8 -> 0 | M9: 185760 | N9: =M9-M8 -> 21 | O9: =O8 -> 2251 | P9: 2261 | Q9: 188720 | R9: =Q9-Q8 -> 182 | S9: =SUM(P9-P8) -> 3 | T9: =SUM(S9*$T$2) -> 0 | U9: =SUM(G9+L9+S9) -> 3 | V9: =R9+N9+I9:I9 -> 203 | W9: =SUM(V9/U9) -> 67.666667 | X9: =X8 -> 2498 | Y9: =X9-X8 -> 0 | Z9: =Z8 -> 141480 | AA9: =Z9-Z8 -> 0 | AB9: =SUM(Y9*$AB$2) -> 0 | AC9: =AC8 -> 1968 | AD9: =AC9-AC8 -> 0 | AE9: =AE8 -> 368312.6 | AF9: =AE9-AE8 -> 0 | AG9: =IF(AD9>0,AF9/AD9,0) -> 0 | AH9: =AF9+AA9 -> 0 | AI9: =SUM(AH9+V9) -> 203 | AJ9: =-tanks!AW11 -> 280.4 | AK9: =SUM(AJ9-AI9) -> 77.4 | AL9: =S9+L9+G9 -> 3 | AM9: =Y9+AD9 -> 0 | AN9: =AN8 -> 65 | AO9: =(AN9/100)*3000 -> 1950 | AP9: =AP8 -> 35 | AQ9: =(AP9/100)*3000 -> 1050 | AR9: =AR8 -> 73 | AS9: =(AR9/100)*3000 -> 2190 | AT9: =SUM(AO9+AQ9+AS9) -> 5190 | AU9: =AT8-AT9+AV9 -> 0 | AX9: =IF(AV9>0,AW9,AX8) -> 0.8
A10: =ELEC!C9 -> 44963 | B10: 217 | C10: 223 | D10: =C9-C10 -> 5 | E10: =D10*8.38 -> 41.9 | F10: =F9 -> 2382 | G10: =F10-F9 -> 0 | H10: =H9 -> 54054 | I10: =SUM(H10-H9) -> 0 | J10: =IF(G10>0,I10/G10,0) -> 0 | K10: 2492 | L10: =K10-K9 -> 2 | M10: 185870 | N10: =M10-M9 -> 110 | O10: =O9 -> 2251 | P10: 2262 | Q10: 188821 | R10: =Q10-Q9 -> 101 | S10: =SUM(P10-P9) -> 1 | T10: =SUM(S10*$T$2) -> 0 | U10: =SUM(G10+L10+S10) -> 3 | V10: =R10+N10+I10:I10 -> 211 | W10: =SUM(V10/U10) -> 70.333333 | X10: =X9 -> 2498 | Y10: =X10-X9 -> 0 | Z10: =Z9 -> 141480 | AA10: =Z10-Z9 -> 0 | AB10: =SUM(Y10*$AB$2) -> 0 | AC10: 1969 | AD10: =AC10-AC9 -> 1 | AE10: 368382 | AF10: =AE10-AE9 -> 69.4 | AG10: =IF(AD10>0,AF10/AD10,0) -> 69.4 | AH10: =AF10+AA10 -> 69.4 | AI10: =SUM(AH10+V10) -> 280.4 | AJ10: =-tanks!AW12 -> 191 | AK10: =SUM(AJ10-AI10) -> -89.4 | AL10: =S10+L10+G10 -> 3 | AM10: =Y10+AD10 -> 1 | AN10: =AN9 -> 65 | AO10: =(AN10/100)*3000 -> 1950 | AP10: =AP9 -> 35 | AQ10: =(AP10/100)*3000 -> 1050 | AR10: =AR9 -> 73 | AS10: =(AR10/100)*3000 -> 2190 | AT10: =SUM(AO10+AQ10+AS10) -> 5190 | AU10: =AT9-AT10+AV10 -> 0 | AX10: =IF(AV10>0,AW10,AX9) -> 0.8
A11: =ELEC!C10 -> 44964 | B11: 212 | C11: 219 | D11: =C10-C11 -> 4 | E11: =D11*8.38 -> 33.52 | F11: =F10 -> 2382 | G11: =F11-F10 -> 0 | H11: =H10 -> 54054 | I11: =SUM(H11-H10) -> 0 | J11: =IF(G11>0,I11/G11,0) -> 0 | K11: =K10 -> 2492 | L11: =K11-K10 -> 0 | M11: 185894 | N11: =M11-M10 -> 24 | O11: =O10 -> 2251 | P11: 2264 | Q11: 188988 | R11: =Q11-Q10 -> 167 | S11: =SUM(P11-P10) -> 2 | T11: =SUM(S11*$T$2) -> 0 | U11: =SUM(G11+L11+S11) -> 2 | V11: =R11+N11+I11:I11 -> 191 | W11: =SUM(V11/U11) -> 95.5 | X11: =X10 -> 2498 | Y11: =X11-X10 -> 0 | Z11: =Z10 -> 141480 | AA11: =Z11-Z10 -> 0 | AB11: =SUM(Y11*$AB$2) -> 0 | AC11: =AC10 -> 1969 | AD11: =AC11-AC10 -> 0 | AE11: =AE10 -> 368382 | AF11: =AE11-AE10 -> 0 | AG11: =IF(AD11>0,AF11/AD11,0) -> 0 | AH11: =AF11+AA11 -> 0 | AI11: =SUM(AH11+V11) -> 191 | AJ11: =-tanks!AW13 -> 321 | AK11: =SUM(AJ11-AI11) -> 130 | AL11: =S11+L11+G11 -> 2 | AM11: =Y11+AD11 -> 0 | AN11: =AN10 -> 65 | AO11: =(AN11/100)*3000 -> 1950 | AP11: =AP10 -> 35 | AQ11: =(AP11/100)*3000 -> 1050 | AR11: =AR10 -> 73 | AS11: =(AR11/100)*3000 -> 2190 | AT11: =SUM(AO11+AQ11+AS11) -> 5190 | AU11: =AT10-AT11+AV11 -> 0 | AX11: =IF(AV11>0,AW11,AX10) -> 0.8
A12: =ELEC!C11 -> 44965 | B12: 235 | C12: 241 | D12: =C11-C12 -> -22 | E12: =D12*8.38 -> -184.36 | F12: =F11 -> 2382 | G12: =F12-F11 -> 0 | H12: =H11 -> 54054 | I12: =SUM(H12-H11) -> 0 | J12: =IF(G12>0,I12/G12,0) -> 0 | K12: =K11 -> 2492 | L12: =K12-K11 -> 0 | M12: =M11 -> 185894 | N12: =M12-M11 -> 0 | O12: =O11 -> 2251 | P12: 2268 | Q12: 189309 | R12: =Q12-Q11 -> 321 | S12: =SUM(P12-P11) -> 4 | T12: =SUM(S12*$T$2) -> 0 | U12: =SUM(G12+L12+S12) -> 4 | V12: =R12+N12+I12:I12 -> 321 | W12: =SUM(V12/U12) -> 80.25 | X12: =X11 -> 2498 | Y12: =X12-X11 -> 0 | Z12: =Z11 -> 141480 | AA12: =Z12-Z11 -> 0 | AB12: =SUM(Y12*$AB$2) -> 0 | AC12: =AC11 -> 1969 | AD12: =AC12-AC11 -> 0 | AE12: =AE11 -> 368382 | AF12: =AE12-AE11 -> 0 | AG12: =IF(AD12>0,AF12/AD12,0) -> 0 | AH12: =AF12+AA12 -> 0 | AI12: =SUM(AH12+V12) -> 321 | AJ12: =-tanks!AW14 -> 0 | AK12: =SUM(AJ12-AI12) -> -321 | AL12: =S12+L12+G12 -> 4 | AM12: =Y12+AD12 -> 0 | AN12: =AN11 -> 65 | AO12: =(AN12/100)*3000 -> 1950 | AP12: =AP11 -> 35 | AQ12: =(AP12/100)*3000 -> 1050 | AR12: =AR11 -> 73 | AS12: =(AR12/100)*3000 -> 2190 | AT12: =SUM(AO12+AQ12+AS12) -> 5190 | AU12: =AT11-AT12+AV12 -> 0 | AX12: =IF(AV12>0,AW12,AX11) -> 0.8
A13: =ELEC!C12 -> 44966 | B13: =B12 -> 235 | C13: =C12 -> 241 | D13: =C12-C13 -> 0 | E13: =D13*8.38 -> 0 | F13: =F12 -> 2382 | G13: =F13-F12 -> 0 | H13: =H12 -> 54054 | I13: =SUM(H13-H12) -> 0 | J13: =IF(G13>0,I13/G13,0) -> 0 | K13: =K12 -> 2492 | L13: =K13-K12 -> 0 | M13: =M12 -> 185894 | N13: =M13-M12 -> 0 | O13: =O12 -> 2251 | P13: =P12 -> 2268 | Q13: =Q12 -> 189309 | R13: =Q13-Q12 -> 0 | S13: =SUM(P13-P12) -> 0 | T13: =SUM(S13*$T$2) -> 0 | U13: =SUM(G13+L13+S13) -> 0 | V13: =R13+N13+I13:I13 -> 0 | W13: =SUM(V13/U13) -> #DIV/0! | X13: =X12 -> 2498 | Y13: =X13-X12 -> 0 | Z13: =Z12 -> 141480 | AA13: =Z13-Z12 -> 0 | AB13: =SUM(Y13*$AB$2) -> 0 | AC13: =AC12 -> 1969 | AD13: =AC13-AC12 -> 0 | AE13: =AE12 -> 368382 | AF13: =AE13-AE12 -> 0 | AG13: =IF(AD13>0,AF13/AD13,0) -> 0 | AH13: =AF13+AA13 -> 0 | AI13: =SUM(AH13+V13) -> 0 | AJ13: =-tanks!AW15 -> 0 | AK13: =SUM(AJ13-AI13) -> 0 | AL13: =S13+L13+G13 -> 0 | AM13: =Y13+AD13 -> 0 | AN13: =AN12 -> 65 | AO13: =(AN13/100)*3000 -> 1950 | AP13: =AP12 -> 35 | AQ13: =(AP13/100)*3000 -> 1050 | AR13: =AR12 -> 73 | AS13: =(AR13/100)*3000 -> 2190 | AT13: =SUM(AO13+AQ13+AS13) -> 5190 | AU13: =AT12-AT13+AV13 -> 0 | AX13: =IF(AV13>0,AW13,AX12) -> 0.8
A14: =ELEC!C13 -> 44967 | B14: =B13 -> 235 | C14: =C13 -> 241 | D14: =C13-C14 -> 0 | E14: =D14*8.38 -> 0 | F14: =F13 -> 2382 | G14: =F14-F13 -> 0 | H14: =H13 -> 54054 | I14: =SUM(H14-H13) -> 0 | J14: =IF(G14>0,I14/G14,0) -> 0 | K14: =K13 -> 2492 | L14: =K14-K13 -> 0 | M14: =M13 -> 185894 | N14: =M14-M13 -> 0 | O14: =O13 -> 2251 | P14: =P13 -> 2268 | Q14: =Q13 -> 189309 | R14: =Q14-Q13 -> 0 | S14: =SUM(P14-P13) -> 0 | T14: =SUM(S14*$T$2) -> 0 | U14: =SUM(G14+L14+S14) -> 0 | V14: =R14+N14+I14:I14 -> 0 | W14: =SUM(V14/U14) -> #DIV/0! | X14: =X13 -> 2498 | Y14: =X14-X13 -> 0 | Z14: =Z13 -> 141480 | AA14: =Z14-Z13 -> 0 | AB14: =SUM(Y14*$AB$2) -> 0 | AC14: =AC13 -> 1969 | AD14: =AC14-AC13 -> 0 | AE14: =AE13 -> 368382 | AF14: =AE14-AE13 -> 0 | AG14: =IF(AD14>0,AF14/AD14,0) -> 0 | AH14: =AF14+AA14 -> 0 | AI14: =SUM(AH14+V14) -> 0 | AJ14: =-tanks!AW16 -> 0 | AK14: =SUM(AJ14-AI14) -> 0 | AL14: =S14+L14+G14 -> 0 | AM14: =Y14+AD14 -> 0 | AN14: =AN13 -> 65 | AO14: =(AN14/100)*3000 -> 1950 | AP14: =AP13 -> 35 | AQ14: =(AP14/100)*3000 -> 1050 | AR14: =AR13 -> 73 | AS14: =(AR14/100)*3000 -> 2190 | AT14: =SUM(AO14+AQ14+AS14) -> 5190 | AU14: =AT13-AT14+AV14 -> 0 | AX14: =IF(AV14>0,AW14,AX13) -> 0.8
A15: =ELEC!C14 -> 44968 | B15: =B14 -> 235 | C15: =C14 -> 241 | D15: =C14-C15 -> 0 | E15: =D15*8.38 -> 0 | F15: =F14 -> 2382 | G15: =F15-F14 -> 0 | H15: =H14 -> 54054 | I15: =SUM(H15-H14) -> 0 | J15: =IF(G15>0,I15/G15,0) -> 0 | K15: =K14 -> 2492 | L15: =K15-K14 -> 0 | M15: =M14 -> 185894 | N15: =M15-M14 -> 0 | O15: =O14 -> 2251 | P15: =P14 -> 2268 | Q15: =Q14 -> 189309 | R15: =Q15-Q14 -> 0 | S15: =SUM(P15-P14) -> 0 | T15: =SUM(S15*$T$2) -> 0 | U15: =SUM(G15+L15+S15) -> 0 | V15: =R15+N15+I15:I15 -> 0 | W15: =SUM(V15/U15) -> #DIV/0! | X15: =X14 -> 2498 | Y15: =X15-X14 -> 0 | Z15: =Z14 -> 141480 | AA15: =Z15-Z14 -> 0 | AB15: =SUM(Y15*$AB$2) -> 0 | AC15: =AC14 -> 1969 | AD15: =AC15-AC14 -> 0 | AE15: =AE14 -> 368382 | AF15: =AE15-AE14 -> 0 | AG15: =IF(AD15>0,AF15/AD15,0) -> 0 | AH15: =AF15+AA15 -> 0 | AI15: =SUM(AH15+V15) -> 0 | AJ15: =-tanks!AW17 -> 636 | AK15: =SUM(AJ15-AI15) -> 636 | AL15: =S15+L15+G15 -> 0 | AM15: =Y15+AD15 -> 0 | AN15: =AN14 -> 65 | AO15: =(AN15/100)*3000 -> 1950 | AP15: =AP14 -> 35 | AQ15: =(AP15/100)*3000 -> 1050 | AR15: =AR14 -> 73 | AS15: =(AR15/100)*3000 -> 2190 | AT15: =SUM(AO15+AQ15+AS15) -> 5190 | AU15: =AT14-AT15+AV15 -> 0 | AX15: =IF(AV15>0,AW15,AX14) -> 0.8
A16: =ELEC!C15 -> 44969 | B16: 230 | C16: 236 | D16: =C15-C16 -> 5 | E16: =D16*8.38 -> 41.9 | F16: =F15 -> 2382 | G16: =F16-F15 -> 0 | H16: =H15 -> 54054 | I16: =SUM(H16-H15) -> 0 | J16: =IF(G16>0,I16/G16,0) -> 0 | K16: =K15 -> 2492 | L16: =K16-K15 -> 0 | M16: =M15 -> 185894 | N16: =M16-M15 -> 0 | O16: =O15 -> 2251 | P16: 2275 | Q16: 189801 | R16: =Q16-Q15 -> 492 | S16: =SUM(P16-P15) -> 7 | T16: =SUM(S16*$T$2) -> 0 | U16: =SUM(G16+L16+S16) -> 7 | V16: =R16+N16+I16:I16 -> 492 | X16: 2499 | Y16: =X16-X15 -> 1 | Z16: 141557 | AA16: =Z16-Z15 -> 77 | AB16: =SUM(Y16*$AB$2) -> 0 | AC16: 1970 | AD16: =AC16-AC15 -> 1 | AE16: 368449 | AF16: =AE16-AE15 -> 67 | AG16: =IF(AD16>0,AF16/AD16,0) -> 67 | AH16: =AF16+AA16 -> 144 | AI16: =SUM(AH16+V16) -> 636 | AJ16: =-tanks!AW18 -> 124 | AK16: =SUM(AJ16-AI16) -> -512 | AL16: =S16+L16+G16 -> 7 | AM16: =Y16+AD16 -> 2 | AN16: =AN15 -> 65 | AO16: =(AN16/100)*3000 -> 1950 | AP16: =AP15 -> 35 | AQ16: =(AP16/100)*3000 -> 1050 | AR16: =AR15 -> 73 | AS16: =(AR16/100)*3000 -> 2190 | AT16: =SUM(AO16+AQ16+AS16) -> 5190 | AU16: =AT15-AT16+AV16 -> 0 | AX16: =IF(AV16>0,AW16,AX15) -> 0.8
A17: =ELEC!C16 -> 44970 | B17: 227 | C17: 233 | D17: =C16-C17 -> 3 | E17: =D17*8.38 -> 25.14 | F17: 2383 | G17: =F17-F16 -> 1 | H17: 54097 | I17: =SUM(H17-H16) -> 43 | J17: =IF(G17>0,I17/G17,0) -> 43 | K17: 2492 | L17: =K17-K16 -> 0 | M17: =M16 -> 185894 | N17: =M17-M16 -> 0 | O17: 1869 | P17: =P16 -> 2275 | Q17: 189842 | R17: =Q17-Q16 -> 41 | S17: =SUM(P17-P16) -> 0 | T17: =SUM(S17*$T$2) -> 0 | U17: =SUM(G17+L17+S17) -> 1 | V17: =R17+N17+I17:I17 -> 84 | X17: =X16 -> 2499 | Y17: =X17-X16 -> 0 | Z17: 141597 | AA17: =Z17-Z16 -> 40 | AB17: =SUM(Y17*$AB$2) -> 0 | AC17: =AC16 -> 1970 | AD17: =AC17-AC16 -> 0 | AE17: =AE16 -> 368449 | AF17: =AE17-AE16 -> 0 | AG17: =IF(AD17>0,AF17/AD17,0) -> 0 | AH17: =AF17+AA17 -> 40 | AI17: =SUM(AH17+V17) -> 124 | AJ17: =-tanks!AW19 -> 300 | AK17: =SUM(AJ17-AI17) -> 176 | AL17: =S17+L17+G17 -> 1 | AM17: =Y17+AD17 -> 0 | AN17: =AN16 -> 65 | AO17: =(AN17/100)*3000 -> 1950 | AP17: =AP16 -> 35 | AQ17: =(AP17/100)*3000 -> 1050 | AR17: =AR16 -> 73 | AS17: =(AR17/100)*3000 -> 2190 | AT17: =SUM(AO17+AQ17+AS17) -> 5190 | AU17: =AT16-AT17+AV17 -> 0 | AX17: =IF(AV17>0,AW17,AX16) -> 0.8
A18: =ELEC!C17 -> 44971 | B18: 223 | C18: 230 | D18: =C17-C18 -> 3 | E18: =D18*8.38 -> 25.14 | F18: 2387 | G18: =F18-F17 -> 4 | H18: 54397 | I18: =SUM(H18-H17) -> 300 | J18: =IF(G18>0,I18/G18,0) -> 75 | K18: =K17 -> 2492 | L18: =K18-K17 -> 0 | M18: =M17 -> 185894 | N18: =M18-M17 -> 0 | O18: =O17 -> 1869 | P18: =P17 -> 2275 | Q18: =Q17 -> 189842 | R18: =Q18-Q17 -> 0 | S18: =SUM(P18-P17) -> 0 | T18: =SUM(S18*$T$2) -> 0 | U18: =SUM(G18+L18+S18) -> 4 | V18: =R18+N18+I18:I18 -> 300 | X18: =X17 -> 2499 | Y18: =X18-X17 -> 0 | Z18: =Z17 -> 141597 | AA18: =Z18-Z17 -> 0 | AB18: =SUM(Y18*$AB$2) -> 0 | AC18: =AC17 -> 1970 | AD18: =AC18-AC17 -> 0 | AE18: =AE17 -> 368449 | AF18: =AE18-AE17 -> 0 | AG18: =IF(AD18>0,AF18/AD18,0) -> 0 | AH18: =AF18+AA18 -> 0 | AI18: =SUM(AH18+V18) -> 300 | AJ18: =-tanks!AW20 -> 310 | AK18: =SUM(AJ18-AI18) -> 10 | AL18: =S18+L18+G18 -> 4 | AM18: =Y18+AD18 -> 0 | AN18: =AN17 -> 65 | AO18: =(AN18/100)*3000 -> 1950 | AP18: =AP17 -> 35 | AQ18: =(AP18/100)*3000 -> 1050 | AR18: =AR17 -> 73 | AS18: =(AR18/100)*3000 -> 2190 | AT18: =SUM(AO18+AQ18+AS18) -> 5190 | AU18: =AT17-AT18+AV18 -> 0 | AX18: =IF(AV18>0,AW18,AX17) -> 0.8
A19: =ELEC!C18 -> 44972 | B19: 220 | C19: 226 | D19: =C18-C19 -> 4 | E19: =D19*8.38 -> 33.52 | F19: 2391 | G19: =F19-F18 -> 4 | H19: 54707 | I19: =SUM(H19-H18) -> 310 | J19: =IF(G19>0,I19/G19,0) -> 77.5 | K19: =K18 -> 2492 | L19: =K19-K18 -> 0 | M19: =M18 -> 185894 | N19: =M19-M18 -> 0 | O19: =O18 -> 1869 | P19: =P18 -> 2275 | Q19: =Q18 -> 189842 | R19: =Q19-Q18 -> 0 | S19: =SUM(P19-P18) -> 0 | T19: =SUM(S19*$T$2) -> 0 | U19: =SUM(G19+L19+S19) -> 4 | V19: =R19+N19+I19:I19 -> 310 | X19: =X18 -> 2499 | Y19: =X19-X18 -> 0 | Z19: =Z18 -> 141597 | AA19: =Z19-Z18 -> 0 | AB19: =SUM(Y19*$AB$2) -> 0 | AC19: =AC18 -> 1970 | AD19: =AC19-AC18 -> 0 | AE19: =AE18 -> 368449 | AF19: =AE19-AE18 -> 0 | AG19: =IF(AD19>0,AF19/AD19,0) -> 0 | AH19: =AF19+AA19 -> 0 | AI19: =SUM(AH19+V19) -> 310 | AJ19: =-tanks!AW21 -> 263 | AK19: =SUM(AJ19-AI19) -> -47 | AL19: =S19+L19+G19 -> 4 | AM19: =Y19+AD19 -> 0 | AN19: =AN18 -> 65 | AO19: =(AN19/100)*3000 -> 1950 | AP19: =AP18 -> 35 | AQ19: =(AP19/100)*3000 -> 1050 | AR19: =AR18 -> 73 | AS19: =(AR19/100)*3000 -> 2190 | AT19: =SUM(AO19+AQ19+AS19) -> 5190 | AU19: =AT18-AT19+AV19 -> 0 | AX19: =IF(AV19>0,AW19,AX18) -> 0.8
A20: =ELEC!C19 -> 44973 | B20: 237 | C20: 243 | D20: =C19-C20 -> -17 | E20: =D20*8.38 -> -142.46 | F20: 2393 | G20: =F20-F19 -> 2 | H20: 54894 | I20: =SUM(H20-H19) -> 187 | J20: =IF(G20>0,I20/G20,0) -> 93.5 | K20: =K19 -> 2492 | L20: =K20-K19 -> 0 | M20: =M19 -> 185894 | N20: =M20-M19 -> 0 | O20: =O19 -> 1869 | P20: =P19 -> 2275 | Q20: =Q19 -> 189842 | R20: =Q20-Q19 -> 0 | S20: =SUM(P20-P19) -> 0 | T20: =SUM(S20*$T$2) -> 0 | U20: =SUM(G20+L20+S20) -> 2 | V20: =R20+N20+I20:I20 -> 187 | X20: =X19 -> 2499 | Y20: =X20-X19 -> 0 | Z20: =Z19 -> 141597 | AA20: =Z20-Z19 -> 0 | AB20: =SUM(Y20*$AB$2) -> 0 | AC20: 1972 | AD20: =AC20-AC19 -> 2 | AE20: 368525 | AF20: =AE20-AE19 -> 76 | AG20: =IF(AD20>0,AF20/AD20,0) -> 38 | AH20: =AF20+AA20 -> 76 | AI20: =SUM(AH20+V20) -> 263 | AJ20: =-tanks!AW22 -> 0 | AK20: =SUM(AJ20-AI20) -> -263 | AL20: =S20+L20+G20 -> 2 | AM20: =Y20+AD20 -> 2 | AN20: =AN19 -> 65 | AO20: =(AN20/100)*3000 -> 1950 | AP20: =AP19 -> 35 | AQ20: =(AP20/100)*3000 -> 1050 | AR20: =AR19 -> 73 | AS20: =(AR20/100)*3000 -> 2190 | AT20: =SUM(AO20+AQ20+AS20) -> 5190 | AU20: =AT19-AT20+AV20 -> 0 | AX20: =IF(AV20>0,AW20,AX19) -> 0.8
A21: =ELEC!C20 -> 44974 | B21: =B20 -> 237 | C21: =C20 -> 243 | D21: =C20-C21 -> 0 | E21: =D21*8.38 -> 0 | F21: =F20 -> 2393 | G21: =F21-F20 -> 0 | H21: =H20 -> 54894 | I21: =SUM(H21-H20) -> 0 | J21: =IF(G21>0,I21/G21,0) -> 0 | K21: =K20 -> 2492 | L21: =K21-K20 -> 0 | M21: =M20 -> 185894 | N21: =M21-M20 -> 0 | O21: =O20 -> 1869 | P21: =P20 -> 2275 | Q21: =Q20 -> 189842 | R21: =Q21-Q20 -> 0 | S21: =SUM(P21-P20) -> 0 | T21: =SUM(S21*$T$2) -> 0 | U21: =SUM(G21+L21+S21) -> 0 | V21: =R21+N21+I21:I21 -> 0 | X21: =X20 -> 2499 | Y21: =X21-X20 -> 0 | Z21: =Z20 -> 141597 | AA21: =Z21-Z20 -> 0 | AB21: =SUM(Y21*$AB$2) -> 0 | AC21: =AC20 -> 1972 | AD21: =AC21-AC20 -> 0 | AE21: =AE20 -> 368525 | AF21: =AE21-AE20 -> 0 | AG21: =IF(AD21>0,AF21/AD21,0) -> 0 | AH21: =AF21+AA21 -> 0 | AI21: =SUM(AH21+V21) -> 0 | AJ21: =-tanks!AW23 -> 0 | AK21: =SUM(AJ21-AI21) -> 0 | AL21: =S21+L21+G21 -> 0 | AM21: =Y21+AD21 -> 0 | AN21: =AN20 -> 65 | AO21: =(AN21/100)*3000 -> 1950 | AP21: =AP20 -> 35 | AQ21: =(AP21/100)*3000 -> 1050 | AR21: =AR20 -> 73 | AS21: =(AR21/100)*3000 -> 2190 | AT21: =SUM(AO21+AQ21+AS21) -> 5190 | AU21: =AT20-AT21+AV21 -> 0 | AX21: =IF(AV21>0,AW21,AX20) -> 0.8
A22: =ELEC!C21 -> 44975 | B22: =B21 -> 237 | C22: =C21 -> 243 | D22: =C21-C22 -> 0 | E22: =D22*8.38 -> 0 | F22: =F21 -> 2393 | G22: =F22-F21 -> 0 | H22: =H21 -> 54894 | I22: =SUM(H22-H21) -> 0 | J22: =IF(G22>0,I22/G22,0) -> 0 | K22: =K21 -> 2492 | L22: =K22-K21 -> 0 | M22: =M21 -> 185894 | N22: =M22-M21 -> 0 | O22: =O21 -> 1869 | P22: =P21 -> 2275 | Q22: =Q21 -> 189842 | R22: =Q22-Q21 -> 0 | S22: =SUM(P22-P21) -> 0 | T22: =SUM(S22*$T$2) -> 0 | U22: =SUM(G22+L22+S22) -> 0 | V22: =R22+N22+I22:I22 -> 0 | X22: =X21 -> 2499 | Y22: =X22-X21 -> 0 | Z22: =Z21 -> 141597 | AA22: =Z22-Z21 -> 0 | AB22: =SUM(Y22*$AB$2) -> 0 | AC22: =AC21 -> 1972 | AD22: =AC22-AC21 -> 0 | AE22: =AE21 -> 368525 | AF22: =AE22-AE21 -> 0 | AG22: =IF(AD22>0,AF22/AD22,0) -> 0 | AH22: =AF22+AA22 -> 0 | AI22: =SUM(AH22+V22) -> 0 | AJ22: =-tanks!AW24 -> 180 | AK22: =SUM(AJ22-AI22) -> 180 | AL22: =S22+L22+G22 -> 0 | AM22: =Y22+AD22 -> 0 | AN22: =AN21 -> 65 | AO22: =(AN22/100)*3000 -> 1950 | AP22: =AP21 -> 35 | AQ22: =(AP22/100)*3000 -> 1050 | AR22: =AR21 -> 73 | AS22: =(AR22/100)*3000 -> 2190 | AT22: =SUM(AO22+AQ22+AS22) -> 5190 | AU22: =AT21-AT22+AV22 -> 0 | AX22: =IF(AV22>0,AW22,AX21) -> 0.8
A23: =ELEC!C22 -> 44976 | B23: 234 | C23: 240 | D23: =C22-C23 -> 3 | E23: =D23*8.38 -> 25.14 | F23: 2396 | G23: =F23-F22 -> 3 | H23: 55074 | I23: =SUM(H23-H22) -> 180 | J23: =IF(G23>0,I23/G23,0) -> 60 | K23: 2492 | L23: =K23-K22 -> 0 | M23: =M22 -> 185894 | N23: =M23-M22 -> 0 | O23: =O22 -> 1869 | P23: =P22 -> 2275 | Q23: =Q22 -> 189842 | R23: =Q23-Q22 -> 0 | S23: =SUM(P23-P22) -> 0 | T23: =SUM(S23*$T$2) -> 0 | U23: =SUM(G23+L23+S23) -> 3 | V23: =R23+N23+I23:I23 -> 180 | X23: =X22 -> 2499 | Y23: =X23-X22 -> 0 | Z23: =Z22 -> 141597 | AA23: =Z23-Z22 -> 0 | AB23: =SUM(Y23*$AB$2) -> 0 | AC23: =AC22 -> 1972 | AD23: =AC23-AC22 -> 0 | AE23: =AE22 -> 368525 | AF23: =AE23-AE22 -> 0 | AG23: =IF(AD23>0,AF23/AD23,0) -> 0 | AH23: =AF23+AA23 -> 0 | AI23: =SUM(AH23+V23) -> 180 | AJ23: =-tanks!AW25 -> 474 | AK23: =SUM(AJ23-AI23) -> 294 | AL23: =S23+L23+G23 -> 3 | AM23: =Y23+AD23 -> 0 | AN23: =AN22 -> 65 | AO23: =(AN23/100)*3000 -> 1950 | AP23: =AP22 -> 35 | AQ23: =(AP23/100)*3000 -> 1050 | AR23: =AR22 -> 73 | AS23: =(AR23/100)*3000 -> 2190 | AT23: =SUM(AO23+AQ23+AS23) -> 5190 | AU23: =AT22-AT23+AV23 -> 0 | AX23: =IF(AV23>0,AW23,AX22) -> 0.8
A24: =ELEC!C23 -> 44977 | B24: 229.5 | C24: 236 | D24: =C23-C24 -> 4 | E24: =D24*8.38 -> 33.52 | F24: 2401 | G24: =F24-F23 -> 5 | H24: 55465 | I24: =SUM(H24-H23) -> 391 | J24: =IF(G24>0,I24/G24,0) -> 78.2 | K24: 2492 | L24: =K24-K23 -> 0 | M24: 185894 | N24: =M24-M23 -> 0 | O24: =O23 -> 1869 | P24: =P23 -> 2275 | Q24: =Q23 -> 189842 | R24: =Q24-Q23 -> 0 | S24: =SUM(P24-P23) -> 0 | T24: =SUM(S24*$T$2) -> 0 | U24: =SUM(G24+L24+S24) -> 5 | V24: =R24+N24+I24:I24 -> 391 | X24: =X23 -> 2499 | Y24: =X24-X23 -> 0 | Z24: 141680 | AA24: =Z24-Z23 -> 83 | AB24: =SUM(Y24*$AB$2) -> 0 | AC24: =AC23 -> 1972 | AD24: =AC24-AC23 -> 0 | AE24: =AE23 -> 368525 | AF24: =AE24-AE23 -> 0 | AG24: =IF(AD24>0,AF24/AD24,0) -> 0 | AH24: =AF24+AA24 -> 83 | AI24: =SUM(AH24+V24) -> 474 | AJ24: =-tanks!AW26 -> 236 | AK24: =SUM(AJ24-AI24) -> -238 | AL24: =S24+L24+G24 -> 5 | AM24: =Y24+AD24 -> 0 | AN24: =AN23 -> 65 | AO24: =(AN24/100)*3000 -> 1950 | AP24: =AP23 -> 35 | AQ24: =(AP24/100)*3000 -> 1050 | AR24: =AR23 -> 73 | AS24: =(AR24/100)*3000 -> 2190 | AT24: =SUM(AO24+AQ24+AS24) -> 5190 | AU24: =AT23-AT24+AV24 -> 0 | AX24: =IF(AV24>0,AW24,AX23) -> 0.8
A25: =ELEC!C24 -> 44978 | B25: 224 | C25: 232 | D25: =C24-C25 -> 4 | E25: =D25*8.38 -> 33.52 | F25: 2404 | G25: =F25-F24 -> 3 | H25: 55701 | I25: =SUM(H25-H24) -> 236 | J25: =IF(G25>0,I25/G25,0) -> 78.666667 | K25: 2492 | L25: =K25-K24 -> 0 | M25: =M24 -> 185894 | N25: =M25-M24 -> 0 | O25: 2251 | P25: =P24 -> 2275 | Q25: =Q24 -> 189842 | R25: =Q25-Q24 -> 0 | S25: =SUM(P25-P24) -> 0 | T25: =SUM(S25*$T$2) -> 0 | U25: =SUM(G25+L25+S25) -> 3 | V25: =R25+N25+I25:I25 -> 236 | X25: =X24 -> 2499 | Y25: =X25-X24 -> 0 | Z25: =Z24 -> 141680 | AA25: =Z25-Z24 -> 0 | AB25: =SUM(Y25*$AB$2) -> 0 | AC25: =AC24 -> 1972 | AD25: =AC25-AC24 -> 0 | AE25: =AE24 -> 368525 | AF25: =AE25-AE24 -> 0 | AG25: =IF(AD25>0,AF25/AD25,0) -> 0 | AH25: =AF25+AA25 -> 0 | AI25: =SUM(AH25+V25) -> 236 | AJ25: =-tanks!AW27 -> 283 | AK25: =SUM(AJ25-AI25) -> 47 | AL25: =S25+L25+G25 -> 3 | AM25: =Y25+AD25 -> 0 | AN25: =AN24 -> 65 | AO25: =(AN25/100)*3000 -> 1950 | AP25: =AP24 -> 35 | AQ25: =(AP25/100)*3000 -> 1050 | AR25: =AR24 -> 73 | AS25: =(AR25/100)*3000 -> 2190 | AT25: =SUM(AO25+AQ25+AS25) -> 5190 | AU25: =AT24-AT25+AV25 -> 0 | AX25: =IF(AV25>0,AW25,AX24) -> 0.8
A26: =ELEC!C25 -> 44979 | B26: 222 | C26: 229 | D26: =C25-C26 -> 3 | E26: =D26*8.38 -> 25.14 | F26: 2408 | G26: =F26-F25 -> 4 | H26: 55984 | I26: =SUM(H26-H25) -> 283 | J26: =IF(G26>0,I26/G26,0) -> 70.75 | K26: =K25 -> 2492 | L26: =K26-K25 -> 0 | M26: =M25 -> 185894 | N26: =M26-M25 -> 0 | O26: =O25 -> 2251 | P26: =P25 -> 2275 | Q26: =Q25 -> 189842 | R26: =Q26-Q25 -> 0 | S26: =SUM(P26-P25) -> 0 | T26: =SUM(S26*$T$2) -> 0 | U26: =SUM(G26+L26+S26) -> 4 | V26: =R26+N26+I26:I26 -> 283 | X26: =X25 -> 2499 | Y26: =X26-X25 -> 0 | Z26: =Z25 -> 141680 | AA26: =Z26-Z25 -> 0 | AB26: =SUM(Y26*$AB$2) -> 0 | AC26: =AC25 -> 1972 | AD26: =AC26-AC25 -> 0 | AE26: =AE25 -> 368525 | AF26: =AE26-AE25 -> 0 | AG26: =IF(AD26>0,AF26/AD26,0) -> 0 | AH26: =AF26+AA26 -> 0 | AI26: =SUM(AH26+V26) -> 283 | AJ26: =-tanks!AW28 -> 306 | AK26: =SUM(AJ26-AI26) -> 23 | AL26: =S26+L26+G26 -> 4 | AM26: =Y26+AD26 -> 0 | AN26: =AN25 -> 65 | AO26: =(AN26/100)*3000 -> 1950 | AP26: =AP25 -> 35 | AQ26: =(AP26/100)*3000 -> 1050 | AR26: =AR25 -> 73 | AS26: =(AR26/100)*3000 -> 2190 | AT26: =SUM(AO26+AQ26+AS26) -> 5190 | AU26: =AT25-AT26+AV26 -> 0 | AX26: =IF(AV26>0,AW26,AX25) -> 0.8
A27: =ELEC!C26 -> 44980 | B27: 218 | C27: 225 | D27: =C26-C27 -> 4 | E27: =D27*8.38 -> 33.52 | F27: 2410 | G27: =F27-F26 -> 2 | H27: 56188 | I27: =SUM(H27-H26) -> 204 | J27: =IF(G27>0,I27/G27,0) -> 102 | K27: 2492 | L27: =K27-K26 -> 0 | M27: =M26 -> 185894 | N27: =M27-M26 -> 0 | O27: =O26 -> 2251 | P27: =P26 -> 2275 | Q27: =Q26 -> 189842 | R27: =Q27-Q26 -> 0 | S27: =SUM(P27-P26) -> 0 | T27: =SUM(S27*$T$2) -> 0 | U27: =SUM(G27+L27+S27) -> 2 | V27: =R27+N27+I27:I27 -> 204 | X27: =X26 -> 2499 | Y27: =X27-X26 -> 0 | Z27: =Z26 -> 141680 | AA27: =Z27-Z26 -> 0 | AB27: =SUM(Y27*$AB$2) -> 0 | AC27: 1973 | AD27: =AC27-AC26 -> 1 | AE27: 368627 | AF27: =AE27-AE26 -> 102 | AG27: =IF(AD27>0,AF27/AD27,0) -> 102 | AH27: =AF27+AA27 -> 102 | AI27: =SUM(AH27+V27) -> 306 | AJ27: =-tanks!AW29 -> 0 | AK27: =SUM(AJ27-AI27) -> -306 | AL27: =S27+L27+G27 -> 2 | AM27: =Y27+AD27 -> 1 | AN27: =AN26 -> 65 | AO27: =(AN27/100)*3000 -> 1950 | AP27: =AP26 -> 35 | AQ27: =(AP27/100)*3000 -> 1050 | AR27: =AR26 -> 73 | AS27: =(AR27/100)*3000 -> 2190 | AT27: =SUM(AO27+AQ27+AS27) -> 5190 | AU27: =AT26-AT27+AV27 -> 0 | AX27: =IF(AV27>0,AW27,AX26) -> 0.8
