Workbook

Sheet TOTAL
A1: Site Name | B1: Day | C1: Month | D1: Year | E1: Total Electricity Kwh | F1: Electricity Tariff ($/Kwh) | G1: Water Utility Supply (m3) m3 | H1: Water Utility Supply (m3) $/m3 | I1: Total Fuel Oil (Liters) | J1: Fuel Oil $/Liter | K1: Room Nights
A2: Kuwait | B2: 1 | C2: 3 | D2: 2023 | E2: =Submetering!E2+Submetering!F2+Submetering!G2+Submetering!H2+Submetering!I2+Submetering!J2+Submetering!K2+Submetering!L2+Submetering!M2+Submetering!N2+Submetering!O2+Submetering!P2+Submetering!Q2 -> 55500 | F2: 0.005 | G2: =Submetering!S2 -> 363.09 | H2: 0.4444 | I2: =Submetering!R2 -> 35.625 | J2: 0.14 | K2: =Hotel!B7 -> 71
A3: Kuwait | B3: =B2+1 -> 2 | C3: 3 | D3: 2023 | E3: =Submetering!E3+Submetering!F3+Submetering!G3+Submetering!H3+Submetering!I3+Submetering!J3+Submetering!K3+Submetering!L3+Submetering!M3+Submetering!N3+Submetering!O3+Submetering!P3+Submetering!Q3 -> 55620 | F3: 0.005 | G3: =Submetering!S3 -> 427.518 | H3: 0.4444 | I3: =Submetering!R3 -> 0 | J3: 0.14 | K3: =Hotel!B8 -> 118
A4: Kuwait | B4: =B3+1 -> 3 | C4: 3 | D4: 2023 | E4: =Submetering!E4+Submetering!F4+Submetering!G4+Submetering!H4+Submetering!I4+Submetering!J4+Submetering!K4+Submetering!L4+Submetering!M4+Submetering!N4+Submetering!O4+Submetering!P4+Submetering!Q4 -> 55710 | F4: 0.005 | G4: =Submetering!S4 -> 412.776 | H4: 0.4444 | I4: =Submetering!R4 -> 0 | J4: 0.14 | K4: =Hotel!B9 -> 185
A5: Kuwait | B5: =B4+1 -> 4 | C5: 3 | D5: 2023 | E5: =Submetering!E5+Submetering!F5+Submetering!G5+Submetering!H5+Submetering!I5+Submetering!J5+Submetering!K5+Submetering!L5+Submetering!M5+Submetering!N5+Submetering!O5+Submetering!P5+Submetering!Q5 -> 56600 | F5: 0.005 | G5: =Submetering!S5 -> 429.975 | H5: 0.4444 | I5: =Submetering!R5 -> 1282.5 | J5: 0.14 | K5: =Hotel!B10 -> 119
A6: Kuwait | B6: =B5+1 -> 5 | C6: 3 | D6: 2023 | E6: =Submetering!E6+Submetering!F6+Submetering!G6+Submetering!H6+Submetering!I6+Submetering!J6+Submetering!K6+Submetering!L6+Submetering!M6+Submetering!N6+Submetering!O6+Submetering!P6+Submetering!Q6 -> 55300 | F6: 0.005 | G6: =Submetering!S6 -> 438.165 | H6: 0.4444 | I6: =Submetering!R6 -> 0 | J6: 0.14 | K6: =Hotel!B11 -> 110
A7: Kuwait | B7: =B6+1 -> 6 | C7: 3 | D7: 2023 | E7: =Submetering!E7+Submetering!F7+Submetering!G7+Submetering!H7+Submetering!I7+Submetering!J7+Submetering!K7+Submetering!L7+Submetering!M7+Submetering!N7+Submetering!O7+Submetering!P7+Submetering!Q7 -> 52290 | F7: 0.005 | G7: =Submetering!S7 -> 423.969 | H7: 0.4444 | I7: =Submetering!R7 -> 623.4375 | J7: 0.14 | K7: =Hotel!B12 -> 137
A8: Kuwait | B8: =B7+1 -> 7 | C8: 3 | D8: 2023 | E8: =Submetering!E8+Submetering!F8+Submetering!G8+Submetering!H8+Submetering!I8+Submetering!J8+Submetering!K8+Submetering!L8+Submetering!M8+Submetering!N8+Submetering!O8+Submetering!P8+Submetering!Q8 -> 56410 | F8: 0.005 | G8: =Submetering!S8 -> 449.085 | H8: 0.4444 | I8: =Submetering!R8 -> 0 | J8: 0.14 | K8: =Hotel!B13 -> 149
A9: Kuwait | B9: =B8+1 -> 8 | C9: 3 | D9: 2023 | E9: =Submetering!E9+Submetering!F9+Submetering!G9+Submetering!H9+Submetering!I9+Submetering!J9+Submetering!K9+Submetering!L9+Submetering!M9+Submetering!N9+Submetering!O9+Submetering!P9+Submetering!Q9 -> 0 | F9: 0.005 | G9: =Submetering!S9 -> 0 | H9: 0.4444 | I9: =Submetering!R9 -> 0 | J9: 0.14 | K9: =Hotel!B14 -> 0
A10: Kuwait | B10: =B9+1 -> 9 | C10: 3 | D10: 2023 | E10: =Submetering!E10+Submetering!F10+Submetering!G10+Submetering!H10+Submetering!I10+Submetering!J10+Submetering!K10+Submetering!L10+Submetering!M10+Submetering!N10+Submetering!O10+Submetering!P10+Submetering!Q10 -> 0 | F10: 0.005 | G10: =Submetering!S10 -> 0 | H10: 0.4444 | I10: =Submetering!R10 -> 0 | J10: 0.14 | K10: =Hotel!B15 -> 0
A11: Kuwait | B11: =B10+1 -> 10 | C11: 3 | D11: 2023 | E11: =Submetering!E11+Submetering!F11+Submetering!G11+Submetering!H11+Submetering!I11+Submetering!J11+Submetering!K11+Submetering!L11+Submetering!M11+Submetering!N11+Submetering!O11+Submetering!P11+Submetering!Q11 -> 0 | F11: 0.005 | G11: =Submetering!S11 -> 0 | H11: 0.4444 | I11: =Submetering!R11 -> 0 | J11: 0.14 | K11: =Hotel!B16 -> 0
A12: Kuwait | B12: =B11+1 -> 11 | C12: 3 | D12: 2023 | E12: =Submetering!E12+Submetering!F12+Submetering!G12+Submetering!H12+Submetering!I12+Submetering!J12+Submetering!K12+Submetering!L12+Submetering!M12+Submetering!N12+Submetering!O12+Submetering!P12+Submetering!Q12 -> 0 | F12: 0.005 | G12: =Submetering!S12 -> 0 | H12: 0.4444 | I12: =Submetering!R12 -> 0 | J12: 0.14 | K12: =Hotel!B17 -> 0
A13: Kuwait | B13: =B12+1 -> 12 | C13: 3 | D13: 2023 | E13: =Submetering!E13+Submetering!F13+Submetering!G13+Submetering!H13+Submetering!I13+Submetering!J13+Submetering!K13+Submetering!L13+Submetering!M13+Submetering!N13+Submetering!O13+Submetering!P13+Submetering!Q13 -> 0 | F13: 0.005 | G13: =Submetering!S13 -> 0 | H13: 0.4444 | I13: =Submetering!R13 -> 0 | J13: 0.14 | K13: =Hotel!B18 -> 0
A14: Kuwait | B14: =B13+1 -> 13 | C14: 3 | D14: 2023 | E14: =Submetering!E14+Submetering!F14+Submetering!G14+Submetering!H14+Submetering!I14+Submetering!J14+Submetering!K14+Submetering!L14+Submetering!M14+Submetering!N14+Submetering!O14+Submetering!P14+Submetering!Q14 -> 0 | F14: 0.005 | G14: =Submetering!S14 -> 0 | H14: 0.4444 | I14: =Submetering!R14 -> 0 | J14: 0.14 | K14: =Hotel!B19 -> 0
... A32: Kuwait | B32: =B31+1 -> 31 | C32: 3 | D32: 2023 | E32: =Submetering!E32+Submetering!F32+Submetering!G32+Submetering!H32+Submetering!I32+Submetering!J32+Submetering!K32+Submetering!L32+Submetering!M32+Submetering!N32+Submetering!O32+Submetering!P32+Submetering!Q32 -> 0 | F32: 0.005 | G32: =Submetering!S32 -> 0 | H32: 0.4444 | I32: =Submetering!R32 -> 0 | J32: 0.14 | K32: =Hotel!B37 -> 0

Sheet Submetering
A1: Site Name | B1: Day | C1: Month | D1: Year | E1: HT.02.02 - KWh | F1: HT.02.04 - KWh | G1: HT.02.07 - KWh | H1: HT.02.03 - KWh | I1: HT.02.06 - KWh | J1: HT.03.03 - KWh | K1: HT.03.07 - KWh | L1: HT.03.05 - KWh | M1: HT.03.08 - KWh | N1: HT.03.04 - KWh | O1: HT.03.06 - KWh | P1: HT.03.01 - KWh | Q1: HT.03.02 - KWh | R1: Fuel (Liters) | S1: Water - m3 | T1: Cooling Towers Water | U1: Room Nights
A2: Kuwait | B2: 1 | C2: =TOTAL!C2 -> 3 | D2: 2023 | E2: =Hotel!Q7 -> 560 | F2: =Hotel!R7 -> 1890 | G2: =Hotel!S7 -> 3130 | H2: =Hotel!T7 -> 980 | I2: =Hotel!U7 -> 5820 | J2: =Hotel!V7 -> 4200 | K2: =Hotel!W7 -> 3230 | L2: =Hotel!X7 -> 4070 | ... Q2: =Hotel!AC7 -> 13030 | R2: =Hotel!AU7 -> 35.625 | S2: =Hotel!BA7 -> 363.09 | T2: =Hotel!AX7 -> 137 | U2: =Hotel!B7 -> 71
A3: Kuwait | B3: =B2+1 -> 2 | C3: =TOTAL!C3 -> 3 | D3: 2023 | E3: =Hotel!Q8 -> 560 | F3: =Hotel!R8 -> 1890 | G3: =Hotel!S8 -> 3140 | H3: =Hotel!T8 -> 980 | I3: =Hotel!U8 -> 6060 | J3: =Hotel!V8 -> 4300 | K3: =Hotel!W8 -> 3130 | L3: =Hotel!X8 -> 4220 | ... Q3: =Hotel!AC8 -> 12570 | R3: =Hotel!AU8 -> 0 | S3: =Hotel!BA8 -> 427.518 | T3: =Hotel!AX8 -> 137 | U3: =Hotel!B8 -> 118
A4: Kuwait | B4: =B3+1 -> 3 | C4: =TOTAL!C4 -> 3 | D4: 2023 | E4: =Hotel!Q9 -> 520 | F4: =Hotel!R9 -> 1760 | G4: =Hotel!S9 -> 3230 | H4: =Hotel!T9 -> 910 | I4: =Hotel!U9 -> 6280 | J4: =Hotel!V9 -> 4070 | K4: =Hotel!W9 -> 3150 | L4: =Hotel!X9 -> 4150 | ... Q4: =Hotel!AC9 -> 12900 | R4: =Hotel!AU9 -> 0 | S4: =Hotel!BA9 -> 412.776 | T4: =Hotel!AX9 -> 136 | U4: =Hotel!B9 -> 185
A5: Kuwait | B5: =B4+1 -> 4 | C5: =TOTAL!C5 -> 3 | D5: 2023 | E5: =Hotel!Q10 -> 540 | F5: =Hotel!R10 -> 1810 | G5: =Hotel!S10 -> 3330 | H5: =Hotel!T10 -> 940 | I5: =Hotel!U10 -> 6320 | J5: =Hotel!V10 -> 4130 | K5: =Hotel!W10 -> 2790 | L5: =Hotel!X10 -> 4210 | ... Q5: =Hotel!AC10 -> 13380 | R5: =Hotel!AU10 -> 1282.5 | S5: =Hotel!BA10 -> 429.975 | T5: =Hotel!AX10 -> 135 | U5: =Hotel!B10 -> 119
A6: Kuwait | B6: =B5+1 -> 5 | C6: =TOTAL!C6 -> 3 | D6: 2023 | E6: =Hotel!Q11 -> 660 | F6: =Hotel!R11 -> 1900 | G6: =Hotel!S11 -> 3310 | H6: =Hotel!T11 -> 990 | I6: =Hotel!U11 -> 5830 | J6: =Hotel!V11 -> 4200 | K6: =Hotel!W11 -> 3040 | L6: =Hotel!X11 -> 3910 | ... Q6: =Hotel!AC11 -> 12290 | R6: =Hotel!AU11 -> 0 | S6: =Hotel!BA11 -> 438.165 | T6: =Hotel!AX11 -> 131 | U6: =Hotel!B11 -> 110
A7: Kuwait | B7: =B6+1 -> 6 | C7: =TOTAL!C7 -> 3 | D7: 2023 | E7: =Hotel!Q12 -> 430 | F7: =Hotel!R12 -> 1770 | G7: =Hotel!S12 -> 3150 | H7: =Hotel!T12 -> 920 | I7: =Hotel!U12 -> 5660 | J7: =Hotel!V12 -> 3910 | K7: =Hotel!W12 -> 3030 | L7: =Hotel!X12 -> 4040 | ... Q7: =Hotel!AC12 -> 11580 | R7: =Hotel!AU12 -> 623.4375 | S7: =Hotel!BA12 -> 423.969 | T7: =Hotel!AX12 -> 131 | U7: =Hotel!B12 -> 137
A8: Kuwait | B8: =B7+1 -> 7 | C8: =TOTAL!C8 -> 3 | D8: 2023 | E8: =Hotel!Q13 -> 560 | F8: =Hotel!R13 -> 1870 | G8: =Hotel!S13 -> 3540 | H8: =Hotel!T13 -> 980 | I8: =Hotel!U13 -> 6140 | J8: =Hotel!V13 -> 4240 | K8: =Hotel!W13 -> 3240 | L8: =Hotel!X13 -> 4210 | ... Q8: =Hotel!AC13 -> 12600 | R8: =Hotel!AU13 -> 0 | S8: =Hotel!BA13 -> 449.085 | T8: =Hotel!AX13 -> 129 | U8: =Hotel!B13 -> 149
A9: Kuwait | B9: =B8+1 -> 8 | C9: =TOTAL!C9 -> 3 | D9: 2023 | E9: =Hotel!Q14 -> 0 | F9: =Hotel!R14 -> 0 | G9: =Hotel!S14 -> 0 | H9: =Hotel!T14 -> 0 | I9: =Hotel!U14 -> 0 | J9: =Hotel!V14 -> 0 | K9: =Hotel!W14 -> 0 | L9: =Hotel!X14 -> 0 | ... Q9: =Hotel!AC14 -> 0 | R9: =Hotel!AU14 -> 0 | S9: =Hotel!BA14 -> 0 | T9: =Hotel!AX14 -> 0 | U9: =Hotel!B14 -> 0
A10: Kuwait | B10: =B9+1 -> 9 | C10: =TOTAL!C10 -> 3 | D10: 2023 | E10: =Hotel!Q15 -> 0 | F10: =Hotel!R15 -> 0 | G10: =Hotel!S15 -> 0 | H10: =Hotel!T15 -> 0 | I10: =Hotel!U15 -> 0 | J10: =Hotel!V15 -> 0 | K10: =Hotel!W15 -> 0 | L10: =Hotel!X15 -> 0 | ... Q10: =Hotel!AC15 -> 0 | R10: =Hotel!AU15 -> 0 | S10: =Hotel!BA15 -> 0 | T10: =Hotel!AX15 -> 0 | U10: =Hotel!B15 -> 0
A11: Kuwait | B11: =B10+1 -> 10 | C11: =TOTAL!C11 -> 3 | D11: 2023 | E11: =Hotel!Q16 -> 0 | F11: =Hotel!R16 -> 0 | G11: =Hotel!S16 -> 0 | H11: =Hotel!T16 -> 0 | I11: =Hotel!U16 -> 0 | J11: =Hotel!V16 -> 0 | K11: =Hotel!W16 -> 0 | L11: =Hotel!X16 -> 0 | ... Q11: =Hotel!AC16 -> 0 | R11: =Hotel!AU16 -> 0 | S11: =Hotel!BA16 -> 0 | T11: =Hotel!AX16 -> 0 | U11: =Hotel!B16 -> 0
A12: Kuwait | B12: =B11+1 -> 11 | C12: =TOTAL!C12 -> 3 | D12: 2023 | E12: =Hotel!Q17 -> 0 | F12: =Hotel!R17 -> 0 | G12: =Hotel!S17 -> 0 | H12: =Hotel!T17 -> 0 | I12: =Hotel!U17 -> 0 | J12: =Hotel!V17 -> 0 | K12: =Hotel!W17 -> 0 | L12: =Hotel!X17 -> 0 | ... Q12: =Hotel!AC17 -> 0 | R12: =Hotel!AU17 -> 0 | S12: =Hotel!BA17 -> 0 | T12: =Hotel!AX17 -> 0 | U12: =Hotel!B17 -> 0
A13: Kuwait | B13: =B12+1 -> 12 | C13: =TOTAL!C13 -> 3 | D13: 2023 | E13: =Hotel!Q18 -> 0 | F13: =Hotel!R18 -> 0 | G13: =Hotel!S18 -> 0 | H13: =Hotel!T18 -> 0 | I13: =Hotel!U18 -> 0 | J13: =Hotel!V18 -> 0 | K13: =Hotel!W18 -> 0 | L13: =Hotel!X18 -> 0 | ... Q13: =Hotel!AC18 -> 0 | R13: =Hotel!AU18 -> 0 | S13: =Hotel!BA18 -> 0 | T13: =Hotel!AX18 -> 0 | U13: =Hotel!B18 -> 0
A14: Kuwait | B14: =B13+1 -> 13 | C14: =TOTAL!C14 -> 3 | D14: 2023 | E14: =Hotel!Q19 -> 0 | F14: =Hotel!R19 -> 0 | G14: =Hotel!S19 -> 0 | H14: =Hotel!T19 -> 0 | I14: =Hotel!U19 -> 0 | J14: =Hotel!V19 -> 0 | K14: =Hotel!W19 -> 0 | L14: =Hotel!X19 -> 0 | ... Q14: =Hotel!AC19 -> 0 | R14: =Hotel!AU19 -> 0 | S14: =Hotel!BA19 -> 0 | T14: =Hotel!AX19 -> 0 | U14: =Hotel!B19 -> 0
... A32: Kuwait | B32: =B31+1 -> 31 | C32: =TOTAL!C32 -> 3 | D32: 2023 | E32: =Hotel!Q37 -> 0 | F32: =Hotel!R37 -> 0 | G32: =Hotel!S37 -> 0 | H32: =Hotel!T37 -> 0 | I32: =Hotel!U37 -> 0 | J32: =Hotel!V37 -> 0 | K32: =Hotel!W37 -> 0 | L32: =Hotel!X37 -> 0 | ... Q32: =Hotel!AC37 -> 0 | R32: =Hotel!AU37 -> 0 | S32: =Hotel!BA37 -> 0 | T32: =Hotel!AX37 -> 0 | U32: =Hotel!B37 -> 0

Sheet Hotel
C1: 1 | D1: 2 | E1: 3 | F1: 4 | G1: 5 | H1: 6 | I1: 7 | J1: 8 | K1: 9 | L1: 10 | M1: 11 | N1: 12 | O1: 13 | Q1: 1 | R1: 2 | S1: 3 | T1: 4 | U1: 5 | V1: 6 | W1: 7 | X1: 8 | Y1: 9 | Z1: 10 | AA1: 11 | AB1: 12 | AC1: 13
A2: 44985 | B2: 106 | C2: 8830450 | D2: 21231640 | E2: 4012970 | F2: 4493120 | G2: 13430070 | H2: 8032340 | I2: 6908740 | J2: 8683040 | K2: 12518220 | L2: 5461610 | M2: 9845100 | N2: 16582140 | O2: 23448280 | Q2: HT.02.02 | R2: HT.02.04 | S2: HT.02.07 | T2: HT.02.03 | U2: HT.02.06 | V2: HT.03.03 | W2: HT.03.07 | X2: HT.03.05 | Y2: HT.03.08 | Z2: HT.03.04 | AA2: HT.03.06 | AB2: HT.03.01 | AC2: HT.03.02 | AW2: 70538 | AY2: 448654
A4: Date | B4: Room Night | C4: March | D4: Electricity - Meter No | Q4: Electricity Consumption -KWh | AD4: Total KWh | AF4: Electricity Consumption - Amount | AS4: Total Kd | AT4: Fuel Consumption (%) | AU4: Fuel Consumption (Liters) | AW4: CT Water Meter Reading | AX4: CT Consumption Cubic Meter | AY4: Water Meter Reading | AZ4: Consumption Gallons | BA4: Consumption Cubic Meter | BB4: Total KD
A5: 2023 | C5: HT.02.02 | D5: HT.02.04 | E5: HT.02.07 | F5: HT.02.03 | G5: HT.02.06 | H5: HT.03.03 | I5: HT.03.07 | J5: HT.03.05 | K5: HT.03.08 | L5: HT.03.04 | M5: HT.03.06 | N5: HT.03.01 | O5: HT.03.02 | Q5: 8483196 | R5: 8483193 | S5: 8483178 | T5: 8483176 | U5: 8483206 | V5: 8483170 | W5: 8483168 | X5: 8483169 | Y5: 8483194 | Z5: 8483199 | AA5: 8483187 | AB5: 8483188 | AC5: 8483174 | AF5: 1 | AG5: 2 | AH5: 3 | AI5: 4 | AJ5: 5 | AK5: 6 | AL5: 7 | AM5: 8 | AN5: 9 | AO5: 10 | AP5: 11 | AQ5: 12 | AR5: 13
C6: 8483196 | D6: 8483193 | E6: 8483178 | F6: 8483176 | G6: 8483206 | H6: 8483170 | I6: 8483168 | J6: 8483169 | K6: 8483194 | L6: 8483199 | M6: 8483187 | N6: 8483188 | O6: 8483174 | AW6: 70538 | AY6: 448654
A7: 44986 | B7: 71 | C7: 8831010 | D7: 21233530 | E7: 4016100 | F7: 4494100 | G7: 13435890 | H7: 8036540 | I7: 6911970 | J7: 8687110 | K7: 12523960 | L7: 5464060 | M7: 9848140 | N7: 16589500 | O7: 23461310 | Q7: =IF((C7-C2<0), "0",C7-C2) -> 560 | R7: =IF((D7-D2<0), "0",D7-D2) -> 1890 | S7: =IF((E7-E2<0), "0",E7-E2) -> 3130 | T7: =IF((F7-F2<0), "0",F7-F2) -> 980 | U7: =IF((G7-G2<0), "0",G7-G2) -> 5820 | V7: =IF((H7-H2<0), "0",H7-H2) -> 4200 | W7: =IF((I7-I2<0), "0",I7-I2) -> 3230 | X7: =IF((J7-J2<0), "0",J7-J2) -> 4070 | ... AC7: =IF((O7-O2<0), "0",O7-O2) -> 13030 | AD7: =SUM(Q7:AC7) -> 55500 | AF7: =Q7*$D$39 -> 2.8 | AG7: =R7*$D$39 -> 9.45 | AH7: =S7*$D$39 -> 15.65 | AI7: =T7*$D$39 -> 4.9 | AJ7: =U7*$D$39 -> 29.1 | AK7: =V7*$D$39 -> 21 | AL7: =W7*$D$39 -> 16.15 | AM7: =X7*$D$39 -> 20.35 | ... AR7: =AC7*$D$39 -> 65.15 | AS7: =SUM(AF7:AR7) -> 277.5 | AT7: 0.2 | AU7: =AT7*$AU$43 -> 35.625 | AW7: 70675 | AX7: =(IF((AW7-AW6<0),"0",AW7-AW6)) -> 137 | AY7: 449984 | AZ7: =(IF((AY7-AY6<0),"0",AY7-AY6))*100 -> 133000 | BA7: =AZ7*$AZ$44*60% -> 363.09 | BB7: =BA7*0.4444 -> 161.3572
A8: 44987 | B8: 118 | C8: 8831570 | D8: 21235420 | E8: 4019240 | F8: 4495080 | G8: 13441950 | H8: 8040840 | I8: 6915100 | J8: 8691330 | K8: 12529680 | L8: 5466510 | M8: 9851360 | N8: 16596880 | O8: 23473880 | Q8: =IF((C8-C7<0), "0",C8-C7) -> 560 | R8: =IF((D8-D7<0), "0",D8-D7) -> 1890 | S8: =IF((E8-E7<0), "0",E8-E7) -> 3140 | T8: =IF((F8-F7<0), "0",F8-F7) -> 980 | U8: =IF((G8-G7<0), "0",G8-G7) -> 6060 | V8: =IF((H8-H7<0), "0",H8-H7) -> 4300 | W8: =IF((I8-I7<0), "0",I8-I7) -> 3130 | X8: =IF((J8-J7<0), "0",J8-J7) -> 4220 | ... AC8: =IF((O8-O7<0), "0",O8-O7) -> 12570 | AD8: =SUM(Q8:AC8) -> 55620 | AF8: =Q8*$D$39 -> 2.8 | AG8: =R8*$D$39 -> 9.45 | AH8: =S8*$D$39 -> 15.7 | AI8: =T8*$D$39 -> 4.9 | AJ8: =U8*$D$39 -> 30.3 | AK8: =V8*$D$39 -> 21.5 | AL8: =W8*$D$39 -> 15.65 | AM8: =X8*$D$39 -> 21.1 | ... AR8: =AC8*$D$39 -> 62.85 | AS8: =SUM(AF8:AR8) -> 278.1 | AT8: 0 | AU8: =AT8*$AU$43 -> 0 | AW8: 70812 | AX8: =(IF((AW8-AW7<0),"0",AW8-AW7)) -> 137 | AY8: 451550 | AZ8: =(IF((AY8-AY7<0),"0",AY8-AY7))*100 -> 156600 | BA8: =AZ8*$AZ$44*60% -> 427.518 | BB8: =BA8*0.4444 -> 189.989
A9: 44988 | B9: 185 | C9: 8832090 | D9: 21237180 | E9: 4022470 | F9: 4495990 | G9: 13448230 | H9: 8044910 | I9: 6918250 | J9: 8695480 | K9: 12535420 | L9: 5469100 | M9: 9854570 | N9: 16604080 | O9: 23486780 | Q9: =IF((C9-C8<0), "0",C9-C8) -> 520 | R9: =IF((D9-D8<0), "0",D9-D8) -> 1760 | S9: =IF((E9-E8<0), "0",E9-E8) -> 3230 | T9: =IF((F9-F8<0), "0",F9-F8) -> 910 | U9: =IF((G9-G8<0), "0",G9-G8) -> 6280 | V9: =IF((H9-H8<0), "0",H9-H8) -> 4070 | W9: =IF((I9-I8<0), "0",I9-I8) -> 3150 | X9: =IF((J9-J8<0), "0",J9-J8) -> 4150 | ... AC9: =IF((O9-O8<0), "0",O9-O8) -> 12900 | AD9: =SUM(Q9:AC9) -> 55710 | AF9: =Q9*$D$39 -> 2.6 | AG9: =R9*$D$39 -> 8.8 | AH9: =S9*$D$39 -> 16.15 | AI9: =T9*$D$39 -> 4.55 | AJ9: =U9*$D$39 -> 31.4 | AK9: =V9*$D$39 -> 20.35 | AL9: =W9*$D$39 -> 15.75 | AM9: =X9*$D$39 -> 20.75 | ... AR9: =AC9*$D$39 -> 64.5 | AS9: =SUM(AF9:AR9) -> 278.55 | AT9: 0 | AU9: =AT9*$AU$43 -> 0 | AW9: 70948 | AX9: =(IF((AW9-AW8<0),"0",AW9-AW8)) -> 136 | AY9: 453062 | AZ9: =(IF((AY9-AY8<0),"0",AY9-AY8))*100 -> 151200 | BA9: =AZ9*$AZ$44*60% -> 412.776 | BB9: =BA9*0.4444 -> 183.43765
A10: 44989 | B10: 119 | C10: 8832630 | D10: 21238990 | E10: 4025800 | F10: 4496930 | G10: 13454550 | H10: 8049040 | I10: 6921040 | J10: 8699690 | K10: 12541450 | L10: 5471710 | M10: 9857770 | N10: 16611390 | O10: 23500160 | Q10: =IF((C10-C9<0), "0",C10-C9) -> 540 | R10: =IF((D10-D9<0), "0",D10-D9) -> 1810 | S10: =IF((E10-E9<0), "0",E10-E9) -> 3330 | T10: =IF((F10-F9<0), "0",F10-F9) -> 940 | U10: =IF((G10-G9<0), "0",G10-G9) -> 6320 | V10: =IF((H10-H9<0), "0",H10-H9) -> 4130 | W10: =IF((I10-I9<0), "0",I10-I9) -> 2790 | X10: =IF((J10-J9<0), "0",J10-J9) -> 4210 | ... AC10: =IF((O10-O9<0), "0",O10-O9) -> 13380 | AD10: =SUM(Q10:AC10) -> 56600 | AF10: =Q10*$D$39 -> 2.7 | AG10: =R10*$D$39 -> 9.05 | AH10: =S10*$D$39 -> 16.65 | AI10: =T10*$D$39 -> 4.7 | AJ10: =U10*$D$39 -> 31.6 | AK10: =V10*$D$39 -> 20.65 | AL10: =W10*$D$39 -> 13.95 | AM10: =X10*$D$39 -> 21.05 | ... AR10: =AC10*$D$39 -> 66.9 | AS10: =SUM(AF10:AR10) -> 283 | AT10: 7.2 | AU10: =AT10*$AU$43 -> 1282.5 | AW10: 71083 | AX10: =(IF((AW10-AW9<0),"0",AW10-AW9)) -> 135 | AY10: 454637 | AZ10: =(IF((AY10-AY9<0),"0",AY10-AY9))*100 -> 157500 | BA10: =AZ10*$AZ$44*60% -> 429.975 | BB10: =BA10*0.4444 -> 191.08089
A11: 44990 | B11: 110 | C11: 8833290 | D11: 21240890 | E11: 4029110 | F11: 4497920 | G11: 13460380 | H11: 8053240 | I11: 6924080 | J11: 8703600 | K11: 12547440 | L11: 5474220 | M11: 9860940 | N11: 16618890 | O11: 23512450 | Q11: =IF((C11-C10<0), "0",C11-C10) -> 660 | R11: =IF((D11-D10<0), "0",D11-D10) -> 1900 | S11: =IF((E11-E10<0), "0",E11-E10) -> 3310 | T11: =IF((F11-F10<0), "0",F11-F10) -> 990 | U11: =IF((G11-G10<0), "0",G11-G10) -> 5830 | V11: =IF((H11-H10<0), "0",H11-H10) -> 4200 | W11: =IF((I11-I10<0), "0",I11-I10) -> 3040 | X11: =IF((J11-J10<0), "0",J11-J10) -> 3910 | ... AC11: =IF((O11-O10<0), "0",O11-O10) -> 12290 | AD11: =SUM(Q11:AC11) -> 55300 | AF11: =Q11*$D$39 -> 3.3 | AG11: =R11*$D$39 -> 9.5 | AH11: =S11*$D$39 -> 16.55 | AI11: =T11*$D$39 -> 4.95 | AJ11: =U11*$D$39 -> 29.15 | AK11: =V11*$D$39 -> 21 | AL11: =W11*$D$39 -> 15.2 | AM11: =X11*$D$39 -> 19.55 | ... AR11: =AC11*$D$39 -> 61.45 | AS11: =SUM(AF11:AR11) -> 276.5 | AT11: 0 | AU11: =AT11*$AU$43 -> 0 | AW11: 71214 | AX11: =(IF((AW11-AW10<0),"0",AW11-AW10)) -> 131 | AY11: 456242 | AZ11: =(IF((AY11-AY10<0),"0",AY11-AY10))*100 -> 160500 | BA11: =AZ11*$AZ$44*60% -> 438.165 | BB11: =BA11*0.4444 -> 194.72053
A12: 44991 | B12: 137 | C12: 8833720 | D12: 21242660 | E12: 4032260 | F12: 4498840 | G12: 13466040 | H12: 8057150 | I12: 6927110 | J12: 8707640 | K12: 12552880 | L12: 5476540 | M12: 9863880 | N12: 16625990 | O12: 23524030 | Q12: =IF((C12-C11<0), "0",C12-C11) -> 430 | R12: =IF((D12-D11<0), "0",D12-D11) -> 1770 | S12: =IF((E12-E11<0), "0",E12-E11) -> 3150 | T12: =IF((F12-F11<0), "0",F12-F11) -> 920 | U12: =IF((G12-G11<0), "0",G12-G11) -> 5660 | V12: =IF((H12-H11<0), "0",H12-H11) -> 3910 | W12: =IF((I12-I11<0), "0",I12-I11) -> 3030 | X12: =IF((J12-J11<0), "0",J12-J11) -> 4040 | ... AC12: =IF((O12-O11<0), "0",O12-O11) -> 11580 | AD12: =SUM(Q12:AC12) -> 52290 | AF12: =Q12*$D$39 -> 2.15 | AG12: =R12*$D$39 -> 8.85 | AH12: =S12*$D$39 -> 15.75 | AI12: =T12*$D$39 -> 4.6 | AJ12: =U12*$D$39 -> 28.3 | AK12: =V12*$D$39 -> 19.55 | AL12: =W12*$D$39 -> 15.15 | AM12: =X12*$D$39 -> 20.2 | ... AR12: =AC12*$D$39 -> 57.9 | AS12: =SUM(AF12:AR12) -> 261.45 | AT12: 3.5 | AU12: =AT12*$AU$43 -> 623.4375 | AW12: 71345 | AX12: =(IF((AW12-AW11<0),"0",AW12-AW11)) -> 131 | AY12: 457795 | AZ12: =(IF((AY12-AY11<0),"0",AY12-AY11))*100 -> 155300 | BA12: =AZ12*$AZ$44*60% -> 423.969 | BB12: =BA12*0.4444 -> 188.41182
A13: 44992 | B13: 149 | C13: 8834280 | D13: 21244530 | E13: 4035800 | F13: 4499820 | G13: 13472180 | H13: 8061390 | I13: 6930350 | J13: 8711850 | K13: 12558780 | L13: 5479050 | M13: 9866920 | N13: 16633570 | O13: 23536630 | Q13: =IF((C13-C12<0), "0",C13-C12) -> 560 | R13: =IF((D13-D12<0), "0",D13-D12) -> 1870 | S13: =IF((E13-E12<0), "0",E13-E12) -> 3540 | T13: =IF((F13-F12<0), "0",F13-F12) -> 980 | U13: =IF((G13-G12<0), "0",G13-G12) -> 6140 | V13: =IF((H13-H12<0), "0",H13-H12) -> 4240 | W13: =IF((I13-I12<0), "0",I13-I12) -> 3240 | X13: =IF((J13-J12<0), "0",J13-J12) -> 4210 | ... AC13: =IF((O13-O12<0), "0",O13-O12) -> 12600 | AD13: =SUM(Q13:AC13) -> 56410 | AF13: =Q13*$D$39 -> 2.8 | AG13: =R13*$D$39 -> 9.35 | AH13: =S13*$D$39 -> 17.7 | AI13: =T13*$D$39 -> 4.9 | AJ13: =U13*$D$39 -> 30.7 | AK13: =V13*$D$39 -> 21.2 | AL13: =W13*$D$39 -> 16.2 | AM13: =X13*$D$39 -> 21.05 | ... AR13: =AC13*$D$39 -> 63 | AS13: =SUM(AF13:AR13) -> 282.05 | AT13: 0 | AU13: =AT13*$AU$43 -> 0 | AW13: 71474 | AX13: =(IF((AW13-AW12<0),"0",AW13-AW12)) -> 129 | AY13: 459440 | AZ13: =(IF((AY13-AY12<0),"0",AY13-AY12))*100 -> 164500 | BA13: =AZ13*$AZ$44*60% -> 449.085 | BB13: =BA13*0.4444 -> 199.57337
A14: 44993 | Q14: =IF((C14-C13<0), "0",C14-C13) -> 0 | R14: =IF((D14-D13<0), "0",D14-D13) -> 0 | S14: =IF((E14-E13<0), "0",E14-E13) -> 0 | T14: =IF((F14-F13<0), "0",F14-F13) -> 0 | U14: =IF((G14-G13<0), "0",G14-G13) -> 0 | V14: =IF((H14-H13<0), "0",H14-H13) -> 0 | W14: =IF((I14-I13<0), "0",I14-I13) -> 0 | X14: =IF((J14-J13<0), "0",J14-J13) -> 0 | ... AC14: =IF((O14-O13<0), "0",O14-O13) -> 0 | AD14: =SUM(Q14:AC14) -> 0 | AF14: =Q14*$D$39 -> 0 | AG14: =R14*$D$39 -> 0 | AH14: =S14*$D$39 -> 0 | AI14: =T14*$D$39 -> 0 | AJ14: =U14*$D$39 -> 0 | AK14: =V14*$D$39 -> 0 | AL14: =W14*$D$39 -> 0 | AM14: =X14*$D$39 -> 0 | ... AR14: =AC14*$D$39 -> 0 | AS14: =SUM(AF14:AR14) -> 0 | AU14: =AT14*$AU$43 -> 0 | AX14: =(IF((AW14-AW13<0),"0",AW14-AW13)) -> 0 | AZ14: =(IF((AY14-AY13<0),"0",AY14-AY13))*100 -> 0 | BA14: =AZ14*$AZ$44*60% -> 0 | BB14: =BA14*0.4444 -> 0
A15: 44994 | Q15: =IF((C15-C14<0), "0",C15-C14) -> 0 | R15: =IF((D15-D14<0), "0",D15-D14) -> 0 | S15: =IF((E15-E14<0), "0",E15-E14) -> 0 | T15: =IF((F15-F14<0), "0",F15-F14) -> 0 | U15: =IF((G15-G14<0), "0",G15-G14) -> 0 | V15: =IF((H15-H14<0), "0",H15-H14) -> 0 | W15: =IF((I15-I14<0), "0",I15-I14) -> 0 | X15: =IF((J15-J14<0), "0",J15-J14) -> 0 | ... AC15: =IF((O15-O14<0), "0",O15-O14) -> 0 | AD15: =SUM(Q15:AC15) -> 0 | AF15: =Q15*$D$39 -> 0 | AG15: =R15*$D$39 -> 0 | AH15: =S15*$D$39 -> 0 | AI15: =T15*$D$39 -> 0 | AJ15: =U15*$D$39 -> 0 | AK15: =V15*$D$39 -> 0 | AL15: =W15*$D$39 -> 0 | AM15: =X15*$D$39 -> 0 | ... AR15: =AC15*$D$39 -> 0 | AS15: =SUM(AF15:AR15) -> 0 | AU15: =AT15*$AU$43 -> 0 | AX15: =(IF((AW15-AW14<0),"0",AW15-AW14)) -> 0 | AZ15: =(IF((AY15-AY14<0),"0",AY15-AY14))*100 -> 0 | BA15: =AZ15*$AZ$44*60% -> 0 | BB15: =BA15*0.4444 -> 0
A16: 44995 | Q16: =IF((C16-C15<0), "0",C16-C15) -> 0 | R16: =IF((D16-D15<0), "0",D16-D15) -> 0 | S16: =IF((E16-E15<0), "0",E16-E15) -> 0 | T16: =IF((F16-F15<0), "0",F16-F15) -> 0 | U16: =IF((G16-G15<0), "0",G16-G15) -> 0 | V16: =IF((H16-H15<0), "0",H16-H15) -> 0 | W16: =IF((I16-I15<0), "0",I16-I15) -> 0 | X16: =IF((J16-J15<0), "0",J16-J15) -> 0 | ... AC16: =IF((O16-O15<0), "0",O16-O15) -> 0 | AD16: =SUM(Q16:AC16) -> 0 | AF16: =Q16*$D$39 -> 0 | AG16: =R16*$D$39 -> 0 | AH16: =S16*$D$39 -> 0 | AI16: =T16*$D$39 -> 0 | AJ16: =U16*$D$39 -> 0 | AK16: =V16*$D$39 -> 0 | AL16: =W16*$D$39 -> 0 | AM16: =X16*$D$39 -> 0 | ... AR16: =AC16*$D$39 -> 0 | AS16: =SUM(AF16:AR16) -> 0 | AU16: =AT16*$AU$43 -> 0 | AX16: =(IF((AW16-AW15<0),"0",AW16-AW15)) -> 0 | AZ16: =(IF((AY16-AY15<0),"0",AY16-AY15))*100 -> 0 | BA16: =AZ16*$AZ$44*60% -> 0 | BB16: =BA16*0.4444 -> 0
A17: 44996 | Q17: =IF((C17-C16<0), "0",C17-C16) -> 0 | R17: =IF((D17-D16<0), "0",D17-D16) -> 0 | S17: =IF((E17-E16<0), "0",E17-E16) -> 0 | T17: =IF((F17-F16<0), "0",F17-F16) -> 0 | U17: =IF((G17-G16<0), "0",G17-G16) -> 0 | V17: =IF((H17-H16<0), "0",H17-H16) -> 0 | W17: =IF((I17-I16<0), "0",I17-I16) -> 0 | X17: =IF((J17-J16<0), "0",J17-J16) -> 0 | ... AC17: =IF((O17-O16<0), "0",O17-O16) -> 0 | AD17: =SUM(Q17:AC17) -> 0 | AF17: =Q17*$D$39 -> 0 | AG17: =R17*$D$39 -> 0 | AH17: =S17*$D$39 -> 0 | AI17: =T17*$D$39 -> 0 | AJ17: =U17*$D$39 -> 0 | AK17: =V17*$D$39 -> 0 | AL17: =W17*$D$39 -> 0 | AM17: =X17*$D$39 -> 0 | ... AR17: =AC17*$D$39 -> 0 | AS17: =SUM(AF17:AR17) -> 0 | AU17: =AT17*$AU$43 -> 0 | AX17: =(IF((AW17-AW16<0),"0",AW17-AW16)) -> 0 | AZ17: =(IF((AY17-AY16<0),"0",AY17-AY16))*100 -> 0 | BA17: =AZ17*$AZ$44*60% -> 0 | BB17: =BA17*0.4444 -> 0
A18: 44997 | Q18: =IF((C18-C17<0), "0",C18-C17) -> 0 | R18: =IF((D18-D17<0), "0",D18-D17) -> 0 | S18: =IF((E18-E17<0), "0",E18-E17) -> 0 | T18: =IF((F18-F17<0), "0",F18-F17) -> 0 | U18: =IF((G18-G17<0), "0",G18-G17) -> 0 | V18: =IF((H18-H17<0), "0",H18-H17) -> 0 | W18: =IF((I18-I17<0), "0",I18-I17) -> 0 | X18: =IF((J18-J17<0), "0",J18-J17) -> 0 | ... AC18: =IF((O18-O17<0), "0",O18-O17) -> 0 | AD18: =SUM(Q18:AC18) -> 0 | AF18: =Q18*$D$39 -> 0 | AG18: =R18*$D$39 -> 0 | AH18: =S18*$D$39 -> 0 | AI18: =T18*$D$39 -> 0 | AJ18: =U18*$D$39 -> 0 | AK18: =V18*$D$39 -> 0 | AL18: =W18*$D$39 -> 0 | AM18: =X18*$D$39 -> 0 | ... AR18: =AC18*$D$39 -> 0 | AS18: =SUM(AF18:AR18) -> 0 | AU18: =AT18*$AU$43 -> 0 | AX18: =(IF((AW18-AW17<0),"0",AW18-AW17)) -> 0 | AZ18: =(IF((AY18-AY17<0),"0",AY18-AY17))*100 -> 0 | BA18: =AZ18*$AZ$44*60% -> 0 | BB18: =BA18*0.4444 -> 0
A19: 44998 | Q19: =IF((C19-C18<0), "0",C19-C18) -> 0 | R19: =IF((D19-D18<0), "0",D19-D18) -> 0 | S19: =IF((E19-E18<0), "0",E19-E18) -> 0 | T19: =IF((F19-F18<0), "0",F19-F18) -> 0 | U19: =IF((G19-G18<0), "0",G19-G18) -> 0 | V19: =IF((H19-H18<0), "0",H19-H18) -> 0 | W19: =IF((I19-I18<0), "0",I19-I18) -> 0 | X19: =IF((J19-J18<0), "0",J19-J18) -> 0 | ... AC19: =IF((O19-O18<0), "0",O19-O18) -> 0 | AD19: =SUM(Q19:AC19) -> 0 | AF19: =Q19*$D$39 -> 0 | AG19: =R19*$D$39 -> 0 | AH19: =S19*$D$39 -> 0 | AI19: =T19*$D$39 -> 0 | AJ19: =U19*$D$39 -> 0 | AK19: =V19*$D$39 -> 0 | AL19: =W19*$D$39 -> 0 | AM19: =X19*$D$39 -> 0 | ... AR19: =AC19*$D$39 -> 0 | AS19: =SUM(AF19:AR19) -> 0 | AU19: =AT19*$AU$43 -> 0 | AX19: =(IF((AW19-AW18<0),"0",AW19-AW18)) -> 0 | AZ19: =(IF((AY19-AY18<0),"0",AY19-AY18))*100 -> 0 | BA19: =AZ19*$AZ$44*60% -> 0 | BB19: =BA19*0.4444 -> 0
A20: 44999 | Q20: =IF((C20-C19<0), "0",C20-C19) -> 0 | R20: =IF((D20-D19<0), "0",D20-D19) -> 0 | S20: =IF((E20-E19<0), "0",E20-E19) -> 0 | T20: =IF((F20-F19<0), "0",F20-F19) -> 0 | U20: =IF((G20-G19<0), "0",G20-G19) -> 0 | V20: =IF((H20-H19<0), "0",H20-H19) -> 0 | W20: =IF((I20-I19<0), "0",I20-I19) -> 0 | X20: =IF((J20-J19<0), "0",J20-J19) -> 0 | ... AC20: =IF((O20-O19<0), "0",O20-O19) -> 0 | AD20: =SUM(Q20:AC20) -> 0 | AF20: =Q20*$D$39 -> 0 | AG20: =R20*$D$39 -> 0 | AH20: =S20*$D$39 -> 0 | AI20: =T20*$D$39 -> 0 | AJ20: =U20*$D$39 -> 0 | AK20: =V20*$D$39 -> 0 | AL20: =W20*$D$39 -> 0 | AM20: =X20*$D$39 -> 0 | ... AR20: =AC20*$D$39 -> 0 | AS20: =SUM(AF20:AR20) -> 0 | AU20: =AT20*$AU$43 -> 0 | AX20: =(IF((AW20-AW19<0),"0",AW20-AW19)) -> 0 | AZ20: =(IF((AY20-AY19<0),"0",AY20-AY19))*100 -> 0 | BA20: =AZ20*$AZ$44*60% -> 0 | BB20: =BA20*0.4444 -> 0
A21: 45000 | Q21: =IF((C21-C20<0), "0",C21-C20) -> 0 | R21: =IF((D21-D20<0), "0",D21-D20) -> 0 | S21: =IF((E21-E20<0), "0",E21-E20) -> 0 | T21: =IF((F21-F20<0), "0",F21-F20) -> 0 | U21: =IF((G21-G20<0), "0",G21-G20) -> 0 | V21: =IF((H21-H20<0), "0",H21-H20) -> 0 | W21: =IF((I21-I20<0), "0",I21-I20) -> 0 | X21: =IF((J21-J20<0), "0",J21-J20) -> 0 | ... AC21: =IF((O21-O20<0), "0",O21-O20) -> 0 | AD21: =SUM(Q21:AC21) -> 0 | AF21: =Q21*$D$39 -> 0 | AG21: =R21*$D$39 -> 0 | AH21: =S21*$D$39 -> 0 | AI21: =T21*$D$39 -> 0 | AJ21: =U21*$D$39 -> 0 | AK21: =V21*$D$39 -> 0 | AL21: =W21*$D$39 -> 0 | AM21: =X21*$D$39 -> 0 | ... AR21: =AC21*$D$39 -> 0 | AS21: =SUM(AF21:AR21) -> 0 | AU21: =AT21*$AU$43 -> 0 | AX21: =(IF((AW21-AW20<0),"0",AW21-AW20)) -> 0 | AZ21: =(IF((AY21-AY20<0),"0",AY21-AY20))*100 -> 0 | BA21: =AZ21*$AZ$44*60% -> 0 | BB21: =BA21*0.4444 -> 0
A22: 45001 | Q22: =IF((C22-C21<0), "0",C22-C21) -> 0 | R22: =IF((D22-D21<0), "0",D22-D21) -> 0 | S22: =IF((E22-E21<0), "0",E22-E21) -> 0 | T22: =IF((F22-F21<0), "0",F22-F21) -> 0 | U22: =IF((G22-G21<0), "0",G22-G21) -> 0 | V22: =IF((H22-H21<0), "0",H22-H21) -> 0 | W22: =IF((I22-I21<0), "0",I22-I21) -> 0 | X22: =IF((J22-J21<0), "0",J22-J21) -> 0 | ... AC22: =IF((O22-O21<0), "0",O22-O21) -> 0 | AD22: =SUM(Q22:AC22) -> 0 | AF22: =Q22*$D$39 -> 0 | AG22: =R22*$D$39 -> 0 | AH22: =S22*$D$39 -> 0 | AI22: =T22*$D$39 -> 0 | AJ22: =U22*$D$39 -> 0 | AK22: =V22*$D$39 -> 0 | AL22: =W22*$D$39 -> 0 | AM22: =X22*$D$39 -> 0 | ... AR22: =AC22*$D$39 -> 0 | AS22: =SUM(AF22:AR22) -> 0 | AU22: =AT22*$AU$43 -> 0 | AX22: =(IF((AW22-AW21<0),"0",AW22-AW21)) -> 0 | AZ22: =(IF((AY22-AY21<0),"0",AY22-AY21))*100 -> 0 | BA22: =AZ22*$AZ$44*60% -> 0 | BB22: =BA22*0.4444 -> 0
A23: 45002 | Q23: =IF((C23-C22<0), "0",C23-C22) -> 0 | R23: =IF((D23-D22<0), "0",D23-D22) -> 0 | S23: =IF((E23-E22<0), "0",E23-E22) -> 0 | T23: =IF((F23-F22<0), "0",F23-F22) -> 0 | U23: =IF((G23-G22<0), "0",G23-G22) -> 0 | V23: =IF((H23-H22<0), "0",H23-H22) -> 0 | W23: =IF((I23-I22<0), "0",I23-I22) -> 0 | X23: =IF((J23-J22<0), "0",J23-J22) -> 0 | ... AC23: =IF((O23-O22<0), "0",O23-O22) -> 0 | AD23: =SUM(Q23:AC23) -> 0 | AF23: =Q23*$D$39 -> 0 | AG23: =R23*$D$39 -> 0 | AH23: =S23*$D$39 -> 0 | AI23: =T23*$D$39 -> 0 | AJ23: =U23*$D$39 -> 0 | AK23: =V23*$D$39 -> 0 | AL23: =W23*$D$39 -> 0 | AM23: =X23*$D$39 -> 0 | ... AR23: =AC23*$D$39 -> 0 | AS23: =SUM(AF23:AR23) -> 0 | AU23: =AT23*$AU$43 -> 0 | AX23: =(IF((AW23-AW22<0),"0",AW23-AW22)) -> 0 | AZ23: =(IF((AY23-AY22<0),"0",AY23-AY22))*100 -> 0 | BA23: =AZ23*$AZ$44*60% -> 0 | BB23: =BA23*0.4444 -> 0
A24: 45003 | Q24: =IF((C24-C23<0), "0",C24-C23) -> 0 | R24: =IF((D24-D23<0), "0",D24-D23) -> 0 | S24: =IF((E24-E23<0), "0",E24-E23) -> 0 | T24: =IF((F24-F23<0), "0",F24-F23) -> 0 | U24: =IF((G24-G23<0), "0",G24-G23) -> 0 | V24: =IF((H24-H23<0), "0",H24-H23) -> 0 | W24: =IF((I24-I23<0), "0",I24-I23) -> 0 | X24: =IF((J24-J23<0), "0",J24-J23) -> 0 | ... AC24: =IF((O24-O23<0), "0",O24-O23) -> 0 | AD24: =SUM(Q24:AC24) -> 0 | AF24: =Q24*$D$39 -> 0 | AG24: =R24*$D$39 -> 0 | AH24: =S24*$D$39 -> 0 | AI24: =T24*$D$39 -> 0 | AJ24: =U24*$D$39 -> 0 | AK24: =V24*$D$39 -> 0 | AL24: =W24*$D$39 -> 0 | AM24: =X24*$D$39 -> 0 | ... AR24: =AC24*$D$39 -> 0 | AS24: =SUM(AF24:AR24) -> 0 | AU24: =AT24*$AU$43 -> 0 | AX24: =(IF((AW24-AW23<0),"0",AW24-AW23)) -> 0 | AZ24: =(IF((AY24-AY23<0),"0",AY24-AY23))*100 -> 0 | BA24: =AZ24*$AZ$44*60% -> 0 | BB24: =BA24*0.4444 -> 0
A25: 45004 | Q25: =IF((C25-C24<0), "0",C25-C24) -> 0 | R25: =IF((D25-D24<0), "0",D25-D24) -> 0 | S25: =IF((E25-E24<0), "0",E25-E24) -> 0 | T25: =IF((F25-F24<0), "0",F25-F24) -> 0 | U25: =IF((G25-G24<0), "0",G25-G24) -> 0 | V25: =IF((H25-H24<0), "0",H25-H24) -> 0 | W25: =IF((I25-I24<0), "0",I25-I24) -> 0 | X25: =IF((J25-J24<0), "0",J25-J24) -> 0 | ... AC25: =IF((O25-O24<0), "0",O25-O24) -> 0 | AD25: =SUM(Q25:AC25) -> 0 | AF25: =Q25*$D$39 -> 0 | AG25: =R25*$D$39 -> 0 | AH25: =S25*$D$39 -> 0 | AI25: =T25*$D$39 -> 0 | AJ25: =U25*$D$39 -> 0 | AK25: =V25*$D$39 -> 0 | AL25: =W25*$D$39 -> 0 | AM25: =X25*$D$39 -> 0 | ... AR25: =AC25*$D$39 -> 0 | AS25: =SUM(AF25:AR25) -> 0 | AU25: =AT25*$AU$43 -> 0 | AX25: =(IF((AW25-AW24<0),"0",AW25-AW24)) -> 0 | AZ25: =(IF((AY25-AY24<0),"0",AY25-AY24))*100 -> 0 | BA25: =AZ25*$AZ$44*60% -> 0 | BB25: =BA25*0.4444 -> 0
... A28: 45007 | Q28: =IF((C28-C27<0), "0",C28-C27) -> 0 | R28: =IF((D28-D27<0), "0",D28-D27) -> 0 | S28: =IF((E28-E27<0), "0",E28-E27) -> 0 | T28: =IF((F28-F27<0), "0",F28-F27) -> 0 | U28: =IF((G28-G27<0), "0",G28-G27) -> 0 | V28: =IF((H28-H27<0), "0",H28-H27) -> 0 | W28: =IF((I28-I27<0), "0",I28-I27) -> 0 | X28: =IF((J28-J27<0), "0",J28-J27) -> 0 | ... AC28: =IF((O28-O27<0), "0",O28-O27) -> 0 | AD28: =SUM(Q28:AC28) -> 0 | AF28: =Q28*$D$39 -> 0 | AG28: =R28*$D$39 -> 0 | AH28: =S28*$D$39 -> 0 | AI28: =T28*$D$39 -> 0 | AJ28: =U28*$D$39 -> 0 | AK28: =V28*$D$39 -> 0 | AL28: =W28*$D$39 -> 0 | AM28: =X28*$D$39 -> 0 | ... AR28: =AC28*$D$39 -> 0 | AS28: =SUM(AF28:AR28) -> 0 | AU28: =AT28*$AU$43 -> 0 | AX28: =(IF((AW28-AW27<0),"0",AW28-AW27)) -> 0 | AZ28: =(IF((AY28-AY27<0),"0",AY28-AY27))*100 -> 0 | BA28: =AZ28*$AZ$44*60% -> 0 | BB28: =BA28*0.4444 -> 0
A29: 45008 | P29: 441854 | Q29: =IF((C29-C28<0), "0",C29-C28) -> 0 | R29: =IF((D29-D28<0), "0",D29-D28) -> 0 | S29: =IF((E29-E28<0), "0",E29-E28) -> 0 | T29: =IF((F29-F28<0), "0",F29-F28) -> 0 | U29: =IF((G29-G28<0), "0",G29-G28) -> 0 | V29: =IF((H29-H28<0), "0",H29-H28) -> 0 | W29: =IF((I29-I28<0), "0",I29-I28) -> 0 | X29: =IF((J29-J28<0), "0",J29-J28) -> 0 | ... AC29: =IF((O29-O28<0), "0",O29-O28) -> 0 | AD29: =SUM(Q29:AC29) -> 0 | AF29: =Q29*$D$39 -> 0 | AG29: =R29*$D$39 -> 0 | AH29: =S29*$D$39 -> 0 | AI29: =T29*$D$39 -> 0 | AJ29: =U29*$D$39 -> 0 | AK29: =V29*$D$39 -> 0 | AL29: =W29*$D$39 -> 0 | AM29: =X29*$D$39 -> 0 | ... AR29: =AC29*$D$39 -> 0 | AS29: =SUM(AF29:AR29) -> 0 | AU29: =AT29*$AU$43 -> 0 | AX29: =(IF((AW29-AW28<0),"0",AW29-AW28)) -> 0 | AZ29: =(IF((AY29-AY28<0),"0",AY29-AY28))*100 -> 0 | BA29: =AZ29*$AZ$44*60% -> 0 | BB29: =BA29*0.4444 -> 0
A30: 45009 | Q30: =IF((C30-C29<0), "0",C30-C29) -> 0 | R30: =IF((D30-D29<0), "0",D30-D29) -> 0 | S30: =IF((E30-E29<0), "0",E30-E29) -> 0 | T30: =IF((F30-F29<0), "0",F30-F29) -> 0 | U30: =IF((G30-G29<0), "0",G30-G29) -> 0 | V30: =IF((H30-H29<0), "0",H30-H29) -> 0 | W30: =IF((I30-I29<0), "0",I30-I29) -> 0 | X30: =IF((J30-J29<0), "0",J30-J29) -> 0 | ... AC30: =IF((O30-O29<0), "0",O30-O29) -> 0 | AD30: =SUM(Q30:AC30) -> 0 | AF30: =Q30*$D$39 -> 0 | AG30: =R30*$D$39 -> 0 | AH30: =S30*$D$39 -> 0 | AI30: =T30*$D$39 -> 0 | AJ30: =U30*$D$39 -> 0 | AK30: =V30*$D$39 -> 0 | AL30: =W30*$D$39 -> 0 | AM30: =X30*$D$39 -> 0 | ... AR30: =AC30*$D$39 -> 0 | AS30: =SUM(AF30:AR30) -> 0 | AU30: =AT30*$AU$43 -> 0 | AX30: =(IF((AW30-AW29<0),"0",AW30-AW29)) -> 0 | AZ30: =(IF((AY30-AY29<0),"0",AY30-AY29))*100 -> 0 | BA30: =AZ30*$AZ$44*60% -> 0 | BB30: =BA30*0.4444 -> 0
A31: 45010 | Q31: =IF((C31-C30<0), "0",C31-C30) -> 0 | R31: =IF((D31-D30<0), "0",D31-D30) -> 0 | S31: =IF((E31-E30<0), "0",E31-E30) -> 0 | T31: =IF((F31-F30<0), "0",F31-F30) -> 0 | U31: =IF((G31-G30<0), "0",G31-G30) -> 0 | V31: =IF((H31-H30<0), "0",H31-H30) -> 0 | W31: =IF((I31-I30<0), "0",I31-I30) -> 0 | X31: =IF((J31-J30<0), "0",J31-J30) -> 0 | ... AC31: =IF((O31-O30<0), "0",O31-O30) -> 0 | AD31: =SUM(Q31:AC31) -> 0 | AF31: =Q31*$D$39 -> 0 | AG31: =R31*$D$39 -> 0 | AH31: =S31*$D$39 -> 0 | AI31: =T31*$D$39 -> 0 | AJ31: =U31*$D$39 -> 0 | AK31: =V31*$D$39 -> 0 | AL31: =W31*$D$39 -> 0 | AM31: =X31*$D$39 -> 0 | ... AR31: =AC31*$D$39 -> 0 | AS31: =SUM(AF31:AR31) -> 0 | AU31: =AT31*$AU$43 -> 0 | AX31: =(IF((AW31-AW30<0),"0",AW31-AW30)) -> 0 | AZ31: =(IF((AY31-AY30<0),"0",AY31-AY30))*100 -> 0 | BA31: =AZ31*$AZ$44*60% -> 0 | BB31: =BA31*0.4444 -> 0
A32: 45011 | Q32: =IF((C32-C31<0), "0",C32-C31) -> 0 | R32: =IF((D32-D31<0), "0",D32-D31) -> 0 | S32: =IF((E32-E31<0), "0",E32-E31) -> 0 | T32: =IF((F32-F31<0), "0",F32-F31) -> 0 | U32: =IF((G32-G31<0), "0",G32-G31) -> 0 | V32: =IF((H32-H31<0), "0",H32-H31) -> 0 | W32: =IF((I32-I31<0), "0",I32-I31) -> 0 | X32: =IF((J32-J31<0), "0",J32-J31) -> 0 | ... AC32: =IF((O32-O31<0), "0",O32-O31) -> 0 | AD32: =SUM(Q32:AC32) -> 0 | AF32: =Q32*$D$39 -> 0 | AG32: =R32*$D$39 -> 0 | AH32: =S32*$D$39 -> 0 | AI32: =T32*$D$39 -> 0 | AJ32: =U32*$D$39 -> 0 | AK32: =V32*$D$39 -> 0 | AL32: =W32*$D$39 -> 0 | AM32: =X32*$D$39 -> 0 | ... AR32: =AC32*$D$39 -> 0 | AS32: =SUM(AF32:AR32) -> 0 | AU32: =AT32*$AU$43 -> 0 | AX32: =(IF((AW32-AW31<0),"0",AW32-AW31)) -> 0 | AZ32: =(IF((AY32-AY31<0),"0",AY32-AY31))*100 -> 0 | BA32: =AZ32*$AZ$44*60% -> 0 | BB32: =BA32*0.4444 -> 0
A33: 45012 | Q33: =IF((C33-C32<0), "0",C33-C32) -> 0 | R33: =IF((D33-D32<0), "0",D33-D32) -> 0 | S33: =IF((E33-E32<0), "0",E33-E32) -> 0 | T33: =IF((F33-F32<0), "0",F33-F32) -> 0 | U33: =IF((G33-G32<0), "0",G33-G32) -> 0 | V33: =IF((H33-H32<0), "0",H33-H32) -> 0 | W33: =IF((I33-I32<0), "0",I33-I32) -> 0 | X33: =IF((J33-J32<0), "0",J33-J32) -> 0 | ... AC33: =IF((O33-O32<0), "0",O33-O32) -> 0 | AD33: =SUM(Q33:AC33) -> 0 | AF33: =Q33*$D$39 -> 0 | AG33: =R33*$D$39 -> 0 | AH33: =S33*$D$39 -> 0 | AI33: =T33*$D$39 -> 0 | AJ33: =U33*$D$39 -> 0 | AK33: =V33*$D$39 -> 0 | AL33: =W33*$D$39 -> 0 | AM33: =X33*$D$39 -> 0 | ... AR33: =AC33*$D$39 -> 0 | AS33: =SUM(AF33:AR33) -> 0 | AU33: =AT33*$AU$43 -> 0 | AX33: =(IF((AW33-AW32<0),"0",AW33-AW32)) -> 0 | AZ33: =(IF((AY33-AY32<0),"0",AY33-AY32))*100 -> 0 | BA33: =AZ33*$AZ$44*60% -> 0 | BB33: =BA33*0.4444 -> 0
A34: 45013 | Q34: =IF((C34-C33<0), "0",C34-C33) -> 0 | R34: =IF((D34-D33<0), "0",D34-D33) -> 0 | S34: =IF((E34-E33<0), "0",E34-E33) -> 0 | T34: =IF((F34-F33<0), "0",F34-F33) -> 0 | U34: =IF((G34-G33<0), "0",G34-G33) -> 0 | V34: =IF((H34-H33<0), "0",H34-H33) -> 0 | W34: =IF((I34-I33<0), "0",I34-I33) -> 0 | X34: =IF((J34-J33<0), "0",J34-J33) -> 0 | ... AC34: =IF((O34-O33<0), "0",O34-O33) -> 0 | AD34: =SUM(Q34:AC34) -> 0 | AF34: =Q34*$D$39 -> 0 | AG34: =R34*$D$39 -> 0 | AH34: =S34*$D$39 -> 0 | AI34: =T34*$D$39 -> 0 | AJ34: =U34*$D$39 -> 0 | AK34: =V34*$D$39 -> 0 | AL34: =W34*$D$39 -> 0 | AM34: =X34*$D$39 -> 0 | ... AR34: =AC34*$D$39 -> 0 | AS34: =SUM(AF34:AR34) -> 0 | AU34: =AT34*$AU$43 -> 0 | AX34: =(IF((AW34-AW33<0),"0",AW34-AW33)) -> 0 | AZ34: =(IF((AY34-AY33<0),"0",AY34-AY33))*100 -> 0 | BA34: =AZ34*$AZ$44*60% -> 0 | BB34: =BA34*0.4444 -> 0
A35: 45014 | Q35: =IF((C35-C34<0), "0",C35-C34) -> 0 | R35: =IF((D35-D34<0), "0",D35-D34) -> 0 | S35: =IF((E35-E34<0), "0",E35-E34) -> 0 | T35: =IF((F35-F34<0), "0",F35-F34) -> 0 | U35: =IF((G35-G34<0), "0",G35-G34) -> 0 | V35: =IF((H35-H34<0), "0",H35-H34) -> 0 | W35: =IF((I35-I34<0), "0",I35-I34) -> 0 | X35: =IF((J35-J34<0), "0",J35-J34) -> 0 | ... AC35: =IF((O35-O34<0), "0",O35-O34) -> 0 | AD35: =SUM(Q35:AC35) -> 0 | AF35: =Q35*$D$39 -> 0 | AG35: =R35*$D$39 -> 0 | AH35: =S35*$D$39 -> 0 | AI35: =T35*$D$39 -> 0 | AJ35: =U35*$D$39 -> 0 | AK35: =V35*$D$39 -> 0 | AL35: =W35*$D$39 -> 0 | AM35: =X35*$D$39 -> 0 | ... AR35: =AC35*$D$39 -> 0 | AS35: =SUM(AF35:AR35) -> 0 | AU35: =AT35*$AU$43 -> 0 | AW35: 0 | AX35: =(IF((AW35-AW34<0),"0",AW35-AW34)) -> 0 | AZ35: =(IF((AY35-AY34<0),"0",AY35-AY34))*100 -> 0 | BA35: =AZ35*$AZ$44*60% -> 0 | BB35: =BA35*0.4444 -> 0
A36: 45015 | Q36: =IF((C36-C35<0), "0",C36-C35) -> 0 | R36: =IF((D36-D35<0), "0",D36-D35) -> 0 | S36: =IF((E36-E35<0), "0",E36-E35) -> 0 | T36: =IF((F36-F35<0), "0",F36-F35) -> 0 | U36: =IF((G36-G35<0), "0",G36-G35) -> 0 | V36: =IF((H36-H35<0), "0",H36-H35) -> 0 | W36: =IF((I36-I35<0), "0",I36-I35) -> 0 | X36: =IF((J36-J35<0), "0",J36-J35) -> 0 | ... AC36: =IF((O36-O35<0), "0",O36-O35) -> 0 | AD36: =SUM(Q36:AC36) -> 0 | AF36: =Q36*$D$39 -> 0 | AG36: =R36*$D$39 -> 0 | AH36: =S36*$D$39 -> 0 | AI36: =T36*$D$39 -> 0 | AJ36: =U36*$D$39 -> 0 | AK36: =V36*$D$39 -> 0 | AL36: =W36*$D$39 -> 0 | AM36: =X36*$D$39 -> 0 | ... AR36: =AC36*$D$39 -> 0 | AS36: =SUM(AF36:AR36) -> 0 | AU36: =AT36*$AU$43 -> 0 | AW36: 0 | AX36: =(IF((AW36-AW35<0),"0",AW36-AW35)) -> 0 | AZ36: =(IF((AY36-AY35<0),"0",AY36-AY35))*100 -> 0 | BA36: =AZ36*$AZ$44*60% -> 0 | BB36: =BA36*0.4444 -> 0
A37: 45016 | Q37: =IF((C37-C36<0), "0",C37-C36) -> 0 | R37: =IF((D37-D36<0), "0",D37-D36) -> 0 | S37: =IF((E37-E36<0), "0",E37-E36) -> 0 | T37: =IF((F37-F36<0), "0",F37-F36) -> 0 | U37: =IF((G37-G36<0), "0",G37-G36) -> 0 | V37: =IF((H37-H36<0), "0",H37-H36) -> 0 | W37: =IF((I37-I36<0), "0",I37-I36) -> 0 | X37: =IF((J37-J36<0), "0",J37-J36) -> 0 | ... AC37: =IF((O37-O36<0), "0",O37-O36) -> 0 | AD37: =SUM(Q37:AC37) -> 0 | AF37: =Q37*$D$39 -> 0 | AG37: =R37*$D$39 -> 0 | AH37: =S37*$D$39 -> 0 | AI37: =T37*$D$39 -> 0 | AJ37: =U37*$D$39 -> 0 | AK37: =V37*$D$39 -> 0 | AL37: =W37*$D$39 -> 0 | AM37: =X37*$D$39 -> 0 | ... AR37: =AC37*$D$39 -> 0 | AS37: =SUM(AF37:AR37) -> 0 | AU37: =AT37*$AU$43 -> 0 | AW37: 0 | AX37: =(IF((AW37-AW36<0),"0",AW37-AW36)) -> 0 | AZ37: =(IF((AY37-AY36<0),"0",AY37-AY36))*100 -> 0 | BA37: =AZ37*$AZ$44*60% -> 0 | BB37: =BA37*0.4444 -> 0
Q38: =SUM(Q7:Q37) -> 3830 | R38: =SUM(R7:R37) -> 12890 | S38: =SUM(S7:S37) -> 22830 | T38: =SUM(T7:T37) -> 6700 | U38: =SUM(U7:U37) -> 42110 | V38: =SUM(V7:V37) -> 29050 | W38: =SUM(W7:W37) -> 21610 | X38: =SUM(X7:X37) -> 28810 | ... AD38: =SUM(AD7:AD37) -> 387430 | AF38: =SUM(AF7:AF37) -> 19.15 | AG38: =SUM(AG7:AG37) -> 64.45 | AH38: =SUM(AH7:AH37) -> 114.15 | AI38: =SUM(AI7:AI37) -> 33.5 | AJ38: =SUM(AJ7:AJ37) -> 210.55 | AK38: =SUM(AK7:AK37) -> 145.25 | AL38: =SUM(AL7:AL37) -> 108.05 | AM38: =SUM(AM7:AM37) -> 144.05 | ... AS38: =SUM(AS7:AS37) -> 1937.15 | AU38: =SUM(AU7:AU37) -> 1941.5625 | AW38: 0 | AX38: =(IF((AW38-AW37<0),"0",AW38-AW37)) -> 0 | AZ38: =(IF((AY38-AY37<0),"0",AY38-AY37))*100 -> 0 | BA38: =SUM(BA7:BA37) -> 2944.578 | BB38: =BA38*0.4444 -> 1308.5705
B39: =SUM(B7:B37) -> 889 | D39: 0.005 | AW39: 0 | AX39: =(IF((AW39-AW38<0),"0",AW39-AW38)) -> 0 | BA39: =AZ39*$AZ$44*60% -> 0
D40: 0.002
AU43: 178.125
AW44: 0.528 | AY44: 0.528 | AZ44: 0.00455
AZ46: =0.002/4.5 -> 0.00044444444
...
