Workbook

Sheet TOTAL
A1: Site Name | B1: Day | C1: Month | D1: Year | E1: Total Electricity Kwh | F1: Electricity Tariff ($/Kwh) | G1: Natual Gas (m3) | H1: Natural Gas $/m3 | I1: Water Utility Supply (m3) m3 | J1: Water Utility Supply (m3) $/m3 | K1: Room Nights | L1: Total Guests
A2: Milan | B2: 1 | C2: 7 | D2: 2022 | E2: ='Hotel Data'!X11 -> 18330 | F2: 0.515 | G2: =INT('Hotel Data'!E11+'Hotel Data'!G11) -> 99 | H2: 2.07 | I2: =INT('Hotel Data'!I11) -> 292 | J2: 1.025 | K2: 98 | L2: 182
A3: Milan | B3: =B2+1 -> 2 | C3: 7 | D3: 2022 | E3: ='Hotel Data'!X12 -> 18303 | F3: 0.515 | G3: =INT('Hotel Data'!E12+'Hotel Data'!G12) -> 98 | H3: 2.07 | I3: =INT('Hotel Data'!I12) -> 298 | J3: 1.025 | K3: 85 | L3: 162
A4: Milan | B4: =B3+1 -> 3 | C4: 7 | D4: 2022 | E4: ='Hotel Data'!X13 -> 18693 | F4: 0.515 | G4: =INT('Hotel Data'!E13+'Hotel Data'!G13) -> 88 | H4: 2.07 | I4: =INT('Hotel Data'!I13) -> 285 | J4: 1.025 | K4: 81 | L4: 150
A5: Milan | B5: =B4+1 -> 4 | C5: 7 | D5: 2022 | E5: ='Hotel Data'!X14 -> 18537 | F5: 0.515 | G5: =INT('Hotel Data'!E14+'Hotel Data'!G14) -> 99 | H5: 2.07 | I5: =INT('Hotel Data'!I14) -> 291 | J5: 1.025 | K5: 84 | L5: 150
A6: Milan | B6: =B5+1 -> 5 | C6: 7 | D6: 2022 | E6: ='Hotel Data'!X15 -> 18942 | F6: 0.515 | G6: =INT('Hotel Data'!E15+'Hotel Data'!G15) -> 161 | H6: 2.07 | I6: =INT('Hotel Data'!I15) -> 289 | J6: 1.025 | K6: 82 | L6: 154
A7: Milan | B7: =B6+1 -> 6 | C7: 7 | D7: 2022 | E7: ='Hotel Data'!X16 -> 19281 | F7: 0.515 | G7: =INT('Hotel Data'!E16+'Hotel Data'!G16) -> 90 | H7: 2.07 | I7: =INT('Hotel Data'!I16) -> 300 | J7: 1.025 | K7: 89 | L7: 159
A8: Milan | B8: =B7+1 -> 7 | C8: 7 | D8: 2022 | E8: ='Hotel Data'!X17 -> 18253 | F8: 0.515 | G8: =INT('Hotel Data'!E17+'Hotel Data'!G17) -> 156 | H8: 2.07 | I8: =INT('Hotel Data'!I17) -> 296 | J8: 1.025 | K8: 96 | L8: 185
A9: Milan | B9: =B8+1 -> 8 | C9: 7 | D9: 2022 | E9: ='Hotel Data'!X18 -> 17264 | F9: 0.515 | G9: =INT('Hotel Data'!E18+'Hotel Data'!G18) -> 195 | H9: 2.07 | I9: =INT('Hotel Data'!I18) -> 278 | J9: 1.025 | K9: 92 | L9: 181
A10: Milan | B10: =B9+1 -> 9 | C10: 7 | D10: 2022 | E10: ='Hotel Data'!X19 -> 16850 | F10: 0.515 | G10: =INT('Hotel Data'!E19+'Hotel Data'!G19) -> 208 | H10: 2.07 | I10: =INT('Hotel Data'!I19) -> 286 | J10: 1.025 | K10: 91 | L10: 156
A11: Milan | B11: =B10+1 -> 10 | C11: 7 | D11: 2022 | E11: ='Hotel Data'!X20 -> 16285 | F11: 0.515 | G11: =INT('Hotel Data'!E20+'Hotel Data'!G20) -> 214 | H11: 2.07 | I11: =INT('Hotel Data'!I20) -> 257 | J11: 1.025 | K11: 91 | L11: 156
A12: Milan | B12: =B11+1 -> 11 | C12: 7 | D12: 2022 | E12: ='Hotel Data'!X21 -> 17500 | F12: 0.515 | G12: =INT('Hotel Data'!E21+'Hotel Data'!G21) -> 170 | H12: 2.07 | I12: =INT('Hotel Data'!I21) -> 274 | J12: 1.025 | K12: 94 | L12: 147
A13: Milan | B13: =B12+1 -> 12 | C13: 7 | D13: 2022 | E13: ='Hotel Data'!X22 -> 18025 | F13: 0.515 | G13: =INT('Hotel Data'!E22+'Hotel Data'!G22) -> 100 | H13: 2.07 | I13: =INT('Hotel Data'!I22) -> 263 | J13: 1.025 | K13: 96 | L13: 174
A14: Milan | B14: =B13+1 -> 13 | C14: 7 | D14: 2022 | E14: ='Hotel Data'!X23 -> 18014 | F14: 0.515 | G14: =INT('Hotel Data'!E23+'Hotel Data'!G23) -> 100 | H14: 2.07 | I14: =INT('Hotel Data'!I23) -> 204 | J14: 1.025 | K14: 89 | L14: 172
... A32: Milan | B32: =B31+1 -> 31 | C32: 7 | D32: 2022 | E32: ='Hotel Data'!X41 -> 16886 | F32: 0.515 | G32: =INT('Hotel Data'!E41+'Hotel Data'!G41) -> 212 | H32: 2.07 | I32: =INT('Hotel Data'!I41) -> 286 | J32: 1.025 | K32: 90 | L32: 169

Sheet Submetering 
A1: Site Name | B1: Day | C1: Month | D1: Year | E1: GAS RISCALD.(m3) | F1: GAS CUCINA (m3) | G1: H2O CONDIZION.ADD (m3) | H1: REINT. H2O ADD (m3) | I1: H2O ADD F CUC P (m3) | J1: H2O SANIT. CALDA (m3) | K1: ENEL CUC.PRINC. P (KWh) | L1: ENEL CUC.PRINC. N. (KWh) | M1: ENEL CUC.PREP. (KWh) | N1: ENEL CUC.VERANDA (KWh) | O1: ENEL LAVANDERIA (KWh) | P1: Room Nights
A2: Milan | B2: 1 | C2: 7 | D2: 2022 | E2: ='Hotel Data'!E11 -> 99 | F2: ='Hotel Data'!G11 -> 0 | G2: ='Hotel Data'!O11 -> 83 | H2: ='Hotel Data'!Q11 -> 34 | I2: ='Hotel Data'!S11 -> 0 | J2: ='Hotel Data'!U11 -> 61 | K2: ='Hotel Data'!AD11 -> 327 | L2: ='Hotel Data'!AG11 -> 1157 | M2: ='Hotel Data'!AJ11 -> 160 | N2: ='Hotel Data'!AN11 -> 501 | O2: ='Hotel Data'!AR11 -> 320 | P2: =TOTAL!K2 -> 98
A3: Milan | B3: =B2+1 -> 2 | C3: 7 | D3: 2022 | E3: ='Hotel Data'!E12 -> 97 | F3: ='Hotel Data'!G12 -> 1 | G3: ='Hotel Data'!O12 -> 92 | H3: ='Hotel Data'!Q12 -> 41 | I3: ='Hotel Data'!S12 -> 0 | J3: ='Hotel Data'!U12 -> 73 | K3: ='Hotel Data'!AD12 -> 345 | L3: ='Hotel Data'!AG12 -> 1185 | M3: ='Hotel Data'!AJ12 -> 144 | N3: ='Hotel Data'!AN12 -> 535 | O3: ='Hotel Data'!AR12 -> 288 | P3: =TOTAL!K3 -> 85
A4: Milan | B4: =B3+1 -> 3 | C4: 7 | D4: 2022 | E4: ='Hotel Data'!E13 -> 88 | F4: ='Hotel Data'!G13 -> 0 | G4: ='Hotel Data'!O13 -> 74 | H4: ='Hotel Data'!Q13 -> 33 | I4: ='Hotel Data'!S13 -> 0 | J4: ='Hotel Data'!U13 -> 52 | K4: ='Hotel Data'!AD13 -> 333 | L4: ='Hotel Data'!AG13 -> 1053 | M4: ='Hotel Data'!AJ13 -> 160 | N4: ='Hotel Data'!AN13 -> 501 | O4: ='Hotel Data'!AR13 -> 312 | P4: =TOTAL!K4 -> 81
A5: Milan | B5: =B4+1 -> 4 | C5: 7 | D5: 2022 | E5: ='Hotel Data'!E14 -> 99 | F5: ='Hotel Data'!G14 -> 0 | G5: ='Hotel Data'!O14 -> 94 | H5: ='Hotel Data'!Q14 -> 37 | I5: ='Hotel Data'!S14 -> 0 | J5: ='Hotel Data'!U14 -> 64 | K5: ='Hotel Data'!AD14 -> 334 | L5: ='Hotel Data'!AG14 -> 1078 | M5: ='Hotel Data'!AJ14 -> 144 | N5: ='Hotel Data'!AN14 -> 505 | O5: ='Hotel Data'!AR14 -> 288 | P5: =TOTAL!K5 -> 84
A6: Milan | B6: =B5+1 -> 5 | C6: 7 | D6: 2022 | E6: ='Hotel Data'!E15 -> 161 | F6: ='Hotel Data'!G15 -> 0 | G6: ='Hotel Data'!O15 -> 101 | H6: ='Hotel Data'!Q15 -> 45 | I6: ='Hotel Data'!S15 -> 0 | J6: ='Hotel Data'!U15 -> 76 | K6: ='Hotel Data'!AD15 -> 339 | L6: ='Hotel Data'!AG15 -> 1187 | M6: ='Hotel Data'!AJ15 -> 152 | N6: ='Hotel Data'!AN15 -> 515 | O6: ='Hotel Data'!AR15 -> 248 | P6: =TOTAL!K6 -> 82
A7: Milan | B7: =B6+1 -> 6 | C7: 7 | D7: 2022 | E7: ='Hotel Data'!E16 -> 90 | F7: ='Hotel Data'!G16 -> 0 | G7: ='Hotel Data'!O16 -> 86 | H7: ='Hotel Data'!Q16 -> 39 | I7: ='Hotel Data'!S16 -> 0 | J7: ='Hotel Data'!U16 -> 67 | K7: ='Hotel Data'!AD16 -> 367 | L7: ='Hotel Data'!AG16 -> 1215 | M7: ='Hotel Data'!AJ16 -> 168 | N7: ='Hotel Data'!AN16 -> 496 | O7: ='Hotel Data'!AR16 -> 272 | P7: =TOTAL!K7 -> 89
A8: Milan | B8: =B7+1 -> 7 | C8: 7 | D8: 2022 | E8: ='Hotel Data'!E17 -> 155 | F8: ='Hotel Data'!G17 -> 1 | G8: ='Hotel Data'!O17 -> 86 | H8: ='Hotel Data'!Q17 -> 38 | I8: ='Hotel Data'!S17 -> 0 | J8: ='Hotel Data'!U17 -> 67 | K8: ='Hotel Data'!AD17 -> 345 | L8: ='Hotel Data'!AG17 -> 1160 | M8: ='Hotel Data'!AJ17 -> 168 | N8: ='Hotel Data'!AN17 -> 476 | O8: ='Hotel Data'!AR17 -> 296 | P8: =TOTAL!K8 -> 96
A9: Milan | B9: =B8+1 -> 8 | C9: 7 | D9: 2022 | E9: ='Hotel Data'!E18 -> 194 | F9: ='Hotel Data'!G18 -> 1 | G9: ='Hotel Data'!O18 -> 75 | H9: ='Hotel Data'!Q18 -> 40 | I9: ='Hotel Data'!S18 -> 0 | J9: ='Hotel Data'!U18 -> 67 | K9: ='Hotel Data'!AD18 -> 359 | L9: ='Hotel Data'!AG18 -> 1104 | M9: ='Hotel Data'!AJ18 -> 176 | N9: ='Hotel Data'!AN18 -> 475 | O9: ='Hotel Data'!AR18 -> 272 | P9: =TOTAL!K9 -> 92
A10: Milan | B10: =B9+1 -> 9 | C10: 7 | D10: 2022 | E10: ='Hotel Data'!E19 -> 208 | F10: ='Hotel Data'!G19 -> 0 | G10: ='Hotel Data'!O19 -> 75 | H10: ='Hotel Data'!Q19 -> 37 | I10: ='Hotel Data'!S19 -> 0 | J10: ='Hotel Data'!U19 -> 68 | K10: ='Hotel Data'!AD19 -> 346 | L10: ='Hotel Data'!AG19 -> 1151 | M10: ='Hotel Data'!AJ19 -> 144 | N10: ='Hotel Data'!AN19 -> 505 | O10: ='Hotel Data'!AR19 -> 296 | P10: =TOTAL!K10 -> 91
A11: Milan | B11: =B10+1 -> 10 | C11: 7 | D11: 2022 | E11: ='Hotel Data'!E20 -> 214 | F11: ='Hotel Data'!G20 -> 0 | G11: ='Hotel Data'!O20 -> 76 | H11: ='Hotel Data'!Q20 -> 33 | I11: ='Hotel Data'!S20 -> 0 | J11: ='Hotel Data'!U20 -> 59 | K11: ='Hotel Data'!AD20 -> 364 | L11: ='Hotel Data'!AG20 -> 1156 | M11: ='Hotel Data'!AJ20 -> 160 | N11: ='Hotel Data'!AN20 -> 508 | O11: ='Hotel Data'!AR20 -> 336 | P11: =TOTAL!K11 -> 91
A12: Milan | B12: =B11+1 -> 11 | C12: 7 | D12: 2022 | E12: ='Hotel Data'!E21 -> 170 | F12: ='Hotel Data'!G21 -> 0 | G12: ='Hotel Data'!O21 -> 77 | H12: ='Hotel Data'!Q21 -> 38 | I12: ='Hotel Data'!S21 -> 0 | J12: ='Hotel Data'!U21 -> 59 | K12: ='Hotel Data'!AD21 -> 356 | L12: ='Hotel Data'!AG21 -> 1180 | M12: ='Hotel Data'!AJ21 -> 168 | N12: ='Hotel Data'!AN21 -> 499 | O12: ='Hotel Data'!AR21 -> 320 | P12: =TOTAL!K12 -> 94
A13: Milan | B13: =B12+1 -> 12 | C13: 7 | D13: 2022 | E13: ='Hotel Data'!E22 -> 98 | F13: ='Hotel Data'!G22 -> 2 | G13: ='Hotel Data'!O22 -> 80 | H13: ='Hotel Data'!Q22 -> 30 | I13: ='Hotel Data'!S22 -> 0 | J13: ='Hotel Data'!U22 -> 56 | K13: ='Hotel Data'!AD22 -> 345 | L13: ='Hotel Data'!AG22 -> 1197 | M13: ='Hotel Data'!AJ22 -> 200 | N13: ='Hotel Data'!AN22 -> 472 | O13: ='Hotel Data'!AR22 -> 296 | P13: =TOTAL!K13 -> 96
A14: Milan | B14: =B13+1 -> 13 | C14: 7 | D14: 2022 | E14: ='Hotel Data'!E23 -> 100 | F14: ='Hotel Data'!G23 -> 0 | G14: ='Hotel Data'!O23 -> 80 | H14: ='Hotel Data'!Q23 -> 36 | I14: ='Hotel Data'!S23 -> 0 | J14: ='Hotel Data'!U23 -> 74 | K14: ='Hotel Data'!AD23 -> 332 | L14: ='Hotel Data'!AG23 -> 1206 | M14: ='Hotel Data'!AJ23 -> 144 | N14: ='Hotel Data'!AN23 -> 474 | O14: ='Hotel Data'!AR23 -> 208 | P14: =TOTAL!K14 -> 89
... A31: Milan | B31: =B30+1 -> 30 | C31: 7 | D31: 2022 | E31: ='Hotel Data'!E40 -> 215 | F31: ='Hotel Data'!G40 -> 0 | G31: ='Hotel Data'!O40 -> 68 | H31: ='Hotel Data'!Q40 -> 102 | I31: ='Hotel Data'!S40 -> 0 | J31: ='Hotel Data'!U40 -> 131 | K31: ='Hotel Data'!AD40 -> 343 | L31: ='Hotel Data'!AG40 -> 1164 | M31: ='Hotel Data'!AJ40 -> 160 | N31: ='Hotel Data'!AN40 -> 477 | O31: ='Hotel Data'!AR40 -> 264 | P31: =TOTAL!K31 -> 100
D32: 2022 | E32: ='Hotel Data'!E41 -> 212 | F32: ='Hotel Data'!G41 -> 0 | G32: ='Hotel Data'!O41 -> 58 | H32: ='Hotel Data'!Q41 -> 90 | I32: ='Hotel Data'!S41 -> 0 | J32: ='Hotel Data'!U41 -> 118 | K32: ='Hotel Data'!AD41 -> 333 | L32: ='Hotel Data'!AG41 -> 1156 | M32: ='Hotel Data'!AJ41 -> 160 | N32: ='Hotel Data'!AN41 -> 497 | O32: ='Hotel Data'!AR41 -> 296 | P32: =TOTAL!K32 -> 90

Sheet Hotel Data
A2: FOUR SEASONS HOTEL MILANO | H2: REPARTO MANUTENZIONE
C3: LUGLIO '09
A4: FOUR SEASONS HOTEL MILANO | H4: REPARTO MANUTENZIONE
C5: LUGLIO '17
AZ6: BUDGET | BA6: BUDGET | BB6: BUDGET | BC6: BUDGET | BD6: BUDGET | BE6: BUDGET | BF6: 42186 | BG6: 42186 | BH6: 42186 | BI6: 42186
D7: GAS RISCALD. | F7: GAS CUCINA | H7: H2O GENERALE | N7: H2O CONDIZION.ADD | P7: REINT. H2O ADD | R7: H2O ADD F CUC P | T7: H2O SANIT. CALDA | V7: ENEL ATTIVA | Y7: ENEL REATT. | AB7: ENEL CUC.PRINC. P | AE7: ENEL CUC.PRINC. N. | AH7: ENEL CUC.PREP. | AL7: ENEL CUC.VERANDA | AP7: ENEL LAVANDERIA | AS7: TEMPER.GG. | AU7: RICAVI | AV7: REFRIGERATA | AW7: lt/ G | AZ7: GAS RISCALD | BA7: GAS CUCINA | BB7: ACQUA GENER. | BC7: ACQUA CONDIZ. | BD7: ENERGIA | BE7: Proiezione BA | BF7: ENEL CUC.PRINC. | BG7: ENEL CUC.PREP. | BH7: ENEL CUC.VER | BI7: ENEL LAVAND.
A9: GG | B9: ORA | C9: NOTE | D9: LETTURA MC | E9: DIFF. G | F9: LETTURA MC | G9: DIFF. G | H9: LETTURA MC | I9: DIFF. G | J9: lett. BA | K9: DIFF. G | L9: GUESTS | M9: mcxcl | N9: LETTURA MC | O9: DIFF. G | P9: LETTURA MC | Q9: DIFF. G | R9: LETTURA MC | S9: DIFF. G | T9: LETTURA MC | U9: DIFF. G | V9: LET. KWH*2200 | W9: DIFF. G | X9: Consumo BA | Y9: LET.KWT | Z9: DIFF. G | AA9: Consumo BA | AB9: LET. KWH | AC9: DIFF. G | AD9: Consumo BA | AE9: LET. KWH | AF9: DIFF. G | AG9: Consumo BA | AH9: LET. KWH*80 | AI9: DIFF. G | AJ9: Consumo BA | AK9: COVERS | AL9: LET. KWH | AM9: DIFF. G | AN9: Consumo Ba | AO9: COVERS | AP9: LET. KWH*80 | AQ9: DIFF. G | AR9: Consumo BA | AS9: MIN | AT9: MAX | AU9: LAVANDERIA
D10: =[1]June!D38 -> 318983 | F10: =[1]June!F38 -> 7042 | H10: =[1]June!H38 -> 75199 | J10: =[1]June!J38 -> 590610 | N10: =[1]June!N38 -> 8407 | P10: =[1]June!P38 -> 92645 | R10: =[1]June!R38 -> 35 | T10: =[1]June!T38 -> 195026 | V10: =[1]June!V38 -> 4734.445 | Y10: =[1]June!Y38 -> 911.652 | AB10: =[1]June!AB38 -> 1735697 | AE10: =[1]June!AE38 -> 5116605 | AH10: =[1]June!AH38 -> 34005 | AL10: =[1]June!AL38 -> 187519 | AP10: =[1]June!AP38 -> 46601 | AV10: =[1]June!AV38 -> 0 | AZ10: =D45 -> 0 | BA10: =F45 -> 0 | BB10: =H45 -> 0 | BC10: =N45 -> 0 | BD10: 570000 | BE10: =BD10 -> 570000 | BF10: 47307 | BG10: 6432 | BH10: 13443 | BI10: 11344
A11: 1 | B11: 00:00 | D11: 319082 | E11: =IF(ISBLANK(D11),0,D11-D10) -> 99 | F11: 7042 | G11: =IF(ISBLANK(F11),0,F11-F10) -> 0 | H11: 75491 | I11: =IF(ISBLANK(H11),0,H11-H10) -> 292 | J11: 590891 | K11: =IF(ISBLANK(J11),0,J11-J10) -> 281 | M11: =I11/L11 -> #DIV/0! | N11: 8490 | O11: =IF(ISBLANK(N11),0,N11-N10) -> 83 | P11: 92679 | Q11: =IF(ISBLANK(P11),0,P11-P10) -> 34 | R11: 35 | S11: =IF(ISBLANK(R11),0,R11-R10) -> 0 | T11: 195087 | U11: =IF(ISBLANK(T11),0,T11-T10) -> 61 | W11: =IF(ISBLANK(V11),0,SUM(V11-V10)*2200) -> 0 | X11: 18330 | Z11: =IF(ISBLANK(Y11),0,SUM(Y11-Y10)*2200) -> 0 | AA11: 2923 | AC11: =IF(ISBLANK(AB11),0,SUM(AB11-AB10)) -> 0 | AD11: 327 | AF11: =IF(ISBLANK(AE11),0,SUM(AE11-AE10)) -> 0 | AG11: 1157 | AI11: =IF(ISBLANK(AH11),0,SUM(AH11-AH10)*80) -> 0 | AJ11: 160 | AM11: =IF(ISBLANK(AL11),0,AL11-AL10) -> 0 | AN11: 501 | AR11: 320 | AS11: 20 | AT11: 34 | AW11: =IF(ISBLANK(AV11),0,AV11-AV10) -> 0 | AY11: 1 | AZ11: =IF(D11<>0,(+D11-D$10)/A11*31,0) -> 3069 | BA11: =IF(F11<>0,(+F11-F$10)/$A11*31,0) -> 0 | BB11: =IF(H11<>0,(+H11-H$10)/$A11*31,0) -> 9052 | BC11: =IF(N11<>0,(+N11-N$10)/$A11*31,0) -> 2573 | BD11: =IF(V11<>0,(+V11-V$10)*2200/$A11*31,0) -> 0 | BE11: =IF(X11<>0,AVERAGE(X11:X$11)*31,) -> 568230 | BF11: =IF(AD11+AG11<>0,AVERAGE(AD$11:AD11)*31+AVERAGE(AG$11:AG11)*31,) -> 46004 | BG11: =IF(AJ11<>0,AVERAGE(AJ11:AJ$11)*31,) -> 4960 | BH11: =IF(AN11<>0,AVERAGE(AN11:AN$11)*31,) -> 15531 | BI11: =IF(AR11<>0,AVERAGE(AR11:AR$11)*31,) -> 9920
A12: =1+A11 -> 2 | B12: 00:00 | D12: 319179 | E12: =IF(ISBLANK(D12),0,D12-D11) -> 97 | F12: 7043 | G12: =IF(ISBLANK(F12),0,F12-F11) -> 1 | H12: 75789 | I12: =IF(ISBLANK(H12),0,H12-H11) -> 298 | J12: 591179 | K12: =IF(ISBLANK(J12),0,J12-J11) -> 288 | M12: =I12/L12 -> #DIV/0! | N12: 8582 | O12: =IF(ISBLANK(N12),0,N12-N11) -> 92 | P12: 92720 | Q12: =IF(ISBLANK(P12),0,P12-P11) -> 41 | R12: 35 | S12: =IF(ISBLANK(R12),0,R12-R11) -> 0 | T12: 195160 | U12: =IF(ISBLANK(T12),0,T12-T11) -> 73 | W12: =IF(ISBLANK(V12),0,SUM(V12-V11)*2200) -> 0 | X12: 18303 | Z12: =IF(ISBLANK(Y12),0,SUM(Y12-Y11)*2200) -> 0 | AA12: 3046 | AC12: =IF(ISBLANK(AB12),0,SUM(AB12-AB11)) -> 0 | AD12: 345 | AF12: =IF(ISBLANK(AE12),0,SUM(AE12-AE11)) -> 0 | AG12: 1185 | AI12: =IF(ISBLANK(AH12),0,SUM(AH12-AH11)*80) -> 0 | AJ12: 144 | AM12: =IF(ISBLANK(AL12),0,AL12-AL11) -> 0 | AN12: 535 | AR12: 288 | AS12: 25 | AT12: 35 | AW12: =IF(ISBLANK(AV12),0,AV12-AV11) -> 0 | AY12: =1+AY11 -> 2 | AZ12: =IF(D12<>0,(+D12-D$10)/A12*31,0) -> 3038 | BA12: =IF(F12<>0,(+F12-F$10)/$A12*31,0) -> 15.5 | BB12: =IF(H12<>0,(+H12-H$10)/$A12*31,0) -> 9145 | BC12: =IF(N12<>0,(+N12-N$10)/$A12*31,0) -> 2712.5 | BD12: =IF(V12<>0,(+V12-V$10)*2200/$A12*31,0) -> 0 | BE12: =IF(X12<>0,AVERAGE(X$11:X12)*31,) -> 567811.5 | BF12: =IF(AD12+AG12<>0,AVERAGE(AD$11:AD12)*31+AVERAGE(AG$11:AG12)*31,) -> 46717 | BG12: =IF(AJ12<>0,AVERAGE(AJ$11:AJ12)*31,) -> 4712 | BH12: =IF(AN12<>0,AVERAGE(AN$11:AN12)*31,) -> 16058 | BI12: =IF(AR12<>0,AVERAGE(AR$11:AR12)*31,) -> 9424
A13: =1+A12 -> 3 | B13: 00:00 | D13: 319267 | E13: =IF(ISBLANK(D13),0,D13-D12) -> 88 | F13: 7043 | G13: =IF(ISBLANK(F13),0,F13-F12) -> 0 | H13: 76074 | I13: =IF(ISBLANK(H13),0,H13-H12) -> 285 | J13: 591453 | K13: =IF(ISBLANK(J13),0,J13-J12) -> 274 | M13: =I13/L13 -> #DIV/0! | N13: 8656 | O13: =IF(ISBLANK(N13),0,N13-N12) -> 74 | P13: 92753 | Q13: =IF(ISBLANK(P13),0,P13-P12) -> 33 | R13: 35 | S13: =IF(ISBLANK(R13),0,R13-R12) -> 0 | T13: 195212 | U13: =IF(ISBLANK(T13),0,T13-T12) -> 52 | W13: =IF(ISBLANK(V13),0,SUM(V13-V12)*2200) -> 0 | X13: 18693 | Z13: =IF(ISBLANK(Y13),0,SUM(Y13-Y12)*2200) -> 0 | AA13: 3180 | AC13: =IF(ISBLANK(AB13),0,SUM(AB13-AB12)) -> 0 | AD13: 333 | AF13: =IF(ISBLANK(AE13),0,SUM(AE13-AE12)) -> 0 | AG13: 1053 | AI13: =IF(ISBLANK(AH13),0,SUM(AH13-AH12)*80) -> 0 | AJ13: 160 | AM13: =IF(ISBLANK(AL13),0,AL13-AL12) -> 0 | AN13: 501 | AR13: 312 | AS13: 26 | AT13: 37 | AW13: =IF(ISBLANK(AV13),0,AV13-AV12) -> 0 | AY13: =1+AY12 -> 3 | AZ13: =IF(D13<>0,(+D13-D$10)/A13*31,0) -> 2934.6667 | BA13: =IF(F13<>0,(+F13-F$10)/$A13*31,0) -> 10.333333 | BB13: =IF(H13<>0,(+H13-H$10)/$A13*31,0) -> 9041.6667 | BC13: =IF(N13<>0,(+N13-N$10)/$A13*31,0) -> 2573 | BD13: =IF(V13<>0,(+V13-V$10)*2200/$A13*31,0) -> 0 | BE13: =IF(X13<>0,AVERAGE(X$11:X13)*31,) -> 571702 | BF13: =IF(AD13+AG13<>0,AVERAGE(AD$11:AD13)*31+AVERAGE(AG$11:AG13)*31,) -> 45466.667 | BG13: =IF(AJ13<>0,AVERAGE(AJ$11:AJ13)*31,) -> 4794.6667 | BH13: =IF(AN13<>0,AVERAGE(AN$11:AN13)*31,) -> 15882.333 | BI13: =IF(AR13<>0,AVERAGE(AR$11:AR13)*31,) -> 9506.6667
A14: =1+A13 -> 4 | B14: 00:00 | D14: 319366 | E14: =IF(ISBLANK(D14),0,D14-D13) -> 99 | F14: 7043 | G14: =IF(ISBLANK(F14),0,F14-F13) -> 0 | H14: 76365 | I14: =IF(ISBLANK(H14),0,H14-H13) -> 291 | J14: 591733 | K14: =IF(ISBLANK(J14),0,J14-J13) -> 280 | M14: =I14/L14 -> #DIV/0! | N14: 8750 | O14: =IF(ISBLANK(N14),0,N14-N13) -> 94 | P14: 92790 | Q14: =IF(ISBLANK(P14),0,P14-P13) -> 37 | R14: 35 | S14: =IF(ISBLANK(R14),0,R14-R13) -> 0 | T14: 195276 | U14: =IF(ISBLANK(T14),0,T14-T13) -> 64 | W14: =IF(ISBLANK(V14),0,SUM(V14-V13)*2200) -> 0 | X14: 18537 | Z14: =IF(ISBLANK(Y14),0,SUM(Y14-Y13)*2200) -> 0 | AA14: 2961 | AC14: =IF(ISBLANK(AB14),0,SUM(AB14-AB13)) -> 0 | AD14: 334 | AF14: =IF(ISBLANK(AE14),0,SUM(AE14-AE13)) -> 0 | AG14: 1078 | AI14: =IF(ISBLANK(AH14),0,SUM(AH14-AH13)*80) -> 0 | AJ14: 144 | AM14: =IF(ISBLANK(AL14),0,AL14-AL13) -> 0 | AN14: 505 | AR14: 288 | AS14: 23 | AT14: 34 | AW14: =IF(ISBLANK(AV14),0,AV14-AV13) -> 0 | AY14: =1+AY13 -> 4 | AZ14: =IF(D14<>0,(+D14-D$10)/A14*31,0) -> 2968.25 | BA14: =IF(F14<>0,(+F14-F$10)/$A14*31,0) -> 7.75 | BB14: =IF(H14<>0,(+H14-H$10)/$A14*31,0) -> 9036.5 | BC14: =IF(N14<>0,(+N14-N$10)/$A14*31,0) -> 2658.25 | BD14: =IF(V14<>0,(+V14-V$10)*2200/$A14*31,0) -> 0 | BE14: =IF(X14<>0,AVERAGE(X$11:X14)*31,) -> 572438.25 | BF14: =IF(AD14+AG14<>0,AVERAGE(AD$11:AD14)*31+AVERAGE(AG$11:AG14)*31,) -> 45043 | BG14: =IF(AJ14<>0,AVERAGE(AJ$11:AJ14)*31,) -> 4712 | BH14: =IF(AN14<>0,AVERAGE(AN$11:AN14)*31,) -> 15825.5 | BI14: =IF(AR14<>0,AVERAGE(AR$11:AR14)*31,) -> 9362
A15: =1+A14 -> 5 | B15: 00:00 | D15: 319527 | E15: =IF(ISBLANK(D15),0,D15-D14) -> 161 | F15: 7043 | G15: =IF(ISBLANK(F15),0,F15-F14) -> 0 | H15: 76654 | I15: =IF(ISBLANK(H15),0,H15-H14) -> 289 | J15: 592013 | K15: =IF(ISBLANK(J15),0,J15-J14) -> 280 | M15: =I15/L15 -> #DIV/0! | N15: 8851 | O15: =IF(ISBLANK(N15),0,N15-N14) -> 101 | P15: 92835 | Q15: =IF(ISBLANK(P15),0,P15-P14) -> 45 | R15: 35 | S15: =IF(ISBLANK(R15),0,R15-R14) -> 0 | T15: 195352 | U15: =IF(ISBLANK(T15),0,T15-T14) -> 76 | W15: =IF(ISBLANK(V15),0,SUM(V15-V14)*2200) -> 0 | X15: 18942 | Z15: =IF(ISBLANK(Y15),0,SUM(Y15-Y14)*2200) -> 0 | AA15: 2879 | AC15: =IF(ISBLANK(AB15),0,SUM(AB15-AB14)) -> 0 | AD15: 339 | AF15: =IF(ISBLANK(AE15),0,SUM(AE15-AE14)) -> 0 | AG15: 1187 | AI15: =IF(ISBLANK(AH15),0,SUM(AH15-AH14)*80) -> 0 | AJ15: 152 | AM15: =IF(ISBLANK(AL15),0,AL15-AL14) -> 0 | AN15: 515 | AR15: 248 | AS15: 22 | AT15: 34 | AW15: =IF(ISBLANK(AV15),0,AV15-AV14) -> 0 | AY15: =1+AY14 -> 5 | AZ15: =IF(D15<>0,(+D15-D$10)/A15*31,0) -> 3372.8 | BA15: =IF(F15<>0,(+F15-F$10)/$A15*31,0) -> 6.2 | BB15: =IF(H15<>0,(+H15-H$10)/$A15*31,0) -> 9021 | BC15: =IF(N15<>0,(+N15-N$10)/$A15*31,0) -> 2752.8 | BD15: =IF(V15<>0,(+V15-V$10)*2200/$A15*31,0) -> 0 | BE15: =IF(X15<>0,AVERAGE(X$11:X15)*31,) -> 575391 | BF15: =IF(AD15+AG15<>0,AVERAGE(AD$11:AD15)*31+AVERAGE(AG$11:AG15)*31,) -> 45495.6 | BG15: =IF(AJ15<>0,AVERAGE(AJ$11:AJ15)*31,) -> 4712 | BH15: =IF(AN15<>0,AVERAGE(AN$11:AN15)*31,) -> 15853.4 | BI15: =IF(AR15<>0,AVERAGE(AR$11:AR15)*31,) -> 9027.2
A16: =1+A15 -> 6 | B16: 00:00 | D16: 319617 | E16: =IF(ISBLANK(D16),0,D16-D15) -> 90 | F16: 7043 | G16: =IF(ISBLANK(F16),0,F16-F15) -> 0 | H16: 76954 | I16: =IF(ISBLANK(H16),0,H16-H15) -> 300 | J16: 592302 | K16: =IF(ISBLANK(J16),0,J16-J15) -> 289 | M16: =I16/L16 -> #DIV/0! | N16: 8937 | O16: =IF(ISBLANK(N16),0,N16-N15) -> 86 | P16: 92874 | Q16: =IF(ISBLANK(P16),0,P16-P15) -> 39 | R16: 35 | S16: =IF(ISBLANK(R16),0,R16-R15) -> 0 | T16: 195419 | U16: =IF(ISBLANK(T16),0,T16-T15) -> 67 | W16: =IF(ISBLANK(V16),0,SUM(V16-V15)*2200) -> 0 | X16: 19281 | Z16: =IF(ISBLANK(Y16),0,SUM(Y16-Y15)*2200) -> 0 | AA16: 2858 | AC16: =IF(ISBLANK(AB16),0,SUM(AB16-AB15)) -> 0 | AD16: 367 | AF16: =IF(ISBLANK(AE16),0,SUM(AE16-AE15)) -> 0 | AG16: 1215 | AI16: =IF(ISBLANK(AH16),0,SUM(AH16-AH15)*80) -> 0 | AJ16: 168 | AM16: =IF(ISBLANK(AL16),0,AL16-AL15) -> 0 | AN16: 496 | AR16: 272 | AS16: 24 | AT16: 33 | AW16: =IF(ISBLANK(AV16),0,AV16-AV15) -> 0 | AY16: =1+AY15 -> 6 | AZ16: =IF(D16<>0,(+D16-D$10)/A16*31,0) -> 3275.6667 | BA16: =IF(F16<>0,(+F16-F$10)/$A16*31,0) -> 5.1666667 | BB16: =IF(H16<>0,(+H16-H$10)/$A16*31,0) -> 9067.5 | BC16: =IF(N16<>0,(+N16-N$10)/$A16*31,0) -> 2738.3333 | BD16: =IF(V16<>0,(+V16-V$10)*2200/$A16*31,0) -> 0 | BE16: =IF(X16<>0,AVERAGE(X$11:X16)*31,) -> 579111 | BF16: =IF(AD16+AG16<>0,AVERAGE(AD$11:AD16)*31+AVERAGE(AG$11:AG16)*31,) -> 46086.667 | BG16: =IF(AJ16<>0,AVERAGE(AJ$11:AJ16)*31,) -> 4794.6667 | BH16: =IF(AN16<>0,AVERAGE(AN$11:AN16)*31,) -> 15773.833 | BI16: =IF(AR16<>0,AVERAGE(AR$11:AR16)*31,) -> 8928
A17: =1+A16 -> 7 | B17: 00:00 | D17: 319772 | E17: =IF(ISBLANK(D17),0,D17-D16) -> 155 | F17: 7044 | G17: =IF(ISBLANK(F17),0,F17-F16) -> 1 | H17: 77250 | I17: =IF(ISBLANK(H17),0,H17-H16) -> 296 | J17: 592587 | K17: =IF(ISBLANK(J17),0,J17-J16) -> 285 | M17: =I17/L17 -> #DIV/0! | N17: 9023 | O17: =IF(ISBLANK(N17),0,N17-N16) -> 86 | P17: 92912 | Q17: =IF(ISBLANK(P17),0,P17-P16) -> 38 | R17: 35 | S17: =IF(ISBLANK(R17),0,R17-R16) -> 0 | T17: 195486 | U17: =IF(ISBLANK(T17),0,T17-T16) -> 67 | W17: =IF(ISBLANK(V17),0,SUM(V17-V16)*2200) -> 0 | X17: 18253 | Z17: =IF(ISBLANK(Y17),0,SUM(Y17-Y16)*2200) -> 0 | AA17: 2761 | AC17: =IF(ISBLANK(AB17),0,SUM(AB17-AB16)) -> 0 | AD17: 345 | AF17: =IF(ISBLANK(AE17),0,SUM(AE17-AE16)) -> 0 | AG17: 1160 | AI17: =IF(ISBLANK(AH17),0,SUM(AH17-AH16)*80) -> 0 | AJ17: 168 | AM17: =IF(ISBLANK(AL17),0,AL17-AL16) -> 0 | AN17: 476 | AR17: 296 | AS17: 23 | AT17: 35 | AW17: =IF(ISBLANK(AV17),0,AV17-AV16) -> 0 | AY17: =1+AY16 -> 7 | AZ17: =IF(D17<>0,(+D17-D$10)/A17*31,0) -> 3494.1429 | BA17: =IF(F17<>0,(+F17-F$10)/$A17*31,0) -> 8.8571429 | BB17: =IF(H17<>0,(+H17-H$10)/$A17*31,0) -> 9083 | BC17: =IF(N17<>0,(+N17-N$10)/$A17*31,0) -> 2728 | BD17: =IF(V17<>0,(+V17-V$10)*2200/$A17*31,0) -> 0 | BE17: =IF(X17<>0,AVERAGE(X$11:X17)*31,) -> 577215.57 | BF17: =IF(AD17+AG17<>0,AVERAGE(AD$11:AD17)*31+AVERAGE(AG$11:AG17)*31,) -> 46167.857 | BG17: =IF(AJ17<>0,AVERAGE(AJ$11:AJ17)*31,) -> 4853.7143 | BH17: =IF(AN17<>0,AVERAGE(AN$11:AN17)*31,) -> 15628.429 | BI17: =IF(AR17<>0,AVERAGE(AR$11:AR17)*31,) -> 8963.4286
A18: =1+A17 -> 8 | B18: 00:00 | D18: 319966 | E18: =IF(ISBLANK(D18),0,D18-D17) -> 194 | F18: 7045 | G18: =IF(ISBLANK(F18),0,F18-F17) -> 1 | H18: 77528 | I18: =IF(ISBLANK(H18),0,H18-H17) -> 278 | J18: 592854 | K18: =IF(ISBLANK(J18),0,J18-J17) -> 267 | M18: =I18/L18 -> #DIV/0! | N18: 9098 | O18: =IF(ISBLANK(N18),0,N18-N17) -> 75 | P18: 92952 | Q18: =IF(ISBLANK(P18),0,P18-P17) -> 40 | R18: 35 | S18: =IF(ISBLANK(R18),0,R18-R17) -> 0 | T18: 195553 | U18: =IF(ISBLANK(T18),0,T18-T17) -> 67 | W18: =IF(ISBLANK(V18),0,SUM(V18-V17)*2200) -> 0 | X18: 17264 | Z18: =IF(ISBLANK(Y18),0,SUM(Y18-Y17)*2200) -> 0 | AA18: 2508 | AC18: =IF(ISBLANK(AB18),0,SUM(AB18-AB17)) -> 0 | AD18: 359 | AF18: =IF(ISBLANK(AE18),0,SUM(AE18-AE17)) -> 0 | AG18: 1104 | AI18: =IF(ISBLANK(AH18),0,SUM(AH18-AH17)*80) -> 0 | AJ18: 176 | AM18: =IF(ISBLANK(AL18),0,AL18-AL17) -> 0 | AN18: 475 | AR18: 272 | AS18: 22 | AT18: 31 | AW18: =IF(ISBLANK(AV18),0,AV18-AV17) -> 0 | AY18: =1+AY17 -> 8 | AZ18: =IF(D18<>0,(+D18-D$10)/A18*31,0) -> 3809.125 | BA18: =IF(F18<>0,(+F18-F$10)/$A18*31,0) -> 11.625 | BB18: =IF(H18<>0,(+H18-H$10)/$A18*31,0) -> 9024.875 | BC18: =IF(N18<>0,(+N18-N$10)/$A18*31,0) -> 2677.625 | BD18: =IF(V18<>0,(+V18-V$10)*2200/$A18*31,0) -> 0 | BE18: =IF(X18<>0,AVERAGE(X$11:X18)*31,) -> 571961.62 | BF18: =IF(AD18+AG18<>0,AVERAGE(AD$11:AD18)*31+AVERAGE(AG$11:AG18)*31,) -> 46066 | BG18: =IF(AJ18<>0,AVERAGE(AJ$11:AJ18)*31,) -> 4929 | BH18: =IF(AN18<>0,AVERAGE(AN$11:AN18)*31,) -> 15515.5 | BI18: =IF(AR18<>0,AVERAGE(AR$11:AR18)*31,) -> 8897
A19: 9 | B19: 00:00 | D19: 320174 | E19: =IF(ISBLANK(D19),0,D19-D18) -> 208 | F19: 7045 | G19: =IF(ISBLANK(F19),0,F19-F18) -> 0 | H19: 77814 | I19: =IF(ISBLANK(H19),0,H19-H18) -> 286 | J19: 593130 | K19: =IF(ISBLANK(J19),0,J19-J18) -> 276 | M19: =I19/L19 -> #DIV/0! | N19: 9173 | O19: =IF(ISBLANK(N19),0,N19-N18) -> 75 | P19: 92989 | Q19: =IF(ISBLANK(P19),0,P19-P18) -> 37 | R19: 35 | S19: =IF(ISBLANK(R19),0,R19-R18) -> 0 | T19: 195621 | U19: =IF(ISBLANK(T19),0,T19-T18) -> 68 | W19: =IF(ISBLANK(V19),0,SUM(V19-V18)*2200) -> 0 | X19: 16850 | Z19: =IF(ISBLANK(Y19),0,SUM(Y19-Y18)*2200) -> 0 | AA19: 2718 | AC19: =IF(ISBLANK(AB19),0,SUM(AB19-AB18)) -> 0 | AD19: 346 | AF19: =IF(ISBLANK(AE19),0,SUM(AE19-AE18)) -> 0 | AG19: 1151 | AI19: =IF(ISBLANK(AH19),0,SUM(AH19-AH18)*80) -> 0 | AJ19: 144 | AM19: =IF(ISBLANK(AL19),0,AL19-AL18) -> 0 | AN19: 505 | AR19: 296 | AS19: 21 | AT19: 32 | AW19: =IF(ISBLANK(AV19),0,AV19-AV18) -> 0 | AY19: =1+AY18 -> 9 | AZ19: =IF(D19<>0,(+D19-D$10)/A19*31,0) -> 4102.3333 | BA19: =IF(F19<>0,(+F19-F$10)/$A19*31,0) -> 10.333333 | BB19: =IF(H19<>0,(+H19-H$10)/$A19*31,0) -> 9007.2222 | BC19: =IF(N19<>0,(+N19-N$10)/$A19*31,0) -> 2638.4444 | BD19: =IF(V19<>0,(+V19-V$10)*2200/$A19*31,0) -> 0 | BE19: =IF(X19<>0,AVERAGE(X$11:X19)*31,) -> 566449.22 | BF19: =IF(AD19+AG19<>0,AVERAGE(AD$11:AD19)*31+AVERAGE(AG$11:AG19)*31,) -> 46103.889 | BG19: =IF(AJ19<>0,AVERAGE(AJ$11:AJ19)*31,) -> 4877.3333 | BH19: =IF(AN19<>0,AVERAGE(AN$11:AN19)*31,) -> 15531 | BI19: =IF(AR19<>0,AVERAGE(AR$11:AR19)*31,) -> 8928
A20: =1+A19 -> 10 | B20: 00:00 | D20: 320388 | E20: =IF(ISBLANK(D20),0,D20-D19) -> 214 | F20: 7045 | G20: =IF(ISBLANK(F20),0,F20-F19) -> 0 | H20: 78071 | I20: =IF(ISBLANK(H20),0,H20-H19) -> 257 | J20: 593378 | K20: =IF(ISBLANK(J20),0,J20-J19) -> 248 | M20: =I20/L20 -> #DIV/0! | N20: 9249 | O20: =IF(ISBLANK(N20),0,N20-N19) -> 76 | P20: 93022 | Q20: =IF(ISBLANK(P20),0,P20-P19) -> 33 | R20: 35 | S20: =IF(ISBLANK(R20),0,R20-R19) -> 0 | T20: 195680 | U20: =IF(ISBLANK(T20),0,T20-T19) -> 59 | V20: 4819 | W20: =IF(ISBLANK(V20),0,SUM(V20-V19)*2200) -> 10601800 | X20: 16285 | Y20: 926 | Z20: =IF(ISBLANK(Y20),0,SUM(Y20-Y19)*2200) -> 2037200 | AA20: 2773 | AB20: 1739163 | AC20: =IF(ISBLANK(AB20),0,SUM(AB20-AB19)) -> 1739163 | AD20: 364 | AE20: 5128051 | AF20: =IF(ISBLANK(AE20),0,SUM(AE20-AE19)) -> 5128051 | AG20: 1156 | AH20: 34024.7 | AI20: =IF(ISBLANK(AH20),0,SUM(AH20-AH19)*80) -> 2721976 | AJ20: 160 | AL20: 192573 | AM20: =IF(ISBLANK(AL20),0,AL20-AL19) -> 192573 | AN20: 508 | AP20: 46638 | AR20: 336 | AS20: 21 | AT20: 33 | AW20: =IF(ISBLANK(AV20),0,AV20-AV19) -> 0 | AY20: =1+AY19 -> 10 | AZ20: =IF(D20<>0,(+D20-D$10)/A20*31,0) -> 4355.5 | BA20: =IF(F20<>0,(+F20-F$10)/$A20*31,0) -> 9.3 | BB20: =IF(H20<>0,(+H20-H$10)/$A20*31,0) -> 8903.2 | BC20: =IF(N20<>0,(+N20-N$10)/$A20*31,0) -> 2610.2 | BD20: =IF(V20<>0,(+V20-V$10)*2200/$A20*31,0) -> 576665.1 | BE20: =IF(X20<>0,AVERAGE(X$11:X20)*31,) -> 560287.8 | BF20: =IF(AD20+AG20<>0,AVERAGE(AD$11:AD20)*31+AVERAGE(AG$11:AG20)*31,) -> 46205.5 | BG20: =IF(AJ20<>0,AVERAGE(AJ$11:AJ20)*31,) -> 4885.6 | BH20: =IF(AN20<>0,AVERAGE(AN$11:AN20)*31,) -> 15552.7 | BI20: =IF(AR20<>0,AVERAGE(AR$11:AR20)*31,) -> 9076.8
A21: =1+A20 -> 11 | B21: 00:00 | D21: 320558 | E21: =IF(ISBLANK(D21),0,D21-D20) -> 170 | F21: 7045 | G21: =IF(ISBLANK(F21),0,F21-F20) -> 0 | H21: 78345 | I21: =IF(ISBLANK(H21),0,H21-H20) -> 274 | J21: 593642 | K21: =IF(ISBLANK(J21),0,J21-J20) -> 264 | M21: =I21/L21 -> #DIV/0! | N21: 9326 | O21: =IF(ISBLANK(N21),0,N21-N20) -> 77 | P21: 93060 | Q21: =IF(ISBLANK(P21),0,P21-P20) -> 38 | R21: 35 | S21: =IF(ISBLANK(R21),0,R21-R20) -> 0 | T21: 195739 | U21: =IF(ISBLANK(T21),0,T21-T20) -> 59 | W21: =IF(ISBLANK(V21),0,SUM(V21-V20)*2200) -> 0 | X21: 17500 | Z21: =IF(ISBLANK(Y21),0,SUM(Y21-Y20)*2200) -> 0 | AA21: 2661 | AC21: =IF(ISBLANK(AB21),0,SUM(AB21-AB20)) -> 0 | AD21: 356 | AF21: =IF(ISBLANK(AE21),0,SUM(AE21-AE20)) -> 0 | AG21: 1180 | AI21: =IF(ISBLANK(AH21),0,SUM(AH21-AH20)*80) -> 0 | AJ21: 168 | AM21: =IF(ISBLANK(AL21),0,AL21-AL20) -> 0 | AN21: 499 | AR21: 320 | AS21: 22 | AT21: 32 | AW21: =IF(ISBLANK(AV21),0,AV21-AV20) -> 0 | AY21: 11 | AZ21: =IF(D21<>0,(+D21-D$10)/A21*31,0) -> 4438.6364 | BA21: =IF(F21<>0,(+F21-F$10)/$A21*31,0) -> 8.4545455 | BB21: =IF(H21<>0,(+H21-H$10)/$A21*31,0) -> 8866 | BC21: =IF(N21<>0,(+N21-N$10)/$A21*31,0) -> 2589.9091 | BD21: =IF(V21<>0,(+V21-V$10)*2200/$A21*31,0) -> 0 | BE21: =IF(X21<>0,AVERAGE(X$11:X21)*31,) -> 558670.73 | BF21: =IF(AD21+AG21<>0,AVERAGE(AD$11:AD21)*31+AVERAGE(AG$11:AG21)*31,) -> 46333.727 | BG21: =IF(AJ21<>0,AVERAGE(AJ$11:AJ21)*31,) -> 4914.9091 | BH21: =IF(AN21<>0,AVERAGE(AN$11:AN21)*31,) -> 15545.091 | BI21: =IF(AR21<>0,AVERAGE(AR$11:AR21)*31,) -> 9153.4545
A22: =1+A21 -> 12 | B22: 00:00 | D22: 320656 | E22: =IF(ISBLANK(D22),0,D22-D21) -> 98 | F22: 7047 | G22: =IF(ISBLANK(F22),0,F22-F21) -> 2 | H22: 78608 | I22: =IF(ISBLANK(H22),0,H22-H21) -> 263 | J22: 593896 | K22: =IF(ISBLANK(J22),0,J22-J21) -> 254 | M22: =I22/L22 -> #DIV/0! | N22: 9406 | O22: =IF(ISBLANK(N22),0,N22-N21) -> 80 | P22: 93090 | Q22: =IF(ISBLANK(P22),0,P22-P21) -> 30 | R22: 35 | S22: =IF(ISBLANK(R22),0,R22-R21) -> 0 | T22: 195795 | U22: =IF(ISBLANK(T22),0,T22-T21) -> 56 | W22: =IF(ISBLANK(V22),0,SUM(V22-V21)*2200) -> 0 | X22: 18025 | Z22: =IF(ISBLANK(Y22),0,SUM(Y22-Y21)*2200) -> 0 | AA22: 2794 | AC22: =IF(ISBLANK(AB22),0,SUM(AB22-AB21)) -> 0 | AD22: 345 | AF22: =IF(ISBLANK(AE22),0,SUM(AE22-AE21)) -> 0 | AG22: 1197 | AI22: =IF(ISBLANK(AH22),0,SUM(AH22-AH21)*80) -> 0 | AJ22: 200 | AM22: =IF(ISBLANK(AL22),0,AL22-AL21) -> 0 | AN22: 472 | AR22: 296 | AS22: 22 | AT22: 31 | AW22: =IF(ISBLANK(AV22),0,AV22-AV21) -> 0 | AY22: =1+AY21 -> 12 | AZ22: =IF(D22<>0,(+D22-D$10)/A22*31,0) -> 4321.9167 | BA22: =IF(F22<>0,(+F22-F$10)/$A22*31,0) -> 12.916667 | BB22: =IF(H22<>0,(+H22-H$10)/$A22*31,0) -> 8806.5833 | BC22: =IF(N22<>0,(+N22-N$10)/$A22*31,0) -> 2580.75 | BD22: =IF(V22<>0,(+V22-V$10)*2200/$A22*31,0) -> 0 | BE22: =IF(X22<>0,AVERAGE(X$11:X22)*31,) -> 558679.42 | BF22: =IF(AD22+AG22<>0,AVERAGE(AD$11:AD22)*31+AVERAGE(AG$11:AG22)*31,) -> 46456.083 | BG22: =IF(AJ22<>0,AVERAGE(AJ$11:AJ22)*31,) -> 5022 | BH22: =IF(AN22<>0,AVERAGE(AN$11:AN22)*31,) -> 15469 | BI22: =IF(AR22<>0,AVERAGE(AR$11:AR22)*31,) -> 9155.3333
A23: 13 | B23: 00:00 | D23: 320756 | E23: =IF(ISBLANK(D23),0,D23-D22) -> 100 | F23: 7047 | G23: =IF(ISBLANK(F23),0,F23-F22) -> 0 | H23: 78812 | I23: =IF(ISBLANK(H23),0,H23-H22) -> 204 | J23: 594189 | K23: =IF(ISBLANK(J23),0,J23-J22) -> 293 | M23: =I23/L23 -> #DIV/0! | N23: 9486 | O23: =IF(ISBLANK(N23),0,N23-N22) -> 80 | P23: 93126 | Q23: =IF(ISBLANK(P23),0,P23-P22) -> 36 | R23: 35 | S23: =IF(ISBLANK(R23),0,R23-R22) -> 0 | T23: 195869 | U23: =IF(ISBLANK(T23),0,T23-T22) -> 74 | W23: =IF(ISBLANK(V23),0,SUM(V23-V22)*2200) -> 0 | X23: 18014 | Z23: =IF(ISBLANK(Y23),0,SUM(Y23-Y22)*2200) -> 0 | AA23: 2776 | AC23: =IF(ISBLANK(AB23),0,SUM(AB23-AB22)) -> 0 | AD23: 332 | AF23: =IF(ISBLANK(AE23),0,SUM(AE23-AE22)) -> 0 | AG23: 1206 | AI23: =IF(ISBLANK(AH23),0,SUM(AH23-AH22)*80) -> 0 | AJ23: 144 | AM23: =IF(ISBLANK(AL23),0,AL23-AL22) -> 0 | AN23: 474 | AR23: 208 | AS23: 23 | AT23: 33 | AW23: =IF(ISBLANK(AV23),0,AV23-AV22) -> 0 | AY23: =1+AY22 -> 13 | AZ23: =IF(D23<>0,(+D23-D$10)/A23*31,0) -> 4227.9231 | BA23: =IF(F23<>0,(+F23-F$10)/$A23*31,0) -> 11.923077 | BB23: =IF(H23<>0,(+H23-H$10)/$A23*31,0) -> 8615.6154 | BC23: =IF(N23<>0,(+N23-N$10)/$A23*31,0) -> 2573 | BD23: =IF(V23<>0,(+V23-V$10)*2200/$A23*31,0) -> 0 | BE23: =IF(X23<>0,AVERAGE(X$11:X23)*31,) -> 558660.54 | BF23: =IF(AD23+AG23<>0,AVERAGE(AD$11:AD23)*31+AVERAGE(AG$11:AG23)*31,) -> 46550.077 | BG23: =IF(AJ23<>0,AVERAGE(AJ$11:AJ23)*31,) -> 4979.0769 | BH23: =IF(AN23<>0,AVERAGE(AN$11:AN23)*31,) -> 15409.385 | BI23: =IF(AR23<>0,AVERAGE(AR$11:AR23)*31,) -> 8947.0769
A24: =1+A23 -> 14 | B24: 00:00 | D24: 320853 | E24: =IF(ISBLANK(D24),0,D24-D23) -> 97 | F24: 7047 | G24: =IF(ISBLANK(F24),0,F24-F23) -> 0 | H24: 79191 | I24: =IF(ISBLANK(H24),0,H24-H23) -> 379 | J24: 594458 | K24: =IF(ISBLANK(J24),0,J24-J23) -> 269 | M24: =I24/L24 -> #DIV/0! | N24: 9576 | O24: =IF(ISBLANK(N24),0,N24-N23) -> 90 | P24: 93161 | Q24: =IF(ISBLANK(P24),0,P24-P23) -> 35 | R24: 35 | S24: =IF(ISBLANK(R24),0,R24-R23) -> 0 | T24: 195932 | U24: =IF(ISBLANK(T24),0,T24-T23) -> 63 | W24: =IF(ISBLANK(V24),0,SUM(V24-V23)*2200) -> 0 | X24: 18472 | Z24: =IF(ISBLANK(Y24),0,SUM(Y24-Y23)*2200) -> 0 | AA24: 2978 | AC24: =IF(ISBLANK(AB24),0,SUM(AB24-AB23)) -> 0 | AD24: 367 | AF24: =IF(ISBLANK(AE24),0,SUM(AE24-AE23)) -> 0 | AG24: 1201 | AI24: =IF(ISBLANK(AH24),0,SUM(AH24-AH23)*80) -> 0 | AJ24: 152 | AM24: =IF(ISBLANK(AL24),0,AL24-AL23) -> 0 | AN24: 478 | AR24: 304 | AS24: 22 | AT24: 31 | AW24: =IF(ISBLANK(AV24),0,AV24-AV23) -> 0 | AY24: =1+AY23 -> 14 | AZ24: =IF(D24<>0,(+D24-D$10)/A24*31,0) -> 4140.7143 | BA24: =IF(F24<>0,(+F24-F$10)/$A24*31,0) -> 11.071429 | BB24: =IF(H24<>0,(+H24-H$10)/$A24*31,0) -> 8839.4286 | BC24: =IF(N24<>0,(+N24-N$10)/$A24*31,0) -> 2588.5 | BD24: =IF(V24<>0,(+V24-V$10)*2200/$A24*31,0) -> 0 | BE24: =IF(X24<>0,AVERAGE(X$11:X24)*31,) -> 559658.5 | BF24: =IF(AD24+AG24<>0,AVERAGE(AD$11:AD24)*31+AVERAGE(AG$11:AG24)*31,) -> 46697.071 | BG24: =IF(AJ24<>0,AVERAGE(AJ$11:AJ24)*31,) -> 4960 | BH24: =IF(AN24<>0,AVERAGE(AN$11:AN24)*31,) -> 15367.143 | BI24: =IF(AR24<>0,AVERAGE(AR$11:AR24)*31,) -> 8981.1429
A25: =1+A24 -> 15 | B25: 00:30 | D25: 320949 | E25: =IF(ISBLANK(D25),0,D25-D24) -> 96 | F25: 7047 | G25: =IF(ISBLANK(F25),0,F25-F24) -> 0 | H25: 79507 | I25: =IF(ISBLANK(H25),0,H25-H24) -> 316 | J25: 594762 | K25: =IF(ISBLANK(J25),0,J25-J24) -> 304 | M25: =I25/L25 -> #DIV/0! | N25: 9667 | O25: =IF(ISBLANK(N25),0,N25-N24) -> 91 | P25: 93196 | Q25: =IF(ISBLANK(P25),0,P25-P24) -> 35 | R25: 35 | S25: =IF(ISBLANK(R25),0,R25-R24) -> 0 | T25: 195999 | U25: =IF(ISBLANK(T25),0,T25-T24) -> 67 | W25: =IF(ISBLANK(V25),0,SUM(V25-V24)*2200) -> 0 | X25: 18789 | Z25: =IF(ISBLANK(Y25),0,SUM(Y25-Y24)*2200) -> 0 | AA25: 2776 | AC25: =IF(ISBLANK(AB25),0,SUM(AB25-AB24)) -> 0 | AD25: 355 | AF25: =IF(ISBLANK(AE25),0,SUM(AE25-AE24)) -> 0 | AG25: 1144 | AI25: =IF(ISBLANK(AH25),0,SUM(AH25-AH24)*80) -> 0 | AJ25: 152 | AM25: =IF(ISBLANK(AL25),0,AL25-AL24) -> 0 | AN25: 452 | AR25: 296 | AS25: 24 | AT25: 29 | AW25: =IF(ISBLANK(AV25),0,AV25-AV24) -> 0 | AY25: =1+AY24 -> 15 | AZ25: =IF(D25<>0,(+D25-D$10)/A25*31,0) -> 4063.0667 | BA25: =IF(F25<>0,(+F25-F$10)/$A25*31,0) -> 10.333333 | BB25: =IF(H25<>0,(+H25-H$10)/$A25*31,0) -> 8903.2 | BC25: =IF(N25<>0,(+N25-N$10)/$A25*31,0) -> 2604 | BD25: =IF(V25<>0,(+V25-V$10)*2200/$A25*31,0) -> 0 | BE25: =IF(X25<>0,AVERAGE(X$11:X25)*31,) -> 561178.53 | BF25: =IF(AD25+AG25<>0,AVERAGE(AD$11:AD25)*31+AVERAGE(AG$11:AG25)*31,) -> 46681.867 | BG25: =IF(AJ25<>0,AVERAGE(AJ$11:AJ25)*31,) -> 4943.4667 | BH25: =IF(AN25<>0,AVERAGE(AN$11:AN25)*31,) -> 15276.8 | BI25: =IF(AR25<>0,AVERAGE(AR$11:AR25)*31,) -> 8994.1333
A26: =1+A25 -> 16 | B26: 00:00 | D26: 321049 | E26: =IF(ISBLANK(D26),0,D26-D25) -> 100 | F26: 7049 | G26: =IF(ISBLANK(F26),0,F26-F25) -> 2 | H26: 79802 | I26: =IF(ISBLANK(H26),0,H26-H25) -> 295 | J26: 595046 | K26: =IF(ISBLANK(J26),0,J26-J25) -> 284 | M26: =I26/L26 -> #DIV/0! | N26: 9757 | O26: =IF(ISBLANK(N26),0,N26-N25) -> 90 | P26: 93234 | Q26: =IF(ISBLANK(P26),0,P26-P25) -> 38 | R26: 35 | S26: =IF(ISBLANK(R26),0,R26-R25) -> 0 | T26: 196067 | U26: =IF(ISBLANK(T26),0,T26-T25) -> 68 | W26: =IF(ISBLANK(V26),0,SUM(V26-V25)*2200) -> 0 | X26: 18780 | Z26: =IF(ISBLANK(Y26),0,SUM(Y26-Y25)*2200) -> 0 | AA26: 3175 | AC26: =IF(ISBLANK(AB26),0,SUM(AB26-AB25)) -> 0 | AD26: 366 | AF26: =IF(ISBLANK(AE26),0,SUM(AE26-AE25)) -> 0 | AG26: 1222 | AI26: =IF(ISBLANK(AH26),0,SUM(AH26-AH25)*80) -> 0 | AJ26: 192 | AM26: =IF(ISBLANK(AL26),0,AL26-AL25) -> 0 | AN26: 439 | AR26: 288 | AS26: 24 | AT26: 24 | AW26: =IF(ISBLANK(AV26),0,AV26-AV25) -> 0 | AY26: =1+AY25 -> 16 | AZ26: =IF(D26<>0,(+D26-D$10)/A26*31,0) -> 4002.875 | BA26: =IF(F26<>0,(+F26-F$10)/$A26*31,0) -> 13.5625 | BB26: =IF(H26<>0,(+H26-H$10)/$A26*31,0) -> 8918.3125 | BC26: =IF(N26<>0,(+N26-N$10)/$A26*31,0) -> 2615.625 | BD26: =IF(V26<>0,(+V26-V$10)*2200/$A26*31,0) -> 0 | BE26: =IF(X26<>0,AVERAGE(X$11:X26)*31,) -> 562491.12 | BF26: =IF(AD26+AG26<>0,AVERAGE(AD$11:AD26)*31+AVERAGE(AG$11:AG26)*31,) -> 46841 | BG26: =IF(AJ26<>0,AVERAGE(AJ$11:AJ26)*31,) -> 5006.5 | BH26: =IF(AN26<>0,AVERAGE(AN$11:AN26)*31,) -> 15172.562 | BI26: =IF(AR26<>0,AVERAGE(AR$11:AR26)*31,) -> 8990
A27: =1+A26 -> 17 | B27: 00:00 | D27: 321175 | E27: =IF(ISBLANK(D27),0,D27-D26) -> 126 | F27: 7049 | G27: =IF(ISBLANK(F27),0,F27-F26) -> 0 | H27: 80101 | I27: =IF(ISBLANK(H27),0,H27-H26) -> 299 | J27: 595335 | K27: =IF(ISBLANK(J27),0,J27-J26) -> 289 | M27: =I27/L27 -> #DIV/0! | N27: 9849 | O27: =IF(ISBLANK(N27),0,N27-N26) -> 92 | P27: 93272 | Q27: =IF(ISBLANK(P27),0,P27-P26) -> 38 | R27: 35 | S27: =IF(ISBLANK(R27),0,R27-R26) -> 0 | T27: 196135 | U27: =IF(ISBLANK(T27),0,T27-T26) -> 68 | W27: =IF(ISBLANK(V27),0,SUM(V27-V26)*2200) -> 0 | X27: 18945 | Z27: =IF(ISBLANK(Y27),0,SUM(Y27-Y26)*2200) -> 0 | AA27: 3352 | AC27: =IF(ISBLANK(AB27),0,SUM(AB27-AB26)) -> 0 | AD27: 362 | AF27: =IF(ISBLANK(AE27),0,SUM(AE27-AE26)) -> 0 | AG27: 1137 | AI27: =IF(ISBLANK(AH27),0,SUM(AH27-AH26)*80) -> 0 | AJ27: 192 | AM27: =IF(ISBLANK(AL27),0,AL27-AL26) -> 0 | AN27: 478 | AR27: 368 | AS27: 25 | AT27: 29 | AW27: =IF(ISBLANK(AV27),0,AV27-AV26) -> 0 | AY27: =1+AY26 -> 17 | AZ27: =IF(D27<>0,(+D27-D$10)/A27*31,0) -> 3997.1765 | BA27: =IF(F27<>0,(+F27-F$10)/$A27*31,0) -> 12.764706 | BB27: =IF(H27<>0,(+H27-H$10)/$A27*31,0) -> 8938.9412 | BC27: =IF(N27<>0,(+N27-N$10)/$A27*31,0) -> 2629.5294 | BD27: =IF(V27<>0,(+V27-V$10)*2200/$A27*31,0) -> 0 | BE27: =IF(X27<>0,AVERAGE(X$11:X27)*31,) -> 563950.18 | BF27: =IF(AD27+AG27<>0,AVERAGE(AD$11:AD27)*31+AVERAGE(AG$11:AG27)*31,) -> 46819.118 | BG27: =IF(AJ27<>0,AVERAGE(AJ$11:AJ27)*31,) -> 5062.1176 | BH27: =IF(AN27<>0,AVERAGE(AN$11:AN27)*31,) -> 15151.706 | BI27: =IF(AR27<>0,AVERAGE(AR$11:AR27)*31,) -> 9132.2353
A28: =1+A27 -> 18 | B28: 00:00 | D28: 321343 | E28: =IF(ISBLANK(D28),0,D28-D27) -> 168 | F28: 7049 | G28: =IF(ISBLANK(F28),0,F28-F27) -> 0 | H28: 80419 | I28: =IF(ISBLANK(H28),0,H28-H27) -> 318 | J28: 595641 | K28: =IF(ISBLANK(J28),0,J28-J27) -> 306 | M28: =I28/L28 -> #DIV/0! | N28: 9946 | O28: =IF(ISBLANK(N28),0,N28-N27) -> 97 | P28: 93312 | Q28: =IF(ISBLANK(P28),0,P28-P27) -> 40 | R28: 35 | S28: =IF(ISBLANK(R28),0,R28-R27) -> 0 | T28: 196208 | U28: =IF(ISBLANK(T28),0,T28-T27) -> 73 | W28: =IF(ISBLANK(V28),0,SUM(V28-V27)*2200) -> 0 | X28: 18630 | Z28: =IF(ISBLANK(Y28),0,SUM(Y28-Y27)*2200) -> 0 | AA28: 2967 | AC28: =IF(ISBLANK(AB28),0,SUM(AB28-AB27)) -> 0 | AD28: 354 | AF28: =IF(ISBLANK(AE28),0,SUM(AE28-AE27)) -> 0 | AG28: 1101 | AI28: =IF(ISBLANK(AH28),0,SUM(AH28-AH27)*80) -> 0 | AJ28: 184 | AM28: =IF(ISBLANK(AL28),0,AL28-AL27) -> 0 | AN28: 486 | AR28: 312 | AS28: 21 | AT28: 33 | AW28: =IF(ISBLANK(AV28),0,AV28-AV27) -> 0 | AY28: =1+AY27 -> 18 | AZ28: =IF(D28<>0,(+D28-D$10)/A28*31,0) -> 4064.4444 | BA28: =IF(F28<>0,(+F28-F$10)/$A28*31,0) -> 12.055556 | BB28: =IF(H28<>0,(+H28-H$10)/$A28*31,0) -> 8990 | BC28: =IF(N28<>0,(+N28-N$10)/$A28*31,0) -> 2650.5 | BD28: =IF(V28<>0,(+V28-V$10)*2200/$A28*31,0) -> 0 | BE28: =IF(X28<>0,AVERAGE(X$11:X28)*31,) -> 564704.61 | BF28: =IF(AD28+AG28<>0,AVERAGE(AD$11:AD28)*31+AVERAGE(AG$11:AG28)*31,) -> 46723.889 | BG28: =IF(AJ28<>0,AVERAGE(AJ$11:AJ28)*31,) -> 5097.7778 | BH28: =IF(AN28<>0,AVERAGE(AN$11:AN28)*31,) -> 15146.944 | BI28: =IF(AR28<>0,AVERAGE(AR$11:AR28)*31,) -> 9162.2222
A29: =1+A28 -> 19 | B29: 00:00 | D29: 321443 | E29: =IF(ISBLANK(D29),0,D29-D28) -> 100 | F29: 7050 | G29: =IF(ISBLANK(F29),0,F29-F28) -> 1 | H29: 80769 | I29: =IF(ISBLANK(H29),0,H29-H28) -> 350 | J29: 595978 | K29: =IF(ISBLANK(J29),0,J29-J28) -> 337 | M29: =I29/L29 -> #DIV/0! | N29: 10037 | O29: =IF(ISBLANK(N29),0,N29-N28) -> 91 | P29: 93409 | Q29: =IF(ISBLANK(P29),0,P29-P28) -> 97 | R29: 35 | S29: =IF(ISBLANK(R29),0,R29-R28) -> 0 | T29: 196329 | U29: =IF(ISBLANK(T29),0,T29-T28) -> 121 | W29: =IF(ISBLANK(V29),0,SUM(V29-V28)*2200) -> 0 | X29: 18979 | Z29: =IF(ISBLANK(Y29),0,SUM(Y29-Y28)*2200) -> 0 | AA29: 2995 | AC29: =IF(ISBLANK(AB29),0,SUM(AB29-AB28)) -> 0 | AD29: 368 | AF29: =IF(ISBLANK(AE29),0,SUM(AE29-AE28)) -> 0 | AG29: 1288 | AI29: =IF(ISBLANK(AH29),0,SUM(AH29-AH28)*80) -> 0 | AJ29: 176 | AM29: =IF(ISBLANK(AL29),0,AL29-AL28) -> 0 | AN29: 456 | AR29: 280 | AS29: 25 | AT29: 35 | AW29: =IF(ISBLANK(AV29),0,AV29-AV28) -> 0 | AY29: =1+AY28 -> 19 | AZ29: =IF(D29<>0,(+D29-D$10)/A29*31,0) -> 4013.6842 | BA29: =IF(F29<>0,(+F29-F$10)/$A29*31,0) -> 13.052632 | BB29: =IF(H29<>0,(+H29-H$10)/$A29*31,0) -> 9087.8947 | BC29: =IF(N29<>0,(+N29-N$10)/$A29*31,0) -> 2659.4737 | BD29: =IF(V29<>0,(+V29-V$10)*2200/$A29*31,0) -> 0 | BE29: =IF(X29<>0,AVERAGE(X$11:X29)*31,) -> 565949.05 | BF29: =IF(AD29+AG29<>0,AVERAGE(AD$11:AD29)*31+AVERAGE(AG$11:AG29)*31,) -> 46966.632 | BG29: =IF(AJ29<>0,AVERAGE(AJ$11:AJ29)*31,) -> 5116.6316 | BH29: =IF(AN29<>0,AVERAGE(AN$11:AN29)*31,) -> 15093.737 | BI29: =IF(AR29<>0,AVERAGE(AR$11:AR29)*31,) -> 9136.8421
A30: =1+A29 -> 20 | B30: 00:00 | D30: 321613 | E30: =IF(ISBLANK(D30),0,D30-D29) -> 170 | F30: 7050 | G30: =IF(ISBLANK(F30),0,F30-F29) -> 0 | H30: 81133 | I30: =IF(ISBLANK(H30),0,H30-H29) -> 364 | J30: 596329 | K30: =IF(ISBLANK(J30),0,J30-J29) -> 351 | M30: =I30/L30 -> #DIV/0! | N30: 10128 | O30: =IF(ISBLANK(N30),0,N30-N29) -> 91 | P30: 93507 | Q30: =IF(ISBLANK(P30),0,P30-P29) -> 98 | R30: 35 | S30: =IF(ISBLANK(R30),0,R30-R29) -> 0 | T30: 196459 | U30: =IF(ISBLANK(T30),0,T30-T29) -> 130 | V30: 4904 | W30: =IF(ISBLANK(V30),0,SUM(V30-V29)*2200) -> 10788800 | X30: 18499 | Y30: 940 | Z30: =IF(ISBLANK(Y30),0,SUM(Y30-Y29)*2200) -> 2068000 | AA30: 2478 | AB30: 1742717 | AC30: =IF(ISBLANK(AB30),0,SUM(AB30-AB29)) -> 1742717 | AD30: 354 | AE30: 5144006 | AF30: =IF(ISBLANK(AE30),0,SUM(AE30-AE29)) -> 5144006 | AG30: 1246 | AH30: 34046 | AI30: =IF(ISBLANK(AH30),0,SUM(AH30-AH29)*80) -> 2723680 | AJ30: 168 | AL30: 197275 | AM30: =IF(ISBLANK(AL30),0,AL30-AL29) -> 197275 | AN30: 472 | AP30: 46675 | AR30: 296 | AS30: 25 | AT30: 37 | AW30: =IF(ISBLANK(AV30),0,AV30-AV29) -> 0 | AY30: =1+AY29 -> 20 | AZ30: =IF(D30<>0,(+D30-D$10)/A30*31,0) -> 4076.5 | BA30: =IF(F30<>0,(+F30-F$10)/$A30*31,0) -> 12.4 | BB30: =IF(H30<>0,(+H30-H$10)/$A30*31,0) -> 9197.7 | BC30: =IF(N30<>0,(+N30-N$10)/$A30*31,0) -> 2667.55 | BD30: =IF(V30<>0,(+V30-V$10)*2200/$A30*31,0) -> 578182.55 | BE30: =IF(X30<>0,AVERAGE(X$11:X30)*31,) -> 566325.05 | BF30: =IF(AD30+AG30<>0,AVERAGE(AD$11:AD30)*31+AVERAGE(AG$11:AG30)*31,) -> 47098.3 | BG30: =IF(AJ30<>0,AVERAGE(AJ$11:AJ30)*31,) -> 5121.2 | BH30: =IF(AN30<>0,AVERAGE(AN$11:AN30)*31,) -> 15070.65 | BI30: =IF(AR30<>0,AVERAGE(AR$11:AR30)*31,) -> 9138.8
A31: =1+A30 -> 21 | B31: 00:00 | D31: 321820 | E31: =IF(ISBLANK(D31),0,D31-D30) -> 207 | F31: 7050 | G31: =IF(ISBLANK(F31),0,F31-F30) -> 0 | H31: 81497 | I31: =IF(ISBLANK(H31),0,H31-H30) -> 364 | J31: 596680 | K31: =IF(ISBLANK(J31),0,J31-J30) -> 351 | M31: =I31/L31 -> #DIV/0! | N31: 10224 | O31: =IF(ISBLANK(N31),0,N31-N30) -> 96 | P31: 93607 | Q31: =IF(ISBLANK(P31),0,P31-P30) -> 100 | R31: 35 | S31: =IF(ISBLANK(R31),0,R31-R30) -> 0 | T31: 196588 | U31: =IF(ISBLANK(T31),0,T31-T30) -> 129 | W31: =IF(ISBLANK(V31),0,SUM(V31-V30)*2200) -> 0 | X31: 18723 | Z31: =IF(ISBLANK(Y31),0,SUM(Y31-Y30)*2200) -> 0 | AA31: 2839 | AC31: =IF(ISBLANK(AB31),0,SUM(AB31-AB30)) -> 0 | AD31: 354 | AF31: =IF(ISBLANK(AE31),0,SUM(AE31-AE30)) -> 0 | AG31: 1124 | AI31: =IF(ISBLANK(AH31),0,SUM(AH31-AH30)*80) -> 0 | AJ31: 184 | AM31: =IF(ISBLANK(AL31),0,AL31-AL30) -> 0 | AN31: 478 | AR31: 296 | AS31: 27 | AT31: 37 | AW31: =IF(ISBLANK(AV31),0,AV31-AV30) -> 0 | AY31: =1+AY30 -> 21 | AZ31: =IF(D31<>0,(+D31-D$10)/A31*31,0) -> 4187.9524 | BA31: =IF(F31<>0,(+F31-F$10)/$A31*31,0) -> 11.809524 | BB31: =IF(H31<>0,(+H31-H$10)/$A31*31,0) -> 9297.0476 | BC31: =IF(N31<>0,(+N31-N$10)/$A31*31,0) -> 2682.2381 | BD31: =IF(V31<>0,(+V31-V$10)*2200/$A31*31,0) -> 0 | BE31: =IF(X31<>0,AVERAGE(X$11:X31)*31,) -> 566995.9 | BF31: =IF(AD31+AG31<>0,AVERAGE(AD$11:AD31)*31+AVERAGE(AG$11:AG31)*31,) -> 47037.333 | BG31: =IF(AJ31<>0,AVERAGE(AJ$11:AJ31)*31,) -> 5148.9524 | BH31: =IF(AN31<>0,AVERAGE(AN$11:AN31)*31,) -> 15058.619 | BI31: =IF(AR31<>0,AVERAGE(AR$11:AR31)*31,) -> 9140.5714
A32: =1+A31 -> 22 | B32: 00:00 | D32: 322015 | E32: =IF(ISBLANK(D32),0,D32-D31) -> 195 | F32: 7050 | G32: =IF(ISBLANK(F32),0,F32-F31) -> 0 | H32: 81846 | I32: =IF(ISBLANK(H32),0,H32-H31) -> 349 | J32: 597016 | K32: =IF(ISBLANK(J32),0,J32-J31) -> 336 | M32: =I32/L32 -> #DIV/0! | N32: 10324 | O32: =IF(ISBLANK(N32),0,N32-N31) -> 100 | P32: 93705 | Q32: =IF(ISBLANK(P32),0,P32-P31) -> 98 | R32: 35 | S32: =IF(ISBLANK(R32),0,R32-R31) -> 0 | T32: 196708 | U32: =IF(ISBLANK(T32),0,T32-T31) -> 120 | W32: =IF(ISBLANK(V32),0,SUM(V32-V31)*2200) -> 0 | X32: 18867 | Z32: =IF(ISBLANK(Y32),0,SUM(Y32-Y31)*2200) -> 0 | AA32: 2787 | AC32: =IF(ISBLANK(AB32),0,SUM(AB32-AB31)) -> 0 | AD32: 362 | AF32: =IF(ISBLANK(AE32),0,SUM(AE32-AE31)) -> 0 | AG32: 1097 | AI32: =IF(ISBLANK(AH32),0,SUM(AH32-AH31)*80) -> 0 | AJ32: 160 | AM32: =IF(ISBLANK(AL32),0,AL32-AL31) -> 0 | AN32: 484 | AR32: 264 | AS32: 24 | AT32: 38 | AW32: =IF(ISBLANK(AV32),0,AV32-AV31) -> 0 | AY32: =1+AY31 -> 22 | AZ32: =IF(D32<>0,(+D32-D$10)/A32*31,0) -> 4272.3636 | BA32: =IF(F32<>0,(+F32-F$10)/$A32*31,0) -> 11.272727 | BB32: =IF(H32<>0,(+H32-H$10)/$A32*31,0) -> 9366.2273 | BC32: =IF(N32<>0,(+N32-N$10)/$A32*31,0) -> 2701.2273 | BD32: =IF(V32<>0,(+V32-V$10)*2200/$A32*31,0) -> 0 | BE32: =IF(X32<>0,AVERAGE(X$11:X32)*31,) -> 567808.68 | BF32: =IF(AD32+AG32<>0,AVERAGE(AD$11:AD32)*31+AVERAGE(AG$11:AG32)*31,) -> 46955.136 | BG32: =IF(AJ32<>0,AVERAGE(AJ$11:AJ32)*31,) -> 5140.3636 | BH32: =IF(AN32<>0,AVERAGE(AN$11:AN32)*31,) -> 15056.136 | BI32: =IF(AR32<>0,AVERAGE(AR$11:AR32)*31,) -> 9097.0909
A33: =1+A32 -> 23 | B33: 00:00 | D33: 322215 | E33: =IF(ISBLANK(D33),0,D33-D32) -> 200 | F33: 7050 | G33: =IF(ISBLANK(F33),0,F33-F32) -> 0 | H33: 82216 | I33: =IF(ISBLANK(H33),0,H33-H32) -> 370 | J33: 597374 | K33: =IF(ISBLANK(J33),0,J33-J32) -> 358 | M33: =I33/L33 -> #DIV/0! | N33: 10427 | O33: =IF(ISBLANK(N33),0,N33-N32) -> 103 | P33: 93807 | Q33: =IF(ISBLANK(P33),0,P33-P32) -> 102 | R33: 35 | S33: =IF(ISBLANK(R33),0,R33-R32) -> 0 | T33: 196837 | U33: =IF(ISBLANK(T33),0,T33-T32) -> 129 | W33: =IF(ISBLANK(V33),0,SUM(V33-V32)*2200) -> 0 | X33: 19488 | Z33: =IF(ISBLANK(Y33),0,SUM(Y33-Y32)*2200) -> 0 | AA33: 2894 | AC33: =IF(ISBLANK(AB33),0,SUM(AB33-AB32)) -> 0 | AD33: 341 | AF33: =IF(ISBLANK(AE33),0,SUM(AE33-AE32)) -> 0 | AG33: 1114 | AI33: =IF(ISBLANK(AH33),0,SUM(AH33-AH32)*80) -> 0 | AJ33: 184 | AM33: =IF(ISBLANK(AL33),0,AL33-AL32) -> 0 | AN33: 505 | AR33: 288 | AS33: 19 | AT33: 34 | AW33: =IF(ISBLANK(AV33),0,AV33-AV32) -> 0 | AY33: =1+AY32 -> 23 | AZ33: =IF(D33<>0,(+D33-D$10)/A33*31,0) -> 4356.1739 | BA33: =IF(F33<>0,(+F33-F$10)/$A33*31,0) -> 10.782609 | BB33: =IF(H33<>0,(+H33-H$10)/$A33*31,0) -> 9457.6957 | BC33: =IF(N33<>0,(+N33-N$10)/$A33*31,0) -> 2722.6087 | BD33: =IF(V33<>0,(+V33-V$10)*2200/$A33*31,0) -> 0 | BE33: =IF(X33<>0,AVERAGE(X$11:X33)*31,) -> 569387.78 | BF33: =IF(AD33+AG33<>0,AVERAGE(AD$11:AD33)*31+AVERAGE(AG$11:AG33)*31,) -> 46874.696 | BG33: =IF(AJ33<>0,AVERAGE(AJ$11:AJ33)*31,) -> 5164.8696 | BH33: =IF(AN33<>0,AVERAGE(AN$11:AN33)*31,) -> 15082.174 | BI33: =IF(AR33<>0,AVERAGE(AR$11:AR33)*31,) -> 9089.7391
A34: =1+A33 -> 24 | B34: 00:00 | D34: 322410 | E34: =IF(ISBLANK(D34),0,D34-D33) -> 195 | F34: 7050 | G34: =IF(ISBLANK(F34),0,F34-F33) -> 0 | H34: 82578 | I34: =IF(ISBLANK(H34),0,H34-H33) -> 362 | J34: 597722 | K34: =IF(ISBLANK(J34),0,J34-J33) -> 348 | M34: =I34/L34 -> #DIV/0! | N34: 10524 | O34: =IF(ISBLANK(N34),0,N34-N33) -> 97 | P34: 93905 | Q34: =IF(ISBLANK(P34),0,P34-P33) -> 98 | R34: 35 | S34: =IF(ISBLANK(R34),0,R34-R33) -> 0 | T34: 196965 | U34: =IF(ISBLANK(T34),0,T34-T33) -> 128 | W34: =IF(ISBLANK(V34),0,SUM(V34-V33)*2200) -> 0 | X34: 19664 | Z34: =IF(ISBLANK(Y34),0,SUM(Y34-Y33)*2200) -> 0 | AA34: 3303 | AC34: =IF(ISBLANK(AB34),0,SUM(AB34-AB33)) -> 0 | AD34: 348 | AF34: =IF(ISBLANK(AE34),0,SUM(AE34-AE33)) -> 0 | AG34: 1207 | AI34: =IF(ISBLANK(AH34),0,SUM(AH34-AH33)*80) -> 0 | AJ34: 192 | AM34: =IF(ISBLANK(AL34),0,AL34-AL33) -> 0 | AN34: 485 | AR34: 288 | AS34: 24 | AT34: 35 | AW34: =IF(ISBLANK(AV34),0,AV34-AV33) -> 0 | AY34: =1+AY33 -> 24 | AZ34: =IF(D34<>0,(+D34-D$10)/A34*31,0) -> 4426.5417 | BA34: =IF(F34<>0,(+F34-F$10)/$A34*31,0) -> 10.333333 | BB34: =IF(H34<>0,(+H34-H$10)/$A34*31,0) -> 9531.2083 | BC34: =IF(N34<>0,(+N34-N$10)/$A34*31,0) -> 2734.4583 | BD34: =IF(V34<>0,(+V34-V$10)*2200/$A34*31,0) -> 0 | BE34: =IF(X34<>0,AVERAGE(X$11:X34)*31,) -> 571062.62 | BF34: =IF(AD34+AG34<>0,AVERAGE(AD$11:AD34)*31+AVERAGE(AG$11:AG34)*31,) -> 46930.125 | BG34: =IF(AJ34<>0,AVERAGE(AJ$11:AJ34)*31,) -> 5197.6667 | BH34: =IF(AN34<>0,AVERAGE(AN$11:AN34)*31,) -> 15080.208 | BI34: =IF(AR34<>0,AVERAGE(AR$11:AR34)*31,) -> 9083
A35: =1+A34 -> 25 | B35: 00:00 | D35: 322566 | E35: =IF(ISBLANK(D35),0,D35-D34) -> 156 | F35: 7050 | G35: =IF(ISBLANK(F35),0,F35-F34) -> 0 | H35: 82940 | I35: =IF(ISBLANK(H35),0,H35-H34) -> 362 | J35: 598072 | K35: =IF(ISBLANK(J35),0,J35-J34) -> 350 | M35: =I35/L35 -> #DIV/0! | N35: 10627 | O35: =IF(ISBLANK(N35),0,N35-N34) -> 103 | P35: 94004 | Q35: =IF(ISBLANK(P35),0,P35-P34) -> 99 | R35: 35 | S35: =IF(ISBLANK(R35),0,R35-R34) -> 0 | T35: 197088 | U35: =IF(ISBLANK(T35),0,T35-T34) -> 123 | W35: =IF(ISBLANK(V35),0,SUM(V35-V34)*2200) -> 0 | X35: 19329 | Z35: =IF(ISBLANK(Y35),0,SUM(Y35-Y34)*2200) -> 0 | AA35: 2949 | AC35: =IF(ISBLANK(AB35),0,SUM(AB35-AB34)) -> 0 | AD35: 340 | AF35: =IF(ISBLANK(AE35),0,SUM(AE35-AE34)) -> 0 | AG35: 1091 | AI35: =IF(ISBLANK(AH35),0,SUM(AH35-AH34)*80) -> 0 | AJ35: 152 | AM35: =IF(ISBLANK(AL35),0,AL35-AL34) -> 0 | AN35: 493 | AR35: 264 | AS35: 24 | AT35: 35 | AW35: =IF(ISBLANK(AV35),0,AV35-AV34) -> 0 | AY35: =1+AY34 -> 25 | AZ35: =IF(D35<>0,(+D35-D$10)/A35*31,0) -> 4442.92 | BA35: =IF(F35<>0,(+F35-F$10)/$A35*31,0) -> 9.92 | BB35: =IF(H35<>0,(+H35-H$10)/$A35*31,0) -> 9598.84 | BC35: =IF(N35<>0,(+N35-N$10)/$A35*31,0) -> 2752.8 | BD35: =IF(V35<>0,(+V35-V$10)*2200/$A35*31,0) -> 0 | BE35: =IF(X35<>0,AVERAGE(X$11:X35)*31,) -> 572188.08 | BF35: =IF(AD35+AG35<>0,AVERAGE(AD$11:AD35)*31+AVERAGE(AG$11:AG35)*31,) -> 46827.36 | BG35: =IF(AJ35<>0,AVERAGE(AJ$11:AJ35)*31,) -> 5178.24 | BH35: =IF(AN35<>0,AVERAGE(AN$11:AN35)*31,) -> 15088.32 | BI35: =IF(AR35<>0,AVERAGE(AR$11:AR35)*31,) -> 9047.04
A36: =1+A35 -> 26 | B36: 00:00 | D36: 322707 | E36: =IF(ISBLANK(D36),0,D36-D35) -> 141 | F36: 7050 | G36: =IF(ISBLANK(F36),0,F36-F35) -> 0 | H36: 83304 | I36: =IF(ISBLANK(H36),0,H36-H35) -> 364 | J36: 598422 | K36: =IF(ISBLANK(J36),0,J36-J35) -> 350 | M36: =I36/L36 -> #DIV/0! | N36: 10723 | O36: =IF(ISBLANK(N36),0,N36-N35) -> 96 | P36: 94104 | Q36: =IF(ISBLANK(P36),0,P36-P35) -> 100 | R36: 35 | S36: =IF(ISBLANK(R36),0,R36-R35) -> 0 | T36: 197213 | U36: =IF(ISBLANK(T36),0,T36-T35) -> 125 | W36: =IF(ISBLANK(V36),0,SUM(V36-V35)*2200) -> 0 | X36: 19287 | Z36: =IF(ISBLANK(Y36),0,SUM(Y36-Y35)*2200) -> 0 | AA36: 2886 | AC36: =IF(ISBLANK(AB36),0,SUM(AB36-AB35)) -> 0 | AD36: 347 | AF36: =IF(ISBLANK(AE36),0,SUM(AE36-AE35)) -> 0 | AG36: 1069 | AI36: =IF(ISBLANK(AH36),0,SUM(AH36-AH35)*80) -> 0 | AJ36: 160 | AM36: =IF(ISBLANK(AL36),0,AL36-AL35) -> 0 | AN36: 497 | AR36: 256 | AS36: 23 | AT36: 32 | AW36: =IF(ISBLANK(AV36),0,AV36-AV35) -> 0 | AY36: =1+AY35 -> 26 | AZ36: =IF(D36<>0,(+D36-D$10)/A36*31,0) -> 4440.1538 | BA36: =IF(F36<>0,(+F36-F$10)/$A36*31,0) -> 9.5384615 | BB36: =IF(H36<>0,(+H36-H$10)/$A36*31,0) -> 9663.6538 | BC36: =IF(N36<>0,(+N36-N$10)/$A36*31,0) -> 2761.3846 | BD36: =IF(V36<>0,(+V36-V$10)*2200/$A36*31,0) -> 0 | BE36: =IF(X36<>0,AVERAGE(X$11:X36)*31,) -> 573176.88 | BF36: =IF(AD36+AG36<>0,AVERAGE(AD$11:AD36)*31+AVERAGE(AG$11:AG36)*31,) -> 46714.615 | BG36: =IF(AJ36<>0,AVERAGE(AJ$11:AJ36)*31,) -> 5169.8462 | BH36: =IF(AN36<>0,AVERAGE(AN$11:AN36)*31,) -> 15100.577 | BI36: =IF(AR36<>0,AVERAGE(AR$11:AR36)*31,) -> 9004.3077
A37: =1+A36 -> 27 | B37: 00:00 | D37: 322918 | E37: =IF(ISBLANK(D37),0,D37-D36) -> 211 | F37: 7050 | G37: =IF(ISBLANK(F37),0,F37-F36) -> 0 | H37: 83652 | I37: =IF(ISBLANK(H37),0,H37-H36) -> 348 | J37: 598758 | K37: =IF(ISBLANK(J37),0,J37-J36) -> 336 | M37: =I37/L37 -> #DIV/0! | N37: 10806 | O37: =IF(ISBLANK(N37),0,N37-N36) -> 83 | P37: 94203 | Q37: =IF(ISBLANK(P37),0,P37-P36) -> 99 | R37: 35 | S37: =IF(ISBLANK(R37),0,R37-R36) -> 0 | T37: 197342 | U37: =IF(ISBLANK(T37),0,T37-T36) -> 129 | W37: =IF(ISBLANK(V37),0,SUM(V37-V36)*2200) -> 0 | X37: 18162 | Z37: =IF(ISBLANK(Y37),0,SUM(Y37-Y36)*2200) -> 0 | AA37: 2841 | AC37: =IF(ISBLANK(AB37),0,SUM(AB37-AB36)) -> 0 | AD37: 347 | AF37: =IF(ISBLANK(AE37),0,SUM(AE37-AE36)) -> 0 | AG37: 1073 | AI37: =IF(ISBLANK(AH37),0,SUM(AH37-AH36)*80) -> 0 | AJ37: 152 | AM37: =IF(ISBLANK(AL37),0,AL37-AL36) -> 0 | AN37: 445 | AR37: 240 | AS37: 22 | AT37: 30 | AW37: =IF(ISBLANK(AV37),0,AV37-AV36) -> 0 | AY37: =1+AY36 -> 27 | AZ37: =IF(D37<>0,(+D37-D$10)/A37*31,0) -> 4517.963 | BA37: =IF(F37<>0,(+F37-F$10)/$A37*31,0) -> 9.1851852 | BB37: =IF(H37<>0,(+H37-H$10)/$A37*31,0) -> 9705.2963 | BC37: =IF(N37<>0,(+N37-N$10)/$A37*31,0) -> 2754.4074 | BD37: =IF(V37<>0,(+V37-V$10)*2200/$A37*31,0) -> 0 | BE37: =IF(X37<>0,AVERAGE(X$11:X37)*31,) -> 572800.78 | BF37: =IF(AD37+AG37<>0,AVERAGE(AD$11:AD37)*31+AVERAGE(AG$11:AG37)*31,) -> 46614.815 | BG37: =IF(AJ37<>0,AVERAGE(AJ$11:AJ37)*31,) -> 5152.8889 | BH37: =IF(AN37<>0,AVERAGE(AN$11:AN37)*31,) -> 15052.222 | BI37: =IF(AR37<>0,AVERAGE(AR$11:AR37)*31,) -> 8946.3704
A38: =1+A37 -> 28 | B38: 00:00 | D38: 323136 | E38: =IF(ISBLANK(D38),0,D38-D37) -> 218 | F38: 7050 | G38: =IF(ISBLANK(F38),0,F38-F37) -> 0 | H38: 84009 | I38: =IF(ISBLANK(H38),0,H38-H37) -> 357 | J38: 599202 | K38: =IF(ISBLANK(J38),0,J38-J37) -> 444 | M38: =I38/L38 -> #DIV/0! | N38: 10892 | O38: =IF(ISBLANK(N38),0,N38-N37) -> 86 | P38: 94301 | Q38: =IF(ISBLANK(P38),0,P38-P37) -> 98 | R38: 36 | S38: =IF(ISBLANK(R38),0,R38-R37) -> 1 | T38: 197472 | U38: =IF(ISBLANK(T38),0,T38-T37) -> 130 | W38: =IF(ISBLANK(V38),0,SUM(V38-V37)*2200) -> 0 | X38: 18511 | Z38: =IF(ISBLANK(Y38),0,SUM(Y38-Y37)*2200) -> 0 | AA38: 2991 | AC38: =IF(ISBLANK(AB38),0,SUM(AB38-AB37)) -> 0 | AD38: 355 | AF38: =IF(ISBLANK(AE38),0,SUM(AE38-AE37)) -> 0 | AG38: 1076 | AI38: =IF(ISBLANK(AH38),0,SUM(AH38-AH37)*80) -> 0 | AJ38: 152 | AM38: =IF(ISBLANK(AL38),0,AL38-AL37) -> 0 | AN38: 434 | AR38: 288 | AS38: 19 | AT38: 31 | AW38: =IF(ISBLANK(AV38),0,AV38-AV37) -> 0 | AY38: =1+AY37 -> 28 | AZ38: =IF(D38<>0,(+D38-D$10)/A38*31,0) -> 4597.9643 | BA38: =IF(F38<>0,(+F38-F$10)/$A38*31,0) -> 8.8571429 | BB38: =IF(H38<>0,(+H38-H$10)/$A38*31,0) -> 9753.9286 | BC38: =IF(N38<>0,(+N38-N$10)/$A38*31,0) -> 2751.25 | BD38: =IF(V38<>0,(+V38-V$10)*2200/$A38*31,0) -> 0 | BE38: =IF(X38<>0,AVERAGE(X$11:X38)*31,) -> 572837.93 | BF38: =IF(AD38+AG38<>0,AVERAGE(AD$11:AD38)*31+AVERAGE(AG$11:AG38)*31,) -> 46534.321 | BG38: =IF(AJ38<>0,AVERAGE(AJ$11:AJ38)*31,) -> 5137.1429 | BH38: =IF(AN38<>0,AVERAGE(AN$11:AN38)*31,) -> 14995.143 | BI38: =IF(AR38<>0,AVERAGE(AR$11:AR38)*31,) -> 8945.7143
A39: =1+A38 -> 29 | B39: 00:00 | D39: 323339 | E39: =IF(ISBLANK(D39),0,D39-D38) -> 203 | F39: 7050 | G39: =IF(ISBLANK(F39),0,F39-F38) -> 0 | H39: 84341 | I39: =IF(ISBLANK(H39),0,H39-H38) -> 332 | J39: 599422 | K39: =IF(ISBLANK(J39),0,J39-J38) -> 220 | M39: =I39/L39 -> #DIV/0! | N39: 10952 | O39: =IF(ISBLANK(N39),0,N39-N38) -> 60 | P39: 94390 | Q39: =IF(ISBLANK(P39),0,P39-P38) -> 89 | R39: 36 | S39: =IF(ISBLANK(R39),0,R39-R38) -> 0 | T39: 197585 | U39: =IF(ISBLANK(T39),0,T39-T38) -> 113 | W39: =IF(ISBLANK(V39),0,SUM(V39-V38)*2200) -> 0 | X39: 18080 | Z39: =IF(ISBLANK(Y39),0,SUM(Y39-Y38)*2200) -> 0 | AA39: 2809 | AC39: =IF(ISBLANK(AB39),0,SUM(AB39-AB38)) -> 0 | AD39: 349 | AF39: =IF(ISBLANK(AE39),0,SUM(AE39-AE38)) -> 0 | AG39: 1187 | AI39: =IF(ISBLANK(AH39),0,SUM(AH39-AH38)*80) -> 0 | AJ39: 176 | AM39: =IF(ISBLANK(AL39),0,AL39-AL38) -> 0 | AN39: 474 | AR39: 328 | AS39: 20 | AT39: 25 | AW39: =IF(ISBLANK(AV39),0,AV39-AV38) -> 0 | AY39: =1+AY38 -> 29 | AZ39: =IF(D39<>0,(+D39-D$10)/A39*31,0) -> 4656.4138 | BA39: =IF(F39<>0,(+F39-F$10)/$A39*31,0) -> 8.5517241 | BB39: =IF(H39<>0,(+H39-H$10)/$A39*31,0) -> 9772.4828 | BC39: =IF(N39<>0,(+N39-N$10)/$A39*31,0) -> 2720.5172 | BD39: =IF(V39<>0,(+V39-V$10)*2200/$A39*31,0) -> 0 | BE39: =IF(X39<>0,AVERAGE(X$11:X39)*31,) -> 572411.79 | BF39: =IF(AD39+AG39<>0,AVERAGE(AD$11:AD39)*31+AVERAGE(AG$11:AG39)*31,) -> 46571.621 | BG39: =IF(AJ39<>0,AVERAGE(AJ$11:AJ39)*31,) -> 5148.1379 | BH39: =IF(AN39<>0,AVERAGE(AN$11:AN39)*31,) -> 14984.759 | BI39: =IF(AR39<>0,AVERAGE(AR$11:AR39)*31,) -> 8987.8621
A40: =1+A39 -> 30 | B40: 00:00 | D40: 323554 | E40: =IF(ISBLANK(D40),0,D40-D39) -> 215 | F40: 7050 | G40: =IF(ISBLANK(F40),0,F40-F39) -> 0 | H40: 84671 | I40: =IF(ISBLANK(H40),0,H40-H39) -> 330 | J40: 599740 | K40: =IF(ISBLANK(J40),0,J40-J39) -> 318 | M40: =I40/L40 -> #DIV/0! | N40: 11020 | O40: =IF(ISBLANK(N40),0,N40-N39) -> 68 | P40: 94492 | Q40: =IF(ISBLANK(P40),0,P40-P39) -> 102 | R40: 36 | S40: =IF(ISBLANK(R40),0,R40-R39) -> 0 | T40: 197716 | U40: =IF(ISBLANK(T40),0,T40-T39) -> 131 | W40: =IF(ISBLANK(V40),0,SUM(V40-V39)*2200) -> 0 | X40: 17203 | Z40: =IF(ISBLANK(Y40),0,SUM(Y40-Y39)*2200) -> 0 | AA40: 2983 | AC40: =IF(ISBLANK(AB40),0,SUM(AB40-AB39)) -> 0 | AD40: 343 | AF40: =IF(ISBLANK(AE40),0,SUM(AE40-AE39)) -> 0 | AG40: 1164 | AI40: =IF(ISBLANK(AH40),0,SUM(AH40-AH39)*80) -> 0 | AJ40: 160 | AM40: =IF(ISBLANK(AL40),0,AL40-AL39) -> 0 | AN40: 477 | AR40: 264 | AS40: 26 | AT40: 32 | AW40: =IF(ISBLANK(AV40),0,AV40-AV39) -> 0 | AY40: =1+AY39 -> 30 | AZ40: =IF(D40<>0,(+D40-D$10)/A40*31,0) -> 4723.3667 | BA40: =IF(F40<>0,(+F40-F$10)/$A40*31,0) -> 8.2666667 | BB40: =IF(H40<>0,(+H40-H$10)/$A40*31,0) -> 9787.7333 | BC40: =IF(N40<>0,(+N40-N$10)/$A40*31,0) -> 2700.1 | BD40: =IF(V40<>0,(+V40-V$10)*2200/$A40*31,0) -> 0 | BE40: =IF(X40<>0,AVERAGE(X$11:X40)*31,) -> 571107.83 | BF40: =IF(AD40+AG40<>0,AVERAGE(AD$11:AD40)*31+AVERAGE(AG$11:AG40)*31,) -> 46576.467 | BG40: =IF(AJ40<>0,AVERAGE(AJ$11:AJ40)*31,) -> 5141.8667 | BH40: =IF(AN40<>0,AVERAGE(AN$11:AN40)*31,) -> 14978.167 | BI40: =IF(AR40<>0,AVERAGE(AR$11:AR40)*31,) -> 8961.0667
