Workbook

Sheet TOTAL
A1: Site Name | B1: Day | C1: Month | D1: Year | E1: Total Electricity Kwh | F1: Electricity Tariff ($/Kwh) | G1: LPG (Kg) | H1: LPG $/Kg | I1: Total Fuel Oil (Liters) | J1: Fuel Oil $/Liter | K1: Water Utility Supply (m3) m3 | L1: Water Utility Supply (m3) $/m3 | M1: Room Nights | N1: Food Covers | O1: Total Guests | P1: Other fleets Petrol (Litres)
A2: Maldives at Landaa Giraavaru | B2: 1 | C2: 3 | D2: 2023 | E2: ='Daily Utility Report'!F8 -> 30677 | F2: 0.354 | G2: ='Daily Utility Report'!H8 -> 225 | H2: 1.15 | I2: ='Diesel consumption'!C8 -> 7750 | J2: 1.3 | K2: ='Daily Utility Report'!G8 -> 350 | L2: 0 | M2: ='Room Nights & Food Covers'!B5 -> 57 | N2: ='Room Nights & Food Covers'!D5 -> 334 | O2: ='Room Nights & Food Covers'!C5 -> 123 | P2: ='Diesel consumption'!F8+'Diesel consumption'!M8 -> 1300
A3: Maldives at Landaa Giraavaru | B3: 2 | C3: 3 | D3: 2023 | E3: ='Daily Utility Report'!F9 -> 31340 | F3: 0.354 | G3: ='Daily Utility Report'!H9 -> 225 | H3: 1.15 | I3: ='Diesel consumption'!C9 -> 7890 | J3: 1.3 | K3: ='Daily Utility Report'!G9 -> 341 | L3: 0 | M3: ='Room Nights & Food Covers'!B6 -> 57 | N3: ='Room Nights & Food Covers'!D6 -> 360 | O3: ='Room Nights & Food Covers'!C6 -> 125 | P3: ='Diesel consumption'!F9+'Diesel consumption'!M9 -> 5190
A4: Maldives at Landaa Giraavaru | B4: 3 | C4: 3 | D4: 2023 | E4: ='Daily Utility Report'!F10 -> 31078 | F4: 0.354 | G4: ='Daily Utility Report'!H10 -> 315 | H4: 1.15 | I4: ='Diesel consumption'!C10 -> 7780 | J4: 1.3 | K4: ='Daily Utility Report'!G10 -> 338 | L4: 0 | M4: ='Room Nights & Food Covers'!B7 -> 58 | N4: ='Room Nights & Food Covers'!D7 -> 355 | O4: ='Room Nights & Food Covers'!C7 -> 128 | P4: ='Diesel consumption'!F10+'Diesel consumption'!M10 -> 1380
A5: Maldives at Landaa Giraavaru | B5: 4 | C5: 3 | D5: 2023 | E5: ='Daily Utility Report'!F11 -> 30229 | F5: 0.354 | G5: ='Daily Utility Report'!H11 -> 270 | H5: 1.15 | I5: ='Diesel consumption'!C11 -> 7580 | J5: 1.3 | K5: ='Daily Utility Report'!G11 -> 377 | L5: 0 | M5: ='Room Nights & Food Covers'!B8 -> 59 | N5: ='Room Nights & Food Covers'!D8 -> 358 | O5: ='Room Nights & Food Covers'!C8 -> 124 | P5: ='Diesel consumption'!F11+'Diesel consumption'!M11 -> 2640
A6: Maldives at Landaa Giraavaru | B6: 5 | C6: 3 | D6: 2023 | E6: ='Daily Utility Report'!F12 -> 28828 | F6: 0.354 | G6: ='Daily Utility Report'!H12 -> 270 | H6: 1.15 | I6: ='Diesel consumption'!C12 -> 7360 | J6: 1.3 | K6: ='Daily Utility Report'!G12 -> 298 | L6: 0 | M6: ='Room Nights & Food Covers'!B9 -> 56 | N6: ='Room Nights & Food Covers'!D9 -> 344 | O6: ='Room Nights & Food Covers'!C9 -> 126 | P6: ='Diesel consumption'!F12+'Diesel consumption'!M12 -> 1200
A7: Maldives at Landaa Giraavaru | B7: 6 | C7: 3 | D7: 2023 | E7: ='Daily Utility Report'!F13 -> 26740 | F7: 0.354 | G7: ='Daily Utility Report'!H13 -> 180 | H7: 1.15 | I7: ='Diesel consumption'!C13 -> 7070 | J7: 1.3 | K7: ='Daily Utility Report'!G13 -> 297 | L7: 0 | M7: ='Room Nights & Food Covers'!B10 -> 63 | N7: ='Room Nights & Food Covers'!D10 -> 393 | O7: ='Room Nights & Food Covers'!C10 -> 135 | P7: ='Diesel consumption'!F13+'Diesel consumption'!M13 -> 3950
A8: Maldives at Landaa Giraavaru | B8: 7 | C8: 3 | D8: 2023 | E8: ='Daily Utility Report'!F14 -> 29279 | F8: 0.354 | G8: ='Daily Utility Report'!H14 -> 315 | H8: 1.15 | I8: ='Diesel consumption'!C14 -> 6410 | J8: 1.3 | K8: ='Daily Utility Report'!G14 -> 344 | L8: 0 | M8: ='Room Nights & Food Covers'!B11 -> 61 | N8: ='Room Nights & Food Covers'!D11 -> 363 | O8: ='Room Nights & Food Covers'!C11 -> 139 | P8: ='Diesel consumption'!F14+'Diesel consumption'!M14 -> 1460
A9: Maldives at Landaa Giraavaru | B9: 8 | C9: 3 | D9: 2023 | E9: ='Daily Utility Report'!F15 -> 31410 | F9: 0.354 | G9: ='Daily Utility Report'!H15 -> 135 | H9: 1.15 | I9: ='Diesel consumption'!C15 -> 9460 | J9: 1.3 | K9: ='Daily Utility Report'!G15 -> 351 | L9: 0 | M9: ='Room Nights & Food Covers'!B12 -> 0 | N9: ='Room Nights & Food Covers'!D12 -> 0 | O9: ='Room Nights & Food Covers'!C12 -> 0 | P9: ='Diesel consumption'!F15+'Diesel consumption'!M15 -> 1290
A10: Maldives at Landaa Giraavaru | B10: 9 | C10: 3 | D10: 2023 | E10: ='Daily Utility Report'!F16 -> 0 | F10: 0.354 | G10: ='Daily Utility Report'!H16 -> 0 | H10: 1.15 | I10: ='Diesel consumption'!C16 -> 0 | J10: 1.3 | K10: ='Daily Utility Report'!G16 -> 0 | L10: 0 | M10: ='Room Nights & Food Covers'!B13 -> 0 | N10: ='Room Nights & Food Covers'!D13 -> 0 | O10: ='Room Nights & Food Covers'!C13 -> 0 | P10: ='Diesel consumption'!F16+'Diesel consumption'!M16 -> 0
A11: Maldives at Landaa Giraavaru | B11: 10 | C11: 3 | D11: 2023 | E11: ='Daily Utility Report'!F17 -> 0 | F11: 0.354 | G11: ='Daily Utility Report'!H17 -> 0 | H11: 1.15 | I11: ='Diesel consumption'!C17 -> 0 | J11: 1.3 | K11: ='Daily Utility Report'!G17 -> 0 | L11: 0 | M11: ='Room Nights & Food Covers'!B14 -> 0 | N11: ='Room Nights & Food Covers'!D14 -> 0 | O11: ='Room Nights & Food Covers'!C14 -> 0 | P11: ='Diesel consumption'!F17+'Diesel consumption'!M17 -> 0
A12: Maldives at Landaa Giraavaru | B12: 11 | C12: 3 | D12: 2023 | E12: ='Daily Utility Report'!F18 -> 0 | F12: 0.354 | G12: ='Daily Utility Report'!H18 -> 0 | H12: 1.15 | I12: ='Diesel consumption'!C18 -> 0 | J12: 1.3 | K12: ='Daily Utility Report'!G18 -> 0 | L12: 0 | M12: ='Room Nights & Food Covers'!B15 -> 0 | N12: ='Room Nights & Food Covers'!D15 -> 0 | O12: ='Room Nights & Food Covers'!C15 -> 0 | P12: ='Diesel consumption'!F18+'Diesel consumption'!M18 -> 0
A13: Maldives at Landaa Giraavaru | B13: 12 | C13: 3 | D13: 2023 | E13: ='Daily Utility Report'!F19 -> 0 | F13: 0.354 | G13: ='Daily Utility Report'!H19 -> 0 | H13: 1.15 | I13: ='Diesel consumption'!C19 -> 0 | J13: 1.3 | K13: ='Daily Utility Report'!G19 -> 0 | L13: 0 | M13: ='Room Nights & Food Covers'!B16 -> 0 | N13: ='Room Nights & Food Covers'!D16 -> 0 | O13: ='Room Nights & Food Covers'!C16 -> 0 | P13: ='Diesel consumption'!F19+'Diesel consumption'!M19 -> 0
... A32: Maldives at Landaa Giraavaru | B32: 31 | C32: 3 | D32: 2023 | E32: ='Daily Utility Report'!F38 -> 0 | F32: 3.354 | G32: ='Daily Utility Report'!H38 -> 0 | H32: 1.15 | I32: ='Diesel consumption'!C38 -> 0 | J32: 4.3 | K32: ='Daily Utility Report'!G38 -> 0 | L32: 3 | M32: ='Room Nights & Food Covers'!B35 -> 0 | N32: ='Room Nights & Food Covers'!D35 -> 0 | O32: ='Room Nights & Food Covers'!C35 -> 0 | P32: ='Diesel consumption'!F38+'Diesel consumption'!M38 -> 0

Sheet Submetering 
A1: Site Name | B1: Day | C1: Month | D1: Year | E1: Solar | F1: GENSET NO 1 | G1: GENSET NO 2 | H1: GENSET NO 3 | I1: GENSET NO 4 | J1: GENSET NO 5 | K1: Main BLU FEEDER PANEL 1 | L1: Main BLU FEEDER PANEL 2 | M1: Main POWER HOUSE FEEDER PANEL NO:3 | N1: Main Kitchen -7 | O1: Main Kitchen -10 | P1: Water treatment Plant | Q1: Sewage treatment Plant | R1: Laundry--8SSB (Machineries) | S1: Laundry-9 (HR/Tuck Shop Building) | T1: New staff accomodation (E0) | U1: Staff block-16(E2-E3) | V1: Staff Block Feeder-3(E4-E5) | W1: Management block-5 (M1 to M6) | X1: SNR STAFF BLOCK (PC Block) | Y1: BOAT DOCK FEEDER - 22 | Z1: RECEPTION Building Full (Finance/Reservation) | AA1: DIVE CENTER (Inc MDC and Recreation) | AB1: 301-307 | AC1: 308-314 | AD1: 315-320 | AE1: 401-407 | AF1: 408-414 | AG1: 415-420 | AH1: SPA - 1 | AI1: SPA - 2 | AJ1: BLU KITCHEN - 1 | AK1: BLU KITCHEN - 2 | AL1: AL BARAKATH | AM1: STAFF KITCHEN | AN1: R/O Plant A | AO1: R/O Plant B | AP1: R/O Plant C | AQ1: R/O Plant D | AR1: Laundry | AS1: Staff Block - E0 | AT1: Staff Block - E1 | AU1: Staff Block - E2 | AV1: Staff Block - E3 | AW1: Staff Block - E4 | AX1: Staff Block - E5 | AY1: Management Block | AZ1: PC Block | BA1: GM Bungalow | BB1: Boat Dock | BC1: Supply Jetty | BD1: Main Kitchen | BE1: Day Facility | BF1: Reception | BG1: Main Pool | BH1: Dive Center | BI1: Albarakthu | BJ1: Blu Resturant | BK1: Main Jetty | BL1: Landaa Estate | BM1: ROOM NIGHTS | BN1: Total Food Covers
A2: Maldives at Landaa Giraavaru | B2: 1 | C2: =TOTAL!C2 -> 3 | D2: =TOTAL!D2 -> 2023 | E2: =Solar!C6 -> 3199 | F2: ='Powerhouse Daily Performance'!C4 -> 4913 | G2: ='Powerhouse Daily Performance'!I4 -> 10599 | H2: ='Powerhouse Daily Performance'!O4 -> 4211 | I2: ='Powerhouse Daily Performance'!U4 -> 2300 | J2: ='Powerhouse Daily Performance'!AA4 -> 5455 | K2: ='FEEDER Consumption '!C6 -> 4504 | L2: ='FEEDER Consumption '!E6 -> 4773 | M2: ='FEEDER Consumption '!G6 -> 11643 | N2: ='FEEDER Consumption '!I6 -> 2300 | O2: ='FEEDER Consumption '!K6 -> 2939 | P2: ='FEEDER Consumption '!M6 -> 1600 | Q2: ='FEEDER Consumption '!O6 -> 433 | R2: ='FEEDER Consumption '!Q6 -> 700 | S2: ='FEEDER Consumption '!S6 -> 1700 | T2: ='FEEDER Consumption '!U6 -> 456 | U2: ='FEEDER Consumption '!W6 -> 400 | V2: ='FEEDER Consumption '!Y6 -> 300 | W2: ='FEEDER Consumption '!AA6 -> 600 | X2: ='FEEDER Consumption '!AC6 -> 140 | Y2: ='FEEDER Consumption '!AE6 -> 380 | Z2: ='FEEDER Consumption '!AG6 -> 1200 | AA2: ='FEEDER Consumption '!AI6 -> 430 | AB2: ='FEEDER Consumption '!AK6 -> 1140 | AC2: ='FEEDER Consumption '!AM6 -> 950 | AD2: ='FEEDER Consumption '!AO6 -> 720 | AE2: ='FEEDER Consumption '!AQ6 -> 1100 | AF2: ='FEEDER Consumption '!AS6 -> 1070 | AG2: ='FEEDER Consumption '!AU6 -> 640 | AH2: ='FEEDER Consumption '!AW6 -> 360 | AI2: ='FEEDER Consumption '!AY6 -> 150 | AJ2: ='FEEDER Consumption '!BA6 -> 1050 | AK2: ='FEEDER Consumption '!BC6 -> 270 | AL2: ='FEEDER Consumption '!BE6 -> 400 | AM2: ='FEEDER Consumption '!BG6 -> 490 | AN2: ='Water Plant Daily Performance'!C4 -> 179 | AO2: ='Water Plant Daily Performance'!I4 -> 0 | AP2: ='Water Plant Daily Performance'!O4 -> 161 | AQ2: ='Water Plant Daily Performance'!U4 -> 10 | AR2: =Water!AD7 -> 25 | AS2: =Water!AH7 -> 6 | AT2: =Water!AJ7 -> 9 | AU2: =Water!AL7 -> 10 | AV2: =Water!AN7 -> 6 | AW2: =Water!AP7 -> 5 | AX2: =Water!AR7 -> 7 | AY2: =Water!AT7 -> 8 | AZ2: =Water!AT7 -> 8 | BA2: =Water!AX7 -> 0 | BB2: =Water!AZ7 -> 3 | BC2: =Water!BB7 -> 2 | BD2: =Water!BD7 -> 28 | BE2: =Water!BF7 -> 8 | BF2: =Water!BH7 -> 1 | BG2: =Water!BJ7 -> 8 | BH2: =Water!BL7 -> 3 | BI2: =Water!BP7 -> 2 | BJ2: =Water!BR7 -> 15 | BK2: =Water!BT7 -> 1 | BL2: =Water!BV7 -> 1 | BM2: ='Room Nights & Food Covers'!B5 -> 57 | BN2: ='Room Nights & Food Covers'!D5 -> 334
A3: Maldives at Landaa Giraavaru | B3: 2 | C3: =TOTAL!C3 -> 3 | D3: =TOTAL!D3 -> 2023 | E3: =Solar!C7 -> 2956 | F3: ='Powerhouse Daily Performance'!C5 -> 6424 | G3: ='Powerhouse Daily Performance'!I5 -> 8247 | H3: ='Powerhouse Daily Performance'!O5 -> 6657 | I3: ='Powerhouse Daily Performance'!U5 -> 2406 | J3: ='Powerhouse Daily Performance'!AA5 -> 4650 | K3: ='FEEDER Consumption '!C7 -> 4442 | L3: ='FEEDER Consumption '!E7 -> 4885 | M3: ='FEEDER Consumption '!G7 -> 12500 | N3: ='FEEDER Consumption '!I7 -> 2400 | O3: ='FEEDER Consumption '!K7 -> 2988 | P3: ='FEEDER Consumption '!M7 -> 1900 | Q3: ='FEEDER Consumption '!O7 -> 462 | R3: ='FEEDER Consumption '!Q7 -> 700 | S3: ='FEEDER Consumption '!S7 -> 1800 | T3: ='FEEDER Consumption '!U7 -> 483 | U3: ='FEEDER Consumption '!W7 -> 400 | V3: ='FEEDER Consumption '!Y7 -> 400 | W3: ='FEEDER Consumption '!AA7 -> 700 | X3: ='FEEDER Consumption '!AC7 -> 160 | Y3: ='FEEDER Consumption '!AE7 -> 390 | Z3: ='FEEDER Consumption '!AG7 -> 1200 | AA3: ='FEEDER Consumption '!AI7 -> 430 | AB3: ='FEEDER Consumption '!AK7 -> 1200 | AC3: ='FEEDER Consumption '!AM7 -> 950 | AD3: ='FEEDER Consumption '!AO7 -> 820 | AE3: ='FEEDER Consumption '!AQ7 -> 1000 | AF3: ='FEEDER Consumption '!AS7 -> 970 | AG3: ='FEEDER Consumption '!AU7 -> 640 | AH3: ='FEEDER Consumption '!AW7 -> 350 | AI3: ='FEEDER Consumption '!AY7 -> 150 | AJ3: ='FEEDER Consumption '!BA7 -> 1030 | AK3: ='FEEDER Consumption '!BC7 -> 260 | AL3: ='FEEDER Consumption '!BE7 -> 440 | AM3: ='FEEDER Consumption '!BG7 -> 500 | AN3: ='Water Plant Daily Performance'!C5 -> 159 | AO3: ='Water Plant Daily Performance'!I5 -> 29 | AP3: ='Water Plant Daily Performance'!O5 -> 151 | AQ3: ='Water Plant Daily Performance'!U5 -> 2 | AR3: =Water!AD8 -> 27 | AS3: =Water!AH8 -> 4 | AT3: =Water!AJ8 -> 8 | AU3: =Water!AL8 -> 11 | AV3: =Water!AN8 -> 10 | AW3: =Water!AP8 -> 5 | AX3: =Water!AR8 -> 10 | AY3: =Water!AT8 -> 9 | AZ3: =Water!AT8 -> 9 | BA3: =Water!AX8 -> 6 | BB3: =Water!AZ8 -> 3 | BC3: =Water!BB8 -> 4 | BD3: =Water!BD8 -> 26 | BE3: =Water!BF8 -> 11 | BF3: =Water!BH8 -> 0 | BG3: =Water!BJ8 -> 11 | BH3: =Water!BL8 -> 4 | BI3: =Water!BP8 -> 6 | BJ3: =Water!BR8 -> 18 | BK3: =Water!BT8 -> 4 | BL3: =Water!BV8 -> 2 | BM3: ='Room Nights & Food Covers'!B6 -> 57 | BN3: ='Room Nights & Food Covers'!D6 -> 360
A4: Maldives at Landaa Giraavaru | B4: 3 | C4: =TOTAL!C4 -> 3 | D4: =TOTAL!D4 -> 2023 | E4: =Solar!C8 -> 3031 | F4: ='Powerhouse Daily Performance'!C6 -> 6018 | G4: ='Powerhouse Daily Performance'!I6 -> 7152 | H4: ='Powerhouse Daily Performance'!O6 -> 4976 | I4: ='Powerhouse Daily Performance'!U6 -> 2650 | J4: ='Powerhouse Daily Performance'!AA6 -> 7251 | K4: ='FEEDER Consumption '!C8 -> 4386 | L4: ='FEEDER Consumption '!E8 -> 4703 | M4: ='FEEDER Consumption '!G8 -> 12335 | N4: ='FEEDER Consumption '!I8 -> 2500 | O4: ='FEEDER Consumption '!K8 -> 2961 | P4: ='FEEDER Consumption '!M8 -> 1700 | Q4: ='FEEDER Consumption '!O8 -> 490 | R4: ='FEEDER Consumption '!Q8 -> 700 | S4: ='FEEDER Consumption '!S8 -> 1900 | T4: ='FEEDER Consumption '!U8 -> 517 | U4: ='FEEDER Consumption '!W8 -> 400 | V4: ='FEEDER Consumption '!Y8 -> 200 | W4: ='FEEDER Consumption '!AA8 -> 700 | X4: ='FEEDER Consumption '!AC8 -> 170 | Y4: ='FEEDER Consumption '!AE8 -> 460 | Z4: ='FEEDER Consumption '!AG8 -> 1100 | AA4: ='FEEDER Consumption '!AI8 -> 510 | AB4: ='FEEDER Consumption '!AK8 -> 1250 | AC4: ='FEEDER Consumption '!AM8 -> 1020 | AD4: ='FEEDER Consumption '!AO8 -> 730 | AE4: ='FEEDER Consumption '!AQ8 -> 1000 | AF4: ='FEEDER Consumption '!AS8 -> 820 | AG4: ='FEEDER Consumption '!AU8 -> 670 | AH4: ='FEEDER Consumption '!AW8 -> 340 | AI4: ='FEEDER Consumption '!AY8 -> 150 | AJ4: ='FEEDER Consumption '!BA8 -> 1060 | AK4: ='FEEDER Consumption '!BC8 -> 280 | AL4: ='FEEDER Consumption '!BE8 -> 430 | AM4: ='FEEDER Consumption '!BG8 -> 460 | AN4: ='Water Plant Daily Performance'!C6 -> 175 | AO4: ='Water Plant Daily Performance'!I6 -> 13 | AP4: ='Water Plant Daily Performance'!O6 -> 150 | AQ4: ='Water Plant Daily Performance'!U6 -> 0 | AR4: =Water!AD9 -> 26 | AS4: =Water!AH9 -> 6 | AT4: =Water!AJ9 -> 8 | AU4: =Water!AL9 -> 12 | AV4: =Water!AN9 -> 6 | AW4: =Water!AP9 -> 6 | AX4: =Water!AR9 -> 9 | AY4: =Water!AT9 -> 8 | AZ4: =Water!AT9 -> 8 | BA4: =Water!AX9 -> 0 | BB4: =Water!AZ9 -> 3 | BC4: =Water!BB9 -> 3 | BD4: =Water!BD9 -> 27 | BE4: =Water!BF9 -> 10 | BF4: =Water!BH9 -> 1 | BG4: =Water!BJ9 -> 3 | BH4: =Water!BL9 -> 3 | BI4: =Water!BP9 -> 3 | BJ4: =Water!BR9 -> 29 | BK4: =Water!BT9 -> 2 | BL4: =Water!BV9 -> 0 | BM4: ='Room Nights & Food Covers'!B7 -> 58 | BN4: ='Room Nights & Food Covers'!D7 -> 355
A5: Maldives at Landaa Giraavaru | B5: 4 | C5: =TOTAL!C5 -> 3 | D5: =TOTAL!D5 -> 2023 | E5: =Solar!C9 -> 2866 | F5: ='Powerhouse Daily Performance'!C7 -> 7692 | G5: ='Powerhouse Daily Performance'!I7 -> 6433 | H5: ='Powerhouse Daily Performance'!O7 -> 4928 | I5: ='Powerhouse Daily Performance'!U7 -> 2943 | J5: ='Powerhouse Daily Performance'!AA7 -> 5367 | K5: ='FEEDER Consumption '!C9 -> 4211 | L5: ='FEEDER Consumption '!E9 -> 4493 | M5: ='FEEDER Consumption '!G9 -> 12340 | N5: ='FEEDER Consumption '!I9 -> 2500 | O5: ='FEEDER Consumption '!K9 -> 2795 | P5: ='FEEDER Consumption '!M9 -> 1800 | Q5: ='FEEDER Consumption '!O9 -> 455 | R5: ='FEEDER Consumption '!Q9 -> 700 | S5: ='FEEDER Consumption '!S9 -> 1800 | T5: ='FEEDER Consumption '!U9 -> 489 | U5: ='FEEDER Consumption '!W9 -> 400 | V5: ='FEEDER Consumption '!Y9 -> 400 | W5: ='FEEDER Consumption '!AA9 -> 600 | X5: ='FEEDER Consumption '!AC9 -> 170 | Y5: ='FEEDER Consumption '!AE9 -> 430 | Z5: ='FEEDER Consumption '!AG9 -> 1200 | AA5: ='FEEDER Consumption '!AI9 -> 440 | AB5: ='FEEDER Consumption '!AK9 -> 1020 | AC5: ='FEEDER Consumption '!AM9 -> 950 | AD5: ='FEEDER Consumption '!AO9 -> 640 | AE5: ='FEEDER Consumption '!AQ9 -> 900 | AF5: ='FEEDER Consumption '!AS9 -> 850 | AG5: ='FEEDER Consumption '!AU9 -> 680 | AH5: ='FEEDER Consumption '!AW9 -> 350 | AI5: ='FEEDER Consumption '!AY9 -> 120 | AJ5: ='FEEDER Consumption '!BA9 -> 980 | AK5: ='FEEDER Consumption '!BC9 -> 250 | AL5: ='FEEDER Consumption '!BE9 -> 410 | AM5: ='FEEDER Consumption '!BG9 -> 460 | AN5: ='Water Plant Daily Performance'!C7 -> 169 | AO5: ='Water Plant Daily Performance'!I7 -> 0 | AP5: ='Water Plant Daily Performance'!O7 -> 118 | AQ5: ='Water Plant Daily Performance'!U7 -> 90 | AR5: =Water!AD10 -> 25 | AS5: =Water!AH10 -> 4 | AT5: =Water!AJ10 -> 5 | AU5: =Water!AL10 -> 9 | AV5: =Water!AN10 -> 9 | AW5: =Water!AP10 -> 6 | AX5: =Water!AR10 -> 8 | AY5: =Water!AT10 -> 7 | AZ5: =Water!AT10 -> 7 | BA5: =Water!AX10 -> 0 | BB5: =Water!AZ10 -> 3 | BC5: =Water!BB10 -> 0 | BD5: =Water!BD10 -> 31 | BE5: =Water!BF10 -> 10 | BF5: =Water!BH10 -> 2 | BG5: =Water!BJ10 -> 6 | BH5: =Water!BL10 -> 3 | BI5: =Water!BP10 -> 6 | BJ5: =Water!BR10 -> 5 | BK5: =Water!BT10 -> 3 | BL5: =Water!BV10 -> 0 | BM5: ='Room Nights & Food Covers'!B8 -> 59 | BN5: ='Room Nights & Food Covers'!D8 -> 358
A6: Maldives at Landaa Giraavaru | B6: 5 | C6: =TOTAL!C6 -> 3 | D6: =TOTAL!D6 -> 2023 | E6: =Solar!C10 -> 2096 | F6: ='Powerhouse Daily Performance'!C8 -> 1750 | G6: ='Powerhouse Daily Performance'!I8 -> 5722 | H6: ='Powerhouse Daily Performance'!O8 -> 7546 | I6: ='Powerhouse Daily Performance'!U8 -> 3257 | J6: ='Powerhouse Daily Performance'!AA8 -> 8457 | K6: ='FEEDER Consumption '!C10 -> 4139 | L6: ='FEEDER Consumption '!E10 -> 4173 | M6: ='FEEDER Consumption '!G10 -> 11889 | N6: ='FEEDER Consumption '!I10 -> 2300 | O6: ='FEEDER Consumption '!K10 -> 2766 | P6: ='FEEDER Consumption '!M10 -> 1500 | Q6: ='FEEDER Consumption '!O10 -> 482 | R6: ='FEEDER Consumption '!Q10 -> 600 | S6: ='FEEDER Consumption '!S10 -> 2100 | T6: ='FEEDER Consumption '!U10 -> 440 | U6: ='FEEDER Consumption '!W10 -> 500 | V6: ='FEEDER Consumption '!Y10 -> 300 | W6: ='FEEDER Consumption '!AA10 -> 600 | X6: ='FEEDER Consumption '!AC10 -> 160 | Y6: ='FEEDER Consumption '!AE10 -> 410 | Z6: ='FEEDER Consumption '!AG10 -> 1100 | AA6: ='FEEDER Consumption '!AI10 -> 440 | AB6: ='FEEDER Consumption '!AK10 -> 950 | AC6: ='FEEDER Consumption '!AM10 -> 930 | AD6: ='FEEDER Consumption '!AO10 -> 700 | AE6: ='FEEDER Consumption '!AQ10 -> 900 | AF6: ='FEEDER Consumption '!AS10 -> 870 | AG6: ='FEEDER Consumption '!AU10 -> 750 | AH6: ='FEEDER Consumption '!AW10 -> 350 | AI6: ='FEEDER Consumption '!AY10 -> 140 | AJ6: ='FEEDER Consumption '!BA10 -> 1130 | AK6: ='FEEDER Consumption '!BC10 -> 280 | AL6: ='FEEDER Consumption '!BE10 -> 460 | AM6: ='FEEDER Consumption '!BG10 -> 460 | AN6: ='Water Plant Daily Performance'!C8 -> 180 | AO6: ='Water Plant Daily Performance'!I8 -> 0 | AP6: ='Water Plant Daily Performance'!O8 -> 104 | AQ6: ='Water Plant Daily Performance'!U8 -> 14 | AR6: =Water!AD11 -> 27 | AS6: =Water!AH11 -> 7 | AT6: =Water!AJ11 -> 7 | AU6: =Water!AL11 -> 11 | AV6: =Water!AN11 -> 9 | AW6: =Water!AP11 -> 5 | AX6: =Water!AR11 -> 8 | AY6: =Water!AT11 -> 3 | AZ6: =Water!AT11 -> 3 | BA6: =Water!AX11 -> 0 | BB6: =Water!AZ11 -> 9 | BC6: =Water!BB11 -> 2 | BD6: =Water!BD11 -> 32 | BE6: =Water!BF11 -> 10 | BF6: =Water!BH11 -> 1 | BG6: =Water!BJ11 -> 2 | BH6: =Water!BL11 -> 3 | BI6: =Water!BP11 -> 3 | BJ6: =Water!BR11 -> 9 | BK6: =Water!BT11 -> 1 | BL6: =Water!BV11 -> 1 | BM6: ='Room Nights & Food Covers'!B9 -> 56 | BN6: ='Room Nights & Food Covers'!D9 -> 344
A7: Maldives at Landaa Giraavaru | B7: 6 | C7: =TOTAL!C7 -> 3 | D7: =TOTAL!D7 -> 2023 | E7: =Solar!C11 -> 1133 | F7: ='Powerhouse Daily Performance'!C9 -> 0 | G7: ='Powerhouse Daily Performance'!I9 -> 16557 | H7: ='Powerhouse Daily Performance'!O9 -> 922 | I7: ='Powerhouse Daily Performance'!U9 -> 626 | J7: ='Powerhouse Daily Performance'!AA9 -> 7502 | K7: ='FEEDER Consumption '!C11 -> 3817 | L7: ='FEEDER Consumption '!E11 -> 3402 | M7: ='FEEDER Consumption '!G11 -> 12185 | N7: ='FEEDER Consumption '!I11 -> 2200 | O7: ='FEEDER Consumption '!K11 -> 2679 | P7: ='FEEDER Consumption '!M11 -> 1500 | Q7: ='FEEDER Consumption '!O11 -> 478 | R7: ='FEEDER Consumption '!Q11 -> 600 | S7: ='FEEDER Consumption '!S11 -> 2100 | T7: ='FEEDER Consumption '!U11 -> 493 | U7: ='FEEDER Consumption '!W11 -> 400 | V7: ='FEEDER Consumption '!Y11 -> 300 | W7: ='FEEDER Consumption '!AA11 -> 700 | X7: ='FEEDER Consumption '!AC11 -> 170 | Y7: ='FEEDER Consumption '!AE11 -> 480 | Z7: ='FEEDER Consumption '!AG11 -> 1100 | AA7: ='FEEDER Consumption '!AI11 -> 380 | AB7: ='FEEDER Consumption '!AK11 -> 630 | AC7: ='FEEDER Consumption '!AM11 -> 640 | AD7: ='FEEDER Consumption '!AO11 -> 420 | AE7: ='FEEDER Consumption '!AQ11 -> 700 | AF7: ='FEEDER Consumption '!AS11 -> 550 | AG7: ='FEEDER Consumption '!AU11 -> 490 | AH7: ='FEEDER Consumption '!AW11 -> 300 | AI7: ='FEEDER Consumption '!AY11 -> 110 | AJ7: ='FEEDER Consumption '!BA11 -> 930 | AK7: ='FEEDER Consumption '!BC11 -> 250 | AL7: ='FEEDER Consumption '!BE11 -> 390 | AM7: ='FEEDER Consumption '!BG11 -> 480 | AN7: ='Water Plant Daily Performance'!C9 -> 189 | AO7: ='Water Plant Daily Performance'!I9 -> 0 | AP7: ='Water Plant Daily Performance'!O9 -> 108 | AQ7: ='Water Plant Daily Performance'!U9 -> 0 | AR7: =Water!AD12 -> 24 | AS7: =Water!AH12 -> 6 | AT7: =Water!AJ12 -> 4 | AU7: =Water!AL12 -> 11 | AV7: =Water!AN12 -> 6 | AW7: =Water!AP12 -> 6 | AX7: =Water!AR12 -> 8 | AY7: =Water!AT12 -> 3 | AZ7: =Water!AT12 -> 3 | BA7: =Water!AX12 -> 1 | BB7: =Water!AZ12 -> 2 | BC7: =Water!BB12 -> 1 | BD7: =Water!BD12 -> 30 | BE7: =Water!BF12 -> 1 | BF7: =Water!BH12 -> 1 | BG7: =Water!BJ12 -> 0 | BH7: =Water!BL12 -> 1 | BI7: =Water!BP12 -> 6 | BJ7: =Water!BR12 -> 0 | BK7: =Water!BT12 -> 1 | BL7: =Water!BV12 -> 0 | BM7: ='Room Nights & Food Covers'!B10 -> 63 | BN7: ='Room Nights & Food Covers'!D10 -> 393
A8: Maldives at Landaa Giraavaru | B8: 7 | C8: =TOTAL!C8 -> 3 | D8: =TOTAL!D8 -> 2023 | E8: =Solar!C12 -> 3060 | F8: ='Powerhouse Daily Performance'!C10 -> 3383 | G8: ='Powerhouse Daily Performance'!I10 -> 12822 | H8: ='Powerhouse Daily Performance'!O10 -> 5953 | I8: ='Powerhouse Daily Performance'!U10 -> 1912 | J8: ='Powerhouse Daily Performance'!AA10 -> 2149 | K8: ='FEEDER Consumption '!C12 -> 3995 | L8: ='FEEDER Consumption '!E12 -> 4439 | M8: ='FEEDER Consumption '!G12 -> 11271 | N8: ='FEEDER Consumption '!I12 -> 2300 | O8: ='FEEDER Consumption '!K12 -> 2797 | P8: ='FEEDER Consumption '!M12 -> 1800 | Q8: ='FEEDER Consumption '!O12 -> 426 | R8: ='FEEDER Consumption '!Q12 -> 700 | S8: ='FEEDER Consumption '!S12 -> 2000 | T8: ='FEEDER Consumption '!U12 -> 445 | U8: ='FEEDER Consumption '!W12 -> 300 | V8: ='FEEDER Consumption '!Y12 -> 300 | W8: ='FEEDER Consumption '!AA12 -> 500 | X8: ='FEEDER Consumption '!AC12 -> 130 | Y8: ='FEEDER Consumption '!AE12 -> 370 | Z8: ='FEEDER Consumption '!AG12 -> 1200 | AA8: ='FEEDER Consumption '!AI12 -> 480 | AB8: ='FEEDER Consumption '!AK12 -> 920 | AC8: ='FEEDER Consumption '!AM12 -> 860 | AD8: ='FEEDER Consumption '!AO12 -> 720 | AE8: ='FEEDER Consumption '!AQ12 -> 1100 | AF8: ='FEEDER Consumption '!AS12 -> 750 | AG8: ='FEEDER Consumption '!AU12 -> 690 | AH8: ='FEEDER Consumption '!AW12 -> 290 | AI8: ='FEEDER Consumption '!AY12 -> 150 | AJ8: ='FEEDER Consumption '!BA12 -> 970 | AK8: ='FEEDER Consumption '!BC12 -> 260 | AL8: ='FEEDER Consumption '!BE12 -> 420 | AM8: ='FEEDER Consumption '!BG12 -> 470 | AN8: ='Water Plant Daily Performance'!C10 -> 148 | AO8: ='Water Plant Daily Performance'!I10 -> 59 | AP8: ='Water Plant Daily Performance'!O10 -> 18 | AQ8: ='Water Plant Daily Performance'!U10 -> 119 | AR8: =Water!AD13 -> 0 | AS8: =Water!AH13 -> 0 | AT8: =Water!AJ13 -> 0 | AU8: =Water!AL13 -> 0 | AV8: =Water!AN13 -> 0 | AW8: =Water!AP13 -> 0 | AX8: =Water!AR13 -> 0 | AY8: =Water!AT13 -> 0 | AZ8: =Water!AT13 -> 0 | BA8: =Water!AX13 -> 0 | BB8: =Water!AZ13 -> 0 | BC8: =Water!BB13 -> 0 | BD8: =Water!BD13 -> 0 | BE8: =Water!BF13 -> 0 | BF8: =Water!BH13 -> 0 | BG8: =Water!BJ13 -> 0 | BH8: =Water!BL13 -> 0 | BI8: =Water!BP13 -> 0 | BJ8: =Water!BR13 -> 0 | BK8: =Water!BT13 -> 0 | BL8: =Water!BV13 -> 0 | BM8: ='Room Nights & Food Covers'!B11 -> 61 | BN8: ='Room Nights & Food Covers'!D11 -> 363
A9: Maldives at Landaa Giraavaru | B9: 8 | C9: =TOTAL!C9 -> 3 | D9: =TOTAL!D9 -> 2023 | E9: =Solar!C13 -> 2975 | F9: ='Powerhouse Daily Performance'!C11 -> 5533 | G9: ='Powerhouse Daily Performance'!I11 -> 9792 | H9: ='Powerhouse Daily Performance'!O11 -> 7800 | I9: ='Powerhouse Daily Performance'!U11 -> 554 | J9: ='Powerhouse Daily Performance'!AA11 -> 4756 | K9: ='FEEDER Consumption '!C13 -> 4488 | L9: ='FEEDER Consumption '!E13 -> 5117 | M9: ='FEEDER Consumption '!G13 -> 12412 | N9: ='FEEDER Consumption '!I13 -> 2400 | O9: ='FEEDER Consumption '!K13 -> 2838 | P9: ='FEEDER Consumption '!M13 -> 1900 | Q9: ='FEEDER Consumption '!O13 -> 488 | R9: ='FEEDER Consumption '!Q13 -> 600 | S9: ='FEEDER Consumption '!S13 -> 1900 | T9: ='FEEDER Consumption '!U13 -> 547 | U9: ='FEEDER Consumption '!W13 -> 400 | V9: ='FEEDER Consumption '!Y13 -> 300 | W9: ='FEEDER Consumption '!AA13 -> 700 | X9: ='FEEDER Consumption '!AC13 -> 160 | Y9: ='FEEDER Consumption '!AE13 -> 390 | Z9: ='FEEDER Consumption '!AG13 -> 1200 | AA9: ='FEEDER Consumption '!AI13 -> 490 | AB9: ='FEEDER Consumption '!AK13 -> 1270 | AC9: ='FEEDER Consumption '!AM13 -> 1120 | AD9: ='FEEDER Consumption '!AO13 -> 1040 | AE9: ='FEEDER Consumption '!AQ13 -> 1200 | AF9: ='FEEDER Consumption '!AS13 -> 900 | AG9: ='FEEDER Consumption '!AU13 -> 760 | AH9: ='FEEDER Consumption '!AW13 -> 250 | AI9: ='FEEDER Consumption '!AY13 -> 130 | AJ9: ='FEEDER Consumption '!BA13 -> 1090 | AK9: ='FEEDER Consumption '!BC13 -> 280 | AL9: ='FEEDER Consumption '!BE13 -> 440 | AM9: ='FEEDER Consumption '!BG13 -> 490 | AN9: ='Water Plant Daily Performance'!C11 -> 176 | AO9: ='Water Plant Daily Performance'!I11 -> 29 | AP9: ='Water Plant Daily Performance'!O11 -> 58 | AQ9: ='Water Plant Daily Performance'!U11 -> 88 | AR9: =Water!AD14 -> 0 | AS9: =Water!AH14 -> 0 | AT9: =Water!AJ14 -> 0 | AU9: =Water!AL14 -> 0 | AV9: =Water!AN14 -> 0 | AW9: =Water!AP14 -> 0 | AX9: =Water!AR14 -> 0 | AY9: =Water!AT14 -> 0 | AZ9: =Water!AT14 -> 0 | BA9: =Water!AX14 -> 0 | BB9: =Water!AZ14 -> 0 | BC9: =Water!BB14 -> 0 | BD9: =Water!BD14 -> 0 | BE9: =Water!BF14 -> 0 | BF9: =Water!BH14 -> 0 | BG9: =Water!BJ14 -> 0 | BH9: =Water!BL14 -> 0 | BI9: =Water!BP14 -> 0 | BJ9: =Water!BR14 -> 0 | BK9: =Water!BT14 -> 0 | BL9: =Water!BV14 -> 0 | BM9: ='Room Nights & Food Covers'!B12 -> 0 | BN9: ='Room Nights & Food Covers'!D12 -> 0
A10: Maldives at Landaa Giraavaru | B10: 9 | C10: =TOTAL!C10 -> 3 | D10: =TOTAL!D10 -> 2023 | E10: =Solar!C14 -> 0 | F10: ='Powerhouse Daily Performance'!C12 -> 0 | G10: ='Powerhouse Daily Performance'!I12 -> 0 | H10: ='Powerhouse Daily Performance'!O12 -> 0 | I10: ='Powerhouse Daily Performance'!U12 -> 0 | J10: ='Powerhouse Daily Performance'!AA12 -> 0 | K10: ='FEEDER Consumption '!C14 -> 0 | L10: ='FEEDER Consumption '!E14 -> 0 | M10: ='FEEDER Consumption '!G14 -> 0 | N10: ='FEEDER Consumption '!I14 -> 0 | O10: ='FEEDER Consumption '!K14 -> 0 | P10: ='FEEDER Consumption '!M14 -> 0 | Q10: ='FEEDER Consumption '!O14 -> 0 | R10: ='FEEDER Consumption '!Q14 -> 0 | S10: ='FEEDER Consumption '!S14 -> 0 | T10: ='FEEDER Consumption '!U14 -> 0 | U10: ='FEEDER Consumption '!W14 -> 0 | V10: ='FEEDER Consumption '!Y14 -> 0 | W10: ='FEEDER Consumption '!AA14 -> 0 | X10: ='FEEDER Consumption '!AC14 -> 0 | Y10: ='FEEDER Consumption '!AE14 -> 0 | Z10: ='FEEDER Consumption '!AG14 -> 0 | AA10: ='FEEDER Consumption '!AI14 -> 0 | AB10: ='FEEDER Consumption '!AK14 -> 0 | AC10: ='FEEDER Consumption '!AM14 -> 0 | AD10: ='FEEDER Consumption '!AO14 -> 0 | AE10: ='FEEDER Consumption '!AQ14 -> 0 | AF10: ='FEEDER Consumption '!AS14 -> 0 | AG10: ='FEEDER Consumption '!AU14 -> 0 | AH10: ='FEEDER Consumption '!AW14 -> 0 | AI10: ='FEEDER Consumption '!AY14 -> 0 | AJ10: ='FEEDER Consumption '!BA14 -> 0 | AK10: ='FEEDER Consumption '!BC14 -> 0 | AL10: ='FEEDER Consumption '!BE14 -> 0 | AM10: ='FEEDER Consumption '!BG14 -> 0 | AN10: ='Water Plant Daily Performance'!C12 -> 0 | AO10: ='Water Plant Daily Performance'!I12 -> 0 | AP10: ='Water Plant Daily Performance'!O12 -> 0 | AQ10: ='Water Plant Daily Performance'!U12 -> 0 | AR10: =Water!AD15 -> 0 | AS10: =Water!AH15 -> 0 | AT10: =Water!AJ15 -> 0 | AU10: =Water!AL15 -> 0 | AV10: =Water!AN15 -> 0 | AW10: =Water!AP15 -> 0 | AX10: =Water!AR15 -> 0 | AY10: =Water!AT15 -> 0 | AZ10: =Water!AT15 -> 0 | BA10: =Water!AX15 -> 0 | BB10: =Water!AZ15 -> 0 | BC10: =Water!BB15 -> 0 | BD10: =Water!BD15 -> 0 | BE10: =Water!BF15 -> 0 | BF10: =Water!BH15 -> 0 | BG10: =Water!BJ15 -> 0 | BH10: =Water!BL15 -> 0 | BI10: =Water!BP15 -> 0 | BJ10: =Water!BR15 -> 0 | BK10: =Water!BT15 -> 0 | BL10: =Water!BV15 -> 0 | BM10: ='Room Nights & Food Covers'!B13 -> 0 | BN10: ='Room Nights & Food Covers'!D13 -> 0
A11: Maldives at Landaa Giraavaru | B11: 10 | C11: =TOTAL!C11 -> 3 | D11: =TOTAL!D11 -> 2023 | E11: =Solar!C15 -> 0 | F11: ='Powerhouse Daily Performance'!C13 -> 0 | G11: ='Powerhouse Daily Performance'!I13 -> 0 | H11: ='Powerhouse Daily Performance'!O13 -> 0 | I11: ='Powerhouse Daily Performance'!U13 -> 0 | J11: ='Powerhouse Daily Performance'!AA13 -> 0 | K11: ='FEEDER Consumption '!C15 -> 0 | L11: ='FEEDER Consumption '!E15 -> 0 | M11: ='FEEDER Consumption '!G15 -> 0 | N11: ='FEEDER Consumption '!I15 -> 0 | O11: ='FEEDER Consumption '!K15 -> 0 | P11: ='FEEDER Consumption '!M15 -> 0 | Q11: ='FEEDER Consumption '!O15 -> 0 | R11: ='FEEDER Consumption '!Q15 -> 0 | S11: ='FEEDER Consumption '!S15 -> 0 | T11: ='FEEDER Consumption '!U15 -> 0 | U11: ='FEEDER Consumption '!W15 -> 0 | V11: ='FEEDER Consumption '!Y15 -> 0 | W11: ='FEEDER Consumption '!AA15 -> 0 | X11: ='FEEDER Consumption '!AC15 -> 0 | Y11: ='FEEDER Consumption '!AE15 -> 0 | Z11: ='FEEDER Consumption '!AG15 -> 0 | AA11: ='FEEDER Consumption '!AI15 -> 0 | AB11: ='FEEDER Consumption '!AK15 -> 0 | AC11: ='FEEDER Consumption '!AM15 -> 0 | AD11: ='FEEDER Consumption '!AO15 -> 0 | AE11: ='FEEDER Consumption '!AQ15 -> 0 | AF11: ='FEEDER Consumption '!AS15 -> 0 | AG11: ='FEEDER Consumption '!AU15 -> 0 | AH11: ='FEEDER Consumption '!AW15 -> 0 | AI11: ='FEEDER Consumption '!AY15 -> 0 | AJ11: ='FEEDER Consumption '!BA15 -> 0 | AK11: ='FEEDER Consumption '!BC15 -> 0 | AL11: ='FEEDER Consumption '!BE15 -> 0 | AM11: ='FEEDER Consumption '!BG15 -> 0 | AN11: ='Water Plant Daily Performance'!C13 -> 0 | AO11: ='Water Plant Daily Performance'!I13 -> 0 | AP11: ='Water Plant Daily Performance'!O13 -> 0 | AQ11: ='Water Plant Daily Performance'!U13 -> 0 | AR11: =Water!AD16 -> 0 | AS11: =Water!AH16 -> 0 | AT11: =Water!AJ16 -> 0 | AU11: =Water!AL16 -> 0 | AV11: =Water!AN16 -> 0 | AW11: =Water!AP16 -> 0 | AX11: =Water!AR16 -> 0 | AY11: =Water!AT16 -> 0 | AZ11: =Water!AT16 -> 0 | BA11: =Water!AX16 -> 0 | BB11: =Water!AZ16 -> 0 | BC11: =Water!BB16 -> 0 | BD11: =Water!BD16 -> 0 | BE11: =Water!BF16 -> 0 | BF11: =Water!BH16 -> 0 | BG11: =Water!BJ16 -> 0 | BH11: =Water!BL16 -> 0 | BI11: =Water!BP16 -> 0 | BJ11: =Water!BR16 -> 0 | BK11: =Water!BT16 -> 0 | BL11: =Water!BV16 -> 0 | BM11: ='Room Nights & Food Covers'!B14 -> 0 | BN11: ='Room Nights & Food Covers'!D14 -> 0
A12: Maldives at Landaa Giraavaru | B12: 11 | C12: =TOTAL!C12 -> 3 | D12: =TOTAL!D12 -> 2023 | E12: =Solar!C16 -> 0 | F12: ='Powerhouse Daily Performance'!C14 -> 0 | G12: ='Powerhouse Daily Performance'!I14 -> 0 | H12: ='Powerhouse Daily Performance'!O14 -> 0 | I12: ='Powerhouse Daily Performance'!U14 -> 0 | J12: ='Powerhouse Daily Performance'!AA14 -> 0 | K12: ='FEEDER Consumption '!C16 -> 0 | L12: ='FEEDER Consumption '!E16 -> 0 | M12: ='FEEDER Consumption '!G16 -> 0 | N12: ='FEEDER Consumption '!I16 -> 0 | O12: ='FEEDER Consumption '!K16 -> 0 | P12: ='FEEDER Consumption '!M16 -> 0 | Q12: ='FEEDER Consumption '!O16 -> 0 | R12: ='FEEDER Consumption '!Q16 -> 0 | S12: ='FEEDER Consumption '!S16 -> 0 | T12: ='FEEDER Consumption '!U16 -> 0 | U12: ='FEEDER Consumption '!W16 -> 0 | V12: ='FEEDER Consumption '!Y16 -> 0 | W12: ='FEEDER Consumption '!AA16 -> 0 | X12: ='FEEDER Consumption '!AC16 -> 0 | Y12: ='FEEDER Consumption '!AE16 -> 0 | Z12: ='FEEDER Consumption '!AG16 -> 0 | AA12: ='FEEDER Consumption '!AI16 -> 0 | AB12: ='FEEDER Consumption '!AK16 -> 0 | AC12: ='FEEDER Consumption '!AM16 -> 0 | AD12: ='FEEDER Consumption '!AO16 -> 0 | AE12: ='FEEDER Consumption '!AQ16 -> 0 | AF12: ='FEEDER Consumption '!AS16 -> 0 | AG12: ='FEEDER Consumption '!AU16 -> 0 | AH12: ='FEEDER Consumption '!AW16 -> 0 | AI12: ='FEEDER Consumption '!AY16 -> 0 | AJ12: ='FEEDER Consumption '!BA16 -> 0 | AK12: ='FEEDER Consumption '!BC16 -> 0 | AL12: ='FEEDER Consumption '!BE16 -> 0 | AM12: ='FEEDER Consumption '!BG16 -> 0 | AN12: ='Water Plant Daily Performance'!C14 -> 0 | AO12: ='Water Plant Daily Performance'!I14 -> 0 | AP12: ='Water Plant Daily Performance'!O14 -> 0 | AQ12: ='Water Plant Daily Performance'!U14 -> 0 | AR12: =Water!AD17 -> 0 | AS12: =Water!AH17 -> 0 | AT12: =Water!AJ17 -> 0 | AU12: =Water!AL17 -> 0 | AV12: =Water!AN17 -> 0 | AW12: =Water!AP17 -> 0 | AX12: =Water!AR17 -> 0 | AY12: =Water!AT17 -> 0 | AZ12: =Water!AT17 -> 0 | BA12: =Water!AX17 -> 0 | BB12: =Water!AZ17 -> 0 | BC12: =Water!BB17 -> 0 | BD12: =Water!BD17 -> 0 | BE12: =Water!BF17 -> 0 | BF12: =Water!BH17 -> 0 | BG12: =Water!BJ17 -> 0 | BH12: =Water!BL17 -> 0 | BI12: =Water!BP17 -> 0 | BJ12: =Water!BR17 -> 0 | BK12: =Water!BT17 -> 0 | BL12: =Water!BV17 -> 0 | BM12: ='Room Nights & Food Covers'!B15 -> 0 | BN12: ='Room Nights & Food Covers'!D15 -> 0
A13: Maldives at Landaa Giraavaru | B13: 12 | C13: =TOTAL!C13 -> 3 | D13: =TOTAL!D13 -> 2023 | E13: =Solar!C17 -> 0 | F13: ='Powerhouse Daily Performance'!C15 -> 0 | G13: ='Powerhouse Daily Performance'!I15 -> 0 | H13: ='Powerhouse Daily Performance'!O15 -> 0 | I13: ='Powerhouse Daily Performance'!U15 -> 0 | J13: ='Powerhouse Daily Performance'!AA15 -> 0 | K13: ='FEEDER Consumption '!C17 -> 0 | L13: ='FEEDER Consumption '!E17 -> 0 | M13: ='FEEDER Consumption '!G17 -> 0 | N13: ='FEEDER Consumption '!I17 -> 0 | O13: ='FEEDER Consumption '!K17 -> 0 | P13: ='FEEDER Consumption '!M17 -> 0 | Q13: ='FEEDER Consumption '!O17 -> 0 | R13: ='FEEDER Consumption '!Q17 -> 0 | S13: ='FEEDER Consumption '!S17 -> 0 | T13: ='FEEDER Consumption '!U17 -> 0 | U13: ='FEEDER Consumption '!W17 -> 0 | V13: ='FEEDER Consumption '!Y17 -> 0 | W13: ='FEEDER Consumption '!AA17 -> 0 | X13: ='FEEDER Consumption '!AC17 -> 0 | Y13: ='FEEDER Consumption '!AE17 -> 0 | Z13: ='FEEDER Consumption '!AG17 -> 0 | AA13: ='FEEDER Consumption '!AI17 -> 0 | AB13: ='FEEDER Consumption '!AK17 -> 0 | AC13: ='FEEDER Consumption '!AM17 -> 0 | AD13: ='FEEDER Consumption '!AO17 -> 0 | AE13: ='FEEDER Consumption '!AQ17 -> 0 | AF13: ='FEEDER Consumption '!AS17 -> 0 | AG13: ='FEEDER Consumption '!AU17 -> 0 | AH13: ='FEEDER Consumption '!AW17 -> 0 | AI13: ='FEEDER Consumption '!AY17 -> 0 | AJ13: ='FEEDER Consumption '!BA17 -> 0 | AK13: ='FEEDER Consumption '!BC17 -> 0 | AL13: ='FEEDER Consumption '!BE17 -> 0 | AM13: ='FEEDER Consumption '!BG17 -> 0 | AN13: ='Water Plant Daily Performance'!C15 -> 0 | AO13: ='Water Plant Daily Performance'!I15 -> 0 | AP13: ='Water Plant Daily Performance'!O15 -> 0 | AQ13: ='Water Plant Daily Performance'!U15 -> 0 | AR13: =Water!AD18 -> 0 | AS13: =Water!AH18 -> 0 | AT13: =Water!AJ18 -> 0 | AU13: =Water!AL18 -> 0 | AV13: =Water!AN18 -> 0 | AW13: =Water!AP18 -> 0 | AX13: =Water!AR18 -> 0 | AY13: =Water!AT18 -> 0 | AZ13: =Water!AT18 -> 0 | BA13: =Water!AX18 -> 0 | BB13: =Water!AZ18 -> 0 | BC13: =Water!BB18 -> 0 | BD13: =Water!BD18 -> 0 | BE13: =Water!BF18 -> 0 | BF13: =Water!BH18 -> 0 | BG13: =Water!BJ18 -> 0 | BH13: =Water!BL18 -> 0 | BI13: =Water!BP18 -> 0 | BJ13: =Water!BR18 -> 0 | BK13: =Water!BT18 -> 0 | BL13: =Water!BV18 -> 0 | BM13: ='Room Nights & Food Covers'!B16 -> 0 | BN13: ='Room Nights & Food Covers'!D16 -> 0
... A29: Maldives at Landaa Giraavaru | B29: 28 | C29: =TOTAL!C29 -> 3 | D29: =TOTAL!D29 -> 2023 | E29: =Solar!C33 -> 0 | F29: ='Powerhouse Daily Performance'!C31 -> 0 | G29: ='Powerhouse Daily Performance'!I31 -> 0 | H29: ='Powerhouse Daily Performance'!O31 -> 0 | I29: ='Powerhouse Daily Performance'!U31 -> 0 | J29: ='Powerhouse Daily Performance'!AA31 -> 0 | K29: ='FEEDER Consumption '!C33 -> 0 | L29: ='FEEDER Consumption '!E33 -> 0 | M29: ='FEEDER Consumption '!G33 -> 0 | N29: ='FEEDER Consumption '!I33 -> 0 | O29: ='FEEDER Consumption '!K33 -> 0 | P29: ='FEEDER Consumption '!M33 -> 0 | Q29: ='FEEDER Consumption '!O33 -> 0 | R29: ='FEEDER Consumption '!Q33 -> 0 | S29: ='FEEDER Consumption '!S33 -> 0 | T29: ='FEEDER Consumption '!U33 -> 0 | U29: ='FEEDER Consumption '!W33 -> 0 | V29: ='FEEDER Consumption '!Y33 -> 0 | W29: ='FEEDER Consumption '!AA33 -> 0 | X29: ='FEEDER Consumption '!AC33 -> 0 | Y29: ='FEEDER Consumption '!AE33 -> 0 | Z29: ='FEEDER Consumption '!AG33 -> 0 | AA29: ='FEEDER Consumption '!AI33 -> 0 | AB29: ='FEEDER Consumption '!AK33 -> 0 | AC29: ='FEEDER Consumption '!AM33 -> 0 | AD29: ='FEEDER Consumption '!AO33 -> 0 | AE29: ='FEEDER Consumption '!AQ33 -> 0 | AF29: ='FEEDER Consumption '!AS33 -> 0 | AG29: ='FEEDER Consumption '!AU33 -> 0 | AH29: ='FEEDER Consumption '!AW33 -> 0 | AI29: ='FEEDER Consumption '!AY33 -> 0 | AJ29: ='FEEDER Consumption '!BA33 -> 0 | AK29: ='FEEDER Consumption '!BC33 -> 0 | AL29: ='FEEDER Consumption '!BE33 -> 0 | AM29: ='FEEDER Consumption '!BG33 -> 0 | AN29: ='Water Plant Daily Performance'!C31 -> 0 | AO29: ='Water Plant Daily Performance'!I31 -> 0 | AP29: ='Water Plant Daily Performance'!O31 -> 0 | AQ29: ='Water Plant Daily Performance'!U31 -> 0 | AR29: =Water!AD34 -> 0 | AS29: =Water!AH34 -> 0 | AT29: =Water!AJ34 -> 0 | AU29: =Water!AL34 -> 0 | AV29: =Water!AN34 -> 0 | AW29: =Water!AP34 -> 0 | AX29: =Water!AR34 -> 0 | AY29: =Water!AT34 -> 0 | AZ29: =Water!AT34 -> 0 | BA29: =Water!AX34 -> 0 | BB29: =Water!AZ34 -> 0 | BC29: =Water!BB34 -> 0 | BD29: =Water!BD34 -> 0 | BE29: =Water!BF34 -> 0 | BF29: =Water!BH34 -> 0 | BG29: =Water!BJ34 -> 0 | BH29: =Water!BL34 -> 0 | BI29: =Water!BP34 -> 0 | BJ29: =Water!BR34 -> 0 | BK29: =Water!BT34 -> 0 | BL29: =Water!BV34 -> 0 | BM29: ='Room Nights & Food Covers'!B32 -> 0 | BN29: ='Room Nights & Food Covers'!D32 -> 0
A30: Maldives at Landaa Giraavaru | B30: 29 | C30: =TOTAL!C30 -> 3 | D30: =TOTAL!D30 -> 2023 | E30: =Solar!C34 -> 0 | F30: ='Powerhouse Daily Performance'!C32 -> 0 | G30: ='Powerhouse Daily Performance'!I32 -> 0 | H30: ='Powerhouse Daily Performance'!O32 -> 0 | I30: ='Powerhouse Daily Performance'!U32 -> 0 | J30: ='Powerhouse Daily Performance'!AA32 -> 0 | K30: ='FEEDER Consumption '!C34 -> 0 | L30: ='FEEDER Consumption '!E34 -> 0 | M30: ='FEEDER Consumption '!G34 -> 0 | N30: ='FEEDER Consumption '!I34 -> 0 | O30: ='FEEDER Consumption '!K34 -> 0 | P30: ='FEEDER Consumption '!M34 -> 0 | Q30: ='FEEDER Consumption '!O34 -> 0 | R30: ='FEEDER Consumption '!Q34 -> 0 | S30: ='FEEDER Consumption '!S34 -> 0 | T30: ='FEEDER Consumption '!U34 -> 0 | U30: ='FEEDER Consumption '!W34 -> 0 | V30: ='FEEDER Consumption '!Y34 -> 0 | W30: ='FEEDER Consumption '!AA34 -> 0 | X30: ='FEEDER Consumption '!AC34 -> 0 | Y30: ='FEEDER Consumption '!AE34 -> 0 | Z30: ='FEEDER Consumption '!AG34 -> 0 | AA30: ='FEEDER Consumption '!AI34 -> 0 | AB30: ='FEEDER Consumption '!AK34 -> 0 | AC30: ='FEEDER Consumption '!AM34 -> 0 | AD30: ='FEEDER Consumption '!AO34 -> 0 | AE30: ='FEEDER Consumption '!AQ34 -> 0 | AF30: ='FEEDER Consumption '!AS34 -> 0 | AG30: ='FEEDER Consumption '!AU34 -> 0 | AH30: ='FEEDER Consumption '!AW34 -> 0 | AI30: ='FEEDER Consumption '!AY34 -> 0 | AJ30: ='FEEDER Consumption '!BA34 -> 0 | AK30: ='FEEDER Consumption '!BC34 -> 0 | AL30: ='FEEDER Consumption '!BE34 -> 0 | AM30: ='FEEDER Consumption '!BG34 -> 0 | AN30: ='Water Plant Daily Performance'!C32 -> 0 | AO30: ='Water Plant Daily Performance'!I32 -> 0 | AP30: ='Water Plant Daily Performance'!O32 -> 0 | AQ30: ='Water Plant Daily Performance'!U32 -> 0 | AR30: =Water!AD35 -> 0 | AS30: =Water!AH35 -> 0 | AT30: =Water!AJ35 -> 0 | AU30: =Water!AL35 -> 0 | AV30: =Water!AN35 -> 0 | AW30: =Water!AP35 -> 0 | AX30: =Water!AR35 -> 0 | AY30: =Water!AT35 -> 0 | AZ30: =Water!AT35 -> 0 | BA30: =Water!AX35 -> 0 | BB30: =Water!AZ35 -> 0 | BC30: =Water!BB35 -> 0 | BD30: =Water!BD35 -> 0 | BE30: =Water!BF35 -> 0 | BF30: =Water!BH35 -> 0 | BG30: =Water!BJ35 -> 0 | BH30: =Water!BL35 -> 0 | BI30: =Water!BP35 -> 0 | BJ30: =Water!BR35 -> 0 | BK30: =Water!BT35 -> 0 | BL30: =Water!BV35 -> 0 | BM30: ='Room Nights & Food Covers'!B36 -> 0 | BN30: ='Room Nights & Food Covers'!D36 -> 2507
A31: Maldives at Landaa Giraavaru | B31: 30 | C31: =TOTAL!C31 -> 3 | D31: =TOTAL!D31 -> 2023 | E31: =Solar!C35 -> 0 | F31: ='Powerhouse Daily Performance'!C33 -> 0 | G31: ='Powerhouse Daily Performance'!I33 -> 0 | H31: ='Powerhouse Daily Performance'!O33 -> 0 | I31: ='Powerhouse Daily Performance'!U33 -> 0 | J31: ='Powerhouse Daily Performance'!AA33 -> 0 | K31: ='FEEDER Consumption '!C35 -> 0 | L31: ='FEEDER Consumption '!E35 -> 0 | M31: ='FEEDER Consumption '!G35 -> 0 | N31: ='FEEDER Consumption '!I35 -> 0 | O31: ='FEEDER Consumption '!K35 -> 0 | P31: ='FEEDER Consumption '!M35 -> 0 | Q31: ='FEEDER Consumption '!O35 -> 0 | R31: ='FEEDER Consumption '!Q35 -> 0 | S31: ='FEEDER Consumption '!S35 -> 0 | T31: ='FEEDER Consumption '!U35 -> 0 | U31: ='FEEDER Consumption '!W35 -> 0 | V31: ='FEEDER Consumption '!Y35 -> 0 | W31: ='FEEDER Consumption '!AA35 -> 0 | X31: ='FEEDER Consumption '!AC35 -> 0 | Y31: ='FEEDER Consumption '!AE35 -> 0 | Z31: ='FEEDER Consumption '!AG35 -> 0 | AA31: ='FEEDER Consumption '!AI35 -> 0 | AB31: ='FEEDER Consumption '!AK35 -> 0 | AC31: ='FEEDER Consumption '!AM35 -> 0 | AD31: ='FEEDER Consumption '!AO35 -> 0 | AE31: ='FEEDER Consumption '!AQ35 -> 0 | AF31: ='FEEDER Consumption '!AS35 -> 0 | AG31: ='FEEDER Consumption '!AU35 -> 0 | AH31: ='FEEDER Consumption '!AW35 -> 0 | AI31: ='FEEDER Consumption '!AY35 -> 0 | AJ31: ='FEEDER Consumption '!BA35 -> 0 | AK31: ='FEEDER Consumption '!BC35 -> 0 | AL31: ='FEEDER Consumption '!BE35 -> 0 | AM31: ='FEEDER Consumption '!BG35 -> 0 | AN31: ='Water Plant Daily Performance'!C33 -> 0 | AO31: ='Water Plant Daily Performance'!I33 -> 0 | AP31: ='Water Plant Daily Performance'!O33 -> 0 | AQ31: ='Water Plant Daily Performance'!U33 -> 0 | AR31: =Water!AD36 -> 0 | AS31: =Water!AH36 -> 0 | AT31: =Water!AJ36 -> 0 | AU31: =Water!AL36 -> 0 | AV31: =Water!AN36 -> 0 | AW31: =Water!AP36 -> 0 | AX31: =Water!AR36 -> 0 | AY31: =Water!AT36 -> 0 | AZ31: =Water!AT36 -> 0 | BA31: =Water!AX36 -> 0 | BB31: =Water!AZ36 -> 0 | BC31: =Water!BB36 -> 0 | BD31: =Water!BD36 -> 0 | BE31: =Water!BF36 -> 0 | BF31: =Water!BH36 -> 0 | BG31: =Water!BJ36 -> 0 | BH31: =Water!BL36 -> 0 | BI31: =Water!BP36 -> 0 | BJ31: =Water!BR36 -> 0 | BK31: =Water!BT36 -> 0 | BL31: =Water!BV36 -> 0 | BM31: ='Room Nights & Food Covers'!B37 -> 0 | BN31: ='Room Nights & Food Covers'!D37 -> 0
A32: Maldives at Landaa Giraavaru | B32: 31 | C32: =TOTAL!C32 -> 3 | D32: =TOTAL!D32 -> 2023 | E32: =Solar!C36 -> 0 | F32: ='Powerhouse Daily Performance'!C34 -> 0 | G32: ='Powerhouse Daily Performance'!I34 -> 0 | H32: ='Powerhouse Daily Performance'!O34 -> 0 | I32: ='Powerhouse Daily Performance'!U34 -> 0 | J32: ='Powerhouse Daily Performance'!AA34 -> 0 | K32: ='FEEDER Consumption '!C36 -> 0 | L32: ='FEEDER Consumption '!E36 -> 0 | M32: ='FEEDER Consumption '!G36 -> 0 | N32: ='FEEDER Consumption '!I36 -> 0 | O32: ='FEEDER Consumption '!K36 -> 0 | P32: ='FEEDER Consumption '!M36 -> 0 | Q32: ='FEEDER Consumption '!O36 -> 0 | R32: ='FEEDER Consumption '!Q36 -> 0 | S32: ='FEEDER Consumption '!S36 -> 0 | T32: ='FEEDER Consumption '!U36 -> 0 | U32: ='FEEDER Consumption '!W36 -> 0 | V32: ='FEEDER Consumption '!Y36 -> 0 | W32: ='FEEDER Consumption '!AA36 -> 0 | X32: ='FEEDER Consumption '!AC36 -> 0 | Y32: ='FEEDER Consumption '!AE36 -> 0 | Z32: ='FEEDER Consumption '!AG36 -> 0 | AA32: ='FEEDER Consumption '!AI36 -> 0 | AB32: ='FEEDER Consumption '!AK36 -> 0 | AC32: ='FEEDER Consumption '!AM36 -> 0 | AD32: ='FEEDER Consumption '!AO36 -> 0 | AE32: ='FEEDER Consumption '!AQ36 -> 0 | AF32: ='FEEDER Consumption '!AS36 -> 0 | AG32: ='FEEDER Consumption '!AU36 -> 0 | AH32: ='FEEDER Consumption '!AW36 -> 0 | AI32: ='FEEDER Consumption '!AY36 -> 0 | AJ32: ='FEEDER Consumption '!BA36 -> 0 | AK32: ='FEEDER Consumption '!BC36 -> 0 | AL32: ='FEEDER Consumption '!BE36 -> 0 | AM32: ='FEEDER Consumption '!BG36 -> 0 | AN32: ='Water Plant Daily Performance'!C34 -> 0 | AO32: ='Water Plant Daily Performance'!I34 -> 0 | AP32: ='Water Plant Daily Performance'!O34 -> 0 | AQ32: ='Water Plant Daily Performance'!U34 -> 0 | AR32: =Water!AD37 -> 0 | AS32: =Water!AH37 -> 0 | AT32: =Water!AJ37 -> 0 | AU32: =Water!AL37 -> 0 | AV32: =Water!AN37 -> 0 | AW32: =Water!AP37 -> 0 | AX32: =Water!AR37 -> 0 | AY32: =Water!AT37 -> 0 | AZ32: =Water!AT37 -> 0 | BA32: =Water!AX37 -> 0 | BB32: =Water!AZ37 -> 0 | BC32: =Water!BB37 -> 0 | BD32: =Water!BD37 -> 0 | BE32: =Water!BF37 -> 0 | BF32: =Water!BH37 -> 0 | BG32: =Water!BJ37 -> 0 | BH32: =Water!BL37 -> 0 | BI32: =Water!BP37 -> 0 | BJ32: =Water!BR37 -> 0 | BK32: =Water!BT37 -> 0 | BL32: =Water!BV37 -> 0 | BM32: ='Room Nights & Food Covers'!B38 -> 0 | BN32: ='Room Nights & Food Covers'!D38 -> 0

Sheet Daily Utility Report
A4: Daily Utility Report
A5: 44958
A7: DAY | B7: Occupancy | C7: No. of Guests | D7: Genset (Kwh) | E7: Solar (Kwh) | F7: Total (Kwh) | G7: Water Consumption ( m3) | H7: Gas Consumption (kg) | I7: Genset Diesel Consumption (Liters) | J7: Boats Diesel Consumption (Liters) | K7: Boats Petrol Consumption (Liters)
A8: 1 | B8: =TOTAL!M2 -> 57 | C8: ='Room Nights & Food Covers'!C5 -> 123 | D8: ='Powerhouse Daily Performance'!AG4 -> 27478 | E8: =Solar!C6 -> 3199 | F8: =E8+D8 -> 30677 | G8: ='Water Plant Daily Performance'!AG4 -> 350 | H8: ='LPG Gas'!G5 -> 225 | I8: ='Diesel consumption'!C8 -> 7750 | J8: ='Diesel consumption'!F8 -> 500 | K8: ='Diesel consumption'!M8 -> 800
A9: 2 | B9: =TOTAL!M3 -> 57 | C9: ='Room Nights & Food Covers'!C6 -> 125 | D9: ='Powerhouse Daily Performance'!AG5 -> 28384 | E9: =Solar!C7 -> 2956 | F9: =E9+D9 -> 31340 | G9: ='Water Plant Daily Performance'!AG5 -> 341 | H9: ='LPG Gas'!G6 -> 225 | I9: ='Diesel consumption'!C9 -> 7890 | J9: ='Diesel consumption'!F9 -> 3440 | K9: ='Diesel consumption'!M9 -> 1750
A10: 3 | B10: =TOTAL!M4 -> 58 | C10: ='Room Nights & Food Covers'!C7 -> 128 | D10: ='Powerhouse Daily Performance'!AG6 -> 28047 | E10: =Solar!C8 -> 3031 | F10: =E10+D10 -> 31078 | G10: ='Water Plant Daily Performance'!AG6 -> 338 | H10: ='LPG Gas'!G7 -> 315 | I10: ='Diesel consumption'!C10 -> 7780 | J10: ='Diesel consumption'!F10 -> 640 | K10: ='Diesel consumption'!M10 -> 740
A11: 4 | B11: =TOTAL!M5 -> 59 | C11: ='Room Nights & Food Covers'!C8 -> 124 | D11: ='Powerhouse Daily Performance'!AG7 -> 27363 | E11: =Solar!C9 -> 2866 | F11: =E11+D11 -> 30229 | G11: ='Water Plant Daily Performance'!AG7 -> 377 | H11: ='LPG Gas'!G8 -> 270 | I11: ='Diesel consumption'!C11 -> 7580 | J11: ='Diesel consumption'!F11 -> 2090 | K11: ='Diesel consumption'!M11 -> 550
A12: 5 | B12: =TOTAL!M6 -> 56 | C12: ='Room Nights & Food Covers'!C9 -> 126 | D12: ='Powerhouse Daily Performance'!AG8 -> 26732 | E12: =Solar!C10 -> 2096 | F12: =E12+D12 -> 28828 | G12: ='Water Plant Daily Performance'!AG8 -> 298 | H12: ='LPG Gas'!G9 -> 270 | I12: ='Diesel consumption'!C12 -> 7360 | J12: ='Diesel consumption'!F12 -> 0 | K12: ='Diesel consumption'!M12 -> 1200
A13: 6 | B13: =TOTAL!M7 -> 63 | C13: ='Room Nights & Food Covers'!C10 -> 135 | D13: ='Powerhouse Daily Performance'!AG9 -> 25607 | E13: =Solar!C11 -> 1133 | F13: =E13+D13 -> 26740 | G13: ='Water Plant Daily Performance'!AG9 -> 297 | H13: ='LPG Gas'!G10 -> 180 | I13: ='Diesel consumption'!C13 -> 7070 | J13: ='Diesel consumption'!F13 -> 1640 | K13: ='Diesel consumption'!M13 -> 2310
A14: 7 | B14: =TOTAL!M8 -> 61 | C14: ='Room Nights & Food Covers'!C11 -> 139 | D14: ='Powerhouse Daily Performance'!AG10 -> 26219 | E14: =Solar!C12 -> 3060 | F14: =E14+D14 -> 29279 | G14: ='Water Plant Daily Performance'!AG10 -> 344 | H14: ='LPG Gas'!G11 -> 315 | I14: ='Diesel consumption'!C14 -> 6410 | J14: ='Diesel consumption'!F14 -> 500 | K14: ='Diesel consumption'!M14 -> 960
A15: 8 | B15: =TOTAL!M9 -> 0 | C15: ='Room Nights & Food Covers'!C12 -> 0 | D15: ='Powerhouse Daily Performance'!AG11 -> 28435 | E15: =Solar!C13 -> 2975 | F15: =E15+D15 -> 31410 | G15: ='Water Plant Daily Performance'!AG11 -> 351 | H15: ='LPG Gas'!G12 -> 135 | I15: ='Diesel consumption'!C15 -> 9460 | J15: ='Diesel consumption'!F15 -> 0 | K15: ='Diesel consumption'!M15 -> 1290
A16: 9 | B16: =TOTAL!M10 -> 0 | C16: ='Room Nights & Food Covers'!C13 -> 0 | D16: ='Powerhouse Daily Performance'!AG12 -> 0 | E16: =Solar!C14 -> 0 | F16: =E16+D16 -> 0 | G16: ='Water Plant Daily Performance'!AG12 -> 0 | H16: ='LPG Gas'!G13 -> 0 | I16: ='Diesel consumption'!C16 -> 0 | J16: ='Diesel consumption'!F16 -> 0 | K16: ='Diesel consumption'!M16 -> 0
A17: 10 | B17: =TOTAL!M11 -> 0 | C17: ='Room Nights & Food Covers'!C14 -> 0 | D17: ='Powerhouse Daily Performance'!AG13 -> 0 | E17: =Solar!C15 -> 0 | F17: =E17+D17 -> 0 | G17: ='Water Plant Daily Performance'!AG13 -> 0 | H17: ='LPG Gas'!G14 -> 0 | I17: ='Diesel consumption'!C17 -> 0 | J17: ='Diesel consumption'!F17 -> 0 | K17: ='Diesel consumption'!M17 -> 0
A18: 11 | B18: =TOTAL!M12 -> 0 | C18: ='Room Nights & Food Covers'!C15 -> 0 | D18: ='Powerhouse Daily Performance'!AG14 -> 0 | E18: =Solar!C16 -> 0 | F18: =E18+D18 -> 0 | G18: ='Water Plant Daily Performance'!AG14 -> 0 | H18: ='LPG Gas'!G15 -> 0 | I18: ='Diesel consumption'!C18 -> 0 | J18: ='Diesel consumption'!F18 -> 0 | K18: ='Diesel consumption'!M18 -> 0
A19: 12 | B19: =TOTAL!M13 -> 0 | C19: ='Room Nights & Food Covers'!C16 -> 0 | D19: ='Powerhouse Daily Performance'!AG15 -> 0 | E19: =Solar!C17 -> 0 | F19: =E19+D19 -> 0 | G19: ='Water Plant Daily Performance'!AG15 -> 0 | H19: ='LPG Gas'!G16 -> 0 | I19: ='Diesel consumption'!C19 -> 0 | J19: ='Diesel consumption'!F19 -> 0 | K19: ='Diesel consumption'!M19 -> 0
... A35: 28 | B35: =TOTAL!M29 -> 0 | C35: ='Room Nights & Food Covers'!C32 -> 0 | D35: ='Powerhouse Daily Performance'!AG31 -> 0 | E35: =Solar!C33 -> 0 | F35: =E35+D35 -> 0 | G35: ='Water Plant Daily Performance'!AG31 -> 0 | H35: ='LPG Gas'!G32 -> 0 | I35: ='Diesel consumption'!C35 -> 0 | J35: ='Diesel consumption'!F35 -> 0 | K35: ='Diesel consumption'!M35 -> 0
A36: 29 | B36: =TOTAL!M30 -> 0 | C36: ='Room Nights & Food Covers'!C36 -> 0 | D36: ='Powerhouse Daily Performance'!AG32 -> 0 | E36: =Solar!C34 -> 0 | F36: =E36+D36 -> 0 | G36: ='Water Plant Daily Performance'!AG32 -> 0 | H36: ='LPG Gas'!G33 -> 0 | I36: ='Diesel consumption'!C36 -> 0 | J36: ='Diesel consumption'!F36 -> 0 | K36: ='Diesel consumption'!M36 -> 0
A37: 30 | B37: =TOTAL!M31 -> 0 | C37: ='Room Nights & Food Covers'!C37 -> 0 | D37: ='Powerhouse Daily Performance'!AG33 -> 0 | E37: =Solar!C35 -> 0 | F37: =E37+D37 -> 0 | G37: ='Water Plant Daily Performance'!AG33 -> 0 | H37: ='LPG Gas'!G34 -> 0 | I37: ='Diesel consumption'!C37 -> 0 | J37: ='Diesel consumption'!F37 -> 0 | K37: ='Diesel consumption'!M37 -> 0
A38: 31 | B38: =TOTAL!M32 -> 0 | C38: ='Room Nights & Food Covers'!C38 -> 0 | D38: ='Powerhouse Daily Performance'!AG34 -> 0 | E38: =Solar!C36 -> 0 | F38: =E38+D38 -> 0 | G38: ='Water Plant Daily Performance'!AG34 -> 0 | H38: ='LPG Gas'!G35 -> 0 | I38: ='Diesel consumption'!C38 -> 0 | J38: ='Diesel consumption'!F38 -> 0 | K38: ='Diesel consumption'!M38 -> 0
A39: Total | D39: ='Powerhouse Daily Performance'!AG35 -> 218265 | E39: =SUM(E8:E38) -> 21316 | F39: =SUM(F8:F35) -> 239581 | G39: =SUM(G8:G38) -> 2696 | H39: ='LPG Gas'!G36 -> 0 | I39: =SUM(I8:I35) -> 61300 | J39: =SUM(J8:J35) -> 8810 | K39: =SUM(K8:K35) -> 9600
A40: Avg | D40: ='Powerhouse Daily Performance'!AG36 -> 0 | E40: =Solar!C38 -> 0 | F40: =F39/A41 -> 7728.4194 | G40: ='Water Plant Daily Performance'!AG36 -> 0 | H40: ='LPG Gas'!G37 -> 0 | I40: =I39/A41 -> 1977.4194 | J40: =J39/A41 -> 284.19355 | K40: =K39/A41 -> 309.67742
A41: 31

Sheet All Genset Readings
A1: All Genset Meter Readings
A4: Date | C4: Generator No. 1 - 1000 KVA | G4: Generator No. 2 - 1600 KVA | K4: Generator No. 3 - 900 KVA | O4: Generator No. 4 - 500 KVA | S4: Generator No. 5 - 1000 KVA
C5: Kwh | D5: R. Hours | E5: Diesel | G5: Kwh | H5: R. Hours | I5: Diesel | K5: Kwh | L5: R. Hours | M5: Diesel | O5: Kwh | P5: R. Hours | Q5: Diesel | S5: Kwh | T5: R. Hours | U5: Diesel
A6: 44985 | C6: 20933641 | D6: 37985 | G6: 35323684 | H6: 43254 | K6: 15890284 | L6: 80806 | O6: 12942208 | P6: 53927 | S6: 21963230 | T6: 83260
A7: =A6+1 -> 44986 | C7: 20938554 | D7: 37996 | E7: 1520 | G7: 35334283 | H7: 43268 | I7: 3230 | K7: 15894495 | L7: 80817 | M7: 1140 | O7: 12944508 | P7: 53937 | Q7: 720 | S7: 21968685 | T7: 83272 | U7: 1120
A8: =A7+1 -> 44987 | C8: 20944978 | D8: 38009 | E8: 1830 | G8: 35342530 | H8: 43278 | I8: 2470 | K8: 15901152 | L8: 80833 | M8: 1600 | O8: 12946914 | P8: 53947 | Q8: 610 | S8: 21973335 | T8: 83282 | U8: 1460
A9: =A8+1 -> 44988 | C9: 20950996 | D9: 38022 | E9: 2070 | G9: 35349682 | H9: 43288 | I9: 2110 | K9: 15906128 | L9: 80845 | M9: 1320 | O9: 12949564 | P9: 53958 | Q9: 810 | S9: 21980586 | T9: 83299 | U9: 1450
A10: =A9+1 -> 44989 | C10: 20958688 | D10: 38038 | E10: 2000 | G10: 35356115 | H10: 43296 | I10: 1920 | K10: 15911056 | L10: 80856 | M10: 1190 | O10: 12952507 | P10: 53970 | Q10: 780 | S10: 21985953 | T10: 83309 | U10: 1480
A11: =A10+1 -> 44990 | C11: 20960438 | D11: 38043 | E11: 500 | G11: 35361837 | H11: 43303 | I11: 1600 | K11: 15918602 | L11: 80873 | M11: 1880 | O11: 12955764 | P11: 53983 | Q11: 590 | S11: 21994410 | T11: 83326 | U11: 2300
A12: =A11+1 -> 44991 | C12: 20960438 | D12: 38043 | E12: 0 | G12: 35378394 | H12: 43325 | I12: 4820 | K12: 15919524 | L12: 80876 | M12: 250 | O12: 12956390 | P12: 53987 | Q12: 120 | S12: 22001912 | T12: 83343 | U12: 1860
A13: =A12+1 -> 44992 | C13: 20963821 | D13: 38051 | E13: 0 | G13: 35391216 | H13: 43343 | I13: 3570 | K13: 15925477 | L13: 80890 | M13: 1890 | O13: 12958302 | P13: 53995 | Q13: 530 | S13: 22004061 | T13: 83348 | U13: 400
A14: =A13+1 -> 44993 | C14: 20969354 | D14: 38063 | E14: 3270 | G14: 35401008 | H14: 43356 | I14: 2770 | K14: 15933277 | L14: 80908 | M14: 2000 | O14: 12958856 | P14: 53998 | Q14: 170 | S14: 22008817 | T14: 83358 | U14: 1190
A15: =A14+1 -> 44994
A16: =A15+1 -> 44995
A17: =A16+1 -> 44996
A18: =A17+1 -> 44997
A19: =A18+1 -> 44998
A20: =A19+1 -> 44999
A21: =A20+1 -> 45000
A22: =A21+1 -> 45001
A23: =A22+1 -> 45002
A24: =A23+1 -> 45003
A25: =A24+1 -> 45004
A26: =A25+1 -> 45005
... A37: =A36+1 -> 45016

Sheet Diesel consumption
A1: Diesel Consumption meter reading
A3: Diesel Consumption - Powerhouse | E3: Diesel Tank Jetty Meter | L3: Petrol Tank Jetty Meter
E5: Boat meter Reading | L5: Boat meter Reading
A6: Date | B6: Today | C6: ConsumptionIn 24 hrs | E6: Reading | F6: Consumption (Liters) | H6: In Barrels | J6: Carbon Emmision | L6: Reading | M6: Consumption (Liters)
A7: ='All Genset Readings'!A6 -> 44985 | B7: 48722640 | E7: 1488590 | H7: =C7/200 -> 0 | J7: =2.68*C7 -> 0 | K7: =J7/1000 -> 0 | L7: 51170
A8: ='All Genset Readings'!A7 -> 44986 | B8: 48730390 | C8: =MAX(0,B8-B7) -> 7750 | E8: 1489090 | F8: =MAX(0,E8-E7) -> 500 | H8: =C8/200 -> 38.75 | J8: =2.68*C8 -> 20770 | K8: =J8/1000 -> 20.77 | L8: 51970 | M8: =MAX(0,L8-L7) -> 800
A9: ='All Genset Readings'!A8 -> 44987 | B9: 48738280 | C9: =MAX(0,B9-B8) -> 7890 | E9: 1492530 | F9: =MAX(0,E9-E8) -> 3440 | H9: =C9/200 -> 39.45 | J9: =2.68*C9 -> 21145.2 | K9: =J9/1000 -> 21.1452 | L9: 53720 | M9: =MAX(0,L9-L8) -> 1750
A10: ='All Genset Readings'!A9 -> 44988 | B10: 48746060 | C10: =MAX(0,B10-B9) -> 7780 | E10: 1493170 | F10: =MAX(0,E10-E9) -> 640 | H10: =C10/200 -> 38.9 | J10: =2.68*C10 -> 20850.4 | K10: =J10/1000 -> 20.8504 | L10: 54460 | M10: =MAX(0,L10-L9) -> 740
A11: ='All Genset Readings'!A10 -> 44989 | B11: 48753640 | C11: =MAX(0,B11-B10) -> 7580 | E11: 1495260 | F11: =MAX(0,E11-E10) -> 2090 | H11: =C11/200 -> 37.9 | J11: =2.68*C11 -> 20314.4 | K11: =J11/1000 -> 20.3144 | L11: 55010 | M11: =MAX(0,L11-L10) -> 550
A12: ='All Genset Readings'!A11 -> 44990 | B12: 48761000 | C12: =MAX(0,B12-B11) -> 7360 | E12: 1495260 | F12: =MAX(0,E12-E11) -> 0 | H12: =C12/200 -> 36.8 | J12: =2.68*C12 -> 19724.8 | K12: =J12/1000 -> 19.7248 | L12: 56210 | M12: =MAX(0,L12-L11) -> 1200
A13: ='All Genset Readings'!A12 -> 44991 | B13: 48768070 | C13: =MAX(0,B13-B12) -> 7070 | E13: 1496900 | F13: =MAX(0,E13-E12) -> 1640 | H13: =C13/200 -> 35.35 | J13: =2.68*C13 -> 18947.6 | K13: =J13/1000 -> 18.9476 | L13: 58520 | M13: =MAX(0,L13-L12) -> 2310
A14: ='All Genset Readings'!A13 -> 44992 | B14: 48774480 | C14: =MAX(0,B14-B13) -> 6410 | E14: 1497400 | F14: =MAX(0,E14-E13) -> 500 | H14: =C14/200 -> 32.05 | J14: =2.68*C14 -> 17178.8 | K14: =J14/1000 -> 17.1788 | L14: 59480 | M14: =MAX(0,L14-L13) -> 960
A15: ='All Genset Readings'!A14 -> 44993 | B15: 48783940 | C15: =MAX(0,B15-B14) -> 9460 | E15: 1497400 | F15: =MAX(0,E15-E14) -> 0 | H15: =C15/200 -> 47.3 | J15: =2.68*C15 -> 25352.8 | K15: =J15/1000 -> 25.3528 | L15: 60770 | M15: =MAX(0,L15-L14) -> 1290
A16: ='All Genset Readings'!A15 -> 44994 | C16: =MAX(0,B16-B15) -> 0 | F16: =MAX(0,E16-E15) -> 0 | H16: =C16/200 -> 0 | J16: =2.68*C16 -> 0 | K16: =J16/1000 -> 0 | M16: =MAX(0,L16-L15) -> 0
A17: ='All Genset Readings'!A16 -> 44995 | C17: =MAX(0,B17-B16) -> 0 | F17: =MAX(0,E17-E16) -> 0 | H17: =C17/200 -> 0 | J17: =2.68*C17 -> 0 | K17: =J17/1000 -> 0 | M17: =MAX(0,L17-L16) -> 0
A18: ='All Genset Readings'!A17 -> 44996 | C18: =MAX(0,B18-B17) -> 0 | F18: =MAX(0,E18-E17) -> 0 | H18: =C18/200 -> 0 | J18: =2.68*C18 -> 0 | K18: =J18/1000 -> 0 | M18: =MAX(0,L18-L17) -> 0
A19: ='All Genset Readings'!A18 -> 44997 | C19: =MAX(0,B19-B18) -> 0 | F19: =MAX(0,E19-E18) -> 0 | H19: =C19/200 -> 0 | J19: =2.68*C19 -> 0 | K19: =J19/1000 -> 0 | M19: =MAX(0,L19-L18) -> 0
A20: ='All Genset Readings'!A19 -> 44998 | C20: =MAX(0,B20-B19) -> 0 | F20: =MAX(0,E20-E19) -> 0 | H20: =C20/200 -> 0 | J20: =2.68*C20 -> 0 | K20: =J20/1000 -> 0 | M20: =MAX(0,L20-L19) -> 0
A21: ='All Genset Readings'!A20 -> 44999 | C21: =MAX(0,B21-B20) -> 0 | F21: =MAX(0,E21-E20) -> 0 | H21: =C21/200 -> 0 | J21: =2.68*C21 -> 0 | K21: =J21/1000 -> 0 | M21: =MAX(0,L21-L20) -> 0
A22: ='All Genset Readings'!A21 -> 45000 | C22: =MAX(0,B22-B21) -> 0 | F22: =MAX(0,E22-E21) -> 0 | H22: =C22/200 -> 0 | J22: =2.68*C22 -> 0 | K22: =J22/1000 -> 0 | M22: =MAX(0,L22-L21) -> 0
A23: ='All Genset Readings'!A22 -> 45001 | C23: =MAX(0,B23-B22) -> 0 | F23: =MAX(0,E23-E22) -> 0 | H23: =C23/200 -> 0 | J23: =2.68*C23 -> 0 | K23: =J23/1000 -> 0 | M23: =MAX(0,L23-L22) -> 0
A24: ='All Genset Readings'!A23 -> 45002 | C24: =MAX(0,B24-B23) -> 0 | F24: =MAX(0,E24-E23) -> 0 | H24: =C24/200 -> 0 | J24: =2.68*C24 -> 0 | K24: =J24/1000 -> 0 | M24: =MAX(0,L24-L23) -> 0
A25: ='All Genset Readings'!A24 -> 45003 | C25: =MAX(0,B25-B24) -> 0 | F25: =MAX(0,E25-E24) -> 0 | H25: =C25/200 -> 0 | J25: =2.68*C25 -> 0 | K25: =J25/1000 -> 0 | M25: =MAX(0,L25-L24) -> 0
A26: ='All Genset Readings'!A25 -> 45004 | C26: =MAX(0,B26-B25) -> 0 | F26: =MAX(0,E26-E25) -> 0 | H26: =C26/200 -> 0 | J26: =2.68*C26 -> 0 | K26: =J26/1000 -> 0 | M26: =MAX(0,L26-L25) -> 0
A27: ='All Genset Readings'!A26 -> 45005 | C27: =MAX(0,B27-B26) -> 0 | F27: =MAX(0,E27-E26) -> 0 | H27: =C27/200 -> 0 | J27: =2.68*C27 -> 0 | K27: =J27/1000 -> 0 | M27: =MAX(0,L27-L26) -> 0
... A35: ='All Genset Readings'!A34 -> 45013 | C35: =MAX(0,B35-B34) -> 0 | F35: =MAX(0,E35-E34) -> 0 | H35: =C35/200 -> 0 | J35: =2.68*C35 -> 0 | K35: =J35/1000 -> 0 | M35: =MAX(0,L35-L34) -> 0
A36: ='All Genset Readings'!A35 -> 45014 | C36: =MAX(0,B36-B35) -> 0 | F36: =MAX(0,E36-E35) -> 0 | H36: =SUM(H7:H35) -> 306.5 | J36: =2.68*C36 -> 0 | K36: =J36/1000 -> 0 | M36: =MAX(0,L36-L35) -> 0
A37: ='All Genset Readings'!A36 -> 45015 | C37: =MAX(0,B37-B36) -> 0 | F37: =MAX(0,E37-E36) -> 0 | M37: =MAX(0,L37-L36) -> 0
