Workbook

Sheet Total
A1: Site Name | B1: Day | C1: Month | D1: Year | E1: Total Electricity Kwh | F1: Electricity Tariff ($/Kwh) | G1: Natual Gas (m3) | H1: Natural Gas $/m3 | I1: Water Utility Supply (m3) m3 | J1: Water Utility Supply (m3) $/m3 | K1: Room Nights
A2: Cairo at The First Residence | B2: 1 | C2: 8 | D2: 2022 | E2: =Elect!BS6+Submetering!AH2 -> 39596.177 | F2: ='Utility Consnsumption'!K13/'Utility Consnsumption'!J13 -> 1.3181724 | G2: =Gas!K7+Submetering!AR2 -> 1608.68 | H2: 3.8 | I2: =Water!H7+Submetering!AM2 -> 866.52 | J2: 10 | K2: =Elect!BT6 -> 158
A3: Cairo at The First Residence | B3: =B2+1 -> 2 | C3: 8 | D3: 2022 | E3: =Elect!BS7+Submetering!AH3 -> 34267.993 | F3: =F2 -> 1.3181724 | G3: =Gas!K8+Submetering!AR3 -> 1072.48 | H3: 3.8 | I3: =Water!H8+Submetering!AM3 -> 116 | J3: 10 | K3: =Elect!BT7 -> 162
A4: Cairo at The First Residence | B4: =B3+1 -> 3 | C4: 8 | D4: 2022 | E4: =Elect!BS8+Submetering!AH4 -> 33135.42 | F4: =F3 -> 1.3181724 | G4: =Gas!K9+Submetering!AR4 -> 1056.38 | H4: 3.8 | I4: =Water!H9+Submetering!AM4 -> 183.86 | J4: 10 | K4: =Elect!BT8 -> 173
A5: Cairo at The First Residence | B5: =B4+1 -> 4 | C5: 8 | D5: 2022 | E5: =Elect!BS9+Submetering!AH5 -> 33662.663 | F5: =F4 -> 1.3181724 | G5: =Gas!K10+Submetering!AR5 -> 1067.1133 | H5: 3.8 | I5: =Water!H10+Submetering!AM5 -> 177.28667 | J5: 10 | K5: =Elect!BT9 -> 202
A6: Cairo at The First Residence | B6: =B5+1 -> 5 | C6: 8 | D6: 2022 | E6: =Elect!BS10+Submetering!AH6 -> 36835.723 | F6: =F5 -> 1.3181724 | G6: =Gas!K11+Submetering!AR6 -> 1476.8467 | H6: 3.8 | I6: =Water!H11+Submetering!AM6 -> 666.03333 | J6: 10 | K6: =Elect!BT10 -> 216
A7: Cairo at The First Residence | B7: =B6+1 -> 6 | C7: 8 | D7: 2022 | E7: =Elect!BS11+Submetering!AH7 -> 30744.545 | F7: =F6 -> 1.3181724 | G7: =Gas!K12+Submetering!AR7 -> 1225.78 | H7: 3.8 | I7: =Water!H12+Submetering!AM7 -> 385.12 | J7: 10 | K7: =Elect!BT11 -> 224
A8: Cairo at The First Residence | B8: =B7+1 -> 7 | C8: 8 | D8: 2022 | E8: =Elect!BS12+Submetering!AH8 -> 33673.663 | F8: =F7 -> 1.3181724 | G8: =Gas!K13+Submetering!AR8 -> 1258.68 | H8: 3.8 | I8: =Water!H13+Submetering!AM8 -> 415.28 | J8: 10 | K8: =Elect!BT12 -> 221
A9: Cairo at The First Residence | B9: =B8+1 -> 8 | C9: 8 | D9: 2022 | E9: =Elect!BS13+Submetering!AH9 -> 34183.317 | F9: =F8 -> 1.3181724 | G9: =Gas!K14+Submetering!AR9 -> 1264.28 | H9: 3.8 | I9: =Water!H14+Submetering!AM9 -> 392.66 | J9: 10 | K9: =Elect!BT13 -> 216
A10: Cairo at The First Residence | B10: =B9+1 -> 9 | C10: 8 | D10: 2022 | E10: =Elect!BS14+Submetering!AH10 -> 34963.623 | F10: =F9 -> 1.3181724 | G10: =Gas!K15+Submetering!AR10 -> 1264.98 | H10: 3.8 | I10: =Water!H15+Submetering!AM10 -> 446.6 | J10: 10 | K10: =Elect!BT14 -> 197
A11: Cairo at The First Residence | B11: =B10+1 -> 10 | C11: 8 | D11: 2022 | E11: =Elect!BS15+Submetering!AH11 -> 34951.475 | F11: =F10 -> 1.3181724 | G11: =Gas!K16+Submetering!AR11 -> 1240.48 | H11: 3.8 | I11: =Water!H16+Submetering!AM11 -> 440.8 | J11: 10 | K11: =Elect!BT15 -> 194
A12: Cairo at The First Residence | B12: =B11+1 -> 11 | C12: 8 | D12: 2022 | E12: =Elect!BS16+Submetering!AH12 -> 35833.125 | F12: =F11 -> 1.3181724 | G12: =Gas!K17+Submetering!AR12 -> 1256.8133 | H12: 3.8 | I12: =Water!H17+Submetering!AM12 -> 444.66667 | J12: 10 | K12: =Elect!BT16 -> 211
A13: Cairo at The First Residence | B13: =B12+1 -> 12 | C13: 8 | D13: 2022 | E13: =Elect!BS17+Submetering!AH13 -> 34246.55 | F13: =F12 -> 1.3181724 | G13: =Gas!K18+Submetering!AR13 -> 1211.5467 | H13: 3.8 | I13: =Water!H18+Submetering!AM13 -> 402.13333 | J13: 10 | K13: =Elect!BT17 -> 239
A14: Cairo at The First Residence | B14: =B13+1 -> 13 | C14: 8 | D14: 2022 | E14: =Elect!BS18+Submetering!AH14 -> 32901.565 | F14: =F13 -> 1.3181724 | G14: =Gas!K19+Submetering!AR14 -> 1218.08 | H14: 3.8 | I14: =Water!H19+Submetering!AM14 -> 386.28 | J14: 10 | K14: =Elect!BT18 -> 227
... A32: Cairo at The First Residence | B32: =B31+1 -> 31 | C32: 8 | D32: 2022 | E32: =Elect!BS36+Submetering!AH32 -> 35463.229 | F32: =F31 -> 1.3181724 | G32: =Gas!K37+Submetering!AR32 -> 1278.2622 | H32: 3.8 | I32: =Water!H37+Submetering!AM32 -> 352.25333 | J32: 10 | K32: =Elect!BT36 -> 134

Sheet Submetering
A1: Site Name | B1: Day | C1: Month | D1: Year | E1: Electricity | F1: Main Feeder -KWh | G1: T2+T8 -KWh | H1: La Gourmandize -KWh | I1: Casino 3rd floor EM -KWh | J1: Casino 3rd floor Normal -KWh | K1: Chiller 1 -KWh | L1: Chiller 2 -KWh | M1: Chiller 3 -KWh | N1: Chiller 4 -KWh | O1: Chiller 5 -KWh | P1: Chiller 6 -KWh | Q1: Cooling towers -KWh | R1: Chiller Pumps -KWh | S1: Cooling Tower Pumps -KWh | T1: Fiber Chiller -KWh | U1: Mall Ceiling light -KWh | V1: LG Bakery -KWh | W1: LG Bakery light ( Old lockers ) -KWh | X1: MCCR1 -KWh | Y1: Children Swimming Pool -KWh | Z1: DPH1 -KWh | AA1: Guest Rooms Emerg. -KWh | AB1: Hotel Hoods -KWh | AC1: Main G2 -KWh | AD1: Old Casino Emergency -KWh | AE1: L / A -KWh | AF1: L / B -KWh | AG1: L / C -KWh | AH1: Boat -KWh | AI1: Water | AJ1: Main water meter 1 -m3 | AK1: Main water meter 2 -m3 | AL1: Main water meter 3 -m3 | AM1: Boat -m3 | AN1: Gas | AO1: Main Gas Flow Meter -m3 | AP1: Laundry Gas Flow Meter -m3 | AQ1: Gourmandize Gas Flow Meter -m3 | AR1: Boat -m3 | AS1: Room Nights
A2: Cairo at The First Residence | B2: 1 | C2: 8 | D2: 2022 | F2: =Elect!J6 -> 6551.3333 | G2: =Elect!K6 -> 5401.3333 | H2: =Elect!Q6 -> 562 | I2: =Elect!S6 -> 140.5 | J2: =Elect!U6 -> 294.5 | K2: =Elect!W6 -> 0 | L2: =Elect!Y6 -> 1226.95 | M2: =Elect!AA6 -> 6873.57 | N2: =Elect!AC6 -> 3188.745 | O2: =Elect!AE6 -> 0 | P2: =Elect!AG6 -> 2824.105 | Q2: =Elect!AI6 -> 1167.9787 | R2: =Elect!AK6 -> 3983.48 | S2: =Elect!AM6 -> 122.35933 | T2: =Elect!AP6 -> 273.825 | U2: =Elect!AR6 -> 165 | V2: =Elect!AT6 -> 173.2 | W2: =Elect!AV6 -> 56.3 | X2: =Elect!AX6 -> 1080.5 | Y2: =Elect!AZ6 -> 0 | Z2: =Elect!BB6 -> 4381.7 | AA2: =Elect!BD6 -> 269.4 | AB2: =Elect!BF6 -> 82.611111 | AC2: =Elect!BH6 -> 6613.12 | AD2: =Elect!BL6 -> 390.1 | AE2: =Elect!BN6 -> 1708.4 | AF2: =Elect!BP6 -> 108 | AG2: =Elect!BR6 -> 164.5 | AH2: =Boat!C4 -> 0 | AJ2: =Water!C7 -> 261 | AK2: =Water!E7 -> 353.8 | AL2: =Water!G7 -> 251.72 | AM2: =Boat!E4 -> 0 | AO2: =Gas!C7 -> 935.98 | AP2: =Gas!E7 -> 672.7 | AQ2: =Gas!G7 -> 90.044444 | AR2: =Boat!G4 -> 0 | AS2: =Elect!BT6 -> 158
A3: Cairo at The First Residence | B3: =B2+1 -> 2 | C3: 8 | D3: 2022 | F3: =Elect!J7 -> 5918 | G3: =Elect!K7 -> 5016 | H3: =Elect!Q7 -> 480 | I3: =Elect!S7 -> 143 | J3: =Elect!U7 -> 281 | K3: =Elect!W7 -> 0 | L3: =Elect!Y7 -> 0 | M3: =Elect!AA7 -> 4241.06 | N3: =Elect!AC7 -> 3978.18 | O3: =Elect!AE7 -> 855.95 | P3: =Elect!AG7 -> 12.19 | Q3: =Elect!AI7 -> 1150.1 | R3: =Elect!AK7 -> 3852.04 | S3: =Elect!AM7 -> 122.96 | T3: =Elect!AP7 -> 296.6625 | U3: =Elect!AR7 -> 177 | V3: =Elect!AT7 -> 168 | W3: =Elect!AV7 -> 64 | X3: =Elect!AX7 -> 1042 | Y3: =Elect!AZ7 -> 0 | Z3: =Elect!BB7 -> 5105 | AA3: =Elect!BD7 -> 263 | AB3: =Elect!BF7 -> 55 | AC3: =Elect!BH7 -> 6486.85 | AD3: =Elect!BL7 -> 313 | AE3: =Elect!BN7 -> 1576 | AF3: =Elect!BP7 -> 111 | AG3: =Elect!BR7 -> 151 | AH3: =Boat!C5 -> 0 | AJ3: =Water!C8 -> 17.4 | AK3: =Water!E8 -> 69.6 | AL3: =Water!G8 -> 29 | AM3: =Boat!E5 -> 0 | AO3: =Gas!C8 -> 935.98 | AP3: =Gas!E8 -> 136.5 | AQ3: =Gas!G8 -> 85 | AR3: =Boat!G5 -> 0 | AS3: =Elect!BT7 -> 162
A4: Cairo at The First Residence | B4: =B3+1 -> 3 | C4: 8 | D4: 2022 | F4: =Elect!J8 -> 5763 | G4: =Elect!K8 -> 4794 | H4: =Elect!Q8 -> 540 | I4: =Elect!S8 -> 139 | J4: =Elect!U8 -> 265 | K4: =Elect!W8 -> 0 | L4: =Elect!Y8 -> 2441.18 | M4: =Elect!AA8 -> 3903.98 | N4: =Elect!AC8 -> 1116.71 | O4: =Elect!AE8 -> 1681.16 | P4: =Elect!AG8 -> 11.66 | Q4: =Elect!AI8 -> 1084.91 | R4: =Elect!AK8 -> 3680.85 | S4: =Elect!AM8 -> 108.12 | T4: =Elect!AP8 -> 280.35 | U4: =Elect!AR8 -> 180 | V4: =Elect!AT8 -> 149 | W4: =Elect!AV8 -> 57 | X4: =Elect!AX8 -> 997 | Y4: =Elect!AZ8 -> 0 | Z4: =Elect!BB8 -> 4571 | AA4: =Elect!BD8 -> 283 | AB4: =Elect!BF8 -> 55 | AC4: =Elect!BH8 -> 6231.5 | AD4: =Elect!BL8 -> 304 | AE4: =Elect!BN8 -> 1526 | AF4: =Elect!BP8 -> 104 | AG4: =Elect!BR8 -> 135 | AH4: =Boat!C6 -> 0 | AJ4: =Water!C9 -> 75.4 | AK4: =Water!E9 -> 46.4 | AL4: =Water!G9 -> 62.06 | AM4: =Boat!E6 -> 0 | AO4: =Gas!C9 -> 935.98 | AP4: =Gas!E9 -> 120.4 | AQ4: =Gas!G9 -> 94 | AR4: =Boat!G6 -> 0 | AS4: =Elect!BT8 -> 173
A5: Cairo at The First Residence | B5: =B4+1 -> 4 | C5: 8 | D5: 2022 | F5: =Elect!J9 -> 5347 | G5: =Elect!K9 -> 4913 | H5: =Elect!Q9 -> 540 | I5: =Elect!S9 -> 137 | J5: =Elect!U9 -> 271 | K5: =Elect!W9 -> 0 | L5: =Elect!Y9 -> 3712.65 | M5: =Elect!AA9 -> 3924.65 | N5: =Elect!AC9 -> 0 | O5: =Elect!AE9 -> 1719.32 | P5: =Elect!AG9 -> 8.48 | Q5: =Elect!AI9 -> 1114.06 | R5: =Elect!AK9 -> 3791.09 | S5: =Elect!AM9 -> 121.9 | T5: =Elect!AP9 -> 296.6625 | U5: =Elect!AR9 -> 167 | V5: =Elect!AT9 -> 166 | W5: =Elect!AV9 -> 60 | X5: =Elect!AX9 -> 1106 | Y5: =Elect!AZ9 -> 0 | Z5: =Elect!BB9 -> 4895 | AA5: =Elect!BD9 -> 281 | AB5: =Elect!BF9 -> 43 | AC5: =Elect!BH9 -> 6368.85 | AD5: =Elect!BL9 -> 301 | AE5: =Elect!BN9 -> 1519 | AF5: =Elect!BP9 -> 108 | AG5: =Elect!BR9 -> 138 | AH5: =Boat!C7 -> 0 | AJ5: =Water!C10 -> 75.4 | AK5: =Water!E10 -> 61.866667 | AL5: =Water!G10 -> 40.02 | AM5: =Boat!E7 -> 0 | AO5: =Gas!C10 -> 935.98 | AP5: =Gas!E10 -> 131.13333 | AQ5: =Gas!G10 -> 88 | AR5: =Boat!G7 -> 0 | AS5: =Elect!BT9 -> 202
A6: Cairo at The First Residence | B6: =B5+1 -> 5 | C6: 8 | D6: 2022 | F6: =Elect!J10 -> 8470 | G6: =Elect!K10 -> 5034 | H6: =Elect!Q10 -> 270 | I6: =Elect!S10 -> 140 | J6: =Elect!U10 -> 273 | K6: =Elect!W10 -> 0 | L6: =Elect!Y10 -> 3879.6 | M6: =Elect!AA10 -> 4012.63 | N6: =Elect!AC10 -> 0 | O6: =Elect!AE10 -> 1666.85 | P6: =Elect!AG10 -> 10.6 | Q6: =Elect!AI10 -> 1129.43 | R6: =Elect!AK10 -> 3851.51 | S6: =Elect!AM10 -> 120.84 | T6: =Elect!AP10 -> 272.8125 | U6: =Elect!AR10 -> 172 | V6: =Elect!AT10 -> 172 | W6: =Elect!AV10 -> 54 | X6: =Elect!AX10 -> 1011 | Y6: =Elect!AZ10 -> 0 | Z6: =Elect!BB10 -> 5022 | AA6: =Elect!BD10 -> 287 | AB6: =Elect!BF10 -> 57 | AC6: =Elect!BH10 -> 6376.45 | AD6: =Elect!BL10 -> 306 | AE6: =Elect!BN10 -> 1509 | AF6: =Elect!BP10 -> 110 | AG6: =Elect!BR10 -> 140 | AH6: =Boat!C8 -> 0 | AJ6: =Water!C11 -> 191.4 | AK6: =Water!E11 -> 286.13333 | AL6: =Water!G11 -> 188.5 | AM6: =Boat!E8 -> 0 | AO6: =Gas!C11 -> 935.98 | AP6: =Gas!E11 -> 540.86667 | AQ6: =Gas!G11 -> 99 | AR6: =Boat!G8 -> 0 | AS6: =Elect!BT10 -> 216
A7: Cairo at The First Residence | B7: =B6+1 -> 6 | C7: 8 | D7: 2022 | F7: =Elect!J11 -> 1859 | G7: =Elect!K11 -> 4423 | H7: =Elect!Q11 -> 750 | I7: =Elect!S11 -> 139 | J7: =Elect!U11 -> 279 | K7: =Elect!W11 -> 0 | L7: =Elect!Y11 -> 3974.47 | M7: =Elect!AA11 -> 4052.91 | N7: =Elect!AC11 -> 0 | O7: =Elect!AE11 -> 1691.23 | P7: =Elect!AG11 -> 10.07 | Q7: =Elect!AI11 -> 1144.8 | R7: =Elect!AK11 -> 3906.63 | S7: =Elect!AM11 -> 117.66 | T7: =Elect!AP11 -> 278.325 | U7: =Elect!AR11 -> 163 | V7: =Elect!AT11 -> 165 | W7: =Elect!AV11 -> 51 | X7: =Elect!AX11 -> 977 | Y7: =Elect!AZ11 -> 0 | Z7: =Elect!BB11 -> 5070 | AA7: =Elect!BD11 -> 246 | AB7: =Elect!BF11 -> 53 | AC7: =Elect!BH11 -> 6234.45 | AD7: =Elect!BL11 -> 303 | AE7: =Elect!BN11 -> 1513 | AF7: =Elect!BP11 -> 106 | AG7: =Elect!BR11 -> 154 | AH7: =Boat!C9 -> 0 | AJ7: =Water!C12 -> 116 | AK7: =Water!E12 -> 156.6 | AL7: =Water!G12 -> 112.52 | AM7: =Boat!E9 -> 0 | AO7: =Gas!C12 -> 935.98 | AP7: =Gas!E12 -> 289.8 | AQ7: =Gas!G12 -> 89 | AR7: =Boat!G9 -> 0 | AS7: =Elect!BT11 -> 224
A8: Cairo at The First Residence | B8: =B7+1 -> 7 | C8: 8 | D8: 2022 | F8: =Elect!J12 -> 5452 | G8: =Elect!K12 -> 4425 | H8: =Elect!Q12 -> 540 | I8: =Elect!S12 -> 137 | J8: =Elect!U12 -> 270 | K8: =Elect!W12 -> 0 | L8: =Elect!Y12 -> 3861.05 | M8: =Elect!AA12 -> 1081.2 | N8: =Elect!AC12 -> 2762.36 | O8: =Elect!AE12 -> 1609.61 | P8: =Elect!AG12 -> 129.32 | Q8: =Elect!AI12 -> 1103.99 | R8: =Elect!AK12 -> 3814.94 | S8: =Elect!AM12 -> 109.18 | T8: =Elect!AP12 -> 283.1625 | U8: =Elect!AR12 -> 149 | V8: =Elect!AT12 -> 153 | W8: =Elect!AV12 -> 62 | X8: =Elect!AX12 -> 980 | Y8: =Elect!AZ12 -> 0 | Z8: =Elect!BB12 -> 5046 | AA8: =Elect!BD12 -> 233 | AB8: =Elect!BF12 -> 64 | AC8: =Elect!BH12 -> 6239.85 | AD8: =Elect!BL12 -> 301 | AE8: =Elect!BN12 -> 1517 | AF8: =Elect!BP12 -> 110 | AG8: =Elect!BR12 -> 145 | AH8: =Boat!C10 -> 0 | AJ8: =Water!C13 -> 133.4 | AK8: =Water!E13 -> 174 | AL8: =Water!G13 -> 107.88 | AM8: =Boat!E10 -> 0 | AO8: =Gas!C13 -> 935.98 | AP8: =Gas!E13 -> 322.7 | AQ8: =Gas!G13 -> 96 | AR8: =Boat!G10 -> 0 | AS8: =Elect!BT12 -> 221
A9: Cairo at The First Residence | B9: =B8+1 -> 8 | C9: 8 | D9: 2022 | F9: =Elect!J13 -> 5595 | G9: =Elect!K13 -> 4549 | H9: =Elect!Q13 -> 540 | I9: =Elect!S13 -> 139 | J9: =Elect!U13 -> 284 | K9: =Elect!W13 -> 0 | L9: =Elect!Y13 -> 4051.32 | M9: =Elect!AA13 -> 0 | N9: =Elect!AC13 -> 3661.24 | O9: =Elect!AE13 -> 1753.77 | P9: =Elect!AG13 -> 10.6 | Q9: =Elect!AI13 -> 1117.77 | R9: =Elect!AK13 -> 3873.24 | S9: =Elect!AM13 -> 107.59 | T9: =Elect!AP13 -> 291.4875 | U9: =Elect!AR13 -> 159 | V9: =Elect!AT13 -> 152 | W9: =Elect!AV13 -> 61 | X9: =Elect!AX13 -> 1088 | Y9: =Elect!AZ13 -> 0 | Z9: =Elect!BB13 -> 5017 | AA9: =Elect!BD13 -> 222 | AB9: =Elect!BF13 -> 55 | AC9: =Elect!BH13 -> 6427.3 | AD9: =Elect!BL13 -> 307 | AE9: =Elect!BN13 -> 1487 | AF9: =Elect!BP13 -> 119 | AG9: =Elect!BR13 -> 165 | AH9: =Boat!C11 -> 0 | AJ9: =Water!C14 -> 127.6 | AK9: =Water!E14 -> 168.2 | AL9: =Water!G14 -> 96.86 | AM9: =Boat!E11 -> 0 | AO9: =Gas!C14 -> 935.98 | AP9: =Gas!E14 -> 328.3 | AQ9: =Gas!G14 -> 94 | AR9: =Boat!G11 -> 0 | AS9: =Elect!BT13 -> 216
A10: Cairo at The First Residence | B10: =B9+1 -> 9 | C10: 8 | D10: 2022 | F10: =Elect!J14 -> 5699 | G10: =Elect!K14 -> 4548 | H10: =Elect!Q14 -> 300 | I10: =Elect!S14 -> 140 | J10: =Elect!U14 -> 272 | K10: =Elect!W14 -> 0 | L10: =Elect!Y14 -> 4097.43 | M10: =Elect!AA14 -> 0 | N10: =Elect!AC14 -> 4008.39 | O10: =Elect!AE14 -> 1908 | P10: =Elect!AG14 -> 10.6 | Q10: =Elect!AI14 -> 1116.71 | R10: =Elect!AK14 -> 3870.06 | S10: =Elect!AM14 -> 121.37 | T10: =Elect!AP14 -> 295.3125 | U10: =Elect!AR14 -> 147 | V10: =Elect!AT14 -> 160 | W10: =Elect!AV14 -> 60 | X10: =Elect!AX14 -> 1044 | Y10: =Elect!AZ14 -> 0 | Z10: =Elect!BB14 -> 5140 | AA10: =Elect!BD14 -> 232 | AB10: =Elect!BF14 -> 130 | AC10: =Elect!BH14 -> 6623.75 | AD10: =Elect!BL14 -> 305 | AE10: =Elect!BN14 -> 1568 | AF10: =Elect!BP14 -> 117 | AG10: =Elect!BR14 -> 139 | AH10: =Boat!C12 -> 0 | AJ10: =Water!C15 -> 145 | AK10: =Water!E15 -> 191.4 | AL10: =Water!G15 -> 110.2 | AM10: =Boat!E12 -> 0 | AO10: =Gas!C15 -> 935.98 | AP10: =Gas!E15 -> 329 | AQ10: =Gas!G15 -> 91 | AR10: =Boat!G12 -> 0 | AS10: =Elect!BT14 -> 197
A11: Cairo at The First Residence | B11: =B10+1 -> 10 | C11: 8 | D11: 2022 | F11: =Elect!J15 -> 5652 | G11: =Elect!K15 -> 4783 | H11: =Elect!Q15 -> 570 | I11: =Elect!S15 -> 140 | J11: =Elect!U15 -> 287 | K11: =Elect!W15 -> 0 | L11: =Elect!Y15 -> 4097.43 | M11: =Elect!AA15 -> 0 | N11: =Elect!AC15 -> 4070.4 | O11: =Elect!AE15 -> 1792.46 | P11: =Elect!AG15 -> 10.07 | Q11: =Elect!AI15 -> 1116.18 | R11: =Elect!AK15 -> 3926.77 | S11: =Elect!AM15 -> 107.59 | T11: =Elect!AP15 -> 274.275 | U11: =Elect!AR15 -> 145 | V11: =Elect!AT15 -> 154 | W11: =Elect!AV15 -> 70 | X11: =Elect!AX15 -> 1114 | Y11: =Elect!AZ15 -> 0 | Z11: =Elect!BB15 -> 4800 | AA11: =Elect!BD15 -> 254 | AB11: =Elect!BF15 -> 111 | AC11: =Elect!BH15 -> 6686.3 | AD11: =Elect!BL15 -> 303 | AE11: =Elect!BN15 -> 1552 | AF11: =Elect!BP15 -> 114 | AG11: =Elect!BR15 -> 151 | AH11: =Boat!C13 -> 0 | AJ11: =Water!C16 -> 145 | AK11: =Water!E16 -> 197.2 | AL11: =Water!G16 -> 98.6 | AM11: =Boat!E13 -> 0 | AO11: =Gas!C16 -> 935.98 | AP11: =Gas!E16 -> 304.5 | AQ11: =Gas!G16 -> 78 | AR11: =Boat!G13 -> 0 | AS11: =Elect!BT15 -> 194
A12: Cairo at The First Residence | B12: =B11+1 -> 11 | C12: 8 | D12: 2022 | F12: =Elect!J16 -> 5348 | G12: =Elect!K16 -> 4688 | H12: =Elect!Q16 -> 600 | I12: =Elect!S16 -> 142 | J12: =Elect!U16 -> 276 | K12: =Elect!W16 -> 0 | L12: =Elect!Y16 -> 4420.73 | M12: =Elect!AA16 -> 0 | N12: =Elect!AC16 -> 4152.55 | O12: =Elect!AE16 -> 1814.72 | P12: =Elect!AG16 -> 10.6 | Q12: =Elect!AI16 -> 1126.25 | R12: =Elect!AK16 -> 3969.7 | S12: =Elect!AM16 -> 103.35 | T12: =Elect!AP16 -> 282.375 | U12: =Elect!AR16 -> 159 | V12: =Elect!AT16 -> 155 | W12: =Elect!AV16 -> 66 | X12: =Elect!AX16 -> 1136 | Y12: =Elect!AZ16 -> 0 | Z12: =Elect!BB16 -> 5456 | AA12: =Elect!BD16 -> 282 | AB12: =Elect!BF16 -> 65 | AC12: =Elect!BH16 -> 6685.85 | AD12: =Elect!BL16 -> 307 | AE12: =Elect!BN16 -> 1538 | AF12: =Elect!BP16 -> 109 | AG12: =Elect!BR16 -> 160 | AH12: =Boat!C14 -> 0 | AJ12: =Water!C17 -> 145 | AK12: =Water!E17 -> 193.33333 | AL12: =Water!G17 -> 106.33333 | AM12: =Boat!E14 -> 0 | AO12: =Gas!C17 -> 935.98 | AP12: =Gas!E17 -> 320.83333 | AQ12: =Gas!G17 -> 156.66667 | AR12: =Boat!G14 -> 0 | AS12: =Elect!BT16 -> 211
A13: Cairo at The First Residence | B13: =B12+1 -> 12 | C13: 8 | D13: 2022 | F13: =Elect!J17 -> 5312 | G13: =Elect!K17 -> 4664 | H13: =Elect!Q17 -> 600 | I13: =Elect!S17 -> 137 | J13: =Elect!U17 -> 268 | K13: =Elect!W17 -> 0 | L13: =Elect!Y17 -> 3893.38 | M13: =Elect!AA17 -> 0 | N13: =Elect!AC17 -> 3855.22 | O13: =Elect!AE17 -> 1807.3 | P13: =Elect!AG17 -> 10.07 | Q13: =Elect!AI17 -> 1123.6 | R13: =Elect!AK17 -> 3957.51 | S13: =Elect!AM17 -> 102.82 | T13: =Elect!AP17 -> 286.65 | U13: =Elect!AR17 -> 148 | V13: =Elect!AT17 -> 157 | W13: =Elect!AV17 -> 50 | X13: =Elect!AX17 -> 1118 | Y13: =Elect!AZ17 -> 0 | Z13: =Elect!BB17 -> 4705 | AA13: =Elect!BD17 -> 273 | AB13: =Elect!BF17 -> 65 | AC13: =Elect!BH17 -> 6782 | AD13: =Elect!BL17 -> 301 | AE13: =Elect!BN17 -> 1531 | AF13: =Elect!BP17 -> 109 | AG13: =Elect!BR17 -> 143 | AH13: =Boat!C15 -> 0 | AJ13: =Water!C18 -> 133.4 | AK13: =Water!E18 -> 166.26667 | AL13: =Water!G18 -> 102.46667 | AM13: =Boat!E15 -> 0 | AO13: =Gas!C18 -> 935.98 | AP13: =Gas!E18 -> 275.56667 | AQ13: =Gas!G18 -> 31.333333 | AR13: =Boat!G15 -> 0 | AS13: =Elect!BT17 -> 239
A14: Cairo at The First Residence | B14: =B13+1 -> 13 | C14: 8 | D14: 2022 | F14: =Elect!J18 -> 5606 | G14: =Elect!K18 -> 3705 | H14: =Elect!Q18 -> 300 | I14: =Elect!S18 -> 141 | J14: =Elect!U18 -> 271 | K14: =Elect!W18 -> 0 | L14: =Elect!Y18 -> 3895.5 | M14: =Elect!AA18 -> 0 | N14: =Elect!AC18 -> 3278.58 | O14: =Elect!AE18 -> 1720.91 | P14: =Elect!AG18 -> 10.07 | Q14: =Elect!AI18 -> 1052.05 | R14: =Elect!AK18 -> 3729.08 | S14: =Elect!AM18 -> 103.35 | T14: =Elect!AP18 -> 293.175 | U14: =Elect!AR18 -> 160 | V14: =Elect!AT18 -> 149 | W14: =Elect!AV18 -> 46 | X14: =Elect!AX18 -> 1012 | Y14: =Elect!AZ18 -> 0 | Z14: =Elect!BB18 -> 4878 | AA14: =Elect!BD18 -> 263 | AB14: =Elect!BF18 -> 65 | AC14: =Elect!BH18 -> 6339.85 | AD14: =Elect!BL18 -> 307 | AE14: =Elect!BN18 -> 1536 | AF14: =Elect!BP18 -> 111 | AG14: =Elect!BR18 -> 179 | AH14: =Boat!C16 -> 0 | AJ14: =Water!C19 -> 121.8 | AK14: =Water!E19 -> 162.4 | AL14: =Water!G19 -> 102.08 | AM14: =Boat!E16 -> 0 | AO14: =Gas!C19 -> 935.98 | AP14: =Gas!E19 -> 282.1 | AQ14: =Gas!G19 -> 92 | AR14: =Boat!G16 -> 0 | AS14: =Elect!BT18 -> 227
... A32: Cairo at The First Residence | B32: =B31+1 -> 31 | C32: 8 | D32: 2022 | F32: =Elect!J36 -> 4795.6667 | G32: =Elect!K36 -> 4615 | H32: =Elect!Q36 -> 600 | I32: =Elect!S36 -> 139 | J32: =Elect!U36 -> 267 | K32: =Elect!W36 -> 0 | L32: =Elect!Y36 -> 4433.6267 | M32: =Elect!AA36 -> 0 | N32: =Elect!AC36 -> 4636.44 | O32: =Elect!AE36 -> 0 | P32: =Elect!AG36 -> 1807.3 | Q32: =Elect!AI36 -> 1226.42 | R32: =Elect!AK36 -> 4120.75 | S32: =Elect!AM36 -> 129.67333 | T32: =Elect!AP36 -> 320.7375 | U32: =Elect!AR36 -> 139.33333 | V32: =Elect!AT36 -> 166 | W32: =Elect!AV36 -> 68 | X32: =Elect!AX36 -> 1166.1481 | Y32: =Elect!AZ36 -> 56.666667 | Z32: =Elect!BB36 -> 5179.3333 | AA32: =Elect!BD36 -> 221.33333 | AB32: =Elect!BF36 -> 70.333333 | AC32: =Elect!BH36 -> 6325.4667 | AD32: =Elect!BL36 -> 100.66667 | AE32: =Elect!BN36 -> 1488.3333 | AF32: =Elect!BP36 -> 87.666667 | AG32: =Elect!BR36 -> 147 | AH32: =Boat!C34 -> 0 | AJ32: =Water!C37 -> 102.46667 | AK32: =Water!E37 -> 143.06667 | AL32: =Water!G37 -> 106.72 | AM32: =Boat!E34 -> 0 | AO32: =Gas!C37 -> 1016.54 | AP32: =Gas!E37 -> 261.72222 | AQ32: =Gas!G37 -> 93 | AR32: =Boat!G34 -> 0 | AS32: =Elect!BT36 -> 134

Sheet Boat
B1: Electricity | D1: Water | F1: Gas
B2: Read | C2: Cons | D2: Read | E2: Cons | F2: Read | G2: Cons
B3: 0 | D3: 0 | F3: 0
A4: 1 | B4: 0 | C4: =B4-B3 -> 0 | D4: 0 | E4: =D4-D3 -> 0 | F4: 0 | G4: =F4-F3 -> 0
A5: 2 | B5: 0 | C5: =B5-B4 -> 0 | D5: 0 | E5: =D5-D4 -> 0 | F5: 0 | G5: =F5-F4 -> 0
A6: 3 | B6: 0 | C6: =B6-B5 -> 0 | D6: 0 | E6: =D6-D5 -> 0 | F6: 0 | G6: =F6-F5 -> 0
A7: 4 | B7: 0 | C7: =B7-B6 -> 0 | D7: 0 | E7: =D7-D6 -> 0 | F7: 0 | G7: =F7-F6 -> 0
A8: 5 | B8: 0 | C8: =B8-B7 -> 0 | D8: 0 | E8: =D8-D7 -> 0 | F8: 0 | G8: =F8-F7 -> 0
A9: 6 | B9: 0 | C9: =B9-B8 -> 0 | D9: 0 | E9: =D9-D8 -> 0 | F9: 0 | G9: =F9-F8 -> 0
A10: 7 | B10: 0 | C10: =B10-B9 -> 0 | D10: 0 | E10: =D10-D9 -> 0 | F10: 0 | G10: =F10-F9 -> 0
A11: 8 | B11: 0 | C11: =B11-B10 -> 0 | D11: 0 | E11: =D11-D10 -> 0 | F11: 0 | G11: =F11-F10 -> 0
A12: 9 | B12: 0 | C12: =B12-B11 -> 0 | D12: 0 | E12: =D12-D11 -> 0 | F12: 0 | G12: =F12-F11 -> 0
A13: 10 | B13: 0 | C13: =B13-B12 -> 0 | D13: 0 | E13: =D13-D12 -> 0 | F13: 0 | G13: =F13-F12 -> 0
A14: 11 | B14: 0 | C14: =B14-B13 -> 0 | D14: 0 | E14: =D14-D13 -> 0 | F14: 0 | G14: =F14-F13 -> 0
A15: 12 | B15: 0 | C15: =B15-B14 -> 0 | D15: 0 | E15: =D15-D14 -> 0 | F15: 0 | G15: =F15-F14 -> 0
... A34: 31 | B34: 0 | C34: =B34-B33 -> 0 | D34: 0 | E34: =D34-D33 -> 0 | F34: 0 | G34: =F34-F33 -> 0
A35: Sum | C35: =SUM(C4:C34) -> 0 | E35: =SUM(E4:E34) -> 0 | G35: =SUM(G4:G34) -> 0

Sheet Elect
A1: 44774 | M1: Electricity | BP1: Gourmandise UP | BR1: 1.6 | BS1: Power Taxes | BU1: Max Demand | BW1: 500 | BX1: Electricity UP | BZ1: 1.15
BS2: Light Taxes | BU2: PF Penalty | BX2: Max. Demand UP | BZ2: 30
A3: Date | B3: COUNTER (1) | D3: MD | F3: KVAR | H3: n | I3: Guest Rooms Consumption | R3: Casino Consumption | V3: Plant Room Shared Loads | AO3: To Be Charged By First Arabian | BK3: From Main Panel G2 | BS3: Total Consumption. | BT3: No. Of | BU3: KWH/ | BV3: No. Of | BW3: KWH/ | BX3: Total Cost | BY3: L.E\ | BZ3: L.E\
B4: Reading | C4: Consp. F: *800 | D4: Reading | E4: Consp F: 80 | F4: Reading | G4: Consp. F:*10 | I4: Main Feeder | J4: Consp | K4: T2+T8 | L4: Trans T2 | M4: Consp | N4: Trans T8 | O4: Consp | P4: La Gourmandize | Q4: Consp *30 | R4: Casino 3rd floor EM | S4: Consp | T4: Casino 3rd floor Normal | U4: Consp | V4: Chiller 1 | W4: Consp 53% | X4: Chiller 2 | Y4: Consp 53% | Z4: Chiller 3 | AA4: Consp 53% | AB4: Chiller 4 | AC4: Consp 53% | AD4: Chiller 5 | AE4: Consp 53% | AF4: Chiller 6 | AG4: Consp 53% | AH4: Cooling Towers | AI4: Consp 53% | AJ4: Chiller Pumps | AK4: Consp 53% | AL4: Cooling Tower Pumps | AM4: Consp 53% | AN4: Total Plant Room Consp | AO4: Fiber Chiller (N24) | AP4: Consp | AQ4: Mall Ceiling light (N4) | AR4: Consp | AS4: LG Bakery (N2) | AT4: Consp | AU4: LG Bakery light ( Old lockers ) | AV4: Consp | AW4: MCCR1 | AX4: Consp | AY4: Children Swimming pool | AZ4: Consp | BA4: DPH1 | BB4: Consp | BC4: Guest Rooms Emergency | BD4: Consp | BE4: Hotel Hoods | BF4: Consp | BG4: Main G2 | BH4: Consp | BI4: Total Consp From First Arabian | BJ4: First Arabian Charge Back | BK4: Old Casino Emergency | BL4: Consp | BM4: L / A | BN4: Consp | BO4: L / B | BP4: Consp | BQ4: L / C | BR4: Consp | BT4: Rooms | BU4: room | BV4: guest | BW4: guest | BY4: Room | BZ4: Guest
A5: Last Month Reading | I5: 25036755 | J5: =IF(I5>=I4,I5-I4,0) -> 0 | K5: =M5+O5 -> 0 | L5: 34862 | M5: =IF(L5>=L4,L5-L4,0) -> 0 | N5: 55208.667 | O5: =IF(N5>=N4,N5-N4,0) -> 0 | P5: 224850.27 | Q5: =IF(P5>=P4,P5-P4,0)*30 -> 0 | R5: 208881.5 | S5: =IF(R5>=R4,R5-R4,0) -> 0 | T5: 380814.5 | U5: =IF(T5>=T4,T5-T4,0) -> 0 | V5: 301819.2 | W5: =IF(V5>=V4,V5-V4,0)*0.53 -> 0 | X5: 459455 | Y5: =IF(X5>=X4,X5-X4,0)*0.53 -> 0 | Z5: 502152 | AA5: =IF(Z5>=Z4,Z5-Z4,0)*0.53 -> 0 | AB5: 818308.5 | AC5: =IF(AB5>=AB4,AB5-AB4,0)*0.53 -> 0 | AD5: 764212 | AE5: =IF(AD5>=AD4,AD5-AD4,0)*0.53 -> 0 | AF5: 899010.5 | AG5: =IF(AF5>=AF4,AF5-AF4,0)*0.53 -> 0 | AH5: 235163.27 | AI5: =IF(AH5>=AH4,AH5-AH4,0)*0.53 -> 0 | AJ5: 742785 | AK5: =IF(AJ5>=AJ4,AJ5-AJ4,0)*0.53 -> 0 | AL5: 541391.13 | AM5: =IF(AL5>=AL4,AL5-AL4,0)*0.53 -> 0 | AN5: =W5+Y5+AA5+AC5+AE5+AG5+AI5+AK5+AM5 -> 0 | AO5: 7889570 | AP5: =IF(AO5>=AO4,AO5-AO4,0)*0.1125 -> 0 | AQ5: 727713 | AR5: =IF(AQ5>=AQ4,AQ5-AQ4,0) -> 0 | AS5: 995039.8 | AT5: =IF(AS5>=AS4,AS5-AS4,0) -> 0 | AU5: 819398.7 | AV5: =IF(AU5>=AU4,AU5-AU4,0) -> 0 | AW5: 2765690.5 | AX5: =IF(AW5>=AW4,AW5-AW4,0) -> 0 | AY5: 229733 | AZ5: =IF(AY5>=AY4,AY5-AY4,0) -> 0 | BA5: 20173362 | BB5: =IF(BA5>=BA4,BA5-BA4,0) -> 0 | BC5: 609145.6 | BD5: =IF(BC5>=BC4,BC5-BC4,0) -> 0 | BE5: 37173.389 | BF5: =IF(BE5>=BE4,BE5-BE4,0) -> 0 | BG5: 25274117 | BH5: =IF(BG5>=BG4,BG5-BG4,0)-(0.45*BN5)-(0.45*BP5)-BR5 -> 0 | BI5: =AP5+AR5+AT5+AV5+AX5+AZ5+BB5+BD5+BF5+BH5 -> 0 | BJ5: =BI5+AN5 -> 0 | BK5: 1464195.9 | BL5: =IF(BK5>=BK4,BK5-BK4,0) -> 0 | BM5: 4139722.6 | BN5: =IF(BM5>=BM4,BM5-BM4,0) -> 0 | BO5: 436020 | BP5: =IF(BO5>=BO4,BO5-BO4,0) -> 0 | BQ5: 544778.5 | BR5: =IF(BQ5>=BQ4,BQ5-BQ4,0) -> 0
A6: 1 | C6: =IF(+B6-B5>0,B6-B5,(B6-B5)>0)*800 -> 0 | E6: =IF(+D6-D5>0,D6-D5,(D6-D5)>0)*80 -> 0 | G6: =IF(+F6-F5>0,F6-F5,(F6-F5)>0)*10 -> 0 | H6: 56 | I6: 25043306 | J6: =IF(I6>=I5,I6-I5,0) -> 6551.3333 | K6: =M6+O6 -> 5401.3333 | L6: 36944 | M6: =IF(L6>=L5,L6-L5,0) -> 2082 | N6: 58528 | O6: =IF(N6>=N5,N6-N5,0) -> 3319.3333 | P6: 224869 | Q6: =IF(P6>=P5,P6-P5,0)*30 -> 562 | R6: 209022 | S6: =IF(R6>=R5,R6-R5,0) -> 140.5 | T6: 381109 | U6: =IF(T6>=T5,T6-T5,0) -> 294.5 | V6: 297550 | W6: =IF(V6>=V5,V6-V5,0)*0.53 -> 0 | X6: 461770 | Y6: =IF(X6>=X5,X6-X5,0)*0.53 -> 1226.95 | Z6: 515121 | AA6: =IF(Z6>=Z5,Z6-Z5,0)*0.53 -> 6873.57 | AB6: 824325 | AC6: =IF(AB6>=AB5,AB6-AB5,0)*0.53 -> 3188.745 | AD6: 764212 | AE6: =IF(AD6>=AD5,AD6-AD5,0)*0.53 -> 0 | AF6: 904339 | AG6: =IF(AF6>=AF5,AF6-AF5,0)*0.53 -> 2824.105 | AH6: 237367 | AI6: =IF(AH6>=AH5,AH6-AH5,0)*0.53 -> 1167.9787 | AJ6: 750301 | AK6: =IF(AJ6>=AJ5,AJ6-AJ5,0)*0.53 -> 3983.48 | AL6: 541622 | AM6: =IF(AL6>=AL5,AL6-AL5,0)*0.53 -> 122.35933 | AN6: =W6+Y6+AA6+AC6+AE6+AG6+AI6+AK6+AM6 -> 19387.188 | AO6: 7892004 | AP6: =IF(AO6>=AO5,AO6-AO5,0)*0.1125 -> 273.825 | AQ6: 727878 | AR6: =IF(AQ6>=AQ5,AQ6-AQ5,0) -> 165 | AS6: 995213 | AT6: =IF(AS6>=AS5,AS6-AS5,0) -> 173.2 | AU6: 819455 | AV6: =IF(AU6>=AU5,AU6-AU5,0) -> 56.3 | AW6: 2766771 | AX6: =IF(AW6>=AW5,AW6-AW5,0) -> 1080.5 | AY6: 229733 | AZ6: =IF(AY6>=AY5,AY6-AY5,0) -> 0 | BA6: 20177744 | BB6: =IF(BA6>=BA5,BA6-BA5,0) -> 4381.7 | BC6: 609415 | BD6: =IF(BC6>=BC5,BC6-BC5,0) -> 269.4 | BE6: 37256 | BF6: =IF(BE6>=BE5,BE6-BE5,0) -> 82.611111 | BG6: 25281712 | BH6: =IF(BG6>=BG5,BG6-BG5,0)-(0.45*BN6)-(0.45*BP6)-BR6 -> 6613.12 | BI6: =AP6+AR6+AT6+AV6+AX6+AZ6+BB6+BD6+BF6+BH6 -> 13095.656 | BJ6: =BI6+AN6 -> 32482.844 | BK6: 1464586 | BL6: =IF(BK6>=BK5,BK6-BK5,0) -> 390.1 | BM6: 4141431 | BN6: =IF(BM6>=BM5,BM6-BM5,0) -> 1708.4 | BO6: 436128 | BP6: =IF(BO6>=BO5,BO6-BO5,0) -> 108 | BQ6: 544943 | BR6: =IF(BQ6>=BQ5,BQ6-BQ5,0) -> 164.5 | BS6: =J6+Q6+AN6+BI6 -> 39596.177 | BT6: 158 | BU6: =IF(BS6>0,BS6/BT5,0) -> #DIV/0! | BW6: =IF(BS6>0,BS6/BV6,0) -> #DIV/0! | BX6: =((BS6-Q6)*$BZ$1)+(Q6*$BR$1) -> 45788.504 | BY6: =IF(BX6>0,BX6/BT5,0) -> #DIV/0! | BZ6: =IF(BX6>0,BX6/BV6,0) -> #DIV/0!
A7: 2 | I7: 25049224 | J7: =IF(I7>=I6,I7-I6,0) -> 5918 | K7: =M7+O7 -> 5016 | L7: 39008 | M7: =IF(L7>=L6,L7-L6,0) -> 2064 | N7: 61480 | O7: =IF(N7>=N6,N7-N6,0) -> 2952 | P7: 224885 | Q7: =IF(P7>=P6,P7-P6,0)*30 -> 480 | R7: 209165 | S7: =IF(R7>=R6,R7-R6,0) -> 143 | T7: 381390 | U7: =IF(T7>=T6,T7-T6,0) -> 281 | V7: 297550 | W7: =IF(V7>=V6,V7-V6,0)*0.53 -> 0 | X7: 461770 | Y7: =IF(X7>=X6,X7-X6,0)*0.53 -> 0 | Z7: 523123 | AA7: =IF(Z7>=Z6,Z7-Z6,0)*0.53 -> 4241.06 | AB7: 831831 | AC7: =IF(AB7>=AB6,AB7-AB6,0)*0.53 -> 3978.18 | AD7: 765827 | AE7: =IF(AD7>=AD6,AD7-AD6,0)*0.53 -> 855.95 | AF7: 904362 | AG7: =IF(AF7>=AF6,AF7-AF6,0)*0.53 -> 12.19 | AH7: 239537 | AI7: =IF(AH7>=AH6,AH7-AH6,0)*0.53 -> 1150.1 | AJ7: 757569 | AK7: =IF(AJ7>=AJ6,AJ7-AJ6,0)*0.53 -> 3852.04 | AL7: 541854 | AM7: =IF(AL7>=AL6,AL7-AL6,0)*0.53 -> 122.96 | AN7: =W7+Y7+AA7+AC7+AE7+AG7+AI7+AK7+AM7 -> 14212.48 | AO7: 7894641 | AP7: =IF(AO7>=AO6,AO7-AO6,0)*0.1125 -> 296.6625 | AQ7: 728055 | AR7: =IF(AQ7>=AQ6,AQ7-AQ6,0) -> 177 | AS7: 995381 | AT7: =IF(AS7>=AS6,AS7-AS6,0) -> 168 | AU7: 819519 | AV7: =IF(AU7>=AU6,AU7-AU6,0) -> 64 | AW7: 2767813 | AX7: =IF(AW7>=AW6,AW7-AW6,0) -> 1042 | AY7: 229733 | AZ7: =IF(AY7>=AY6,AY7-AY6,0) -> 0 | BA7: 20182849 | BB7: =IF(BA7>=BA6,BA7-BA6,0) -> 5105 | BC7: 609678 | BD7: =IF(BC7>=BC6,BC7-BC6,0) -> 263 | BE7: 37311 | BF7: =IF(BE7>=BE6,BE7-BE6,0) -> 55 | BG7: 25289109 | BH7: =IF(BG7>=BG6,BG7-BG6,0)-(0.45*BN7)-(0.45*BP7)-BR7 -> 6486.85 | BI7: =AP7+AR7+AT7+AV7+AX7+AZ7+BB7+BD7+BF7+BH7 -> 13657.513 | BJ7: =BI7+AN7 -> 27869.993 | BK7: 1464899 | BL7: =IF(BK7>=BK6,BK7-BK6,0) -> 313 | BM7: 4143007 | BN7: =IF(BM7>=BM6,BM7-BM6,0) -> 1576 | BO7: 436239 | BP7: =IF(BO7>=BO6,BO7-BO6,0) -> 111 | BQ7: 545094 | BR7: =IF(BQ7>=BQ6,BQ7-BQ6,0) -> 151 | BS7: =J7+Q7+AN7+BI7 -> 34267.993 | BT7: 162 | BU7: =IF(BS7>0,BS7/BT6,0) -> 216.88603 | BW7: =IF(BS7>0,BS7/BV7,0) -> #DIV/0! | BX7: =((BS7-Q7)*$BZ$1)+(Q7*$BR$1) -> 39624.191 | BY7: =IF(BX7>0,BX7/BT6,0) -> 250.78602 | BZ7: =IF(BX7>0,BX7/BV7,0) -> #DIV/0!
A8: 3 | C8: =IF(+B8-B7>0,B8-B7,(B8-B7)>0)*800 -> 0 | E8: =IF(+D8-D7>0,D8-D7,(D8-D7)>0)*80 -> 0 | G8: =IF(+F8-F7>0,F8-F7,(F8-F7)>0)*10 -> 0 | H8: 57 | I8: 25054987 | J8: =IF(I8>=I7,I8-I7,0) -> 5763 | K8: =M8+O8 -> 4794 | L8: 40968 | M8: =IF(L8>=L7,L8-L7,0) -> 1960 | N8: 64314 | O8: =IF(N8>=N7,N8-N7,0) -> 2834 | P8: 224903 | Q8: =IF(P8>=P7,P8-P7,0)*30 -> 540 | R8: 209304 | S8: =IF(R8>=R7,R8-R7,0) -> 139 | T8: 381655 | U8: =IF(T8>=T7,T8-T7,0) -> 265 | V8: 297550 | W8: =IF(V8>=V7,V8-V7,0)*0.53 -> 0 | X8: 466376 | Y8: =IF(X8>=X7,X8-X7,0)*0.53 -> 2441.18 | Z8: 530489 | AA8: =IF(Z8>=Z7,Z8-Z7,0)*0.53 -> 3903.98 | AB8: 833938 | AC8: =IF(AB8>=AB7,AB8-AB7,0)*0.53 -> 1116.71 | AD8: 768999 | AE8: =IF(AD8>=AD7,AD8-AD7,0)*0.53 -> 1681.16 | AF8: 904384 | AG8: =IF(AF8>=AF7,AF8-AF7,0)*0.53 -> 11.66 | AH8: 241584 | AI8: =IF(AH8>=AH7,AH8-AH7,0)*0.53 -> 1084.91 | AJ8: 764514 | AK8: =IF(AJ8>=AJ7,AJ8-AJ7,0)*0.53 -> 3680.85 | AL8: 542058 | AM8: =IF(AL8>=AL7,AL8-AL7,0)*0.53 -> 108.12 | AN8: =W8+Y8+AA8+AC8+AE8+AG8+AI8+AK8+AM8 -> 14028.57 | AO8: 7897133 | AP8: =IF(AO8>=AO7,AO8-AO7,0)*0.1125 -> 280.35 | AQ8: 728235 | AR8: =IF(AQ8>=AQ7,AQ8-AQ7,0) -> 180 | AS8: 995530 | AT8: =IF(AS8>=AS7,AS8-AS7,0) -> 149 | AU8: 819576 | AV8: =IF(AU8>=AU7,AU8-AU7,0) -> 57 | AW8: 2768810 | AX8: =IF(AW8>=AW7,AW8-AW7,0) -> 997 | AY8: 229733 | AZ8: =IF(AY8>=AY7,AY8-AY7,0) -> 0 | BA8: 20187420 | BB8: =IF(BA8>=BA7,BA8-BA7,0) -> 4571 | BC8: 609961 | BD8: =IF(BC8>=BC7,BC8-BC7,0) -> 283 | BE8: 37366 | BF8: =IF(BE8>=BE7,BE8-BE7,0) -> 55 | BG8: 25296209 | BH8: =IF(BG8>=BG7,BG8-BG7,0)-(0.45*BN8)-(0.45*BP8)-BR8 -> 6231.5 | BI8: =AP8+AR8+AT8+AV8+AX8+AZ8+BB8+BD8+BF8+BH8 -> 12803.85 | BJ8: =BI8+AN8 -> 26832.42 | BK8: 1465203 | BL8: =IF(BK8>=BK7,BK8-BK7,0) -> 304 | BM8: 4144533 | BN8: =IF(BM8>=BM7,BM8-BM7,0) -> 1526 | BO8: 436343 | BP8: =IF(BO8>=BO7,BO8-BO7,0) -> 104 | BQ8: 545229 | BR8: =IF(BQ8>=BQ7,BQ8-BQ7,0) -> 135 | BS8: =J8+Q8+AN8+BI8 -> 33135.42 | BT8: 173 | BU8: =IF(BS8>0,BS8/BT7,0) -> 204.53963 | BW8: =IF(BS8>0,BS8/BV8,0) -> #DIV/0! | BX8: =((BS8-Q8)*$BZ$1)+(Q8*$BR$1) -> 38348.733 | BY8: =IF(BX8>0,BX8/BT7,0) -> 236.72057 | BZ8: =IF(BX8>0,BX8/BV8,0) -> #DIV/0!
A9: 4 | C9: =IF(+B9-B8>0,B9-B8,(B9-B8)>0)*800 -> 0 | E9: =IF(+D9-D8>0,D9-D8,(D9-D8)>0)*80 -> 0 | G9: =IF(+F9-F8>0,F9-F8,(F9-F8)>0)*10 -> 0 | I9: 25060334 | J9: =IF(I9>=I8,I9-I8,0) -> 5347 | K9: =M9+O9 -> 4913 | L9: 42903 | M9: =IF(L9>=L8,L9-L8,0) -> 1935 | N9: 67292 | O9: =IF(N9>=N8,N9-N8,0) -> 2978 | P9: 224921 | Q9: =IF(P9>=P8,P9-P8,0)*30 -> 540 | R9: 209441 | S9: =IF(R9>=R8,R9-R8,0) -> 137 | T9: 381926 | U9: =IF(T9>=T8,T9-T8,0) -> 271 | V9: 297550 | W9: =IF(V9>=V8,V9-V8,0)*0.53 -> 0 | X9: 473381 | Y9: =IF(X9>=X8,X9-X8,0)*0.53 -> 3712.65 | Z9: 537894 | AA9: =IF(Z9>=Z8,Z9-Z8,0)*0.53 -> 3924.65 | AB9: 833938 | AC9: =IF(AB9>=AB8,AB9-AB8,0)*0.53 -> 0 | AD9: 772243 | AE9: =IF(AD9>=AD8,AD9-AD8,0)*0.53 -> 1719.32 | AF9: 904400 | AG9: =IF(AF9>=AF8,AF9-AF8,0)*0.53 -> 8.48 | AH9: 243686 | AI9: =IF(AH9>=AH8,AH9-AH8,0)*0.53 -> 1114.06 | AJ9: 771667 | AK9: =IF(AJ9>=AJ8,AJ9-AJ8,0)*0.53 -> 3791.09 | AL9: 542288 | AM9: =IF(AL9>=AL8,AL9-AL8,0)*0.53 -> 121.9 | AN9: =W9+Y9+AA9+AC9+AE9+AG9+AI9+AK9+AM9 -> 14392.15 | AO9: 7899770 | AP9: =IF(AO9>=AO8,AO9-AO8,0)*0.1125 -> 296.6625 | AQ9: 728402 | AR9: =IF(AQ9>=AQ8,AQ9-AQ8,0) -> 167 | AS9: 995696 | AT9: =IF(AS9>=AS8,AS9-AS8,0) -> 166 | AU9: 819636 | AV9: =IF(AU9>=AU8,AU9-AU8,0) -> 60 | AW9: 2769916 | AX9: =IF(AW9>=AW8,AW9-AW8,0) -> 1106 | AY9: 229733 | AZ9: =IF(AY9>=AY8,AY9-AY8,0) -> 0 | BA9: 20192315 | BB9: =IF(BA9>=BA8,BA9-BA8,0) -> 4895 | BC9: 610242 | BD9: =IF(BC9>=BC8,BC9-BC8,0) -> 281 | BE9: 37409 | BF9: =IF(BE9>=BE8,BE9-BE8,0) -> 43 | BG9: 25303448 | BH9: =IF(BG9>=BG8,BG9-BG8,0)-(0.45*BN9)-(0.45*BP9)-BR9 -> 6368.85 | BI9: =AP9+AR9+AT9+AV9+AX9+AZ9+BB9+BD9+BF9+BH9 -> 13383.513 | BJ9: =BI9+AN9 -> 27775.662 | BK9: 1465504 | BL9: =IF(BK9>=BK8,BK9-BK8,0) -> 301 | BM9: 4146052 | BN9: =IF(BM9>=BM8,BM9-BM8,0) -> 1519 | BO9: 436451 | BP9: =IF(BO9>=BO8,BO9-BO8,0) -> 108 | BQ9: 545367 | BR9: =IF(BQ9>=BQ8,BQ9-BQ8,0) -> 138 | BS9: =J9+Q9+AN9+BI9 -> 33662.663 | BT9: 202 | BU9: =IF(BS9>0,BS9/BT8,0) -> 194.58186 | BW9: =IF(BS9>0,BS9/BV9,0) -> #DIV/0! | BX9: =((BS9-Q9)*$BZ$1)+(Q9*$BR$1) -> 38955.062 | BY9: =IF(BX9>0,BX9/BT8,0) -> 225.17377 | BZ9: =IF(BX9>0,BX9/BV9,0) -> #DIV/0!
A10: 5 | C10: =IF(+B10-B9>0,B10-B9,(B10-B9)>0)*800 -> 0 | E10: =IF(+D10-D9>0,D10-D9,(D10-D9)>0)*80 -> 0 | G10: =IF(+F10-F9>0,F10-F9,(F10-F9)>0)*10 -> 0 | H10: 58 | I10: 25068804 | J10: =IF(I10>=I9,I10-I9,0) -> 8470 | K10: =M10+O10 -> 5034 | L10: 44855 | M10: =IF(L10>=L9,L10-L9,0) -> 1952 | N10: 70374 | O10: =IF(N10>=N9,N10-N9,0) -> 3082 | P10: 224930 | Q10: =IF(P10>=P9,P10-P9,0)*30 -> 270 | R10: 209581 | S10: =IF(R10>=R9,R10-R9,0) -> 140 | T10: 382199 | U10: =IF(T10>=T9,T10-T9,0) -> 273 | V10: 297550 | W10: =IF(V10>=V9,V10-V9,0)*0.53 -> 0 | X10: 480701 | Y10: =IF(X10>=X9,X10-X9,0)*0.53 -> 3879.6 | Z10: 545465 | AA10: =IF(Z10>=Z9,Z10-Z9,0)*0.53 -> 4012.63 | AB10: 833938 | AC10: =IF(AB10>=AB9,AB10-AB9,0)*0.53 -> 0 | AD10: 775388 | AE10: =IF(AD10>=AD9,AD10-AD9,0)*0.53 -> 1666.85 | AF10: 904420 | AG10: =IF(AF10>=AF9,AF10-AF9,0)*0.53 -> 10.6 | AH10: 245817 | AI10: =IF(AH10>=AH9,AH10-AH9,0)*0.53 -> 1129.43 | AJ10: 778934 | AK10: =IF(AJ10>=AJ9,AJ10-AJ9,0)*0.53 -> 3851.51 | AL10: 542516 | AM10: =IF(AL10>=AL9,AL10-AL9,0)*0.53 -> 120.84 | AN10: =W10+Y10+AA10+AC10+AE10+AG10+AI10+AK10+AM10 -> 14671.46 | AO10: 7902195 | AP10: =IF(AO10>=AO9,AO10-AO9,0)*0.1125 -> 272.8125 | AQ10: 728574 | AR10: =IF(AQ10>=AQ9,AQ10-AQ9,0) -> 172 | AS10: 995868 | AT10: =IF(AS10>=AS9,AS10-AS9,0) -> 172 | AU10: 819690 | AV10: =IF(AU10>=AU9,AU10-AU9,0) -> 54 | AW10: 2770927 | AX10: =IF(AW10>=AW9,AW10-AW9,0) -> 1011 | AY10: 229733 | AZ10: =IF(AY10>=AY9,AY10-AY9,0) -> 0 | BA10: 20197337 | BB10: =IF(BA10>=BA9,BA10-BA9,0) -> 5022 | BC10: 610529 | BD10: =IF(BC10>=BC9,BC10-BC9,0) -> 287 | BE10: 37466 | BF10: =IF(BE10>=BE9,BE10-BE9,0) -> 57 | BG10: 25310693 | BH10: =IF(BG10>=BG9,BG10-BG9,0)-(0.45*BN10)-(0.45*BP10)-BR10 -> 6376.45 | BI10: =AP10+AR10+AT10+AV10+AX10+AZ10+BB10+BD10+BF10+BH10 -> 13424.263 | BJ10: =BI10+AN10 -> 28095.723 | BK10: 1465810 | BL10: =IF(BK10>=BK9,BK10-BK9,0) -> 306 | BM10: 4147561 | BN10: =IF(BM10>=BM9,BM10-BM9,0) -> 1509 | BO10: 436561 | BP10: =IF(BO10>=BO9,BO10-BO9,0) -> 110 | BQ10: 545507 | BR10: =IF(BQ10>=BQ9,BQ10-BQ9,0) -> 140 | BS10: =J10+Q10+AN10+BI10 -> 36835.723 | BT10: 216 | BU10: =IF(BS10>0,BS10/BT9,0) -> 182.35506 | BW10: =IF(BS10>0,BS10/BV10,0) -> #DIV/0! | BX10: =((BS10-Q10)*$BZ$1)+(Q10*$BR$1) -> 42482.581 | BY10: =IF(BX10>0,BX10/BT9,0) -> 210.30981 | BZ10: =IF(BX10>0,BX10/BV10,0) -> #DIV/0!
A11: 6 | C11: =IF(+B11-B10>0,B11-B10,(B11-B10)>0)*800 -> 0 | E11: =IF(+D11-D10>0,D11-D10,(D11-D10)>0)*80 -> 0 | G11: =IF(+F11-F10>0,F11-F10,(F11-F10)>0)*10 -> 0 | I11: 25070663 | J11: =IF(I11>=I10,I11-I10,0) -> 1859 | K11: =M11+O11 -> 4423 | L11: 46770 | M11: =IF(L11>=L10,L11-L10,0) -> 1915 | N11: 72882 | O11: =IF(N11>=N10,N11-N10,0) -> 2508 | P11: 224955 | Q11: =IF(P11>=P10,P11-P10,0)*30 -> 750 | R11: 209720 | S11: =IF(R11>=R10,R11-R10,0) -> 139 | T11: 382478 | U11: =IF(T11>=T10,T11-T10,0) -> 279 | V11: 297550 | W11: =IF(V11>=V10,V11-V10,0)*0.53 -> 0 | X11: 488200 | Y11: =IF(X11>=X10,X11-X10,0)*0.53 -> 3974.47 | Z11: 553112 | AA11: =IF(Z11>=Z10,Z11-Z10,0)*0.53 -> 4052.91 | AB11: 833938 | AC11: =IF(AB11>=AB10,AB11-AB10,0)*0.53 -> 0 | AD11: 778579 | AE11: =IF(AD11>=AD10,AD11-AD10,0)*0.53 -> 1691.23 | AF11: 904439 | AG11: =IF(AF11>=AF10,AF11-AF10,0)*0.53 -> 10.07 | AH11: 247977 | AI11: =IF(AH11>=AH10,AH11-AH10,0)*0.53 -> 1144.8 | AJ11: 786305 | AK11: =IF(AJ11>=AJ10,AJ11-AJ10,0)*0.53 -> 3906.63 | AL11: 542738 | AM11: =IF(AL11>=AL10,AL11-AL10,0)*0.53 -> 117.66 | AN11: =W11+Y11+AA11+AC11+AE11+AG11+AI11+AK11+AM11 -> 14897.77 | AO11: 7904669 | AP11: =IF(AO11>=AO10,AO11-AO10,0)*0.1125 -> 278.325 | AQ11: 728737 | AR11: =IF(AQ11>=AQ10,AQ11-AQ10,0) -> 163 | AS11: 996033 | AT11: =IF(AS11>=AS10,AS11-AS10,0) -> 165 | AU11: 819741 | AV11: =IF(AU11>=AU10,AU11-AU10,0) -> 51 | AW11: 2771904 | AX11: =IF(AW11>=AW10,AW11-AW10,0) -> 977 | AY11: 229733 | AZ11: =IF(AY11>=AY10,AY11-AY10,0) -> 0 | BA11: 20202407 | BB11: =IF(BA11>=BA10,BA11-BA10,0) -> 5070 | BC11: 610775 | BD11: =IF(BC11>=BC10,BC11-BC10,0) -> 246 | BE11: 37519 | BF11: =IF(BE11>=BE10,BE11-BE10,0) -> 53 | BG11: 25317810 | BH11: =IF(BG11>=BG10,BG11-BG10,0)-(0.45*BN11)-(0.45*BP11)-BR11 -> 6234.45 | BI11: =AP11+AR11+AT11+AV11+AX11+AZ11+BB11+BD11+BF11+BH11 -> 13237.775 | BJ11: =BI11+AN11 -> 28135.545 | BK11: 1466113 | BL11: =IF(BK11>=BK10,BK11-BK10,0) -> 303 | BM11: 4149074 | BN11: =IF(BM11>=BM10,BM11-BM10,0) -> 1513 | BO11: 436667 | BP11: =IF(BO11>=BO10,BO11-BO10,0) -> 106 | BQ11: 545661 | BR11: =IF(BQ11>=BQ10,BQ11-BQ10,0) -> 154 | BS11: =J11+Q11+AN11+BI11 -> 30744.545 | BT11: 224 | BU11: =IF(BS11>0,BS11/BT10,0) -> 142.33586 | BW11: =IF(BS11>0,BS11/BV11,0) -> #DIV/0! | BX11: =((BS11-Q11)*$BZ$1)+(Q11*$BR$1) -> 35693.727 | BY11: =IF(BX11>0,BX11/BT10,0) -> 165.24873 | BZ11: =IF(BX11>0,BX11/BV11,0) -> #DIV/0!
A12: 7 | C12: =IF(+B12-B11>0,B12-B11,(B12-B11)>0)*800 -> 0 | E12: =IF(+D12-D11>0,D12-D11,(D12-D11)>0)*80 -> 0 | G12: =IF(+F12-F11>0,F12-F11,(F12-F11)>0)*10 -> 0 | H12: 59 | I12: 25076115 | J12: =IF(I12>=I11,I12-I11,0) -> 5452 | K12: =M12+O12 -> 4425 | L12: 48712 | M12: =IF(L12>=L11,L12-L11,0) -> 1942 | N12: 75365 | O12: =IF(N12>=N11,N12-N11,0) -> 2483 | P12: 224973 | Q12: =IF(P12>=P11,P12-P11,0)*30 -> 540 | R12: 209857 | S12: =IF(R12>=R11,R12-R11,0) -> 137 | T12: 382748 | U12: =IF(T12>=T11,T12-T11,0) -> 270 | V12: 297550 | W12: =IF(V12>=V11,V12-V11,0)*0.53 -> 0 | X12: 495485 | Y12: =IF(X12>=X11,X12-X11,0)*0.53 -> 3861.05 | Z12: 555152 | AA12: =IF(Z12>=Z11,Z12-Z11,0)*0.53 -> 1081.2 | AB12: 839150 | AC12: =IF(AB12>=AB11,AB12-AB11,0)*0.53 -> 2762.36 | AD12: 781616 | AE12: =IF(AD12>=AD11,AD12-AD11,0)*0.53 -> 1609.61 | AF12: 904683 | AG12: =IF(AF12>=AF11,AF12-AF11,0)*0.53 -> 129.32 | AH12: 250060 | AI12: =IF(AH12>=AH11,AH12-AH11,0)*0.53 -> 1103.99 | AJ12: 793503 | AK12: =IF(AJ12>=AJ11,AJ12-AJ11,0)*0.53 -> 3814.94 | AL12: 542944 | AM12: =IF(AL12>=AL11,AL12-AL11,0)*0.53 -> 109.18 | AN12: =W12+Y12+AA12+AC12+AE12+AG12+AI12+AK12+AM12 -> 14471.65 | AO12: 7907186 | AP12: =IF(AO12>=AO11,AO12-AO11,0)*0.1125 -> 283.1625 | AQ12: 728886 | AR12: =IF(AQ12>=AQ11,AQ12-AQ11,0) -> 149 | AS12: 996186 | AT12: =IF(AS12>=AS11,AS12-AS11,0) -> 153 | AU12: 819803 | AV12: =IF(AU12>=AU11,AU12-AU11,0) -> 62 | AW12: 2772884 | AX12: =IF(AW12>=AW11,AW12-AW11,0) -> 980 | AY12: 229733 | AZ12: =IF(AY12>=AY11,AY12-AY11,0) -> 0 | BA12: 20207453 | BB12: =IF(BA12>=BA11,BA12-BA11,0) -> 5046 | BC12: 611008 | BD12: =IF(BC12>=BC11,BC12-BC11,0) -> 233 | BE12: 37583 | BF12: =IF(BE12>=BE11,BE12-BE11,0) -> 64 | BG12: 25324927 | BH12: =IF(BG12>=BG11,BG12-BG11,0)-(0.45*BN12)-(0.45*BP12)-BR12 -> 6239.85 | BI12: =AP12+AR12+AT12+AV12+AX12+AZ12+BB12+BD12+BF12+BH12 -> 13210.013 | BJ12: =BI12+AN12 -> 27681.663 | BK12: 1466414 | BL12: =IF(BK12>=BK11,BK12-BK11,0) -> 301 | BM12: 4150591 | BN12: =IF(BM12>=BM11,BM12-BM11,0) -> 1517 | BO12: 436777 | BP12: =IF(BO12>=BO11,BO12-BO11,0) -> 110 | BQ12: 545806 | BR12: =IF(BQ12>=BQ11,BQ12-BQ11,0) -> 145 | BS12: =J12+Q12+AN12+BI12 -> 33673.663 | BT12: 221 | BU12: =IF(BS12>0,BS12/BT11,0) -> 150.32885 | BW12: =IF(BS12>0,BS12/BV12,0) -> #DIV/0! | BX12: =((BS12-Q12)*$BZ$1)+(Q12*$BR$1) -> 38967.712 | BY12: =IF(BX12>0,BX12/BT11,0) -> 173.963 | BZ12: =IF(BX12>0,BX12/BV12,0) -> #DIV/0!
A13: 8 | C13: =IF(+B13-B12>0,B13-B12,(B13-B12)>0)*800 -> 0 | E13: =IF(+D13-D12>0,D13-D12,(D13-D12)>0)*80 -> 0 | G13: =IF(+F13-F12>0,F13-F12,(F13-F12)>0)*10 -> 0 | I13: 25081710 | J13: =IF(I13>=I12,I13-I12,0) -> 5595 | K13: =M13+O13 -> 4549 | L13: 50754 | M13: =IF(L13>=L12,L13-L12,0) -> 2042 | N13: 77872 | O13: =IF(N13>=N12,N13-N12,0) -> 2507 | P13: 224991 | Q13: =IF(P13>=P12,P13-P12,0)*30 -> 540 | R13: 209996 | S13: =IF(R13>=R12,R13-R12,0) -> 139 | T13: 383032 | U13: =IF(T13>=T12,T13-T12,0) -> 284 | V13: 297550 | W13: =IF(V13>=V12,V13-V12,0)*0.53 -> 0 | X13: 503129 | Y13: =IF(X13>=X12,X13-X12,0)*0.53 -> 4051.32 | Z13: 555152 | AA13: =IF(Z13>=Z12,Z13-Z12,0)*0.53 -> 0 | AB13: 846058 | AC13: =IF(AB13>=AB12,AB13-AB12,0)*0.53 -> 3661.24 | AD13: 784925 | AE13: =IF(AD13>=AD12,AD13-AD12,0)*0.53 -> 1753.77 | AF13: 904703 | AG13: =IF(AF13>=AF12,AF13-AF12,0)*0.53 -> 10.6 | AH13: 252169 | AI13: =IF(AH13>=AH12,AH13-AH12,0)*0.53 -> 1117.77 | AJ13: 800811 | AK13: =IF(AJ13>=AJ12,AJ13-AJ12,0)*0.53 -> 3873.24 | AL13: 543147 | AM13: =IF(AL13>=AL12,AL13-AL12,0)*0.53 -> 107.59 | AN13: =W13+Y13+AA13+AC13+AE13+AG13+AI13+AK13+AM13 -> 14575.53 | AO13: 7909777 | AP13: =IF(AO13>=AO12,AO13-AO12,0)*0.1125 -> 291.4875 | AQ13: 729045 | AR13: =IF(AQ13>=AQ12,AQ13-AQ12,0) -> 159 | AS13: 996338 | AT13: =IF(AS13>=AS12,AS13-AS12,0) -> 152 | AU13: 819864 | AV13: =IF(AU13>=AU12,AU13-AU12,0) -> 61 | AW13: 2773972 | AX13: =IF(AW13>=AW12,AW13-AW12,0) -> 1088 | AY13: 229733 | AZ13: =IF(AY13>=AY12,AY13-AY12,0) -> 0 | BA13: 20212470 | BB13: =IF(BA13>=BA12,BA13-BA12,0) -> 5017 | BC13: 611230 | BD13: =IF(BC13>=BC12,BC13-BC12,0) -> 222 | BE13: 37638 | BF13: =IF(BE13>=BE12,BE13-BE12,0) -> 55 | BG13: 25332242 | BH13: =IF(BG13>=BG12,BG13-BG12,0)-(0.45*BN13)-(0.45*BP13)-BR13 -> 6427.3 | BI13: =AP13+AR13+AT13+AV13+AX13+AZ13+BB13+BD13+BF13+BH13 -> 13472.788 | BJ13: =BI13+AN13 -> 28048.318 | BK13: 1466721 | BL13: =IF(BK13>=BK12,BK13-BK12,0) -> 307 | BM13: 4152078 | BN13: =IF(BM13>=BM12,BM13-BM12,0) -> 1487 | BO13: 436896 | BP13: =IF(BO13>=BO12,BO13-BO12,0) -> 119 | BQ13: 545971 | BR13: =IF(BQ13>=BQ12,BQ13-BQ12,0) -> 165 | BS13: =J13+Q13+AN13+BI13 -> 34183.317 | BT13: 216 | BU13: =IF(BS13>0,BS13/BT12,0) -> 154.67564 | BW13: =IF(BS13>0,BS13/BV13,0) -> #DIV/0! | BX13: =((BS13-Q13)*$BZ$1)+(Q13*$BR$1) -> 39553.815 | BY13: =IF(BX13>0,BX13/BT12,0) -> 178.97654 | BZ13: =IF(BX13>0,BX13/BV13,0) -> #DIV/0!
A14: 9 | C14: =IF(+B14-B13>0,B14-B13,(B14-B13)>0)*800 -> 0 | E14: =IF(+D14-D13>0,D14-D13,(D14-D13)>0)*80 -> 0 | G14: =IF(+F14-F13>0,F14-F13,(F14-F13)>0)*10 -> 0 | H14: 60 | I14: 25087409 | J14: =IF(I14>=I13,I14-I13,0) -> 5699 | K14: =M14+O14 -> 4548 | L14: 52734 | M14: =IF(L14>=L13,L14-L13,0) -> 1980 | N14: 80440 | O14: =IF(N14>=N13,N14-N13,0) -> 2568 | P14: 225001 | Q14: =IF(P14>=P13,P14-P13,0)*30 -> 300 | R14: 210136 | S14: =IF(R14>=R13,R14-R13,0) -> 140 | T14: 383304 | U14: =IF(T14>=T13,T14-T13,0) -> 272 | V14: 297550 | W14: =IF(V14>=V13,V14-V13,0)*0.53 -> 0 | X14: 510860 | Y14: =IF(X14>=X13,X14-X13,0)*0.53 -> 4097.43 | Z14: 555152 | AA14: =IF(Z14>=Z13,Z14-Z13,0)*0.53 -> 0 | AB14: 853621 | AC14: =IF(AB14>=AB13,AB14-AB13,0)*0.53 -> 4008.39 | AD14: 788525 | AE14: =IF(AD14>=AD13,AD14-AD13,0)*0.53 -> 1908 | AF14: 904723 | AG14: =IF(AF14>=AF13,AF14-AF13,0)*0.53 -> 10.6 | AH14: 254276 | AI14: =IF(AH14>=AH13,AH14-AH13,0)*0.53 -> 1116.71 | AJ14: 808113 | AK14: =IF(AJ14>=AJ13,AJ14-AJ13,0)*0.53 -> 3870.06 | AL14: 543376 | AM14: =IF(AL14>=AL13,AL14-AL13,0)*0.53 -> 121.37 | AN14: =W14+Y14+AA14+AC14+AE14+AG14+AI14+AK14+AM14 -> 15132.56 | AO14: 7912402 | AP14: =IF(AO14>=AO13,AO14-AO13,0)*0.1125 -> 295.3125 | AQ14: 729192 | AR14: =IF(AQ14>=AQ13,AQ14-AQ13,0) -> 147 | AS14: 996498 | AT14: =IF(AS14>=AS13,AS14-AS13,0) -> 160 | AU14: 819924 | AV14: =IF(AU14>=AU13,AU14-AU13,0) -> 60 | AW14: 2775016 | AX14: =IF(AW14>=AW13,AW14-AW13,0) -> 1044 | AY14: 229733 | AZ14: =IF(AY14>=AY13,AY14-AY13,0) -> 0 | BA14: 20217610 | BB14: =IF(BA14>=BA13,BA14-BA13,0) -> 5140 | BC14: 611462 | BD14: =IF(BC14>=BC13,BC14-BC13,0) -> 232 | BE14: 37768 | BF14: =IF(BE14>=BE13,BE14-BE13,0) -> 130 | BG14: 25339763 | BH14: =IF(BG14>=BG13,BG14-BG13,0)-(0.45*BN14)-(0.45*BP14)-BR14 -> 6623.75 | BI14: =AP14+AR14+AT14+AV14+AX14+AZ14+BB14+BD14+BF14+BH14 -> 13832.062 | BJ14: =BI14+AN14 -> 28964.623 | BK14: 1467026 | BL14: =IF(BK14>=BK13,BK14-BK13,0) -> 305 | BM14: 4153646 | BN14: =IF(BM14>=BM13,BM14-BM13,0) -> 1568 | BO14: 437013 | BP14: =IF(BO14>=BO13,BO14-BO13,0) -> 117 | BQ14: 546110 | BR14: =IF(BQ14>=BQ13,BQ14-BQ13,0) -> 139 | BS14: =J14+Q14+AN14+BI14 -> 34963.623 | BT14: 197 | BU14: =IF(BS14>0,BS14/BT13,0) -> 161.86862 | BW14: =IF(BS14>0,BS14/BV14,0) -> #DIV/0! | BX14: =((BS14-Q14)*$BZ$1)+(Q14*$BR$1) -> 40343.166 | BY14: =IF(BX14>0,BX14/BT13,0) -> 186.77392 | BZ14: =IF(BX14>0,BX14/BV14,0) -> #DIV/0!
A15: 10 | C15: =IF(+B15-B14>0,B15-B14,(B15-B14)>0)*800 -> 0 | E15: =IF(+D15-D14>0,D15-D14,(D15-D14)>0)*80 -> 0 | G15: =IF(+F15-F14>0,F15-F14,(F15-F14)>0)*10 -> 0 | I15: 25093061 | J15: =IF(I15>=I14,I15-I14,0) -> 5652 | K15: =M15+O15 -> 4783 | L15: 54736 | M15: =IF(L15>=L14,L15-L14,0) -> 2002 | N15: 83221 | O15: =IF(N15>=N14,N15-N14,0) -> 2781 | P15: 225020 | Q15: =IF(P15>=P14,P15-P14,0)*30 -> 570 | R15: 210276 | S15: =IF(R15>=R14,R15-R14,0) -> 140 | T15: 383591 | U15: =IF(T15>=T14,T15-T14,0) -> 287 | V15: 297550 | W15: =IF(V15>=V14,V15-V14,0)*0.53 -> 0 | X15: 518591 | Y15: =IF(X15>=X14,X15-X14,0)*0.53 -> 4097.43 | Z15: 555152 | AA15: =IF(Z15>=Z14,Z15-Z14,0)*0.53 -> 0 | AB15: 861301 | AC15: =IF(AB15>=AB14,AB15-AB14,0)*0.53 -> 4070.4 | AD15: 791907 | AE15: =IF(AD15>=AD14,AD15-AD14,0)*0.53 -> 1792.46 | AF15: 904742 | AG15: =IF(AF15>=AF14,AF15-AF14,0)*0.53 -> 10.07 | AH15: 256382 | AI15: =IF(AH15>=AH14,AH15-AH14,0)*0.53 -> 1116.18 | AJ15: 815522 | AK15: =IF(AJ15>=AJ14,AJ15-AJ14,0)*0.53 -> 3926.77 | AL15: 543579 | AM15: =IF(AL15>=AL14,AL15-AL14,0)*0.53 -> 107.59 | AN15: =W15+Y15+AA15+AC15+AE15+AG15+AI15+AK15+AM15 -> 15120.9 | AO15: 7914840 | AP15: =IF(AO15>=AO14,AO15-AO14,0)*0.1125 -> 274.275 | AQ15: 729337 | AR15: =IF(AQ15>=AQ14,AQ15-AQ14,0) -> 145 | AS15: 996652 | AT15: =IF(AS15>=AS14,AS15-AS14,0) -> 154 | AU15: 819994 | AV15: =IF(AU15>=AU14,AU15-AU14,0) -> 70 | AW15: 2776130 | AX15: =IF(AW15>=AW14,AW15-AW14,0) -> 1114 | AY15: 229733 | AZ15: =IF(AY15>=AY14,AY15-AY14,0) -> 0 | BA15: 20222410 | BB15: =IF(BA15>=BA14,BA15-BA14,0) -> 4800 | BC15: 611716 | BD15: =IF(BC15>=BC14,BC15-BC14,0) -> 254 | BE15: 37879 | BF15: =IF(BE15>=BE14,BE15-BE14,0) -> 111 | BG15: 25347350 | BH15: =IF(BG15>=BG14,BG15-BG14,0)-(0.45*BN15)-(0.45*BP15)-BR15 -> 6686.3 | BI15: =AP15+AR15+AT15+AV15+AX15+AZ15+BB15+BD15+BF15+BH15 -> 13608.575 | BJ15: =BI15+AN15 -> 28729.475 | BK15: 1467329 | BL15: =IF(BK15>=BK14,BK15-BK14,0) -> 303 | BM15: 4155198 | BN15: =IF(BM15>=BM14,BM15-BM14,0) -> 1552 | BO15: 437127 | BP15: =IF(BO15>=BO14,BO15-BO14,0) -> 114 | BQ15: 546261 | BR15: =IF(BQ15>=BQ14,BQ15-BQ14,0) -> 151 | BS15: =J15+Q15+AN15+BI15 -> 34951.475 | BT15: 194 | BU15: =IF(BS15>0,BS15/BT14,0) -> 177.41865 | BW15: =IF(BS15>0,BS15/BV15,0) -> #DIV/0! | BX15: =((BS15-Q15)*$BZ$1)+(Q15*$BR$1) -> 40450.696 | BY15: =IF(BX15>0,BX15/BT14,0) -> 205.33348 | BZ15: =IF(BX15>0,BX15/BV15,0) -> #DIV/0!
A16: 11 | C16: =IF(+B16-B15>0,B16-B15,(B16-B15)>0)*800 -> 0 | E16: =IF(+D16-D15>0,D16-D15,(D16-D15)>0)*80 -> 0 | G16: =IF(+F16-F15>0,F16-F15,(F16-F15)>0)*10 -> 0 | H16: 61 | I16: 25098409 | J16: =IF(I16>=I15,I16-I15,0) -> 5348 | K16: =M16+O16 -> 4688 | L16: 56752 | M16: =IF(L16>=L15,L16-L15,0) -> 2016 | N16: 85893 | O16: =IF(N16>=N15,N16-N15,0) -> 2672 | P16: 225040 | Q16: =IF(P16>=P15,P16-P15,0)*30 -> 600 | R16: 210418 | S16: =IF(R16>=R15,R16-R15,0) -> 142 | T16: 383867 | U16: =IF(T16>=T15,T16-T15,0) -> 276 | V16: 297550 | W16: =IF(V16>=V15,V16-V15,0)*0.53 -> 0 | X16: 526932 | Y16: =IF(X16>=X15,X16-X15,0)*0.53 -> 4420.73 | Z16: 555152 | AA16: =IF(Z16>=Z15,Z16-Z15,0)*0.53 -> 0 | AB16: 869136 | AC16: =IF(AB16>=AB15,AB16-AB15,0)*0.53 -> 4152.55 | AD16: 795331 | AE16: =IF(AD16>=AD15,AD16-AD15,0)*0.53 -> 1814.72 | AF16: 904762 | AG16: =IF(AF16>=AF15,AF16-AF15,0)*0.53 -> 10.6 | AH16: 258507 | AI16: =IF(AH16>=AH15,AH16-AH15,0)*0.53 -> 1126.25 | AJ16: 823012 | AK16: =IF(AJ16>=AJ15,AJ16-AJ15,0)*0.53 -> 3969.7 | AL16: 543774 | AM16: =IF(AL16>=AL15,AL16-AL15,0)*0.53 -> 103.35 | AN16: =W16+Y16+AA16+AC16+AE16+AG16+AI16+AK16+AM16 -> 15597.9 | AO16: 7917350 | AP16: =IF(AO16>=AO15,AO16-AO15,0)*0.1125 -> 282.375 | AQ16: 729496 | AR16: =IF(AQ16>=AQ15,AQ16-AQ15,0) -> 159 | AS16: 996807 | AT16: =IF(AS16>=AS15,AS16-AS15,0) -> 155 | AU16: 820060 | AV16: =IF(AU16>=AU15,AU16-AU15,0) -> 66 | AW16: 2777266 | AX16: =IF(AW16>=AW15,AW16-AW15,0) -> 1136 | AY16: 229733 | AZ16: =IF(AY16>=AY15,AY16-AY15,0) -> 0 | BA16: 20227866 | BB16: =IF(BA16>=BA15,BA16-BA15,0) -> 5456 | BC16: 611998 | BD16: =IF(BC16>=BC15,BC16-BC15,0) -> 282 | BE16: 37944 | BF16: =IF(BE16>=BE15,BE16-BE15,0) -> 65 | BG16: 25354937 | BH16: =IF(BG16>=BG15,BG16-BG15,0)-(0.45*BN16)-(0.45*BP16)-BR16 -> 6685.85 | BI16: =AP16+AR16+AT16+AV16+AX16+AZ16+BB16+BD16+BF16+BH16 -> 14287.225 | BJ16: =BI16+AN16 -> 29885.125 | BK16: 1467636 | BL16: =IF(BK16>=BK15,BK16-BK15,0) -> 307 | BM16: 4156736 | BN16: =IF(BM16>=BM15,BM16-BM15,0) -> 1538 | BO16: 437236 | BP16: =IF(BO16>=BO15,BO16-BO15,0) -> 109 | BQ16: 546421 | BR16: =IF(BQ16>=BQ15,BQ16-BQ15,0) -> 160 | BS16: =J16+Q16+AN16+BI16 -> 35833.125 | BT16: 211 | BU16: =IF(BS16>0,BS16/BT15,0) -> 184.70683 | BW16: =IF(BS16>0,BS16/BV16,0) -> #DIV/0! | BX16: =((BS16-Q16)*$BZ$1)+(Q16*$BR$1) -> 41478.094 | BY16: =IF(BX16>0,BX16/BT15,0) -> 213.80461 | BZ16: =IF(BX16>0,BX16/BV16,0) -> #DIV/0!
A17: 12 | C17: =IF(+B17-B16>0,B17-B16,(B17-B16)>0)*800 -> 0 | E17: =IF(+D17-D16>0,D17-D16,(D17-D16)>0)*80 -> 0 | G17: =IF(+F17-F16>0,F17-F16,(F17-F16)>0)*10 -> 0 | I17: 25103721 | J17: =IF(I17>=I16,I17-I16,0) -> 5312 | K17: =M17+O17 -> 4664 | L17: 58819 | M17: =IF(L17>=L16,L17-L16,0) -> 2067 | N17: 88490 | O17: =IF(N17>=N16,N17-N16,0) -> 2597 | P17: 225060 | Q17: =IF(P17>=P16,P17-P16,0)*30 -> 600 | R17: 210555 | S17: =IF(R17>=R16,R17-R16,0) -> 137 | T17: 384135 | U17: =IF(T17>=T16,T17-T16,0) -> 268 | V17: 297550 | W17: =IF(V17>=V16,V17-V16,0)*0.53 -> 0 | X17: 534278 | Y17: =IF(X17>=X16,X17-X16,0)*0.53 -> 3893.38 | Z17: 555152 | AA17: =IF(Z17>=Z16,Z17-Z16,0)*0.53 -> 0 | AB17: 876410 | AC17: =IF(AB17>=AB16,AB17-AB16,0)*0.53 -> 3855.22 | AD17: 798741 | AE17: =IF(AD17>=AD16,AD17-AD16,0)*0.53 -> 1807.3 | AF17: 904781 | AG17: =IF(AF17>=AF16,AF17-AF16,0)*0.53 -> 10.07 | AH17: 260627 | AI17: =IF(AH17>=AH16,AH17-AH16,0)*0.53 -> 1123.6 | AJ17: 830479 | AK17: =IF(AJ17>=AJ16,AJ17-AJ16,0)*0.53 -> 3957.51 | AL17: 543968 | AM17: =IF(AL17>=AL16,AL17-AL16,0)*0.53 -> 102.82 | AN17: =W17+Y17+AA17+AC17+AE17+AG17+AI17+AK17+AM17 -> 14749.9 | AO17: 7919898 | AP17: =IF(AO17>=AO16,AO17-AO16,0)*0.1125 -> 286.65 | AQ17: 729644 | AR17: =IF(AQ17>=AQ16,AQ17-AQ16,0) -> 148 | AS17: 996964 | AT17: =IF(AS17>=AS16,AS17-AS16,0) -> 157 | AU17: 820110 | AV17: =IF(AU17>=AU16,AU17-AU16,0) -> 50 | AW17: 2778384 | AX17: =IF(AW17>=AW16,AW17-AW16,0) -> 1118 | AY17: 229733 | AZ17: =IF(AY17>=AY16,AY17-AY16,0) -> 0 | BA17: 20232571 | BB17: =IF(BA17>=BA16,BA17-BA16,0) -> 4705 | BC17: 612271 | BD17: =IF(BC17>=BC16,BC17-BC16,0) -> 273 | BE17: 38009 | BF17: =IF(BE17>=BE16,BE17-BE16,0) -> 65 | BG17: 25362600 | BH17: =IF(BG17>=BG16,BG17-BG16,0)-(0.45*BN17)-(0.45*BP17)-BR17 -> 6782 | BI17: =AP17+AR17+AT17+AV17+AX17+AZ17+BB17+BD17+BF17+BH17 -> 13584.65 | BJ17: =BI17+AN17 -> 28334.55 | BK17: 1467937 | BL17: =IF(BK17>=BK16,BK17-BK16,0) -> 301 | BM17: 4158267 | BN17: =IF(BM17>=BM16,BM17-BM16,0) -> 1531 | BO17: 437345 | BP17: =IF(BO17>=BO16,BO17-BO16,0) -> 109 | BQ17: 546564 | BR17: =IF(BQ17>=BQ16,BQ17-BQ16,0) -> 143 | BS17: =J17+Q17+AN17+BI17 -> 34246.55 | BT17: 239 | BU17: =IF(BS17>0,BS17/BT16,0) -> 162.30592 | BW17: =IF(BS17>0,BS17/BV17,0) -> #DIV/0! | BX17: =((BS17-Q17)*$BZ$1)+(Q17*$BR$1) -> 39653.533 | BY17: =IF(BX17>0,BX17/BT16,0) -> 187.93143 | BZ17: =IF(BX17>0,BX17/BV17,0) -> #DIV/0!
A18: 13 | C18: =IF(+B18-B17>0,B18-B17,(B18-B17)>0)*800 -> 0 | E18: =IF(+D18-D17>0,D18-D17,(D18-D17)>0)*80 -> 0 | G18: =IF(+F18-F17>0,F18-F17,(F18-F17)>0)*10 -> 0 | H18: 62 | I18: 25109327 | J18: =IF(I18>=I17,I18-I17,0) -> 5606 | K18: =M18+O18 -> 3705 | L18: 60687 | M18: =IF(L18>=L17,L18-L17,0) -> 1868 | N18: 90327 | O18: =IF(N18>=N17,N18-N17,0) -> 1837 | P18: 225070 | Q18: =IF(P18>=P17,P18-P17,0)*30 -> 300 | R18: 210696 | S18: =IF(R18>=R17,R18-R17,0) -> 141 | T18: 384406 | U18: =IF(T18>=T17,T18-T17,0) -> 271 | V18: 297550 | W18: =IF(V18>=V17,V18-V17,0)*0.53 -> 0 | X18: 541628 | Y18: =IF(X18>=X17,X18-X17,0)*0.53 -> 3895.5 | Z18: 555152 | AA18: =IF(Z18>=Z17,Z18-Z17,0)*0.53 -> 0 | AB18: 882596 | AC18: =IF(AB18>=AB17,AB18-AB17,0)*0.53 -> 3278.58 | AD18: 801988 | AE18: =IF(AD18>=AD17,AD18-AD17,0)*0.53 -> 1720.91 | AF18: 904800 | AG18: =IF(AF18>=AF17,AF18-AF17,0)*0.53 -> 10.07 | AH18: 262612 | AI18: =IF(AH18>=AH17,AH18-AH17,0)*0.53 -> 1052.05 | AJ18: 837515 | AK18: =IF(AJ18>=AJ17,AJ18-AJ17,0)*0.53 -> 3729.08 | AL18: 544163 | AM18: =IF(AL18>=AL17,AL18-AL17,0)*0.53 -> 103.35 | AN18: =W18+Y18+AA18+AC18+AE18+AG18+AI18+AK18+AM18 -> 13789.54 | AO18: 7922504 | AP18: =IF(AO18>=AO17,AO18-AO17,0)*0.1125 -> 293.175 | AQ18: 729804 | AR18: =IF(AQ18>=AQ17,AQ18-AQ17,0) -> 160 | AS18: 997113 | AT18: =IF(AS18>=AS17,AS18-AS17,0) -> 149 | AU18: 820156 | AV18: =IF(AU18>=AU17,AU18-AU17,0) -> 46 | AW18: 2779396 | AX18: =IF(AW18>=AW17,AW18-AW17,0) -> 1012 | AY18: 229733 | AZ18: =IF(AY18>=AY17,AY18-AY17,0) -> 0 | BA18: 20237449 | BB18: =IF(BA18>=BA17,BA18-BA17,0) -> 4878 | BC18: 612534 | BD18: =IF(BC18>=BC17,BC18-BC17,0) -> 263 | BE18: 38074 | BF18: =IF(BE18>=BE17,BE18-BE17,0) -> 65 | BG18: 25369860 | BH18: =IF(BG18>=BG17,BG18-BG17,0)-(0.45*BN18)-(0.45*BP18)-BR18 -> 6339.85 | BI18: =AP18+AR18+AT18+AV18+AX18+AZ18+BB18+BD18+BF18+BH18 -> 13206.025 | BJ18: =BI18+AN18 -> 26995.565 | BK18: 1468244 | BL18: =IF(BK18>=BK17,BK18-BK17,0) -> 307 | BM18: 4159803 | BN18: =IF(BM18>=BM17,BM18-BM17,0) -> 1536 | BO18: 437456 | BP18: =IF(BO18>=BO17,BO18-BO17,0) -> 111 | BQ18: 546743 | BR18: =IF(BQ18>=BQ17,BQ18-BQ17,0) -> 179 | BS18: =J18+Q18+AN18+BI18 -> 32901.565 | BT18: 227 | BU18: =IF(BS18>0,BS18/BT17,0) -> 137.66345 | BW18: =IF(BS18>0,BS18/BV18,0) -> #DIV/0! | BX18: =((BS18-Q18)*$BZ$1)+(Q18*$BR$1) -> 37971.8 | BY18: =IF(BX18>0,BX18/BT17,0) -> 158.87782 | BZ18: =IF(BX18>0,BX18/BV18,0) -> #DIV/0!
A19: 14 | C19: =IF(+B19-B18>0,B19-B18,(B19-B18)>0)*800 -> 0 | E19: =IF(+D19-D18>0,D19-D18,(D19-D18)>0)*80 -> 0 | G19: =IF(+F19-F18>0,F19-F18,(F19-F18)>0)*10 -> 0 | I19: 25114752 | J19: =IF(I19>=I18,I19-I18,0) -> 5425 | K19: =M19+O19 -> 4020 | L19: 62648 | M19: =IF(L19>=L18,L19-L18,0) -> 1961 | N19: 92386 | O19: =IF(N19>=N18,N19-N18,0) -> 2059 | P19: 225090 | Q19: =IF(P19>=P18,P19-P18,0)*30 -> 600 | R19: 210835 | S19: =IF(R19>=R18,R19-R18,0) -> 139 | T19: 384672 | U19: =IF(T19>=T18,T19-T18,0) -> 266 | V19: 297550 | W19: =IF(V19>=V18,V19-V18,0)*0.53 -> 0 | X19: 549326 | Y19: =IF(X19>=X18,X19-X18,0)*0.53 -> 4079.94 | Z19: 555152 | AA19: =IF(Z19>=Z18,Z19-Z18,0)*0.53 -> 0 | AB19: 888902 | AC19: =IF(AB19>=AB18,AB19-AB18,0)*0.53 -> 3342.18 | AD19: 805103 | AE19: =IF(AD19>=AD18,AD19-AD18,0)*0.53 -> 1650.95 | AF19: 904819 | AG19: =IF(AF19>=AF18,AF19-AF18,0)*0.53 -> 10.07 | AH19: 264703 | AI19: =IF(AH19>=AH18,AH19-AH18,0)*0.53 -> 1108.23 | AJ19: 844875 | AK19: =IF(AJ19>=AJ18,AJ19-AJ18,0)*0.53 -> 3900.8 | AL19: 544375 | AM19: =IF(AL19>=AL18,AL19-AL18,0)*0.53 -> 112.36 | AN19: =W19+Y19+AA19+AC19+AE19+AG19+AI19+AK19+AM19 -> 14204.53 | AO19: 7925108 | AP19: =IF(AO19>=AO18,AO19-AO18,0)*0.1125 -> 292.95 | AQ19: 729975 | AR19: =IF(AQ19>=AQ18,AQ19-AQ18,0) -> 171 | AS19: 997269 | AT19: =IF(AS19>=AS18,AS19-AS18,0) -> 156 | AU19: 820216 | AV19: =IF(AU19>=AU18,AU19-AU18,0) -> 60 | AW19: 2780439 | AX19: =IF(AW19>=AW18,AW19-AW18,0) -> 1043 | AY19: 229733 | AZ19: =IF(AY19>=AY18,AY19-AY18,0) -> 0 | BA19: 20242347 | BB19: =IF(BA19>=BA18,BA19-BA18,0) -> 4898 | BC19: 612788 | BD19: =IF(BC19>=BC18,BC19-BC18,0) -> 254 | BE19: 38169 | BF19: =IF(BE19>=BE18,BE19-BE18,0) -> 95 | BG19: 25377029 | BH19: =IF(BG19>=BG18,BG19-BG18,0)-(0.45*BN19)-(0.45*BP19)-BR19 -> 6248.9 | BI19: =AP19+AR19+AT19+AV19+AX19+AZ19+BB19+BD19+BF19+BH19 -> 13218.85 | BJ19: =BI19+AN19 -> 27423.38 | BK19: 1468548 | BL19: =IF(BK19>=BK18,BK19-BK18,0) -> 304 | BM19: 4161356 | BN19: =IF(BM19>=BM18,BM19-BM18,0) -> 1553 | BO19: 437561 | BP19: =IF(BO19>=BO18,BO19-BO18,0) -> 105 | BQ19: 546917 | BR19: =IF(BQ19>=BQ18,BQ19-BQ18,0) -> 174 | BS19: =J19+Q19+AN19+BI19 -> 33448.38 | BT19: 216 | BU19: =IF(BS19>0,BS19/BT18,0) -> 147.34969 | BW19: =IF(BS19>0,BS19/BV19,0) -> #DIV/0! | BX19: =((BS19-Q19)*$BZ$1)+(Q19*$BR$1) -> 38735.637 | BY19: =IF(BX19>0,BX19/BT18,0) -> 170.64157 | BZ19: =IF(BX19>0,BX19/BV19,0) -> #DIV/0!
A20: 15 | C20: =IF(+B20-B19>0,B20-B19,(B20-B19)>0)*800 -> 0 | E20: =IF(+D20-D19>0,D20-D19,(D20-D19)>0)*80 -> 0 | G20: =IF(+F20-F19>0,F20-F19,(F20-F19)>0)*10 -> 0 | H20: 63 | I20: 25119721 | J20: =IF(I20>=I19,I20-I19,0) -> 4969 | K20: =M20+O20 -> 4024 | L20: 64546 | M20: =IF(L20>=L19,L20-L19,0) -> 1898 | N20: 94512 | O20: =IF(N20>=N19,N20-N19,0) -> 2126 | P20: 225100 | Q20: =IF(P20>=P19,P20-P19,0)*30 -> 300 | R20: 210974 | S20: =IF(R20>=R19,R20-R19,0) -> 139 | T20: 384933 | U20: =IF(T20>=T19,T20-T19,0) -> 261 | V20: 302968 | W20: =IF(V20>=V19,V20-V19,0)*0.53 -> 2871.54 | X20: 551756 | Y20: =IF(X20>=X19,X20-X19,0)*0.53 -> 1287.9 | Z20: 560333 | AA20: =IF(Z20>=Z19,Z20-Z19,0)*0.53 -> 2745.93 | AB20: 890810 | AC20: =IF(AB20>=AB19,AB20-AB19,0)*0.53 -> 1011.24 | AD20: 808487 | AE20: =IF(AD20>=AD19,AD20-AD19,0)*0.53 -> 1793.52 | AF20: 904840 | AG20: =IF(AF20>=AF19,AF20-AF19,0)*0.53 -> 11.13 | AH20: 266822 | AI20: =IF(AH20>=AH19,AH20-AH19,0)*0.53 -> 1123.07 | AJ20: 852301 | AK20: =IF(AJ20>=AJ19,AJ20-AJ19,0)*0.53 -> 3935.78 | AL20: 544586 | AM20: =IF(AL20>=AL19,AL20-AL19,0)*0.53 -> 111.83 | AN20: =W20+Y20+AA20+AC20+AE20+AG20+AI20+AK20+AM20 -> 14891.94 | AO20: 7927809 | AP20: =IF(AO20>=AO19,AO20-AO19,0)*0.1125 -> 303.8625 | AQ20: 730145 | AR20: =IF(AQ20>=AQ19,AQ20-AQ19,0) -> 170 | AS20: 997423 | AT20: =IF(AS20>=AS19,AS20-AS19,0) -> 154 | AU20: 820279 | AV20: =IF(AU20>=AU19,AU20-AU19,0) -> 63 | AW20: 2781496 | AX20: =IF(AW20>=AW19,AW20-AW19,0) -> 1057 | AY20: 229733 | AZ20: =IF(AY20>=AY19,AY20-AY19,0) -> 0 | BA20: 20247428 | BB20: =IF(BA20>=BA19,BA20-BA19,0) -> 5081 | BC20: 613046 | BD20: =IF(BC20>=BC19,BC20-BC19,0) -> 258 | BE20: 38217 | BF20: =IF(BE20>=BE19,BE20-BE19,0) -> 48 | BG20: 25384051 | BH20: =IF(BG20>=BG19,BG20-BG19,0)-(0.45*BN20)-(0.45*BP20)-BR20 -> 6145.9 | BI20: =AP20+AR20+AT20+AV20+AX20+AZ20+BB20+BD20+BF20+BH20 -> 13280.763 | BJ20: =BI20+AN20 -> 28172.702 | BK20: 1468853 | BL20: =IF(BK20>=BK19,BK20-BK19,0) -> 305 | BM20: 4162885 | BN20: =IF(BM20>=BM19,BM20-BM19,0) -> 1529 | BO20: 437670 | BP20: =IF(BO20>=BO19,BO20-BO19,0) -> 109 | BQ20: 547056 | BR20: =IF(BQ20>=BQ19,BQ20-BQ19,0) -> 139 | BS20: =J20+Q20+AN20+BI20 -> 33441.702 | BT20: 211 | BU20: =IF(BS20>0,BS20/BT20,0) -> 158.49148 | BW20: =IF(BS20>0,BS20/BV20,0) -> #DIV/0! | BX20: =((BS20-Q20)*$BZ$1)+(Q20*$BR$1) -> 38592.958 | BY20: =IF(BX20>0,BX20/BT20,0) -> 182.90501 | BZ20: =IF(BX20>0,BX20/BV20,0) -> #DIV/0!
