Workbook

Sheet Total
A1: Site Name | B1: Day | C1: Month | D1: Year | E1: Total Electricity Kwh | F1: Electricity Tariff ($/Kwh) | G1: Natual Gas (m3) | H1: Natural Gas $/m3 | I1: Water Utility Supply (m3) m3 | J1: Water Utility Supply (m3) $/m3 | K1: Room Nights
A2: Cairo at The First Residence | B2: 1 | C2: 8 | D2: 2022 | E2: =Elect!BS6+Submetering!AH2 -> 26128.563 | F2: ='Utility Consnsumption'!K13/'Utility Consnsumption'!J13 -> 1.3909353 | G2: =Gas!K7+Submetering!AR2 -> 4034.4844 | H2: 3.8 | I2: =Water!H7+Submetering!AM2 -> 433.405 | J2: 10 | K2: =Elect!BT6 -> 238
A3: Cairo at The First Residence | B3: =B2+1 -> 2 | C3: 8 | D3: 2022 | E3: =Elect!BS7+Submetering!AH3 -> 23425.48 | F3: =F2 -> 1.3909353 | G3: =Gas!K8+Submetering!AR3 -> 1966.56 | H3: 3.8 | I3: =Water!H8+Submetering!AM3 -> 258.1 | J3: 10 | K3: =Elect!BT7 -> 227
A4: Cairo at The First Residence | B4: =B3+1 -> 3 | C4: 8 | D4: 2022 | E4: =Elect!BS8+Submetering!AH4 -> 25080.585 | F4: =F3 -> 1.3909353 | G4: =Gas!K9+Submetering!AR4 -> 2100.1 | H4: 3.8 | I4: =Water!H9+Submetering!AM4 -> 342.78 | J4: 10 | K4: =Elect!BT8 -> 213
A5: Cairo at The First Residence | B5: =B4+1 -> 4 | C5: 8 | D5: 2022 | E5: =Elect!BS9+Submetering!AH5 -> 23163.165 | F5: =F4 -> 1.3909353 | G5: =Gas!K10+Submetering!AR5 -> 2271.86 | H5: 3.8 | I5: =Water!H10+Submetering!AM5 -> 311.46 | J5: 10 | K5: =Elect!BT9 -> 202
A6: Cairo at The First Residence | B6: =B5+1 -> 5 | C6: 8 | D6: 2022 | E6: =Elect!BS10+Submetering!AH6 -> 24521.783 | F6: =F5 -> 1.3909353 | G6: =Gas!K11+Submetering!AR6 -> 1973.64 | H6: 3.8 | I6: =Water!H11+Submetering!AM6 -> 352.06 | J6: 10 | K6: =Elect!BT10 -> 196
A7: Cairo at The First Residence | B7: =B6+1 -> 6 | C7: 8 | D7: 2022 | E7: =Elect!BS11+Submetering!AH7 -> 25763.33 | F7: =F6 -> 1.3909353 | G7: =Gas!K12+Submetering!AR7 -> 2108.8 | H7: 3.8 | I7: =Water!H12+Submetering!AM7 -> 359.6 | J7: 10 | K7: =Elect!BT11 -> 214
A8: Cairo at The First Residence | B8: =B7+1 -> 7 | C8: 8 | D8: 2022 | E8: =Elect!BS12+Submetering!AH8 -> 26164.928 | F8: =F7 -> 1.3909353 | G8: =Gas!K13+Submetering!AR8 -> 2077.64 | H8: 3.8 | I8: =Water!H13+Submetering!AM8 -> 418.18 | J8: 10 | K8: =Elect!BT12 -> 254
A9: Cairo at The First Residence | B9: =B8+1 -> 8 | C9: 8 | D9: 2022 | E9: =Elect!BS13+Submetering!AH9 -> 22257.475 | F9: =F8 -> 1.3909353 | G9: =Gas!K14+Submetering!AR9 -> 2136.04 | H9: 3.8 | I9: =Water!H14+Submetering!AM9 -> 425.72 | J9: 10 | K9: =Elect!BT13 -> 239
A10: Cairo at The First Residence | B10: =B9+1 -> 9 | C10: 8 | D10: 2022 | E10: =Elect!BS14+Submetering!AH10 -> 25597.536 | F10: =F9 -> 1.3909353 | G10: =Gas!K15+Submetering!AR10 -> 2128.36 | H10: 3.8 | I10: =Water!H15+Submetering!AM10 -> 441.38 | J10: 10 | K10: =Elect!BT14 -> 220
A11: Cairo at The First Residence | B11: =B10+1 -> 10 | C11: 8 | D11: 2022 | E11: =Elect!BS15+Submetering!AH11 -> 18687.874 | F11: =F10 -> 1.3909353 | G11: =Gas!K16+Submetering!AR11 -> 2151.04 | H11: 3.8 | I11: =Water!H16+Submetering!AM11 -> 412.96 | J11: 10 | K11: =Elect!BT15 -> 185
A12: Cairo at The First Residence | B12: =B11+1 -> 11 | C12: 8 | D12: 2022 | E12: =Elect!BS16+Submetering!AH12 -> 25872.397 | F12: =F11 -> 1.3909353 | G12: =Gas!K17+Submetering!AR12 -> 2132.2 | H12: 3.8 | I12: =Water!H17+Submetering!AM12 -> 432.274 | J12: 10 | K12: =Elect!BT16 -> 156
A13: Cairo at The First Residence | B13: =B12+1 -> 12 | C13: 8 | D13: 2022 | E13: =Elect!BS17+Submetering!AH13 -> 24551.895 | F13: =F12 -> 1.3909353 | G13: =Gas!K18+Submetering!AR13 -> 2137.468 | H13: 3.8 | I13: =Water!H18+Submetering!AM13 -> 427.518 | J13: 10 | K13: =Elect!BT17 -> 199
A14: Cairo at The First Residence | B14: =B13+1 -> 13 | C14: 8 | D14: 2022 | E14: =Elect!BS18+Submetering!AH14 -> 24650.18 | F14: =F13 -> 1.3909353 | G14: =Gas!K19+Submetering!AR14 -> 1881.892 | H14: 3.8 | I14: =Water!H19+Submetering!AM14 -> 310.068 | J14: 10 | K14: =Elect!BT18 -> 212
... A32: Cairo at The First Residence | B32: =B31+1 -> 31 | C32: 8 | D32: 2022 | E32: =Elect!BS36+Submetering!AH32 -> 24520.76 | F32: =F31 -> 1.3909353 | G32: =Gas!K37+Submetering!AR32 -> 2378.32 | H32: 3.8 | I32: =Water!H37+Submetering!AM32 -> 370.62 | J32: 10 | K32: =Elect!BT36 -> 250

Sheet Submetering
A1: Site Name | B1: Day | C1: Month | D1: Year | E1: Electricity | F1: Main Feeder -KWh | G1: T2+T8 -KWh | H1: La Gourmandize -KWh | I1: Casino 3rd floor EM -KWh | J1: Casino 3rd floor Normal -KWh | K1: Chiller 1 -KWh | L1: Chiller 2 -KWh | M1: Chiller 3 -KWh | N1: Chiller 4 -KWh | O1: Chiller 5 -KWh | P1: Chiller 6 -KWh | Q1: Cooling towers -KWh | R1: Chiller Pumps -KWh | S1: Cooling Tower Pumps -KWh | T1: Fiber Chiller -KWh | U1: Mall Ceiling light -KWh | V1: LG Bakery -KWh | W1: LG Bakery light ( Old lockers ) -KWh | X1: MCCR1 -KWh | Y1: Children Swimming Pool -KWh | Z1: DPH1 -KWh | AA1: Guest Rooms Emerg. -KWh | AB1: Hotel Hoods -KWh | AC1: Main G2 -KWh | AD1: Old Casino Emergency -KWh | AE1: L / A -KWh | AF1: L / B -KWh | AG1: L / C -KWh | AH1: Boat -KWh | AI1: Water | AJ1: Main water meter 1 -m3 | AK1: Main water meter 2 -m3 | AL1: Main water meter 3 -m3 | AM1: Boat -m3 | AN1: Gas | AO1: Main Gas Flow Meter -m3 | AP1: Laundry Gas Flow Meter -m3 | AQ1: Gourmandize Gas Flow Meter -m3 | AR1: Boat -m3 | AS1: Room Nights
A2: Cairo at The First Residence | B2: 1 | C2: 8 | D2: 2022 | F2: =Elect!J6 -> 6443.9444 | G2: =Elect!K6 -> 3741.8333 | H2: =Elect!Q6 -> 425 | I2: =Elect!S6 -> 140.66667 | J2: =Elect!U6 -> 299.83333 | K2: =Elect!W6 -> 1756.8617 | L2: =Elect!Y6 -> 0 | M2: =Elect!AA6 -> 0 | N2: =Elect!AC6 -> 0 | O2: =Elect!AE6 -> 13.161667 | P2: =Elect!AG6 -> 12.543333 | Q2: =Elect!AI6 -> 312.78833 | R2: =Elect!AK6 -> 4158.0267 | S2: =Elect!AM6 -> 118.985 | T2: =Elect!AP6 -> 112.44375 | U2: =Elect!AR6 -> 162.33333 | V2: =Elect!AT6 -> 93.166667 | W2: =Elect!AV6 -> 40.833333 | X2: =Elect!AX6 -> 843.16667 | Y2: =Elect!AZ6 -> 10.666667 | Z2: =Elect!BB6 -> 5238.1667 | AA2: =Elect!BD6 -> 233.16667 | AB2: =Elect!BF6 -> 44 | AC2: =Elect!BH6 -> 6109.3083 | AD2: =Elect!BL6 -> 225.16667 | AE2: =Elect!BN6 -> 961.16667 | AF2: =Elect!BP6 -> 170 | AG2: =Elect!BR6 -> 149.33333 | AH2: =Boat!C4 -> 0 | AJ2: =Water!C7 -> 162.88333 | AK2: =Water!E7 -> 146.74 | AL2: =Water!G7 -> 123.78167 | AM2: =Boat!E4 -> 0 | AO2: =Gas!C7 -> 3529.1817 | AP2: =Gas!E7 -> 505.30278 | AQ2: =Gas!G7 -> 122.26852 | AR2: =Boat!G4 -> 0 | AS2: =Elect!BT6 -> 238
A3: Cairo at The First Residence | B3: =B2+1 -> 2 | C3: 8 | D3: 2022 | F3: =Elect!J7 -> 6181 | G3: =Elect!K7 -> 3985 | H3: =Elect!Q7 -> 480 | I3: =Elect!S7 -> 138 | J3: =Elect!U7 -> 235 | K3: =Elect!W7 -> 2088.2 | L3: =Elect!Y7 -> 0 | M3: =Elect!AA7 -> 0 | N3: =Elect!AC7 -> 0 | O3: =Elect!AE7 -> 15.37 | P3: =Elect!AG7 -> 14.31 | Q3: =Elect!AI7 -> 271.89 | R3: =Elect!AK7 -> 2304.97 | S3: =Elect!AM7 -> 112.89 | T3: =Elect!AP7 -> 38.25 | U3: =Elect!AR7 -> 194 | V3: =Elect!AT7 -> 96 | W3: =Elect!AV7 -> 43 | X3: =Elect!AX7 -> 955 | Y3: =Elect!AZ7 -> 10 | Z3: =Elect!BB7 -> 5054 | AA3: =Elect!BD7 -> 221 | AB3: =Elect!BF7 -> 45 | AC3: =Elect!BH7 -> 5300.6 | AD3: =Elect!BL7 -> 163 | AE3: =Elect!BN7 -> 1119 | AF3: =Elect!BP7 -> 133 | AG3: =Elect!BR7 -> 151 | AH3: =Boat!C5 -> 0 | AJ3: =Water!C8 -> 69.6 | AK3: =Water!E8 -> 87 | AL3: =Water!G8 -> 101.5 | AM3: =Boat!E5 -> 0 | AO3: =Gas!C8 -> 1622.86 | AP3: =Gas!E8 -> 343.7 | AQ3: =Gas!G8 -> 75 | AR3: =Boat!G5 -> 0 | AS3: =Elect!BT7 -> 227
A4: Cairo at The First Residence | B4: =B3+1 -> 3 | C4: 8 | D4: 2022 | F4: =Elect!J8 -> 6253 | G4: =Elect!K8 -> 4301 | H4: =Elect!Q8 -> 540 | I4: =Elect!S8 -> 151 | J4: =Elect!U8 -> 263 | K4: =Elect!W8 -> 2313.45 | L4: =Elect!Y8 -> 0 | M4: =Elect!AA8 -> 0 | N4: =Elect!AC8 -> 0 | O4: =Elect!AE8 -> 14.31 | P4: =Elect!AG8 -> 13.25 | Q4: =Elect!AI8 -> 294.68 | R4: =Elect!AK8 -> 2532.87 | S4: =Elect!AM8 -> 121.9 | T4: =Elect!AP8 -> 28.575 | U4: =Elect!AR8 -> 189 | V4: =Elect!AT8 -> 92 | W4: =Elect!AV8 -> 47 | X4: =Elect!AX8 -> 1007 | Y4: =Elect!AZ8 -> 11 | Z4: =Elect!BB8 -> 5129 | AA4: =Elect!BD8 -> 248 | AB4: =Elect!BF8 -> 50 | AC4: =Elect!BH8 -> 6195.55 | AD4: =Elect!BL8 -> 324 | AE4: =Elect!BN8 -> 1295 | AF4: =Elect!BP8 -> 146 | AG4: =Elect!BR8 -> 156 | AH4: =Boat!C6 -> 0 | AJ4: =Water!C9 -> 104.4 | AK4: =Water!E9 -> 127.6 | AL4: =Water!G9 -> 110.78 | AM4: =Boat!E6 -> 0 | AO4: =Gas!C9 -> 1717.2 | AP4: =Gas!E9 -> 382.9 | AQ4: =Gas!G9 -> 95 | AR4: =Boat!G6 -> 0 | AS4: =Elect!BT8 -> 213
A5: Cairo at The First Residence | B5: =B4+1 -> 4 | C5: 8 | D5: 2022 | F5: =Elect!J9 -> 5829 | G5: =Elect!K9 -> 4389 | H5: =Elect!Q9 -> 540 | I5: =Elect!S9 -> 138 | J5: =Elect!U9 -> 239 | K5: =Elect!W9 -> 2363.8 | L5: =Elect!Y9 -> 0 | M5: =Elect!AA9 -> 0 | N5: =Elect!AC9 -> 0 | O5: =Elect!AE9 -> 12.19 | P5: =Elect!AG9 -> 11.66 | Q5: =Elect!AI9 -> 295.21 | R5: =Elect!AK9 -> 2612.37 | S5: =Elect!AM9 -> 125.61 | T5: =Elect!AP9 -> 10.125 | U5: =Elect!AR9 -> 203 | V5: =Elect!AT9 -> 71 | W5: =Elect!AV9 -> 48 | X5: =Elect!AX9 -> 1035 | Y5: =Elect!AZ9 -> 10 | Z5: =Elect!BB9 -> 5079 | AA5: =Elect!BD9 -> 195 | AB5: =Elect!BF9 -> 50 | AC5: =Elect!BH9 -> 4672.2 | AD5: =Elect!BL9 -> 259 | AE5: =Elect!BN9 -> 912 | AF5: =Elect!BP9 -> 112 | AG5: =Elect!BR9 -> 107 | AH5: =Boat!C7 -> 0 | AJ5: =Water!C10 -> 92.8 | AK5: =Water!E10 -> 110.2 | AL5: =Water!G10 -> 108.46 | AM5: =Boat!E7 -> 0 | AO5: =Gas!C10 -> 1893.16 | AP5: =Gas!E10 -> 378.7 | AQ5: =Gas!G10 -> 104 | AR5: =Boat!G7 -> 0 | AS5: =Elect!BT9 -> 202
A6: Cairo at The First Residence | B6: =B5+1 -> 5 | C6: 8 | D6: 2022 | F6: =Elect!J10 -> 6773 | G6: =Elect!K10 -> 4615 | H6: =Elect!Q10 -> 570 | I6: =Elect!S10 -> 162 | J6: =Elect!U10 -> 285 | K6: =Elect!W10 -> 1512.62 | L6: =Elect!Y10 -> 1348.32 | M6: =Elect!AA10 -> 0 | N6: =Elect!AC10 -> 0 | O6: =Elect!AE10 -> 12.72 | P6: =Elect!AG10 -> 12.19 | Q6: =Elect!AI10 -> 191.33 | R6: =Elect!AK10 -> 2223.35 | S6: =Elect!AM10 -> 123.49 | T6: =Elect!AP10 -> 110.8125 | U6: =Elect!AR10 -> 201 | V6: =Elect!AT10 -> 96 | W6: =Elect!AV10 -> 47 | X6: =Elect!AX10 -> 991 | Y6: =Elect!AZ10 -> 12 | Z6: =Elect!BB10 -> 4830 | AA6: =Elect!BD10 -> 244 | AB6: =Elect!BF10 -> 76 | AC6: =Elect!BH10 -> 5146.95 | AD6: =Elect!BL10 -> 92 | AE6: =Elect!BN10 -> 1079 | AF6: =Elect!BP10 -> 130 | AG6: =Elect!BR10 -> 151 | AH6: =Boat!C8 -> 0 | AJ6: =Water!C11 -> 110.2 | AK6: =Water!E11 -> 121.8 | AL6: =Water!G11 -> 120.06 | AM6: =Boat!E8 -> 0 | AO6: =Gas!C11 -> 1557.14 | AP6: =Gas!E11 -> 416.5 | AQ6: =Gas!G11 -> 91 | AR6: =Boat!G8 -> 0 | AS6: =Elect!BT10 -> 196
A7: Cairo at The First Residence | B7: =B6+1 -> 6 | C7: 8 | D7: 2022 | F7: =Elect!J11 -> 6934 | G7: =Elect!K11 -> 3800 | H7: =Elect!Q11 -> 570 | I7: =Elect!S11 -> 135 | J7: =Elect!U11 -> 240 | K7: =Elect!W11 -> 2537.64 | L7: =Elect!Y11 -> 0 | M7: =Elect!AA11 -> 0 | N7: =Elect!AC11 -> 0 | O7: =Elect!AE11 -> 15.9 | P7: =Elect!AG11 -> 14.84 | Q7: =Elect!AI11 -> 151.58 | R7: =Elect!AK11 -> 1817.37 | S7: =Elect!AM11 -> 98.05 | T7: =Elect!AP11 -> 124.65 | U7: =Elect!AR11 -> 174 | V7: =Elect!AT11 -> 137 | W7: =Elect!AV11 -> 35 | X7: =Elect!AX11 -> 784 | Y7: =Elect!AZ11 -> 10 | Z7: =Elect!BB11 -> 5746 | AA7: =Elect!BD11 -> 287 | AB7: =Elect!BF11 -> 83 | AC7: =Elect!BH11 -> 6243.3 | AD7: =Elect!BL11 -> 94 | AE7: =Elect!BN11 -> 1234 | AF7: =Elect!BP11 -> 152 | AG7: =Elect!BR11 -> 144 | AH7: =Boat!C9 -> 0 | AJ7: =Water!C12 -> 116 | AK7: =Water!E12 -> 139.2 | AL7: =Water!G12 -> 104.4 | AM7: =Boat!E9 -> 0 | AO7: =Gas!C12 -> 1749 | AP7: =Gas!E12 -> 359.8 | AQ7: =Gas!G12 -> 83 | AR7: =Boat!G9 -> 0 | AS7: =Elect!BT11 -> 214
A8: Cairo at The First Residence | B8: =B7+1 -> 7 | C8: 8 | D8: 2022 | F8: =Elect!J12 -> 7377 | G8: =Elect!K12 -> 3947 | H8: =Elect!Q12 -> 600 | I8: =Elect!S12 -> 135 | J8: =Elect!U12 -> 241 | K8: =Elect!W12 -> 2671.73 | L8: =Elect!Y12 -> 0 | M8: =Elect!AA12 -> 0 | N8: =Elect!AC12 -> 0 | O8: =Elect!AE12 -> 12.19 | P8: =Elect!AG12 -> 11.66 | Q8: =Elect!AI12 -> 179.67 | R8: =Elect!AK12 -> 2124.77 | S8: =Elect!AM12 -> 110.77 | T8: =Elect!AP12 -> 142.9875 | U8: =Elect!AR12 -> 192 | V8: =Elect!AT12 -> 131 | W8: =Elect!AV12 -> 41 | X8: =Elect!AX12 -> 884 | Y8: =Elect!AZ12 -> 10 | Z8: =Elect!BB12 -> 5560 | AA8: =Elect!BD12 -> 265 | AB8: =Elect!BF12 -> 17 | AC8: =Elect!BH12 -> 5834.15 | AD8: =Elect!BL12 -> 312 | AE8: =Elect!BN12 -> 1134 | AF8: =Elect!BP12 -> 139 | AG8: =Elect!BR12 -> 135 | AH8: =Boat!C10 -> 0 | AJ8: =Water!C13 -> 139.2 | AK8: =Water!E13 -> 168.2 | AL8: =Water!G13 -> 110.78 | AM8: =Boat!E10 -> 0 | AO8: =Gas!C13 -> 1673.74 | AP8: =Gas!E13 -> 403.9 | AQ8: =Gas!G13 -> 106 | AR8: =Boat!G10 -> 0 | AS8: =Elect!BT12 -> 254
A9: Cairo at The First Residence | B9: =B8+1 -> 8 | C9: 8 | D9: 2022 | F9: =Elect!J13 -> 5450 | G9: =Elect!K13 -> 4238 | H9: =Elect!Q13 -> 540 | I9: =Elect!S13 -> 151 | J9: =Elect!U13 -> 271 | K9: =Elect!W13 -> 2089.79 | L9: =Elect!Y13 -> 0 | M9: =Elect!AA13 -> 0 | N9: =Elect!AC13 -> 0 | O9: =Elect!AE13 -> 13.25 | P9: =Elect!AG13 -> 12.19 | Q9: =Elect!AI13 -> 137.8 | R9: =Elect!AK13 -> 2194.73 | S9: =Elect!AM13 -> 104.94 | T9: =Elect!AP13 -> 107.325 | U9: =Elect!AR13 -> 176 | V9: =Elect!AT13 -> 90 | W9: =Elect!AV13 -> 42 | X9: =Elect!AX13 -> 925 | Y9: =Elect!AZ13 -> 11 | Z9: =Elect!BB13 -> 4768 | AA9: =Elect!BD13 -> 184 | AB9: =Elect!BF13 -> 45 | AC9: =Elect!BH13 -> 5366.45 | AD9: =Elect!BL13 -> 223 | AE9: =Elect!BN13 -> 825 | AF9: =Elect!BP13 -> 94 | AG9: =Elect!BR13 -> 93 | AH9: =Boat!C11 -> 0 | AJ9: =Water!C14 -> 139.2 | AK9: =Water!E14 -> 174 | AL9: =Water!G14 -> 112.52 | AM9: =Boat!E11 -> 0 | AO9: =Gas!C14 -> 1742.64 | AP9: =Gas!E14 -> 393.4 | AQ9: =Gas!G14 -> 90 | AR9: =Boat!G11 -> 0 | AS9: =Elect!BT13 -> 239
A10: Cairo at The First Residence | B10: =B9+1 -> 9 | C10: 8 | D10: 2022 | F10: =Elect!J14 -> 6568 | G10: =Elect!K14 -> 6056 | H10: =Elect!Q14 -> 570 | I10: =Elect!S14 -> 139 | J10: =Elect!U14 -> 237 | K10: =Elect!W14 -> 2563.08 | L10: =Elect!Y14 -> 0 | M10: =Elect!AA14 -> 0 | N10: =Elect!AC14 -> 0 | O10: =Elect!AE14 -> 13.25 | P10: =Elect!AG14 -> 12.19 | Q10: =Elect!AI14 -> 168.54 | R10: =Elect!AK14 -> 2952.63 | S10: =Elect!AM14 -> 156.35 | T10: =Elect!AP14 -> 105.4125 | U10: =Elect!AR14 -> 183 | V10: =Elect!AT14 -> 117.33333 | W10: =Elect!AV14 -> 57 | X10: =Elect!AX14 -> 1159 | Y10: =Elect!AZ14 -> 10 | Z10: =Elect!BB14 -> 4891 | AA10: =Elect!BD14 -> 453 | AB10: =Elect!BF14 -> 45 | AC10: =Elect!BH14 -> 5572.75 | AD10: =Elect!BL14 -> 319 | AE10: =Elect!BN14 -> 1061 | AF10: =Elect!BP14 -> 124 | AG10: =Elect!BR14 -> 130 | AH10: =Boat!C12 -> 0 | AJ10: =Water!C15 -> 150.8 | AK10: =Water!E15 -> 179.8 | AL10: =Water!G15 -> 110.78 | AM10: =Boat!E12 -> 0 | AO10: =Gas!C15 -> 1744.76 | AP10: =Gas!E15 -> 383.6 | AQ10: =Gas!G15 -> 111 | AR10: =Boat!G12 -> 0 | AS10: =Elect!BT14 -> 220
A11: Cairo at The First Residence | B11: =B10+1 -> 10 | C11: 8 | D11: 2022 | F11: =Elect!J15 -> 4747 | G11: =Elect!K15 -> 4471 | H11: =Elect!Q15 -> 480 | I11: =Elect!S15 -> 140 | J11: =Elect!U15 -> 247 | K11: =Elect!W15 -> 1929.2 | L11: =Elect!Y15 -> 118.19 | M11: =Elect!AA15 -> 0 | N11: =Elect!AC15 -> 0 | O11: =Elect!AE15 -> 12.19 | P11: =Elect!AG15 -> 12.19 | Q11: =Elect!AI15 -> 152.11 | R11: =Elect!AK15 -> 1997.04 | S11: =Elect!AM15 -> 108.65 | T11: =Elect!AP15 -> 117.7875 | U11: =Elect!AR15 -> 194 | V11: =Elect!AT15 -> 103.66667 | W11: =Elect!AV15 -> 42 | X11: =Elect!AX15 -> 846 | Y11: =Elect!AZ15 -> 11 | Z11: =Elect!BB15 -> 3551 | AA11: =Elect!BD15 -> 301 | AB11: =Elect!BF15 -> 37 | AC11: =Elect!BH15 -> 3927.85 | AD11: =Elect!BL15 -> 272 | AE11: =Elect!BN15 -> 865 | AF11: =Elect!BP15 -> 102 | AG11: =Elect!BR15 -> 131 | AH11: =Boat!C13 -> 0 | AJ11: =Water!C16 -> 139.2 | AK11: =Water!E16 -> 168.2 | AL11: =Water!G16 -> 105.56 | AM11: =Boat!E13 -> 0 | AO11: =Gas!C16 -> 1774.44 | AP11: =Gas!E16 -> 376.6 | AQ11: =Gas!G16 -> 99 | AR11: =Boat!G13 -> 0 | AS11: =Elect!BT15 -> 185
A12: Cairo at The First Residence | B12: =B11+1 -> 11 | C12: 8 | D12: 2022 | F12: =Elect!J16 -> 8905 | G12: =Elect!K16 -> 4104 | H12: =Elect!Q16 -> 540 | I12: =Elect!S16 -> 149 | J12: =Elect!U16 -> 253 | K12: =Elect!W16 -> 1837.51 | L12: =Elect!Y16 -> 0 | M12: =Elect!AA16 -> 0 | N12: =Elect!AC16 -> 0 | O12: =Elect!AE16 -> 13.78 | P12: =Elect!AG16 -> 12.72 | Q12: =Elect!AI16 -> 128.26 | R12: =Elect!AK16 -> 1888.92 | S12: =Elect!AM16 -> 97.52 | T12: =Elect!AP16 -> 81.3375 | U12: =Elect!AR16 -> 199 | V12: =Elect!AT16 -> 107 | W12: =Elect!AV16 -> 39 | X12: =Elect!AX16 -> 707 | Y12: =Elect!AZ16 -> 11 | Z12: =Elect!BB16 -> 5376 | AA12: =Elect!BD16 -> 36 | AB12: =Elect!BF16 -> 50 | AC12: =Elect!BH16 -> 5842.35 | AD12: =Elect!BL16 -> 322 | AE12: =Elect!BN16 -> 997 | AF12: =Elect!BP16 -> 120 | AG12: =Elect!BR16 -> 127 | AH12: =Boat!C14 -> 0 | AJ12: =Water!C17 -> 145 | AK12: =Water!E17 -> 174.58 | AL12: =Water!G17 -> 112.694 | AM12: =Boat!E14 -> 0 | AO12: =Gas!C17 -> 1743.7 | AP12: =Gas!E17 -> 388.5 | AQ12: =Gas!G17 -> 100.5 | AR12: =Boat!G14 -> 0 | AS12: =Elect!BT16 -> 156
A13: Cairo at The First Residence | B13: =B12+1 -> 12 | C13: 8 | D13: 2022 | F13: =Elect!J17 -> 5252 | G13: =Elect!K17 -> 5328 | H13: =Elect!Q17 -> 570 | I13: =Elect!S17 -> 143 | J13: =Elect!U17 -> 247 | K13: =Elect!W17 -> 2327.23 | L13: =Elect!Y17 -> 0 | M13: =Elect!AA17 -> 0 | N13: =Elect!AC17 -> 0 | O13: =Elect!AE17 -> 13.25 | P13: =Elect!AG17 -> 12.19 | Q13: =Elect!AI17 -> 160.59 | R13: =Elect!AK17 -> 2522.27 | S13: =Elect!AM17 -> 126.14 | T13: =Elect!AP17 -> 116.775 | U13: =Elect!AR17 -> 195 | V13: =Elect!AT17 -> 98 | W13: =Elect!AV17 -> 49 | X13: =Elect!AX17 -> 903 | Y13: =Elect!AZ17 -> 10 | Z13: =Elect!BB17 -> 5642 | AA13: =Elect!BD17 -> 129 | AB13: =Elect!BF17 -> 50 | AC13: =Elect!BH17 -> 6375.45 | AD13: =Elect!BL17 -> 363 | AE13: =Elect!BN17 -> 1101 | AF13: =Elect!BP17 -> 138 | AG13: =Elect!BR17 -> 146 | AH13: =Boat!C15 -> 0 | AJ13: =Water!C18 -> 143.84 | AK13: =Water!E18 -> 173.42 | AL13: =Water!G18 -> 110.258 | AM13: =Boat!E15 -> 0 | AO13: =Gas!C18 -> 1753.028 | AP13: =Gas!E18 -> 384.44 | AQ13: =Gas!G18 -> 101.1 | AR13: =Boat!G15 -> 0 | AS13: =Elect!BT17 -> 199
A14: Cairo at The First Residence | B14: =B13+1 -> 13 | C14: 8 | D14: 2022 | F14: =Elect!J18 -> 8745 | G14: =Elect!K18 -> 4493 | H14: =Elect!Q18 -> 570 | I14: =Elect!S18 -> 148 | J14: =Elect!U18 -> 260 | K14: =Elect!W18 -> 1963.65 | L14: =Elect!Y18 -> 0 | M14: =Elect!AA18 -> 0 | N14: =Elect!AC18 -> 0 | O14: =Elect!AE18 -> 13.25 | P14: =Elect!AG18 -> 12.19 | Q14: =Elect!AI18 -> 130.91 | R14: =Elect!AK18 -> 2097.74 | S14: =Elect!AM18 -> 104.94 | T14: =Elect!AP18 -> 99.9 | U14: =Elect!AR18 -> 180 | V14: =Elect!AT18 -> 63 | W14: =Elect!AV18 -> 38 | X14: =Elect!AX18 -> 740 | Y14: =Elect!AZ18 -> 11 | Z14: =Elect!BB18 -> 5114 | AA14: =Elect!BD18 -> 161 | AB14: =Elect!BF18 -> 50 | AC14: =Elect!BH18 -> 4555.6 | AD14: =Elect!BL18 -> 256 | AE14: =Elect!BN18 -> 769 | AF14: =Elect!BP18 -> 103 | AG14: =Elect!BR18 -> 104 | AH14: =Boat!C16 -> 0 | AJ14: =Water!C19 -> 111.36 | AK14: =Water!E19 -> 133.4 | AL14: =Water!G19 -> 65.308 | AM14: =Boat!E16 -> 0 | AO14: =Gas!C19 -> 1507.532 | AP14: =Gas!E19 -> 374.36 | AQ14: =Gas!G19 -> 80.4 | AR14: =Boat!G16 -> 0 | AS14: =Elect!BT18 -> 212
... A32: Cairo at The First Residence | B32: =B31+1 -> 31 | C32: 8 | D32: 2022 | F32: =Elect!J36 -> 6371.6667 | G32: =Elect!K36 -> 4328.6667 | H32: =Elect!Q36 -> 480 | I32: =Elect!S36 -> 143.33333 | J32: =Elect!U36 -> 253.66667 | K32: =Elect!W36 -> 2865.18 | L32: =Elect!Y36 -> 0 | M32: =Elect!AA36 -> 0 | N32: =Elect!AC36 -> 0 | O32: =Elect!AE36 -> 0 | P32: =Elect!AG36 -> 12.19 | Q32: =Elect!AI36 -> 264.29333 | R32: =Elect!AK36 -> 2274.4067 | S32: =Elect!AM36 -> 114.65667 | T32: =Elect!AP36 -> 163.8 | U32: =Elect!AR36 -> 200.66667 | V32: =Elect!AT36 -> 137.33333 | W32: =Elect!AV36 -> 42.333333 | X32: =Elect!AX36 -> 864.66667 | Y32: =Elect!AZ36 -> 57 | Z32: =Elect!BB36 -> 4906.6667 | AA32: =Elect!BD36 -> 231 | AB32: =Elect!BF36 -> 47 | AC32: =Elect!BH36 -> 5487.9 | AD32: =Elect!BL36 -> 204.66667 | AE32: =Elect!BN36 -> 996.33333 | AF32: =Elect!BP36 -> 21.666667 | AG32: =Elect!BR36 -> 156 | AH32: =Boat!C34 -> 0 | AJ32: =Water!C37 -> 110.2 | AK32: =Water!E37 -> 133.4 | AL32: =Water!G37 -> 127.02 | AM32: =Boat!E34 -> 0 | AO32: =Gas!C37 -> 1862.42 | AP32: =Gas!E37 -> 515.9 | AQ32: =Gas!G37 -> 130 | AR32: =Boat!G34 -> 0 | AS32: =Elect!BT36 -> 250

Sheet Boat
B1: Electricity | D1: Water | F1: Gas
B2: Read | C2: Cons | D2: Read | E2: Cons | F2: Read | G2: Cons
B3: 0 | D3: 0 | F3: 0
A4: 1 | B4: 0 | C4: =B4-B3 -> 0 | D4: 0 | E4: =D4-D3 -> 0 | F4: 0 | G4: =F4-F3 -> 0
A5: 2 | B5: 0 | C5: =B5-B4 -> 0 | D5: 0 | E5: =D5-D4 -> 0 | F5: 0 | G5: =F5-F4 -> 0
A6: 3 | B6: 0 | C6: =B6-B5 -> 0 | D6: 0 | E6: =D6-D5 -> 0 | F6: 0 | G6: =F6-F5 -> 0
A7: 4 | B7: 0 | C7: =B7-B6 -> 0 | D7: 0 | E7: =D7-D6 -> 0 | F7: 0 | G7: =F7-F6 -> 0
A8: 5 | B8: 0 | C8: =B8-B7 -> 0 | D8: 0 | E8: =D8-D7 -> 0 | F8: 0 | G8: =F8-F7 -> 0
A9: 6 | B9: 0 | C9: =B9-B8 -> 0 | D9: 0 | E9: =D9-D8 -> 0 | F9: 0 | G9: =F9-F8 -> 0
A10: 7 | B10: 0 | C10: =B10-B9 -> 0 | D10: 0 | E10: =D10-D9 -> 0 | F10: 0 | G10: =F10-F9 -> 0
A11: 8 | B11: 0 | C11: =B11-B10 -> 0 | D11: 0 | E11: =D11-D10 -> 0 | F11: 0 | G11: =F11-F10 -> 0
A12: 9 | B12: 0 | C12: =B12-B11 -> 0 | D12: 0 | E12: =D12-D11 -> 0 | F12: 0 | G12: =F12-F11 -> 0
A13: 10 | B13: 0 | C13: =B13-B12 -> 0 | D13: 0 | E13: =D13-D12 -> 0 | F13: 0 | G13: =F13-F12 -> 0
A14: 11 | B14: 0 | C14: =B14-B13 -> 0 | D14: 0 | E14: =D14-D13 -> 0 | F14: 0 | G14: =F14-F13 -> 0
A15: 12 | B15: 0 | C15: =B15-B14 -> 0 | D15: 0 | E15: =D15-D14 -> 0 | F15: 0 | G15: =F15-F14 -> 0
... A34: 31 | B34: 0 | C34: =B34-B33 -> 0 | D34: 0 | E34: =D34-D33 -> 0 | F34: 0 | G34: =F34-F33 -> 0
A35: Sum | C35: =SUM(C4:C34) -> 0 | E35: =SUM(E4:E34) -> 0 | G35: =SUM(G4:G34) -> 0

Sheet Water
A1: =Elect!A1 -> 44927 | T1: Main Water UP | V1: 4 | W1: Water Truck UP
A3: Day | E3: Water Incoming | I3: New casino | N3: Rooms Consumption | P3: Public Areas consumption | R3: Swimming pool | T3: No. of rooms | U3: Cons. Per occ. room | V3: No. of guest | W3: Cons. Per guest | X3: Total cost | Y3: L.E\ | Z3: L.E\
B4: Main water meter 1 | D4: Main water meter 2 | F4: Main water meter 3 | H4: Total Inc. | I4: Hot water | K4: Cold water | N4: Express Riser | O4: Consp. | P4: Read. | Q4: Cons. | R4: Read. | S4: Cons. | Y4: Room | Z4: Guest
B5: Counter | C5: Produc 58% | D5: Counter | E5: Produc 58% | F5: Counter | G5: Produc 58% | I5: Counter | K5: Counter
B6: 90625.917 | C6: =IF(B6>=B5,B6-B5,0)*10*0.58 -> 0 | D6: 14017.7 | E6: =IF(D6>=D5,D6-D5,0)*10*0.58 -> 0 | F6: 68296.583 | G6: =IF(F6>=F5,F6-F5,0)*0.58 -> 0 | I6: 322 | K6: 5583
A7: 1 | B7: 90654 | C7: =IF(B7>=B6,B7-B6,0)*10*0.58 -> 162.88333 | D7: 14043 | E7: =IF(D7>=D6,D7-D6,0)*10*0.58 -> 146.74 | F7: 68510 | G7: =IF(F7>=F6,F7-F6,0)*0.58 -> 123.78167 | H7: =C7+E7+G7 -> 433.405 | O7: =IF(N7>=N6,N7-N6,0) -> 0 | Q7: =(H7-O7)*0.58 -> 251.3749 | S7: =IF(R7-R6>0,R7-R6,0) -> 0 | T7: =Elect!BT6 -> 238 | U7: =H7/T7 -> 1.8210294 | V7: =Elect!BV6 -> 0 | W7: =H7/V7 -> #DIV/0! | X7: =H7*V1 -> 1733.62 | Y7: =IF(X7>0,X7/T7,0) -> 7.2841176 | Z7: 0
A8: 2 | B8: 90666 | C8: =IF(B8>=B7,B8-B7,0)*10*0.58 -> 69.6 | D8: 14058 | E8: =IF(D8>=D7,D8-D7,0)*10*0.58 -> 87 | F8: 68685 | G8: =IF(F8>=F7,F8-F7,0)*0.58 -> 101.5 | H8: =C8+E8+G8 -> 258.1 | O8: =IF(N8>=N7,N8-N7,0) -> 0 | Q8: =(H8-O8)*0.58 -> 149.698 | S8: =IF(R8-R7>0,R8-R7,0) -> 0 | T8: =Elect!BT7 -> 227 | U8: =H8/T8 -> 1.1370044 | V8: =Elect!BV7 -> 0 | W8: =H8/V8 -> #DIV/0! | X8: =H8*V1 -> 1032.4 | Y8: =IF(X8>0,X8/T8,0) -> 4.5480176 | Z8: =IF(X8>0,X8/V8,0) -> #DIV/0!
A9: 3 | B9: 90684 | C9: =IF(B9>=B8,B9-B8,0)*10*0.58 -> 104.4 | D9: 14080 | E9: =IF(D9>=D8,D9-D8,0)*10*0.58 -> 127.6 | F9: 68876 | G9: =IF(F9>=F8,F9-F8,0)*0.58 -> 110.78 | H9: =C9+E9+G9 -> 342.78 | O9: =IF(N9>=N8,N9-N8,0) -> 0 | Q9: =(H9-O9)*0.58 -> 198.8124 | S9: =IF(R9-R8>0,R9-R8,0) -> 0 | T9: =Elect!BT8 -> 213 | U9: =H9/T9 -> 1.6092958 | V9: =Elect!BV8 -> 0 | W9: =H9/V9 -> #DIV/0! | X9: =H9*V1 -> 1371.12 | Y9: =IF(X9>0,X9/T9,0) -> 6.4371831 | Z9: =IF(X9>0,X9/V9,0) -> #DIV/0!
A10: 4 | B10: 90700 | C10: =IF(B10>=B9,B10-B9,0)*10*0.58 -> 92.8 | D10: 14099 | E10: =IF(D10>=D9,D10-D9,0)*10*0.58 -> 110.2 | F10: 69063 | G10: =IF(F10>=F9,F10-F9,0)*0.58 -> 108.46 | H10: =C10+E10+G10 -> 311.46 | O10: =IF(N10>=N9,N10-N9,0) -> 0 | Q10: =(H10-O10)*0.58 -> 180.6468 | S10: =IF(R10-R9>0,R10-R9,0) -> 0 | T10: =Elect!BT9 -> 202 | U10: =H10/T10 -> 1.5418812 | V10: =Elect!BV9 -> 0 | W10: =H10/V10 -> #DIV/0! | X10: =H10*V1 -> 1245.84 | Y10: =IF(X10>0,X10/T10,0) -> 6.1675248 | Z10: =IF(X10>0,X10/V10,0) -> #DIV/0!
A11: 5 | B11: 90719 | C11: =IF(B11>=B10,B11-B10,0)*10*0.58 -> 110.2 | D11: 14120 | E11: =IF(D11>=D10,D11-D10,0)*10*0.58 -> 121.8 | F11: 69270 | G11: =IF(F11>=F10,F11-F10,0)*0.58 -> 120.06 | H11: =C11+E11+G11 -> 352.06 | O11: =IF(N11>=N10,N11-N10,0) -> 0 | Q11: =(H11-O11)*0.58 -> 204.1948 | S11: =IF(R11-R10>0,R11-R10,0) -> 0 | T11: =Elect!BT10 -> 196 | U11: =H11/T11 -> 1.7962245 | V11: =Elect!BV10 -> 0 | W11: =H11/V11 -> #DIV/0! | X11: =H11*V1 -> 1408.24 | Y11: =IF(X11>0,X11/T11,0) -> 7.184898 | Z11: =IF(X11>0,X11/V11,0) -> #DIV/0!
A12: 6 | B12: 90739 | C12: =IF(B12>=B11,B12-B11,0)*10*0.58 -> 116 | D12: 14144 | E12: =IF(D12>=D11,D12-D11,0)*10*0.58 -> 139.2 | F12: 69450 | G12: =IF(F12>=F11,F12-F11,0)*0.58 -> 104.4 | H12: =C12+E12+G12 -> 359.6 | O12: =IF(N12>=N11,N12-N11,0) -> 0 | Q12: =(H12-O12)*0.58 -> 208.568 | S12: =IF(R12-R11>0,R12-R11,0) -> 0 | T12: =Elect!BT11 -> 214 | U12: =H12/T12 -> 1.6803738 | V12: =Elect!BV11 -> 0 | W12: =H12/V12 -> #DIV/0! | X12: =H12*V1 -> 1438.4 | Y12: =IF(X12>0,X12/T12,0) -> 6.7214953 | Z12: =IF(X12>0,X12/V12,0) -> #DIV/0!
A13: 7 | B13: 90763 | C13: =IF(B13>=B12,B13-B12,0)*10*0.58 -> 139.2 | D13: 14173 | E13: =IF(D13>=D12,D13-D12,0)*10*0.58 -> 168.2 | F13: 69641 | G13: =IF(F13>=F12,F13-F12,0)*0.58 -> 110.78 | H13: =C13+E13+G13 -> 418.18 | O13: =IF(N13>=N12,N13-N12,0) -> 0 | Q13: =(H13-O13)*0.58 -> 242.5444 | S13: =IF(R13-R12>0,R13-R12,0) -> 0 | T13: =Elect!BT12 -> 254 | U13: =H13/T13 -> 1.646378 | V13: =Elect!BV12 -> 0 | W13: =H13/V13 -> #DIV/0! | X13: =H13*V1 -> 1672.72 | Y13: =IF(X13>0,X13/T13,0) -> 6.5855118 | Z13: =IF(X13>0,X13/V13,0) -> #DIV/0!
A14: 8 | B14: 90787 | C14: =IF(B14>=B13,B14-B13,0)*10*0.58 -> 139.2 | D14: 14203 | E14: =IF(D14>=D13,D14-D13,0)*10*0.58 -> 174 | F14: 69835 | G14: =IF(F14>=F13,F14-F13,0)*0.58 -> 112.52 | H14: =C14+E14+G14 -> 425.72 | O14: =IF(N14>=N13,N14-N13,0) -> 0 | Q14: =(H14-O14)*0.58 -> 246.9176 | S14: =IF(R14-R13>0,R14-R13,0) -> 0 | T14: =Elect!BT13 -> 239 | U14: =H14/T14 -> 1.7812552 | V14: =Elect!BV13 -> 0 | W14: =H14/V14 -> #DIV/0! | X14: =H14*V1 -> 1702.88 | Y14: =IF(X14>0,X14/T14,0) -> 7.1250209 | Z14: =IF(X14>0,X14/V14,0) -> #DIV/0!
A15: 9 | B15: 90813 | C15: =IF(B15>=B14,B15-B14,0)*10*0.58 -> 150.8 | D15: 14234 | E15: =IF(D15>=D14,D15-D14,0)*10*0.58 -> 179.8 | F15: 70026 | G15: =IF(F15>=F14,F15-F14,0)*0.58 -> 110.78 | H15: =C15+E15+G15 -> 441.38 | O15: =IF(N15>=N14,N15-N14,0) -> 0 | Q15: =(H15-O15)*0.58 -> 256.0004 | S15: =IF(R15-R14>0,R15-R14,0) -> 0 | T15: =Elect!BT14 -> 220 | U15: =H15/T15 -> 2.0062727 | V15: =Elect!BV14 -> 0 | W15: =H15/V15 -> #DIV/0! | X15: =H15*V1 -> 1765.52 | Y15: =IF(X15>0,X15/T15,0) -> 8.0250909 | Z15: =IF(X15>0,X15/V15,0) -> #DIV/0!
A16: 10 | B16: 90837 | C16: =IF(B16>=B15,B16-B15,0)*10*0.58 -> 139.2 | D16: 14263 | E16: =IF(D16>=D15,D16-D15,0)*10*0.58 -> 168.2 | F16: 70208 | G16: =IF(F16>=F15,F16-F15,0)*0.58 -> 105.56 | H16: =C16+E16+G16 -> 412.96 | O16: =IF(N16>=N15,N16-N15,0) -> 0 | Q16: =(H16-O16)*0.58 -> 239.5168 | S16: =IF(R16-R15>0,R16-R15,0) -> 0 | T16: =Elect!BT15 -> 185 | U16: =H16/T16 -> 2.2322162 | V16: =Elect!BV15 -> 0 | W16: =H16/V16 -> #DIV/0! | X16: =H16*V1 -> 1651.84 | Y16: =IF(X16>0,X16/T16,0) -> 8.9288649 | Z16: =IF(X16>0,X16/V16,0) -> #DIV/0!
A17: 11 | B17: 90862 | C17: =IF(B17>=B16,B17-B16,0)*10*0.58 -> 145 | D17: 14293.1 | E17: =IF(D17>=D16,D17-D16,0)*10*0.58 -> 174.58 | F17: 70402.3 | G17: =IF(F17>=F16,F17-F16,0)*0.58 -> 112.694 | H17: =C17+E17+G17 -> 432.274 | O17: =IF(N17>=N16,N17-N16,0) -> 0 | Q17: =(H17-O17)*0.58 -> 250.71892 | S17: =IF(R17-R16>0,R17-R16,0) -> 0 | T17: =Elect!BT16 -> 156 | U17: =H17/T17 -> 2.7709872 | V17: =Elect!BV16 -> 0 | W17: =H17/V17 -> #DIV/0! | X17: =H17*V1 -> 1729.096 | Y17: =IF(X17>0,X17/T17,0) -> 11.083949 | Z17: =IF(X17>0,X17/V17,0) -> #DIV/0!
A18: 12 | B18: 90886.8 | C18: =IF(B18>=B17,B18-B17,0)*10*0.58 -> 143.84 | D18: 14323 | E18: =IF(D18>=D17,D18-D17,0)*10*0.58 -> 173.42 | F18: 70592.4 | G18: =IF(F18>=F17,F18-F17,0)*0.58 -> 110.258 | H18: =C18+E18+G18 -> 427.518 | O18: =IF(N18>=N17,N18-N17,0) -> 0 | Q18: =(H18-O18)*0.58 -> 247.96044 | S18: =IF(R18-R17>0,R18-R17,0) -> 0 | T18: =Elect!BT17 -> 199 | U18: =H18/T18 -> 2.1483317 | V18: =Elect!BV17 -> 0 | W18: =H18/V18 -> #DIV/0! | X18: =H18*V1 -> 1710.072 | Y18: =IF(X18>0,X18/T18,0) -> 8.5933266 | Z18: =IF(X18>0,X18/V18,0) -> #DIV/0!
A19: 13 | B19: 90906 | C19: =IF(B19>=B18,B19-B18,0)*10*0.58 -> 111.36 | D19: 14346 | E19: =IF(D19>=D18,D19-D18,0)*10*0.58 -> 133.4 | F19: 70705 | G19: =IF(F19>=F18,F19-F18,0)*0.58 -> 65.308 | H19: =C19+E19+G19 -> 310.068 | O19: =IF(N19>=N18,N19-N18,0) -> 0 | Q19: =(H19-O19)*0.58 -> 179.83944 | S19: =IF(R19-R18>0,R19-R18,0) -> 0 | T19: =Elect!BT18 -> 212 | U19: =H19/T19 -> 1.4625849 | V19: =Elect!BV18 -> 0 | W19: =H19/V19 -> #DIV/0! | X19: =H19*V1 -> 1240.272 | Y19: =IF(X19>0,X19/T19,0) -> 5.8503396 | Z19: =IF(X19>0,X19/V19,0) -> #DIV/0!
A20: 14 | B20: 90929 | C20: =IF(B20>=B19,B20-B19,0)*10*0.58 -> 133.4 | D20: 14374 | E20: =IF(D20>=D19,D20-D19,0)*10*0.58 -> 162.4 | F20: 70950 | G20: =IF(F20>=F19,F20-F19,0)*0.58 -> 142.1 | H20: =C20+E20+G20 -> 437.9 | O20: =IF(N20>=N19,N20-N19,0) -> 0 | Q20: =(H20-O20)*0.58 -> 253.982 | S20: =IF(R20-R19>0,R20-R19,0) -> 0 | T20: =Elect!BT19 -> 238 | U20: =H20/T20 -> 1.839916 | V20: =Elect!BV19 -> 0 | W20: =H20/V20 -> #DIV/0! | X20: =H20*V1 -> 1751.6 | Y20: =IF(X20>0,X20/T20,0) -> 7.3596639 | Z20: =IF(X20>0,X20/V20,0) -> #DIV/0!
A21: 15 | B21: 90951 | C21: =IF(B21>=B20,B21-B20,0)*10*0.58 -> 127.6 | D21: 14399 | E21: =IF(D21>=D20,D21-D20,0)*10*0.58 -> 145 | F21: 71150 | G21: =IF(F21>=F20,F21-F20,0)*0.58 -> 116 | H21: =C21+E21+G21 -> 388.6 | O21: =IF(N21>=N20,N21-N20,0) -> 0 | Q21: =(H21-O21)*0.58 -> 225.388 | S21: =IF(R21-R20>0,R21-R20,0) -> 0 | T21: =Elect!BT20 -> 229 | U21: =H21/T21 -> 1.6969432 | V21: =Elect!BV20 -> 0 | W21: =H21/V21 -> #DIV/0! | X21: =H21*V1 -> 1554.4 | Y21: =IF(X21>0,X21/T21,0) -> 6.7877729 | Z21: =IF(X21>0,X21/V21,0) -> #DIV/0!
A22: 16 | B22: 90966 | C22: =IF(B22>=B21,B22-B21,0)*10*0.58 -> 87 | D22: 14417 | E22: =IF(D22>=D21,D22-D21,0)*10*0.58 -> 104.4 | F22: 71347 | G22: =IF(F22>=F21,F22-F21,0)*0.58 -> 114.26 | H22: =C22+E22+G22 -> 305.66 | O22: =IF(N22>=N21,N22-N21,0) -> 0 | Q22: =(H22-O22)*0.58 -> 177.2828 | S22: =IF(R22-R21>0,R22-R21,0) -> 0 | T22: =Elect!BT21 -> 213 | U22: =H22/T22 -> 1.4350235 | V22: =Elect!BV21 -> 0 | W22: =H22/V22 -> #DIV/0! | X22: =H22*V1 -> 1222.64 | Y22: =IF(X22>0,X22/T22,0) -> 5.7400939 | Z22: =IF(X22>0,X22/V22,0) -> #DIV/0!
A23: 17 | B23: 90983 | C23: =IF(B23>=B22,B23-B22,0)*10*0.58 -> 98.6 | D23: 14436 | E23: =IF(D23>=D22,D23-D22,0)*10*0.58 -> 110.2 | F23: 71548 | G23: =IF(F23>=F22,F23-F22,0)*0.58 -> 116.58 | H23: =C23+E23+G23 -> 325.38 | O23: =IF(N23>=N22,N23-N22,0) -> 0 | Q23: =(H23-O23)*0.58 -> 188.7204 | S23: =IF(R23-R22>0,R23-R22,0) -> 0 | T23: =Elect!BT22 -> 198 | U23: =H23/T23 -> 1.6433333 | V23: =Elect!BV22 -> 0 | W23: =H23/V23 -> #DIV/0! | X23: =H23*V1 -> 1301.52 | Y23: =IF(X23>0,X23/T23,0) -> 6.5733333 | Z23: =IF(X23>0,X23/V23,0) -> #DIV/0!
A24: 18 | B24: 91002 | C24: =IF(B24>=B23,B24-B23,0)*10*0.58 -> 110.2 | D24: 14457 | E24: =IF(D24>=D23,D24-D23,0)*10*0.58 -> 121.8 | F24: 71780 | G24: =IF(F24>=F23,F24-F23,0)*0.58 -> 134.56 | H24: =C24+E24+G24 -> 366.56 | O24: =IF(N24>=N23,N24-N23,0) -> 0 | Q24: =(H24-O24)*0.58 -> 212.6048 | S24: =IF(R24-R23>0,R24-R23,0) -> 0 | T24: =Elect!BT23 -> 170 | U24: =H24/T24 -> 2.1562353 | V24: =Elect!BV23 -> 0 | W24: =H24/V24 -> #DIV/0! | X24: =H24*V1 -> 1466.24 | Y24: =IF(X24>0,X24/T24,0) -> 8.6249412 | Z24: =IF(X24>0,X24/V24,0) -> #DIV/0!
A25: 19 | B25: 91016 | C25: =IF(B25>=B24,B25-B24,0)*10*0.58 -> 81.2 | D25: 14473 | E25: =IF(D25>=D24,D25-D24,0)*10*0.58 -> 92.8 | F25: 71957 | G25: =IF(F25>=F24,F25-F24,0)*0.58 -> 102.66 | H25: =C25+E25+G25 -> 276.66 | O25: =IF(N25>=N24,N25-N24,0) -> 0 | Q25: =(H25-O25)*0.58 -> 160.4628 | S25: =IF(R25-R24>0,R25-R24,0) -> 0 | T25: =Elect!BT24 -> 206 | U25: =H25/T25 -> 1.3430097 | V25: =Elect!BV24 -> 0 | W25: =H25/V25 -> #DIV/0! | X25: =H25*V1 -> 1106.64 | Y25: =IF(X25>0,X25/T25,0) -> 5.3720388 | Z25: =IF(X25>0,X25/V25,0) -> #DIV/0!
A26: 20 | B26: 91032 | C26: =IF(B26>=B25,B26-B25,0)*10*0.58 -> 92.8 | D26: 14491 | E26: =IF(D26>=D25,D26-D25,0)*10*0.58 -> 104.4 | F26: 72155 | G26: =IF(F26>=F25,F26-F25,0)*0.58 -> 114.84 | H26: =C26+E26+G26 -> 312.04 | O26: =IF(N26>=N25,N26-N25,0) -> 0 | Q26: =(H26-O26)*0.58 -> 180.9832 | S26: =IF(R26-R25>0,R26-R25,0) -> 0 | T26: =Elect!BT25 -> 228 | U26: =H26/T26 -> 1.3685965 | V26: =Elect!BV25 -> 0 | W26: =H26/V26 -> #DIV/0! | X26: =H26*V1 -> 1248.16 | Y26: =IF(X26>0,X26/T26,0) -> 5.474386 | Z26: =IF(X26>0,X26/V26,0) -> #DIV/0!
A27: 21 | B27: 91050 | C27: =IF(B27>=B26,B27-B26,0)*10*0.58 -> 104.4 | D27: 14510 | E27: =IF(D27>=D26,D27-D26,0)*10*0.58 -> 110.2 | F27: 72376 | G27: =IF(F27>=F26,F27-F26,0)*0.58 -> 128.18 | H27: =C27+E27+G27 -> 342.78 | O27: =IF(N27>=N26,N27-N26,0) -> 0 | Q27: =(H27-O27)*0.58 -> 198.8124 | S27: =IF(R27-R26>0,R27-R26,0) -> 0 | T27: =Elect!BT26 -> 248 | U27: =H27/T27 -> 1.3821774 | V27: =Elect!BV26 -> 0 | W27: =H27/V27 -> #DIV/0! | X27: =H27*V1 -> 1371.12 | Y27: =IF(X27>0,X27/T27,0) -> 5.5287097 | Z27: =IF(X27>0,X27/V27,0) -> #DIV/0!
A28: 22 | B28: 91064 | C28: =IF(B28>=B27,B28-B27,0)*10*0.58 -> 81.2 | D28: 14527 | E28: =IF(D28>=D27,D28-D27,0)*10*0.58 -> 98.6 | F28: 72577 | G28: =IF(F28>=F27,F28-F27,0)*0.58 -> 116.58 | H28: =C28+E28+G28 -> 296.38 | O28: =IF(N28>=N27,N28-N27,0) -> 0 | Q28: =(H28-O28)*0.58 -> 171.9004 | S28: =IF(R28-R27>0,R28-R27,0) -> 0 | T28: =Elect!BT27 -> 225 | U28: =H28/T28 -> 1.3172444 | V28: =Elect!BV27 -> 0 | W28: =H28/V28 -> #DIV/0! | X28: =H28*V1 -> 1185.52 | Y28: =IF(X28>0,X28/T28,0) -> 5.2689778 | Z28: =IF(X28>0,X28/V28,0) -> #DIV/0!
A29: 23 | B29: 91081 | C29: =IF(B29>=B28,B29-B28,0)*10*0.58 -> 98.6 | D29: 14545 | E29: =IF(D29>=D28,D29-D28,0)*10*0.58 -> 104.4 | F29: 72772 | G29: =IF(F29>=F28,F29-F28,0)*0.58 -> 113.1 | H29: =C29+E29+G29 -> 316.1 | O29: =IF(N29>=N28,N29-N28,0) -> 0 | Q29: =(H29-O29)*0.58 -> 183.338 | S29: =IF(R29-R28>0,R29-R28,0) -> 0 | T29: =Elect!BT28 -> 201 | U29: =H29/T29 -> 1.5726368 | V29: =Elect!BV28 -> 0 | W29: =H29/V29 -> #DIV/0! | X29: =H29*V1 -> 1264.4 | Y29: =IF(X29>0,X29/T29,0) -> 6.2905473 | Z29: =IF(X29>0,X29/V29,0) -> #DIV/0!
A30: 24 | B30: 91098 | C30: =IF(B30>=B29,B30-B29,0)*10*0.58 -> 98.6 | D30: 14565 | E30: =IF(D30>=D29,D30-D29,0)*10*0.58 -> 116 | F30: 72981 | G30: =IF(F30>=F29,F30-F29,0)*0.58 -> 121.22 | H30: =C30+E30+G30 -> 335.82 | O30: =IF(N30>=N29,N30-N29,0) -> 0 | Q30: =(H30-O30)*0.58 -> 194.7756 | S30: =IF(R30-R29>0,R30-R29,0) -> 0 | T30: =Elect!BT29 -> 196 | U30: =H30/T30 -> 1.7133673 | V30: =Elect!BV29 -> 0 | W30: =H30/V30 -> #DIV/0! | X30: =H30*V1 -> 1343.28 | Y30: =IF(X30>0,X30/T30,0) -> 6.8534694 | Z30: =IF(X30>0,X30/V30,0) -> #DIV/0!
A31: 25 | B31: 91113 | C31: =IF(B31>=B30,B31-B30,0)*10*0.58 -> 87 | D31: 14587 | E31: =IF(D31>=D30,D31-D30,0)*10*0.58 -> 127.6 | F31: 73191 | G31: =IF(F31>=F30,F31-F30,0)*0.58 -> 121.8 | H31: =C31+E31+G31 -> 336.4 | O31: =IF(N31>=N30,N31-N30,0) -> 0 | Q31: =(H31-O31)*0.58 -> 195.112 | S31: =IF(R31-R30>0,R31-R30,0) -> 0 | T31: =Elect!BT30 -> 143 | U31: =H31/T31 -> 2.3524476 | V31: =Elect!BV30 -> 0 | W31: =H31/V31 -> #DIV/0! | X31: =H31*V1 -> 1345.6 | Y31: =IF(X31>0,X31/T31,0) -> 9.4097902 | Z31: =IF(X31>0,X31/V31,0) -> #DIV/0!
A32: 26 | B32: 91135 | C32: =IF(B32>=B31,B32-B31,0)*10*0.58 -> 127.6 | D32: 14601 | E32: =IF(D32>=D31,D32-D31,0)*10*0.58 -> 81.2 | F32: 73408 | G32: =IF(F32>=F31,F32-F31,0)*0.58 -> 125.86 | H32: =C32+E32+G32 -> 334.66 | O32: =IF(N32>=N31,N32-N31,0) -> 0 | Q32: =(H32-O32)*0.58 -> 194.1028 | S32: =IF(R32-R31>0,R32-R31,0) -> 0 | T32: =Elect!BT31 -> 163 | U32: =H32/T32 -> 2.0531288 | V32: =Elect!BV31 -> 0 | W32: =H32/V32 -> #DIV/0! | X32: =H32*V1 -> 1338.64 | Y32: =IF(X32>0,X32/T32,0) -> 8.2125153 | Z32: =IF(X32>0,X32/V32,0) -> #DIV/0!
A33: 27 | B33: 91145 | C33: =IF(B33>=B32,B33-B32,0)*10*0.58 -> 58 | D33: 14619 | E33: =IF(D33>=D32,D33-D32,0)*10*0.58 -> 104.4 | F33: 73623 | G33: =IF(F33>=F32,F33-F32,0)*0.58 -> 124.7 | H33: =C33+E33+G33 -> 287.1 | O33: =IF(N33>=N32,N33-N32,0) -> 0 | Q33: =(H33-O33)*0.58 -> 166.518 | S33: =IF(R33-R32>0,R33-R32,0) -> 0 | T33: =Elect!BT32 -> 207 | U33: =H33/T33 -> 1.3869565 | V33: =Elect!BV32 -> 0 | W33: =H33/V33 -> #DIV/0! | X33: =H33*V1 -> 1148.4 | Y33: =IF(X33>0,X33/T33,0) -> 5.5478261 | Z33: =IF(X33>0,X33/V33,0) -> #DIV/0!
A34: 28 | B34: 91162 | C34: =IF(B34>=B33,B34-B33,0)*10*0.58 -> 98.6 | D34: 14638 | E34: =IF(D34>=D33,D34-D33,0)*10*0.58 -> 110.2 | F34: 73851 | G34: =IF(F34>=F33,F34-F33,0)*0.58 -> 132.24 | H34: =C34+E34+G34 -> 341.04 | O34: =IF(N34>=N33,N34-N33,0) -> 0 | Q34: =(H34-O34)*0.58 -> 197.8032 | S34: =IF(R34-R33>0,R34-R33,0) -> 0 | T34: =Elect!BT33 -> 225 | U34: =H34/T34 -> 1.5157333 | V34: =Elect!BV33 -> 0 | W34: =H34/V34 -> #DIV/0! | X34: =H34*V1 -> 1364.16 | Y34: =IF(X34>0,X34/T34,0) -> 6.0629333 | Z34: =IF(X34>0,X34/V34,0) -> #DIV/0!
A35: 29 | B35: 91177 | C35: =IF(B35>=B34,B35-B34,0)*10*0.58 -> 87 | D35: 14655 | E35: =IF(D35>=D34,D35-D34,0)*10*0.58 -> 98.6 | F35: 74035 | G35: =IF(F35>=F34,F35-F34,0)*0.58 -> 106.72 | H35: =C35+E35+G35 -> 292.32 | O35: =IF(N35>=N34,N35-N34,0) -> 0 | Q35: =(H35-O35)*0.58 -> 169.5456 | S35: =IF(R35-R34>0,R35-R34,0) -> 0 | T35: =Elect!BT34 -> 241 | U35: =H35/T35 -> 1.2129461 | V35: =Elect!BV34 -> 0 | W35: =H35/V35 -> #DIV/0! | X35: =H35*V1 -> 1169.28 | Y35: =IF(X35>0,X35/T35,0) -> 4.8517842 | Z35: =IF(X35>0,X35/V35,0) -> #DIV/0!
A36: 30 | B36: 91198 | C36: =IF(B36>=B35,B36-B35,0)*10*0.58 -> 121.8 | D36: 14680 | E36: =IF(D36>=D35,D36-D35,0)*10*0.58 -> 145 | F36: 74220 | G36: =IF(F36>=F35,F36-F35,0)*0.58 -> 107.3 | H36: =C36+E36+G36 -> 374.1 | I36: 331 | K36: 5727 | O36: =IF(N36>=N35,N36-N35,0) -> 0 | Q36: =(H36-O36)*0.58 -> 216.978 | S36: =IF(R36-R35>0,R36-R35,0) -> 0 | T36: =Elect!BT35 -> 250 | U36: =H36/T36 -> 1.4964 | V36: =Elect!BV35 -> 0 | W36: =H36/V36 -> #DIV/0! | X36: =H36*V1 -> 1496.4 | Y36: =IF(X36>0,X36/T36,0) -> 5.9856 | Z36: =IF(X36>0,X36/V36,0) -> #DIV/0!
A37: 31 | B37: 91217 | C37: =IF(B37>=B36,B37-B36,0)*10*0.58 -> 110.2 | D37: 14703 | E37: =IF(D37>=D36,D37-D36,0)*10*0.58 -> 133.4 | F37: 74439 | G37: =IF(F37>=F36,F37-F36,0)*0.58 -> 127.02 | H37: =C37+E37+G37 -> 370.62 | O37: =IF(N37>=N36,N37-N36,0) -> 0 | Q37: =(H37-O37)*0.58 -> 214.9596 | S37: =IF(R37-R36>0,R37-R36,0) -> 0 | T37: =Elect!BT36 -> 250 | U37: =H37/T37 -> 1.48248 | V37: =Elect!BV36 -> 0 | W37: =H37/V37 -> #DIV/0! | X37: =H37*V7 -> 0 | Y37: =IF(X37>0,X37/T37,0) -> 0 | Z37: =IF(X37>0,X37/V37,0) -> 0
A38: MTD | C38: =SUM(C7:C37) -> 3428.2833 | E38: =SUM(E7:E37) -> 3974.74 | G38: =SUM(G7:G37) -> 3562.6017 | H38: =SUM(H7:H37) -> 10965.625 | O38: =SUM(O7:O36) -> 0 | Q38: =SUM(Q7:Q34) -> 5758.5793 | S38: =SUM(S7:S34) -> 0 | T38: =SUM(T7:T36) -> 6336 | U38: =IF(H38>0,H38/T38,0) -> 1.7306858 | V38: =SUM(V7:V36) -> 0 | W38: =IF(H38>0,H38/V38,0) -> #DIV/0! | X38: =SUM(X7:X36) -> 42380.02 | Y38: =IF(X38>0,X38/T38,0) -> 6.6887658 | Z38: =IF(X38>0,X38/V38,0) -> #DIV/0!
A39: AVER. Act | C39: =C38/B48 -> 114.27611 | E39: =E38/B48 -> 132.49133 | G39: =G38/B48 -> 118.75339 | H39: =H38/B48 -> 365.52083 | O39: =O38/B48 -> 0 | Q39: =Q38/B48 -> 191.95264 | S39: =S38/C48 -> #DIV/0! | T39: =T38/B48 -> 211.2 | U39: =IF(H39>0,H39/T39,0) -> 1.7306858 | V39: =V38/B48 -> 0 | W39: =IF(H39>0,H39/V39,0) -> #DIV/0! | X39: =X38/B48 -> 1412.6673 | Y39: =IF(X39>0,X39/T39,0) -> 6.6887658 | Z39: =IF(X39>0,X39/V39,0) -> #DIV/0!
A40: TOTAL Budget | T40: =YTD!Q2341 -> 0 | U40: =IF(#REF!>0,#REF!/T40,0) -> #REF! | V40: =YTD!Q2342 -> 0 | W40: =IF(#REF!>0,#REF!/V40,0) -> #REF! | X40: =YTD!Q2346 -> 0 | Y40: =IF(X40>0,X40/T40,0) -> 0 | Z40: =IF(X40>0,X40/V40,0) -> 0
A41: Budget MTD | T41: =T42*C48 -> #VALUE! | U41: =IF(#REF!>0,#REF!/T41,0) -> #REF! | V41: =V42*C48 -> #VALUE! | W41: =IF(#REF!>0,#REF!/V41,0) -> #REF! | X41: =#REF!*5.62 -> #REF! | Y41: =IF(X41>0,X41/T41,0) -> #REF! | Z41: =IF(X41>0,X41/V41,0) -> #REF!
...

Sheet Gas
A1: =Elect!A1 -> 44927 | E1: Gas | H1: Gas UP | J1: 3.9
A4: NO. | B4: Main Gas Flow Meter | D4: Laundry Gas Flow Meter | F4: Grumandiz Gas Flow Meter | H4: Plant Room Gas Share Cost | I4: Hotel Consumption Cost | J4: La Grumandiz Cost | K4: Total Natural Gas Consumption
B5: Read | C5: Cons | D5: Read | E5: Cons | F5: Read | G5: Cons | H5: LE/DAY | I5: LE/DAY | J5: LE/DAY | K5: Cons
B6: 8451913.6 | C6: =IF(B6>=B5,B6-B5,0)*1.06 -> 0 | D6: 614831.14 | E6: =IF(D6>=D5,D6-D5,0)*0.7 -> 0 | F6: 632071.73 | G6: =IF(F6>=F5,F6-F5,0) -> 0 | K6: =C6+E6 -> 0
A7: 1 | B7: 8455243 | C7: =IF(B7>=B6,B7-B6,0)*1.06 -> 3529.1817 | D7: 615553 | E7: =IF(D7>=D6,D7-D6,0)*0.7 -> 505.30278 | F7: 632194 | G7: =IF(F7>=F6,F7-F6,0) -> 122.26852 | H7: =(E7*0.55)*1.61 -> 447.44561 | I7: =C7*J1 -> 13763.809 | J7: =G7*J1 -> 476.84722 | K7: =C7+E7 -> 4034.4844
A8: 2 | B8: 8456774 | C8: =IF(B8>=B7,B8-B7,0)*1.06 -> 1622.86 | D8: 616044 | E8: =IF(D8>=D7,D8-D7,0)*0.7 -> 343.7 | F8: 632269 | G8: =IF(F8>=F7,F8-F7,0) -> 75 | H8: =(E8*0.55)*1.61 -> 304.34635 | I8: =C8*J1 -> 6329.154 | J8: =G8*J1 -> 292.5 | K8: =C8+E8 -> 1966.56
A9: 3 | B9: 8458394 | C9: =IF(B9>=B8,B9-B8,0)*1.06 -> 1717.2 | D9: 616591 | E9: =IF(D9>=D8,D9-D8,0)*0.7 -> 382.9 | F9: 632364 | G9: =IF(F9>=F8,F9-F8,0) -> 95 | H9: =(E9*0.55)*1.61 -> 339.05795 | I9: =C9*J1 -> 6697.08 | J9: =G9*J1 -> 370.5 | K9: =C9+E9 -> 2100.1
A10: 4 | B10: 8460180 | C10: =IF(B10>=B9,B10-B9,0)*1.06 -> 1893.16 | D10: 617132 | E10: =IF(D10>=D9,D10-D9,0)*0.7 -> 378.7 | F10: 632468 | G10: =IF(F10>=F9,F10-F9,0) -> 104 | H10: =(E10*0.55)*1.61 -> 335.33885 | I10: =C10*J1 -> 7383.324 | J10: =G10*J1 -> 405.6 | K10: =C10+E10 -> 2271.86
A11: 5 | B11: 8461649 | C11: =IF(B11>=B10,B11-B10,0)*1.06 -> 1557.14 | D11: 617727 | E11: =IF(D11>=D10,D11-D10,0)*0.7 -> 416.5 | F11: 632559 | G11: =IF(F11>=F10,F11-F10,0) -> 91 | H11: =(E11*0.55)*1.61 -> 368.81075 | I11: =C11*J1 -> 6072.846 | J11: =G11*J1 -> 354.9 | K11: =C11+E11 -> 1973.64
A12: 6 | B12: 8463299 | C12: =IF(B12>=B11,B12-B11,0)*1.06 -> 1749 | D12: 618241 | E12: =IF(D12>=D11,D12-D11,0)*0.7 -> 359.8 | F12: 632642 | G12: =IF(F12>=F11,F12-F11,0) -> 83 | H12: =(E12*0.55)*1.61 -> 318.6029 | I12: =C12*J1 -> 6821.1 | J12: =G12*J1 -> 323.7 | K12: =C12+E12 -> 2108.8
A13: 7 | B13: 8464878 | C13: =IF(B13>=B12,B13-B12,0)*1.06 -> 1673.74 | D13: 618818 | E13: =IF(D13>=D12,D13-D12,0)*0.7 -> 403.9 | F13: 632748 | G13: =IF(F13>=F12,F13-F12,0) -> 106 | H13: =(E13*0.55)*1.61 -> 357.65345 | I13: =C13*J1 -> 6527.586 | J13: =G13*J1 -> 413.4 | K13: =C13+E13 -> 2077.64
A14: 8 | B14: 8466522 | C14: =IF(B14>=B13,B14-B13,0)*1.06 -> 1742.64 | D14: 619380 | E14: =IF(D14>=D13,D14-D13,0)*0.7 -> 393.4 | F14: 632838 | G14: =IF(F14>=F13,F14-F13,0) -> 90 | H14: =(E14*0.55)*1.61 -> 348.3557 | I14: =C14*J1 -> 6796.296 | J14: =G14*J1 -> 351 | K14: =C14+E14 -> 2136.04
A15: 9 | B15: 8468168 | C15: =IF(B15>=B14,B15-B14,0)*1.06 -> 1744.76 | D15: 619928 | E15: =IF(D15>=D14,D15-D14,0)*0.7 -> 383.6 | F15: 632949 | G15: =IF(F15>=F14,F15-F14,0) -> 111 | H15: =(E15*0.55)*1.61 -> 339.6778 | I15: =C15*J1 -> 6804.564 | J15: =G15*J1 -> 432.9 | K15: =C15+E15 -> 2128.36
A16: 10 | B16: 8469842 | C16: =IF(B16>=B15,B16-B15,0)*1.06 -> 1774.44 | D16: 620466 | E16: =IF(D16>=D15,D16-D15,0)*0.7 -> 376.6 | F16: 633048 | G16: =IF(F16>=F15,F16-F15,0) -> 99 | H16: =(E16*0.55)*1.61 -> 333.4793 | I16: =C16*J1 -> 6920.316 | J16: =G16*J1 -> 386.1 | K16: =C16+E16 -> 2151.04
A17: 11 | B17: 8471487 | C17: =IF(B17>=B16,B17-B16,0)*1.06 -> 1743.7 | D17: 621021 | E17: =IF(D17>=D16,D17-D16,0)*0.7 -> 388.5 | F17: 633148.5 | G17: =IF(F17>=F16,F17-F16,0) -> 100.5 | H17: =(E17*0.55)*1.61 -> 344.01675 | I17: =C17*J1 -> 6800.43 | J17: =G17*J1 -> 391.95 | K17: =C17+E17 -> 2132.2
A18: 12 | B18: 8473140.8 | C18: =IF(B18>=B17,B18-B17,0)*1.06 -> 1753.028 | D18: 621570.2 | E18: =IF(D18>=D17,D18-D17,0)*0.7 -> 384.44 | F18: 633249.6 | G18: =IF(F18>=F17,F18-F17,0) -> 101.1 | H18: =(E18*0.55)*1.61 -> 340.42162 | I18: =C18*J1 -> 6836.8092 | J18: =G18*J1 -> 394.29 | K18: =C18+E18 -> 2137.468
A19: 13 | B19: 8474563 | C19: =IF(B19>=B18,B19-B18,0)*1.06 -> 1507.532 | D19: 622105 | E19: =IF(D19>=D18,D19-D18,0)*0.7 -> 374.36 | F19: 633330 | G19: =IF(F19>=F18,F19-F18,0) -> 80.4 | H19: =(E19*0.55)*1.61 -> 331.49578 | I19: =C19*J1 -> 5879.3748 | J19: =G19*J1 -> 313.56 | K19: =C19+E19 -> 1881.892
A20: 14 | B20: 8476134 | C20: =IF(B20>=B19,B20-B19,0)*1.06 -> 1665.26 | D20: 622698 | E20: =IF(D20>=D19,D20-D19,0)*0.7 -> 415.1 | F20: 633442 | G20: =IF(F20>=F19,F20-F19,0) -> 112 | H20: =(E20*0.55)*1.61 -> 367.57105 | I20: =C20*J1 -> 6494.514 | J20: =G20*J1 -> 436.8 | K20: =C20+E20 -> 2080.36
A21: 15 | B21: 8477679 | C21: =IF(B21>=B20,B21-B20,0)*1.06 -> 1637.7 | D21: 623244 | E21: =IF(D21>=D20,D21-D20,0)*0.7 -> 382.2 | F21: 633541 | G21: =IF(F21>=F20,F21-F20,0) -> 99 | H21: =(E21*0.55)*1.61 -> 338.4381 | I21: =C21*J1 -> 6387.03 | J21: =G21*J1 -> 386.1 | K21: =C21+E21 -> 2019.9
A22: 16 | B22: 8479262 | C22: =IF(B22>=B21,B22-B21,0)*1.06 -> 1677.98 | D22: 623793 | E22: =IF(D22>=D21,D22-D21,0)*0.7 -> 384.3 | F22: 633639 | G22: =IF(F22>=F21,F22-F21,0) -> 98 | H22: =(E22*0.55)*1.61 -> 340.29765 | I22: =C22*J1 -> 6544.122 | J22: =G22*J1 -> 382.2 | K22: =C22+E22 -> 2062.28
A23: 17 | B23: 8481323 | C23: =IF(B23>=B22,B23-B22,0)*1.06 -> 2184.66 | D23: 624345 | E23: =IF(D23>=D22,D23-D22,0)*0.7 -> 386.4 | F23: 633730 | G23: =IF(F23>=F22,F23-F22,0) -> 91 | H23: =(E23*0.55)*1.61 -> 342.1572 | I23: =C23*J1 -> 8520.174 | J23: =G23*J1 -> 354.9 | K23: =C23+E23 -> 2571.06
A24: 18 | B24: 8482592 | C24: =IF(B24>=B23,B24-B23,0)*1.06 -> 1345.14 | D24: 625013 | E24: =IF(D24>=D23,D24-D23,0)*0.7 -> 467.6 | F24: 633832 | G24: =IF(F24>=F23,F24-F23,0) -> 102 | H24: =(E24*0.55)*1.61 -> 414.0598 | I24: =C24*J1 -> 5246.046 | J24: =G24*J1 -> 397.8 | K24: =C24+E24 -> 1812.74
A25: 19 | B25: 8483992 | C25: =IF(B25>=B24,B25-B24,0)*1.06 -> 1484 | D25: 625557 | E25: =IF(D25>=D24,D25-D24,0)*0.7 -> 380.8 | F25: 633914 | G25: =IF(F25>=F24,F25-F24,0) -> 82 | H25: =(E25*0.55)*1.61 -> 337.1984 | I25: =C25*J1 -> 5787.6 | J25: =G25*J1 -> 319.8 | K25: =C25+E25 -> 1864.8
A26: 20 | B26: 8485406 | C26: =IF(B26>=B25,B26-B25,0)*1.06 -> 1498.84 | D26: 626063 | E26: =IF(D26>=D25,D26-D25,0)*0.7 -> 354.2 | F26: 633998 | G26: =IF(F26>=F25,F26-F25,0) -> 84 | H26: =(E26*0.55)*1.61 -> 313.6441 | I26: =C26*J1 -> 5845.476 | J26: =G26*J1 -> 327.6 | K26: =C26+E26 -> 1853.04
A27: 21 | B27: 8486965 | C27: =IF(B27>=B26,B27-B26,0)*1.06 -> 1652.54 | D27: 626642 | E27: =IF(D27>=D26,D27-D26,0)*0.7 -> 405.3 | F27: 634097 | G27: =IF(F27>=F26,F27-F26,0) -> 99 | H27: =(E27*0.55)*1.61 -> 358.89315 | I27: =C27*J1 -> 6444.906 | J27: =G27*J1 -> 386.1 | K27: =C27+E27 -> 2057.84
A28: 22 | B28: 8488568 | C28: =IF(B28>=B27,B28-B27,0)*1.06 -> 1699.18 | D28: 627182 | E28: =IF(D28>=D27,D28-D27,0)*0.7 -> 378 | F28: 634190 | G28: =IF(F28>=F27,F28-F27,0) -> 93 | H28: =(E28*0.55)*1.61 -> 334.719 | I28: =C28*J1 -> 6626.802 | J28: =G28*J1 -> 362.7
A29: 23 | B29: 8490033 | C29: =IF(B29>=B28,B29-B28,0)*1.06 -> 1552.9 | D29: 627775 | E29: =IF(D29>=D28,D29-D28,0)*0.7 -> 415.1 | F29: 634279 | G29: =IF(F29>=F28,F29-F28,0) -> 89 | H29: =(E29*0.55)*1.61 -> 367.57105 | I29: =C29*J1 -> 6056.31 | J29: =G29*J1 -> 347.1 | K29: =C29+E29 -> 1968
A30: 24 | B30: 8491568 | C30: =IF(B30>=B29,B30-B29,0)*1.06 -> 1627.1 | D30: 628356 | E30: =IF(D30>=D29,D30-D29,0)*0.7 -> 406.7 | F30: 634370.67 | G30: =IF(F30>=F29,F30-F29,0) -> 91.666667 | H30: =(E30*0.55)*1.61 -> 360.13285 | I30: =C30*J1 -> 6345.69 | J30: =G30*J1 -> 357.5 | K30: =C30+E30 -> 2033.8
A31: 25 | B31: 8493064 | C31: =IF(B31>=B30,B31-B30,0)*1.06 -> 1585.76 | D31: 628886 | E31: =IF(D31>=D30,D31-D30,0)*0.7 -> 371 | F31: 634454 | G31: =IF(F31>=F30,F31-F30,0) -> 83.333333 | H31: =(E31*0.55)*1.61 -> 328.5205 | I31: =C31*J3 -> 0 | J31: =G31*J1 -> 325 | K31: =C31+E31 -> 1956.76
A32: 26 | B32: 8494749 | C32: =IF(B32>=B31,B32-B31,0)*1.06 -> 1786.1 | D32: 629492 | E32: =IF(D32>=D31,D32-D31,0)*0.7 -> 424.2 | F32: 634563 | G32: =IF(F32>=F31,F32-F31,0) -> 109 | H32: =(E32*0.55)*1.61 -> 375.6291 | I32: =C32*J1 -> 6965.79 | J32: =G32*J1 -> 425.1 | K32: =C32+E32 -> 2210.3
A33: 27 | B33: 8496190 | C33: =IF(B33>=B32,B33-B32,0)*1.06 -> 1527.46 | D33: 630023 | E33: =IF(D33>=D32,D33-D32,0)*0.7 -> 371.7 | F33: 634670 | G33: =IF(F33>=F32,F33-F32,0) -> 107 | H33: =(E33*0.55)*1.61 -> 329.14035 | I33: =C33*J1 -> 5957.094 | J33: =G33*J1 -> 417.3 | K33: =C33+E33 -> 1899.16
A34: 28 | B34: 8497743 | C34: =IF(B34>=B33,B34-B33,0)*1.06 -> 1646.18 | D34: 630640 | E34: =IF(D34>=D33,D34-D33,0)*0.7 -> 431.9 | F34: 634788 | G34: =IF(F34>=F33,F34-F33,0) -> 118 | H34: =(E34*0.55)*1.61 -> 382.44745 | I34: =C34*J1 -> 6420.102 | J34: =G34*J1 -> 460.2 | K34: =C34+E34 -> 2078.08
A35: 29 | B35: 8499051 | C35: =IF(B35>=B34,B35-B34,0)*1.06 -> 1386.48 | D35: 631699 | E35: =IF(D35>=D34,D35-D34,0)*0.7 -> 741.3 | F35: 634930 | G35: =IF(F35>=F34,F35-F34,0) -> 142 | H35: =(E35*0.55)*1.61 -> 656.42115 | I35: =C35*J1 -> 5407.272 | J35: =G35*J1 -> 553.8 | K35: =C35+E35 -> 2127.78
A36: 30 | B36: 8500816 | C36: =IF(B36>=B35,B36-B35,0)*1.06 -> 1870.9 | D36: 631723 | E36: =IF(D36>=D35,D36-D35,0)*0.7 -> 16.8 | F36: 634977 | G36: =IF(F36>=F35,F36-F35,0) -> 47 | H36: =(E36*0.55)*1.61 -> 14.8764 | I36: =C36*J1 -> 7296.51 | J36: =G36*J1 -> 183.3 | K36: =C36+E36 -> 1887.7
A37: 31 | B37: 8502573 | C37: =IF(B37>=B36,B37-B36,0)*1.06 -> 1862.42 | D37: 632460 | E37: =IF(D37>=D36,D37-D36,0)*0.7 -> 515.9 | F37: 635107 | G37: =IF(F37>=F36,F37-F36,0) -> 130 | H37: =(E37*0.55)*1.61 -> 456.82945 | I37: =C37*J1 -> 7263.438 | J37: =G37*J1 -> 507 | K37: =C37+E37 -> 2378.32
A38: MTD | C38: =SUM(C7:C37) -> 53698.982 | E38: =SUM(E7:E37) -> 12340.203 | G38: =SUM(G7:G37) -> 3035.2685 | H38: =SUM(H6:H37) -> 10927.25 | I38: =SUM(I6:I37) -> 203241.56 | J38: =SUM(J6:J37) -> 11837.547 | K38: =SUM(K6:K37) -> 63962.004
A39: Average MTD. | C39: =C38/A42 -> 1789.9661 | E39: =E38/A42 -> 411.34009 | G39: =G38/A42 -> 101.17562 | H39: =H38/A42 -> 364.24165 | I39: =I38/A42 -> 6774.7188 | J39: =J38/A42 -> 394.58491
A41: No of Days MTD
A42: =COUNTIF(B7:B36,">0") -> 30

Sheet Sheet1

Sheet Sheet2

Sheet Consp
A1: =Elect!A1 -> 44927 | L1: Summary | P1: =Elect!A1 -> 44927
B2: Elect Consuumption | H2: Water Incoming | U2: Water Consumption | AC2: Irrigation | AG2: Gas | AJ2: Cost | AK2: Solar Meter [ LIT ] | AL2: No. of Eng. | AM2: No. of Gardners | AN2: Cons. (lit) | AO2: Received Gas (tons) | AP2: Fuel Cost | AQ2: Solar level [cm] | AR2: Received Solar (tons) | AS2: Fuel Cost | AT2: Occupancy 10 | AV2: Occupancy07 | AZ2: Elect 2009 | BE2: Elect 2010 | BJ2: Water 2009 | BO2: Water 2010
A3: Date | B3: COUNTER (2) | D3: MD | F3: KVAR | H3: R.O | J3: Qenna | L3: Trucks | N3: Rimievera Line Meter | O3: Total Inc. | Q3: Total Main S.Pool | S3: Total Bar & Beach cons. | U3: Total S. Pool cons. | W3: Hotel consumption. | Y3: Sold Water | AA3: Irr. Water from R.O | AC3: Irr. Consumption. | AE3: Storage Water One tank | AF3: Grand Cons | AG3: % | AH3: Stock | AI3: Cons. | AJ3: 0 | AT3: No of guest | AU3: No. of rooms | AV3: No. of rooms | AW3: No. of guest | AX3: Cons. Per occ. room | AY3: Cons. Per guest | AZ3: Total cost | BA3: cost per room | BB3: cost per guest | BC3: Cons. Per occ. room | BD3: Cons. Per guest | BE3: Total cost | BF3: cost per room | BG3: cost per guest | BH3: Cons. Per occ. room | BI3: Cons. Per guest | BJ3: Total cost | BK3: cost per room | BL3: cost per guest | BM3: Cons. Per occ. room | BN3: Cons. Per guest | BO3: Total cost | BP3: cost per room | BQ3: cost per guest
B4: 2013 | C4: 2014 | D4: 2013 | E4: 2014 | F4: 2013 | G4: 2014 | H4: 2013 | I4: 2014 | J4: 2009 | K4: 2010 | L4: 2009 | M4: 2010 | O4: 2009 | P4: 2010 | Q4: 2009 | R4: 2010 | S4: 2009 | T4: 2010 | U4: 2009 | V4: 2010 | W4: 2009 | X4: 2010 | Y4: 2009 | Z4: 2010 | AA4: 2009 | AB4: 2010 | AC4: 2009 | AD4: 2010
A5: 1 | B5: 33600 | C5: =Elect!J6 -> 6443.9444 | D5: 0 | E5: =Elect!M6 -> 1741 | F5: 20 | G5: =Elect!O6 -> 2000.8333 | H5: 800 | I5: =Water!C7 -> 162.88333 | J5: 0 | K5: =Water!E7 -> 146.74 | L5: 0 | M5: =Water!#REF! -> #REF! | N5: =Water!#REF! -> #REF! | O5: 1005 | P5: =Water!H7 -> 433.405 | Q5: 114 | R5: =Water!O7 -> 0 | S5: 13 | T5: =Water!#REF! -> #REF! | U5: 147 | V5: =Water!#REF! -> #REF! | W5: 755 | X5: =Water!Q7 -> 251.3749 | Y5: 0 | Z5: =Water!#REF! -> #REF! | AA5: 0 | AB5: 0 | AC5: 690 | AD5: =Water!#REF! -> #REF! | AE5: =Water!#REF! -> #REF! | AF5: =Water!#REF! -> #REF! | AG5: =Gas!#REF! -> #REF! | AH5: =Gas!C7 -> 3529.1817 | AI5: =Gas!#REF! -> #REF! | AJ5: =Gas!J7 -> 476.84722 | AK5: =Gas!#REF! -> #REF! | AL5: =Gas!#REF! -> #REF! | AM5: =Gas!#REF! -> #REF! | AN5: =Gas!#REF! -> #REF! | AO5: =Gas!#REF! -> #REF! | AP5: =Gas!#REF! -> #REF! | AQ5: =Gas!#REF! -> #REF! | AR5: =Gas!#REF! -> #REF! | AS5: =Gas!#REF! -> #REF! | AT5: =Elect!BR6 -> 149.33333 | AU5: =Elect!BP6 -> 170 | AV5: =Elect!#REF! -> #REF! | AW5: =Elect!BR6 -> 149.33333 | AX5: 48.695652 | AY5: 24.705882 | AZ5: 8835.4834 | BA5: 12.805048 | BB5: 6.496679 | BC5: =Elect!#REF! -> #REF! | BD5: =Elect!#REF! -> #REF! | BE5: =Elect!#REF! -> #REF! | BF5: =Elect!#REF! -> #REF! | BG5: =Elect!#REF! -> #REF! | BH5: 1.142029 | BI5: 0.57941176 | BJ5: 4569.1158 | BK5: 6.6219069 | BL5: 3.3596439 | BM5: =Water!U7 -> 1.8210294 | BN5: =Water!W7 -> #DIV/0! | BO5: =Water!X7 -> 1733.62 | BP5: =Water!Y7 -> 7.2841176 | BQ5: =Water!Z7 -> 0
A6: 2 | B6: 31200 | C6: =Elect!J7 -> 6181 | D6: 0 | E6: =Elect!M7 -> 2110 | F6: 20 | G6: =Elect!O7 -> 1875 | H6: 936 | I6: =Water!C8 -> 69.6 | J6: 0 | K6: =Water!E8 -> 87 | L6: 0 | M6: =Water!#REF! -> #REF! | N6: =Water!#REF! -> #REF! | O6: 1006 | P6: =Water!H8 -> 258.1 | Q6: 113 | R6: =Water!O8 -> 0 | S6: 17 | T6: =Water!#REF! -> #REF! | U6: 140 | V6: =Water!#REF! -> #REF! | W6: 792 | X6: =Water!Q8 -> 149.698 | Y6: 0 | Z6: =Water!#REF! -> #REF! | AA6: 0 | AB6: 0 | AC6: 370 | AD6: =Water!#REF! -> #REF! | AE6: =Water!#REF! -> #REF! | AF6: =Water!#REF! -> #REF! | AG6: =Gas!B7 -> 8455243 | AH6: =Gas!C8 -> 1622.86 | AI6: =Gas!#REF! -> #REF! | AJ6: =Gas!J8 -> 292.5 | AK6: =Gas!#REF! -> #REF! | AL6: =Gas!#REF! -> #REF! | AM6: =Gas!#REF! -> #REF! | AN6: =Gas!#REF! -> #REF! | AO6: =Gas!#REF! -> #REF! | AP6: =Gas!#REF! -> #REF! | AQ6: =Gas!#REF! -> #REF! | AR6: =Gas!#REF! -> #REF! | AS6: =Gas!#REF! -> #REF! | AT6: =Elect!BR7 -> 151 | AU6: =Elect!BP7 -> 133 | AX6: 47.416413 | AY6: 23.981553 | AZ6: 8299.2754 | BA6: 12.612881 | BB6: 6.379151 | BC6: =Elect!BQ7 -> 566724 | BD6: =Elect!#REF! -> #REF! | BE6: =Elect!#REF! -> #REF! | BF6: =Elect!#REF! -> #REF! | BG6: =Elect!#REF! -> #REF! | BH6: 1.2021277 | BI6: 0.60799385 | BJ6: 5345.8654 | BK6: 8.1244156 | BL6: 4.1090434 | BM6: =Water!U8 -> 1.1370044 | BN6: =Water!W8 -> #DIV/0! | BO6: =Water!X8 -> 1032.4 | BP6: =Water!Y8 -> 4.5480176 | BQ6: =Water!Z8 -> #DIV/0!
A7: 3 | B7: 31200 | C7: =Elect!J8 -> 6253 | D7: 0 | E7: =Elect!M8 -> 2264 | F7: 20 | G7: =Elect!O8 -> 2037 | H7: 685 | I7: =Water!C9 -> 104.4 | J7: 0 | K7: =Water!E9 -> 127.6 | L7: 0 | M7: =Water!#REF! -> #REF! | N7: =Water!#REF! -> #REF! | O7: 902 | P7: =Water!H9 -> 342.78 | Q7: 126 | R7: =Water!O9 -> 0 | S7: 26 | T7: =Water!#REF! -> #REF! | U7: 134 | V7: =Water!#REF! -> #REF! | W7: 766 | X7: =Water!Q9 -> 198.8124 | Y7: 0 | Z7: =Water!#REF! -> #REF! | AA7: 0 | AB7: 0 | AC7: 740 | AD7: =Water!#REF! -> #REF! | AE7: =Water!#REF! -> #REF! | AF7: =Water!#REF! -> #REF! | AG7: =Gas!B9 -> 8458394 | AH7: =Gas!C9 -> 1717.2 | AI7: =Gas!#REF! -> #REF! | AJ7: =Gas!J9 -> 370.5 | AK7: =Gas!#REF! -> #REF! | AL7: =Gas!#REF! -> #REF! | AM7: =Gas!#REF! -> #REF! | AN7: =Gas!#REF! -> #REF! | AO7: =Gas!#REF! -> #REF! | AP7: =Gas!#REF! -> #REF! | AQ7: =Gas!#REF! -> #REF! | AR7: =Gas!#REF! -> #REF! | AS7: =Gas!#REF! -> #REF! | AT7: =Elect!BR8 -> 156 | AU7: =Elect!BP8 -> 146 | AX7: 47.926267 | AY7: 24.223602 | AZ7: 8299.2754 | BA7: 12.748503 | BB7: 6.4435368 | BC7: =Elect!BQ8 -> 566880 | BD7: =Elect!#REF! -> #REF! | BE7: =Elect!#REF! -> #REF! | BF7: =Elect!#REF! -> #REF! | BG7: =Elect!#REF! -> #REF! | BH7: 1.0875576 | BI7: 0.54968944 | BJ7: 3912.3054 | BK7: 6.0096857 | BL7: 3.0375042 | BM7: =Water!U9 -> 1.6092958 | BN7: =Water!W9 -> #DIV/0! | BO7: =Water!X9 -> 1371.12 | BP7: =Water!Y9 -> 6.4371831 | BQ7: =Water!Z9 -> #DIV/0!
A8: 4 | B8: 33600 | C8: =Elect!J9 -> 5829 | D8: 0 | E8: =Elect!M9 -> 2366 | F8: 20 | G8: =Elect!O9 -> 2023 | H8: 786 | I8: =Water!C10 -> 92.8 | J8: 0 | K8: =Water!E10 -> 110.2 | L8: 0 | M8: =Water!#REF! -> #REF! | N8: =Water!#REF! -> #REF! | O8: 930 | P8: =Water!H10 -> 311.46 | Q8: 153 | R8: =Water!O10 -> 0 | S8: 46 | T8: =Water!#REF! -> #REF! | U8: 150 | V8: =Water!#REF! -> #REF! | W8: 766 | X8: =Water!Q10 -> 180.6468 | Y8: 0 | Z8: =Water!#REF! -> #REF! | AA8: 0 | AB8: 0 | AC8: 820 | AD8: =Water!#REF! -> #REF! | AE8: =Water!#REF! -> #REF! | AF8: =Water!#REF! -> #REF! | AG8: =Gas!B10 -> 8460180 | AH8: =Gas!C10 -> 1893.16 | AI8: =Gas!#REF! -> #REF! | AJ8: =Gas!J10 -> 405.6 | AK8: =Gas!#REF! -> #REF! | AL8: =Gas!#REF! -> #REF! | AM8: =Gas!#REF! -> #REF! | AN8: =Gas!#REF! -> #REF! | AO8: =Gas!#REF! -> #REF! | AP8: =Gas!#REF! -> #REF! | AQ8: =Gas!#REF! -> #REF! | AR8: =Gas!#REF! -> #REF! | AS8: =Gas!#REF! -> #REF! | AT8: =Elect!BR9 -> 107 | AU8: =Elect!BP9 -> 112 | AX8: 51.06383 | AY8: 25.866051 | AZ8: 8835.4834 | BA8: 13.427786 | BB8: 6.8017578 | BC8: =Elect!BQ9 -> 566987 | BD8: =Elect!#REF! -> #REF! | BE8: =Elect!#REF! -> #REF! | BF8: =Elect!#REF! -> #REF! | BG8: =Elect!#REF! -> #REF! | BH8: 1.2218845 | BI8: 0.61893764 | BJ8: 4489.1562 | BK8: 6.8224259 | BL8: 3.4558555 | BM8: =Water!U10 -> 1.5418812 | BN8: =Water!W10 -> #DIV/0! | BO8: =Water!X10 -> 1245.84 | BP8: =Water!Y10 -> 6.1675248 | BQ8: =Water!Z10 -> #DIV/0!
A9: 5 | B9: 31200 | C9: =Elect!J10 -> 6773 | D9: 0 | E9: =Elect!M10 -> 2435 | F9: 20 | G9: =Elect!O10 -> 2180 | H9: 789 | I9: =Water!C11 -> 110.2 | J9: 0 | K9: =Water!E11 -> 121.8 | L9: 0 | M9: =Water!#REF! -> #REF! | N9: =Water!#REF! -> #REF! | O9: 1003 | P9: =Water!H11 -> 352.06 | Q9: 102 | R9: =Water!O11 -> 0 | S9: 8 | T9: =Water!#REF! -> #REF! | U9: 130 | V9: =Water!#REF! -> #REF! | W9: 735 | X9: =Water!Q11 -> 204.1948 | Y9: 0 | Z9: =Water!#REF! -> #REF! | AA9: 0 | AB9: 0 | AC9: 640 | AD9: =Water!#REF! -> #REF! | AE9: =Water!#REF! -> #REF! | AF9: =Water!#REF! -> #REF! | AG9: =Gas!B11 -> 8461649 | AH9: =Gas!C11 -> 1557.14 | AI9: =Gas!#REF! -> #REF! | AJ9: =Gas!J11 -> 354.9 | AK9: =Gas!#REF! -> #REF! | AL9: =Gas!#REF! -> #REF! | AM9: =Gas!#REF! -> #REF! | AN9: =Gas!#REF! -> #REF! | AO9: =Gas!#REF! -> #REF! | AP9: =Gas!#REF! -> #REF! | AQ9: =Gas!#REF! -> #REF! | AR9: =Gas!#REF! -> #REF! | AS9: =Gas!#REF! -> #REF! | AT9: =Elect!BR10 -> 151 | AU9: =Elect!BP10 -> 130 | AX9: 49.840256 | AY9: 25.181598 | AZ9: 8299.2754 | BA9: 13.257628 | BB9: 6.698366 | BC9: =Elect!BQ10 -> 567138 | BD9: =Elect!#REF! -> #REF! | BE9: =Elect!#REF! -> #REF! | BF9: =Elect!#REF! -> #REF! | BG9: =Elect!#REF! -> #REF! | BH9: 1.1980831 | BI9: 0.60532688 | BJ9: 4506.2904 | BK9: 7.198547 | BL9: 3.6370383 | BM9: =Water!U11 -> 1.7962245 | BN9: =Water!W11 -> #DIV/0! | BO9: =Water!X11 -> 1408.24 | BP9: =Water!Y11 -> 7.184898 | BQ9: =Water!Z11 -> #DIV/0!
