Workbook

Sheet TOTAL
A1: Site Name | B1: Day | C1: Month | D1: Year | E1: Total Electricity Kwh | F1: Electricity Tariff ($/Kwh) | G1: Total Fuel Oil (Liter) | H1: Fuel Oil $/Liter | I1: Water Utility Supply (m3) m3 | J1: Water Utility Supply (m3) $/m3 | K1: LPG (Kg) | L1: LPG $/Kg | M1: Room Nights | N1: Total Guests | O1: Food Covers
A2: Maldives at Kuda Huraa | B2: 1 | C2: 3 | D2: 2023 | E2: 19380 | G2: 5327 | I2: 351 | M2: 39.6 | N2: 91 | O2: 242
A3: Maldives at Kuda Huraa | B3: =B2+1 -> 2 | C3: 3 | D3: 2023 | E3: 21050 | G3: 5689 | I3: 347 | M3: 37.5 | N3: 87 | O3: 219
A4: Maldives at Kuda Huraa | B4: =B3+1 -> 3 | C4: 3 | D4: 2023 | E4: 19280 | G4: 5310 | I4: 327 | M4: 41.7 | N4: 101 | O4: 237
A5: Maldives at Kuda Huraa | B5: =B4+1 -> 4 | C5: 3 | D5: 2023 | E5: 19240 | G5: 5325 | I5: 344 | M5: 42.7 | N5: 106 | O5: 246
A6: Maldives at Kuda Huraa | B6: =B5+1 -> 5 | C6: 3 | D6: 2023 | E6: 20170 | G6: 5551 | I6: 352 | M6: 43.8 | N6: 113 | O6: 273
A7: Maldives at Kuda Huraa | B7: =B6+1 -> 6 | C7: 3 | D7: 2023 | E7: 18280 | G7: 5251 | I7: 337 | M7: 37.5 | N7: 92 | O7: 236
A8: Maldives at Kuda Huraa | B8: =B7+1 -> 7 | C8: 3 | D8: 2023 | E8: 20030 | G8: 5195 | I8: 295 | M8: 37.5 | N8: 81 | O8: 229
A9: Maldives at Kuda Huraa | B9: =B8+1 -> 8 | C9: 3 | D9: 2023 | E9: 21310 | G9: 6041 | I9: 372 | M9: 41.7 | N9: 88 | O9: 245
A10: Maldives at Kuda Huraa | B10: =B9+1 -> 9 | C10: 3 | D10: 2023 | E10: 20250 | G10: 5626 | I10: 363 | M10: 47.9 | N10: 111 | O10: 286
A11: Maldives at Kuda Huraa | B11: =B10+1 -> 10 | C11: 3 | D11: 2023 | E11: 20510 | G11: 5758 | I11: 339 | M11: 42.7 | N11: 105 | O11: 316
A12: Maldives at Kuda Huraa | B12: =B11+1 -> 11 | C12: 3 | D12: 2023 | E12: 20140 | G12: 5568 | I12: 378 | M12: 40.6 | N12: 91 | O12: 249
A13: Maldives at Kuda Huraa | B13: =B12+1 -> 12 | C13: 3 | D13: 2023 | E13: 20060 | G13: 5627 | I13: 352 | M13: 37.5 | N13: 86 | O13: 231
A14: Maldives at Kuda Huraa | B14: =B13+1 -> 13 | C14: 3 | D14: 2023
A15: Maldives at Kuda Huraa | B15: =B14+1 -> 14 | C15: 3 | D15: 2023
A16: Maldives at Kuda Huraa | B16: =B15+1 -> 15 | C16: 3 | D16: 2023
A17: Maldives at Kuda Huraa | B17: =B16+1 -> 16 | C17: 3 | D17: 2023
A18: Maldives at Kuda Huraa | B18: =B17+1 -> 17 | C18: 3 | D18: 2023
A19: Maldives at Kuda Huraa | B19: =B18+1 -> 18 | C19: 3 | D19: 2023
A20: Maldives at Kuda Huraa | B20: =B19+1 -> 19 | C20: 3 | D20: 2023
A21: Maldives at Kuda Huraa | B21: =B20+1 -> 20 | C21: 3 | D21: 2023
A22: Maldives at Kuda Huraa | B22: =B21+1 -> 21 | C22: 3 | D22: 2023
A23: Maldives at Kuda Huraa | B23: =B22+1 -> 22 | C23: 3 | D23: 2023
A24: Maldives at Kuda Huraa | B24: =B23+1 -> 23 | C24: 3 | D24: 2023
A25: Maldives at Kuda Huraa | B25: =B24+1 -> 24 | C25: 3 | D25: 2023
... A32: Maldives at Kuda Huraa | B32: =B31+1 -> 31 | C32: 3 | D32: 2023
A33: Total | E33: =SUM(E2:E32) -> 239700 | F33: 0 | G33: =SUM(G2:G32) -> 66268 | H33: 0 | I33: =SUM(I2:I32) -> 4157 | J33: 0 | K33: =SUM(K2:K31) -> 0 | L33: 0 | M33: =SUM(M2:M32) -> 490.7 | N33: =SUM(N2:N32) -> 1152 | O33: =SUM(O2:O32) -> 3009

Sheet Submeters
A1: Site Name | B1: Day | C1: Month | D1: Year | E1: Reef Club | F1: Kitchen | G1: Pastry | H1: Laundry | I1: Laundry A | J1: Laundry B | K1: Laundry C | L1: STP -1 | M1: M - Block /PC | N1: B&C Block | O1: Feeder -101-112 | P1: Feeder -113-123 | Q1: Feeder -124-134 | R1: Feeder -201-208 | S1: Feeder -209-216 | T1: Feeder -217-224 | U1: Feeder -301-319 | V1: Feeder 401-419 | W1: Spa
A2: Maldives at Kuda Huraa | B2: 1 | C2: 2 | D2: 2023 | E2: 480 | F2: 2500 | G2: 260 | H2: =I2+J2+K2 -> 1230 | I2: =('Kwh Reading'!J5-'Kwh Reading'!J4)*1000 -> 570 | J2: =('Kwh Reading'!K5-'Kwh Reading'!K4)*1000 -> 310 | K2: =('Kwh Reading'!L5-'Kwh Reading'!L4)*1000 -> 350 | L2: =('Kwh Reading'!R5-'Kwh Reading'!R4) -> 137 | M2: =('Kwh Reading'!I5-'Kwh Reading'!I4)*1000 -> 290 | N2: =('Kwh Reading'!B5-'Kwh Reading'!B4)*1000000 -> 1200 | O2: =('Kwh Reading'!M5-'Kwh Reading'!M4)*1000 -> 420 | P2: =('Kwh Reading'!H5-'Kwh Reading'!H4)*1000000 -> 700 | Q2: =('Kwh Reading'!P5-'Kwh Reading'!P4)*1000000 -> 500 | R2: =('Kwh Reading'!G5-'Kwh Reading'!G4)*1000000 -> 500 | S2: =('Kwh Reading'!Q5-'Kwh Reading'!Q4)*1000 -> 410 | T2: =('Kwh Reading'!N5-'Kwh Reading'!N4)*1000 -> 420 | U2: ='Kwh Reading'!E5-'Kwh Reading'!E4 -> 2773.98 | V2: ='Kwh Reading'!D5-'Kwh Reading'!D4 -> 1805.15 | W2: =('Kwh Reading'!O5-'Kwh Reading'!O4)*1000 -> 220
A3: Maldives at Kuda Huraa | B3: =B2+1 -> 2 | C3: 2 | D3: 2023 | E3: =('Kwh Reading'!S6-'Kwh Reading'!S5)*1000 -> 560 | F3: =('Kwh Reading'!F6-'Kwh Reading'!F5)*1000000 -> 2600 | G3: =('Kwh Reading'!C6-'Kwh Reading'!C5)*1000 -> 260 | H3: =I3+J3+K3 -> 1310 | I3: =('Kwh Reading'!J6-'Kwh Reading'!J5)*1000 -> 590 | J3: =('Kwh Reading'!K6-'Kwh Reading'!K5)*1000 -> 350 | K3: =('Kwh Reading'!L6-'Kwh Reading'!L5)*1000 -> 370 | L3: =('Kwh Reading'!R6-'Kwh Reading'!R5) -> 127.5 | M3: =('Kwh Reading'!I6-'Kwh Reading'!I5)*1000 -> 310 | N3: =('Kwh Reading'!B6-'Kwh Reading'!B5)*1000000 -> 1200 | O3: =('Kwh Reading'!M6-'Kwh Reading'!M5)*1000 -> 520 | P3: =('Kwh Reading'!H6-'Kwh Reading'!H5)*1000000 -> 800 | Q3: =('Kwh Reading'!P6-'Kwh Reading'!P5)*1000000 -> 500 | R3: =('Kwh Reading'!G6-'Kwh Reading'!G5)*1000000 -> 600 | S3: =('Kwh Reading'!Q6-'Kwh Reading'!Q5)*1000 -> 490 | T3: =('Kwh Reading'!N6-'Kwh Reading'!N5)*1000 -> 500 | U3: ='Kwh Reading'!E6-'Kwh Reading'!E5 -> 3114.13 | V3: ='Kwh Reading'!D6-'Kwh Reading'!D5 -> 1870.73 | W3: =('Kwh Reading'!O6-'Kwh Reading'!O5)*1000 -> 210
A4: Maldives at Kuda Huraa | B4: =B3+1 -> 3 | C4: 2 | D4: 2023 | E4: =('Kwh Reading'!S7-'Kwh Reading'!S6)*1000 -> 530 | F4: =('Kwh Reading'!F7-'Kwh Reading'!F6)*1000000 -> 2400 | G4: =('Kwh Reading'!C7-'Kwh Reading'!C6)*1000 -> 260 | H4: =I4+J4+K4 -> 1180 | I4: =('Kwh Reading'!J7-'Kwh Reading'!J6)*1000 -> 510 | J4: =('Kwh Reading'!K7-'Kwh Reading'!K6)*1000 -> 320 | K4: =('Kwh Reading'!L7-'Kwh Reading'!L6)*1000 -> 350 | L4: =('Kwh Reading'!R7-'Kwh Reading'!R6) -> 127.3 | M4: =('Kwh Reading'!I7-'Kwh Reading'!I6)*1000 -> 280 | N4: =('Kwh Reading'!B7-'Kwh Reading'!B6)*1000000 -> 1100 | O4: =('Kwh Reading'!M7-'Kwh Reading'!M6)*1000 -> 450 | P4: =('Kwh Reading'!H7-'Kwh Reading'!H6)*1000000 -> 600 | Q4: =('Kwh Reading'!P7-'Kwh Reading'!P6)*1000000 -> 600 | R4: =('Kwh Reading'!G7-'Kwh Reading'!G6)*1000000 -> 600 | S4: =('Kwh Reading'!Q7-'Kwh Reading'!Q6)*1000 -> 380 | T4: =('Kwh Reading'!N7-'Kwh Reading'!N6)*1000 -> 380 | U4: ='Kwh Reading'!E7-'Kwh Reading'!E6 -> 2725.7 | V4: ='Kwh Reading'!D7-'Kwh Reading'!D6 -> 1757.6 | W4: =('Kwh Reading'!O7-'Kwh Reading'!O6)*1000 -> 210
A5: Maldives at Kuda Huraa | B5: =B4+1 -> 4 | C5: 2 | D5: 2023 | E5: =('Kwh Reading'!S8-'Kwh Reading'!S7)*1000 -> 300 | F5: =('Kwh Reading'!F8-'Kwh Reading'!F7)*1000000 -> 2400 | G5: =('Kwh Reading'!C8-'Kwh Reading'!C7)*1000 -> 270 | H5: =I5+J5+K5 -> 1110 | I5: =('Kwh Reading'!J8-'Kwh Reading'!J7)*1000 -> 400 | J5: =('Kwh Reading'!K8-'Kwh Reading'!K7)*1000 -> 350 | K5: =('Kwh Reading'!L8-'Kwh Reading'!L7)*1000 -> 360 | L5: =('Kwh Reading'!R8-'Kwh Reading'!R7) -> 118.5 | M5: =('Kwh Reading'!I8-'Kwh Reading'!I7)*1000 -> 300 | N5: =('Kwh Reading'!B8-'Kwh Reading'!B7)*1000000 -> 1200 | O5: =('Kwh Reading'!M8-'Kwh Reading'!M7)*1000 -> 470 | P5: =('Kwh Reading'!H8-'Kwh Reading'!H7)*1000000 -> 700 | Q5: =('Kwh Reading'!P8-'Kwh Reading'!P7)*1000000 -> 500 | R5: =('Kwh Reading'!G8-'Kwh Reading'!G7)*1000000 -> 500 | S5: =('Kwh Reading'!Q8-'Kwh Reading'!Q7)*1000 -> 400 | T5: =('Kwh Reading'!N8-'Kwh Reading'!N7)*1000 -> 390 | U5: ='Kwh Reading'!E8-'Kwh Reading'!E7 -> 2568.26 | V5: ='Kwh Reading'!D8-'Kwh Reading'!D7 -> 1866.61 | W5: =('Kwh Reading'!O8-'Kwh Reading'!O7)*1000 -> 260
A6: Maldives at Kuda Huraa | B6: =B5+1 -> 5 | C6: 2 | D6: 2023 | E6: =('Kwh Reading'!S9-'Kwh Reading'!S8)*1000 -> 550 | F6: =('Kwh Reading'!F9-'Kwh Reading'!F8)*1000000 -> 2500 | G6: =('Kwh Reading'!C9-'Kwh Reading'!C8)*1000 -> 270 | H6: =I6+J6+K6 -> 1370 | I6: =('Kwh Reading'!J9-'Kwh Reading'!J8)*1000 -> 570 | J6: =('Kwh Reading'!K9-'Kwh Reading'!K8)*1000 -> 360 | K6: =('Kwh Reading'!L9-'Kwh Reading'!L8)*1000 -> 440 | L6: =('Kwh Reading'!R9-'Kwh Reading'!R8) -> 128.9 | M6: =('Kwh Reading'!I9-'Kwh Reading'!I8)*1000 -> 300 | N6: =('Kwh Reading'!B9-'Kwh Reading'!B8)*1000000 -> 1200 | O6: =('Kwh Reading'!M9-'Kwh Reading'!M8)*1000 -> 520 | P6: =('Kwh Reading'!H9-'Kwh Reading'!H8)*1000000 -> 700 | Q6: =('Kwh Reading'!P9-'Kwh Reading'!P8)*1000000 -> 500 | R6: =('Kwh Reading'!G9-'Kwh Reading'!G8)*1000000 -> 600 | S6: =('Kwh Reading'!Q9-'Kwh Reading'!Q8)*1000 -> 440 | T6: =('Kwh Reading'!N9-'Kwh Reading'!N8)*1000 -> 420 | U6: ='Kwh Reading'!E9-'Kwh Reading'!E8 -> 3017.45 | V6: ='Kwh Reading'!D9-'Kwh Reading'!D8 -> 1977.84 | W6: =('Kwh Reading'!O9-'Kwh Reading'!O8)*1000 -> 230
A7: Maldives at Kuda Huraa | B7: =B6+1 -> 6 | C7: 2 | D7: 2023 | E7: =('Kwh Reading'!S10-'Kwh Reading'!S9)*1000 -> 550 | F7: =('Kwh Reading'!F10-'Kwh Reading'!F9)*1000000 -> 2400 | G7: =('Kwh Reading'!C10-'Kwh Reading'!C9)*1000 -> 270 | H7: =I7+J7+K7 -> 1430 | I7: =('Kwh Reading'!J10-'Kwh Reading'!J9)*1000 -> 650 | J7: =('Kwh Reading'!K10-'Kwh Reading'!K9)*1000 -> 380 | K7: =('Kwh Reading'!L10-'Kwh Reading'!L9)*1000 -> 400 | L7: =('Kwh Reading'!R10-'Kwh Reading'!R9) -> 120.9 | M7: =('Kwh Reading'!I10-'Kwh Reading'!I9)*1000 -> 240 | N7: =('Kwh Reading'!B10-'Kwh Reading'!B9)*1000000 -> 1000 | O7: =('Kwh Reading'!M10-'Kwh Reading'!M9)*1000 -> 430 | P7: =('Kwh Reading'!H10-'Kwh Reading'!H9)*1000000 -> 500 | Q7: =('Kwh Reading'!P10-'Kwh Reading'!P9)*1000000 -> 500 | R7: =('Kwh Reading'!G10-'Kwh Reading'!G9)*1000000 -> 500 | S7: =('Kwh Reading'!Q10-'Kwh Reading'!Q9)*1000 -> 310 | T7: =('Kwh Reading'!N10-'Kwh Reading'!N9)*1000 -> 350 | U7: ='Kwh Reading'!E10-'Kwh Reading'!E9 -> 2472.16 | V7: ='Kwh Reading'!D10-'Kwh Reading'!D9 -> 1538.55 | W7: =('Kwh Reading'!O10-'Kwh Reading'!O9)*1000 -> 250
A8: Maldives at Kuda Huraa | B8: =B7+1 -> 7 | C8: 2 | D8: 2023 | E8: =('Kwh Reading'!S11-'Kwh Reading'!S10)*1000 -> 550 | F8: =('Kwh Reading'!F11-'Kwh Reading'!F10)*1000000 -> 2400 | G8: =('Kwh Reading'!C11-'Kwh Reading'!C10)*1000 -> 280 | H8: =I8+J8+K8 -> 1400 | I8: =('Kwh Reading'!J11-'Kwh Reading'!J10)*1000 -> 640 | J8: =('Kwh Reading'!K11-'Kwh Reading'!K10)*1000 -> 360 | K8: =('Kwh Reading'!L11-'Kwh Reading'!L10)*1000 -> 400 | L8: =('Kwh Reading'!R11-'Kwh Reading'!R10) -> 136.1 | M8: =('Kwh Reading'!I11-'Kwh Reading'!I10)*1000 -> 280 | N8: =('Kwh Reading'!B11-'Kwh Reading'!B10)*1000000 -> 1100 | O8: =('Kwh Reading'!M11-'Kwh Reading'!M10)*1000 -> 480 | P8: =('Kwh Reading'!H11-'Kwh Reading'!H10)*1000000 -> 600 | Q8: =('Kwh Reading'!P11-'Kwh Reading'!P10)*1000000 -> 500 | R8: =('Kwh Reading'!G11-'Kwh Reading'!G10)*1000000 -> 600 | S8: =('Kwh Reading'!Q11-'Kwh Reading'!Q10)*1000 -> 290 | T8: =('Kwh Reading'!N11-'Kwh Reading'!N10)*1000 -> 420 | U8: ='Kwh Reading'!E11-'Kwh Reading'!E10 -> 2962.32 | V8: ='Kwh Reading'!D11-'Kwh Reading'!D10 -> 2057.22 | W8: =('Kwh Reading'!O11-'Kwh Reading'!O10)*1000 -> 210
A9: Maldives at Kuda Huraa | B9: =B8+1 -> 8 | C9: 2 | D9: 2023 | E9: =('Kwh Reading'!S12-'Kwh Reading'!S11)*1000 -> 550 | F9: =('Kwh Reading'!F12-'Kwh Reading'!F11)*1000000 -> 2400 | G9: =('Kwh Reading'!C12-'Kwh Reading'!C11)*1000 -> 260 | H9: =I9+J9+K9 -> 1310 | I9: =('Kwh Reading'!J12-'Kwh Reading'!J11)*1000 -> 570 | J9: =('Kwh Reading'!K12-'Kwh Reading'!K11)*1000 -> 380 | K9: =('Kwh Reading'!L12-'Kwh Reading'!L11)*1000 -> 360 | L9: =('Kwh Reading'!R12-'Kwh Reading'!R11) -> 119.5 | M9: =('Kwh Reading'!I12-'Kwh Reading'!I11)*1000 -> 290 | N9: =('Kwh Reading'!B12-'Kwh Reading'!B11)*1000000 -> 1300 | O9: =('Kwh Reading'!M12-'Kwh Reading'!M11)*1000 -> 510 | P9: =('Kwh Reading'!H12-'Kwh Reading'!H11)*1000000 -> 700 | Q9: =('Kwh Reading'!P12-'Kwh Reading'!P11)*1000000 -> 600 | R9: =('Kwh Reading'!G12-'Kwh Reading'!G11)*1000000 -> 600 | S9: =('Kwh Reading'!Q12-'Kwh Reading'!Q11)*1000 -> 360 | T9: =('Kwh Reading'!N12-'Kwh Reading'!N11)*1000 -> 430 | U9: ='Kwh Reading'!E12-'Kwh Reading'!E11 -> 3034.3 | V9: ='Kwh Reading'!D12-'Kwh Reading'!D11 -> 2274.32 | W9: =('Kwh Reading'!O12-'Kwh Reading'!O11)*1000 -> 270
A10: Maldives at Kuda Huraa | B10: =B9+1 -> 9 | C10: 2 | D10: 2023 | E10: =('Kwh Reading'!S13-'Kwh Reading'!S12)*1000 -> 550 | F10: =('Kwh Reading'!F13-'Kwh Reading'!F12)*1000000 -> 2400 | G10: =('Kwh Reading'!C13-'Kwh Reading'!C12)*1000 -> 260 | H10: =I10+J10+K10 -> 1180 | I10: =('Kwh Reading'!J13-'Kwh Reading'!J12)*1000 -> 510 | J10: =('Kwh Reading'!K13-'Kwh Reading'!K12)*1000 -> 320 | K10: =('Kwh Reading'!L13-'Kwh Reading'!L12)*1000 -> 350 | L10: =('Kwh Reading'!R13-'Kwh Reading'!R12) -> 135.4 | M10: =('Kwh Reading'!I13-'Kwh Reading'!I12)*1000 -> 290 | N10: =('Kwh Reading'!B13-'Kwh Reading'!B12)*1000000 -> 1200 | O10: =('Kwh Reading'!M13-'Kwh Reading'!M12)*1000 -> 550 | P10: =('Kwh Reading'!H13-'Kwh Reading'!H12)*1000000 -> 600 | Q10: =('Kwh Reading'!P13-'Kwh Reading'!P12)*1000000 -> 500 | R10: =('Kwh Reading'!G13-'Kwh Reading'!G12)*1000000 -> 600 | S10: =('Kwh Reading'!Q13-'Kwh Reading'!Q12)*1000 -> 300 | T10: =('Kwh Reading'!N13-'Kwh Reading'!N12)*1000 -> 400 | U10: ='Kwh Reading'!E13-'Kwh Reading'!E12 -> 2992.26 | V10: ='Kwh Reading'!D13-'Kwh Reading'!D12 -> 2109.82 | W10: =('Kwh Reading'!O13-'Kwh Reading'!O12)*1000 -> 260
A11: Maldives at Kuda Huraa | B11: =B10+1 -> 10 | C11: 2 | D11: 2023 | E11: =('Kwh Reading'!S14-'Kwh Reading'!S13)*1000 -> 560 | F11: =('Kwh Reading'!F14-'Kwh Reading'!F13)*1000000 -> 2400 | G11: =('Kwh Reading'!C14-'Kwh Reading'!C13)*1000 -> 270 | H11: =I11+J11+K11 -> 1270 | I11: =('Kwh Reading'!J14-'Kwh Reading'!J13)*1000 -> 570 | J11: =('Kwh Reading'!K14-'Kwh Reading'!K13)*1000 -> 360 | K11: =('Kwh Reading'!L14-'Kwh Reading'!L13)*1000 -> 340 | L11: =('Kwh Reading'!R14-'Kwh Reading'!R13) -> 131.6 | M11: =('Kwh Reading'!I14-'Kwh Reading'!I13)*1000 -> 300 | N11: =('Kwh Reading'!B14-'Kwh Reading'!B13)*1000000 -> 1100 | O11: =('Kwh Reading'!M14-'Kwh Reading'!M13)*1000 -> 510 | P11: =('Kwh Reading'!H14-'Kwh Reading'!H13)*1000000 -> 600 | Q11: =('Kwh Reading'!P14-'Kwh Reading'!P13)*1000000 -> 500 | R11: =('Kwh Reading'!G14-'Kwh Reading'!G13)*1000000 -> 500 | S11: =('Kwh Reading'!Q14-'Kwh Reading'!Q13)*1000 -> 400 | T11: =('Kwh Reading'!N14-'Kwh Reading'!N13)*1000 -> 470 | U11: ='Kwh Reading'!E14-'Kwh Reading'!E13 -> 3003.21 | V11: ='Kwh Reading'!D14-'Kwh Reading'!D13 -> 2105.26 | W11: =('Kwh Reading'!O14-'Kwh Reading'!O13)*1000 -> 260
A12: Maldives at Kuda Huraa | B12: =B11+1 -> 11 | C12: 2 | D12: 2023 | E12: =('Kwh Reading'!S15-'Kwh Reading'!S14)*1000 -> 330 | F12: =('Kwh Reading'!F15-'Kwh Reading'!F14)*1000000 -> 2500 | G12: =('Kwh Reading'!C15-'Kwh Reading'!C14)*1000 -> 270 | H12: =I12+J12+K12 -> 1350 | I12: =('Kwh Reading'!J15-'Kwh Reading'!J14)*1000 -> 610 | J12: =('Kwh Reading'!K15-'Kwh Reading'!K14)*1000 -> 400 | K12: =('Kwh Reading'!L15-'Kwh Reading'!L14)*1000 -> 340 | L12: =('Kwh Reading'!R15-'Kwh Reading'!R14) -> 136.2 | M12: =('Kwh Reading'!I15-'Kwh Reading'!I14)*1000 -> 330 | N12: =('Kwh Reading'!B15-'Kwh Reading'!B14)*1000000 -> 1200 | O12: =('Kwh Reading'!M15-'Kwh Reading'!M14)*1000 -> 560 | P12: =('Kwh Reading'!H15-'Kwh Reading'!H14)*1000000 -> 700 | Q12: =('Kwh Reading'!P15-'Kwh Reading'!P14)*1000000 -> 500 | R12: =('Kwh Reading'!G15-'Kwh Reading'!G14)*1000000 -> 600 | S12: =('Kwh Reading'!Q15-'Kwh Reading'!Q14)*1000 -> 380 | T12: =('Kwh Reading'!N15-'Kwh Reading'!N14)*1000 -> 410 | U12: ='Kwh Reading'!E15-'Kwh Reading'!E14 -> 2567.11 | V12: ='Kwh Reading'!D15-'Kwh Reading'!D14 -> 2037.69 | W12: =('Kwh Reading'!O15-'Kwh Reading'!O14)*1000 -> 260
A13: Maldives at Kuda Huraa | B13: =B12+1 -> 12 | C13: 2 | D13: 2023 | E13: =('Kwh Reading'!S16-'Kwh Reading'!S15)*1000 -> 590 | F13: =('Kwh Reading'!F16-'Kwh Reading'!F15)*1000000 -> 2400 | G13: =('Kwh Reading'!C16-'Kwh Reading'!C15)*1000 -> 260 | H13: =I13+J13+K13 -> 1390 | I13: =('Kwh Reading'!J16-'Kwh Reading'!J15)*1000 -> 630 | J13: =('Kwh Reading'!K16-'Kwh Reading'!K15)*1000 -> 380 | K13: =('Kwh Reading'!L16-'Kwh Reading'!L15)*1000 -> 380 | L13: =('Kwh Reading'!R16-'Kwh Reading'!R15) -> 128.9 | M13: =('Kwh Reading'!I16-'Kwh Reading'!I15)*1000 -> 340 | N13: =('Kwh Reading'!B16-'Kwh Reading'!B15)*1000000 -> 1200 | O13: =('Kwh Reading'!M16-'Kwh Reading'!M15)*1000 -> 560 | P13: =('Kwh Reading'!H16-'Kwh Reading'!H15)*1000000 -> 700 | Q13: =('Kwh Reading'!P16-'Kwh Reading'!P15)*1000000 -> 600 | R13: =('Kwh Reading'!G16-'Kwh Reading'!G15)*1000000 -> 600 | S13: =('Kwh Reading'!Q16-'Kwh Reading'!Q15)*1000 -> 360 | T13: =('Kwh Reading'!N16-'Kwh Reading'!N15)*1000 -> 410 | U13: ='Kwh Reading'!E16-'Kwh Reading'!E15 -> 3014.32 | V13: ='Kwh Reading'!D16-'Kwh Reading'!D15 -> 2071.12 | W13: =('Kwh Reading'!O16-'Kwh Reading'!O15)*1000 -> 240
A14: Maldives at Kuda Huraa | B14: =B13+1 -> 13 | C14: 2 | D14: 2023 | E14: =('Kwh Reading'!S17-'Kwh Reading'!S16)*1000 -> -722570 | F14: =('Kwh Reading'!F17-'Kwh Reading'!F16)*1000000 -> -3988100 | G14: =('Kwh Reading'!C17-'Kwh Reading'!C16)*1000 -> -386490 | H14: =I14+J14+K14 -> -1557230 | I14: =('Kwh Reading'!J17-'Kwh Reading'!J16)*1000 -> -614970 | J14: =('Kwh Reading'!K17-'Kwh Reading'!K16)*1000 -> -552660 | K14: =('Kwh Reading'!L17-'Kwh Reading'!L16)*1000 -> -389600 | L14: =('Kwh Reading'!R17-'Kwh Reading'!R16) -> -29092.8 | M14: =('Kwh Reading'!I17-'Kwh Reading'!I16)*1000 -> -420810 | N14: =('Kwh Reading'!B17-'Kwh Reading'!B16)*1000000 -> -1681100 | O14: =('Kwh Reading'!M17-'Kwh Reading'!M16)*1000 -> -920580 | P14: =('Kwh Reading'!H17-'Kwh Reading'!H16)*1000000 -> -1153900 | Q14: =('Kwh Reading'!P17-'Kwh Reading'!P16)*1000000 -> -1111900 | R14: =('Kwh Reading'!G17-'Kwh Reading'!G16)*1000000 -> -1220200 | S14: =('Kwh Reading'!Q17-'Kwh Reading'!Q16)*1000 -> -805530 | T14: =('Kwh Reading'!N17-'Kwh Reading'!N16)*1000 -> -831200 | U14: ='Kwh Reading'!E17-'Kwh Reading'!E16 -> -9824563 | V14: ='Kwh Reading'!D17-'Kwh Reading'!D16 -> -253718.48 | W14: =('Kwh Reading'!O17-'Kwh Reading'!O16)*1000 -> -286290
... A32: Maldives at Kuda Huraa | B32: =B31+1 -> 31 | C32: 2 | D32: 2023 | E32: =('Kwh Reading'!S35-'Kwh Reading'!S34)*1000 -> 0 | F32: =('Kwh Reading'!F35-'Kwh Reading'!F34)*1000000 -> 0 | G32: =('Kwh Reading'!C35-'Kwh Reading'!C34)*1000 -> 0 | H32: =I32+J32+K32 -> 0 | I32: =('Kwh Reading'!J35-'Kwh Reading'!J34)*1000 -> 0 | J32: =('Kwh Reading'!K35-'Kwh Reading'!K34)*1000 -> 0 | K32: =('Kwh Reading'!L35-'Kwh Reading'!L34)*1000 -> 0 | L32: =('Kwh Reading'!R35-'Kwh Reading'!R34) -> 0 | M32: =('Kwh Reading'!I35-'Kwh Reading'!I34)*1000 -> 0 | N32: =('Kwh Reading'!B35-'Kwh Reading'!B34)*1000000 -> 0 | O32: =('Kwh Reading'!M35-'Kwh Reading'!M34)*1000 -> 0 | P32: =('Kwh Reading'!H35-'Kwh Reading'!H34)*1000000 -> 0 | Q32: =('Kwh Reading'!P35-'Kwh Reading'!P34)*1000000 -> 0 | R32: =('Kwh Reading'!G35-'Kwh Reading'!G34)*1000000 -> 0 | S32: =('Kwh Reading'!Q35-'Kwh Reading'!Q34)*1000 -> 0 | T32: =('Kwh Reading'!N35-'Kwh Reading'!N34)*1000 -> 0 | U32: ='Kwh Reading'!E35-'Kwh Reading'!E34 -> 0 | V32: ='Kwh Reading'!D35-'Kwh Reading'!D34 -> 0 | W32: =('Kwh Reading'!O35-'Kwh Reading'!O34)*1000 -> 0
A33: Total | E33: =SUM(E2:E31) -> -716470 | F33: =SUM(F2:F31) -> -3958800 | G33: =SUM(G2:G31) -> -383300 | I33: =SUM(I2:I31) -> -608150 | J33: =SUM(J2:J31) -> -548390 | K33: =SUM(K2:K31) -> -385160 | L33: =SUM(L2:L31) -> -27545 | M33: =SUM(M2:M31) -> -417260 | N33: =SUM(N2:N31) -> -1667100 | O33: =SUM(O2:O31) -> -914600 | P33: =SUM(P2:P31) -> -1146000 | ... W33: =SUM(W2:W31) -> -283410

Sheet Kwh Reading
A1: Electric Consumption Record (4pm)
A2: Month | B2: BOH-1/ B&C Block GWH | C2: Pastry MWH | D2: Feeder 401-419 KWH | E2: Feeder 301-319 KWH | F2: Kitchen GWH | G2: Feeder 201-208 GWH | H2: Feeder 113-123 | I2: M - Block /PC MWH | J2: Laundry MWH | M2: Feeder 101-112 MWH | N2: Feeder 217-224 | O2: Spa MWH | P2: Feeder 124-134 | Q2: Feeder 209-216 | R2: STP -1 MWH | S2: Reef Club MWH | U2: Room Nights | V2: Total Guests | W2: Food Covers
J3: A | K3: B | L3: C
A4: 44986 | B4: 1.6671 | C4: 383.3 | D4: 230246.57 | E4: 9790317.8 | F4: 3.959 | G4: 1.2134 | H4: 1.146 | I4: 417.26 | J4: 608.15 | K4: 548.39 | L4: 385.16 | M4: 914.6 | N4: 826.2 | O4: 283.41 | P4: 1.1056 | Q4: 801.01 | R4: 27545 | S4: 716.41
A5: 44987 | B5: 1.6683 | C5: 383.56 | D5: 232051.72 | E5: 9793091.8 | F5: 3.9613 | G5: 1.2139 | H5: 1.1467 | I5: 417.55 | J5: 608.72 | K5: 548.7 | L5: 385.51 | M5: 915.02 | N5: 826.62 | O5: 283.63 | P5: 1.1061 | Q5: 801.42 | R5: 27682 | S5: 716.95
A6: 44988 | B6: 1.6695 | C6: 383.82 | D6: 233922.45 | E6: 9796205.9 | F6: 3.9639 | G6: 1.2145 | H6: 1.1475 | I6: 417.86 | J6: 609.31 | K6: 549.05 | L6: 385.88 | M6: 915.54 | N6: 827.12 | O6: 283.84 | P6: 1.1066 | Q6: 801.91 | R6: 27809.5 | S6: 717.51
A7: 44989 | B7: 1.6706 | C7: 384.08 | D7: 235680.05 | E7: 9798931.6 | F7: 3.9663 | G7: 1.2151 | H7: 1.1481 | I7: 418.14 | J7: 609.82 | K7: 549.37 | L7: 386.23 | M7: 915.99 | N7: 827.5 | O7: 284.05 | P7: 1.1072 | Q7: 802.29 | R7: 27936.8 | S7: 718.04
A8: 44990 | B8: 1.6718 | C8: 384.35 | D8: 237546.66 | E8: 9801499.9 | F8: 3.9687 | G8: 1.2156 | H8: 1.1488 | I8: 418.44 | J8: 610.22 | K8: 549.72 | L8: 386.59 | M8: 916.46 | N8: 827.89 | O8: 284.31 | P8: 1.1077 | Q8: 802.69 | R8: 28055.3 | S8: 718.34
A9: 44991 | B9: 1.673 | C9: 384.62 | D9: 239524.5 | E9: 9804517.3 | F9: 3.9712 | G9: 1.2162 | H9: 1.1495 | I9: 418.74 | J9: 610.79 | K9: 550.08 | L9: 387.03 | M9: 916.98 | N9: 828.31 | O9: 284.54 | P9: 1.1082 | Q9: 803.13 | R9: 28184.2 | S9: 718.89
A10: 44992 | B10: 1.674 | C10: 384.89 | D10: 241063.05 | E10: 9806989.5 | F10: 3.9736 | G10: 1.2167 | H10: 1.15 | I10: 418.98 | J10: 611.44 | K10: 550.46 | L10: 387.43 | M10: 917.41 | N10: 828.66 | O10: 284.79 | P10: 1.1087 | Q10: 803.44 | R10: 28305.1 | S10: 719.44
A11: 44993 | B11: 1.6751 | C11: 385.17 | D11: 243120.27 | E11: 9809951.8 | F11: 3.976 | G11: 1.2173 | H11: 1.1506 | I11: 419.26 | J11: 612.08 | K11: 550.82 | L11: 387.83 | M11: 917.89 | N11: 829.08 | O11: 285 | P11: 1.1092 | Q11: 803.73 | R11: 28441.2 | S11: 719.99
A12: 44994 | B12: 1.6764 | C12: 385.43 | D12: 245394.59 | E12: 9812986.1 | F12: 3.9784 | G12: 1.2179 | H12: 1.1513 | I12: 419.55 | J12: 612.65 | K12: 551.2 | L12: 388.19 | M12: 918.4 | N12: 829.51 | O12: 285.27 | P12: 1.1098 | Q12: 804.09 | R12: 28560.7 | S12: 720.54
A13: 44995 | B13: 1.6776 | C13: 385.69 | D13: 247504.41 | E13: 9815978.4 | F13: 3.9808 | G13: 1.2185 | H13: 1.1519 | I13: 419.84 | J13: 613.16 | K13: 551.52 | L13: 388.54 | M13: 918.95 | N13: 829.91 | O13: 285.53 | P13: 1.1103 | Q13: 804.39 | R13: 28696.1 | S13: 721.09
A14: 44996 | B14: 1.6787 | C14: 385.96 | D14: 249609.67 | E14: 9818981.6 | F14: 3.9832 | G14: 1.219 | H14: 1.1525 | I14: 420.14 | J14: 613.73 | K14: 551.88 | L14: 388.88 | M14: 919.46 | N14: 830.38 | O14: 285.79 | P14: 1.1108 | Q14: 804.79 | R14: 28827.7 | S14: 721.65
A15: 44997 | B15: 1.6799 | C15: 386.23 | D15: 251647.36 | E15: 9821548.7 | F15: 3.9857 | G15: 1.2196 | H15: 1.1532 | I15: 420.47 | J15: 614.34 | K15: 552.28 | L15: 389.22 | M15: 920.02 | N15: 830.79 | O15: 286.05 | P15: 1.1113 | Q15: 805.17 | R15: 28963.9 | S15: 721.98
A16: 44998 | B16: 1.6811 | C16: 386.49 | D16: 253718.48 | E16: 9824563 | F16: 3.9881 | G16: 1.2202 | H16: 1.1539 | I16: 420.81 | J16: 614.97 | K16: 552.66 | L16: 389.6 | M16: 920.58 | N16: 831.2 | O16: 286.29 | P16: 1.1119 | Q16: 805.53 | R16: 29092.8 | S16: 722.57
A17: 44999
A18: 45000
A19: 45001
A20: 45002
A21: 45003
A22: 45004
A23: 45005
A24: 45006
A25: 45007
A26: 45008
A27: 45009
A28: 45010
... A32: 45014
A33: 45015 | R33: 0
A34: 45016 | R34: 0 | U34: =SUM(U4:U33) -> 0 | V34: =SUM(V4:V33) -> 0 | W34: =SUM(W4:W33) -> 0
A35: 45017 | R35: 0
S41: ……..

Sheet Kwh area wise 
A2: Month | B2: Total KWH | C2: Reef Club Kitchen KWH | D2: Main Kitchen KWH | E2: Pastry Kitchen KWH | F2: Laundry KWH | G2: STP KWH | H2: Kuda Huraa Accomodation KWH | I2: Guest Room Beach Pavilion & Beach Bungalow KWH | J2: Guest Room Water Bungalow KWH | K2: Spa KWH | L2: Others KWH
A3: ='Kwh Reading'!A4 -> 44986 | B3: =TOTAL!E2 -> 19380 | C3: ='Kwh area wise '!E3 -> 260 | D3: =Submeters!F2 -> 2500 | E3: =Submeters!G2 -> 260 | F3: =(Submeters!I2+Submeters!J2+Submeters!K2) -> 1230 | G3: =Submeters!L2 -> 137 | H3: =(Submeters!M2+Submeters!N2) -> 1490 | I3: =(Submeters!O2+Submeters!P2+Submeters!Q2+Submeters!R2+Submeters!S2+Submeters!T2) -> 2950 | J3: =(Submeters!U2+Submeters!V2) -> 4579.13 | K3: =Submeters!W2 -> 220 | L3: =B3-C3-D3-E3-F3-G3-H3-I3-J3-K3 -> 5753.87
A4: ='Kwh Reading'!A5 -> 44987 | B4: =TOTAL!E3 -> 21050 | C4: =Submeters!E3 -> 560 | D4: =Submeters!F3 -> 2600 | E4: =Submeters!G3 -> 260 | F4: =(Submeters!I3+Submeters!J3+Submeters!K3) -> 1310 | G4: =Submeters!L3 -> 127.5 | H4: =(Submeters!M3+Submeters!N3) -> 1510 | I4: =(Submeters!O3+Submeters!P3+Submeters!Q3+Submeters!R3+Submeters!S3+Submeters!T3) -> 3410 | J4: =(Submeters!U3+Submeters!V3) -> 4984.86 | K4: =Submeters!W3 -> 210 | L4: =B4-C4-D4-E4-F4-G4-H4-I4-J4-K4 -> 6077.64
A5: ='Kwh Reading'!A6 -> 44988 | B5: =TOTAL!E4 -> 19280 | C5: =Submeters!E4 -> 530 | D5: =Submeters!F4 -> 2400 | E5: =Submeters!G4 -> 260 | F5: =(Submeters!I4+Submeters!J4+Submeters!K4) -> 1180 | G5: =Submeters!L4 -> 127.3 | H5: =(Submeters!M4+Submeters!N4) -> 1380 | I5: =(Submeters!O4+Submeters!P4+Submeters!Q4+Submeters!R4+Submeters!S4+Submeters!T4) -> 3010 | J5: =(Submeters!U4+Submeters!V4) -> 4483.3 | K5: =Submeters!W4 -> 210 | L5: =B5-C5-D5-E5-F5-G5-H5-I5-J5-K5 -> 5699.4
A6: ='Kwh Reading'!A7 -> 44989 | B6: =TOTAL!E5 -> 19240 | C6: =Submeters!E5 -> 300 | D6: =Submeters!F5 -> 2400 | E6: =Submeters!G5 -> 270 | F6: =(Submeters!I5+Submeters!J5+Submeters!K5) -> 1110 | G6: =Submeters!L5 -> 118.5 | H6: =(Submeters!M5+Submeters!N5) -> 1500 | I6: =(Submeters!O5+Submeters!P5+Submeters!Q5+Submeters!R5+Submeters!S5+Submeters!T5) -> 2960 | J6: =(Submeters!U5+Submeters!V5) -> 4434.87 | K6: =Submeters!W5 -> 260 | L6: =B6-C6-D6-E6-F6-G6-H6-I6-J6-K6 -> 5886.63
A7: ='Kwh Reading'!A8 -> 44990 | B7: =TOTAL!E6 -> 20170 | C7: =Submeters!E6 -> 550 | D7: =Submeters!F6 -> 2500 | E7: =Submeters!G6 -> 270 | F7: =(Submeters!I6+Submeters!J6+Submeters!K6) -> 1370 | G7: =Submeters!L6 -> 128.9 | H7: =(Submeters!M6+Submeters!N6) -> 1500 | I7: =(Submeters!O6+Submeters!P6+Submeters!Q6+Submeters!R6+Submeters!S6+Submeters!T6) -> 3180 | J7: =(Submeters!U6+Submeters!V6) -> 4995.29 | K7: =Submeters!W6 -> 230 | L7: =B7-C7-D7-E7-F7-G7-H7-I7-J7-K7 -> 5445.81
A8: ='Kwh Reading'!A9 -> 44991 | B8: =TOTAL!E7 -> 18280 | C8: =Submeters!E7 -> 550 | D8: =Submeters!F7 -> 2400 | E8: =Submeters!G7 -> 270 | F8: =(Submeters!I7+Submeters!J7+Submeters!K7) -> 1430 | G8: =Submeters!L7 -> 120.9 | H8: =(Submeters!M7+Submeters!N7) -> 1240 | I8: =(Submeters!O7+Submeters!P7+Submeters!Q7+Submeters!R7+Submeters!S7+Submeters!T7) -> 2590 | J8: =(Submeters!U7+Submeters!V7) -> 4010.71 | K8: =Submeters!W7 -> 250 | L8: =B8-C8-D8-E8-F8-G8-H8-I8-J8-K8 -> 5418.39
A9: ='Kwh Reading'!A10 -> 44992 | B9: =TOTAL!E8 -> 20030 | C9: =Submeters!E8 -> 550 | D9: =Submeters!F8 -> 2400 | E9: =Submeters!G8 -> 280 | F9: =(Submeters!I8+Submeters!J8+Submeters!K8) -> 1400 | G9: =Submeters!L8 -> 136.1 | H9: =(Submeters!M8+Submeters!N8) -> 1380 | I9: =(Submeters!O8+Submeters!P8+Submeters!Q8+Submeters!R8+Submeters!S8+Submeters!T8) -> 2890 | J9: =(Submeters!U8+Submeters!V8) -> 5019.54 | K9: =Submeters!W8 -> 210 | L9: =B9-C9-D9-E9-F9-G9-H9-I9-J9-K9 -> 5764.36
A10: ='Kwh Reading'!A11 -> 44993 | B10: =TOTAL!E9 -> 21310 | C10: =Submeters!E9 -> 550 | D10: =Submeters!F9 -> 2400 | E10: =Submeters!G9 -> 260 | F10: =(Submeters!I9+Submeters!J9+Submeters!K9) -> 1310 | G10: =Submeters!L9 -> 119.5 | H10: =(Submeters!M9+Submeters!N9) -> 1590 | I10: =(Submeters!O9+Submeters!P9+Submeters!Q9+Submeters!R9+Submeters!S9+Submeters!T9) -> 3200 | J10: =(Submeters!U9+Submeters!V9) -> 5308.62 | K10: =Submeters!W9 -> 270 | L10: =B10-C10-D10-E10-F10-G10-H10-I10-J10-K10 -> 6301.88
A11: ='Kwh Reading'!A12 -> 44994 | B11: =TOTAL!E10 -> 20250 | C11: =Submeters!E10 -> 550 | D11: =Submeters!F10 -> 2400 | E11: =Submeters!G10 -> 260 | F11: =(Submeters!I10+Submeters!J10+Submeters!K10) -> 1180 | G11: =Submeters!L10 -> 135.4 | H11: =(Submeters!M10+Submeters!N10) -> 1490 | I11: =(Submeters!O10+Submeters!P10+Submeters!Q10+Submeters!R10+Submeters!S10+Submeters!T10) -> 2950 | J11: =(Submeters!U10+Submeters!V10) -> 5102.08 | K11: =Submeters!W10 -> 260 | L11: =B11-C11-D11-E11-F11-G11-H11-I11-J11-K11 -> 5922.52
A12: ='Kwh Reading'!A13 -> 44995 | B12: =TOTAL!E11 -> 20510 | C12: =Submeters!E11 -> 560 | D12: =Submeters!F11 -> 2400 | E12: =Submeters!G11 -> 270 | F12: =(Submeters!I11+Submeters!J11+Submeters!K11) -> 1270 | G12: =Submeters!L11 -> 131.6 | H12: =(Submeters!M11+Submeters!N11) -> 1400 | I12: =(Submeters!O11+Submeters!P11+Submeters!Q11+Submeters!R11+Submeters!S11+Submeters!T11) -> 2980 | J12: =(Submeters!U11+Submeters!V11) -> 5108.47 | K12: =Submeters!W11 -> 260 | L12: =B12-C12-D12-E12-F12-G12-H12-I12-J12-K12 -> 6129.93
A13: ='Kwh Reading'!A14 -> 44996 | B13: =TOTAL!E12 -> 20140 | C13: =Submeters!E12 -> 330 | D13: =Submeters!F12 -> 2500 | E13: =Submeters!G12 -> 270 | F13: =(Submeters!I12+Submeters!J12+Submeters!K12) -> 1350 | G13: =Submeters!L12 -> 136.2 | H13: =(Submeters!M12+Submeters!N12) -> 1530 | I13: =(Submeters!O12+Submeters!P12+Submeters!Q12+Submeters!R12+Submeters!S12+Submeters!T12) -> 3150 | J13: =(Submeters!U12+Submeters!V12) -> 4604.8 | K13: =Submeters!W12 -> 260 | L13: =B13-C13-D13-E13-F13-G13-H13-I13-J13-K13 -> 6009
A14: ='Kwh Reading'!A15 -> 44997 | B14: =TOTAL!E13 -> 20060 | C14: =Submeters!E13 -> 590 | D14: =Submeters!F13 -> 2400 | E14: =Submeters!G13 -> 260 | F14: =(Submeters!I13+Submeters!J13+Submeters!K13) -> 1390 | G14: =Submeters!L13 -> 128.9 | H14: =(Submeters!M13+Submeters!N13) -> 1540 | I14: =(Submeters!O13+Submeters!P13+Submeters!Q13+Submeters!R13+Submeters!S13+Submeters!T13) -> 3230 | J14: =(Submeters!U13+Submeters!V13) -> 5085.44 | K14: =Submeters!W13 -> 240 | L14: =B14-C14-D14-E14-F14-G14-H14-I14-J14-K14 -> 5195.66
A15: ='Kwh Reading'!A16 -> 44998 | B15: =TOTAL!E14 -> 0 | C15: =Submeters!E14 -> -722570 | D15: =Submeters!F14 -> -3988100 | E15: =Submeters!G14 -> -386490 | F15: =(Submeters!I14+Submeters!J14+Submeters!K14) -> -1557230 | G15: =Submeters!L14 -> -29092.8 | H15: =(Submeters!M14+Submeters!N14) -> -2101910 | I15: =(Submeters!O14+Submeters!P14+Submeters!Q14+Submeters!R14+Submeters!S14+Submeters!T14) -> -6043310 | J15: =(Submeters!U14+Submeters!V14) -> -10078281 | K15: =Submeters!W14 -> -286290 | L15: =B15-C15-D15-E15-F15-G15-H15-I15-J15-K15 -> 25193274
... A30: ='Kwh Reading'!A31 -> 45013 | B30: =TOTAL!E29 -> 0 | C30: =Submeters!E29 -> 0 | D30: =Submeters!F29 -> 0 | E30: =Submeters!G29 -> 0 | F30: =(Submeters!I29+Submeters!J29+Submeters!K29) -> 0 | G30: =Submeters!L29 -> 0 | H30: =(Submeters!M29+Submeters!N29) -> 0 | I30: =(Submeters!O29+Submeters!P29+Submeters!Q29+Submeters!R29+Submeters!S29+Submeters!T29) -> 0 | J30: =(Submeters!U29+Submeters!V29) -> 0 | K30: =Submeters!W29 -> 0 | L30: =B30-C30-D30-E30-F30-G30-H30-I30-J30-K30 -> 0
A31: Total kwh | B31: =SUM(B3:B30) -> 239700 | C31: =SUM(C3:C30) -> -716690 | D31: =SUM(D3:D30) -> -3958800 | E31: =SUM(E3:E30) -> -383300 | F31: =SUM(F3:F30) -> -1541700 | G31: =SUM(G3:G30) -> -27545 | H31: =SUM(H3:H30) -> -2084360 | I31: =SUM(I3:I30) -> -6006810 | ... L31: =SUM(L3:L30) -> 25262879 | M31: =C31+D31+E31+F31+G31+H31+I31+J31+K31+L31 -> 239700
A33: Total $ | B33: =TOTAL!F2 -> 0 | C33: =C31*B33 -> 0 | D33: =D31*B33 -> 0 | E33: =E31*B33 -> 0 | F33: =F31*B33 -> 0 | G33: =G31*B33 -> 0 | H33: =H31*B33 -> 0 | I33: =I31*B33 -> 0 | J33: =J31*B33 -> 0 | K33: =K31*B33 -> 0 | L33: =L31*B33 -> 0 | M33: =C33+D33+E33+F33+G33+H33+I33+J33+K33+L33 -> 0

Sheet  Kwh area wise $ 
A2: Month | B2: $ /Per KWH | C2: Total $ | D2: Reef Club $ | E2: Kitchen $ | F2: Pastry $ | G2: Laundry $ | H2: STP $ | I2: Kuda Huraa Accomodation $ | J2: Guest Room Beach Pavilion & Beach Bungalow $ | K2: Guest Room Water Bungalow $ | L2: Spa $ | M2: Others $
A3: ='Kwh Reading'!A4 -> 44986 | B3: =TOTAL!F2 -> 0 | C3: =D3+E3+F3+G3+H3=I3+J3+K3+L3+M3 -> #REF! | D3: =Submeters!E2*' Kwh area wise $ '!B3 -> 0 | E3: =Submeters!F2*' Kwh area wise $ '!B3 -> 0 | F3: =Submeters!G2*' Kwh area wise $ '!B3 -> 0 | G3: =(Submeters!I2+Submeters!J2+Submeters!K2)*' Kwh area wise $ '!B3 -> 0 | H3: =(Submeters!L2)*' Kwh area wise $ '!B3 -> 0 | I3: =(Submeters!M2+Submeters!N2)*' Kwh area wise $ '!B3 -> 0 | J3: =(Submeters!O2+Submeters!P2+Submeters!Q2+Submeters!R2+Submeters!S2+Submeters!T2)*' Kwh area wise $ '!B3 -> 0 | K3: =(Submeters!U2+Submeters!V2)*' Kwh area wise $ '!B3 -> 0 | L3: =Submeters!W2*' Kwh area wise $ '!B3 -> 0 | M3: =Submeters!#REF!*' Kwh area wise $ '!B3 -> #REF!
A4: ='Kwh Reading'!A5 -> 44987 | B4: =TOTAL!F3 -> 0 | C4: =D4+E4+F4+G4+H4=I4+J4+K4+L4+M4 -> #REF! | D4: =Submeters!E3*' Kwh area wise $ '!B4 -> 0 | E4: =Submeters!F3*' Kwh area wise $ '!B4 -> 0 | F4: =Submeters!G3*' Kwh area wise $ '!B4 -> 0 | G4: =(Submeters!I3+Submeters!J3+Submeters!K3)*' Kwh area wise $ '!B4 -> 0 | H4: =(Submeters!L3)*' Kwh area wise $ '!B4 -> 0 | I4: =(Submeters!M3+Submeters!N3)*' Kwh area wise $ '!B4 -> 0 | J4: =(Submeters!O3+Submeters!P3+Submeters!Q3+Submeters!R3+Submeters!S3+Submeters!T3)*' Kwh area wise $ '!B4 -> 0 | K4: =(Submeters!U3+Submeters!V3)*' Kwh area wise $ '!B4 -> 0 | L4: =Submeters!W3*' Kwh area wise $ '!B4 -> 0 | M4: =Submeters!#REF!*' Kwh area wise $ '!B4 -> #REF!
A5: ='Kwh Reading'!A6 -> 44988 | B5: =TOTAL!F4 -> 0 | C5: =D5+E5+F5+G5+H5=I5+J5+K5+L5+M5 -> #REF! | D5: =Submeters!E4*' Kwh area wise $ '!B5 -> 0 | E5: =Submeters!F4*' Kwh area wise $ '!B5 -> 0 | F5: =Submeters!G4*' Kwh area wise $ '!B5 -> 0 | G5: =(Submeters!I4+Submeters!J4+Submeters!K4)*' Kwh area wise $ '!B5 -> 0 | H5: =(Submeters!L4)*' Kwh area wise $ '!B5 -> 0 | I5: =(Submeters!M4+Submeters!N4)*' Kwh area wise $ '!B5 -> 0 | J5: =(Submeters!O4+Submeters!P4+Submeters!Q4+Submeters!R4+Submeters!S4+Submeters!T4)*' Kwh area wise $ '!B5 -> 0 | K5: =(Submeters!U4+Submeters!V4)*' Kwh area wise $ '!B5 -> 0 | L5: =Submeters!W4*' Kwh area wise $ '!B5 -> 0 | M5: =Submeters!#REF!*' Kwh area wise $ '!B5 -> #REF!
A6: ='Kwh Reading'!A7 -> 44989 | B6: =TOTAL!F5 -> 0 | C6: =D6+E6+F6+G6+H6=I6+J6+K6+L6+M6 -> #REF! | D6: =Submeters!E5*' Kwh area wise $ '!B6 -> 0 | E6: =Submeters!F5*' Kwh area wise $ '!B6 -> 0 | F6: =Submeters!G5*' Kwh area wise $ '!B6 -> 0 | G6: =(Submeters!I5+Submeters!J5+Submeters!K5)*' Kwh area wise $ '!B6 -> 0 | H6: =(Submeters!L5)*' Kwh area wise $ '!B6 -> 0 | I6: =(Submeters!M5+Submeters!N5)*' Kwh area wise $ '!B6 -> 0 | J6: =(Submeters!O5+Submeters!P5+Submeters!Q5+Submeters!R5+Submeters!S5+Submeters!T5)*' Kwh area wise $ '!B6 -> 0 | K6: =(Submeters!U5+Submeters!V5)*' Kwh area wise $ '!B6 -> 0 | L6: =Submeters!W5*' Kwh area wise $ '!B6 -> 0 | M6: =Submeters!#REF!*' Kwh area wise $ '!B6 -> #REF!
A7: ='Kwh Reading'!A8 -> 44990 | B7: =TOTAL!F6 -> 0 | C7: =D7+E7+F7+G7+H7=I7+J7+K7+L7+M7 -> #REF! | D7: =Submeters!E6*' Kwh area wise $ '!B7 -> 0 | E7: =Submeters!F6*' Kwh area wise $ '!B7 -> 0 | F7: =Submeters!G6*' Kwh area wise $ '!B7 -> 0 | G7: =(Submeters!I6+Submeters!J6+Submeters!K6)*' Kwh area wise $ '!B7 -> 0 | H7: =(Submeters!L6)*' Kwh area wise $ '!B7 -> 0 | I7: =(Submeters!M6+Submeters!N6)*' Kwh area wise $ '!B7 -> 0 | J7: =(Submeters!O6+Submeters!P6+Submeters!Q6+Submeters!R6+Submeters!S6+Submeters!T6)*' Kwh area wise $ '!B7 -> 0 | K7: =(Submeters!U6+Submeters!V6)*' Kwh area wise $ '!B7 -> 0 | L7: =Submeters!W6*' Kwh area wise $ '!B7 -> 0 | M7: =Submeters!#REF!*' Kwh area wise $ '!B7 -> #REF!
A8: ='Kwh Reading'!A9 -> 44991 | B8: =TOTAL!F7 -> 0 | C8: =D8+E8+F8+G8+H8=I8+J8+K8+L8+M8 -> #REF! | D8: =Submeters!E7*' Kwh area wise $ '!B8 -> 0 | E8: =Submeters!F7*' Kwh area wise $ '!B8 -> 0 | F8: =Submeters!G7*' Kwh area wise $ '!B8 -> 0 | G8: =(Submeters!I7+Submeters!J7+Submeters!K7)*' Kwh area wise $ '!B8 -> 0 | H8: =(Submeters!L7)*' Kwh area wise $ '!B8 -> 0 | I8: =(Submeters!M7+Submeters!N7)*' Kwh area wise $ '!B8 -> 0 | J8: =(Submeters!O7+Submeters!P7+Submeters!Q7+Submeters!R7+Submeters!S7+Submeters!T7)*' Kwh area wise $ '!B8 -> 0 | K8: =(Submeters!U7+Submeters!V7)*' Kwh area wise $ '!B8 -> 0 | L8: =Submeters!W7*' Kwh area wise $ '!B8 -> 0 | M8: =Submeters!#REF!*' Kwh area wise $ '!B8 -> #REF!
A9: ='Kwh Reading'!A10 -> 44992 | B9: =TOTAL!F8 -> 0 | C9: =D9+E9+F9+G9+H9=I9+J9+K9+L9+M9 -> #REF! | D9: =Submeters!E8*' Kwh area wise $ '!B9 -> 0 | E9: =Submeters!F8*' Kwh area wise $ '!B9 -> 0 | F9: =Submeters!G8*' Kwh area wise $ '!B9 -> 0 | G9: =(Submeters!I8+Submeters!J8+Submeters!K8)*' Kwh area wise $ '!B9 -> 0 | H9: =(Submeters!L8)*' Kwh area wise $ '!B9 -> 0 | I9: =(Submeters!M8+Submeters!N8)*' Kwh area wise $ '!B9 -> 0 | J9: =(Submeters!O8+Submeters!P8+Submeters!Q8+Submeters!R8+Submeters!S8+Submeters!T8)*' Kwh area wise $ '!B9 -> 0 | K9: =(Submeters!U8+Submeters!V8)*' Kwh area wise $ '!B9 -> 0 | L9: =Submeters!W8*' Kwh area wise $ '!B9 -> 0 | M9: =Submeters!#REF!*' Kwh area wise $ '!B9 -> #REF!
A10: ='Kwh Reading'!A11 -> 44993 | B10: =TOTAL!F9 -> 0 | C10: =D10+E10+F10+G10+H10=I10+J10+K10+L10+M10 -> #REF! | D10: =Submeters!E9*' Kwh area wise $ '!B10 -> 0 | E10: =Submeters!F9*' Kwh area wise $ '!B10 -> 0 | F10: =Submeters!G9*' Kwh area wise $ '!B10 -> 0 | G10: =(Submeters!I9+Submeters!J9+Submeters!K9)*' Kwh area wise $ '!B10 -> 0 | H10: =(Submeters!L9)*' Kwh area wise $ '!B10 -> 0 | I10: =(Submeters!M9+Submeters!N9)*' Kwh area wise $ '!B10 -> 0 | J10: =(Submeters!O9+Submeters!P9+Submeters!Q9+Submeters!R9+Submeters!S9+Submeters!T9)*' Kwh area wise $ '!B10 -> 0 | K10: =(Submeters!U9+Submeters!V9)*' Kwh area wise $ '!B10 -> 0 | L10: =Submeters!W9*' Kwh area wise $ '!B10 -> 0 | M10: =Submeters!#REF!*' Kwh area wise $ '!B10 -> #REF!
A11: ='Kwh Reading'!A12 -> 44994 | B11: =TOTAL!F10 -> 0 | C11: =D11+E11+F11+G11+H11=I11+J11+K11+L11+M11 -> #REF! | D11: =Submeters!E10*' Kwh area wise $ '!B11 -> 0 | E11: =Submeters!F10*' Kwh area wise $ '!B11 -> 0 | F11: =Submeters!G10*' Kwh area wise $ '!B11 -> 0 | G11: =(Submeters!I10+Submeters!J10+Submeters!K10)*' Kwh area wise $ '!B11 -> 0 | H11: =(Submeters!L10)*' Kwh area wise $ '!B11 -> 0 | I11: =(Submeters!M10+Submeters!N10)*' Kwh area wise $ '!B11 -> 0 | J11: =(Submeters!O10+Submeters!P10+Submeters!Q10+Submeters!R10+Submeters!S10+Submeters!T10)*' Kwh area wise $ '!B11 -> 0 | K11: =(Submeters!U10+Submeters!V10)*' Kwh area wise $ '!B11 -> 0 | L11: =Submeters!W10*' Kwh area wise $ '!B11 -> 0 | M11: =Submeters!#REF!*' Kwh area wise $ '!B11 -> #REF!
A12: ='Kwh Reading'!A13 -> 44995 | B12: =TOTAL!F11 -> 0 | C12: =D12+E12+F12+G12+H12=I12+J12+K12+L12+M12 -> #REF! | D12: =Submeters!E11*' Kwh area wise $ '!B12 -> 0 | E12: =Submeters!F11*' Kwh area wise $ '!B12 -> 0 | F12: =Submeters!G11*' Kwh area wise $ '!B12 -> 0 | G12: =(Submeters!I11+Submeters!J11+Submeters!K11)*' Kwh area wise $ '!B12 -> 0 | H12: =(Submeters!L11)*' Kwh area wise $ '!B12 -> 0 | I12: =(Submeters!M11+Submeters!N11)*' Kwh area wise $ '!B12 -> 0 | J12: =(Submeters!O11+Submeters!P11+Submeters!Q11+Submeters!R11+Submeters!S11+Submeters!T11)*' Kwh area wise $ '!B12 -> 0 | K12: =(Submeters!U11+Submeters!V11)*' Kwh area wise $ '!B12 -> 0 | L12: =Submeters!W11*' Kwh area wise $ '!B12 -> 0 | M12: =Submeters!#REF!*' Kwh area wise $ '!B12 -> #REF!
A13: ='Kwh Reading'!A14 -> 44996 | B13: =TOTAL!F12 -> 0 | C13: =D13+E13+F13+G13+H13=I13+J13+K13+L13+M13 -> #REF! | D13: =Submeters!E12*' Kwh area wise $ '!B13 -> 0 | E13: =Submeters!F12*' Kwh area wise $ '!B13 -> 0 | F13: =Submeters!G12*' Kwh area wise $ '!B13 -> 0 | G13: =(Submeters!I12+Submeters!J12+Submeters!K12)*' Kwh area wise $ '!B13 -> 0 | H13: =(Submeters!L12)*' Kwh area wise $ '!B13 -> 0 | I13: =(Submeters!M12+Submeters!N12)*' Kwh area wise $ '!B13 -> 0 | J13: =(Submeters!O12+Submeters!P12+Submeters!Q12+Submeters!R12+Submeters!S12+Submeters!T12)*' Kwh area wise $ '!B13 -> 0 | K13: =(Submeters!U12+Submeters!V12)*' Kwh area wise $ '!B13 -> 0 | L13: =Submeters!W12*' Kwh area wise $ '!B13 -> 0 | M13: =Submeters!#REF!*' Kwh area wise $ '!B13 -> #REF!
A14: ='Kwh Reading'!A15 -> 44997 | B14: =TOTAL!F13 -> 0 | C14: =D14+E14+F14+G14+H14=I14+J14+K14+L14+M14 -> #REF! | D14: =Submeters!E13*' Kwh area wise $ '!B14 -> 0 | E14: =Submeters!F13*' Kwh area wise $ '!B14 -> 0 | F14: =Submeters!G13*' Kwh area wise $ '!B14 -> 0 | G14: =(Submeters!I13+Submeters!J13+Submeters!K13)*' Kwh area wise $ '!B14 -> 0 | H14: =(Submeters!L13)*' Kwh area wise $ '!B14 -> 0 | I14: =(Submeters!M13+Submeters!N13)*' Kwh area wise $ '!B14 -> 0 | J14: =(Submeters!O13+Submeters!P13+Submeters!Q13+Submeters!R13+Submeters!S13+Submeters!T13)*' Kwh area wise $ '!B14 -> 0 | K14: =(Submeters!U13+Submeters!V13)*' Kwh area wise $ '!B14 -> 0 | L14: =Submeters!W13*' Kwh area wise $ '!B14 -> 0 | M14: =Submeters!#REF!*' Kwh area wise $ '!B14 -> #REF!
... A30: ='Kwh Reading'!A31 -> 45013 | B30: =TOTAL!F29 -> 0 | C30: =D30+E30+F30+G30+H30=I30+J30+K30+L30+M30 -> #REF! | D30: =Submeters!E29*' Kwh area wise $ '!B30 -> 0 | E30: =Submeters!F29*' Kwh area wise $ '!B30 -> 0 | F30: =Submeters!G29*' Kwh area wise $ '!B30 -> 0 | G30: =(Submeters!I29+Submeters!J29+Submeters!K29)*' Kwh area wise $ '!B30 -> 0 | H30: =(Submeters!L29)*' Kwh area wise $ '!B30 -> 0 | I30: =(Submeters!M29+Submeters!N29)*' Kwh area wise $ '!B30 -> 0 | J30: =(Submeters!O29+Submeters!P29+Submeters!Q29+Submeters!R29+Submeters!S29+Submeters!T29)*' Kwh area wise $ '!B30 -> 0 | K30: =(Submeters!U29+Submeters!V29)*' Kwh area wise $ '!B30 -> 0 | L30: =Submeters!W29*' Kwh area wise $ '!B30 -> 0 | M30: =Submeters!#REF!*' Kwh area wise $ '!B30 -> #REF!
A31: Total | C31: =SUM(C3:C30) -> #REF! | D31: =SUM(D3:D30) -> 0 | E31: =SUM(E3:E30) -> 0 | F31: =SUM(F3:F30) -> 0 | G31: =SUM(G3:G30) -> 0 | H31: =SUM(H3:H30) -> 0 | I31: =SUM(I3:I30) -> 0 | J31: =SUM(J3:J30) -> 0 | ... M31: =SUM(M3:M30) -> #REF! | N31: =D31+E31+F31+G31+H31+I31+J31+K31+L31+M31 -> #REF!

Sheet Water Reading
B1: Meter 1 | C1: Meter 2 | D1: Meter 6 | E1: Meter 8 | F1: Meter 7 | G1: Meter 9 | H1: Meter 3 | I1: Meter 5 | J1: Meter 10 | K1: Meter 13 | L1: Meter 16 | M1: Meter 17 | N1: Meter 15 | O1: Meter 14 | P1: Meter 4 | Q1: Meter 11 | R1: Meter 12 | S1: Meter 18
A2: Date | B2: Main Meter 1 | C2: Main Meter 2 | D2: Beach Bunglow | E2: Kuda Huraa staff | F2: Bodu hura staff | G2: Laundry | H2: Water Bunglow | I2: Main Kitchen | J2: Second stage | K2: Supply jetty | L2: Staff housing A | M2: Staff housing B | N2: Spa | O2: Staff jetty | P2: Main pool | Q2: Reef club pool | R2: Reef club kitchen | S2: STP Product
A3: 44986 | B3: 34866 | C3: 54872 | D3: 311328 | E3: 291053 | F3: 28108 | G3: 126434 | H3: 2769 | I3: 81336 | J3: 24460 | K3: 1024 | L3: 19789 | M3: 29130 | N3: 9271 | O3: 2609 | P3: 33745 | Q3: 2651 | R3: 1271 | S3: 70596
A4: 44987 | B4: 34994 | C4: 55100 | D4: 311510 | E4: 291120 | F4: 28134 | G4: 126459 | H4: 2790 | I4: 81360 | J4: 24466 | K4: 1024 | L4: 19791 | M4: 29137 | N4: 9273 | O4: 2611 | P4: 33766 | Q4: 2658 | R4: 1276 | S4: 70596
A5: 44988 | B5: 35124 | C5: 55333 | D5: 311673 | E5: 291198 | F5: 28167 | G5: 126485 | H5: 2820 | I5: 81370 | J5: 24473 | K5: 1024 | L5: 19794 | M5: 29144 | N5: 9276 | O5: 2613 | P5: 33782 | Q5: 2665 | R5: 1281 | S5: 70596
A6: 44989 | B6: 35243 | C6: 55546 | D6: 311791 | E6: 291279 | F6: 28192 | G6: 126510 | H6: 2856 | I6: 81405 | J6: 24480 | K6: 1024 | L6: 19797 | M6: 29149 | N6: 9291 | O6: 2613 | P6: 33806 | Q6: 2672 | R6: 1287 | S6: 70596
A7: 44990 | B7: 35373 | C7: 55777 | D7: 311933 | E7: 291384 | F7: 28222 | G7: 126533 | H7: 2893 | I7: 81406 | J7: 24486 | K7: 1024 | L7: 19799 | M7: 29156 | N7: 9331 | O7: 2615 | P7: 33806 | Q7: 2673 | R7: 1287 | S7: 70596
A8: 44991 | B8: 35502 | C8: 56007 | D8: 312051 | E8: 291503 | F8: 28254 | G8: 126558 | H8: 2927 | I8: 81423 | J8: 24493 | K8: 1024 | L8: 19803 | M8: 29163 | N8: 9386 | O8: 2616 | P8: 33822 | Q8: 2677 | R8: 1292 | S8: 71198
A9: 44992 | B9: 35630 | C9: 56234 | D9: 312158 | E9: 291622 | F9: 28283 | G9: 126586 | H9: 2958 | I9: 81435 | J9: 24500 | K9: 1024 | L9: 19805 | M9: 29167 | N9: 9447 | O9: 2618 | P9: 33832 | Q9: 2687 | R9: 1298 | S9: 71320
A10: 44993 | B10: 35752 | C10: 56455 | D10: 312286 | E10: 291724 | F10: 28283 | G10: 126613 | H10: 2976 | I10: 81453 | J10: 24506 | K10: 1024 | L10: 19808 | M10: 29173 | N10: 9489 | O10: 2619 | P10: 33849 | Q10: 2714 | R10: 1302 | S10: 71441
A11: 44994 | B11: 35882 | C11: 56687 | D11: 312412 | E11: 291829 | F11: 28344 | G11: 126636 | H11: 3003 | I11: 81476 | J11: 24513 | K11: 1024 | L11: 19811 | M11: 29181 | N11: 9528 | O11: 2621 | P11: 33872 | Q11: 2726 | R11: 1307 | S11: 71552
A12: 44995 | B12: 36051 | C12: 56904 | D12: 312573 | E12: 291922 | F12: 28374 | G12: 126663 | H12: 3029 | I12: 81496 | J12: 24519 | K12: 1024 | L12: 19814 | M12: 29186 | N12: 9571 | O12: 2623 | P12: 33889 | Q12: 2730 | R12: 1311 | S12: 71697
A13: 44996 | B13: 36174 | C13: 57123 | D13: 312701 | E13: 292037 | F13: 28402 | G13: 126688 | H13: 3060 | I13: 81502 | J13: 24525 | K13: 1024 | L13: 19817 | M13: 29190 | N13: 9620 | O13: 2623 | P13: 33894 | Q13: 2737 | R13: 1317 | S13: 71802
A14: 44997 | B14: 36317 | C14: 57374 | D14: 312864 | E14: 292143 | F14: 28435 | G14: 126713 | H14: 3088 | I14: 81518 | J14: 24532 | K14: 1024 | L14: 19821 | M14: 29195 | N14: 9665 | O14: 2625 | P14: 33910 | Q14: 2749 | R14: 1318 | S14: 71802
A15: 44998 | B15: 36449 | C15: 57607 | D15: 313003 | E15: 292248 | F15: 28465 | G15: 126740 | H15: 3115 | I15: 81535 | J15: 24539 | K15: 1024 | L15: 19824 | M15: 29201 | N15: 9715 | O15: 2627 | P15: 33926 | Q15: 2758 | R15: 1325 | S15: 71802
A16: 44999 | K16: 1024
A17: 45000 | K17: 1024
A18: 45001 | K18: 1024
A19: 45002 | K19: 1024
A20: 45003 | K20: 1024
A21: 45004 | K21: 1024
A22: 45005 | K22: 1024
A23: 45006 | K23: 1024
A24: 45007 | K24: 1024
A25: 45008 | K25: 1024
A26: 45009 | K26: 1024
A27: 45010 | K27: 1024
... A33: 45016 | K33: 1024
A34: 45017

Sheet Water consumption
A2: Date | B2: RO production (Ro 1 : 4) | C2: Total Consumption M3 (Meter 1 : 2) | E2: Water Bunglow | G2: Beach bunglow | I2: Main Pool | K2: Main kitchen | M2: Reef club kitchen | O2: Reef club pool | Q2: Bodu Huraa staff | S2: Kuda Huraa staff | U2: SPA | W2: Laundry | Y2: Second stage | AA2: Total | AC2: Total STP product
C3: M3 | D3: % of Total production | E3: M3 | F3: % | G3: M3 | H3: % | I3: M3 | J3: % | K3: M3 | L3: % | M3: M3 | N3: % | O3: M3 | P3: % | Q3: M3 | R3: % | S3: M3 | T3: % | U3: M3 | V3: % | W3: M3 | X3: % | Y3: M3 | Z3: % | AA3: M3 | AB3: % | AC3: M3 | AD3: %
A4: ='Water Reading'!A3 -> 44986 | B4: =TOTAL!I2 -> 351 | C4: =('Water Reading'!B4-'Water Reading'!B3)+('Water Reading'!C4-'Water Reading'!C3) -> 356 | D4: =C4/B4 -> 1.014245 | E4: ='Water Reading'!H4-'Water Reading'!H3 -> 21 | F4: =E4/C4 -> 0.058988764 | G4: =('Water Reading'!D4-'Water Reading'!D3)-('Water Reading'!R4-'Water Reading'!R3)-('Water Reading'!Q4-'Water Reading'!Q3) -> 170 | H4: =G4/C4 -> 0.47752809 | I4: ='Water Reading'!P4-'Water Reading'!P3 -> 21 | J4: =I4/C4 -> 0.058988764 | K4: =('Water Reading'!I4-'Water Reading'!I3)-('Water Reading'!P4-'Water Reading'!P3) -> 3 | L4: =K4/C4 -> 0.0084269663 | M4: ='Water Reading'!R4-'Water Reading'!R3 -> 5 | N4: =M4/C4 -> 0.014044944 | O4: ='Water Reading'!Q4-'Water Reading'!Q3 -> 7 | P4: =O4/C4 -> 0.019662921 | Q4: ='Water Reading'!F4-'Water Reading'!F3 -> 26 | R4: =Q4/C4 -> 0.073033708 | S4: ='Water Reading'!E4-'Water Reading'!E3 -> 67 | T4: =S4/C4 -> 0.18820225 | U4: ='Water Reading'!N4-'Water Reading'!N3 -> 2 | V4: =U4/E4 -> 0.095238095 | W4: ='Water Reading'!G4-'Water Reading'!G3 -> 25 | X4: =W4/C4 -> 0.070224719 | Y4: ='Water Reading'!J4-'Water Reading'!J3 -> 6 | Z4: =Y4/C4 -> 0.016853933 | AA4: =E4+I4+K4+M4+O4+G4+Q4+S4+W4+Y4 -> 351 | AB4: =AA4/B4 -> 1 | AC4: ='Water Reading'!S4-'Water Reading'!S3 -> 0 | AD4: =AC4/C4 -> 0
A5: ='Water Reading'!A4 -> 44987 | B5: =TOTAL!I3 -> 347 | C5: =('Water Reading'!B5-'Water Reading'!B4)+('Water Reading'!C5-'Water Reading'!C4) -> 363 | D5: =C5/B5 -> 1.0461095 | E5: ='Water Reading'!H5-'Water Reading'!H4 -> 30 | F5: =E5/C5 -> 0.082644628 | G5: =('Water Reading'!D5-'Water Reading'!D4)-('Water Reading'!R5-'Water Reading'!R4)-('Water Reading'!Q5-'Water Reading'!Q4) -> 151 | H5: =G5/C5 -> 0.41597796 | I5: ='Water Reading'!P5-'Water Reading'!P4 -> 16 | J5: =I5/C5 -> 0.044077135 | K5: =('Water Reading'!I5-'Water Reading'!I4)-('Water Reading'!P5-'Water Reading'!P4) -> -6 | L5: =K5/C5 -> -0.016528926 | M5: ='Water Reading'!R5-'Water Reading'!R4 -> 5 | N5: =M5/C5 -> 0.013774105 | O5: ='Water Reading'!Q5-'Water Reading'!Q4 -> 7 | P5: =O5/C5 -> 0.019283747 | Q5: ='Water Reading'!F5-'Water Reading'!F4 -> 33 | R5: =Q5/C5 -> 0.090909091 | S5: ='Water Reading'!E5-'Water Reading'!E4 -> 78 | T5: =S5/C5 -> 0.21487603 | U5: ='Water Reading'!N5-'Water Reading'!N4 -> 3 | V5: =U5/E5 -> 0.1 | W5: ='Water Reading'!G5-'Water Reading'!G4 -> 26 | X5: =W5/C5 -> 0.071625344 | Y5: ='Water Reading'!J5-'Water Reading'!J4 -> 7 | Z5: =Y5/C5 -> 0.019283747 | AA5: =E5+I5+K5+M5+O5+G5+Q5+S5+W5+Y5 -> 347 | AB5: =AA5/B5 -> 1 | AC5: ='Water Reading'!S5-'Water Reading'!S4 -> 0 | AD5: =AC5/C5 -> 0
A6: ='Water Reading'!A5 -> 44988 | B6: =TOTAL!I4 -> 327 | C6: =('Water Reading'!B6-'Water Reading'!B5)+('Water Reading'!C6-'Water Reading'!C5) -> 332 | D6: =C6/B6 -> 1.0152905 | E6: ='Water Reading'!H6-'Water Reading'!H5 -> 36 | F6: =E6/C6 -> 0.10843373 | G6: =('Water Reading'!D6-'Water Reading'!D5)-('Water Reading'!R6-'Water Reading'!R5)-('Water Reading'!Q6-'Water Reading'!Q5) -> 105 | H6: =G6/C6 -> 0.31626506 | I6: ='Water Reading'!P6-'Water Reading'!P5 -> 24 | J6: =I6/C6 -> 0.072289157 | K6: =('Water Reading'!I6-'Water Reading'!I5)-('Water Reading'!P6-'Water Reading'!P5) -> 11 | L6: =K6/C6 -> 0.03313253 | M6: ='Water Reading'!R6-'Water Reading'!R5 -> 6 | N6: =M6/C6 -> 0.018072289 | O6: ='Water Reading'!Q6-'Water Reading'!Q5 -> 7 | P6: =O6/C6 -> 0.021084337 | Q6: ='Water Reading'!F6-'Water Reading'!F5 -> 25 | R6: =Q6/C6 -> 0.075301205 | S6: ='Water Reading'!E6-'Water Reading'!E5 -> 81 | T6: =S6/C6 -> 0.2439759 | U6: ='Water Reading'!N6-'Water Reading'!N5 -> 15 | V6: =U6/E6 -> 0.41666667 | W6: ='Water Reading'!G6-'Water Reading'!G5 -> 25 | X6: =W6/C6 -> 0.075301205 | Y6: ='Water Reading'!J6-'Water Reading'!J5 -> 7 | Z6: =Y6/C6 -> 0.021084337 | AA6: =E6+I6+K6+M6+O6+G6+Q6+S6+W6+Y6 -> 327 | AB6: =AA6/B6 -> 1 | AC6: ='Water Reading'!S6-'Water Reading'!S5 -> 0 | AD6: =AC6/C6 -> 0
A7: ='Water Reading'!A6 -> 44989 | B7: =TOTAL!I5 -> 344 | C7: =('Water Reading'!B7-'Water Reading'!B6)+('Water Reading'!C7-'Water Reading'!C6) -> 361 | D7: =C7/B7 -> 1.0494186 | E7: ='Water Reading'!H7-'Water Reading'!H6 -> 37 | F7: =E7/C7 -> 0.10249307 | G7: =('Water Reading'!D7-'Water Reading'!D6)-('Water Reading'!R7-'Water Reading'!R6)-('Water Reading'!Q7-'Water Reading'!Q6) -> 141 | H7: =G7/C7 -> 0.39058172 | I7: ='Water Reading'!P7-'Water Reading'!P6 -> 0 | J7: =I7/C7 -> 0 | K7: =('Water Reading'!I7-'Water Reading'!I6)-('Water Reading'!P7-'Water Reading'!P6) -> 1 | L7: =K7/C7 -> 0.0027700831 | M7: ='Water Reading'!R7-'Water Reading'!R6 -> 0 | N7: =M7/C7 -> 0 | O7: ='Water Reading'!Q7-'Water Reading'!Q6 -> 1 | P7: =O7/C7 -> 0.0027700831 | Q7: ='Water Reading'!F7-'Water Reading'!F6 -> 30 | R7: =Q7/C7 -> 0.083102493 | S7: ='Water Reading'!E7-'Water Reading'!E6 -> 105 | T7: =S7/C7 -> 0.29085873 | U7: ='Water Reading'!N7-'Water Reading'!N6 -> 40 | V7: =U7/E7 -> 1.0810811 | W7: ='Water Reading'!G7-'Water Reading'!G6 -> 23 | X7: =W7/C7 -> 0.063711911 | Y7: ='Water Reading'!J7-'Water Reading'!J6 -> 6 | Z7: =Y7/C7 -> 0.016620499 | AA7: =E7+I7+K7+M7+O7+G7+Q7+S7+W7+Y7 -> 344 | AB7: =AA7/B7 -> 1 | AC7: ='Water Reading'!S7-'Water Reading'!S6 -> 0 | AD7: =AC7/C7 -> 0
A8: ='Water Reading'!A7 -> 44990 | B8: =TOTAL!I6 -> 352 | C8: =('Water Reading'!B8-'Water Reading'!B7)+('Water Reading'!C8-'Water Reading'!C7) -> 359 | D8: =C8/B8 -> 1.0198864 | E8: ='Water Reading'!H8-'Water Reading'!H7 -> 34 | F8: =E8/C8 -> 0.094707521 | G8: =('Water Reading'!D8-'Water Reading'!D7)-('Water Reading'!R8-'Water Reading'!R7)-('Water Reading'!Q8-'Water Reading'!Q7) -> 109 | H8: =G8/C8 -> 0.30362117 | I8: ='Water Reading'!P8-'Water Reading'!P7 -> 16 | J8: =I8/C8 -> 0.044568245 | K8: =('Water Reading'!I8-'Water Reading'!I7)-('Water Reading'!P8-'Water Reading'!P7) -> 1 | L8: =K8/C8 -> 0.0027855153 | M8: ='Water Reading'!R8-'Water Reading'!R7 -> 5 | N8: =M8/C8 -> 0.013927577 | O8: ='Water Reading'!Q8-'Water Reading'!Q7 -> 4 | P8: =O8/C8 -> 0.011142061 | Q8: ='Water Reading'!F8-'Water Reading'!F7 -> 32 | R8: =Q8/C8 -> 0.08913649 | S8: ='Water Reading'!E8-'Water Reading'!E7 -> 119 | T8: =S8/C8 -> 0.33147632 | U8: ='Water Reading'!N8-'Water Reading'!N7 -> 55 | V8: =U8/E8 -> 1.6176471 | W8: ='Water Reading'!G8-'Water Reading'!G7 -> 25 | X8: =W8/C8 -> 0.069637883 | Y8: ='Water Reading'!J8-'Water Reading'!J7 -> 7 | Z8: =Y8/C8 -> 0.019498607 | AA8: =E8+I8+K8+M8+O8+G8+Q8+S8+W8+Y8 -> 352 | AB8: =AA8/B8 -> 1 | AC8: ='Water Reading'!S8-'Water Reading'!S7 -> 602 | AD8: =AC8/C8 -> 1.6768802
A9: ='Water Reading'!A8 -> 44991 | B9: =TOTAL!I7 -> 337 | C9: =('Water Reading'!B9-'Water Reading'!B8)+('Water Reading'!C9-'Water Reading'!C8) -> 355 | D9: =C9/B9 -> 1.0534125 | E9: ='Water Reading'!H9-'Water Reading'!H8 -> 31 | F9: =E9/C9 -> 0.087323944 | G9: =('Water Reading'!D9-'Water Reading'!D8)-('Water Reading'!R9-'Water Reading'!R8)-('Water Reading'!Q9-'Water Reading'!Q8) -> 91 | H9: =G9/C9 -> 0.25633803 | I9: ='Water Reading'!P9-'Water Reading'!P8 -> 10 | J9: =I9/C9 -> 0.028169014 | K9: =('Water Reading'!I9-'Water Reading'!I8)-('Water Reading'!P9-'Water Reading'!P8) -> 2 | L9: =K9/C9 -> 0.0056338028 | M9: ='Water Reading'!R9-'Water Reading'!R8 -> 6 | N9: =M9/C9 -> 0.016901408 | O9: ='Water Reading'!Q9-'Water Reading'!Q8 -> 10 | P9: =O9/C9 -> 0.028169014 | Q9: ='Water Reading'!F9-'Water Reading'!F8 -> 29 | R9: =Q9/C9 -> 0.081690141 | S9: ='Water Reading'!E9-'Water Reading'!E8 -> 119 | T9: =S9/C9 -> 0.33521127 | U9: ='Water Reading'!N9-'Water Reading'!N8 -> 61 | V9: =U9/E9 -> 1.9677419 | W9: ='Water Reading'!G9-'Water Reading'!G8 -> 28 | X9: =W9/C9 -> 0.078873239 | Y9: ='Water Reading'!J9-'Water Reading'!J8 -> 7 | Z9: =Y9/C9 -> 0.01971831 | AA9: =E9+I9+K9+M9+O9+G9+Q9+S9+W9+Y9 -> 333 | AB9: =AA9/B9 -> 0.98813056 | AC9: ='Water Reading'!S9-'Water Reading'!S8 -> 122 | AD9: =AC9/C9 -> 0.34366197
A10: ='Water Reading'!A9 -> 44992 | B10: =TOTAL!I8 -> 295 | C10: =('Water Reading'!B10-'Water Reading'!B9)+('Water Reading'!C10-'Water Reading'!C9) -> 343 | D10: =C10/B10 -> 1.1627119 | E10: ='Water Reading'!H10-'Water Reading'!H9 -> 18 | F10: =E10/C10 -> 0.052478134 | G10: =('Water Reading'!D10-'Water Reading'!D9)-('Water Reading'!R10-'Water Reading'!R9)-('Water Reading'!Q10-'Water Reading'!Q9) -> 97 | H10: =G10/C10 -> 0.28279883 | I10: ='Water Reading'!P10-'Water Reading'!P9 -> 17 | J10: =I10/C10 -> 0.049562682 | K10: =('Water Reading'!I10-'Water Reading'!I9)-('Water Reading'!P10-'Water Reading'!P9) -> 1 | L10: =K10/C10 -> 0.0029154519 | M10: ='Water Reading'!R10-'Water Reading'!R9 -> 4 | N10: =M10/C10 -> 0.011661808 | O10: ='Water Reading'!Q10-'Water Reading'!Q9 -> 27 | P10: =O10/C10 -> 0.078717201 | Q10: ='Water Reading'!F10-'Water Reading'!F9 -> 0 | R10: =Q10/C10 -> 0 | S10: ='Water Reading'!E10-'Water Reading'!E9 -> 102 | T10: =S10/C10 -> 0.29737609 | U10: ='Water Reading'!N10-'Water Reading'!N9 -> 42 | V10: =U10/E10 -> 2.3333333 | W10: ='Water Reading'!G10-'Water Reading'!G9 -> 27 | X10: =W10/C10 -> 0.078717201 | Y10: ='Water Reading'!J10-'Water Reading'!J9 -> 6 | Z10: =Y10/C10 -> 0.017492711 | AA10: =E10+I10+K10+M10+O10+G10+Q10+S10+W10+Y10 -> 299 | AB10: =AA10/B10 -> 1.0135593 | AC10: ='Water Reading'!S10-'Water Reading'!S9 -> 121 | AD10: =AC10/C10 -> 0.35276968
A11: ='Water Reading'!A10 -> 44993 | B11: =TOTAL!I9 -> 372 | C11: =('Water Reading'!B11-'Water Reading'!B10)+('Water Reading'!C11-'Water Reading'!C10) -> 362 | D11: =C11/B11 -> 0.97311828 | E11: ='Water Reading'!H11-'Water Reading'!H10 -> 27 | F11: =E11/C11 -> 0.074585635 | G11: =('Water Reading'!D11-'Water Reading'!D10)-('Water Reading'!R11-'Water Reading'!R10)-('Water Reading'!Q11-'Water Reading'!Q10) -> 109 | H11: =G11/C11 -> 0.30110497 | I11: ='Water Reading'!P11-'Water Reading'!P10 -> 23 | J11: =I11/C11 -> 0.063535912 | K11: =('Water Reading'!I11-'Water Reading'!I10)-('Water Reading'!P11-'Water Reading'!P10) -> 0 | L11: =K11/C11 -> 0 | M11: ='Water Reading'!R11-'Water Reading'!R10 -> 5 | N11: =M11/C11 -> 0.013812155 | O11: ='Water Reading'!Q11-'Water Reading'!Q10 -> 12 | P11: =O11/C11 -> 0.033149171 | Q11: ='Water Reading'!F11-'Water Reading'!F10 -> 61 | R11: =Q11/C11 -> 0.16850829 | S11: ='Water Reading'!E11-'Water Reading'!E10 -> 105 | T11: =S11/C11 -> 0.29005525 | U11: ='Water Reading'!N11-'Water Reading'!N10 -> 39 | V11: =U11/E11 -> 1.4444444 | W11: ='Water Reading'!G11-'Water Reading'!G10 -> 23 | X11: =W11/C11 -> 0.063535912 | Y11: ='Water Reading'!J11-'Water Reading'!J10 -> 7 | Z11: =Y11/C11 -> 0.019337017 | AA11: =E11+I11+K11+M11+O11+G11+Q11+S11+W11+Y11 -> 372 | AB11: =AA11/B11 -> 1 | AC11: ='Water Reading'!S11-'Water Reading'!S10 -> 111 | AD11: =AC11/C11 -> 0.30662983
A12: ='Water Reading'!A11 -> 44994 | B12: =TOTAL!I10 -> 363 | C12: =('Water Reading'!B12-'Water Reading'!B11)+('Water Reading'!C12-'Water Reading'!C11) -> 386 | D12: =C12/B12 -> 1.0633609 | E12: ='Water Reading'!H12-'Water Reading'!H11 -> 26 | F12: =E12/C12 -> 0.067357513 | G12: =('Water Reading'!D12-'Water Reading'!D11)-('Water Reading'!R12-'Water Reading'!R11)-('Water Reading'!Q12-'Water Reading'!Q11) -> 153 | H12: =G12/C12 -> 0.39637306 | I12: ='Water Reading'!P12-'Water Reading'!P11 -> 17 | J12: =I12/C12 -> 0.044041451 | K12: =('Water Reading'!I12-'Water Reading'!I11)-('Water Reading'!P12-'Water Reading'!P11) -> 3 | L12: =K12/C12 -> 0.0077720207 | M12: ='Water Reading'!R12-'Water Reading'!R11 -> 4 | N12: =M12/C12 -> 0.010362694 | O12: ='Water Reading'!Q12-'Water Reading'!Q11 -> 4 | P12: =O12/C12 -> 0.010362694 | Q12: ='Water Reading'!F12-'Water Reading'!F11 -> 30 | R12: =Q12/C12 -> 0.077720207 | S12: ='Water Reading'!E12-'Water Reading'!E11 -> 93 | T12: =S12/C12 -> 0.24093264 | U12: ='Water Reading'!N12-'Water Reading'!N11 -> 43 | V12: =U12/E12 -> 1.6538462 | W12: ='Water Reading'!G12-'Water Reading'!G11 -> 27 | X12: =W12/C12 -> 0.069948187 | Y12: ='Water Reading'!J12-'Water Reading'!J11 -> 6 | Z12: =Y12/C12 -> 0.015544041 | AA12: =E12+I12+K12+M12+O12+G12+Q12+S12+W12+Y12 -> 363 | AB12: =AA12/B12 -> 1 | AC12: ='Water Reading'!S12-'Water Reading'!S11 -> 145 | AD12: =AC12/C12 -> 0.37564767
A13: ='Water Reading'!A12 -> 44995 | B13: =TOTAL!I11 -> 339 | C13: =('Water Reading'!B13-'Water Reading'!B12)+('Water Reading'!C13-'Water Reading'!C12) -> 342 | D13: =C13/B13 -> 1.0088496 | E13: ='Water Reading'!H13-'Water Reading'!H12 -> 31 | F13: =E13/C13 -> 0.090643275 | G13: =('Water Reading'!D13-'Water Reading'!D12)-('Water Reading'!R13-'Water Reading'!R12)-('Water Reading'!Q13-'Water Reading'!Q12) -> 115 | H13: =G13/C13 -> 0.33625731 | I13: ='Water Reading'!P13-'Water Reading'!P12 -> 5 | J13: =I13/C13 -> 0.014619883 | K13: =('Water Reading'!I13-'Water Reading'!I12)-('Water Reading'!P13-'Water Reading'!P12) -> 1 | L13: =K13/C13 -> 0.0029239766 | M13: ='Water Reading'!R13-'Water Reading'!R12 -> 6 | N13: =M13/C13 -> 0.01754386 | O13: ='Water Reading'!Q13-'Water Reading'!Q12 -> 7 | P13: =O13/C13 -> 0.020467836 | Q13: ='Water Reading'!F13-'Water Reading'!F12 -> 28 | R13: =Q13/C13 -> 0.081871345 | S13: ='Water Reading'!E13-'Water Reading'!E12 -> 115 | T13: =S13/C13 -> 0.33625731 | U13: ='Water Reading'!N13-'Water Reading'!N12 -> 49 | V13: =U13/E13 -> 1.5806452 | W13: ='Water Reading'!G13-'Water Reading'!G12 -> 25 | X13: =W13/C13 -> 0.073099415 | Y13: ='Water Reading'!J13-'Water Reading'!J12 -> 6 | Z13: =Y13/C13 -> 0.01754386 | AA13: =E13+I13+K13+M13+O13+G13+Q13+S13+W13+Y13 -> 339 | AB13: =AA13/B13 -> 1 | AC13: ='Water Reading'!S13-'Water Reading'!S12 -> 105 | AD13: =AC13/C13 -> 0.30701754
