Workbook

Sheet Total
A1: Site Name | B1: Day | C1: Month | D1: Year | E1: Total Electricity Kwh | F1: Electricity Tariff ($/Kwh) | G1: Natual Gas (m3) | H1: Natural Gas $/m3 | I1: Water Utility Supply (m3) m3 | J1: Water Utility Supply (m3) $/m3 | K1: Room Nights
A2: Cairo at The First Residence | B2: 1 | C2: 2 | D2: 2022 | E2: =Elect!BS6 -> 20567.575 | F2: ='Utility Consnsumption'!K13/'Utility Consnsumption'!J13 -> 1.4405136 | G2: =Gas!K7 -> 1389.7 | H2: 3.8 | I2: =Water!H7 -> 261 | J2: 10 | K2: =Elect!BT6 -> 194
A3: Cairo at The First Residence | B3: =B2+1 -> 2 | C3: 2 | D3: 2022 | E3: =Elect!BS7 -> 21197.693 | F3: =F2 -> 1.4405136 | G3: =Gas!K8 -> 1527.6 | H3: 3.8 | I3: =Water!H8 -> 350.9 | J3: 10 | K3: =Elect!BT7 -> 194
A4: Cairo at The First Residence | B4: =B3+1 -> 3 | C4: 2 | D4: 2022 | E4: =Elect!BS8 -> 21392.107 | F4: =F3 -> 1.4405136 | G4: =Gas!K9 -> 1527.6 | H4: 3.8 | I4: =Water!H9 -> 350.9 | J4: 10 | K4: =Elect!BT8 -> 212
A5: Cairo at The First Residence | B5: =B4+1 -> 4 | C5: 2 | D5: 2022 | E5: =Elect!BS9 -> 20634.482 | F5: =F4 -> 1.4405136 | G5: =Gas!K10 -> 1405.1 | H5: 3.8 | I5: =Water!H10 -> 498.8 | J5: 10 | K5: =Elect!BT9 -> 234
A6: Cairo at The First Residence | B6: =B5+1 -> 5 | C6: 2 | D6: 2022 | E6: =Elect!BS10 -> 21277.972 | F6: =F5 -> 1.4405136 | G6: =Gas!K11 -> 1451.3 | H6: 3.8 | I6: =Water!H11 -> 284.2 | J6: 10 | K6: =Elect!BT10 -> 216
A7: Cairo at The First Residence | B7: =B6+1 -> 6 | C7: 2 | D7: 2022 | E7: =Elect!BS11 -> 21292.912 | F7: =F6 -> 1.4405136 | G7: =Gas!K12 -> 1451.3 | H7: 3.8 | I7: =Water!H12 -> 284.2 | J7: 10 | K7: =Elect!BT11 -> 198
A8: Cairo at The First Residence | B8: =B7+1 -> 7 | C8: 2 | D8: 2022 | E8: =Elect!BS12 -> 21163.747 | F8: =F7 -> 1.4405136 | G8: =Gas!K13 -> 1451.3 | H8: 3.8 | I8: =Water!H13 -> 284.2 | J8: 10 | K8: =Elect!BT12 -> 180
A9: Cairo at The First Residence | B9: =B8+1 -> 8 | C9: 2 | D9: 2022 | E9: =Elect!BS13 -> 22864.5 | F9: =F8 -> 1.4405136 | G9: =Gas!K14 -> 1451.3 | H9: 3.8 | I9: =Water!H14 -> 290 | J9: 10 | K9: =Elect!BT13 -> 170
A10: Cairo at The First Residence | B10: =B9+1 -> 9 | C10: 2 | D10: 2022 | E10: =Elect!BS14 -> 22124.987 | F10: =F9 -> 1.4405136 | G10: =Gas!K15 -> 1451.3 | H10: 3.8 | I10: =Water!H15 -> 234.9 | J10: 10 | K10: =Elect!BT14 -> 154
A11: Cairo at The First Residence | B11: =B10+1 -> 10 | C11: 2 | D11: 2022 | E11: =Elect!BS15 -> 20310.153 | F11: =F10 -> 1.4405136 | G11: =Gas!K16 -> 1312.7 | H11: 3.8 | I11: =Water!H16 -> 329.15 | J11: 10 | K11: =Elect!BT15 -> 195
A12: Cairo at The First Residence | B12: =B11+1 -> 11 | C12: 2 | D12: 2022 | E12: =Elect!BS16 -> 22712.118 | F12: =F11 -> 1.4405136 | G12: =Gas!K17 -> 1312.7 | H12: 3.8 | I12: =Water!H17 -> 295.31667 | J12: 10 | K12: =Elect!BT16 -> 209
A13: Cairo at The First Residence | B13: =B12+1 -> 12 | C13: 2 | D13: 2022 | E13: =Elect!BS17 -> 20766.423 | F13: =F12 -> 1.4405136 | G13: =Gas!K18 -> 1312.7 | H13: 3.8 | I13: =Water!H18 -> 303.775 | J13: 10 | K13: =Elect!BT17 -> 192
A14: Cairo at The First Residence | B14: =B13+1 -> 13 | C14: 2 | D14: 2022 | E14: =Elect!BS18 -> 25491.97 | F14: =F13 -> 1.4405136 | G14: =Gas!K19 -> 1312.7 | H14: 3.8 | I14: =Water!H19 -> 303.775 | J14: 10 | K14: =Elect!BT18 -> 228
... A32: Cairo at The First Residence | B32: =B31+1 -> 31 | C32: 2 | D32: 2022 | E32: =Elect!BS36 -> 0 | F32: =F31 -> 1.4405136 | G32: =Gas!K37 -> 1060 | H32: 3.8 | I32: =Water!H37 -> 0 | J32: 10 | K32: =Elect!BT36 -> 0

Sheet Submetering
A1: Site Name | B1: Day | C1: Month | D1: Year | E1: Electricity | F1: Main Feeder -KWh | G1: T2+T8 -KWh | H1: La Gourmandize -KWh | I1: Casino 3rd floor EM -KWh | J1: Casino 3rd floor Normal -KWh | K1: Chiller 1 -KWh | L1: Chiller 2 -KWh | M1: Chiller 3 -KWh | N1: Chiller 4 -KWh | O1: Chiller 5 -KWh | P1: Chiller 6 -KWh | Q1: Cooling towers -KWh | R1: Chiller Pumps -KWh | S1: Cooling Tower Pumps -KWh | T1: Fiber Chiller -KWh | U1: Mall Ceiling light -KWh | V1: LG Bakery -KWh | W1: LG Bakery light ( Old lockers ) -KWh | X1: MCCR1 -KWh | Y1: Children Swimming Pool -KWh | Z1: DPH1 -KWh | AA1: Guest Rooms Emerg. -KWh | AB1: Hotel Hoods -KWh | AC1: Main G2 -KWh | AD1: Old Casino Emergency -KWh | AE1: L / A -KWh | AF1: L / B -KWh | AG1: L / C -KWh | AH1: Water | AI1: Main water meter 1 -m3 | AJ1: Main water meter 2 -m3 | AK1: Main water meter 3 -m3 | AL1: Gas | AM1: Main Gas Flow Meter -m3 | AN1: Laundry Gas Flow Meter -m3 | AO1: Gourmandize Gas Flow Meter -m3 | AP1: Room Nights
A2: Cairo at The First Residence | B2: 1 | C2: 2 | D2: 2022 | F2: =Elect!J6 -> 6679 | G2: =Elect!K6 -> 4420 | H2: =Elect!Q6 -> 360 | I2: =Elect!S6 -> 143 | J2: =Elect!U6 -> 259.5 | K2: =Elect!W6 -> 1564.56 | L2: =Elect!Y6 -> 0 | M2: =Elect!AA6 -> 0 | N2: =Elect!AC6 -> 0 | O2: =Elect!AE6 -> 13.25 | P2: =Elect!AG6 -> 13.25 | Q2: =Elect!AI6 -> 134.62 | R2: =Elect!AK6 -> 1835.39 | S2: =Elect!AM6 -> 148.93 | T2: =Elect!AP6 -> 4.725 | U2: =Elect!AR6 -> 323 | V2: =Elect!AT6 -> 185 | W2: =Elect!AV6 -> 52 | X2: =Elect!AX6 -> 577 | Y2: =Elect!AZ6 -> 5 | Z2: =Elect!BB6 -> 3727 | AA2: =Elect!BD6 -> 214 | AB2: =Elect!BF6 -> 56 | AC2: =Elect!BH6 -> 4674.85 | AD2: =Elect!BL6 -> 63 | AE2: =Elect!BN6 -> 971 | AF2: =Elect!BP6 -> 136 | AG2: =Elect!BR6 -> 111 | AI2: =Water!C7 -> 110.2 | AJ2: =Water!E7 -> 150.8 | AK2: =Water!G7 -> 0 | AM2: =Gas!C7 -> 1060 | AN2: =Gas!E7 -> 329.7 | AO2: =Gas!G7 -> 257 | AP2: =Elect!BT6 -> 194
A3: Cairo at The First Residence | B3: =B2+1 -> 2 | C3: 2 | D3: 2022 | F3: =Elect!J7 -> 6640 | G3: =Elect!K7 -> 4321 | H3: =Elect!Q7 -> 600 | I3: =Elect!S7 -> 145 | J3: =Elect!U7 -> 269 | K3: =Elect!W7 -> 988.45 | L3: =Elect!Y7 -> 0 | M3: =Elect!AA7 -> 0 | N3: =Elect!AC7 -> 0 | O3: =Elect!AE7 -> 13.25 | P3: =Elect!AG7 -> 12.72 | Q3: =Elect!AI7 -> 408.63 | R3: =Elect!AK7 -> 2044.74 | S3: =Elect!AM7 -> 155.29 | T3: =Elect!AP7 -> 4.1625 | U3: =Elect!AR7 -> 338 | V3: =Elect!AT7 -> 161 | W3: =Elect!AV7 -> 43 | X3: =Elect!AX7 -> 575 | Y3: =Elect!AZ7 -> 6 | Z3: =Elect!BB7 -> 4029 | AA3: =Elect!BD7 -> 218 | AB3: =Elect!BF7 -> 127 | AC3: =Elect!BH7 -> 4833.45 | AD3: =Elect!BL7 -> 60 | AE3: =Elect!BN7 -> 937 | AF3: =Elect!BP7 -> 142 | AG3: =Elect!BR7 -> 133 | AI3: =Water!C8 -> 150.8 | AJ3: =Water!E8 -> 191.4 | AK3: =Water!G8 -> 8.7 | AM3: =Gas!C8 -> 1060 | AN3: =Gas!E8 -> 467.6 | AO3: =Gas!G8 -> 0 | AP3: =Elect!BT7 -> 194
A4: Cairo at The First Residence | B4: =B3+1 -> 3 | C4: 2 | D4: 2022 | F4: =Elect!J8 -> 6891 | G4: =Elect!K8 -> 4131 | H4: =Elect!Q8 -> 570 | I4: =Elect!S8 -> 140 | J4: =Elect!U8 -> 246 | K4: =Elect!W8 -> 967.78 | L4: =Elect!Y8 -> 0 | M4: =Elect!AA8 -> 0 | N4: =Elect!AC8 -> 0 | O4: =Elect!AE8 -> 13.78 | P4: =Elect!AG8 -> 13.25 | Q4: =Elect!AI8 -> 399.09 | R4: =Elect!AK8 -> 2267.87 | S4: =Elect!AM8 -> 156.35 | T4: =Elect!AP8 -> 4.3875 | U4: =Elect!AR8 -> 326 | V4: =Elect!AT8 -> 147 | W4: =Elect!AV8 -> 43 | X4: =Elect!AX8 -> 577 | Y4: =Elect!AZ8 -> 6 | Z4: =Elect!BB8 -> 4140 | AA4: =Elect!BD8 -> 224 | AB4: =Elect!BF8 -> 0 | AC4: =Elect!BH8 -> 4645.6 | AD4: =Elect!BL8 -> 60 | AE4: =Elect!BN8 -> 777 | AF4: =Elect!BP8 -> 135 | AG4: =Elect!BR8 -> 128 | AI4: =Water!C9 -> 150.8 | AJ4: =Water!E9 -> 191.4 | AK4: =Water!G9 -> 8.7 | AM4: =Gas!C9 -> 1060 | AN4: =Gas!E9 -> 467.6 | AO4: =Gas!G9 -> 0 | AP4: =Elect!BT8 -> 212
A5: Cairo at The First Residence | B5: =B4+1 -> 4 | C5: 2 | D5: 2022 | F5: =Elect!J9 -> 6741 | G5: =Elect!K9 -> 4176 | H5: =Elect!Q9 -> 600 | I5: =Elect!S9 -> 138 | J5: =Elect!U9 -> 245 | K5: =Elect!W9 -> 795 | L5: =Elect!Y9 -> 0 | M5: =Elect!AA9 -> 0 | N5: =Elect!AC9 -> 0 | O5: =Elect!AE9 -> 13.25 | P5: =Elect!AG9 -> 12.72 | Q5: =Elect!AI9 -> 372.06 | R5: =Elect!AK9 -> 1766.49 | S5: =Elect!AM9 -> 148.4 | T5: =Elect!AP9 -> 4.1625 | U5: =Elect!AR9 -> 332 | V5: =Elect!AT9 -> 158 | W5: =Elect!AV9 -> 36 | X5: =Elect!AX9 -> 530 | Y5: =Elect!AZ9 -> 6 | Z5: =Elect!BB9 -> 4127 | AA5: =Elect!BD9 -> 204 | AB5: =Elect!BF9 -> 54 | AC5: =Elect!BH9 -> 4734.4 | AD5: =Elect!BL9 -> 60 | AE5: =Elect!BN9 -> 830 | AF5: =Elect!BP9 -> 138 | AG5: =Elect!BR9 -> 129 | AI5: =Water!C10 -> 278.4 | AJ5: =Water!E10 -> 211.7 | AK5: =Water!G10 -> 8.7 | AM5: =Gas!C10 -> 1060 | AN5: =Gas!E10 -> 345.1 | AO5: =Gas!G10 -> 125 | AP5: =Elect!BT9 -> 234
A6: Cairo at The First Residence | B6: =B5+1 -> 5 | C6: 2 | D6: 2022 | F6: =Elect!J10 -> 6857 | G6: =Elect!K10 -> 4372 | H6: =Elect!Q10 -> 630 | I6: =Elect!S10 -> 142 | J6: =Elect!U10 -> 250 | K6: =Elect!W10 -> 965.13 | L6: =Elect!Y10 -> 0 | M6: =Elect!AA10 -> 0 | N6: =Elect!AC10 -> 0 | O6: =Elect!AE10 -> 13.78 | P6: =Elect!AG10 -> 13.78 | Q6: =Elect!AI10 -> 399.09 | R6: =Elect!AK10 -> 1835.39 | S6: =Elect!AM10 -> 155.29 | T6: =Elect!AP10 -> 4.6125 | U6: =Elect!AR10 -> 366 | V6: =Elect!AT10 -> 162 | W6: =Elect!AV10 -> 41 | X6: =Elect!AX10 -> 559 | Y6: =Elect!AZ10 -> 6 | Z6: =Elect!BB10 -> 4321 | AA6: =Elect!BD10 -> 139 | AB6: =Elect!BF10 -> 32 | AC6: =Elect!BH10 -> 4777.9 | AD6: =Elect!BL10 -> 60 | AE6: =Elect!BN10 -> 839 | AF6: =Elect!BP10 -> 139 | AG6: =Elect!BR10 -> 130 | AI6: =Water!C11 -> 104.4 | AJ6: =Water!E11 -> 171.1 | AK6: =Water!G11 -> 8.7 | AM6: =Gas!C11 -> 1060 | AN6: =Gas!E11 -> 391.3 | AO6: =Gas!G11 -> 125 | AP6: =Elect!BT10 -> 216
A7: Cairo at The First Residence | B7: =B6+1 -> 6 | C7: 2 | D7: 2022 | F7: =Elect!J11 -> 6703 | G7: =Elect!K11 -> 4233 | H7: =Elect!Q11 -> 360 | I7: =Elect!S11 -> 143 | J7: =Elect!U11 -> 256 | K7: =Elect!W11 -> 1103.46 | L7: =Elect!Y11 -> 0 | M7: =Elect!AA11 -> 0 | N7: =Elect!AC11 -> 0 | O7: =Elect!AE11 -> 13.25 | P7: =Elect!AG11 -> 12.72 | Q7: =Elect!AI11 -> 417.11 | R7: =Elect!AK11 -> 1998.63 | S7: =Elect!AM11 -> 156.88 | T7: =Elect!AP11 -> 4.1625 | U7: =Elect!AR11 -> 315 | V7: =Elect!AT11 -> 167 | W7: =Elect!AV11 -> 43 | X7: =Elect!AX11 -> 578 | Y7: =Elect!AZ11 -> 6 | Z7: =Elect!BB11 -> 4215 | AA7: =Elect!BD11 -> 281 | AB7: =Elect!BF11 -> 77 | AC7: =Elect!BH11 -> 4841.7 | AD7: =Elect!BL11 -> 61 | AE7: =Elect!BN11 -> 848 | AF7: =Elect!BP11 -> 126 | AG7: =Elect!BR11 -> 132 | AI7: =Water!C12 -> 104.4 | AJ7: =Water!E12 -> 171.1 | AK7: =Water!G12 -> 8.7 | AM7: =Gas!C12 -> 1060 | AN7: =Gas!E12 -> 391.3 | AO7: =Gas!G12 -> 125 | AP7: =Elect!BT11 -> 198
A8: Cairo at The First Residence | B8: =B7+1 -> 7 | C8: 2 | D8: 2022 | F8: =Elect!J12 -> 6377 | G8: =Elect!K12 -> 4224 | H8: =Elect!Q12 -> 630 | I8: =Elect!S12 -> 139 | J8: =Elect!U12 -> 245 | K8: =Elect!W12 -> 1308.04 | L8: =Elect!Y12 -> 0 | M8: =Elect!AA12 -> 0 | N8: =Elect!AC12 -> 0 | O8: =Elect!AE12 -> 13.25 | P8: =Elect!AG12 -> 12.72 | Q8: =Elect!AI12 -> 400.15 | R8: =Elect!AK12 -> 2121.06 | S8: =Elect!AM12 -> 155.29 | T8: =Elect!AP12 -> 4.3875 | U8: =Elect!AR12 -> 339 | V8: =Elect!AT12 -> 120 | W8: =Elect!AV12 -> 44 | X8: =Elect!AX12 -> 579 | Y8: =Elect!AZ12 -> 6 | Z8: =Elect!BB12 -> 4124 | AA8: =Elect!BD12 -> 220 | AB8: =Elect!BF12 -> 34 | AC8: =Elect!BH12 -> 4675.85 | AD8: =Elect!BL12 -> 60 | AE8: =Elect!BN12 -> 848 | AF8: =Elect!BP12 -> 119 | AG8: =Elect!BR12 -> 124 | AI8: =Water!C13 -> 104.4 | AJ8: =Water!E13 -> 171.1 | AK8: =Water!G13 -> 8.7 | AM8: =Gas!C13 -> 1060 | AN8: =Gas!E13 -> 391.3 | AO8: =Gas!G13 -> 125 | AP8: =Elect!BT12 -> 180
A9: Cairo at The First Residence | B9: =B8+1 -> 8 | C9: 2 | D9: 2022 | F9: =Elect!J13 -> 6377 | G9: =Elect!K13 -> 4454 | H9: =Elect!Q13 -> 540 | I9: =Elect!S13 -> 145 | J9: =Elect!U13 -> 262 | K9: =Elect!W13 -> 1417.75 | L9: =Elect!Y13 -> 0 | M9: =Elect!AA13 -> 0 | N9: =Elect!AC13 -> 0 | O9: =Elect!AE13 -> 15.37 | P9: =Elect!AG13 -> 15.37 | Q9: =Elect!AI13 -> 425.59 | R9: =Elect!AK13 -> 2145.97 | S9: =Elect!AM13 -> 164.3 | T9: =Elect!AP13 -> 4.95 | U9: =Elect!AR13 -> 358 | V9: =Elect!AT13 -> 150 | W9: =Elect!AV13 -> 46 | X9: =Elect!AX13 -> 619 | Y9: =Elect!AZ13 -> 6 | Z9: =Elect!BB13 -> 4735 | AA9: =Elect!BD13 -> 267 | AB9: =Elect!BF13 -> 34 | AC9: =Elect!BH13 -> 5543.2 | AD9: =Elect!BL13 -> 71 | AE9: =Elect!BN13 -> 1004 | AF9: =Elect!BP13 -> 140 | AG9: =Elect!BR13 -> 155 | AI9: =Water!C14 -> 104.4 | AJ9: =Water!E14 -> 185.6 | AK9: =Water!G14 -> 0 | AM9: =Gas!C14 -> 1060 | AN9: =Gas!E14 -> 391.3 | AO9: =Gas!G14 -> 125 | AP9: =Elect!BT13 -> 170
A10: Cairo at The First Residence | B10: =B9+1 -> 9 | C10: 2 | D10: 2022 | F10: =Elect!J14 -> 6885 | G10: =Elect!K14 -> 5180 | H10: =Elect!Q14 -> 600 | I10: =Elect!S14 -> 168 | J10: =Elect!U14 -> 298 | K10: =Elect!W14 -> 1298.5 | L10: =Elect!Y14 -> 0 | M10: =Elect!AA14 -> 0 | N10: =Elect!AC14 -> 0 | O10: =Elect!AE14 -> 14.31 | P10: =Elect!AG14 -> 13.78 | Q10: =Elect!AI14 -> 499.26 | R10: =Elect!AK14 -> 2422.63 | S10: =Elect!AM14 -> 187.62 | T10: =Elect!AP14 -> 4.3875 | U10: =Elect!AR14 -> 360 | V10: =Elect!AT14 -> 140 | W10: =Elect!AV14 -> 51 | X10: =Elect!AX14 -> 678 | Y10: =Elect!AZ14 -> 7 | Z10: =Elect!BB14 -> 3584 | AA10: =Elect!BD14 -> 217 | AB10: =Elect!BF14 -> 34 | AC10: =Elect!BH14 -> 5128.5 | AD10: =Elect!BL14 -> 63 | AE10: =Elect!BN14 -> 884 | AF10: =Elect!BP14 -> 126 | AG10: =Elect!BR14 -> 139 | AI10: =Water!C15 -> 104.4 | AJ10: =Water!E15 -> 127.6 | AK10: =Water!G15 -> 2.9 | AM10: =Gas!C15 -> 1060 | AN10: =Gas!E15 -> 391.3 | AO10: =Gas!G15 -> 125 | AP10: =Elect!BT14 -> 154
A11: Cairo at The First Residence | B11: =B10+1 -> 10 | C11: 2 | D11: 2022 | F11: =Elect!J15 -> 7165 | G11: =Elect!K15 -> 3454 | H11: =Elect!Q15 -> 570 | I11: =Elect!S15 -> 118 | J11: =Elect!U15 -> 207 | K11: =Elect!W15 -> 827.33 | L11: =Elect!Y15 -> 0 | M11: =Elect!AA15 -> 0 | N11: =Elect!AC15 -> 0 | O11: =Elect!AE15 -> 12.19 | P11: =Elect!AG15 -> 11.13 | Q11: =Elect!AI15 -> 305.28 | R11: =Elect!AK15 -> 1517.92 | S11: =Elect!AM15 -> 118.19 | T11: =Elect!AP15 -> 3.7125 | U11: =Elect!AR15 -> 322 | V11: =Elect!AT15 -> 113 | W11: =Elect!AV15 -> 32 | X11: =Elect!AX15 -> 443 | Y11: =Elect!AZ15 -> 5 | Z11: =Elect!BB15 -> 4266 | AA11: =Elect!BD15 -> 192 | AB11: =Elect!BF15 -> 34 | AC11: =Elect!BH15 -> 4372.4 | AD11: =Elect!BL15 -> 53 | AE11: =Elect!BN15 -> 744 | AF11: =Elect!BP15 -> 104 | AG11: =Elect!BR15 -> 116 | AI11: =Water!C16 -> 150.8 | AJ11: =Water!E16 -> 178.35 | AK11: =Water!G16 -> 0 | AM11: =Gas!C16 -> 1060 | AN11: =Gas!E16 -> 252.7 | AO11: =Gas!G16 -> 55 | AP11: =Elect!BT15 -> 195
A12: Cairo at The First Residence | B12: =B11+1 -> 11 | C12: 2 | D12: 2022 | F12: =Elect!J16 -> 7160 | G12: =Elect!K16 -> 4364 | H12: =Elect!Q16 -> 600 | I12: =Elect!S16 -> 145 | J12: =Elect!U16 -> 260 | K12: =Elect!W16 -> 1340.37 | L12: =Elect!Y16 -> 0 | M12: =Elect!AA16 -> 0 | N12: =Elect!AC16 -> 0 | O12: =Elect!AE16 -> 14.31 | P12: =Elect!AG16 -> 13.25 | Q12: =Elect!AI16 -> 430.89 | R12: =Elect!AK16 -> 2105.16 | S12: =Elect!AM16 -> 161.65 | T12: =Elect!AP16 -> 4.3875 | U12: =Elect!AR16 -> 333 | V12: =Elect!AT16 -> 101 | W12: =Elect!AV16 -> 38 | X12: =Elect!AX16 -> 586 | Y12: =Elect!AZ16 -> 6 | Z12: =Elect!BB16 -> 4687 | AA12: =Elect!BD16 -> 199 | AB12: =Elect!BF16 -> 34 | AC12: =Elect!BH16 -> 4898.1 | AD12: =Elect!BL16 -> 62 | AE12: =Elect!BN16 -> 840 | AF12: =Elect!BP16 -> 122 | AG12: =Elect!BR16 -> 144 | AI12: =Water!C17 -> 150.8 | AJ12: =Water!E17 -> 144.51667 | AK12: =Water!G17 -> 0 | AM12: =Gas!C17 -> 1060 | AN12: =Gas!E17 -> 252.7 | AO12: =Gas!G17 -> 55 | AP12: =Elect!BT16 -> 209
A13: Cairo at The First Residence | B13: =B12+1 -> 12 | C13: 2 | D13: 2022 | F13: =Elect!J17 -> 6495 | G13: =Elect!K17 -> 3913 | H13: =Elect!Q17 -> 300 | I13: =Elect!S17 -> 135 | J13: =Elect!U17 -> 236 | K13: =Elect!W17 -> 1291.08 | L13: =Elect!Y17 -> 0 | M13: =Elect!AA17 -> 0 | N13: =Elect!AC17 -> 0 | O13: =Elect!AE17 -> 14.31 | P13: =Elect!AG17 -> 13.78 | Q13: =Elect!AI17 -> 378.95 | R13: =Elect!AK17 -> 1876.73 | S13: =Elect!AM17 -> 144.16 | T13: =Elect!AP17 -> 4.1625 | U13: =Elect!AR17 -> 338 | V13: =Elect!AT17 -> 128 | W13: =Elect!AV17 -> 37 | X13: =Elect!AX17 -> 540 | Y13: =Elect!AZ17 -> 6 | Z13: =Elect!BB17 -> 4282 | AA13: =Elect!BD17 -> 201 | AB13: =Elect!BF17 -> 34 | AC13: =Elect!BH17 -> 4682.25 | AD13: =Elect!BL17 -> 180 | AE13: =Elect!BN17 -> 799 | AF13: =Elect!BP17 -> 116 | AG13: =Elect!BR17 -> 134 | AI13: =Water!C18 -> 150.8 | AJ13: =Water!E18 -> 152.975 | AK13: =Water!G18 -> 0 | AM13: =Gas!C18 -> 1060 | AN13: =Gas!E18 -> 252.7 | AO13: =Gas!G18 -> 55 | AP13: =Elect!BT17 -> 192
A14: Cairo at The First Residence | B14: =B13+1 -> 13 | C14: 2 | D14: 2022 | F14: =Elect!J18 -> 7359 | G14: =Elect!K18 -> 5567 | H14: =Elect!Q18 -> 690 | I14: =Elect!S18 -> 146 | J14: =Elect!U18 -> 274 | K14: =Elect!W18 -> 1583.11 | L14: =Elect!Y18 -> 38.69 | M14: =Elect!AA18 -> 29.68 | N14: =Elect!AC18 -> 59.36 | O14: =Elect!AE18 -> 11.66 | P14: =Elect!AG18 -> 11.66 | Q14: =Elect!AI18 -> 526.29 | R14: =Elect!AK18 -> 2657.42 | S14: =Elect!AM18 -> 156.35 | T14: =Elect!AP18 -> 53.55 | U14: =Elect!AR18 -> 327 | V14: =Elect!AT18 -> 162 | W14: =Elect!AV18 -> 53 | X14: =Elect!AX18 -> 722 | Y14: =Elect!AZ18 -> 6 | Z14: =Elect!BB18 -> 5435 | AA14: =Elect!BD18 -> 242 | AB14: =Elect!BF18 -> 34 | AC14: =Elect!BH18 -> 5334.2 | AD14: =Elect!BL18 -> 280 | AE14: =Elect!BN18 -> 823 | AF14: =Elect!BP18 -> 141 | AG14: =Elect!BR18 -> 146 | AI14: =Water!C19 -> 150.8 | AJ14: =Water!E19 -> 152.975 | AK14: =Water!G19 -> 0 | AM14: =Gas!C19 -> 1060 | AN14: =Gas!E19 -> 252.7 | AO14: =Gas!G19 -> 55 | AP14: =Elect!BT18 -> 228
... A32: Cairo at The First Residence | B32: =B31+1 -> 31 | C32: 2 | D32: 2022 | F32: =Elect!J36 -> 0 | G32: =Elect!K36 -> 0 | H32: =Elect!Q36 -> 0 | I32: =Elect!S36 -> 0 | J32: =Elect!U36 -> 0 | K32: =Elect!W36 -> 0 | L32: =Elect!Y36 -> 0 | M32: =Elect!AA36 -> 0 | N32: =Elect!AC36 -> 0 | O32: =Elect!AE36 -> 0 | P32: =Elect!AG36 -> 0 | Q32: =Elect!AI36 -> 0 | R32: =Elect!AK36 -> 0 | S32: =Elect!AM36 -> 0 | T32: =Elect!AP36 -> 0 | U32: =Elect!AR36 -> 0 | V32: =Elect!AT36 -> 0 | W32: =Elect!AV36 -> 0 | X32: =Elect!AX36 -> 0 | Y32: =Elect!AZ36 -> 0 | Z32: =Elect!BB36 -> 0 | AA32: =Elect!BD36 -> 0 | AB32: =Elect!BF36 -> 0 | AC32: =Elect!BH36 -> 0 | AD32: =Elect!BL36 -> 0 | AE32: =Elect!BN36 -> 0 | AF32: =Elect!BP36 -> 0 | AG32: =Elect!BR36 -> 0 | AI32: =Water!C37 -> 0 | AJ32: =Water!E37 -> 0 | AK32: =Water!G37 -> 0 | AM32: =Gas!C37 -> 1060 | AN32: =Gas!E37 -> 0 | AO32: =Gas!G37 -> 0 | AP32: =Elect!BT36 -> 0

Sheet Elect
A1: February | M1: Electricity | BJ1: =SUM(BJ21:BJ33) -> 193200.42 | BP1: Gourmandise UP | BR1: 1.6 | BS1: Power Taxes | BU1: Max Demand | BW1: 500 | BX1: Electricity UP | BZ1: 1.15
BS2: Light Taxes | BU2: PF Penalty | BX2: Max. Demand UP | BZ2: 30
A3: Date | B3: COUNTER (1) | D3: MD | F3: KVAR | H3: n | I3: Guest Rooms Consumption | R3: Casino Consumption | V3: Plant Room Shared Loads | AO3: To Be Charged By First Arabian | BK3: From Main Panel G2 | BS3: Total Consumption. | BT3: No. Of | BU3: KWH/ | BV3: No. Of | BW3: KWH/ | BX3: Total Cost | BY3: L.E\ | BZ3: L.E\
B4: Reading | C4: Consp. F: *800 | D4: Reading | E4: Consp F: 80 | F4: Reading | G4: Consp. F:*10 | I4: Main Feeder | J4: Consp | K4: T2+T8 | L4: Trans T2 | M4: Consp | N4: Trans T8 | O4: Consp | P4: La Gourmandize | Q4: Consp *30 | R4: Casino 3rd floor EM | S4: Consp | T4: Casino 3rd floor Normal | U4: Consp | V4: Chiller 1 | W4: Consp 53% | X4: Chiller 2 | Y4: Consp 53% | Z4: Chiller 3 | AA4: Consp 53% | AB4: Chiller 4 | AC4: Consp 53% | AD4: Chiller 5 | AE4: Consp 53% | AF4: Chiller 6 | AG4: Consp 53% | AH4: Cooling Towers | AI4: Consp 53% | AJ4: Chiller Pumps | AK4: Consp 53% | AL4: Cooling Tower Pumps | AM4: Consp 53% | AN4: Total Plant Room Consp | AO4: Fiber Chiller (N24) | AP4: Consp | AQ4: Mall Ceiling light (N4) | AR4: Consp | AS4: LG Bakery (N2) | AT4: Consp | AU4: LG Bakery light ( Old lockers ) | AV4: Consp | AW4: MCCR1 | AX4: Consp | AY4: Children Swimming pool | AZ4: Consp | BA4: DPH1 | BB4: Consp | BC4: Guest Rooms Emergency | BD4: Consp | BE4: Hotel Hoods | BF4: Consp | BG4: Main G2 | BH4: Consp | BI4: Total Consp From First Arabian | BJ4: First Arabian Charge Back | BK4: Old Casino Emergency | BL4: Consp | BM4: L / A | BN4: Consp | BO4: L / B | BP4: Consp | BQ4: L / C | BR4: Consp | BT4: Rooms | BU4: room | BV4: guest | BW4: guest | BY4: Room | BZ4: Guest
A5: Last Month Reading | I5: 23935086 | J5: =IF(I5>=I4,I5-I4,0) -> 0 | K5: =M5+O5 -> 0 | L5: 682610 | M5: =IF(L5>=L4,L5-L4,0) -> 0 | N5: 568451 | O5: =IF(N5>=N4,N5-N4,0) -> 0 | P5: 221729 | Q5: =IF(P5>=P4,P5-P4,0)*30 -> 0 | R5: 182286 | S5: =IF(R5>=R4,R5-R4,0) -> 0 | T5: 333231.5 | U5: =IF(T5>=T4,T5-T4,0) -> 0 | V5: 792076 | W5: =IF(V5>=V4,V5-V4,0)*0.53 -> 0 | X5: 120756 | Y5: =IF(X5>=X4,X5-X4,0)*0.53 -> 0 | Z5: 134745 | AA5: =IF(Z5>=Z4,Z5-Z4,0)*0.53 -> 0 | AB5: 488293 | AC5: =IF(AB5>=AB4,AB5-AB4,0)*0.53 -> 0 | AD5: 656991 | AE5: =IF(AD5>=AD4,AD5-AD4,0)*0.53 -> 0 | AF5: 835653 | AG5: =IF(AF5>=AF4,AF5-AF4,0)*0.53 -> 0 | AH5: 988484 | AI5: =IF(AH5>=AH4,AH5-AH4,0)*0.53 -> 0 | AJ5: 753327 | AK5: =IF(AJ5>=AJ4,AJ5-AJ4,0)*0.53 -> 0 | AL5: 493166 | AM5: =IF(AL5>=AL4,AL5-AL4,0)*0.53 -> 0 | AN5: =W5+Y5+AA5+AC5+AE5+AG5+AI5+AK5+AM5 -> 0 | AO5: 7651074 | AP5: =IF(AO5>=AO4,AO5-AO4,0)*0.1125 -> 0 | AQ5: 677433 | AR5: =IF(AQ5>=AQ4,AQ5-AQ4,0) -> 0 | AS5: 966158 | AT5: =IF(AS5>=AS4,AS5-AS4,0) -> 0 | AU5: 810198 | AV5: =IF(AU5>=AU4,AU5-AU4,0) -> 0 | AW5: 2620992 | AX5: =IF(AW5>=AW4,AW5-AW4,0) -> 0 | AY5: 229553 | AZ5: =IF(AY5>=AY4,AY5-AY4,0) -> 0 | BA5: 19297389 | BB5: =IF(BA5>=BA4,BA5-BA4,0) -> 0 | BC5: 567310 | BD5: =IF(BC5>=BC4,BC5-BC4,0) -> 0 | BE5: 26749 | BF5: =IF(BE5>=BE4,BE5-BE4,0) -> 0 | BG5: 24129548 | BH5: =IF(BG5>=BG4,BG5-BG4,0)-(0.45*BN5)-(0.45*BP5)-BR5 -> 0 | BI5: =AP5+AR5+AT5+AV5+AX5+AZ5+BB5+BD5+BF5+BH5 -> 0 | BJ5: =BI5+AN5 -> 0 | BK5: 1425459 | BL5: =IF(BK5>=BK4,BK5-BK4,0) -> 0 | BM5: 3933145 | BN5: =IF(BM5>=BM4,BM5-BM4,0) -> 0 | BO5: 413761 | BP5: =IF(BO5>=BO4,BO5-BO4,0) -> 0 | BQ5: 517957 | BR5: =IF(BQ5>=BQ4,BQ5-BQ4,0) -> 0
A6: 1 | C6: =IF(+B6-B5>0,B6-B5,(B6-B5)>0)*800 -> 0 | E6: =IF(+D6-D5>0,D6-D5,(D6-D5)>0)*80 -> 0 | G6: =IF(+F6-F5>0,F6-F5,(F6-F5)>0)*10 -> 0 | H6: 56 | I6: 23941765 | J6: =IF(I6>=I5,I6-I5,0) -> 6679 | K6: =M6+O6 -> 4420 | L6: 685291 | M6: =IF(L6>=L5,L6-L5,0) -> 2681 | N6: 570190 | O6: =IF(N6>=N5,N6-N5,0) -> 1739 | P6: 221741 | Q6: =IF(P6>=P5,P6-P5,0)*30 -> 360 | R6: 182429 | S6: =IF(R6>=R5,R6-R5,0) -> 143 | T6: 333491 | U6: =IF(T6>=T5,T6-T5,0) -> 259.5 | V6: 795028 | W6: =IF(V6>=V5,V6-V5,0)*0.53 -> 1564.56 | X6: 120756 | Y6: =IF(X6>=X5,X6-X5,0)*0.53 -> 0 | Z6: 134745 | AA6: =IF(Z6>=Z5,Z6-Z5,0)*0.53 -> 0 | AB6: 488293 | AC6: =IF(AB6>=AB5,AB6-AB5,0)*0.53 -> 0 | AD6: 657016 | AE6: =IF(AD6>=AD5,AD6-AD5,0)*0.53 -> 13.25 | AF6: 835678 | AG6: =IF(AF6>=AF5,AF6-AF5,0)*0.53 -> 13.25 | AH6: 988738 | AI6: =IF(AH6>=AH5,AH6-AH5,0)*0.53 -> 134.62 | AJ6: 756790 | AK6: =IF(AJ6>=AJ5,AJ6-AJ5,0)*0.53 -> 1835.39 | AL6: 493447 | AM6: =IF(AL6>=AL5,AL6-AL5,0)*0.53 -> 148.93 | AN6: =W6+Y6+AA6+AC6+AE6+AG6+AI6+AK6+AM6 -> 3710 | AO6: 7651116 | AP6: =IF(AO6>=AO5,AO6-AO5,0)*0.1125 -> 4.725 | AQ6: 677756 | AR6: =IF(AQ6>=AQ5,AQ6-AQ5,0) -> 323 | AS6: 966343 | AT6: =IF(AS6>=AS5,AS6-AS5,0) -> 185 | AU6: 810250 | AV6: =IF(AU6>=AU5,AU6-AU5,0) -> 52 | AW6: 2621569 | AX6: =IF(AW6>=AW5,AW6-AW5,0) -> 577 | AY6: 229558 | AZ6: =IF(AY6>=AY5,AY6-AY5,0) -> 5 | BA6: 19301116 | BB6: =IF(BA6>=BA5,BA6-BA5,0) -> 3727 | BC6: 567524 | BD6: =IF(BC6>=BC5,BC6-BC5,0) -> 214 | BE6: 26805 | BF6: =IF(BE6>=BE5,BE6-BE5,0) -> 56 | BG6: 24134832 | BH6: =IF(BG6>=BG5,BG6-BG5,0)-(0.45*BN6)-(0.45*BP6)-BR6 -> 4674.85 | BI6: =AP6+AR6+AT6+AV6+AX6+AZ6+BB6+BD6+BF6+BH6 -> 9818.575 | BJ6: =BI6+AN6 -> 13528.575 | BK6: 1425522 | BL6: =IF(BK6>=BK5,BK6-BK5,0) -> 63 | BM6: 3934116 | BN6: =IF(BM6>=BM5,BM6-BM5,0) -> 971 | BO6: 413897 | BP6: =IF(BO6>=BO5,BO6-BO5,0) -> 136 | BQ6: 518068 | BR6: =IF(BQ6>=BQ5,BQ6-BQ5,0) -> 111 | BS6: =J6+Q6+AN6+BI6 -> 20567.575 | BT6: 194 | BU6: =IF(BS6>0,BS6/BT5,0) -> #DIV/0! | BW6: =IF(BS6>0,BS6/BV6,0) -> #DIV/0! | BX6: =((BS6-Q6)*$BZ$1)+(Q6*$BR$1) -> 23814.711 | BY6: =IF(BX6>0,BX6/BT5,0) -> #DIV/0! | BZ6: =IF(BX6>0,BX6/BV6,0) -> #DIV/0!
A7: 2 | I7: 23948405 | J7: =IF(I7>=I6,I7-I6,0) -> 6640 | K7: =M7+O7 -> 4321 | L7: 687873 | M7: =IF(L7>=L6,L7-L6,0) -> 2582 | N7: 571929 | O7: =IF(N7>=N6,N7-N6,0) -> 1739 | P7: 221761 | Q7: =IF(P7>=P6,P7-P6,0)*30 -> 600 | R7: 182574 | S7: =IF(R7>=R6,R7-R6,0) -> 145 | T7: 333760 | U7: =IF(T7>=T6,T7-T6,0) -> 269 | V7: 796893 | W7: =IF(V7>=V6,V7-V6,0)*0.53 -> 988.45 | X7: 120756 | Y7: =IF(X7>=X6,X7-X6,0)*0.53 -> 0 | Z7: 134745 | AA7: =IF(Z7>=Z6,Z7-Z6,0)*0.53 -> 0 | AB7: 488293 | AC7: =IF(AB7>=AB6,AB7-AB6,0)*0.53 -> 0 | AD7: 657041 | AE7: =IF(AD7>=AD6,AD7-AD6,0)*0.53 -> 13.25 | AF7: 835702 | AG7: =IF(AF7>=AF6,AF7-AF6,0)*0.53 -> 12.72 | AH7: 989509 | AI7: =IF(AH7>=AH6,AH7-AH6,0)*0.53 -> 408.63 | AJ7: 760648 | AK7: =IF(AJ7>=AJ6,AJ7-AJ6,0)*0.53 -> 2044.74 | AL7: 493740 | AM7: =IF(AL7>=AL6,AL7-AL6,0)*0.53 -> 155.29 | AN7: =W7+Y7+AA7+AC7+AE7+AG7+AI7+AK7+AM7 -> 3623.08 | AO7: 7651153 | AP7: =IF(AO7>=AO6,AO7-AO6,0)*0.1125 -> 4.1625 | AQ7: 678094 | AR7: =IF(AQ7>=AQ6,AQ7-AQ6,0) -> 338 | AS7: 966504 | AT7: =IF(AS7>=AS6,AS7-AS6,0) -> 161 | AU7: 810293 | AV7: =IF(AU7>=AU6,AU7-AU6,0) -> 43 | AW7: 2622144 | AX7: =IF(AW7>=AW6,AW7-AW6,0) -> 575 | AY7: 229564 | AZ7: =IF(AY7>=AY6,AY7-AY6,0) -> 6 | BA7: 19305145 | BB7: =IF(BA7>=BA6,BA7-BA6,0) -> 4029 | BC7: 567742 | BD7: =IF(BC7>=BC6,BC7-BC6,0) -> 218 | BE7: 26932 | BF7: =IF(BE7>=BE6,BE7-BE6,0) -> 127 | BG7: 24140284 | BH7: =IF(BG7>=BG6,BG7-BG6,0)-(0.45*BN7)-(0.45*BP7)-BR7 -> 4833.45 | BI7: =AP7+AR7+AT7+AV7+AX7+AZ7+BB7+BD7+BF7+BH7 -> 10334.613 | BJ7: =BI7+AN7 -> 13957.693 | BK7: 1425582 | BL7: =IF(BK7>=BK6,BK7-BK6,0) -> 60 | BM7: 3935053 | BN7: =IF(BM7>=BM6,BM7-BM6,0) -> 937 | BO7: 414039 | BP7: =IF(BO7>=BO6,BO7-BO6,0) -> 142 | BQ7: 518201 | BR7: =IF(BQ7>=BQ6,BQ7-BQ6,0) -> 133 | BS7: =J7+Q7+AN7+BI7 -> 21197.693 | BT7: 194 | BU7: =IF(BS7>0,BS7/BT6,0) -> 109.26646 | BW7: =IF(BS7>0,BS7/BV7,0) -> #DIV/0! | BX7: =((BS7-Q7)*$BZ$1)+(Q7*$BR$1) -> 24647.346 | BY7: =IF(BX7>0,BX7/BT6,0) -> 127.04818 | BZ7: =IF(BX7>0,BX7/BV7,0) -> #DIV/0!
A8: 3 | C8: =IF(+B8-B7>0,B8-B7,(B8-B7)>0)*800 -> 0 | E8: =IF(+D8-D7>0,D8-D7,(D8-D7)>0)*80 -> 0 | G8: =IF(+F8-F7>0,F8-F7,(F8-F7)>0)*10 -> 0 | H8: 57 | I8: 23955296 | J8: =IF(I8>=I7,I8-I7,0) -> 6891 | K8: =M8+O8 -> 4131 | L8: 690576 | M8: =IF(L8>=L7,L8-L7,0) -> 2703 | N8: 573357 | O8: =IF(N8>=N7,N8-N7,0) -> 1428 | P8: 221780 | Q8: =IF(P8>=P7,P8-P7,0)*30 -> 570 | R8: 182714 | S8: =IF(R8>=R7,R8-R7,0) -> 140 | T8: 334006 | U8: =IF(T8>=T7,T8-T7,0) -> 246 | V8: 798719 | W8: =IF(V8>=V7,V8-V7,0)*0.53 -> 967.78 | X8: 120756 | Y8: =IF(X8>=X7,X8-X7,0)*0.53 -> 0 | Z8: 134745 | AA8: =IF(Z8>=Z7,Z8-Z7,0)*0.53 -> 0 | AB8: 488293 | AC8: =IF(AB8>=AB7,AB8-AB7,0)*0.53 -> 0 | AD8: 657067 | AE8: =IF(AD8>=AD7,AD8-AD7,0)*0.53 -> 13.78 | AF8: 835727 | AG8: =IF(AF8>=AF7,AF8-AF7,0)*0.53 -> 13.25 | AH8: 990262 | AI8: =IF(AH8>=AH7,AH8-AH7,0)*0.53 -> 399.09 | AJ8: 764927 | AK8: =IF(AJ8>=AJ7,AJ8-AJ7,0)*0.53 -> 2267.87 | AL8: 494035 | AM8: =IF(AL8>=AL7,AL8-AL7,0)*0.53 -> 156.35 | AN8: =W8+Y8+AA8+AC8+AE8+AG8+AI8+AK8+AM8 -> 3818.12 | AO8: 7651192 | AP8: =IF(AO8>=AO7,AO8-AO7,0)*0.1125 -> 4.3875 | AQ8: 678420 | AR8: =IF(AQ8>=AQ7,AQ8-AQ7,0) -> 326 | AS8: 966651 | AT8: =IF(AS8>=AS7,AS8-AS7,0) -> 147 | AU8: 810336 | AV8: =IF(AU8>=AU7,AU8-AU7,0) -> 43 | AW8: 2622721 | AX8: =IF(AW8>=AW7,AW8-AW7,0) -> 577 | AY8: 229570 | AZ8: =IF(AY8>=AY7,AY8-AY7,0) -> 6 | BA8: 19309285 | BB8: =IF(BA8>=BA7,BA8-BA7,0) -> 4140 | BC8: 567966 | BD8: =IF(BC8>=BC7,BC8-BC7,0) -> 224 | BE8: 26911 | BF8: =IF(BE8>=BE7,BE8-BE7,0) -> 0 | BG8: 24145468 | BH8: =IF(BG8>=BG7,BG8-BG7,0)-(0.45*BN8)-(0.45*BP8)-BR8 -> 4645.6 | BI8: =AP8+AR8+AT8+AV8+AX8+AZ8+BB8+BD8+BF8+BH8 -> 10112.987 | BJ8: =BI8+AN8 -> 13931.107 | BK8: 1425642 | BL8: =IF(BK8>=BK7,BK8-BK7,0) -> 60 | BM8: 3935830 | BN8: =IF(BM8>=BM7,BM8-BM7,0) -> 777 | BO8: 414174 | BP8: =IF(BO8>=BO7,BO8-BO7,0) -> 135 | BQ8: 518329 | BR8: =IF(BQ8>=BQ7,BQ8-BQ7,0) -> 128 | BS8: =J8+Q8+AN8+BI8 -> 21392.107 | BT8: 212 | BU8: =IF(BS8>0,BS8/BT7,0) -> 110.2686 | BW8: =IF(BS8>0,BS8/BV8,0) -> #DIV/0! | BX8: =((BS8-Q8)*$BZ$1)+(Q8*$BR$1) -> 24857.424 | BY8: =IF(BX8>0,BX8/BT7,0) -> 128.13105 | BZ8: =IF(BX8>0,BX8/BV8,0) -> #DIV/0!
A9: 4 | C9: =IF(+B9-B8>0,B9-B8,(B9-B8)>0)*800 -> 0 | E9: =IF(+D9-D8>0,D9-D8,(D9-D8)>0)*80 -> 0 | G9: =IF(+F9-F8>0,F9-F8,(F9-F8)>0)*10 -> 0 | I9: 23962037 | J9: =IF(I9>=I8,I9-I8,0) -> 6741 | K9: =M9+O9 -> 4176 | L9: 693336 | M9: =IF(L9>=L8,L9-L8,0) -> 2760 | N9: 574773 | O9: =IF(N9>=N8,N9-N8,0) -> 1416 | P9: 221800 | Q9: =IF(P9>=P8,P9-P8,0)*30 -> 600 | R9: 182852 | S9: =IF(R9>=R8,R9-R8,0) -> 138 | T9: 334251 | U9: =IF(T9>=T8,T9-T8,0) -> 245 | V9: 800219 | W9: =IF(V9>=V8,V9-V8,0)*0.53 -> 795 | X9: 120756 | Y9: =IF(X9>=X8,X9-X8,0)*0.53 -> 0 | Z9: 134745 | AA9: =IF(Z9>=Z8,Z9-Z8,0)*0.53 -> 0 | AB9: 488293 | AC9: =IF(AB9>=AB8,AB9-AB8,0)*0.53 -> 0 | AD9: 657092 | AE9: =IF(AD9>=AD8,AD9-AD8,0)*0.53 -> 13.25 | AF9: 835751 | AG9: =IF(AF9>=AF8,AF9-AF8,0)*0.53 -> 12.72 | AH9: 990964 | AI9: =IF(AH9>=AH8,AH9-AH8,0)*0.53 -> 372.06 | AJ9: 768260 | AK9: =IF(AJ9>=AJ8,AJ9-AJ8,0)*0.53 -> 1766.49 | AL9: 494315 | AM9: =IF(AL9>=AL8,AL9-AL8,0)*0.53 -> 148.4 | AN9: =W9+Y9+AA9+AC9+AE9+AG9+AI9+AK9+AM9 -> 3107.92 | AO9: 7651229 | AP9: =IF(AO9>=AO8,AO9-AO8,0)*0.1125 -> 4.1625 | AQ9: 678752 | AR9: =IF(AQ9>=AQ8,AQ9-AQ8,0) -> 332 | AS9: 966809 | AT9: =IF(AS9>=AS8,AS9-AS8,0) -> 158 | AU9: 810372 | AV9: =IF(AU9>=AU8,AU9-AU8,0) -> 36 | AW9: 2623251 | AX9: =IF(AW9>=AW8,AW9-AW8,0) -> 530 | AY9: 229576 | AZ9: =IF(AY9>=AY8,AY9-AY8,0) -> 6 | BA9: 19313412 | BB9: =IF(BA9>=BA8,BA9-BA8,0) -> 4127 | BC9: 568170 | BD9: =IF(BC9>=BC8,BC9-BC8,0) -> 204 | BE9: 26965 | BF9: =IF(BE9>=BE8,BE9-BE8,0) -> 54 | BG9: 24150767 | BH9: =IF(BG9>=BG8,BG9-BG8,0)-(0.45*BN9)-(0.45*BP9)-BR9 -> 4734.4 | BI9: =AP9+AR9+AT9+AV9+AX9+AZ9+BB9+BD9+BF9+BH9 -> 10185.562 | BJ9: =BI9+AN9 -> 13293.483 | BK9: 1425702 | BL9: =IF(BK9>=BK8,BK9-BK8,0) -> 60 | BM9: 3936660 | BN9: =IF(BM9>=BM8,BM9-BM8,0) -> 830 | BO9: 414312 | BP9: =IF(BO9>=BO8,BO9-BO8,0) -> 138 | BQ9: 518458 | BR9: =IF(BQ9>=BQ8,BQ9-BQ8,0) -> 129 | BS9: =J9+Q9+AN9+BI9 -> 20634.482 | BT9: 234 | BU9: =IF(BS9>0,BS9/BT8,0) -> 97.332465 | BW9: =IF(BS9>0,BS9/BV9,0) -> #DIV/0! | BX9: =((BS9-Q9)*$BZ$1)+(Q9*$BR$1) -> 23999.655 | BY9: =IF(BX9>0,BX9/BT8,0) -> 113.20592 | BZ9: =IF(BX9>0,BX9/BV9,0) -> #DIV/0!
A10: 5 | C10: =IF(+B10-B9>0,B10-B9,(B10-B9)>0)*800 -> 0 | E10: =IF(+D10-D9>0,D10-D9,(D10-D9)>0)*80 -> 0 | G10: =IF(+F10-F9>0,F10-F9,(F10-F9)>0)*10 -> 0 | H10: 58 | I10: 23968894 | J10: =IF(I10>=I9,I10-I9,0) -> 6857 | K10: =M10+O10 -> 4372 | L10: 696118 | M10: =IF(L10>=L9,L10-L9,0) -> 2782 | N10: 576363 | O10: =IF(N10>=N9,N10-N9,0) -> 1590 | P10: 221821 | Q10: =IF(P10>=P9,P10-P9,0)*30 -> 630 | R10: 182994 | S10: =IF(R10>=R9,R10-R9,0) -> 142 | T10: 334501 | U10: =IF(T10>=T9,T10-T9,0) -> 250 | V10: 802040 | W10: =IF(V10>=V9,V10-V9,0)*0.53 -> 965.13 | X10: 120756 | Y10: =IF(X10>=X9,X10-X9,0)*0.53 -> 0 | Z10: 134745 | AA10: =IF(Z10>=Z9,Z10-Z9,0)*0.53 -> 0 | AB10: 488293 | AC10: =IF(AB10>=AB9,AB10-AB9,0)*0.53 -> 0 | AD10: 657118 | AE10: =IF(AD10>=AD9,AD10-AD9,0)*0.53 -> 13.78 | AF10: 835777 | AG10: =IF(AF10>=AF9,AF10-AF9,0)*0.53 -> 13.78 | AH10: 991717 | AI10: =IF(AH10>=AH9,AH10-AH9,0)*0.53 -> 399.09 | AJ10: 771723 | AK10: =IF(AJ10>=AJ9,AJ10-AJ9,0)*0.53 -> 1835.39 | AL10: 494608 | AM10: =IF(AL10>=AL9,AL10-AL9,0)*0.53 -> 155.29 | AN10: =W10+Y10+AA10+AC10+AE10+AG10+AI10+AK10+AM10 -> 3382.46 | AO10: 7651270 | AP10: =IF(AO10>=AO9,AO10-AO9,0)*0.1125 -> 4.6125 | AQ10: 679118 | AR10: =IF(AQ10>=AQ9,AQ10-AQ9,0) -> 366 | AS10: 966971 | AT10: =IF(AS10>=AS9,AS10-AS9,0) -> 162 | AU10: 810413 | AV10: =IF(AU10>=AU9,AU10-AU9,0) -> 41 | AW10: 2623810 | AX10: =IF(AW10>=AW9,AW10-AW9,0) -> 559 | AY10: 229582 | AZ10: =IF(AY10>=AY9,AY10-AY9,0) -> 6 | BA10: 19317733 | BB10: =IF(BA10>=BA9,BA10-BA9,0) -> 4321 | BC10: 568309 | BD10: =IF(BC10>=BC9,BC10-BC9,0) -> 139 | BE10: 26997 | BF10: =IF(BE10>=BE9,BE10-BE9,0) -> 32 | BG10: 24156115 | BH10: =IF(BG10>=BG9,BG10-BG9,0)-(0.45*BN10)-(0.45*BP10)-BR10 -> 4777.9 | BI10: =AP10+AR10+AT10+AV10+AX10+AZ10+BB10+BD10+BF10+BH10 -> 10408.513 | BJ10: =BI10+AN10 -> 13790.972 | BK10: 1425762 | BL10: =IF(BK10>=BK9,BK10-BK9,0) -> 60 | BM10: 3937499 | BN10: =IF(BM10>=BM9,BM10-BM9,0) -> 839 | BO10: 414451 | BP10: =IF(BO10>=BO9,BO10-BO9,0) -> 139 | BQ10: 518588 | BR10: =IF(BQ10>=BQ9,BQ10-BQ9,0) -> 130 | BS10: =J10+Q10+AN10+BI10 -> 21277.972 | BT10: 216 | BU10: =IF(BS10>0,BS10/BT9,0) -> 90.931506 | BW10: =IF(BS10>0,BS10/BV10,0) -> #DIV/0! | BX10: =((BS10-Q10)*$BZ$1)+(Q10*$BR$1) -> 24753.168 | BY10: =IF(BX10>0,BX10/BT9,0) -> 105.78277 | BZ10: =IF(BX10>0,BX10/BV10,0) -> #DIV/0!
A11: 6 | C11: =IF(+B11-B10>0,B11-B10,(B11-B10)>0)*800 -> 0 | E11: =IF(+D11-D10>0,D11-D10,(D11-D10)>0)*80 -> 0 | G11: =IF(+F11-F10>0,F11-F10,(F11-F10)>0)*10 -> 0 | I11: 23975597 | J11: =IF(I11>=I10,I11-I10,0) -> 6703 | K11: =M11+O11 -> 4233 | L11: 698750 | M11: =IF(L11>=L10,L11-L10,0) -> 2632 | N11: 577964 | O11: =IF(N11>=N10,N11-N10,0) -> 1601 | P11: 221833 | Q11: =IF(P11>=P10,P11-P10,0)*30 -> 360 | R11: 183137 | S11: =IF(R11>=R10,R11-R10,0) -> 143 | T11: 334757 | U11: =IF(T11>=T10,T11-T10,0) -> 256 | V11: 804122 | W11: =IF(V11>=V10,V11-V10,0)*0.53 -> 1103.46 | X11: 120756 | Y11: =IF(X11>=X10,X11-X10,0)*0.53 -> 0 | Z11: 134745 | AA11: =IF(Z11>=Z10,Z11-Z10,0)*0.53 -> 0 | AB11: 488293 | AC11: =IF(AB11>=AB10,AB11-AB10,0)*0.53 -> 0 | AD11: 657143 | AE11: =IF(AD11>=AD10,AD11-AD10,0)*0.53 -> 13.25 | AF11: 835801 | AG11: =IF(AF11>=AF10,AF11-AF10,0)*0.53 -> 12.72 | AH11: 992504 | AI11: =IF(AH11>=AH10,AH11-AH10,0)*0.53 -> 417.11 | AJ11: 775494 | AK11: =IF(AJ11>=AJ10,AJ11-AJ10,0)*0.53 -> 1998.63 | AL11: 494904 | AM11: =IF(AL11>=AL10,AL11-AL10,0)*0.53 -> 156.88 | AN11: =W11+Y11+AA11+AC11+AE11+AG11+AI11+AK11+AM11 -> 3702.05 | AO11: 7651307 | AP11: =IF(AO11>=AO10,AO11-AO10,0)*0.1125 -> 4.1625 | AQ11: 679433 | AR11: =IF(AQ11>=AQ10,AQ11-AQ10,0) -> 315 | AS11: 967138 | AT11: =IF(AS11>=AS10,AS11-AS10,0) -> 167 | AU11: 810456 | AV11: =IF(AU11>=AU10,AU11-AU10,0) -> 43 | AW11: 2624388 | AX11: =IF(AW11>=AW10,AW11-AW10,0) -> 578 | AY11: 229588 | AZ11: =IF(AY11>=AY10,AY11-AY10,0) -> 6 | BA11: 19321948 | BB11: =IF(BA11>=BA10,BA11-BA10,0) -> 4215 | BC11: 568590 | BD11: =IF(BC11>=BC10,BC11-BC10,0) -> 281 | BE11: 27074 | BF11: =IF(BE11>=BE10,BE11-BE10,0) -> 77 | BG11: 24161527 | BH11: =IF(BG11>=BG10,BG11-BG10,0)-(0.45*BN11)-(0.45*BP11)-BR11 -> 4841.7 | BI11: =AP11+AR11+AT11+AV11+AX11+AZ11+BB11+BD11+BF11+BH11 -> 10527.862 | BJ11: =BI11+AN11 -> 14229.912 | BK11: 1425823 | BL11: =IF(BK11>=BK10,BK11-BK10,0) -> 61 | BM11: 3938347 | BN11: =IF(BM11>=BM10,BM11-BM10,0) -> 848 | BO11: 414577 | BP11: =IF(BO11>=BO10,BO11-BO10,0) -> 126 | BQ11: 518720 | BR11: =IF(BQ11>=BQ10,BQ11-BQ10,0) -> 132 | BS11: =J11+Q11+AN11+BI11 -> 21292.912 | BT11: 198 | BU11: =IF(BS11>0,BS11/BT10,0) -> 98.578299 | BW11: =IF(BS11>0,BS11/BV11,0) -> #DIV/0! | BX11: =((BS11-Q11)*$BZ$1)+(Q11*$BR$1) -> 24648.849 | BY11: =IF(BX11>0,BX11/BT10,0) -> 114.11504 | BZ11: =IF(BX11>0,BX11/BV11,0) -> #DIV/0!
A12: 7 | C12: =IF(+B12-B11>0,B12-B11,(B12-B11)>0)*800 -> 0 | E12: =IF(+D12-D11>0,D12-D11,(D12-D11)>0)*80 -> 0 | G12: =IF(+F12-F11>0,F12-F11,(F12-F11)>0)*10 -> 0 | H12: 59 | I12: 23981974 | J12: =IF(I12>=I11,I12-I11,0) -> 6377 | K12: =M12+O12 -> 4224 | L12: 701402 | M12: =IF(L12>=L11,L12-L11,0) -> 2652 | N12: 579536 | O12: =IF(N12>=N11,N12-N11,0) -> 1572 | P12: 221854 | Q12: =IF(P12>=P11,P12-P11,0)*30 -> 630 | R12: 183276 | S12: =IF(R12>=R11,R12-R11,0) -> 139 | T12: 335002 | U12: =IF(T12>=T11,T12-T11,0) -> 245 | V12: 806590 | W12: =IF(V12>=V11,V12-V11,0)*0.53 -> 1308.04 | X12: 120756 | Y12: =IF(X12>=X11,X12-X11,0)*0.53 -> 0 | Z12: 134745 | AA12: =IF(Z12>=Z11,Z12-Z11,0)*0.53 -> 0 | AB12: 488293 | AC12: =IF(AB12>=AB11,AB12-AB11,0)*0.53 -> 0 | AD12: 657168 | AE12: =IF(AD12>=AD11,AD12-AD11,0)*0.53 -> 13.25 | AF12: 835825 | AG12: =IF(AF12>=AF11,AF12-AF11,0)*0.53 -> 12.72 | AH12: 993259 | AI12: =IF(AH12>=AH11,AH12-AH11,0)*0.53 -> 400.15 | AJ12: 779496 | AK12: =IF(AJ12>=AJ11,AJ12-AJ11,0)*0.53 -> 2121.06 | AL12: 495197 | AM12: =IF(AL12>=AL11,AL12-AL11,0)*0.53 -> 155.29 | AN12: =W12+Y12+AA12+AC12+AE12+AG12+AI12+AK12+AM12 -> 4010.51 | AO12: 7651346 | AP12: =IF(AO12>=AO11,AO12-AO11,0)*0.1125 -> 4.3875 | AQ12: 679772 | AR12: =IF(AQ12>=AQ11,AQ12-AQ11,0) -> 339 | AS12: 967258 | AT12: =IF(AS12>=AS11,AS12-AS11,0) -> 120 | AU12: 810500 | AV12: =IF(AU12>=AU11,AU12-AU11,0) -> 44 | AW12: 2624967 | AX12: =IF(AW12>=AW11,AW12-AW11,0) -> 579 | AY12: 229594 | AZ12: =IF(AY12>=AY11,AY12-AY11,0) -> 6 | BA12: 19326072 | BB12: =IF(BA12>=BA11,BA12-BA11,0) -> 4124 | BC12: 568810 | BD12: =IF(BC12>=BC11,BC12-BC11,0) -> 220 | BE12: 27108 | BF12: =IF(BE12>=BE11,BE12-BE11,0) -> 34 | BG12: 24166762 | BH12: =IF(BG12>=BG11,BG12-BG11,0)-(0.45*BN12)-(0.45*BP12)-BR12 -> 4675.85 | BI12: =AP12+AR12+AT12+AV12+AX12+AZ12+BB12+BD12+BF12+BH12 -> 10146.237 | BJ12: =BI12+AN12 -> 14156.747 | BK12: 1425883 | BL12: =IF(BK12>=BK11,BK12-BK11,0) -> 60 | BM12: 3939195 | BN12: =IF(BM12>=BM11,BM12-BM11,0) -> 848 | BO12: 414696 | BP12: =IF(BO12>=BO11,BO12-BO11,0) -> 119 | BQ12: 518844 | BR12: =IF(BQ12>=BQ11,BQ12-BQ11,0) -> 124 | BS12: =J12+Q12+AN12+BI12 -> 21163.747 | BT12: 180 | BU12: =IF(BS12>0,BS12/BT11,0) -> 106.88761 | BW12: =IF(BS12>0,BS12/BV12,0) -> #DIV/0! | BX12: =((BS12-Q12)*$BZ$1)+(Q12*$BR$1) -> 24621.81 | BY12: =IF(BX12>0,BX12/BT11,0) -> 124.35257 | BZ12: =IF(BX12>0,BX12/BV12,0) -> #DIV/0!
A13: 8 | C13: =IF(+B13-B12>0,B13-B12,(B13-B12)>0)*800 -> 0 | E13: =IF(+D13-D12>0,D13-D12,(D13-D12)>0)*80 -> 0 | G13: =IF(+F13-F12>0,F13-F12,(F13-F12)>0)*10 -> 0 | I13: 23988351 | J13: =IF(I13>=I12,I13-I12,0) -> 6377 | K13: =M13+O13 -> 4454 | L13: 704129 | M13: =IF(L13>=L12,L13-L12,0) -> 2727 | N13: 581263 | O13: =IF(N13>=N12,N13-N12,0) -> 1727 | P13: 221872 | Q13: =IF(P13>=P12,P13-P12,0)*30 -> 540 | R13: 183421 | S13: =IF(R13>=R12,R13-R12,0) -> 145 | T13: 335264 | U13: =IF(T13>=T12,T13-T12,0) -> 262 | V13: 809265 | W13: =IF(V13>=V12,V13-V12,0)*0.53 -> 1417.75 | X13: 120756 | Y13: =IF(X13>=X12,X13-X12,0)*0.53 -> 0 | Z13: 134745 | AA13: =IF(Z13>=Z12,Z13-Z12,0)*0.53 -> 0 | AB13: 488293 | AC13: =IF(AB13>=AB12,AB13-AB12,0)*0.53 -> 0 | AD13: 657197 | AE13: =IF(AD13>=AD12,AD13-AD12,0)*0.53 -> 15.37 | AF13: 835854 | AG13: =IF(AF13>=AF12,AF13-AF12,0)*0.53 -> 15.37 | AH13: 994062 | AI13: =IF(AH13>=AH12,AH13-AH12,0)*0.53 -> 425.59 | AJ13: 783545 | AK13: =IF(AJ13>=AJ12,AJ13-AJ12,0)*0.53 -> 2145.97 | AL13: 495507 | AM13: =IF(AL13>=AL12,AL13-AL12,0)*0.53 -> 164.3 | AN13: =W13+Y13+AA13+AC13+AE13+AG13+AI13+AK13+AM13 -> 4184.35 | AO13: 7651390 | AP13: =IF(AO13>=AO12,AO13-AO12,0)*0.1125 -> 4.95 | AQ13: 680130 | AR13: =IF(AQ13>=AQ12,AQ13-AQ12,0) -> 358 | AS13: 967408 | AT13: =IF(AS13>=AS12,AS13-AS12,0) -> 150 | AU13: 810546 | AV13: =IF(AU13>=AU12,AU13-AU12,0) -> 46 | AW13: 2625586 | AX13: =IF(AW13>=AW12,AW13-AW12,0) -> 619 | AY13: 229600 | AZ13: =IF(AY13>=AY12,AY13-AY12,0) -> 6 | BA13: 19330807 | BB13: =IF(BA13>=BA12,BA13-BA12,0) -> 4735 | BC13: 569077 | BD13: =IF(BC13>=BC12,BC13-BC12,0) -> 267 | BE13: 27142 | BF13: =IF(BE13>=BE12,BE13-BE12,0) -> 34 | BG13: 24172975 | BH13: =IF(BG13>=BG12,BG13-BG12,0)-(0.45*BN13)-(0.45*BP13)-BR13 -> 5543.2 | BI13: =AP13+AR13+AT13+AV13+AX13+AZ13+BB13+BD13+BF13+BH13 -> 11763.15 | BJ13: =BI13+AN13 -> 15947.5 | BK13: 1425954 | BL13: =IF(BK13>=BK12,BK13-BK12,0) -> 71 | BM13: 3940199 | BN13: =IF(BM13>=BM12,BM13-BM12,0) -> 1004 | BO13: 414836 | BP13: =IF(BO13>=BO12,BO13-BO12,0) -> 140 | BQ13: 518999 | BR13: =IF(BQ13>=BQ12,BQ13-BQ12,0) -> 155 | BS13: =J13+Q13+AN13+BI13 -> 22864.5 | BT13: 170 | BU13: =IF(BS13>0,BS13/BT12,0) -> 127.025 | BW13: =IF(BS13>0,BS13/BV13,0) -> #DIV/0! | BX13: =((BS13-Q13)*$BZ$1)+(Q13*$BR$1) -> 26537.175 | BY13: =IF(BX13>0,BX13/BT12,0) -> 147.42875 | BZ13: =IF(BX13>0,BX13/BV13,0) -> #DIV/0!
A14: 9 | C14: =IF(+B14-B13>0,B14-B13,(B14-B13)>0)*800 -> 0 | E14: =IF(+D14-D13>0,D14-D13,(D14-D13)>0)*80 -> 0 | G14: =IF(+F14-F13>0,F14-F13,(F14-F13)>0)*10 -> 0 | H14: 60 | I14: 23995236 | J14: =IF(I14>=I13,I14-I13,0) -> 6885 | K14: =M14+O14 -> 5180 | L14: 707470 | M14: =IF(L14>=L13,L14-L13,0) -> 3341 | N14: 583102 | O14: =IF(N14>=N13,N14-N13,0) -> 1839 | P14: 221892 | Q14: =IF(P14>=P13,P14-P13,0)*30 -> 600 | R14: 183589 | S14: =IF(R14>=R13,R14-R13,0) -> 168 | T14: 335562 | U14: =IF(T14>=T13,T14-T13,0) -> 298 | V14: 811715 | W14: =IF(V14>=V13,V14-V13,0)*0.53 -> 1298.5 | X14: 120756 | Y14: =IF(X14>=X13,X14-X13,0)*0.53 -> 0 | Z14: 134745 | AA14: =IF(Z14>=Z13,Z14-Z13,0)*0.53 -> 0 | AB14: 488293 | AC14: =IF(AB14>=AB13,AB14-AB13,0)*0.53 -> 0 | AD14: 657224 | AE14: =IF(AD14>=AD13,AD14-AD13,0)*0.53 -> 14.31 | AF14: 835880 | AG14: =IF(AF14>=AF13,AF14-AF13,0)*0.53 -> 13.78 | AH14: 995004 | AI14: =IF(AH14>=AH13,AH14-AH13,0)*0.53 -> 499.26 | AJ14: 788116 | AK14: =IF(AJ14>=AJ13,AJ14-AJ13,0)*0.53 -> 2422.63 | AL14: 495861 | AM14: =IF(AL14>=AL13,AL14-AL13,0)*0.53 -> 187.62 | AN14: =W14+Y14+AA14+AC14+AE14+AG14+AI14+AK14+AM14 -> 4436.1 | AO14: 7651429 | AP14: =IF(AO14>=AO13,AO14-AO13,0)*0.1125 -> 4.3875 | AQ14: 680490 | AR14: =IF(AQ14>=AQ13,AQ14-AQ13,0) -> 360 | AS14: 967548 | AT14: =IF(AS14>=AS13,AS14-AS13,0) -> 140 | AU14: 810597 | AV14: =IF(AU14>=AU13,AU14-AU13,0) -> 51 | AW14: 2626264 | AX14: =IF(AW14>=AW13,AW14-AW13,0) -> 678 | AY14: 229607 | AZ14: =IF(AY14>=AY13,AY14-AY13,0) -> 7 | BA14: 19334391 | BB14: =IF(BA14>=BA13,BA14-BA13,0) -> 3584 | BC14: 569294 | BD14: =IF(BC14>=BC13,BC14-BC13,0) -> 217 | BE14: 27176 | BF14: =IF(BE14>=BE13,BE14-BE13,0) -> 34 | BG14: 24178697 | BH14: =IF(BG14>=BG13,BG14-BG13,0)-(0.45*BN14)-(0.45*BP14)-BR14 -> 5128.5 | BI14: =AP14+AR14+AT14+AV14+AX14+AZ14+BB14+BD14+BF14+BH14 -> 10203.888 | BJ14: =BI14+AN14 -> 14639.987 | BK14: 1426017 | BL14: =IF(BK14>=BK13,BK14-BK13,0) -> 63 | BM14: 3941083 | BN14: =IF(BM14>=BM13,BM14-BM13,0) -> 884 | BO14: 414962 | BP14: =IF(BO14>=BO13,BO14-BO13,0) -> 126 | BQ14: 519138 | BR14: =IF(BQ14>=BQ13,BQ14-BQ13,0) -> 139 | BS14: =J14+Q14+AN14+BI14 -> 22124.987 | BT14: 154 | BU14: =IF(BS14>0,BS14/BT13,0) -> 130.14699 | BW14: =IF(BS14>0,BS14/BV14,0) -> #DIV/0! | BX14: =((BS14-Q14)*$BZ$1)+(Q14*$BR$1) -> 25713.736 | BY14: =IF(BX14>0,BX14/BT13,0) -> 151.25727 | BZ14: =IF(BX14>0,BX14/BV14,0) -> #DIV/0!
A15: 10 | C15: =IF(+B15-B14>0,B15-B14,(B15-B14)>0)*800 -> 0 | E15: =IF(+D15-D14>0,D15-D14,(D15-D14)>0)*80 -> 0 | G15: =IF(+F15-F14>0,F15-F14,(F15-F14)>0)*10 -> 0 | I15: 24002401 | J15: =IF(I15>=I14,I15-I14,0) -> 7165 | K15: =M15+O15 -> 3454 | L15: 709688 | M15: =IF(L15>=L14,L15-L14,0) -> 2218 | N15: 584338 | O15: =IF(N15>=N14,N15-N14,0) -> 1236 | P15: 221911 | Q15: =IF(P15>=P14,P15-P14,0)*30 -> 570 | R15: 183707 | S15: =IF(R15>=R14,R15-R14,0) -> 118 | T15: 335769 | U15: =IF(T15>=T14,T15-T14,0) -> 207 | V15: 813276 | W15: =IF(V15>=V14,V15-V14,0)*0.53 -> 827.33 | X15: 120756 | Y15: =IF(X15>=X14,X15-X14,0)*0.53 -> 0 | Z15: 134745 | AA15: =IF(Z15>=Z14,Z15-Z14,0)*0.53 -> 0 | AB15: 488293 | AC15: =IF(AB15>=AB14,AB15-AB14,0)*0.53 -> 0 | AD15: 657247 | AE15: =IF(AD15>=AD14,AD15-AD14,0)*0.53 -> 12.19 | AF15: 835901 | AG15: =IF(AF15>=AF14,AF15-AF14,0)*0.53 -> 11.13 | AH15: 995580 | AI15: =IF(AH15>=AH14,AH15-AH14,0)*0.53 -> 305.28 | AJ15: 790980 | AK15: =IF(AJ15>=AJ14,AJ15-AJ14,0)*0.53 -> 1517.92 | AL15: 496084 | AM15: =IF(AL15>=AL14,AL15-AL14,0)*0.53 -> 118.19 | AN15: =W15+Y15+AA15+AC15+AE15+AG15+AI15+AK15+AM15 -> 2792.04 | AO15: 7651462 | AP15: =IF(AO15>=AO14,AO15-AO14,0)*0.1125 -> 3.7125 | AQ15: 680812 | AR15: =IF(AQ15>=AQ14,AQ15-AQ14,0) -> 322 | AS15: 967661 | AT15: =IF(AS15>=AS14,AS15-AS14,0) -> 113 | AU15: 810629 | AV15: =IF(AU15>=AU14,AU15-AU14,0) -> 32 | AW15: 2626707 | AX15: =IF(AW15>=AW14,AW15-AW14,0) -> 443 | AY15: 229612 | AZ15: =IF(AY15>=AY14,AY15-AY14,0) -> 5 | BA15: 19338657 | BB15: =IF(BA15>=BA14,BA15-BA14,0) -> 4266 | BC15: 569486 | BD15: =IF(BC15>=BC14,BC15-BC14,0) -> 192 | BE15: 27210 | BF15: =IF(BE15>=BE14,BE15-BE14,0) -> 34 | BG15: 24183567 | BH15: =IF(BG15>=BG14,BG15-BG14,0)-(0.45*BN15)-(0.45*BP15)-BR15 -> 4372.4 | BI15: =AP15+AR15+AT15+AV15+AX15+AZ15+BB15+BD15+BF15+BH15 -> 9783.1125 | BJ15: =BI15+AN15 -> 12575.153 | BK15: 1426070 | BL15: =IF(BK15>=BK14,BK15-BK14,0) -> 53 | BM15: 3941827 | BN15: =IF(BM15>=BM14,BM15-BM14,0) -> 744 | BO15: 415066 | BP15: =IF(BO15>=BO14,BO15-BO14,0) -> 104 | BQ15: 519254 | BR15: =IF(BQ15>=BQ14,BQ15-BQ14,0) -> 116 | BS15: =J15+Q15+AN15+BI15 -> 20310.153 | BT15: 195 | BU15: =IF(BS15>0,BS15/BT14,0) -> 131.88411 | BW15: =IF(BS15>0,BS15/BV15,0) -> #DIV/0! | BX15: =((BS15-Q15)*$BZ$1)+(Q15*$BR$1) -> 23613.175 | BY15: =IF(BX15>0,BX15/BT14,0) -> 153.33231 | BZ15: =IF(BX15>0,BX15/BV15,0) -> #DIV/0!
A16: 11 | C16: =IF(+B16-B15>0,B16-B15,(B16-B15)>0)*800 -> 0 | E16: =IF(+D16-D15>0,D16-D15,(D16-D15)>0)*80 -> 0 | G16: =IF(+F16-F15>0,F16-F15,(F16-F15)>0)*10 -> 0 | H16: 61 | I16: 24009561 | J16: =IF(I16>=I15,I16-I15,0) -> 7160 | K16: =M16+O16 -> 4364 | L16: 712486 | M16: =IF(L16>=L15,L16-L15,0) -> 2798 | N16: 585904 | O16: =IF(N16>=N15,N16-N15,0) -> 1566 | P16: 221931 | Q16: =IF(P16>=P15,P16-P15,0)*30 -> 600 | R16: 183852 | S16: =IF(R16>=R15,R16-R15,0) -> 145 | T16: 336029 | U16: =IF(T16>=T15,T16-T15,0) -> 260 | V16: 815805 | W16: =IF(V16>=V15,V16-V15,0)*0.53 -> 1340.37 | X16: 120756 | Y16: =IF(X16>=X15,X16-X15,0)*0.53 -> 0 | Z16: 134745 | AA16: =IF(Z16>=Z15,Z16-Z15,0)*0.53 -> 0 | AB16: 488293 | AC16: =IF(AB16>=AB15,AB16-AB15,0)*0.53 -> 0 | AD16: 657274 | AE16: =IF(AD16>=AD15,AD16-AD15,0)*0.53 -> 14.31 | AF16: 835926 | AG16: =IF(AF16>=AF15,AF16-AF15,0)*0.53 -> 13.25 | AH16: 996393 | AI16: =IF(AH16>=AH15,AH16-AH15,0)*0.53 -> 430.89 | AJ16: 794952 | AK16: =IF(AJ16>=AJ15,AJ16-AJ15,0)*0.53 -> 2105.16 | AL16: 496389 | AM16: =IF(AL16>=AL15,AL16-AL15,0)*0.53 -> 161.65 | AN16: =W16+Y16+AA16+AC16+AE16+AG16+AI16+AK16+AM16 -> 4065.63 | AO16: 7651501 | AP16: =IF(AO16>=AO15,AO16-AO15,0)*0.1125 -> 4.3875 | AQ16: 681145 | AR16: =IF(AQ16>=AQ15,AQ16-AQ15,0) -> 333 | AS16: 967762 | AT16: =IF(AS16>=AS15,AS16-AS15,0) -> 101 | AU16: 810667 | AV16: =IF(AU16>=AU15,AU16-AU15,0) -> 38 | AW16: 2627293 | AX16: =IF(AW16>=AW15,AW16-AW15,0) -> 586 | AY16: 229618 | AZ16: =IF(AY16>=AY15,AY16-AY15,0) -> 6 | BA16: 19343344 | BB16: =IF(BA16>=BA15,BA16-BA15,0) -> 4687 | BC16: 569685 | BD16: =IF(BC16>=BC15,BC16-BC15,0) -> 199 | BE16: 27244 | BF16: =IF(BE16>=BE15,BE16-BE15,0) -> 34 | BG16: 24189042 | BH16: =IF(BG16>=BG15,BG16-BG15,0)-(0.45*BN16)-(0.45*BP16)-BR16 -> 4898.1 | BI16: =AP16+AR16+AT16+AV16+AX16+AZ16+BB16+BD16+BF16+BH16 -> 10886.487 | BJ16: =BI16+AN16 -> 14952.118 | BK16: 1426132 | BL16: =IF(BK16>=BK15,BK16-BK15,0) -> 62 | BM16: 3942667 | BN16: =IF(BM16>=BM15,BM16-BM15,0) -> 840 | BO16: 415188 | BP16: =IF(BO16>=BO15,BO16-BO15,0) -> 122 | BQ16: 519398 | BR16: =IF(BQ16>=BQ15,BQ16-BQ15,0) -> 144 | BS16: =J16+Q16+AN16+BI16 -> 22712.118 | BT16: 209 | BU16: =IF(BS16>0,BS16/BT15,0) -> 116.4724 | BW16: =IF(BS16>0,BS16/BV16,0) -> #DIV/0! | BX16: =((BS16-Q16)*$BZ$1)+(Q16*$BR$1) -> 26388.935 | BY16: =IF(BX16>0,BX16/BT15,0) -> 135.32787 | BZ16: =IF(BX16>0,BX16/BV16,0) -> #DIV/0!
A17: 12 | C17: =IF(+B17-B16>0,B17-B16,(B17-B16)>0)*800 -> 0 | E17: =IF(+D17-D16>0,D17-D16,(D17-D16)>0)*80 -> 0 | G17: =IF(+F17-F16>0,F17-F16,(F17-F16)>0)*10 -> 0 | I17: 24016056 | J17: =IF(I17>=I16,I17-I16,0) -> 6495 | K17: =M17+O17 -> 3913 | L17: 714927 | M17: =IF(L17>=L16,L17-L16,0) -> 2441 | N17: 587376 | O17: =IF(N17>=N16,N17-N16,0) -> 1472 | P17: 221941 | Q17: =IF(P17>=P16,P17-P16,0)*30 -> 300 | R17: 183987 | S17: =IF(R17>=R16,R17-R16,0) -> 135 | T17: 336265 | U17: =IF(T17>=T16,T17-T16,0) -> 236 | V17: 818241 | W17: =IF(V17>=V16,V17-V16,0)*0.53 -> 1291.08 | X17: 120756 | Y17: =IF(X17>=X16,X17-X16,0)*0.53 -> 0 | Z17: 134745 | AA17: =IF(Z17>=Z16,Z17-Z16,0)*0.53 -> 0 | AB17: 488293 | AC17: =IF(AB17>=AB16,AB17-AB16,0)*0.53 -> 0 | AD17: 657301 | AE17: =IF(AD17>=AD16,AD17-AD16,0)*0.53 -> 14.31 | AF17: 835952 | AG17: =IF(AF17>=AF16,AF17-AF16,0)*0.53 -> 13.78 | AH17: 997108 | AI17: =IF(AH17>=AH16,AH17-AH16,0)*0.53 -> 378.95 | AJ17: 798493 | AK17: =IF(AJ17>=AJ16,AJ17-AJ16,0)*0.53 -> 1876.73 | AL17: 496661 | AM17: =IF(AL17>=AL16,AL17-AL16,0)*0.53 -> 144.16 | AN17: =W17+Y17+AA17+AC17+AE17+AG17+AI17+AK17+AM17 -> 3719.01 | AO17: 7651538 | AP17: =IF(AO17>=AO16,AO17-AO16,0)*0.1125 -> 4.1625 | AQ17: 681483 | AR17: =IF(AQ17>=AQ16,AQ17-AQ16,0) -> 338 | AS17: 967890 | AT17: =IF(AS17>=AS16,AS17-AS16,0) -> 128 | AU17: 810704 | AV17: =IF(AU17>=AU16,AU17-AU16,0) -> 37 | AW17: 2627833 | AX17: =IF(AW17>=AW16,AW17-AW16,0) -> 540 | AY17: 229624 | AZ17: =IF(AY17>=AY16,AY17-AY16,0) -> 6 | BA17: 19347626 | BB17: =IF(BA17>=BA16,BA17-BA16,0) -> 4282 | BC17: 569886 | BD17: =IF(BC17>=BC16,BC17-BC16,0) -> 201 | BE17: 27278 | BF17: =IF(BE17>=BE16,BE17-BE16,0) -> 34 | BG17: 24194270 | BH17: =IF(BG17>=BG16,BG17-BG16,0)-(0.45*BN17)-(0.45*BP17)-BR17 -> 4682.25 | BI17: =AP17+AR17+AT17+AV17+AX17+AZ17+BB17+BD17+BF17+BH17 -> 10252.413 | BJ17: =BI17+AN17 -> 13971.423 | BK17: 1426312 | BL17: =IF(BK17>=BK16,BK17-BK16,0) -> 180 | BM17: 3943466 | BN17: =IF(BM17>=BM16,BM17-BM16,0) -> 799 | BO17: 415304 | BP17: =IF(BO17>=BO16,BO17-BO16,0) -> 116 | BQ17: 519532 | BR17: =IF(BQ17>=BQ16,BQ17-BQ16,0) -> 134 | BS17: =J17+Q17+AN17+BI17 -> 20766.423 | BT17: 192 | BU17: =IF(BS17>0,BS17/BT16,0) -> 99.360873 | BW17: =IF(BS17>0,BS17/BV17,0) -> #DIV/0! | BX17: =((BS17-Q17)*$BZ$1)+(Q17*$BR$1) -> 24016.386 | BY17: =IF(BX17>0,BX17/BT16,0) -> 114.91094 | BZ17: =IF(BX17>0,BX17/BV17,0) -> #DIV/0!
A18: 13 | C18: =IF(+B18-B17>0,B18-B17,(B18-B17)>0)*800 -> 0 | E18: =IF(+D18-D17>0,D18-D17,(D18-D17)>0)*80 -> 0 | G18: =IF(+F18-F17>0,F18-F17,(F18-F17)>0)*10 -> 0 | H18: 62 | I18: 24023415 | J18: =IF(I18>=I17,I18-I17,0) -> 7359 | K18: =M18+O18 -> 5567 | L18: 718426 | M18: =IF(L18>=L17,L18-L17,0) -> 3499 | N18: 589444 | O18: =IF(N18>=N17,N18-N17,0) -> 2068 | P18: 221964 | Q18: =IF(P18>=P17,P18-P17,0)*30 -> 690 | R18: 184133 | S18: =IF(R18>=R17,R18-R17,0) -> 146 | T18: 336539 | U18: =IF(T18>=T17,T18-T17,0) -> 274 | V18: 821228 | W18: =IF(V18>=V17,V18-V17,0)*0.53 -> 1583.11 | X18: 120829 | Y18: =IF(X18>=X17,X18-X17,0)*0.53 -> 38.69 | Z18: 134801 | AA18: =IF(Z18>=Z17,Z18-Z17,0)*0.53 -> 29.68 | AB18: 488405 | AC18: =IF(AB18>=AB17,AB18-AB17,0)*0.53 -> 59.36 | AD18: 657323 | AE18: =IF(AD18>=AD17,AD18-AD17,0)*0.53 -> 11.66 | AF18: 835974 | AG18: =IF(AF18>=AF17,AF18-AF17,0)*0.53 -> 11.66 | AH18: 998101 | AI18: =IF(AH18>=AH17,AH18-AH17,0)*0.53 -> 526.29 | AJ18: 803507 | AK18: =IF(AJ18>=AJ17,AJ18-AJ17,0)*0.53 -> 2657.42 | AL18: 496956 | AM18: =IF(AL18>=AL17,AL18-AL17,0)*0.53 -> 156.35 | AN18: =W18+Y18+AA18+AC18+AE18+AG18+AI18+AK18+AM18 -> 5074.22 | AO18: 7652014 | AP18: =IF(AO18>=AO17,AO18-AO17,0)*0.1125 -> 53.55 | AQ18: 681810 | AR18: =IF(AQ18>=AQ17,AQ18-AQ17,0) -> 327 | AS18: 968052 | AT18: =IF(AS18>=AS17,AS18-AS17,0) -> 162 | AU18: 810757 | AV18: =IF(AU18>=AU17,AU18-AU17,0) -> 53 | AW18: 2628555 | AX18: =IF(AW18>=AW17,AW18-AW17,0) -> 722 | AY18: 229630 | AZ18: =IF(AY18>=AY17,AY18-AY17,0) -> 6 | BA18: 19353061 | BB18: =IF(BA18>=BA17,BA18-BA17,0) -> 5435 | BC18: 570128 | BD18: =IF(BC18>=BC17,BC18-BC17,0) -> 242 | BE18: 27312 | BF18: =IF(BE18>=BE17,BE18-BE17,0) -> 34 | BG18: 24200184 | BH18: =IF(BG18>=BG17,BG18-BG17,0)-(0.45*BN18)-(0.45*BP18)-BR18 -> 5334.2 | BI18: =AP18+AR18+AT18+AV18+AX18+AZ18+BB18+BD18+BF18+BH18 -> 12368.75 | BJ18: =BI18+AN18 -> 17442.97 | BK18: 1426592 | BL18: =IF(BK18>=BK17,BK18-BK17,0) -> 280 | BM18: 3944289 | BN18: =IF(BM18>=BM17,BM18-BM17,0) -> 823 | BO18: 415445 | BP18: =IF(BO18>=BO17,BO18-BO17,0) -> 141 | BQ18: 519678 | BR18: =IF(BQ18>=BQ17,BQ18-BQ17,0) -> 146 | BS18: =J18+Q18+AN18+BI18 -> 25491.97 | BT18: 228 | BU18: =IF(BS18>0,BS18/BT17,0) -> 132.77068 | BW18: =IF(BS18>0,BS18/BV18,0) -> #DIV/0! | BX18: =((BS18-Q18)*$BZ$1)+(Q18*$BR$1) -> 29626.265 | BY18: =IF(BX18>0,BX18/BT17,0) -> 154.30347 | BZ18: =IF(BX18>0,BX18/BV18,0) -> #DIV/0!
A19: 14 | C19: =IF(+B19-B18>0,B19-B18,(B19-B18)>0)*800 -> 0 | E19: =IF(+D19-D18>0,D19-D18,(D19-D18)>0)*80 -> 0 | G19: =IF(+F19-F18>0,F19-F18,(F19-F18)>0)*10 -> 0 | I19: 24030241 | J19: =IF(I19>=I18,I19-I18,0) -> 6826 | K19: =M19+O19 -> 3170 | L19: 720274 | M19: =IF(L19>=L18,L19-L18,0) -> 1848 | N19: 590766 | O19: =IF(N19>=N18,N19-N18,0) -> 1322 | P19: 221981 | Q19: =IF(P19>=P18,P19-P18,0)*30 -> 510 | R19: 184273 | S19: =IF(R19>=R18,R19-R18,0) -> 140 | T19: 336791 | U19: =IF(T19>=T18,T19-T18,0) -> 252 | V19: 822964 | W19: =IF(V19>=V18,V19-V18,0)*0.53 -> 920.08 | X19: 120829 | Y19: =IF(X19>=X18,X19-X18,0)*0.53 -> 0 | Z19: 134801 | AA19: =IF(Z19>=Z18,Z19-Z18,0)*0.53 -> 0 | AB19: 488405 | AC19: =IF(AB19>=AB18,AB19-AB18,0)*0.53 -> 0 | AD19: 657348 | AE19: =IF(AD19>=AD18,AD19-AD18,0)*0.53 -> 13.25 | AF19: 835998 | AG19: =IF(AF19>=AF18,AF19-AF18,0)*0.53 -> 12.72 | AH19: 998633 | AI19: =IF(AH19>=AH18,AH19-AH18,0)*0.53 -> 281.96 | AJ19: 805959 | AK19: =IF(AJ19>=AJ18,AJ19-AJ18,0)*0.53 -> 1299.56 | AL19: 497159 | AM19: =IF(AL19>=AL18,AL19-AL18,0)*0.53 -> 107.59 | AN19: =W19+Y19+AA19+AC19+AE19+AG19+AI19+AK19+AM19 -> 2635.16 | AO19: 7652871 | AP19: =IF(AO19>=AO18,AO19-AO18,0)*0.1125 -> 96.4125 | AQ19: 682112 | AR19: =IF(AQ19>=AQ18,AQ19-AQ18,0) -> 302 | AS19: 968183 | AT19: =IF(AS19>=AS18,AS19-AS18,0) -> 131 | AU19: 810790 | AV19: =IF(AU19>=AU18,AU19-AU18,0) -> 33 | AW19: 2628991 | AX19: =IF(AW19>=AW18,AW19-AW18,0) -> 436 | AY19: 229636 | AZ19: =IF(AY19>=AY18,AY19-AY18,0) -> 6 | BA19: 19356431 | BB19: =IF(BA19>=BA18,BA19-BA18,0) -> 3370 | BC19: 570396 | BD19: =IF(BC19>=BC18,BC19-BC18,0) -> 268 | BE19: 27346 | BF19: =IF(BE19>=BE18,BE19-BE18,0) -> 34 | BG19: 24206185 | BH19: =IF(BG19>=BG18,BG19-BG18,0)-(0.45*BN19)-(0.45*BP19)-BR19 -> 5418.7 | BI19: =AP19+AR19+AT19+AV19+AX19+AZ19+BB19+BD19+BF19+BH19 -> 10095.112 | BJ19: =BI19+AN19 -> 12730.272 | BK19: 1426887 | BL19: =IF(BK19>=BK18,BK19-BK18,0) -> 295 | BM19: 3945118 | BN19: =IF(BM19>=BM18,BM19-BM18,0) -> 829 | BO19: 415590 | BP19: =IF(BO19>=BO18,BO19-BO18,0) -> 145 | BQ19: 519822 | BR19: =IF(BQ19>=BQ18,BQ19-BQ18,0) -> 144 | BS19: =J19+Q19+AN19+BI19 -> 20066.272 | BT19: 230 | BU19: =IF(BS19>0,BS19/BT18,0) -> 88.009967 | BW19: =IF(BS19>0,BS19/BV19,0) -> #DIV/0! | BX19: =((BS19-Q19)*$BZ$1)+(Q19*$BR$1) -> 23305.713 | BY19: =IF(BX19>0,BX19/BT18,0) -> 102.21804 | BZ19: =IF(BX19>0,BX19/BV19,0) -> #DIV/0!
A20: 15 | C20: =IF(+B20-B19>0,B20-B19,(B20-B19)>0)*800 -> 0 | E20: =IF(+D20-D19>0,D20-D19,(D20-D19)>0)*80 -> 0 | G20: =IF(+F20-F19>0,F20-F19,(F20-F19)>0)*10 -> 0 | H20: 63 | I20: 24038128 | J20: =IF(I20>=I19,I20-I19,0) -> 7887 | K20: =M20+O20 -> 4907 | L20: 723199 | M20: =IF(L20>=L19,L20-L19,0) -> 2925 | N20: 592748 | O20: =IF(N20>=N19,N20-N19,0) -> 1982 | P20: 221992 | Q20: =IF(P20>=P19,P20-P19,0)*30 -> 330 | R20: 184439 | S20: =IF(R20>=R19,R20-R19,0) -> 166 | T20: 337094 | U20: =IF(T20>=T19,T20-T19,0) -> 303 | V20: 825875 | W20: =IF(V20>=V19,V20-V19,0)*0.53 -> 1542.83 | X20: 120829 | Y20: =IF(X20>=X19,X20-X19,0)*0.53 -> 0 | Z20: 134801 | AA20: =IF(Z20>=Z19,Z20-Z19,0)*0.53 -> 0 | AB20: 488405 | AC20: =IF(AB20>=AB19,AB20-AB19,0)*0.53 -> 0 | AD20: 657377 | AE20: =IF(AD20>=AD19,AD20-AD19,0)*0.53 -> 15.37 | AF20: 836026 | AG20: =IF(AF20>=AF19,AF20-AF19,0)*0.53 -> 14.84 | AH20: 999471 | AI20: =IF(AH20>=AH19,AH20-AH19,0)*0.53 -> 444.14 | AJ20: 810117 | AK20: =IF(AJ20>=AJ19,AJ20-AJ19,0)*0.53 -> 2203.74 | AL20: 497481 | AM20: =IF(AL20>=AL19,AL20-AL19,0)*0.53 -> 170.66 | AN20: =W20+Y20+AA20+AC20+AE20+AG20+AI20+AK20+AM20 -> 4391.58 | AO20: 7653604 | AP20: =IF(AO20>=AO19,AO20-AO19,0)*0.1125 -> 82.4625 | AQ20: 682443 | AR20: =IF(AQ20>=AQ19,AQ20-AQ19,0) -> 331 | AS20: 968314 | AT20: =IF(AS20>=AS19,AS20-AS19,0) -> 131 | AU20: 810838 | AV20: =IF(AU20>=AU19,AU20-AU19,0) -> 48 | AW20: 2629601 | AX20: =IF(AW20>=AW19,AW20-AW19,0) -> 610 | AY20: 229643 | AZ20: =IF(AY20>=AY19,AY20-AY19,0) -> 7 | BA20: 19361845 | BB20: =IF(BA20>=BA19,BA20-BA19,0) -> 5414 | BC20: 570642 | BD20: =IF(BC20>=BC19,BC20-BC19,0) -> 246 | BE20: 27380 | BF20: =IF(BE20>=BE19,BE20-BE19,0) -> 34 | BG20: 24211755 | BH20: =IF(BG20>=BG19,BG20-BG19,0)-(0.45*BN20)-(0.45*BP20)-BR20 -> 5031.95 | BI20: =AP20+AR20+AT20+AV20+AX20+AZ20+BB20+BD20+BF20+BH20 -> 11935.413 | BJ20: =BI20+AN20 -> 16326.993 | BK20: 1427172 | BL20: =IF(BK20>=BK19,BK20-BK19,0) -> 285 | BM20: 3945870 | BN20: =IF(BM20>=BM19,BM20-BM19,0) -> 752 | BO20: 415727 | BP20: =IF(BO20>=BO19,BO20-BO19,0) -> 137 | BQ20: 519960 | BR20: =IF(BQ20>=BQ19,BQ20-BQ19,0) -> 138 | BS20: =J20+Q20+AN20+BI20 -> 24543.993 | BT20: 235 | BU20: =IF(BS20>0,BS20/BT20,0) -> 104.44252 | BW20: =IF(BS20>0,BS20/BV20,0) -> #DIV/0! | BX20: =((BS20-Q20)*$BZ$1)+(Q20*$BR$1) -> 28374.091 | BY20: =IF(BX20>0,BX20/BT20,0) -> 120.74081 | BZ20: =IF(BX20>0,BX20/BV20,0) -> #DIV/0!
A21: 16 | C21: =IF(+B21-B20>0,B21-B20,(B21-B20)>0)*800 -> 0 | E21: =IF(+D21-D20>0,D21-D20,(D21-D20)>0)*80 -> 0 | G21: =IF(+F21-F20>0,F21-F20,(F21-F20)>0)*10 -> 0 | I21: 24044642 | J21: =IF(I21>=I20,I21-I20,0) -> 6514 | K21: =M21+O21 -> 4061 | L21: 725615 | M21: =IF(L21>=L20,L21-L20,0) -> 2416 | N21: 594393 | O21: =IF(N21>=N20,N21-N20,0) -> 1645 | P21: 222012 | Q21: =IF(P21>=P20,P21-P20,0)*30 -> 600 | R21: 184556 | S21: =IF(R21>=R20,R21-R20,0) -> 117 | T21: 337306 | U21: =IF(T21>=T20,T21-T20,0) -> 212 | V21: 828031 | W21: =IF(V21>=V20,V21-V20,0)*0.53 -> 1142.68 | X21: 121075 | Y21: =IF(X21>=X20,X21-X20,0)*0.53 -> 130.38 | Z21: 134801 | AA21: =IF(Z21>=Z20,Z21-Z20,0)*0.53 -> 0 | AB21: 488405 | AC21: =IF(AB21>=AB20,AB21-AB20,0)*0.53 -> 0 | AD21: 657401 | AE21: =IF(AD21>=AD20,AD21-AD20,0)*0.53 -> 12.72 | AF21: 836050 | AG21: =IF(AF21>=AF20,AF21-AF20,0)*0.53 -> 12.72 | AI21: =IF(AH21>=AH20,AH21-AH20,0)*0.53 -> 0 | AJ21: 813352 | AK21: =IF(AJ21>=AJ20,AJ21-AJ20,0)*0.53 -> 1714.55 | AL21: 497745 | AM21: =IF(AL21>=AL20,AL21-AL20,0)*0.53 -> 139.92 | AN21: =W21+Y21+AA21+AC21+AE21+AG21+AI21+AK21+AM21 -> 3152.97 | AO21: 7654284 | AP21: =IF(AO21>=AO20,AO21-AO20,0)*0.1125 -> 76.5 | AQ21: 682767 | AR21: =IF(AQ21>=AQ20,AQ21-AQ20,0) -> 324 | AS21: 968445 | AT21: =IF(AS21>=AS20,AS21-AS20,0) -> 131 | AU21: 810876 | AV21: =IF(AU21>=AU20,AU21-AU20,0) -> 38 | AW21: 2630125 | AX21: =IF(AW21>=AW20,AW21-AW20,0) -> 524 | AY21: 229648 | AZ21: =IF(AY21>=AY20,AY21-AY20,0) -> 5 | BA21: 19366209 | BB21: =IF(BA21>=BA20,BA21-BA20,0) -> 4364 | BC21: 570878 | BD21: =IF(BC21>=BC20,BC21-BC20,0) -> 236 | BE21: 27414 | BF21: =IF(BE21>=BE20,BE21-BE20,0) -> 34 | BG21: 24216983 | BH21: =IF(BG21>=BG20,BG21-BG20,0)-(0.45*BN21)-(0.45*BP21)-BR21 -> 4720.95 | BI21: =AP21+AR21+AT21+AV21+AX21+AZ21+BB21+BD21+BF21+BH21 -> 10453.45 | BJ21: =BI21+AN21 -> 13606.42 | BK21: 1427434 | BL21: =IF(BK21>=BK20,BK21-BK20,0) -> 262 | BM21: 3946560 | BN21: =IF(BM21>=BM20,BM21-BM20,0) -> 690 | BO21: 415846 | BP21: =IF(BO21>=BO20,BO21-BO20,0) -> 119 | BQ21: 520103 | BR21: =IF(BQ21>=BQ20,BQ21-BQ20,0) -> 143 | BS21: =J21+Q21+AN21+BI21 -> 20720.42 | BT21: 248 | BU21: =IF(BS21>0,BS21/BT21,0) -> 83.550081 | BW21: =IF(BS21>0,BS21/BV21,0) -> #DIV/0! | BX21: =((BS21-Q21)*$BZ$1)+(Q21*$BR$1) -> 24098.483 | BY21: =IF(BX21>0,BX21/BT21,0) -> 97.171302 | BZ21: =IF(BX21>0,BX21/BV21,0) -> #DIV/0!
