Workbook

Sheet Total
A1: Site Name | B1: Day | C1: Month | D1: Year | E1: Total Electricity Kwh | F1: Electricity Tariff ($/Kwh) | G1: Natual Gas (m3) | H1: Natural Gas $/m3 | I1: Water Utility Supply (m3) m3 | J1: Water Utility Supply (m3) $/m3 | K1: Room Nights
A2: Cairo at The First Residence | B2: 1 | C2: 1 | D2: 2022 | E2: =Elect!BS6 -> 21837.963 | F2: ='Utility Consnsumption'!K13/'Utility Consnsumption'!J13 -> 1.4111954 | G2: =Gas!K7 -> 2864.3 | H2: 3.8 | I2: =Water!H7 -> 539.4 | J2: 10 | K2: =Elect!BT6 -> 232
A3: Cairo at The First Residence | B3: =B2+1 -> 2 | C3: 1 | D3: 2022 | E3: =Elect!BS7 -> 23186.298 | F3: =F2 -> 1.4111954 | G3: =Gas!K8 -> 1821.3 | H3: 3.8 | I3: =Water!H8 -> 237.8 | J3: 10 | K3: =Elect!BT7 -> 191
A4: Cairo at The First Residence | B4: =B3+1 -> 3 | C4: 1 | D4: 2022 | E4: =Elect!BS8 -> 21488.202 | F4: =F3 -> 1.4111954 | G4: =Gas!K9 -> 1829 | H4: 3.8 | I4: =Water!H9 -> 348 | J4: 10 | K4: =Elect!BT8 -> 219
A5: Cairo at The First Residence | B5: =B4+1 -> 4 | C5: 1 | D5: 2022 | E5: =Elect!BS9 -> 22502.702 | F5: =F4 -> 1.4111954 | G5: =Gas!K10 -> 1808.7 | H5: 3.8 | I5: =Water!H10 -> 336.4 | J5: 10 | K5: =Elect!BT9 -> 205
A6: Cairo at The First Residence | B6: =B5+1 -> 5 | C6: 1 | D6: 2022 | E6: =Elect!BS10 -> 23106.327 | F6: =F5 -> 1.4111954 | G6: =Gas!K11 -> 1808.7 | H6: 3.8 | I6: =Water!H11 -> 336.4 | J6: 10 | K6: =Elect!BT10 -> 199
A7: Cairo at The First Residence | B7: =B6+1 -> 6 | C7: 1 | D7: 2022 | E7: =Elect!BS11 -> 20150.848 | F7: =F6 -> 1.4111954 | G7: =Gas!K12 -> 1808.7 | H7: 3.8 | I7: =Water!H12 -> 336.4 | J7: 10 | K7: =Elect!BT11 -> 203
A8: Cairo at The First Residence | B8: =B7+1 -> 7 | C8: 1 | D8: 2022 | E8: =Elect!BS12 -> 20696.565 | F8: =F7 -> 1.4111954 | G8: =Gas!K13 -> 1763.2 | H8: 3.8 | I8: =Water!H13 -> 353.8 | J8: 10 | K8: =Elect!BT12 -> 233
A9: Cairo at The First Residence | B9: =B8+1 -> 8 | C9: 1 | D9: 2022 | E9: =Elect!BS13 -> 21269.522 | F9: =F8 -> 1.4111954 | G9: =Gas!K14 -> 1763.2 | H9: 3.8 | I9: =Water!H14 -> 353.8 | J9: 10 | K9: =Elect!BT13 -> 238
A10: Cairo at The First Residence | B10: =B9+1 -> 9 | C10: 1 | D10: 2022 | E10: =Elect!BS14 -> 20624.493 | F10: =F9 -> 1.4111954 | G10: =Gas!K15 -> 1811.5 | H10: 3.8 | I10: =Water!H15 -> 336.4 | J10: 10 | K10: =Elect!BT14 -> 220
A11: Cairo at The First Residence | B11: =B10+1 -> 10 | C11: 1 | D11: 2022 | E11: =Elect!BS15 -> 23026.137 | F11: =F10 -> 1.4111954 | G11: =Gas!K16 -> 1811.5 | H11: 3.8 | I11: =Water!H16 -> 377 | J11: 10 | K11: =Elect!BT15 -> 211
A12: Cairo at The First Residence | B12: =B11+1 -> 11 | C12: 1 | D12: 2022 | E12: =Elect!BS16 -> 20406.878 | F12: =F11 -> 1.4111954 | G12: =Gas!K17 -> 1811.5 | H12: 3.8 | I12: =Water!H17 -> 382.8 | J12: 10 | K12: =Elect!BT16 -> 201
A13: Cairo at The First Residence | B13: =B12+1 -> 12 | C13: 1 | D13: 2022 | E13: =Elect!BS17 -> 21834.893 | F13: =F12 -> 1.4111954 | G13: =Gas!K18 -> 1811.5 | H13: 3.8 | I13: =Water!H18 -> 382.8 | J13: 10 | K13: =Elect!BT17 -> 179
A14: Cairo at The First Residence | B14: =B13+1 -> 13 | C14: 1 | D14: 2022 | E14: =Elect!BS18 -> 22562.368 | F14: =F13 -> 1.4111954 | G14: =Gas!K19 -> 1811.5 | H14: 3.8 | I14: =Water!H19 -> 382.8 | J14: 10 | K14: =Elect!BT18 -> 207
... A32: Cairo at The First Residence | B32: =B31+1 -> 31 | C32: 1 | D32: 2022 | E32: =Elect!BS36 -> 22026.787 | F32: =F31 -> 1.4111954 | G32: =Gas!K37 -> 1870.3 | H32: 3.8 | I32: =Water!H37 -> 284.2 | J32: 10 | K32: =Elect!BT36 -> 190

Sheet Submetering
A1: Site Name | B1: Day | C1: Month | D1: Year | E1: Electricity | F1: Main Feeder -KWh | G1: T2+T8 -KWh | H1: La Gourmandize -KWh | I1: Casino 3rd floor EM -KWh | J1: Casino 3rd floor Normal -KWh | K1: Chiller 1 -KWh | L1: Chiller 2 -KWh | M1: Chiller 3 -KWh | N1: Chiller 4 -KWh | O1: Chiller 5 -KWh | P1: Chiller 6 -KWh | Q1: Cooling towers -KWh | R1: Chiller Pumps -KWh | S1: Cooling Tower Pumps -KWh | T1: Fiber Chiller -KWh | U1: Mall Ceiling light -KWh | V1: LG Bakery -KWh | W1: LG Bakery light ( Old lockers ) -KWh | X1: MCCR1 -KWh | Y1: Children Swimming Pool -KWh | Z1: DPH1 -KWh | AA1: Guest Rooms Emerg. -KWh | AB1: Hotel Hoods -KWh | AC1: Main G2 -KWh | AD1: Old Casino Emergency -KWh | AE1: L / A -KWh | AF1: L / B -KWh | AG1: L / C -KWh | AH1: Water | AI1: Main water meter 1 -m3 | AJ1: Main water meter 2 -m3 | AK1: Main water meter 3 -m3 | AL1: Gas | AM1: Main Gas Flow Meter -m3 | AN1: Laundry Gas Flow Meter -m3 | AO1: Gourmandize Gas Flow Meter -m3 | AP1: Room Nights
A2: Cairo at The First Residence | B2: 1 | C2: 1 | D2: 2022 | F2: =Elect!J6 -> 5837 | G2: =Elect!K6 -> 3617 | H2: =Elect!Q6 -> 540 | I2: =Elect!S6 -> 132 | J2: =Elect!U6 -> 257 | K2: =Elect!W6 -> 719.74 | L2: =Elect!Y6 -> 91.69 | M2: =Elect!AA6 -> 0 | N2: =Elect!AC6 -> 0 | O2: =Elect!AE6 -> 15.37 | P2: =Elect!AG6 -> 14.31 | Q2: =Elect!AI6 -> 528.41 | R2: =Elect!AK6 -> 3404.72 | S2: =Elect!AM6 -> 144.16 | T2: =Elect!AP6 -> 4.1625 | U2: =Elect!AR6 -> 331 | V2: =Elect!AT6 -> 116 | W2: =Elect!AV6 -> 24 | X2: =Elect!AX6 -> 487 | Y2: =Elect!AZ6 -> 69 | Z2: =Elect!BB6 -> 4331 | AA2: =Elect!BD6 -> 212 | AB2: =Elect!BF6 -> 38 | AC2: =Elect!BH6 -> 4930.4 | AD2: =Elect!BL6 -> 314 | AE2: =Elect!BN6 -> 383 | AF2: =Elect!BP6 -> 125 | AG2: =Elect!BR6 -> 141 | AI2: =Water!C7 -> 284.2 | AJ2: =Water!E7 -> 249.4 | AK2: =Water!G7 -> 5.8 | AM2: =Gas!C7 -> 1473.4 | AN2: =Gas!E7 -> 1390.9 | AO2: =Gas!G7 -> 186 | AP2: =Elect!BT6 -> 232
A3: Cairo at The First Residence | B3: =B2+1 -> 2 | C3: 1 | D3: 2022 | F3: =Elect!J7 -> 6605 | G3: =Elect!K7 -> 3882 | H3: =Elect!Q7 -> 570 | I3: =Elect!S7 -> 148 | J3: =Elect!U7 -> 274 | K3: =Elect!W7 -> 1250.8 | L3: =Elect!Y7 -> 0 | M3: =Elect!AA7 -> 0 | N3: =Elect!AC7 -> 0 | O3: =Elect!AE7 -> 13.78 | P3: =Elect!AG7 -> 13.25 | Q3: =Elect!AI7 -> 587.77 | R3: =Elect!AK7 -> 2593.82 | S3: =Elect!AM7 -> 163.24 | T3: =Elect!AP7 -> 4.3875 | U3: =Elect!AR7 -> 353 | V3: =Elect!AT7 -> 136 | W3: =Elect!AV7 -> 28 | X3: =Elect!AX7 -> 622 | Y3: =Elect!AZ7 -> 66 | Z3: =Elect!BB7 -> 4687 | AA3: =Elect!BD7 -> 254 | AB3: =Elect!BF7 -> 52 | AC3: =Elect!BH7 -> 5186.25 | AD3: =Elect!BL7 -> 275 | AE3: =Elect!BN7 -> 938 | AF3: =Elect!BP7 -> 157 | AG3: =Elect!BR7 -> 164 | AI3: =Water!C8 -> 98.6 | AJ3: =Water!E8 -> 139.2 | AK3: =Water!G8 -> 0 | AM3: =Gas!C8 -> 1473.4 | AN3: =Gas!E8 -> 347.9 | AO3: =Gas!G8 -> 82 | AP3: =Elect!BT7 -> 191
A4: Cairo at The First Residence | B4: =B3+1 -> 3 | C4: 1 | D4: 2022 | F4: =Elect!J8 -> 6146 | G4: =Elect!K8 -> 3709 | H4: =Elect!Q8 -> 480 | I4: =Elect!S8 -> 142 | J4: =Elect!U8 -> 201 | K4: =Elect!W8 -> 1217.94 | L4: =Elect!Y8 -> 12.19 | M4: =Elect!AA8 -> 40.28 | N4: =Elect!AC8 -> 24.38 | O4: =Elect!AE8 -> 12.72 | P4: =Elect!AG8 -> 12.19 | Q4: =Elect!AI8 -> 581.94 | R4: =Elect!AK8 -> 2132.72 | S4: =Elect!AM8 -> 154.23 | T4: =Elect!AP8 -> 4.1625 | U4: =Elect!AR8 -> 329 | V4: =Elect!AT8 -> 136 | W4: =Elect!AV8 -> 29 | X4: =Elect!AX8 -> 578 | Y4: =Elect!AZ8 -> 59 | Z4: =Elect!BB8 -> 4533 | AA4: =Elect!BD8 -> 259 | AB4: =Elect!BF8 -> 51 | AC4: =Elect!BH8 -> 4695.45 | AD4: =Elect!BL8 -> 246 | AE4: =Elect!BN8 -> 862 | AF4: =Elect!BP8 -> 137 | AG4: =Elect!BR8 -> 149 | AI4: =Water!C9 -> 150.8 | AJ4: =Water!E9 -> 197.2 | AK4: =Water!G9 -> 0 | AM4: =Gas!C9 -> 1473.4 | AN4: =Gas!E9 -> 355.6 | AO4: =Gas!G9 -> 102 | AP4: =Elect!BT8 -> 219
A5: Cairo at The First Residence | B5: =B4+1 -> 4 | C5: 1 | D5: 2022 | F5: =Elect!J9 -> 6575 | G5: =Elect!K9 -> 3994 | H5: =Elect!Q9 -> 570 | I5: =Elect!S9 -> 138 | J5: =Elect!U9 -> 330 | K5: =Elect!W9 -> 1102.4 | L5: =Elect!Y9 -> 0 | M5: =Elect!AA9 -> 0 | N5: =Elect!AC9 -> 0 | O5: =Elect!AE9 -> 12.19 | P5: =Elect!AG9 -> 12.19 | Q5: =Elect!AI9 -> 458.98 | R5: =Elect!AK9 -> 2027.78 | S5: =Elect!AM9 -> 164.3 | T5: =Elect!AP9 -> 4.6125 | U5: =Elect!AR9 -> 326 | V5: =Elect!AT9 -> 137 | W5: =Elect!AV9 -> 33 | X5: =Elect!AX9 -> 617 | Y5: =Elect!AZ9 -> 65 | Z5: =Elect!BB9 -> 4856 | AA5: =Elect!BD9 -> 291 | AB5: =Elect!BF9 -> 52 | AC5: =Elect!BH9 -> 5198.25 | AD5: =Elect!BL9 -> 269 | AE5: =Elect!BN9 -> 949 | AF5: =Elect!BP9 -> 146 | AG5: =Elect!BR9 -> 151 | AI5: =Water!C10 -> 145 | AJ5: =Water!E10 -> 191.4 | AK5: =Water!G10 -> 0 | AM5: =Gas!C10 -> 1473.4 | AN5: =Gas!E10 -> 335.3 | AO5: =Gas!G10 -> 171 | AP5: =Elect!BT9 -> 205
A6: Cairo at The First Residence | B6: =B5+1 -> 5 | C6: 1 | D6: 2022 | F6: =Elect!J10 -> 6573 | G6: =Elect!K10 -> 4119 | H6: =Elect!Q10 -> 510 | I6: =Elect!S10 -> 144 | J6: =Elect!U10 -> 272 | K6: =Elect!W10 -> 1726.74 | L6: =Elect!Y10 -> 0 | M6: =Elect!AA10 -> 0 | N6: =Elect!AC10 -> 0 | O6: =Elect!AE10 -> 14.31 | P6: =Elect!AG10 -> 13.78 | Q6: =Elect!AI10 -> 465.87 | R6: =Elect!AK10 -> 2319.28 | S6: =Elect!AM10 -> 170.66 | T6: =Elect!AP10 -> 4.3875 | U6: =Elect!AR10 -> 305 | V6: =Elect!AT10 -> 138 | W6: =Elect!AV10 -> 25 | X6: =Elect!AX10 -> 638 | Y6: =Elect!AZ10 -> 61 | Z6: =Elect!BB10 -> 4811 | AA6: =Elect!BD10 -> 262 | AB6: =Elect!BF10 -> 54 | AC6: =Elect!BH10 -> 5014.3 | AD6: =Elect!BL10 -> 263 | AE6: =Elect!BN10 -> 919 | AF6: =Elect!BP10 -> 127 | AG6: =Elect!BR10 -> 161 | AI6: =Water!C11 -> 145 | AJ6: =Water!E11 -> 191.4 | AK6: =Water!G11 -> 0 | AM6: =Gas!C11 -> 1473.4 | AN6: =Gas!E11 -> 335.3 | AO6: =Gas!G11 -> 139 | AP6: =Elect!BT10 -> 199
A7: Cairo at The First Residence | B7: =B6+1 -> 6 | C7: 1 | D7: 2022 | F7: =Elect!J11 -> 5578 | G7: =Elect!K11 -> 3498 | H7: =Elect!Q11 -> 510 | I7: =Elect!S11 -> 134 | J7: =Elect!U11 -> 252 | K7: =Elect!W11 -> 1262.99 | L7: =Elect!Y11 -> 0 | M7: =Elect!AA11 -> 0 | N7: =Elect!AC11 -> 0 | O7: =Elect!AE11 -> 12.19 | P7: =Elect!AG11 -> 11.66 | Q7: =Elect!AI11 -> 414.99 | R7: =Elect!AK11 -> 1996.51 | S7: =Elect!AM11 -> 153.17 | T7: =Elect!AP11 -> 4.3875 | U7: =Elect!AR11 -> 316 | V7: =Elect!AT11 -> 129 | W7: =Elect!AV11 -> 23 | X7: =Elect!AX11 -> 576 | Y7: =Elect!AZ11 -> 58 | Z7: =Elect!BB11 -> 4274 | AA7: =Elect!BD11 -> 236 | AB7: =Elect!BF11 -> 54 | AC7: =Elect!BH11 -> 4540.95 | AD7: =Elect!BL11 -> 242 | AE7: =Elect!BN11 -> 812 | AF7: =Elect!BP11 -> 137 | AG7: =Elect!BR11 -> 147 | AI7: =Water!C12 -> 145 | AJ7: =Water!E12 -> 191.4 | AK7: =Water!G12 -> 0 | AM7: =Gas!C12 -> 1473.4 | AN7: =Gas!E12 -> 335.3 | AO7: =Gas!G12 -> 103 | AP7: =Elect!BT11 -> 203
A8: Cairo at The First Residence | B8: =B7+1 -> 7 | C8: 1 | D8: 2022 | F8: =Elect!J12 -> 5618 | G8: =Elect!K12 -> 3516 | H8: =Elect!Q12 -> 480 | I8: =Elect!S12 -> 140 | J8: =Elect!U12 -> 265 | K8: =Elect!W12 -> 1335.6 | L8: =Elect!Y12 -> 0 | M8: =Elect!AA12 -> 0 | N8: =Elect!AC12 -> 0 | O8: =Elect!AE12 -> 13.25 | P8: =Elect!AG12 -> 12.72 | Q8: =Elect!AI12 -> 430.36 | R8: =Elect!AK12 -> 2163.46 | S8: =Elect!AM12 -> 156.35 | T8: =Elect!AP12 -> 4.275 | U8: =Elect!AR12 -> 345 | V8: =Elect!AT12 -> 133 | W8: =Elect!AV12 -> 17 | X8: =Elect!AX12 -> 588 | Y8: =Elect!AZ12 -> 30 | Z8: =Elect!BB12 -> 4236 | AA8: =Elect!BD12 -> 259 | AB8: =Elect!BF12 -> 56 | AC8: =Elect!BH12 -> 4818.55 | AD8: =Elect!BL12 -> 255 | AE8: =Elect!BN12 -> 882 | AF8: =Elect!BP12 -> 139 | AG8: =Elect!BR12 -> 154 | AI8: =Water!C13 -> 150.8 | AJ8: =Water!E13 -> 203 | AK8: =Water!G13 -> 0 | AM8: =Gas!C13 -> 1473.4 | AN8: =Gas!E13 -> 289.8 | AO8: =Gas!G13 -> 103 | AP8: =Elect!BT12 -> 233
A9: Cairo at The First Residence | B9: =B8+1 -> 8 | C9: 1 | D9: 2022 | F9: =Elect!J13 -> 5864 | G9: =Elect!K13 -> 3590 | H9: =Elect!Q13 -> 510 | I9: =Elect!S13 -> 142 | J9: =Elect!U13 -> 265 | K9: =Elect!W13 -> 1401.32 | L9: =Elect!Y13 -> 257.58 | M9: =Elect!AA13 -> 0 | N9: =Elect!AC13 -> 0 | O9: =Elect!AE13 -> 13.25 | P9: =Elect!AG13 -> 12.72 | Q9: =Elect!AI13 -> 414.46 | R9: =Elect!AK13 -> 2071.24 | S9: =Elect!AM13 -> 155.29 | T9: =Elect!AP13 -> 4.1625 | U9: =Elect!AR13 -> 317 | V9: =Elect!AT13 -> 139 | W9: =Elect!AV13 -> 20 | X9: =Elect!AX13 -> 590 | Y9: =Elect!AZ13 -> 0 | Z9: =Elect!BB13 -> 4343 | AA9: =Elect!BD13 -> 260 | AB9: =Elect!BF13 -> 46 | AC9: =Elect!BH13 -> 4850.5 | AD9: =Elect!BL13 -> 255 | AE9: =Elect!BN13 -> 900 | AF9: =Elect!BP13 -> 130 | AG9: =Elect!BR13 -> 157 | AI9: =Water!C14 -> 150.8 | AJ9: =Water!E14 -> 203 | AK9: =Water!G14 -> 0 | AM9: =Gas!C14 -> 1473.4 | AN9: =Gas!E14 -> 289.8 | AO9: =Gas!G14 -> 103 | AP9: =Elect!BT13 -> 238
A10: Cairo at The First Residence | B10: =B9+1 -> 9 | C10: 1 | D10: 2022 | F10: =Elect!J14 -> 5583 | G10: =Elect!K14 -> 3778 | H10: =Elect!Q14 -> 480 | I10: =Elect!S14 -> 137 | J10: =Elect!U14 -> 253 | K10: =Elect!W14 -> 1171.3 | L10: =Elect!Y14 -> 0 | M10: =Elect!AA14 -> 0 | N10: =Elect!AC14 -> 0 | O10: =Elect!AE14 -> 12.72 | P10: =Elect!AG14 -> 12.72 | Q10: =Elect!AI14 -> 419.76 | R10: =Elect!AK14 -> 2187.84 | S10: =Elect!AM14 -> 157.94 | T10: =Elect!AP14 -> 4.1625 | U10: =Elect!AR14 -> 322 | V10: =Elect!AT14 -> 146 | W10: =Elect!AV14 -> 28 | X10: =Elect!AX14 -> 591 | Y10: =Elect!AZ14 -> 0 | Z10: =Elect!BB14 -> 4454 | AA10: =Elect!BD14 -> 240 | AB10: =Elect!BF14 -> 46 | AC10: =Elect!BH14 -> 4768.05 | AD10: =Elect!BL14 -> 250 | AE10: =Elect!BN14 -> 879 | AF10: =Elect!BP14 -> 132 | AG10: =Elect!BR14 -> 152 | AI10: =Water!C15 -> 145 | AJ10: =Water!E15 -> 191.4 | AK10: =Water!G15 -> 0 | AM10: =Gas!C15 -> 1473.4 | AN10: =Gas!E15 -> 338.1 | AO10: =Gas!G15 -> 103 | AP10: =Elect!BT14 -> 220
A11: Cairo at The First Residence | B11: =B10+1 -> 10 | C11: 1 | D11: 2022 | F11: =Elect!J15 -> 7367 | G11: =Elect!K15 -> 4484 | H11: =Elect!Q15 -> 570 | I11: =Elect!S15 -> 150 | J11: =Elect!U15 -> 278 | K11: =Elect!W15 -> 1014.95 | L11: =Elect!Y15 -> 0 | M11: =Elect!AA15 -> 0 | N11: =Elect!AC15 -> 0 | O11: =Elect!AE15 -> 14.31 | P11: =Elect!AG15 -> 13.78 | Q11: =Elect!AI15 -> 463.75 | R11: =Elect!AK15 -> 2390.3 | S11: =Elect!AM15 -> 173.31 | T11: =Elect!AP15 -> 4.8375 | U11: =Elect!AR15 -> 332 | V11: =Elect!AT15 -> 152 | W11: =Elect!AV15 -> 40 | X11: =Elect!AX15 -> 625 | Y11: =Elect!AZ15 -> 0 | Z11: =Elect!BB15 -> 4484 | AA11: =Elect!BD15 -> 273 | AB11: =Elect!BF15 -> 64 | AC11: =Elect!BH15 -> 5043.9 | AD11: =Elect!BL15 -> 267 | AE11: =Elect!BN15 -> 918 | AF11: =Elect!BP15 -> 140 | AG11: =Elect!BR15 -> 151 | AI11: =Water!C16 -> 162.4 | AJ11: =Water!E16 -> 214.6 | AK11: =Water!G16 -> 0 | AM11: =Gas!C16 -> 1473.4 | AN11: =Gas!E16 -> 338.1 | AO11: =Gas!G16 -> 103 | AP11: =Elect!BT15 -> 211
A12: Cairo at The First Residence | B12: =B11+1 -> 11 | C12: 1 | D12: 2022 | F12: =Elect!J16 -> 6246 | G12: =Elect!K16 -> 3878 | H12: =Elect!Q16 -> 510 | I12: =Elect!S16 -> 130 | J12: =Elect!U16 -> 244 | K12: =Elect!W16 -> 950.29 | L12: =Elect!Y16 -> 0 | M12: =Elect!AA16 -> 0 | N12: =Elect!AC16 -> 0 | O12: =Elect!AE16 -> 11.66 | P12: =Elect!AG16 -> 11.66 | Q12: =Elect!AI16 -> 393.26 | R12: =Elect!AK16 -> 2143.32 | S12: =Elect!AM16 -> 148.4 | T12: =Elect!AP16 -> 4.3875 | U12: =Elect!AR16 -> 324 | V12: =Elect!AT16 -> 133 | W12: =Elect!AV16 -> 27 | X12: =Elect!AX16 -> 545 | Y12: =Elect!AZ16 -> 0 | Z12: =Elect!BB16 -> 4155 | AA12: =Elect!BD16 -> 242 | AB12: =Elect!BF16 -> 54 | AC12: =Elect!BH16 -> 4507.9 | AD12: =Elect!BL16 -> 240 | AE12: =Elect!BN16 -> 811 | AF12: =Elect!BP16 -> 127 | AG12: =Elect!BR16 -> 138 | AI12: =Water!C17 -> 162.4 | AJ12: =Water!E17 -> 220.4 | AK12: =Water!G17 -> 0 | AM12: =Gas!C17 -> 1473.4 | AN12: =Gas!E17 -> 338.1 | AO12: =Gas!G17 -> 103 | AP12: =Elect!BT16 -> 201
A13: Cairo at The First Residence | B13: =B12+1 -> 12 | C13: 1 | D13: 2022 | F13: =Elect!J17 -> 6655 | G13: =Elect!K17 -> 4174 | H13: =Elect!Q17 -> 450 | I13: =Elect!S17 -> 138 | J13: =Elect!U17 -> 257 | K13: =Elect!W17 -> 1049.4 | L13: =Elect!Y17 -> 0 | M13: =Elect!AA17 -> 0 | N13: =Elect!AC17 -> 0 | O13: =Elect!AE17 -> 12.72 | P13: =Elect!AG17 -> 12.72 | Q13: =Elect!AI17 -> 438.84 | R13: =Elect!AK17 -> 2360.62 | S13: =Elect!AM17 -> 162.18 | T13: =Elect!AP17 -> 4.1625 | U13: =Elect!AR17 -> 327 | V13: =Elect!AT17 -> 136 | W13: =Elect!AV17 -> 21 | X13: =Elect!AX17 -> 589 | Y13: =Elect!AZ17 -> 0 | Z13: =Elect!BB17 -> 4537 | AA13: =Elect!BD17 -> 237 | AB13: =Elect!BF17 -> 56 | AC13: =Elect!BH17 -> 4786.25 | AD13: =Elect!BL17 -> 255 | AE13: =Elect!BN17 -> 879 | AF13: =Elect!BP17 -> 136 | AG13: =Elect!BR17 -> 139 | AI13: =Water!C18 -> 162.4 | AJ13: =Water!E18 -> 220.4 | AK13: =Water!G18 -> 0 | AM13: =Gas!C18 -> 1473.4 | AN13: =Gas!E18 -> 338.1 | AO13: =Gas!G18 -> 103 | AP13: =Elect!BT17 -> 179
A14: Cairo at The First Residence | B14: =B13+1 -> 13 | C14: 1 | D14: 2022 | F14: =Elect!J18 -> 6659 | G14: =Elect!K18 -> 4184 | H14: =Elect!Q18 -> 540 | I14: =Elect!S18 -> 139 | J14: =Elect!U18 -> 251 | K14: =Elect!W18 -> 1052.58 | L14: =Elect!Y18 -> 0 | M14: =Elect!AA18 -> 0 | N14: =Elect!AC18 -> 0 | O14: =Elect!AE18 -> 13.78 | P14: =Elect!AG18 -> 13.25 | Q14: =Elect!AI18 -> 443.61 | R14: =Elect!AK18 -> 2365.39 | S14: =Elect!AM18 -> 163.77 | T14: =Elect!AP18 -> 4.8375 | U14: =Elect!AR18 -> 320 | V14: =Elect!AT18 -> 139 | W14: =Elect!AV18 -> 23 | X14: =Elect!AX18 -> 585 | Y14: =Elect!AZ18 -> 0 | Z14: =Elect!BB18 -> 4835 | AA14: =Elect!BD18 -> 233 | AB14: =Elect!BF18 -> 51 | AC14: =Elect!BH18 -> 5120.15 | AD14: =Elect!BL18 -> 265 | AE14: =Elect!BN18 -> 912 | AF14: =Elect!BP18 -> 141 | AG14: =Elect!BR18 -> 145 | AI14: =Water!C19 -> 162.4 | AJ14: =Water!E19 -> 220.4 | AK14: =Water!G19 -> 0 | AM14: =Gas!C19 -> 1473.4 | AN14: =Gas!E19 -> 338.1 | AO14: =Gas!G19 -> 103 | AP14: =Elect!BT18 -> 207
... A32: Cairo at The First Residence | B32: =B31+1 -> 31 | C32: 1 | D32: 2022 | F32: =Elect!J36 -> 8003 | G32: =Elect!K36 -> 4648 | H32: =Elect!Q36 -> 630 | I32: =Elect!S36 -> 138 | J32: =Elect!U36 -> 267.5 | K32: =Elect!W36 -> 512.51 | L32: =Elect!Y36 -> 0 | M32: =Elect!AA36 -> 0 | N32: =Elect!AC36 -> 0 | O32: =Elect!AE36 -> 13.78 | P32: =Elect!AG36 -> 12.72 | Q32: =Elect!AI36 -> 402.27 | R32: =Elect!AK36 -> 2076.01 | S32: =Elect!AM36 -> 154.76 | T32: =Elect!AP36 -> 4.3875 | U32: =Elect!AR36 -> 320 | V32: =Elect!AT36 -> 114 | W32: =Elect!AV36 -> 33 | X32: =Elect!AX36 -> 532 | Y32: =Elect!AZ36 -> 6 | Z32: =Elect!BB36 -> 4266 | AA32: =Elect!BD36 -> 209 | AB32: =Elect!BF36 -> 52 | AC32: =Elect!BH36 -> 4685.35 | AD32: =Elect!BL36 -> 59 | AE32: =Elect!BN36 -> 789 | AF32: =Elect!BP36 -> 148 | AG32: =Elect!BR36 -> 139 | AI32: =Water!C37 -> 121.8 | AJ32: =Water!E37 -> 162.4 | AK32: =Water!G37 -> 0 | AM32: =Gas!C37 -> 1473.4 | AN32: =Gas!E37 -> 396.9 | AO32: =Gas!G37 -> 81 | AP32: =Elect!BT36 -> 190

Sheet Sheet1

Sheet Sheet2

Sheet Elect
A1: January | M1: Electricity | BP1: Gourmandise UP | BR1: 1.6 | BS1: Power Taxes | BU1: Max Demand | BW1: 500 | BX1: Electricity UP | BZ1: 1.15
BS2: Light Taxes | BU2: PF Penalty | BX2: Max. Demand UP | BZ2: 30
A3: Date | B3: COUNTER (1) | D3: MD | F3: KVAR | H3: n | I3: Guest Rooms Consumption | R3: Casino Consumption | V3: Plant Room Shared Loads | AO3: To Be Charged By First Arabian | BK3: From Main Panel G2 | BS3: Total Consumption. | BT3: No. Of | BU3: KWH/ | BV3: No. Of | BW3: KWH/ | BX3: Total Cost | BY3: L.E\ | BZ3: L.E\
B4: Reading | C4: Consp. F: *800 | D4: Reading | E4: Consp F: 80 | F4: Reading | G4: Consp. F:*10 | I4: Main Feeder | J4: Consp | K4: T2+T8 | L4: Trans T2 | M4: Consp | N4: Trans T8 | O4: Consp | P4: La Gourmandize | Q4: Consp *30 | R4: Casino 3rd floor EM | S4: Consp | T4: Casino 3rd floor Normal | U4: Consp | V4: Chiller 1 | W4: Consp 53% | X4: Chiller 2 | Y4: Consp 53% | Z4: Chiller 3 | AA4: Consp 53% | AB4: Chiller 4 | AC4: Consp 53% | AD4: Chiller 5 | AE4: Consp 53% | AF4: Chiller 6 | AG4: Consp 53% | AH4: Cooling Towers | AI4: Consp 53% | AJ4: Chiller Pumps | AK4: Consp 53% | AL4: Cooling Tower Pumps | AM4: Consp 53% | AN4: Total Plant Room Consp | AO4: Fiber Chiller (N24) | AP4: Consp | AQ4: Mall Ceiling light (N4) | AR4: Consp | AS4: LG Bakery (N2) | AT4: Consp | AU4: LG Bakery light ( Old lockers ) | AV4: Consp | AW4: MCCR1 | AX4: Consp | AY4: Children Swimming pool | AZ4: Consp | BA4: DPH1 | BB4: Consp | BC4: Guest Rooms Emergency | BD4: Consp | BE4: Hotel Hoods | BF4: Consp | BG4: Main G2 | BH4: Consp | BI4: Total Consp From First Arabian | BJ4: First Arabian Charge Back | BK4: Old Casino Emergency | BL4: Consp | BM4: L / A | BN4: Consp | BO4: L / B | BP4: Consp | BQ4: L / C | BR4: Consp | BT4: Rooms | BU4: room | BV4: guest | BW4: guest | BY4: Room | BZ4: Guest
A5: Last Month Reading | I5: 23715588 | J5: =IF(I5>=I4,I5-I4,0) -> 0 | K5: =M5+O5 -> 0 | L5: 595387 | M5: =IF(L5>=L4,L5-L4,0) -> 0 | N5: 522852 | O5: =IF(N5>=N4,N5-N4,0) -> 0 | P5: 221186 | Q5: =IF(P5>=P4,P5-P4,0)*30 -> 0 | R5: 177935 | S5: =IF(R5>=R4,R5-R4,0) -> 0 | T5: 325086 | U5: =IF(T5>=T4,T5-T4,0) -> 0 | V5: 734409 | W5: =IF(V5>=V4,V5-V4,0)*0.53 -> 0 | X5: 116729 | Y5: =IF(X5>=X4,X5-X4,0)*0.53 -> 0 | Z5: 134669 | AA5: =IF(Z5>=Z4,Z5-Z4,0)*0.53 -> 0 | AB5: 488247 | AC5: =IF(AB5>=AB4,AB5-AB4,0)*0.53 -> 0 | AD5: 656201 | AE5: =IF(AD5>=AD4,AD5-AD4,0)*0.53 -> 0 | AF5: 834896 | AG5: =IF(AF5>=AF4,AF5-AF4,0)*0.53 -> 0 | AH5: 967240 | AI5: =IF(AH5>=AH4,AH5-AH4,0)*0.53 -> 0 | AJ5: 621756 | AK5: =IF(AJ5>=AJ4,AJ5-AJ4,0)*0.53 -> 0 | AL5: 484025 | AM5: =IF(AL5>=AL4,AL5-AL4,0)*0.53 -> 0 | AN5: =W5+Y5+AA5+AC5+AE5+AG5+AI5+AK5+AM5 -> 0 | AO5: 7649849 | AP5: =IF(AO5>=AO4,AO5-AO4,0)*0.1125 -> 0 | AQ5: 667350 | AR5: =IF(AQ5>=AQ4,AQ5-AQ4,0) -> 0 | AS5: 961991 | AT5: =IF(AS5>=AS4,AS5-AS4,0) -> 0 | AU5: 809269 | AV5: =IF(AU5>=AU4,AU5-AU4,0) -> 0 | AW5: 2603425 | AX5: =IF(AW5>=AW4,AW5-AW4,0) -> 0 | AY5: 229064 | AZ5: =IF(AY5>=AY4,AY5-AY4,0) -> 0 | BA5: 19163085 | BB5: =IF(BA5>=BA4,BA5-BA4,0) -> 0 | BC5: 560194 | BD5: =IF(BC5>=BC4,BC5-BC4,0) -> 0 | BE5: 25110 | BF5: =IF(BE5>=BE4,BE5-BE4,0) -> 0 | BG5: 23964679 | BH5: =IF(BG5>=BG4,BG5-BG4,0)-(0.45*BN5)-(0.45*BP5)-BR5 -> 0 | BI5: =AP5+AR5+AT5+AV5+AX5+AZ5+BB5+BD5+BF5+BH5 -> 0 | BJ5: =BI5+AN5 -> 0 | BK5: 1419836 | BL5: =IF(BK5>=BK4,BK5-BK4,0) -> 0 | BM5: 3909467 | BN5: =IF(BM5>=BM4,BM5-BM4,0) -> 0 | BO5: 409591 | BP5: =IF(BO5>=BO4,BO5-BO4,0) -> 0 | BQ5: 513610 | BR5: =IF(BQ5>=BQ4,BQ5-BQ4,0) -> 0
A6: 1 | C6: =IF(+B6-B5>0,B6-B5,(B6-B5)>0)*800 -> 0 | E6: =IF(+D6-D5>0,D6-D5,(D6-D5)>0)*80 -> 0 | G6: =IF(+F6-F5>0,F6-F5,(F6-F5)>0)*10 -> 0 | H6: 56 | I6: 23721425 | J6: =IF(I6>=I5,I6-I5,0) -> 5837 | K6: =M6+O6 -> 3617 | L6: 597404 | M6: =IF(L6>=L5,L6-L5,0) -> 2017 | N6: 524452 | O6: =IF(N6>=N5,N6-N5,0) -> 1600 | P6: 221204 | Q6: =IF(P6>=P5,P6-P5,0)*30 -> 540 | R6: 178067 | S6: =IF(R6>=R5,R6-R5,0) -> 132 | T6: 325343 | U6: =IF(T6>=T5,T6-T5,0) -> 257 | V6: 735767 | W6: =IF(V6>=V5,V6-V5,0)*0.53 -> 719.74 | X6: 116902 | Y6: =IF(X6>=X5,X6-X5,0)*0.53 -> 91.69 | Z6: 134669 | AA6: =IF(Z6>=Z5,Z6-Z5,0)*0.53 -> 0 | AB6: 488247 | AC6: =IF(AB6>=AB5,AB6-AB5,0)*0.53 -> 0 | AD6: 656230 | AE6: =IF(AD6>=AD5,AD6-AD5,0)*0.53 -> 15.37 | AF6: 834923 | AG6: =IF(AF6>=AF5,AF6-AF5,0)*0.53 -> 14.31 | AH6: 968237 | AI6: =IF(AH6>=AH5,AH6-AH5,0)*0.53 -> 528.41 | AJ6: 628180 | AK6: =IF(AJ6>=AJ5,AJ6-AJ5,0)*0.53 -> 3404.72 | AL6: 484297 | AM6: =IF(AL6>=AL5,AL6-AL5,0)*0.53 -> 144.16 | AN6: =W6+Y6+AA6+AC6+AE6+AG6+AI6+AK6+AM6 -> 4918.4 | AO6: 7649886 | AP6: =IF(AO6>=AO5,AO6-AO5,0)*0.1125 -> 4.1625 | AQ6: 667681 | AR6: =IF(AQ6>=AQ5,AQ6-AQ5,0) -> 331 | AS6: 962107 | AT6: =IF(AS6>=AS5,AS6-AS5,0) -> 116 | AU6: 809293 | AV6: =IF(AU6>=AU5,AU6-AU5,0) -> 24 | AW6: 2603912 | AX6: =IF(AW6>=AW5,AW6-AW5,0) -> 487 | AY6: 229133 | AZ6: =IF(AY6>=AY5,AY6-AY5,0) -> 69 | BA6: 19167416 | BB6: =IF(BA6>=BA5,BA6-BA5,0) -> 4331 | BC6: 560406 | BD6: =IF(BC6>=BC5,BC6-BC5,0) -> 212 | BE6: 25148 | BF6: =IF(BE6>=BE5,BE6-BE5,0) -> 38 | BG6: 23969979 | BH6: =IF(BG6>=BG5,BG6-BG5,0)-(0.45*BN6)-(0.45*BP6)-BR6 -> 4930.4 | BI6: =AP6+AR6+AT6+AV6+AX6+AZ6+BB6+BD6+BF6+BH6 -> 10542.562 | BJ6: =BI6+AN6 -> 15460.962 | BK6: 1420150 | BL6: =IF(BK6>=BK5,BK6-BK5,0) -> 314 | BM6: 3909850 | BN6: =IF(BM6>=BM5,BM6-BM5,0) -> 383 | BO6: 409716 | BP6: =IF(BO6>=BO5,BO6-BO5,0) -> 125 | BQ6: 513751 | BR6: =IF(BQ6>=BQ5,BQ6-BQ5,0) -> 141 | BS6: =J6+Q6+AN6+BI6 -> 21837.963 | BT6: 232 | BU6: =IF(BS6>0,BS6/BT5,0) -> #DIV/0! | BW6: =IF(BS6>0,BS6/BV6,0) -> #DIV/0! | BX6: =((BS6-Q6)*$BZ$1)+(Q6*$BR$1) -> 25356.657 | BY6: =IF(BX6>0,BX6/BT5,0) -> #DIV/0! | BZ6: =IF(BX6>0,BX6/BV6,0) -> #DIV/0!
A7: 2 | I7: 23728030 | J7: =IF(I7>=I6,I7-I6,0) -> 6605 | K7: =M7+O7 -> 3882 | L7: 599815 | M7: =IF(L7>=L6,L7-L6,0) -> 2411 | N7: 525923 | O7: =IF(N7>=N6,N7-N6,0) -> 1471 | P7: 221223 | Q7: =IF(P7>=P6,P7-P6,0)*30 -> 570 | R7: 178215 | S7: =IF(R7>=R6,R7-R6,0) -> 148 | T7: 325617 | U7: =IF(T7>=T6,T7-T6,0) -> 274 | V7: 738127 | W7: =IF(V7>=V6,V7-V6,0)*0.53 -> 1250.8 | X7: 116902 | Y7: =IF(X7>=X6,X7-X6,0)*0.53 -> 0 | Z7: 134669 | AA7: =IF(Z7>=Z6,Z7-Z6,0)*0.53 -> 0 | AB7: 488247 | AC7: =IF(AB7>=AB6,AB7-AB6,0)*0.53 -> 0 | AD7: 656256 | AE7: =IF(AD7>=AD6,AD7-AD6,0)*0.53 -> 13.78 | AF7: 834948 | AG7: =IF(AF7>=AF6,AF7-AF6,0)*0.53 -> 13.25 | AH7: 969346 | AI7: =IF(AH7>=AH6,AH7-AH6,0)*0.53 -> 587.77 | AJ7: 633074 | AK7: =IF(AJ7>=AJ6,AJ7-AJ6,0)*0.53 -> 2593.82 | AL7: 484605 | AM7: =IF(AL7>=AL6,AL7-AL6,0)*0.53 -> 163.24 | AN7: =W7+Y7+AA7+AC7+AE7+AG7+AI7+AK7+AM7 -> 4622.66 | AO7: 7649925 | AP7: =IF(AO7>=AO6,AO7-AO6,0)*0.1125 -> 4.3875 | AQ7: 668034 | AR7: =IF(AQ7>=AQ6,AQ7-AQ6,0) -> 353 | AS7: 962243 | AT7: =IF(AS7>=AS6,AS7-AS6,0) -> 136 | AU7: 809321 | AV7: =IF(AU7>=AU6,AU7-AU6,0) -> 28 | AW7: 2604534 | AX7: =IF(AW7>=AW6,AW7-AW6,0) -> 622 | AY7: 229199 | AZ7: =IF(AY7>=AY6,AY7-AY6,0) -> 66 | BA7: 19172103 | BB7: =IF(BA7>=BA6,BA7-BA6,0) -> 4687 | BC7: 560660 | BD7: =IF(BC7>=BC6,BC7-BC6,0) -> 254 | BE7: 25200 | BF7: =IF(BE7>=BE6,BE7-BE6,0) -> 52 | BG7: 23975822 | BH7: =IF(BG7>=BG6,BG7-BG6,0)-(0.45*BN7)-(0.45*BP7)-BR7 -> 5186.25 | BI7: =AP7+AR7+AT7+AV7+AX7+AZ7+BB7+BD7+BF7+BH7 -> 11388.638 | BJ7: =BI7+AN7 -> 16011.298 | BK7: 1420425 | BL7: =IF(BK7>=BK6,BK7-BK6,0) -> 275 | BM7: 3910788 | BN7: =IF(BM7>=BM6,BM7-BM6,0) -> 938 | BO7: 409873 | BP7: =IF(BO7>=BO6,BO7-BO6,0) -> 157 | BQ7: 513915 | BR7: =IF(BQ7>=BQ6,BQ7-BQ6,0) -> 164 | BS7: =J7+Q7+AN7+BI7 -> 23186.298 | BT7: 191 | BU7: =IF(BS7>0,BS7/BT6,0) -> 99.940938 | BW7: =IF(BS7>0,BS7/BV7,0) -> #DIV/0! | BX7: =((BS7-Q7)*$BZ$1)+(Q7*$BR$1) -> 26920.742 | BY7: =IF(BX7>0,BX7/BT6,0) -> 116.03768 | BZ7: =IF(BX7>0,BX7/BV7,0) -> #DIV/0!
A8: 3 | C8: =IF(+B8-B7>0,B8-B7,(B8-B7)>0)*800 -> 0 | E8: =IF(+D8-D7>0,D8-D7,(D8-D7)>0)*80 -> 0 | G8: =IF(+F8-F7>0,F8-F7,(F8-F7)>0)*10 -> 0 | H8: 57 | I8: 23734176 | J8: =IF(I8>=I7,I8-I7,0) -> 6146 | K8: =M8+O8 -> 3709 | L8: 602116 | M8: =IF(L8>=L7,L8-L7,0) -> 2301 | N8: 527331 | O8: =IF(N8>=N7,N8-N7,0) -> 1408 | P8: 221239 | Q8: =IF(P8>=P7,P8-P7,0)*30 -> 480 | R8: 178357 | S8: =IF(R8>=R7,R8-R7,0) -> 142 | T8: 325818 | U8: =IF(T8>=T7,T8-T7,0) -> 201 | V8: 740425 | W8: =IF(V8>=V7,V8-V7,0)*0.53 -> 1217.94 | X8: 116925 | Y8: =IF(X8>=X7,X8-X7,0)*0.53 -> 12.19 | Z8: 134745 | AA8: =IF(Z8>=Z7,Z8-Z7,0)*0.53 -> 40.28 | AB8: 488293 | AC8: =IF(AB8>=AB7,AB8-AB7,0)*0.53 -> 24.38 | AD8: 656280 | AE8: =IF(AD8>=AD7,AD8-AD7,0)*0.53 -> 12.72 | AF8: 834971 | AG8: =IF(AF8>=AF7,AF8-AF7,0)*0.53 -> 12.19 | AH8: 970444 | AI8: =IF(AH8>=AH7,AH8-AH7,0)*0.53 -> 581.94 | AJ8: 637098 | AK8: =IF(AJ8>=AJ7,AJ8-AJ7,0)*0.53 -> 2132.72 | AL8: 484896 | AM8: =IF(AL8>=AL7,AL8-AL7,0)*0.53 -> 154.23 | AN8: =W8+Y8+AA8+AC8+AE8+AG8+AI8+AK8+AM8 -> 4188.59 | AO8: 7649962 | AP8: =IF(AO8>=AO7,AO8-AO7,0)*0.1125 -> 4.1625 | AQ8: 668363 | AR8: =IF(AQ8>=AQ7,AQ8-AQ7,0) -> 329 | AS8: 962379 | AT8: =IF(AS8>=AS7,AS8-AS7,0) -> 136 | AU8: 809350 | AV8: =IF(AU8>=AU7,AU8-AU7,0) -> 29 | AW8: 2605112 | AX8: =IF(AW8>=AW7,AW8-AW7,0) -> 578 | AY8: 229258 | AZ8: =IF(AY8>=AY7,AY8-AY7,0) -> 59 | BA8: 19176636 | BB8: =IF(BA8>=BA7,BA8-BA7,0) -> 4533 | BC8: 560919 | BD8: =IF(BC8>=BC7,BC8-BC7,0) -> 259 | BE8: 25251 | BF8: =IF(BE8>=BE7,BE8-BE7,0) -> 51 | BG8: 23981116 | BH8: =IF(BG8>=BG7,BG8-BG7,0)-(0.45*BN8)-(0.45*BP8)-BR8 -> 4695.45 | BI8: =AP8+AR8+AT8+AV8+AX8+AZ8+BB8+BD8+BF8+BH8 -> 10673.613 | BJ8: =BI8+AN8 -> 14862.203 | BK8: 1420671 | BL8: =IF(BK8>=BK7,BK8-BK7,0) -> 246 | BM8: 3911650 | BN8: =IF(BM8>=BM7,BM8-BM7,0) -> 862 | BO8: 410010 | BP8: =IF(BO8>=BO7,BO8-BO7,0) -> 137 | BQ8: 514064 | BR8: =IF(BQ8>=BQ7,BQ8-BQ7,0) -> 149 | BS8: =J8+Q8+AN8+BI8 -> 21488.202 | BT8: 219 | BU8: =IF(BS8>0,BS8/BT7,0) -> 112.50368 | BW8: =IF(BS8>0,BS8/BV8,0) -> #DIV/0! | BX8: =((BS8-Q8)*$BZ$1)+(Q8*$BR$1) -> 24927.433 | BY8: =IF(BX8>0,BX8/BT7,0) -> 130.51012 | BZ8: =IF(BX8>0,BX8/BV8,0) -> #DIV/0!
A9: 4 | C9: =IF(+B9-B8>0,B9-B8,(B9-B8)>0)*800 -> 0 | E9: =IF(+D9-D8>0,D9-D8,(D9-D8)>0)*80 -> 0 | G9: =IF(+F9-F8>0,F9-F8,(F9-F8)>0)*10 -> 0 | I9: 23740751 | J9: =IF(I9>=I8,I9-I8,0) -> 6575 | K9: =M9+O9 -> 3994 | L9: 604576 | M9: =IF(L9>=L8,L9-L8,0) -> 2460 | N9: 528865 | O9: =IF(N9>=N8,N9-N8,0) -> 1534 | P9: 221258 | Q9: =IF(P9>=P8,P9-P8,0)*30 -> 570 | R9: 178495 | S9: =IF(R9>=R8,R9-R8,0) -> 138 | T9: 326148 | U9: =IF(T9>=T8,T9-T8,0) -> 330 | V9: 742505 | W9: =IF(V9>=V8,V9-V8,0)*0.53 -> 1102.4 | X9: 116925 | Y9: =IF(X9>=X8,X9-X8,0)*0.53 -> 0 | Z9: 134745 | AA9: =IF(Z9>=Z8,Z9-Z8,0)*0.53 -> 0 | AB9: 488293 | AC9: =IF(AB9>=AB8,AB9-AB8,0)*0.53 -> 0 | AD9: 656303 | AE9: =IF(AD9>=AD8,AD9-AD8,0)*0.53 -> 12.19 | AF9: 834994 | AG9: =IF(AF9>=AF8,AF9-AF8,0)*0.53 -> 12.19 | AH9: 971310 | AI9: =IF(AH9>=AH8,AH9-AH8,0)*0.53 -> 458.98 | AJ9: 640924 | AK9: =IF(AJ9>=AJ8,AJ9-AJ8,0)*0.53 -> 2027.78 | AL9: 485206 | AM9: =IF(AL9>=AL8,AL9-AL8,0)*0.53 -> 164.3 | AN9: =W9+Y9+AA9+AC9+AE9+AG9+AI9+AK9+AM9 -> 3777.84 | AO9: 7650003 | AP9: =IF(AO9>=AO8,AO9-AO8,0)*0.1125 -> 4.6125 | AQ9: 668689 | AR9: =IF(AQ9>=AQ8,AQ9-AQ8,0) -> 326 | AS9: 962516 | AT9: =IF(AS9>=AS8,AS9-AS8,0) -> 137 | AU9: 809383 | AV9: =IF(AU9>=AU8,AU9-AU8,0) -> 33 | AW9: 2605729 | AX9: =IF(AW9>=AW8,AW9-AW8,0) -> 617 | AY9: 229323 | AZ9: =IF(AY9>=AY8,AY9-AY8,0) -> 65 | BA9: 19181492 | BB9: =IF(BA9>=BA8,BA9-BA8,0) -> 4856 | BC9: 561210 | BD9: =IF(BC9>=BC8,BC9-BC8,0) -> 291 | BE9: 25303 | BF9: =IF(BE9>=BE8,BE9-BE8,0) -> 52 | BG9: 23986958 | BH9: =IF(BG9>=BG8,BG9-BG8,0)-(0.45*BN9)-(0.45*BP9)-BR9 -> 5198.25 | BI9: =AP9+AR9+AT9+AV9+AX9+AZ9+BB9+BD9+BF9+BH9 -> 11579.862 | BJ9: =BI9+AN9 -> 15357.702 | BK9: 1420940 | BL9: =IF(BK9>=BK8,BK9-BK8,0) -> 269 | BM9: 3912599 | BN9: =IF(BM9>=BM8,BM9-BM8,0) -> 949 | BO9: 410156 | BP9: =IF(BO9>=BO8,BO9-BO8,0) -> 146 | BQ9: 514215 | BR9: =IF(BQ9>=BQ8,BQ9-BQ8,0) -> 151 | BS9: =J9+Q9+AN9+BI9 -> 22502.702 | BT9: 205 | BU9: =IF(BS9>0,BS9/BT8,0) -> 102.75207 | BW9: =IF(BS9>0,BS9/BV9,0) -> #DIV/0! | BX9: =((BS9-Q9)*$BZ$1)+(Q9*$BR$1) -> 26134.608 | BY9: =IF(BX9>0,BX9/BT8,0) -> 119.33611 | BZ9: =IF(BX9>0,BX9/BV9,0) -> #DIV/0!
A10: 5 | C10: =IF(+B10-B9>0,B10-B9,(B10-B9)>0)*800 -> 0 | E10: =IF(+D10-D9>0,D10-D9,(D10-D9)>0)*80 -> 0 | G10: =IF(+F10-F9>0,F10-F9,(F10-F9)>0)*10 -> 0 | H10: 58 | I10: 23747324 | J10: =IF(I10>=I9,I10-I9,0) -> 6573 | K10: =M10+O10 -> 4119 | L10: 607115 | M10: =IF(L10>=L9,L10-L9,0) -> 2539 | N10: 530445 | O10: =IF(N10>=N9,N10-N9,0) -> 1580 | P10: 221275 | Q10: =IF(P10>=P9,P10-P9,0)*30 -> 510 | R10: 178639 | S10: =IF(R10>=R9,R10-R9,0) -> 144 | T10: 326420 | U10: =IF(T10>=T9,T10-T9,0) -> 272 | V10: 745763 | W10: =IF(V10>=V9,V10-V9,0)*0.53 -> 1726.74 | X10: 116925 | Y10: =IF(X10>=X9,X10-X9,0)*0.53 -> 0 | Z10: 134745 | AA10: =IF(Z10>=Z9,Z10-Z9,0)*0.53 -> 0 | AB10: 488293 | AC10: =IF(AB10>=AB9,AB10-AB9,0)*0.53 -> 0 | AD10: 656330 | AE10: =IF(AD10>=AD9,AD10-AD9,0)*0.53 -> 14.31 | AF10: 835020 | AG10: =IF(AF10>=AF9,AF10-AF9,0)*0.53 -> 13.78 | AH10: 972189 | AI10: =IF(AH10>=AH9,AH10-AH9,0)*0.53 -> 465.87 | AJ10: 645300 | AK10: =IF(AJ10>=AJ9,AJ10-AJ9,0)*0.53 -> 2319.28 | AL10: 485528 | AM10: =IF(AL10>=AL9,AL10-AL9,0)*0.53 -> 170.66 | AN10: =W10+Y10+AA10+AC10+AE10+AG10+AI10+AK10+AM10 -> 4710.64 | AO10: 7650042 | AP10: =IF(AO10>=AO9,AO10-AO9,0)*0.1125 -> 4.3875 | AQ10: 668994 | AR10: =IF(AQ10>=AQ9,AQ10-AQ9,0) -> 305 | AS10: 962654 | AT10: =IF(AS10>=AS9,AS10-AS9,0) -> 138 | AU10: 809408 | AV10: =IF(AU10>=AU9,AU10-AU9,0) -> 25 | AW10: 2606367 | AX10: =IF(AW10>=AW9,AW10-AW9,0) -> 638 | AY10: 229384 | AZ10: =IF(AY10>=AY9,AY10-AY9,0) -> 61 | BA10: 19186303 | BB10: =IF(BA10>=BA9,BA10-BA9,0) -> 4811 | BC10: 561472 | BD10: =IF(BC10>=BC9,BC10-BC9,0) -> 262 | BE10: 25357 | BF10: =IF(BE10>=BE9,BE10-BE9,0) -> 54 | BG10: 23992604 | BH10: =IF(BG10>=BG9,BG10-BG9,0)-(0.45*BN10)-(0.45*BP10)-BR10 -> 5014.3 | BI10: =AP10+AR10+AT10+AV10+AX10+AZ10+BB10+BD10+BF10+BH10 -> 11312.688 | BJ10: =BI10+AN10 -> 16023.327 | BK10: 1421203 | BL10: =IF(BK10>=BK9,BK10-BK9,0) -> 263 | BM10: 3913518 | BN10: =IF(BM10>=BM9,BM10-BM9,0) -> 919 | BO10: 410283 | BP10: =IF(BO10>=BO9,BO10-BO9,0) -> 127 | BQ10: 514376 | BR10: =IF(BQ10>=BQ9,BQ10-BQ9,0) -> 161 | BS10: =J10+Q10+AN10+BI10 -> 23106.327 | BT10: 199 | BU10: =IF(BS10>0,BS10/BT9,0) -> 112.71379 | BW10: =IF(BS10>0,BS10/BV10,0) -> #DIV/0! | BX10: =((BS10-Q10)*$BZ$1)+(Q10*$BR$1) -> 26801.777 | BY10: =IF(BX10>0,BX10/BT9,0) -> 130.74037 | BZ10: =IF(BX10>0,BX10/BV10,0) -> #DIV/0!
A11: 6 | C11: =IF(+B11-B10>0,B11-B10,(B11-B10)>0)*800 -> 0 | E11: =IF(+D11-D10>0,D11-D10,(D11-D10)>0)*80 -> 0 | G11: =IF(+F11-F10>0,F11-F10,(F11-F10)>0)*10 -> 0 | I11: 23752902 | J11: =IF(I11>=I10,I11-I10,0) -> 5578 | K11: =M11+O11 -> 3498 | L11: 609280 | M11: =IF(L11>=L10,L11-L10,0) -> 2165 | N11: 531778 | O11: =IF(N11>=N10,N11-N10,0) -> 1333 | P11: 221292 | Q11: =IF(P11>=P10,P11-P10,0)*30 -> 510 | R11: 178773 | S11: =IF(R11>=R10,R11-R10,0) -> 134 | T11: 326672 | U11: =IF(T11>=T10,T11-T10,0) -> 252 | V11: 748146 | W11: =IF(V11>=V10,V11-V10,0)*0.53 -> 1262.99 | X11: 116925 | Y11: =IF(X11>=X10,X11-X10,0)*0.53 -> 0 | Z11: 134745 | AA11: =IF(Z11>=Z10,Z11-Z10,0)*0.53 -> 0 | AB11: 488293 | AC11: =IF(AB11>=AB10,AB11-AB10,0)*0.53 -> 0 | AD11: 656353 | AE11: =IF(AD11>=AD10,AD11-AD10,0)*0.53 -> 12.19 | AF11: 835042 | AG11: =IF(AF11>=AF10,AF11-AF10,0)*0.53 -> 11.66 | AH11: 972972 | AI11: =IF(AH11>=AH10,AH11-AH10,0)*0.53 -> 414.99 | AJ11: 649067 | AK11: =IF(AJ11>=AJ10,AJ11-AJ10,0)*0.53 -> 1996.51 | AL11: 485817 | AM11: =IF(AL11>=AL10,AL11-AL10,0)*0.53 -> 153.17 | AN11: =W11+Y11+AA11+AC11+AE11+AG11+AI11+AK11+AM11 -> 3851.51 | AO11: 7650081 | AP11: =IF(AO11>=AO10,AO11-AO10,0)*0.1125 -> 4.3875 | AQ11: 669310 | AR11: =IF(AQ11>=AQ10,AQ11-AQ10,0) -> 316 | AS11: 962783 | AT11: =IF(AS11>=AS10,AS11-AS10,0) -> 129 | AU11: 809431 | AV11: =IF(AU11>=AU10,AU11-AU10,0) -> 23 | AW11: 2606943 | AX11: =IF(AW11>=AW10,AW11-AW10,0) -> 576 | AY11: 229442 | AZ11: =IF(AY11>=AY10,AY11-AY10,0) -> 58 | BA11: 19190577 | BB11: =IF(BA11>=BA10,BA11-BA10,0) -> 4274 | BC11: 561708 | BD11: =IF(BC11>=BC10,BC11-BC10,0) -> 236 | BE11: 25411 | BF11: =IF(BE11>=BE10,BE11-BE10,0) -> 54 | BG11: 23997719 | BH11: =IF(BG11>=BG10,BG11-BG10,0)-(0.45*BN11)-(0.45*BP11)-BR11 -> 4540.95 | BI11: =AP11+AR11+AT11+AV11+AX11+AZ11+BB11+BD11+BF11+BH11 -> 10211.338 | BJ11: =BI11+AN11 -> 14062.848 | BK11: 1421445 | BL11: =IF(BK11>=BK10,BK11-BK10,0) -> 242 | BM11: 3914330 | BN11: =IF(BM11>=BM10,BM11-BM10,0) -> 812 | BO11: 410420 | BP11: =IF(BO11>=BO10,BO11-BO10,0) -> 137 | BQ11: 514523 | BR11: =IF(BQ11>=BQ10,BQ11-BQ10,0) -> 147 | BS11: =J11+Q11+AN11+BI11 -> 20150.848 | BT11: 203 | BU11: =IF(BS11>0,BS11/BT10,0) -> 101.26054 | BW11: =IF(BS11>0,BS11/BV11,0) -> #DIV/0! | BX11: =((BS11-Q11)*$BZ$1)+(Q11*$BR$1) -> 23402.975 | BY11: =IF(BX11>0,BX11/BT10,0) -> 117.60289 | BZ11: =IF(BX11>0,BX11/BV11,0) -> #DIV/0!
A12: 7 | C12: =IF(+B12-B11>0,B12-B11,(B12-B11)>0)*800 -> 0 | E12: =IF(+D12-D11>0,D12-D11,(D12-D11)>0)*80 -> 0 | G12: =IF(+F12-F11>0,F12-F11,(F12-F11)>0)*10 -> 0 | H12: 59 | I12: 23758520 | J12: =IF(I12>=I11,I12-I11,0) -> 5618 | K12: =M12+O12 -> 3516 | L12: 611439 | M12: =IF(L12>=L11,L12-L11,0) -> 2159 | N12: 533135 | O12: =IF(N12>=N11,N12-N11,0) -> 1357 | P12: 221308 | Q12: =IF(P12>=P11,P12-P11,0)*30 -> 480 | R12: 178913 | S12: =IF(R12>=R11,R12-R11,0) -> 140 | T12: 326937 | U12: =IF(T12>=T11,T12-T11,0) -> 265 | V12: 750666 | W12: =IF(V12>=V11,V12-V11,0)*0.53 -> 1335.6 | X12: 116439 | Y12: =IF(X12>=X11,X12-X11,0)*0.53 -> 0 | Z12: 134745 | AA12: =IF(Z12>=Z11,Z12-Z11,0)*0.53 -> 0 | AB12: 488293 | AC12: =IF(AB12>=AB11,AB12-AB11,0)*0.53 -> 0 | AD12: 656378 | AE12: =IF(AD12>=AD11,AD12-AD11,0)*0.53 -> 13.25 | AF12: 835066 | AG12: =IF(AF12>=AF11,AF12-AF11,0)*0.53 -> 12.72 | AH12: 973784 | AI12: =IF(AH12>=AH11,AH12-AH11,0)*0.53 -> 430.36 | AJ12: 653149 | AK12: =IF(AJ12>=AJ11,AJ12-AJ11,0)*0.53 -> 2163.46 | AL12: 486112 | AM12: =IF(AL12>=AL11,AL12-AL11,0)*0.53 -> 156.35 | AN12: =W12+Y12+AA12+AC12+AE12+AG12+AI12+AK12+AM12 -> 4111.74 | AO12: 7650119 | AP12: =IF(AO12>=AO11,AO12-AO11,0)*0.1125 -> 4.275 | AQ12: 669655 | AR12: =IF(AQ12>=AQ11,AQ12-AQ11,0) -> 345 | AS12: 962916 | AT12: =IF(AS12>=AS11,AS12-AS11,0) -> 133 | AU12: 809448 | AV12: =IF(AU12>=AU11,AU12-AU11,0) -> 17 | AW12: 2607531 | AX12: =IF(AW12>=AW11,AW12-AW11,0) -> 588 | AY12: 229472 | AZ12: =IF(AY12>=AY11,AY12-AY11,0) -> 30 | BA12: 19194813 | BB12: =IF(BA12>=BA11,BA12-BA11,0) -> 4236 | BC12: 561967 | BD12: =IF(BC12>=BC11,BC12-BC11,0) -> 259 | BE12: 25467 | BF12: =IF(BE12>=BE11,BE12-BE11,0) -> 56 | BG12: 24003151 | BH12: =IF(BG12>=BG11,BG12-BG11,0)-(0.45*BN12)-(0.45*BP12)-BR12 -> 4818.55 | BI12: =AP12+AR12+AT12+AV12+AX12+AZ12+BB12+BD12+BF12+BH12 -> 10486.825 | BJ12: =BI12+AN12 -> 14598.565 | BK12: 1421700 | BL12: =IF(BK12>=BK11,BK12-BK11,0) -> 255 | BM12: 3915212 | BN12: =IF(BM12>=BM11,BM12-BM11,0) -> 882 | BO12: 410559 | BP12: =IF(BO12>=BO11,BO12-BO11,0) -> 139 | BQ12: 514677 | BR12: =IF(BQ12>=BQ11,BQ12-BQ11,0) -> 154 | BS12: =J12+Q12+AN12+BI12 -> 20696.565 | BT12: 233 | BU12: =IF(BS12>0,BS12/BT11,0) -> 101.95352 | BW12: =IF(BS12>0,BS12/BV12,0) -> #DIV/0! | BX12: =((BS12-Q12)*$BZ$1)+(Q12*$BR$1) -> 24017.05 | BY12: =IF(BX12>0,BX12/BT11,0) -> 118.31059 | BZ12: =IF(BX12>0,BX12/BV12,0) -> #DIV/0!
A13: 8 | C13: =IF(+B13-B12>0,B13-B12,(B13-B12)>0)*800 -> 0 | E13: =IF(+D13-D12>0,D13-D12,(D13-D12)>0)*80 -> 0 | G13: =IF(+F13-F12>0,F13-F12,(F13-F12)>0)*10 -> 0 | I13: 23764384 | J13: =IF(I13>=I12,I13-I12,0) -> 5864 | K13: =M13+O13 -> 3590 | L13: 613655 | M13: =IF(L13>=L12,L13-L12,0) -> 2216 | N13: 534509 | O13: =IF(N13>=N12,N13-N12,0) -> 1374 | P13: 221325 | Q13: =IF(P13>=P12,P13-P12,0)*30 -> 510 | R13: 179055 | S13: =IF(R13>=R12,R13-R12,0) -> 142 | T13: 327202 | U13: =IF(T13>=T12,T13-T12,0) -> 265 | V13: 753310 | W13: =IF(V13>=V12,V13-V12,0)*0.53 -> 1401.32 | X13: 116925 | Y13: =IF(X13>=X12,X13-X12,0)*0.53 -> 257.58 | Z13: 134745 | AA13: =IF(Z13>=Z12,Z13-Z12,0)*0.53 -> 0 | AB13: 488293 | AC13: =IF(AB13>=AB12,AB13-AB12,0)*0.53 -> 0 | AD13: 656403 | AE13: =IF(AD13>=AD12,AD13-AD12,0)*0.53 -> 13.25 | AF13: 835090 | AG13: =IF(AF13>=AF12,AF13-AF12,0)*0.53 -> 12.72 | AH13: 974566 | AI13: =IF(AH13>=AH12,AH13-AH12,0)*0.53 -> 414.46 | AJ13: 657057 | AK13: =IF(AJ13>=AJ12,AJ13-AJ12,0)*0.53 -> 2071.24 | AL13: 486405 | AM13: =IF(AL13>=AL12,AL13-AL12,0)*0.53 -> 155.29 | AN13: =W13+Y13+AA13+AC13+AE13+AG13+AI13+AK13+AM13 -> 4325.86 | AO13: 7650156 | AP13: =IF(AO13>=AO12,AO13-AO12,0)*0.1125 -> 4.1625 | AQ13: 669972 | AR13: =IF(AQ13>=AQ12,AQ13-AQ12,0) -> 317 | AS13: 963055 | AT13: =IF(AS13>=AS12,AS13-AS12,0) -> 139 | AU13: 809468 | AV13: =IF(AU13>=AU12,AU13-AU12,0) -> 20 | AW13: 2608121 | AX13: =IF(AW13>=AW12,AW13-AW12,0) -> 590 | AY13: 229472 | AZ13: =IF(AY13>=AY12,AY13-AY12,0) -> 0 | BA13: 19199156 | BB13: =IF(BA13>=BA12,BA13-BA12,0) -> 4343 | BC13: 562227 | BD13: =IF(BC13>=BC12,BC13-BC12,0) -> 260 | BE13: 25513 | BF13: =IF(BE13>=BE12,BE13-BE12,0) -> 46 | BG13: 24008622 | BH13: =IF(BG13>=BG12,BG13-BG12,0)-(0.45*BN13)-(0.45*BP13)-BR13 -> 4850.5 | BI13: =AP13+AR13+AT13+AV13+AX13+AZ13+BB13+BD13+BF13+BH13 -> 10569.663 | BJ13: =BI13+AN13 -> 14895.522 | BK13: 1421955 | BL13: =IF(BK13>=BK12,BK13-BK12,0) -> 255 | BM13: 3916112 | BN13: =IF(BM13>=BM12,BM13-BM12,0) -> 900 | BO13: 410689 | BP13: =IF(BO13>=BO12,BO13-BO12,0) -> 130 | BQ13: 514834 | BR13: =IF(BQ13>=BQ12,BQ13-BQ12,0) -> 157 | BS13: =J13+Q13+AN13+BI13 -> 21269.522 | BT13: 238 | BU13: =IF(BS13>0,BS13/BT12,0) -> 91.285504 | BW13: =IF(BS13>0,BS13/BV13,0) -> #DIV/0! | BX13: =((BS13-Q13)*$BZ$1)+(Q13*$BR$1) -> 24689.451 | BY13: =IF(BX13>0,BX13/BT12,0) -> 105.96331 | BZ13: =IF(BX13>0,BX13/BV13,0) -> #DIV/0!
A14: 9 | C14: =IF(+B14-B13>0,B14-B13,(B14-B13)>0)*800 -> 0 | E14: =IF(+D14-D13>0,D14-D13,(D14-D13)>0)*80 -> 0 | G14: =IF(+F14-F13>0,F14-F13,(F14-F13)>0)*10 -> 0 | H14: 60 | I14: 23769967 | J14: =IF(I14>=I13,I14-I13,0) -> 5583 | K14: =M14+O14 -> 3778 | L14: 615991 | M14: =IF(L14>=L13,L14-L13,0) -> 2336 | N14: 535951 | O14: =IF(N14>=N13,N14-N13,0) -> 1442 | P14: 221341 | Q14: =IF(P14>=P13,P14-P13,0)*30 -> 480 | R14: 179192 | S14: =IF(R14>=R13,R14-R13,0) -> 137 | T14: 327455 | U14: =IF(T14>=T13,T14-T13,0) -> 253 | V14: 755520 | W14: =IF(V14>=V13,V14-V13,0)*0.53 -> 1171.3 | X14: 116925 | Y14: =IF(X14>=X13,X14-X13,0)*0.53 -> 0 | Z14: 134745 | AA14: =IF(Z14>=Z13,Z14-Z13,0)*0.53 -> 0 | AB14: 488293 | AC14: =IF(AB14>=AB13,AB14-AB13,0)*0.53 -> 0 | AD14: 656427 | AE14: =IF(AD14>=AD13,AD14-AD13,0)*0.53 -> 12.72 | AF14: 835114 | AG14: =IF(AF14>=AF13,AF14-AF13,0)*0.53 -> 12.72 | AH14: 975358 | AI14: =IF(AH14>=AH13,AH14-AH13,0)*0.53 -> 419.76 | AJ14: 661185 | AK14: =IF(AJ14>=AJ13,AJ14-AJ13,0)*0.53 -> 2187.84 | AL14: 486703 | AM14: =IF(AL14>=AL13,AL14-AL13,0)*0.53 -> 157.94 | AN14: =W14+Y14+AA14+AC14+AE14+AG14+AI14+AK14+AM14 -> 3962.28 | AO14: 7650193 | AP14: =IF(AO14>=AO13,AO14-AO13,0)*0.1125 -> 4.1625 | AQ14: 670294 | AR14: =IF(AQ14>=AQ13,AQ14-AQ13,0) -> 322 | AS14: 963201 | AT14: =IF(AS14>=AS13,AS14-AS13,0) -> 146 | AU14: 809496 | AV14: =IF(AU14>=AU13,AU14-AU13,0) -> 28 | AW14: 2608712 | AX14: =IF(AW14>=AW13,AW14-AW13,0) -> 591 | AY14: 229472 | AZ14: =IF(AY14>=AY13,AY14-AY13,0) -> 0 | BA14: 19203610 | BB14: =IF(BA14>=BA13,BA14-BA13,0) -> 4454 | BC14: 562467 | BD14: =IF(BC14>=BC13,BC14-BC13,0) -> 240 | BE14: 25559 | BF14: =IF(BE14>=BE13,BE14-BE13,0) -> 46 | BG14: 24013997 | BH14: =IF(BG14>=BG13,BG14-BG13,0)-(0.45*BN14)-(0.45*BP14)-BR14 -> 4768.05 | BI14: =AP14+AR14+AT14+AV14+AX14+AZ14+BB14+BD14+BF14+BH14 -> 10599.213 | BJ14: =BI14+AN14 -> 14561.493 | BK14: 1422205 | BL14: =IF(BK14>=BK13,BK14-BK13,0) -> 250 | BM14: 3916991 | BN14: =IF(BM14>=BM13,BM14-BM13,0) -> 879 | BO14: 410821 | BP14: =IF(BO14>=BO13,BO14-BO13,0) -> 132 | BQ14: 514986 | BR14: =IF(BQ14>=BQ13,BQ14-BQ13,0) -> 152 | BS14: =J14+Q14+AN14+BI14 -> 20624.493 | BT14: 220 | BU14: =IF(BS14>0,BS14/BT13,0) -> 86.657532 | BW14: =IF(BS14>0,BS14/BV14,0) -> #DIV/0! | BX14: =((BS14-Q14)*$BZ$1)+(Q14*$BR$1) -> 23934.166 | BY14: =IF(BX14>0,BX14/BT13,0) -> 100.56372 | BZ14: =IF(BX14>0,BX14/BV14,0) -> #DIV/0!
A15: 10 | C15: =IF(+B15-B14>0,B15-B14,(B15-B14)>0)*800 -> 0 | E15: =IF(+D15-D14>0,D15-D14,(D15-D14)>0)*80 -> 0 | G15: =IF(+F15-F14>0,F15-F14,(F15-F14)>0)*10 -> 0 | I15: 23777334 | J15: =IF(I15>=I14,I15-I14,0) -> 7367 | K15: =M15+O15 -> 4484 | L15: 618882 | M15: =IF(L15>=L14,L15-L14,0) -> 2891 | N15: 537544 | O15: =IF(N15>=N14,N15-N14,0) -> 1593 | P15: 221360 | Q15: =IF(P15>=P14,P15-P14,0)*30 -> 570 | R15: 179342 | S15: =IF(R15>=R14,R15-R14,0) -> 150 | T15: 327733 | U15: =IF(T15>=T14,T15-T14,0) -> 278 | V15: 757435 | W15: =IF(V15>=V14,V15-V14,0)*0.53 -> 1014.95 | X15: 116925 | Y15: =IF(X15>=X14,X15-X14,0)*0.53 -> 0 | Z15: 134745 | AA15: =IF(Z15>=Z14,Z15-Z14,0)*0.53 -> 0 | AB15: 488293 | AC15: =IF(AB15>=AB14,AB15-AB14,0)*0.53 -> 0 | AD15: 656454 | AE15: =IF(AD15>=AD14,AD15-AD14,0)*0.53 -> 14.31 | AF15: 835140 | AG15: =IF(AF15>=AF14,AF15-AF14,0)*0.53 -> 13.78 | AH15: 976233 | AI15: =IF(AH15>=AH14,AH15-AH14,0)*0.53 -> 463.75 | AJ15: 665695 | AK15: =IF(AJ15>=AJ14,AJ15-AJ14,0)*0.53 -> 2390.3 | AL15: 487030 | AM15: =IF(AL15>=AL14,AL15-AL14,0)*0.53 -> 173.31 | AN15: =W15+Y15+AA15+AC15+AE15+AG15+AI15+AK15+AM15 -> 4070.4 | AO15: 7650236 | AP15: =IF(AO15>=AO14,AO15-AO14,0)*0.1125 -> 4.8375 | AQ15: 670626 | AR15: =IF(AQ15>=AQ14,AQ15-AQ14,0) -> 332 | AS15: 963353 | AT15: =IF(AS15>=AS14,AS15-AS14,0) -> 152 | AU15: 809536 | AV15: =IF(AU15>=AU14,AU15-AU14,0) -> 40 | AW15: 2609337 | AX15: =IF(AW15>=AW14,AW15-AW14,0) -> 625 | AY15: 229472 | AZ15: =IF(AY15>=AY14,AY15-AY14,0) -> 0 | BA15: 19208094 | BB15: =IF(BA15>=BA14,BA15-BA14,0) -> 4484 | BC15: 562740 | BD15: =IF(BC15>=BC14,BC15-BC14,0) -> 273 | BE15: 25623 | BF15: =IF(BE15>=BE14,BE15-BE14,0) -> 64 | BG15: 24019668 | BH15: =IF(BG15>=BG14,BG15-BG14,0)-(0.45*BN15)-(0.45*BP15)-BR15 -> 5043.9 | BI15: =AP15+AR15+AT15+AV15+AX15+AZ15+BB15+BD15+BF15+BH15 -> 11018.737 | BJ15: =BI15+AN15 -> 15089.137 | BK15: 1422472 | BL15: =IF(BK15>=BK14,BK15-BK14,0) -> 267 | BM15: 3917909 | BN15: =IF(BM15>=BM14,BM15-BM14,0) -> 918 | BO15: 410961 | BP15: =IF(BO15>=BO14,BO15-BO14,0) -> 140 | BQ15: 515137 | BR15: =IF(BQ15>=BQ14,BQ15-BQ14,0) -> 151 | BS15: =J15+Q15+AN15+BI15 -> 23026.137 | BT15: 211 | BU15: =IF(BS15>0,BS15/BT14,0) -> 104.66426 | BW15: =IF(BS15>0,BS15/BV15,0) -> #DIV/0! | BX15: =((BS15-Q15)*$BZ$1)+(Q15*$BR$1) -> 26736.558 | BY15: =IF(BX15>0,BX15/BT14,0) -> 121.52981 | BZ15: =IF(BX15>0,BX15/BV15,0) -> #DIV/0!
A16: 11 | C16: =IF(+B16-B15>0,B16-B15,(B16-B15)>0)*800 -> 0 | E16: =IF(+D16-D15>0,D16-D15,(D16-D15)>0)*80 -> 0 | G16: =IF(+F16-F15>0,F16-F15,(F16-F15)>0)*10 -> 0 | H16: 61 | I16: 23783580 | J16: =IF(I16>=I15,I16-I15,0) -> 6246 | K16: =M16+O16 -> 3878 | L16: 621407 | M16: =IF(L16>=L15,L16-L15,0) -> 2525 | N16: 538897 | O16: =IF(N16>=N15,N16-N15,0) -> 1353 | P16: 221377 | Q16: =IF(P16>=P15,P16-P15,0)*30 -> 510 | R16: 179472 | S16: =IF(R16>=R15,R16-R15,0) -> 130 | T16: 327977 | U16: =IF(T16>=T15,T16-T15,0) -> 244 | V16: 759228 | W16: =IF(V16>=V15,V16-V15,0)*0.53 -> 950.29 | X16: 116925 | Y16: =IF(X16>=X15,X16-X15,0)*0.53 -> 0 | Z16: 134745 | AA16: =IF(Z16>=Z15,Z16-Z15,0)*0.53 -> 0 | AB16: 488293 | AC16: =IF(AB16>=AB15,AB16-AB15,0)*0.53 -> 0 | AD16: 656476 | AE16: =IF(AD16>=AD15,AD16-AD15,0)*0.53 -> 11.66 | AF16: 835162 | AG16: =IF(AF16>=AF15,AF16-AF15,0)*0.53 -> 11.66 | AH16: 976975 | AI16: =IF(AH16>=AH15,AH16-AH15,0)*0.53 -> 393.26 | AJ16: 669739 | AK16: =IF(AJ16>=AJ15,AJ16-AJ15,0)*0.53 -> 2143.32 | AL16: 487310 | AM16: =IF(AL16>=AL15,AL16-AL15,0)*0.53 -> 148.4 | AN16: =W16+Y16+AA16+AC16+AE16+AG16+AI16+AK16+AM16 -> 3658.59 | AO16: 7650275 | AP16: =IF(AO16>=AO15,AO16-AO15,0)*0.1125 -> 4.3875 | AQ16: 670950 | AR16: =IF(AQ16>=AQ15,AQ16-AQ15,0) -> 324 | AS16: 963486 | AT16: =IF(AS16>=AS15,AS16-AS15,0) -> 133 | AU16: 809563 | AV16: =IF(AU16>=AU15,AU16-AU15,0) -> 27 | AW16: 2609882 | AX16: =IF(AW16>=AW15,AW16-AW15,0) -> 545 | AY16: 229472 | AZ16: =IF(AY16>=AY15,AY16-AY15,0) -> 0 | BA16: 19212249 | BB16: =IF(BA16>=BA15,BA16-BA15,0) -> 4155 | BC16: 562982 | BD16: =IF(BC16>=BC15,BC16-BC15,0) -> 242 | BE16: 25677 | BF16: =IF(BE16>=BE15,BE16-BE15,0) -> 54 | BG16: 24024736 | BH16: =IF(BG16>=BG15,BG16-BG15,0)-(0.45*BN16)-(0.45*BP16)-BR16 -> 4507.9 | BI16: =AP16+AR16+AT16+AV16+AX16+AZ16+BB16+BD16+BF16+BH16 -> 9992.2875 | BJ16: =BI16+AN16 -> 13650.878 | BK16: 1422712 | BL16: =IF(BK16>=BK15,BK16-BK15,0) -> 240 | BM16: 3918720 | BN16: =IF(BM16>=BM15,BM16-BM15,0) -> 811 | BO16: 411088 | BP16: =IF(BO16>=BO15,BO16-BO15,0) -> 127 | BQ16: 515275 | BR16: =IF(BQ16>=BQ15,BQ16-BQ15,0) -> 138 | BS16: =J16+Q16+AN16+BI16 -> 20406.878 | BT16: 201 | BU16: =IF(BS16>0,BS16/BT15,0) -> 96.715059 | BW16: =IF(BS16>0,BS16/BV16,0) -> #DIV/0! | BX16: =((BS16-Q16)*$BZ$1)+(Q16*$BR$1) -> 23697.409 | BY16: =IF(BX16>0,BX16/BT15,0) -> 112.31 | BZ16: =IF(BX16>0,BX16/BV16,0) -> #DIV/0!
A17: 12 | C17: =IF(+B17-B16>0,B17-B16,(B17-B16)>0)*800 -> 0 | E17: =IF(+D17-D16>0,D17-D16,(D17-D16)>0)*80 -> 0 | G17: =IF(+F17-F16>0,F17-F16,(F17-F16)>0)*10 -> 0 | I17: 23790235 | J17: =IF(I17>=I16,I17-I16,0) -> 6655 | K17: =M17+O17 -> 4174 | L17: 624095 | M17: =IF(L17>=L16,L17-L16,0) -> 2688 | N17: 540383 | O17: =IF(N17>=N16,N17-N16,0) -> 1486 | P17: 221392 | Q17: =IF(P17>=P16,P17-P16,0)*30 -> 450 | R17: 179610 | S17: =IF(R17>=R16,R17-R16,0) -> 138 | T17: 328234 | U17: =IF(T17>=T16,T17-T16,0) -> 257 | V17: 761208 | W17: =IF(V17>=V16,V17-V16,0)*0.53 -> 1049.4 | X17: 116925 | Y17: =IF(X17>=X16,X17-X16,0)*0.53 -> 0 | Z17: 134745 | AA17: =IF(Z17>=Z16,Z17-Z16,0)*0.53 -> 0 | AB17: 488293 | AC17: =IF(AB17>=AB16,AB17-AB16,0)*0.53 -> 0 | AD17: 656500 | AE17: =IF(AD17>=AD16,AD17-AD16,0)*0.53 -> 12.72 | AF17: 835186 | AG17: =IF(AF17>=AF16,AF17-AF16,0)*0.53 -> 12.72 | AH17: 977803 | AI17: =IF(AH17>=AH16,AH17-AH16,0)*0.53 -> 438.84 | AJ17: 674193 | AK17: =IF(AJ17>=AJ16,AJ17-AJ16,0)*0.53 -> 2360.62 | AL17: 487616 | AM17: =IF(AL17>=AL16,AL17-AL16,0)*0.53 -> 162.18 | AN17: =W17+Y17+AA17+AC17+AE17+AG17+AI17+AK17+AM17 -> 4036.48 | AO17: 7650312 | AP17: =IF(AO17>=AO16,AO17-AO16,0)*0.1125 -> 4.1625 | AQ17: 671277 | AR17: =IF(AQ17>=AQ16,AQ17-AQ16,0) -> 327 | AS17: 963622 | AT17: =IF(AS17>=AS16,AS17-AS16,0) -> 136 | AU17: 809584 | AV17: =IF(AU17>=AU16,AU17-AU16,0) -> 21 | AW17: 2610471 | AX17: =IF(AW17>=AW16,AW17-AW16,0) -> 589 | AY17: 229472 | AZ17: =IF(AY17>=AY16,AY17-AY16,0) -> 0 | BA17: 19216786 | BB17: =IF(BA17>=BA16,BA17-BA16,0) -> 4537 | BC17: 563219 | BD17: =IF(BC17>=BC16,BC17-BC16,0) -> 237 | BE17: 25733 | BF17: =IF(BE17>=BE16,BE17-BE16,0) -> 56 | BG17: 24030118 | BH17: =IF(BG17>=BG16,BG17-BG16,0)-(0.45*BN17)-(0.45*BP17)-BR17 -> 4786.25 | BI17: =AP17+AR17+AT17+AV17+AX17+AZ17+BB17+BD17+BF17+BH17 -> 10693.413 | BJ17: =BI17+AN17 -> 14729.893 | BK17: 1422967 | BL17: =IF(BK17>=BK16,BK17-BK16,0) -> 255 | BM17: 3919599 | BN17: =IF(BM17>=BM16,BM17-BM16,0) -> 879 | BO17: 411224 | BP17: =IF(BO17>=BO16,BO17-BO16,0) -> 136 | BQ17: 515414 | BR17: =IF(BQ17>=BQ16,BQ17-BQ16,0) -> 139 | BS17: =J17+Q17+AN17+BI17 -> 21834.893 | BT17: 179 | BU17: =IF(BS17>0,BS17/BT16,0) -> 108.63131 | BW17: =IF(BS17>0,BS17/BV17,0) -> #DIV/0! | BX17: =((BS17-Q17)*$BZ$1)+(Q17*$BR$1) -> 25312.626 | BY17: =IF(BX17>0,BX17/BT16,0) -> 125.93346 | BZ17: =IF(BX17>0,BX17/BV17,0) -> #DIV/0!
A18: 13 | C18: =IF(+B18-B17>0,B18-B17,(B18-B17)>0)*800 -> 0 | E18: =IF(+D18-D17>0,D18-D17,(D18-D17)>0)*80 -> 0 | G18: =IF(+F18-F17>0,F18-F17,(F18-F17)>0)*10 -> 0 | H18: 62 | I18: 23796894 | J18: =IF(I18>=I17,I18-I17,0) -> 6659 | K18: =M18+O18 -> 4184 | L18: 626789 | M18: =IF(L18>=L17,L18-L17,0) -> 2694 | N18: 541873 | O18: =IF(N18>=N17,N18-N17,0) -> 1490 | P18: 221410 | Q18: =IF(P18>=P17,P18-P17,0)*30 -> 540 | R18: 179749 | S18: =IF(R18>=R17,R18-R17,0) -> 139 | T18: 328485 | U18: =IF(T18>=T17,T18-T17,0) -> 251 | V18: 763194 | W18: =IF(V18>=V17,V18-V17,0)*0.53 -> 1052.58 | X18: 116925 | Y18: =IF(X18>=X17,X18-X17,0)*0.53 -> 0 | Z18: 134745 | AA18: =IF(Z18>=Z17,Z18-Z17,0)*0.53 -> 0 | AB18: 488293 | AC18: =IF(AB18>=AB17,AB18-AB17,0)*0.53 -> 0 | AD18: 656526 | AE18: =IF(AD18>=AD17,AD18-AD17,0)*0.53 -> 13.78 | AF18: 835211 | AG18: =IF(AF18>=AF17,AF18-AF17,0)*0.53 -> 13.25 | AH18: 978640 | AI18: =IF(AH18>=AH17,AH18-AH17,0)*0.53 -> 443.61 | AJ18: 678656 | AK18: =IF(AJ18>=AJ17,AJ18-AJ17,0)*0.53 -> 2365.39 | AL18: 487925 | AM18: =IF(AL18>=AL17,AL18-AL17,0)*0.53 -> 163.77 | AN18: =W18+Y18+AA18+AC18+AE18+AG18+AI18+AK18+AM18 -> 4052.38 | AO18: 7650355 | AP18: =IF(AO18>=AO17,AO18-AO17,0)*0.1125 -> 4.8375 | AQ18: 671597 | AR18: =IF(AQ18>=AQ17,AQ18-AQ17,0) -> 320 | AS18: 963761 | AT18: =IF(AS18>=AS17,AS18-AS17,0) -> 139 | AU18: 809607 | AV18: =IF(AU18>=AU17,AU18-AU17,0) -> 23 | AW18: 2611056 | AX18: =IF(AW18>=AW17,AW18-AW17,0) -> 585 | AY18: 229472 | AZ18: =IF(AY18>=AY17,AY18-AY17,0) -> 0 | BA18: 19221621 | BB18: =IF(BA18>=BA17,BA18-BA17,0) -> 4835 | BC18: 563452 | BD18: =IF(BC18>=BC17,BC18-BC17,0) -> 233 | BE18: 25784 | BF18: =IF(BE18>=BE17,BE18-BE17,0) -> 51 | BG18: 24035857 | BH18: =IF(BG18>=BG17,BG18-BG17,0)-(0.45*BN18)-(0.45*BP18)-BR18 -> 5120.15 | BI18: =AP18+AR18+AT18+AV18+AX18+AZ18+BB18+BD18+BF18+BH18 -> 11310.987 | BJ18: =BI18+AN18 -> 15363.368 | BK18: 1423232 | BL18: =IF(BK18>=BK17,BK18-BK17,0) -> 265 | BM18: 3920511 | BN18: =IF(BM18>=BM17,BM18-BM17,0) -> 912 | BO18: 411365 | BP18: =IF(BO18>=BO17,BO18-BO17,0) -> 141 | BQ18: 515559 | BR18: =IF(BQ18>=BQ17,BQ18-BQ17,0) -> 145 | BS18: =J18+Q18+AN18+BI18 -> 22562.368 | BT18: 207 | BU18: =IF(BS18>0,BS18/BT17,0) -> 126.04675 | BW18: =IF(BS18>0,BS18/BV18,0) -> #DIV/0! | BX18: =((BS18-Q18)*$BZ$1)+(Q18*$BR$1) -> 26189.723 | BY18: =IF(BX18>0,BX18/BT17,0) -> 146.3113 | BZ18: =IF(BX18>0,BX18/BV18,0) -> #DIV/0!
A19: 14 | C19: =IF(+B19-B18>0,B19-B18,(B19-B18)>0)*800 -> 0 | E19: =IF(+D19-D18>0,D19-D18,(D19-D18)>0)*80 -> 0 | G19: =IF(+F19-F18>0,F19-F18,(F19-F18)>0)*10 -> 0 | I19: 23803960 | J19: =IF(I19>=I18,I19-I18,0) -> 7066 | K19: =M19+O19 -> 4000 | L19: 629289 | M19: =IF(L19>=L18,L19-L18,0) -> 2500 | N19: 543373 | O19: =IF(N19>=N18,N19-N18,0) -> 1500 | P19: 221428 | Q19: =IF(P19>=P18,P19-P18,0)*30 -> 540 | R19: 179889 | S19: =IF(R19>=R18,R19-R18,0) -> 140 | T19: 328746 | U19: =IF(T19>=T18,T19-T18,0) -> 261 | V19: 765094 | W19: =IF(V19>=V18,V19-V18,0)*0.53 -> 1007 | X19: 116925 | Y19: =IF(X19>=X18,X19-X18,0)*0.53 -> 0 | Z19: 134745 | AA19: =IF(Z19>=Z18,Z19-Z18,0)*0.53 -> 0 | AB19: 488293 | AC19: =IF(AB19>=AB18,AB19-AB18,0)*0.53 -> 0 | AD19: 656549 | AE19: =IF(AD19>=AD18,AD19-AD18,0)*0.53 -> 12.19 | AF19: 835235 | AG19: =IF(AF19>=AF18,AF19-AF18,0)*0.53 -> 12.72 | AH19: 979470 | AI19: =IF(AH19>=AH18,AH19-AH18,0)*0.53 -> 439.9 | AJ19: 683117 | AK19: =IF(AJ19>=AJ18,AJ19-AJ18,0)*0.53 -> 2364.33 | AL19: 488230 | AM19: =IF(AL19>=AL18,AL19-AL18,0)*0.53 -> 161.65 | AN19: =W19+Y19+AA19+AC19+AE19+AG19+AI19+AK19+AM19 -> 3997.79 | AO19: 7650395 | AP19: =IF(AO19>=AO18,AO19-AO18,0)*0.1125 -> 4.5 | AQ19: 671926 | AR19: =IF(AQ19>=AQ18,AQ19-AQ18,0) -> 329 | AS19: 963895 | AT19: =IF(AS19>=AS18,AS19-AS18,0) -> 134 | AU19: 809612 | AV19: =IF(AU19>=AU18,AU19-AU18,0) -> 5 | AW19: 2611056 | AX19: =IF(AW19>=AW18,AW19-AW18,0) -> 0 | AY19: 229472 | AZ19: =IF(AY19>=AY18,AY19-AY18,0) -> 0 | BA19: 19225863 | BB19: =IF(BA19>=BA18,BA19-BA18,0) -> 4242 | BC19: 563665 | BD19: =IF(BC19>=BC18,BC19-BC18,0) -> 213 | BE19: 25839 | BF19: =IF(BE19>=BE18,BE19-BE18,0) -> 55 | BG19: 24040797 | BH19: =IF(BG19>=BG18,BG19-BG18,0)-(0.45*BN19)-(0.45*BP19)-BR19 -> 4480.7 | BI19: =AP19+AR19+AT19+AV19+AX19+AZ19+BB19+BD19+BF19+BH19 -> 9463.2 | BJ19: =BI19+AN19 -> 13460.99 | BK19: 1423474 | BL19: =IF(BK19>=BK18,BK19-BK18,0) -> 242 | BM19: 3921117 | BN19: =IF(BM19>=BM18,BM19-BM18,0) -> 606 | BO19: 411493 | BP19: =IF(BO19>=BO18,BO19-BO18,0) -> 128 | BQ19: 515688 | BR19: =IF(BQ19>=BQ18,BQ19-BQ18,0) -> 129 | BS19: =J19+Q19+AN19+BI19 -> 21066.99 | BT19: 215 | BU19: =IF(BS19>0,BS19/BT18,0) -> 101.7729 | BW19: =IF(BS19>0,BS19/BV19,0) -> #DIV/0! | BX19: =((BS19-Q19)*$BZ$1)+(Q19*$BR$1) -> 24470.038 | BY19: =IF(BX19>0,BX19/BT18,0) -> 118.21275 | BZ19: =IF(BX19>0,BX19/BV19,0) -> #DIV/0!
A20: 15 | C20: =IF(+B20-B19>0,B20-B19,(B20-B19)>0)*800 -> 0 | E20: =IF(+D20-D19>0,D20-D19,(D20-D19)>0)*80 -> 0 | G20: =IF(+F20-F19>0,F20-F19,(F20-F19)>0)*10 -> 0 | H20: 63 | I20: 23810471 | J20: =IF(I20>=I19,I20-I19,0) -> 6511 | K20: =M20+O20 -> 4004 | L20: 631790 | M20: =IF(L20>=L19,L20-L19,0) -> 2501 | N20: 544876 | O20: =IF(N20>=N19,N20-N19,0) -> 1503 | P20: 221446 | Q20: =IF(P20>=P19,P20-P19,0)*30 -> 540 | R20: 180030 | S20: =IF(R20>=R19,R20-R19,0) -> 141 | T20: 329006 | U20: =IF(T20>=T19,T20-T19,0) -> 260 | V20: 766995 | W20: =IF(V20>=V19,V20-V19,0)*0.53 -> 1007.53 | X20: 116925 | Y20: =IF(X20>=X19,X20-X19,0)*0.53 -> 0 | Z20: 134745 | AA20: =IF(Z20>=Z19,Z20-Z19,0)*0.53 -> 0 | AB20: 488293 | AC20: =IF(AB20>=AB19,AB20-AB19,0)*0.53 -> 0 | AD20: 656575 | AE20: =IF(AD20>=AD19,AD20-AD19,0)*0.53 -> 13.78 | AF20: 835260 | AG20: =IF(AF20>=AF19,AF20-AF19,0)*0.53 -> 13.25 | AH20: 980299 | AI20: =IF(AH20>=AH19,AH20-AH19,0)*0.53 -> 439.37 | AJ20: 687573 | AK20: =IF(AJ20>=AJ19,AJ20-AJ19,0)*0.53 -> 2361.68 | AL20: 488537 | AM20: =IF(AL20>=AL19,AL20-AL19,0)*0.53 -> 162.71 | AN20: =W20+Y20+AA20+AC20+AE20+AG20+AI20+AK20+AM20 -> 3998.32 | AO20: 7650432 | AP20: =IF(AO20>=AO19,AO20-AO19,0)*0.1125 -> 4.1625 | AQ20: 672254 | AR20: =IF(AQ20>=AQ19,AQ20-AQ19,0) -> 328 | AS20: 964031 | AT20: =IF(AS20>=AS19,AS20-AS19,0) -> 136 | AU20: 809628 | AV20: =IF(AU20>=AU19,AU20-AU19,0) -> 16 | AW20: 2611646 | AX20: =IF(AW20>=AW19,AW20-AW19,0) -> 590 | AY20: 229472 | AZ20: =IF(AY20>=AY19,AY20-AY19,0) -> 0 | BA20: 19230454 | BB20: =IF(BA20>=BA19,BA20-BA19,0) -> 4591 | BC20: 563881 | BD20: =IF(BC20>=BC19,BC20-BC19,0) -> 216 | BE20: 25894 | BF20: =IF(BE20>=BE19,BE20-BE19,0) -> 55 | BG20: 24045965 | BH20: =IF(BG20>=BG19,BG20-BG19,0)-(0.45*BN20)-(0.45*BP20)-BR20 -> 4694.75 | BI20: =AP20+AR20+AT20+AV20+AX20+AZ20+BB20+BD20+BF20+BH20 -> 10630.913 | BJ20: =BI20+AN20 -> 14629.233 | BK20: 1423730 | BL20: =IF(BK20>=BK19,BK20-BK19,0) -> 256 | BM20: 3921723 | BN20: =IF(BM20>=BM19,BM20-BM19,0) -> 606 | BO20: 411632 | BP20: =IF(BO20>=BO19,BO20-BO19,0) -> 139 | BQ20: 515826 | BR20: =IF(BQ20>=BQ19,BQ20-BQ19,0) -> 138 | BS20: =J20+Q20+AN20+BI20 -> 21680.232 | BT20: 197 | BU20: =IF(BS20>0,BS20/BT20,0) -> 110.05194 | BW20: =IF(BS20>0,BS20/BV20,0) -> #DIV/0! | BX20: =((BS20-Q20)*$BZ$1)+(Q20*$BR$1) -> 25175.267 | BY20: =IF(BX20>0,BX20/BT20,0) -> 127.79324 | BZ20: =IF(BX20>0,BX20/BV20,0) -> #DIV/0!
A21: 16 | C21: =IF(+B21-B20>0,B21-B20,(B21-B20)>0)*800 -> 0 | E21: =IF(+D21-D20>0,D21-D20,(D21-D20)>0)*80 -> 0 | G21: =IF(+F21-F20>0,F21-F20,(F21-F20)>0)*10 -> 0 | I21: 23818488 | J21: =IF(I21>=I20,I21-I20,0) -> 8017 | K21: =M21+O21 -> 5075 | L21: 635323 | M21: =IF(L21>=L20,L21-L20,0) -> 3533 | N21: 546418 | O21: =IF(N21>=N20,N21-N20,0) -> 1542 | P21: 221463 | Q21: =IF(P21>=P20,P21-P20,0)*30 -> 510 | R21: 180177 | S21: =IF(R21>=R20,R21-R20,0) -> 147 | T21: 329273 | U21: =IF(T21>=T20,T21-T20,0) -> 267 | V21: 768349 | W21: =IF(V21>=V20,V21-V20,0)*0.53 -> 717.62 | X21: 118791 | Y21: =IF(X21>=X20,X21-X20,0)*0.53 -> 988.98 | Z21: 134745 | AA21: =IF(Z21>=Z20,Z21-Z20,0)*0.53 -> 0 | AB21: 488293 | AC21: =IF(AB21>=AB20,AB21-AB20,0)*0.53 -> 0 | AD21: 656608 | AE21: =IF(AD21>=AD20,AD21-AD20,0)*0.53 -> 17.49 | AF21: 835284 | AG21: =IF(AF21>=AF20,AF21-AF20,0)*0.53 -> 12.72 | AH21: 981107 | AI21: =IF(AH21>=AH20,AH21-AH20,0)*0.53 -> 428.24 | AJ21: 691599 | AK21: =IF(AJ21>=AJ20,AJ21-AJ20,0)*0.53 -> 2133.78 | AL21: 488805 | AM21: =IF(AL21>=AL20,AL21-AL20,0)*0.53 -> 142.04 | AN21: =W21+Y21+AA21+AC21+AE21+AG21+AI21+AK21+AM21 -> 4440.87 | AO21: 7650487 | AP21: =IF(AO21>=AO20,AO21-AO20,0)*0.1125 -> 6.1875 | AQ21: 672619 | AR21: =IF(AQ21>=AQ20,AQ21-AQ20,0) -> 365 | AS21: 964168 | AT21: =IF(AS21>=AS20,AS21-AS20,0) -> 137 | AU21: 809666 | AV21: =IF(AU21>=AU20,AU21-AU20,0) -> 38 | AW21: 2612641 | AX21: =IF(AW21>=AW20,AW21-AW20,0) -> 995 | AY21: 229472 | AZ21: =IF(AY21>=AY20,AY21-AY20,0) -> 0 | BA21: 19234813 | BB21: =IF(BA21>=BA20,BA21-BA20,0) -> 4359 | BC21: 564098 | BD21: =IF(BC21>=BC20,BC21-BC20,0) -> 217 | BE21: 25946 | BF21: =IF(BE21>=BE20,BE21-BE20,0) -> 52 | BG21: 24051230 | BH21: =IF(BG21>=BG20,BG21-BG20,0)-(0.45*BN21)-(0.45*BP21)-BR21 -> 4717.6 | BI21: =AP21+AR21+AT21+AV21+AX21+AZ21+BB21+BD21+BF21+BH21 -> 10886.788 | BJ21: =BI21+AN21 -> 15327.658 | BK21: 1423986 | BL21: =IF(BK21>=BK20,BK21-BK20,0) -> 256 | BM21: 3922498 | BN21: =IF(BM21>=BM20,BM21-BM20,0) -> 775 | BO21: 411769 | BP21: =IF(BO21>=BO20,BO21-BO20,0) -> 137 | BQ21: 515963 | BR21: =IF(BQ21>=BQ20,BQ21-BQ20,0) -> 137 | BS21: =J21+Q21+AN21+BI21 -> 23854.658 | BT21: 176 | BU21: =IF(BS21>0,BS21/BT21,0) -> 135.53783 | BW21: =IF(BS21>0,BS21/BV21,0) -> #DIV/0! | BX21: =((BS21-Q21)*$BZ$1)+(Q21*$BR$1) -> 27662.356 | BY21: =IF(BX21>0,BX21/BT21,0) -> 157.17248 | BZ21: =IF(BX21>0,BX21/BV21,0) -> #DIV/0!
