Workbook

Sheet Total
A1: Site Name | B1: Day | C1: Month | D1: Year | E1: Total Electricity Kwh | F1: Electricity Tariff ($/Kwh) | G1: Natual Gas (m3) | H1: Natural Gas $/m3 | I1: Water Utility Supply (m3) m3 | J1: Water Utility Supply (m3) $/m3 | K1: Room Nights
A2: Cairo at The First Residence | B2: 1 | C2: 2 | D2: 2023 | E2: =Elect!BS6 -> 22903.342 | F2: ='Utility Consnsumption'!K13/'Utility Consnsumption'!J13 -> 1.4175396 | G2: =Gas!K7 -> 1521.52 | H2: 3.8 | I2: =Water!H7 -> 209.38 | J2: 10 | K2: =Elect!BT6 -> 97
A3: Cairo at The First Residence | B3: =B2+1 -> 2 | C3: 2 | D3: 2023 | E3: =Elect!BS7 -> 24396.613 | F3: =F2 -> 1.4175396 | G3: =Gas!K8 -> 1768.92 | H3: 3.8 | I3: =Water!H8 -> 256.36 | J3: 10 | K3: =Elect!BT7 -> 128
A4: Cairo at The First Residence | B4: =B3+1 -> 3 | C4: 2 | D4: 2023 | E4: =Elect!BS8 -> 24713.8 | F4: =F3 -> 1.4175396 | G4: =Gas!K9 -> 1850.1 | H4: 3.8 | I4: =Water!H9 -> 336.98 | J4: 10 | K4: =Elect!BT8 -> 130
A5: Cairo at The First Residence | B5: =B4+1 -> 4 | C5: 2 | D5: 2023 | E5: =Elect!BS9 -> 23918.855 | F5: =F4 -> 1.4175396 | G5: =Gas!K10 -> 2263.36 | H5: 3.8 | I5: =Water!H10 -> 346.26 | J5: 10 | K5: =Elect!BT9 -> 236
A6: Cairo at The First Residence | B6: =B5+1 -> 5 | C6: 2 | D6: 2023 | E6: =Elect!BS10 -> 22880.134 | F6: =F5 -> 1.4175396 | G6: =Gas!K11 -> 1987.8533 | H6: 3.8 | I6: =Water!H11 -> 340.07333 | J6: 10 | K6: =Elect!BT10 -> 237
A7: Cairo at The First Residence | B7: =B6+1 -> 6 | C7: 2 | D7: 2023 | E7: =Elect!BS11 -> 22884.966 | F7: =F6 -> 1.4175396 | G7: =Gas!K12 -> 1699.8867 | H7: 3.8 | I7: =Water!H12 -> 283.42667 | J7: 10 | K7: =Elect!BT11 -> 196
A8: Cairo at The First Residence | B8: =B7+1 -> 7 | C8: 2 | D8: 2023 | E8: =Elect!BS12 -> 23212.385 | F8: =F7 -> 1.4175396 | G8: =Gas!K13 -> 1865.36 | H8: 3.8 | I8: =Water!H13 -> 296.96 | J8: 10 | K8: =Elect!BT12 -> 163
A9: Cairo at The First Residence | B9: =B8+1 -> 8 | C9: 2 | D9: 2023 | E9: =Elect!BS13 -> 23300.592 | F9: =F8 -> 1.4175396 | G9: =Gas!K14 -> 1971.34 | H9: 3.8 | I9: =Water!H14 -> 337.56 | J9: 10 | K9: =Elect!BT13 -> 149
A10: Cairo at The First Residence | B10: =B9+1 -> 9 | C10: 2 | D10: 2023 | E10: =Elect!BS14 -> 22906.683 | F10: =F9 -> 1.4175396 | G10: =Gas!K15 -> 1873.04 | H10: 3.8 | I10: =Water!H15 -> 294.06 | J10: 10 | K10: =Elect!BT14 -> 162
A11: Cairo at The First Residence | B11: =B10+1 -> 10 | C11: 2 | D11: 2023 | E11: =Elect!BS15 -> 22569.905 | F11: =F10 -> 1.4175396 | G11: =Gas!K16 -> 1939.46 | H11: 3.8 | I11: =Water!H16 -> 326.54 | J11: 10 | K11: =Elect!BT15 -> 176
A12: Cairo at The First Residence | B12: =B11+1 -> 11 | C12: 2 | D12: 2023 | E12: =Elect!BS16 -> 22584 | F12: =F11 -> 1.4175396 | G12: =Gas!K17 -> 2352.6 | H12: 3.8 | I12: =Water!H17 -> 345.68 | J12: 10 | K12: =Elect!BT16 -> 234
A13: Cairo at The First Residence | B13: =B12+1 -> 12 | C13: 2 | D13: 2023 | E13: =Elect!BS17 -> 25259.357 | F13: =F12 -> 1.4175396 | G13: =Gas!K18 -> 2262.58 | H13: 3.8 | I13: =Water!H18 -> 331.76 | J13: 10 | K13: =Elect!BT17 -> 240
A14: Cairo at The First Residence | B14: =B13+1 -> 13 | C14: 2 | D14: 2023 | E14: =Elect!BS18 -> 21667.537 | F14: =F13 -> 1.4175396 | G14: =Gas!K19 -> 1870.74 | H14: 3.8 | I14: =Water!H19 -> 333.5 | J14: 10 | K14: =Elect!BT18 -> 246
... A29: Cairo at The First Residence | B29: =B28+1 -> 28 | C29: 2 | D29: 2023 | E29: =Elect!BS33 -> 24134.626 | F29: =F28 -> 1.4175396 | G29: =Gas!K34 -> 2103.06 | H29: 3.8 | I29: =Water!H34 -> 335.82 | J29: 10 | K29: =Elect!BT33 -> 230.66667

Sheet Submetering
A1: Site Name | B1: Day | C1: Month | D1: Year | E1: Electricity | F1: Main Feeder -KWh | G1: T2+T8 -KWh | H1: La Gourmandize -KWh | I1: Casino 3rd floor EM -KWh | J1: Casino 3rd floor Normal -KWh | K1: Chiller 1 -KWh | L1: Chiller 2 -KWh | M1: Chiller 3 -KWh | N1: Chiller 4 -KWh | O1: Chiller 5 -KWh | P1: Chiller 6 -KWh | Q1: Cooling towers -KWh | R1: Chiller Pumps -KWh | S1: Cooling Tower Pumps -KWh | T1: Fiber Chiller -KWh | U1: Mall Ceiling light -KWh | V1: LG Bakery -KWh | W1: LG Bakery light ( Old lockers ) -KWh | X1: MCCR1 -KWh | Y1: Children Swimming Pool -KWh | Z1: DPH1 -KWh | AA1: Guest Rooms Emerg. -KWh | AB1: Hotel Hoods -KWh | AC1: Main G2 -KWh | AD1: Old Casino Emergency -KWh | AE1: L / A -KWh | AF1: L / B -KWh | AG1: L / C -KWh | AH1: Boat -KWh | AI1: Water | AJ1: Main water meter 1 -m3 | AK1: Main water meter 2 -m3 | AL1: Main water meter 3 -m3 | AM1: Boat -m3 | AN1: Gas | AO1: Main Gas Flow Meter -m3 | AP1: Laundry Gas Flow Meter -m3 | AQ1: Gourmandize Gas Flow Meter -m3 | AR1: Boat -m3 | AS1: Room Nights
A2: Cairo at The First Residence | B2: 1 | C2: 2 | D2: 2023 | F2: =Elect!J6 -> 7543.3333 | G2: =Elect!K6 -> 3061.3333 | H2: =Elect!Q6 -> 420 | I2: =Elect!S6 -> 144.66667 | J2: =Elect!U6 -> 245.33333 | K2: =Elect!W6 -> 1654.13 | L2: =Elect!Y6 -> 0 | M2: =Elect!AA6 -> 0 | N2: =Elect!AC6 -> 0 | O2: =Elect!AE6 -> 26.5 | P2: =Elect!AG6 -> 12.72 | Q2: =Elect!AI6 -> 63.776667 | R2: =Elect!AK6 -> 1898.8133 | S2: =Elect!AM6 -> 119.07333 | T2: =Elect!AP6 -> 141.8625 | U2: =Elect!AR6 -> 187.33333 | V2: =Elect!AT6 -> 138.66667 | W2: =Elect!AV6 -> 43.666667 | X2: =Elect!AX6 -> 482.33333 | Y2: =Elect!AZ6 -> 620 | Z2: =Elect!BB6 -> 4326.3333 | AA2: =Elect!BD6 -> 232 | AB2: =Elect!BF6 -> 37 | AC2: =Elect!BH6 -> 4955.8 | AD2: =Elect!BL6 -> 356.33333 | AE2: =Elect!BN6 -> 929.66667 | AF2: =Elect!BP6 -> 133 | AG2: =Elect!BR6 -> 121 | AH2: =#REF! -> #REF! | AJ2: =Water!C7 -> 58 | AK2: =Water!E7 -> 58 | AL2: =Water!G7 -> 93.38 | AM2: 0 | AO2: =Gas!C7 -> 1194.62 | AP2: =Gas!E7 -> 326.9 | AQ2: =Gas!G7 -> 90 | AR2: 0 | AS2: =Elect!BT6 -> 97
A3: Cairo at The First Residence | B3: =B2+1 -> 2 | C3: 2 | D3: 2023 | F3: =Elect!J7 -> 7209 | G3: =Elect!K7 -> 6980 | H3: =Elect!Q7 -> 420 | I3: =Elect!S7 -> 148 | J3: =Elect!U7 -> 254 | K3: =Elect!W7 -> 2147.03 | L3: =Elect!Y7 -> 0 | M3: =Elect!AA7 -> 0 | N3: =Elect!AC7 -> 0 | O3: =Elect!AE7 -> 13.78 | P3: =Elect!AG7 -> 12.72 | Q3: =Elect!AI7 -> 136.21 | R3: =Elect!AK7 -> 2065.41 | S3: =Elect!AM7 -> 124.55 | T3: =Elect!AP7 -> 148.1625 | U3: =Elect!AR7 -> 195 | V3: =Elect!AT7 -> 130 | W3: =Elect!AV7 -> 44 | X3: =Elect!AX7 -> 679 | Y3: =Elect!AZ7 -> 635 | Z3: =Elect!BB7 -> 4742 | AA3: =Elect!BD7 -> 177 | AB3: =Elect!BF7 -> 39 | AC3: =Elect!BH7 -> 5478.75 | AD3: =Elect!BL7 -> 289 | AE3: =Elect!BN7 -> 1048 | AF3: =Elect!BP7 -> 117 | AG3: =Elect!BR7 -> 128 | AH3: =#REF! -> #REF! | AJ3: =Water!C8 -> 75.4 | AK3: =Water!E8 -> 87 | AL3: =Water!G8 -> 93.96 | AM3: 0 | AO3: =Gas!C8 -> 1374.82 | AP3: =Gas!E8 -> 394.1 | AQ3: =Gas!G8 -> 107 | AR3: 0 | AS3: =Elect!BT7 -> 128
A4: Cairo at The First Residence | B4: =B3+1 -> 3 | C4: 2 | D4: 2023 | F4: =Elect!J8 -> 6942 | G4: =Elect!K8 -> 4568 | H4: =Elect!Q8 -> 420 | I4: =Elect!S8 -> 146 | J4: =Elect!U8 -> 263 | K4: =Elect!W8 -> 2217.52 | L4: =Elect!Y8 -> 0 | M4: =Elect!AA8 -> 18.02 | N4: =Elect!AC8 -> 0 | O4: =Elect!AE8 -> 12.72 | P4: =Elect!AG8 -> 12.19 | Q4: =Elect!AI8 -> 173.31 | R4: =Elect!AK8 -> 1993.33 | S4: =Elect!AM8 -> 115.01 | T4: =Elect!AP8 -> 146.7 | U4: =Elect!AR8 -> 202 | V4: =Elect!AT8 -> 113 | W4: =Elect!AV8 -> 40 | X4: =Elect!AX8 -> 643 | Y4: =Elect!AZ8 -> 1040 | Z4: =Elect!BB8 -> 4808 | AA4: =Elect!BD8 -> 199 | AB4: =Elect!BF8 -> 40 | AC4: =Elect!BH8 -> 5578 | AD4: =Elect!BL8 -> 241 | AE4: =Elect!BN8 -> 1002 | AF4: =Elect!BP8 -> 118 | AG4: =Elect!BR8 -> 154 | AH4: =#REF! -> #REF! | AJ4: =Water!C9 -> 98.6 | AK4: =Water!E9 -> 110.2 | AL4: =Water!G9 -> 128.18 | AM4: 0 | AO4: =Gas!C9 -> 1484 | AP4: =Gas!E9 -> 366.1 | AQ4: =Gas!G9 -> 108 | AR4: 0 | AS4: =Elect!BT8 -> 130
A5: Cairo at The First Residence | B5: =B4+1 -> 4 | C5: 2 | D5: 2023 | F5: =Elect!J9 -> 6919 | G5: =Elect!K9 -> 4728 | H5: =Elect!Q9 -> 360 | I5: =Elect!S9 -> 142 | J5: =Elect!U9 -> 253 | K5: =Elect!W9 -> 2164.52 | L5: =Elect!Y9 -> 0 | M5: =Elect!AA9 -> 0 | N5: =Elect!AC9 -> 0 | O5: =Elect!AE9 -> 13.25 | P5: =Elect!AG9 -> 12.72 | Q5: =Elect!AI9 -> 174.37 | R5: =Elect!AK9 -> 1990.15 | S5: =Elect!AM9 -> 113.42 | T5: =Elect!AP9 -> 155.475 | U5: =Elect!AR9 -> 202 | V5: =Elect!AT9 -> 111 | W5: =Elect!AV9 -> 40 | X5: =Elect!AX9 -> 622 | Y5: =Elect!AZ9 -> 610 | Z5: =Elect!BB9 -> 4853 | AA5: =Elect!BD9 -> 178 | AB5: =Elect!BF9 -> 40 | AC5: =Elect!BH9 -> 5359.95 | AD5: =Elect!BL9 -> 88 | AE5: =Elect!BN9 -> 1011 | AF5: =Elect!BP9 -> 118 | AG5: =Elect!BR9 -> 157 | AH5: =#REF! -> #REF! | AJ5: =Water!C10 -> 110.2 | AK5: =Water!E10 -> 110.2 | AL5: =Water!G10 -> 125.86 | AM5: 0 | AO5: =Gas!C10 -> 1734.16 | AP5: =Gas!E10 -> 529.2 | AQ5: =Gas!G10 -> 109 | AR5: 0 | AS5: =Elect!BT9 -> 236
A6: Cairo at The First Residence | B6: =B5+1 -> 5 | C6: 2 | D6: 2023 | F6: =Elect!J10 -> 6667 | G6: =Elect!K10 -> 4562.3333 | H6: =Elect!Q10 -> 390 | I6: =Elect!S10 -> 141 | J6: =Elect!U10 -> 247 | K6: =Elect!W10 -> 1929.2 | L6: =Elect!Y10 -> 0 | M6: =Elect!AA10 -> 0 | N6: =Elect!AC10 -> 0 | O6: =Elect!AE10 -> 12.19 | P6: =Elect!AG10 -> 12.366667 | Q6: =Elect!AI10 -> 155.82 | R6: =Elect!AK10 -> 1883.09 | S6: =Elect!AM10 -> 114.48 | T6: =Elect!AP10 -> 149.7375 | U6: =Elect!AR10 -> 198 | V6: =Elect!AT10 -> 121 | W6: =Elect!AV10 -> 40 | X6: =Elect!AX10 -> 655 | Y6: =Elect!AZ10 -> 599 | Z6: =Elect!BB10 -> 4606 | AA6: =Elect!BD10 -> 186 | AB6: =Elect!BF10 -> 40 | AC6: =Elect!BH10 -> 5121.25 | AD6: =Elect!BL10 -> 103 | AE6: =Elect!BN10 -> 1008 | AF6: =Elect!BP10 -> 107 | AG6: =Elect!BR10 -> 155 | AH6: =#REF! -> #REF! | AJ6: =Water!C11 -> 102.46667 | AK6: =Water!E11 -> 110.2 | AL6: =Water!G11 -> 127.40667 | AM6: 0 | AO6: =Gas!C11 -> 1567.3867 | AP6: =Gas!E11 -> 420.46667 | AQ6: =Gas!G11 -> 108.33333 | AR6: 0 | AS6: =Elect!BT10 -> 237
A7: Cairo at The First Residence | B7: =B6+1 -> 6 | C7: 2 | D7: 2023 | F7: =Elect!J11 -> 7219 | G7: =Elect!K11 -> 4924 | H7: =Elect!Q11 -> 450 | I7: =Elect!S11 -> 142 | J7: =Elect!U11 -> 248 | K7: =Elect!W11 -> 1286.84 | L7: =Elect!Y11 -> 0 | M7: =Elect!AA11 -> 22.26 | N7: =Elect!AC11 -> 0 | O7: =Elect!AE11 -> 13.78 | P7: =Elect!AG11 -> 12.543333 | Q7: =Elect!AI11 -> 157.41 | R7: =Elect!AK11 -> 1776.56 | S7: =Elect!AM11 -> 112.36 | T7: =Elect!AP11 -> 136.4625 | U7: =Elect!AR11 -> 197 | V7: =Elect!AT11 -> 113 | W7: =Elect!AV11 -> 41 | X7: =Elect!AX11 -> 719 | Y7: =Elect!AZ11 -> 946 | Z7: =Elect!BB11 -> 4370 | AA7: =Elect!BD11 -> 192 | AB7: =Elect!BF11 -> 40 | AC7: =Elect!BH11 -> 5079.75 | AD7: =Elect!BL11 -> 90 | AE7: =Elect!BN11 -> 978 | AF7: =Elect!BP11 -> 107 | AG7: =Elect!BR11 -> 156 | AH7: =#REF! -> #REF! | AJ7: =Water!C12 -> 83.133333 | AK7: =Water!E12 -> 116 | AL7: =Water!G12 -> 84.293333 | AM7: 0 | AO7: =Gas!C12 -> 1341.2533 | AP7: =Gas!E12 -> 358.63333 | AQ7: =Gas!G12 -> 58.666667 | AR7: 0 | AS7: =Elect!BT11 -> 196
A8: Cairo at The First Residence | B8: =B7+1 -> 7 | C8: 2 | D8: 2023 | F8: =Elect!J12 -> 7366 | G8: =Elect!K12 -> 5085 | H8: =Elect!Q12 -> 540 | I8: =Elect!S12 -> 146 | J8: =Elect!U12 -> 256 | K8: =Elect!W12 -> 1381.18 | L8: =Elect!Y12 -> 0 | M8: =Elect!AA12 -> 0 | N8: =Elect!AC12 -> 0 | O8: =Elect!AE12 -> 13.25 | P8: =Elect!AG12 -> 12.72 | Q8: =Elect!AI12 -> 127.2 | R8: =Elect!AK12 -> 1865.07 | S8: =Elect!AM12 -> 118.19 | T8: =Elect!AP12 -> 115.425 | U8: =Elect!AR12 -> 200 | V8: =Elect!AT12 -> 130 | W8: =Elect!AV12 -> 42 | X8: =Elect!AX12 -> 754 | Y8: =Elect!AZ12 -> 577 | Z8: =Elect!BB12 -> 4432 | AA8: =Elect!BD12 -> 226 | AB8: =Elect!BF12 -> 40 | AC8: =Elect!BH12 -> 5272.35 | AD8: =Elect!BL12 -> 85 | AE8: =Elect!BN12 -> 1043 | AF8: =Elect!BP12 -> 114 | AG8: =Elect!BR12 -> 165 | AH8: =#REF! -> #REF! | AJ8: =Water!C13 -> 87 | AK8: =Water!E13 -> 98.6 | AL8: =Water!G13 -> 111.36 | AM8: 0 | AO8: =Gas!C13 -> 1469.16 | AP8: =Gas!E13 -> 396.2 | AQ8: =Gas!G13 -> 82 | AR8: 0 | AS8: =Elect!BT12 -> 163
A9: Cairo at The First Residence | B9: =B8+1 -> 8 | C9: 2 | D9: 2023 | F9: =Elect!J13 -> 7366 | G9: =Elect!K13 -> 5113 | H9: =Elect!Q13 -> 450 | I9: =Elect!S13 -> 146 | J9: =Elect!U13 -> 252 | K9: =Elect!W13 -> 1281.01 | L9: =Elect!Y13 -> 0 | M9: =Elect!AA13 -> 0 | N9: =Elect!AC13 -> 0 | O9: =Elect!AE13 -> 13.78 | P9: =Elect!AG13 -> 13.25 | Q9: =Elect!AI13 -> 118.19 | R9: =Elect!AK13 -> 1768.61 | S9: =Elect!AM13 -> 118.19 | T9: =Elect!AP13 -> 59.0625 | U9: =Elect!AR13 -> 207 | V9: =Elect!AT13 -> 99 | W9: =Elect!AV13 -> 41 | X9: =Elect!AX13 -> 735 | Y9: =Elect!AZ13 -> 625 | Z9: =Elect!BB13 -> 4740 | AA9: =Elect!BD13 -> 187 | AB9: =Elect!BF13 -> 40 | AC9: =Elect!BH13 -> 5438.5 | AD9: =Elect!BL13 -> 297 | AE9: =Elect!BN13 -> 1018 | AF9: =Elect!BP13 -> 112 | AG9: =Elect!BR13 -> 164 | AH9: =#REF! -> #REF! | AJ9: =Water!C14 -> 104.4 | AK9: =Water!E14 -> 121.8 | AL9: =Water!G14 -> 111.36 | AM9: 0 | AO9: =Gas!C14 -> 1573.04 | AP9: =Gas!E14 -> 398.3 | AQ9: =Gas!G14 -> 94 | AR9: 0 | AS9: =Elect!BT13 -> 149
A10: Cairo at The First Residence | B10: =B9+1 -> 9 | C10: 2 | D10: 2023 | F10: =Elect!J14 -> 7319 | G10: =Elect!K14 -> 5084 | H10: =Elect!Q14 -> 420 | I10: =Elect!S14 -> 141 | J10: =Elect!U14 -> 252 | K10: =Elect!W14 -> 1346.73 | L10: =Elect!Y14 -> 0 | M10: =Elect!AA14 -> 0 | N10: =Elect!AC14 -> 0 | O10: =Elect!AE14 -> 13.25 | P10: =Elect!AG14 -> 12.72 | Q10: =Elect!AI14 -> 120.31 | R10: =Elect!AK14 -> 1760.66 | S10: =Elect!AM14 -> 111.3 | T10: =Elect!AP14 -> 120.7125 | U10: =Elect!AR14 -> 203 | V10: =Elect!AT14 -> 108 | W10: =Elect!AV14 -> 40 | X10: =Elect!AX14 -> 740 | Y10: =Elect!AZ14 -> 582 | Z10: =Elect!BB14 -> 4546 | AA10: =Elect!BD14 -> 168 | AB10: =Elect!BF14 -> 35 | AC10: =Elect!BH14 -> 5260 | AD10: =Elect!BL14 -> 267 | AE10: =Elect!BN14 -> 972 | AF10: =Elect!BP14 -> 108 | AG10: =Elect!BR14 -> 120 | AH10: =#REF! -> #REF! | AJ10: =Water!C15 -> 87 | AK10: =Water!E15 -> 98.6 | AL10: =Water!G15 -> 108.46 | AM10: 0 | AO10: =Gas!C15 -> 1467.04 | AP10: =Gas!E15 -> 406 | AQ10: =Gas!G15 -> 82 | AR10: 0 | AS10: =Elect!BT14 -> 162
A11: Cairo at The First Residence | B11: =B10+1 -> 10 | C11: 2 | D11: 2023 | F11: =Elect!J15 -> 7532 | G11: =Elect!K15 -> 4924 | H11: =Elect!Q15 -> 480 | I11: =Elect!S15 -> 145 | J11: =Elect!U15 -> 262 | K11: =Elect!W15 -> 1330.83 | L11: =Elect!Y15 -> 0 | M11: =Elect!AA15 -> 0 | N11: =Elect!AC15 -> 0 | O11: =Elect!AE15 -> 15.9 | P11: =Elect!AG15 -> 12.19 | Q11: =Elect!AI15 -> 125.61 | R11: =Elect!AK15 -> 1485.06 | S11: =Elect!AM15 -> 110.24 | T11: =Elect!AP15 -> 101.025 | U11: =Elect!AR15 -> 174 | V11: =Elect!AT15 -> 140 | W11: =Elect!AV15 -> 40 | X11: =Elect!AX15 -> 740 | Y11: =Elect!AZ15 -> 10 | Z11: =Elect!BB15 -> 4704 | AA11: =Elect!BD15 -> 176 | AB11: =Elect!BF15 -> 35 | AC11: =Elect!BH15 -> 5358.05 | AD11: =Elect!BL15 -> 277 | AE11: =Elect!BN15 -> 978 | AF11: =Elect!BP15 -> 113 | AG11: =Elect!BR15 -> 157 | AH11: =#REF! -> #REF! | AJ11: =Water!C16 -> 98.6 | AK11: =Water!E16 -> 116 | AL11: =Water!G16 -> 111.94 | AM11: 0 | AO11: =Gas!C16 -> 1495.66 | AP11: =Gas!E16 -> 443.8 | AQ11: =Gas!G16 -> 86 | AR11: 0 | AS11: =Elect!BT15 -> 176
A12: Cairo at The First Residence | B12: =B11+1 -> 11 | C12: 2 | D12: 2023 | F12: =Elect!J16 -> 7099 | G12: =Elect!K16 -> 4845 | H12: =Elect!Q16 -> 420 | I12: =Elect!S16 -> 137 | J12: =Elect!U16 -> 248 | K12: =Elect!W16 -> 1598.48 | L12: =Elect!Y16 -> 0 | M12: =Elect!AA16 -> 0 | N12: =Elect!AC16 -> 0 | O12: =Elect!AE16 -> 10.07 | P12: =Elect!AG16 -> 12.72 | Q12: =Elect!AI16 -> 152.11 | R12: =Elect!AK16 -> 1787.69 | S12: =Elect!AM16 -> 111.83 | T12: =Elect!AP16 -> 114.3 | U12: =Elect!AR16 -> 187 | V12: =Elect!AT16 -> 132 | W12: =Elect!AV16 -> 41 | X12: =Elect!AX16 -> 744 | Y12: =Elect!AZ16 -> 10 | Z12: =Elect!BB16 -> 4594 | AA12: =Elect!BD16 -> 193 | AB12: =Elect!BF16 -> 40 | AC12: =Elect!BH16 -> 5336.8 | AD12: =Elect!BL16 -> 269 | AE12: =Elect!BN16 -> 947 | AF12: =Elect!BP16 -> 109 | AG12: =Elect!BR16 -> 152 | AH12: =#REF! -> #REF! | AJ12: =Water!C17 -> 110.2 | AK12: =Water!E17 -> 121.8 | AL12: =Water!G17 -> 113.68 | AM12: 0 | AO12: =Gas!C17 -> 1844.4 | AP12: =Gas!E17 -> 508.2 | AQ12: =Gas!G17 -> 110 | AR12: 0 | AS12: =Elect!BT16 -> 234
A13: Cairo at The First Residence | B13: =B12+1 -> 12 | C13: 2 | D13: 2023 | F13: =Elect!J17 -> 9020 | G13: =Elect!K17 -> 4796 | H13: =Elect!Q17 -> 450 | I13: =Elect!S17 -> 155 | J13: =Elect!U17 -> 268 | K13: =Elect!W17 -> 1541.24 | L13: =Elect!Y17 -> 0 | M13: =Elect!AA17 -> 0 | N13: =Elect!AC17 -> 0 | O13: =Elect!AE17 -> 13.78 | P13: =Elect!AG17 -> 12.72 | Q13: =Elect!AI17 -> 156.88 | R13: =Elect!AK17 -> 1866.13 | S13: =Elect!AM17 -> 116.07 | T13: =Elect!AP17 -> 58.3875 | U13: =Elect!AR17 -> 207 | V13: =Elect!AT17 -> 131 | W13: =Elect!AV17 -> 42 | X13: =Elect!AX17 -> 754 | Y13: =Elect!AZ17 -> 11 | Z13: =Elect!BB17 -> 4847 | AA13: =Elect!BD17 -> 252 | AB13: =Elect!BF17 -> 40 | AC13: =Elect!BH17 -> 5740.15 | AD13: =Elect!BL17 -> 209 | AE13: =Elect!BN17 -> 996 | AF13: =Elect!BP17 -> 117 | AG13: =Elect!BR17 -> 168 | AH13: =#REF! -> #REF! | AJ13: =Water!C18 -> 104.4 | AK13: =Water!E18 -> 121.8 | AL13: =Water!G18 -> 105.56 | AM13: 0 | AO13: =Gas!C18 -> 1836.98 | AP13: =Gas!E18 -> 425.6 | AQ13: =Gas!G18 -> 108 | AR13: 0 | AS13: =Elect!BT17 -> 240
A14: Cairo at The First Residence | B14: =B13+1 -> 13 | C14: 2 | D14: 2023 | F14: =Elect!J18 -> 5557 | G14: =Elect!K18 -> 2502 | H14: =Elect!Q18 -> 570 | I14: =Elect!S18 -> 138 | J14: =Elect!U18 -> 237 | K14: =Elect!W18 -> 1515.27 | L14: =Elect!Y18 -> 0 | M14: =Elect!AA18 -> 0 | N14: =Elect!AC18 -> 0 | O14: =Elect!AE18 -> 13.78 | P14: =Elect!AG18 -> 12.72 | Q14: =Elect!AI18 -> 155.82 | R14: =Elect!AK18 -> 1989.62 | S14: =Elect!AM18 -> 110.24 | T14: =Elect!AP18 -> 95.7375 | U14: =Elect!AR18 -> 186 | V14: =Elect!AT18 -> 143 | W14: =Elect!AV18 -> 40 | X14: =Elect!AX18 -> 685 | Y14: =Elect!AZ18 -> 10 | Z14: =Elect!BB18 -> 4864 | AA14: =Elect!BD18 -> 268 | AB14: =Elect!BF18 -> 74 | AC14: =Elect!BH18 -> 5377.35 | AD14: =Elect!BL18 -> 197 | AE14: =Elect!BN18 -> 969 | AF14: =Elect!BP18 -> 108 | AG14: =Elect!BR18 -> 161 | AH14: =#REF! -> #REF! | AJ14: =Water!C19 -> 104.4 | AK14: =Water!E19 -> 121.8 | AL14: =Water!G19 -> 107.3 | AM14: 0 | AO14: =Gas!C19 -> 1408.74 | AP14: =Gas!E19 -> 462 | AQ14: =Gas!G19 -> 83 | AR14: 0 | AS14: =Elect!BT18 -> 246
... A29: Cairo at The First Residence | B29: =B28+1 -> 28 | C29: 2 | D29: 2023 | F29: =Elect!J33 -> 7444.3333 | G29: =Elect!K33 -> 3800.3333 | H29: =Elect!Q33 -> 560 | I29: =Elect!S33 -> 141.33333 | J29: =Elect!U33 -> 264.33333 | K29: =Elect!W33 -> 2196.85 | L29: =Elect!Y33 -> 0 | M29: =Elect!AA33 -> 0 | N29: =Elect!AC33 -> 0 | O29: =Elect!AE33 -> 0 | P29: =Elect!AG33 -> 12.013333 | Q29: =Elect!AI33 -> 228.60667 | R29: =Elect!AK33 -> 2056.0467 | S29: =Elect!AM33 -> 115.36333 | T29: =Elect!AP33 -> 90.5625 | U29: =Elect!AR33 -> 190.66667 | V29: =Elect!AT33 -> 116 | W29: =Elect!AV33 -> 40.333333 | X29: =Elect!AX33 -> 968.66667 | Y29: =Elect!AZ33 -> 0 | Z29: =Elect!BB33 -> 4383.6667 | AA29: =Elect!BD33 -> 275.33333 | AB29: =Elect!BF33 -> 48.5 | AC29: =Elect!BH33 -> 5407.6833 | AD29: =Elect!BL33 -> 269.33333 | AE29: =Elect!BN33 -> 948 | AF29: =Elect!BP33 -> 109 | AG29: =Elect!BR33 -> 36.666667 | AH29: =#REF! -> #REF! | AJ29: =Water!C34 -> 104.4 | AK29: =Water!E34 -> 121.8 | AL29: =Water!G34 -> 109.62 | AM29: 0 | AO29: =Gas!C34 -> 1622.86 | AP29: =Gas!E34 -> 480.2 | AQ29: =Gas!G34 -> 89 | AR29: 0 | AS29: =Elect!BT33 -> 230.66667
W30: =Elect!AV34 -> 0 | X30: =Elect!AX34 -> 0 | Y30: =Elect!AZ34 -> 0 | Z30: =Elect!BB34 -> 0 | AA30: =Elect!BD34 -> 0 | AB30: =Elect!BF34 -> 0 | AC30: =Elect!BH34 -> 0 | AD30: =Elect!BL34 -> 0 | AE30: =Elect!BN34 -> 0 | AF30: =Elect!BP34 -> 0 | AG30: =Elect!BR34 -> 0 | AH30: =#REF! -> #REF! | AJ30: =Water!C35 -> 0 | AK30: =Water!E35 -> 0 | AL30: =Water!G35 -> 0 | AM30: 0 | AO30: =Gas!C35 -> 0 | AP30: =Gas!E35 -> 0 | AQ30: =Gas!G35 -> 0 | AR30: 0 | AS30: =Elect!BT34 -> 0
W31: =Elect!AV35 -> 0 | X31: =Elect!AX35 -> 0 | Y31: =Elect!AZ35 -> 0 | Z31: =Elect!BB35 -> 0 | AA31: =Elect!BD35 -> 0 | AB31: =Elect!BF35 -> 0 | AC31: =Elect!BH35 -> 0 | AD31: =Elect!BL35 -> 0 | AE31: =Elect!BN35 -> 0 | AF31: =Elect!BP35 -> 0 | AG31: =Elect!BR35 -> 0 | AH31: =#REF! -> #REF! | AJ31: =Water!C36 -> 0 | AK31: =Water!E36 -> 0 | AL31: =Water!G36 -> 0 | AM31: 0 | AO31: =Gas!C36 -> 0 | AP31: =Gas!E36 -> 0 | AQ31: =Gas!G36 -> 0 | AR31: 0 | AS31: =Elect!BT35 -> 0
W32: =Elect!AV36 -> 0 | X32: =Elect!AX36 -> 0 | Y32: =Elect!AZ36 -> 0 | Z32: =Elect!BB36 -> 0 | AA32: =Elect!BD36 -> 0 | AB32: =Elect!BF36 -> 0 | AC32: =Elect!BH36 -> 0 | AD32: =Elect!BL36 -> 0 | AE32: =Elect!BN36 -> 0 | AF32: =Elect!BP36 -> 0 | AG32: =Elect!BR36 -> 0 | AH32: =#REF! -> #REF! | AJ32: =Water!C37 -> 0 | AK32: =Water!E37 -> 0 | AL32: =Water!G37 -> 0 | AM32: 0 | AO32: =Gas!C37 -> 0 | AP32: =Gas!E37 -> 0 | AQ32: =Gas!G37 -> 0 | AR32: 0 | AS32: =Elect!BT36 -> 0

Sheet Elect
A1: 44958 | M1: Electricity | BP1: Gourmandise UP | BR1: 1.6 | BS1: Power Taxes | BU1: Max Demand | BW1: 500 | BX1: Electricity UP | BZ1: 1.15
BS2: Light Taxes | BU2: PF Penalty | BX2: Max. Demand UP | BZ2: 30
A3: Date | B3: COUNTER (1) | D3: MD | F3: KVAR | H3: n | I3: Guest Rooms Consumption | R3: Casino Consumption | V3: Plant Room Shared Loads | AO3: To Be Charged By First Arabian | BK3: From Main Panel G2 | BS3: Total Consumption. | BT3: No. Of | BU3: KWH/ | BV3: No. Of | BW3: KWH/ | BX3: Total Cost | BY3: L.E\ | BZ3: L.E\
B4: Reading | C4: Consp. F: *800 | D4: Reading | E4: Consp F: 80 | F4: Reading | G4: Consp. F:*10 | I4: Main Feeder | J4: Consp | K4: T2+T8 | L4: Trans T2 | M4: Consp | N4: Trans T8 | O4: Consp | P4: La Gourmandize | Q4: Consp *30 | R4: Casino 3rd floor EM | S4: Consp | T4: Casino 3rd floor Normal | U4: Consp | V4: Chiller 1 | W4: Consp 53% | X4: Chiller 2 | Y4: Consp 53% | Z4: Chiller 3 | AA4: Consp 53% | AB4: Chiller 4 | AC4: Consp 53% | AD4: Chiller 5 | AE4: Consp 53% | AF4: Chiller 6 | AG4: Consp 53% | AH4: Cooling Towers | AI4: Consp 53% | AJ4: Chiller Pumps | AK4: Consp 53% | AL4: Cooling Tower Pumps | AM4: Consp 53% | AN4: Total Plant Room Consp | AO4: Fiber Chiller (N24) | AP4: Consp | AQ4: Mall Ceiling light (N4) | AR4: Consp | AS4: LG Bakery (N2) | AT4: Consp | AU4: LG Bakery light ( Old lockers ) | AV4: Consp | AW4: MCCR1 | AX4: Consp | AY4: Children Swimming pool | AZ4: Consp | BA4: DPH1 | BB4: Consp | BC4: Guest Rooms Emergency | BD4: Consp | BE4: Hotel Hoods | BF4: Consp | BG4: Main G2 | BH4: Consp | BI4: Total Consp From First Arabian | BJ4: First Arabian Charge Back | BK4: Old Casino Emergency | BL4: Consp | BM4: L / A | BN4: Consp | BO4: L / B | BP4: Consp | BQ4: L / C | BR4: Consp | BT4: Rooms | BU4: room | BV4: guest | BW4: guest | BY4: Room | BZ4: Guest
A5: Last Month Reading | I5: 25991238 | J5: =IF(I5>=I4,I5-I4,0) -> 0 | K5: =M5+O5 -> 0 | L5: 404725.67 | M5: =IF(L5>=L4,L5-L4,0) -> 0 | N5: 426081 | O5: =IF(N5>=N4,N5-N4,0) -> 0 | P5: 228195 | Q5: =IF(P5>=P4,P5-P4,0)*30 -> 0 | R5: 234971.33 | S5: =IF(R5>=R4,R5-R4,0) -> 0 | T5: 428547.67 | U5: =IF(T5>=T4,T5-T4,0) -> 0 | V5: 895229 | W5: =IF(V5>=V4,V5-V4,0)*0.53 -> 0 | X5: 839916 | Y5: =IF(X5>=X4,X5-X4,0)*0.53 -> 0 | Z5: 871759 | AA5: =IF(Z5>=Z4,Z5-Z4,0)*0.53 -> 0 | AB5: 184962 | AC5: =IF(AB5>=AB4,AB5-AB4,0)*0.53 -> 0 | AD5: 863299 | AE5: =IF(AD5>=AD4,AD5-AD4,0)*0.53 -> 0 | AF5: 1010940 | AG5: =IF(AF5>=AF4,AF5-AF4,0)*0.53 -> 0 | AH5: 445421.67 | AI5: =IF(AH5>=AH4,AH5-AH4,0)*0.53 -> 0 | AJ5: 774987.33 | AK5: =IF(AJ5>=AJ4,AJ5-AJ4,0)*0.53 -> 0 | AL5: 580792.33 | AM5: =IF(AL5>=AL4,AL5-AL4,0)*0.53 -> 0 | AN5: =W5+Y5+AA5+AC5+AE5+AG5+AI5+AK5+AM5 -> 0 | AO5: 8236771 | AP5: =IF(AO5>=AO4,AO5-AO4,0)*0.1125 -> 0 | AQ5: 762289.67 | AR5: =IF(AQ5>=AQ4,AQ5-AQ4,0) -> 0 | AS5: 23114.333 | AT5: =IF(AS5>=AS4,AS5-AS4,0) -> 0 | AU5: 828493.33 | AV5: =IF(AU5>=AU4,AU5-AU4,0) -> 0 | AW5: 2932469.7 | AX5: =IF(AW5>=AW4,AW5-AW4,0) -> 0 | AY5: 234748 | AZ5: =IF(AY5>=AY4,AY5-AY4,0) -> 0 | BA5: 21094072 | BB5: =IF(BA5>=BA4,BA5-BA4,0) -> 0 | BC5: 653479 | BD5: =IF(BC5>=BC4,BC5-BC4,0) -> 0 | BE5: 47700 | BF5: =IF(BE5>=BE4,BE5-BE4,0) -> 0 | BG5: 26512695 | BH5: =IF(BG5>=BG4,BG5-BG4,0)-(0.45*BN5)-(0.45*BP5)-BR5 -> 0 | BI5: =AP5+AR5+AT5+AV5+AX5+AZ5+BB5+BD5+BF5+BH5 -> 0 | BJ5: =BI5+AN5 -> 0 | BK5: 1508370.7 | BL5: =IF(BK5>=BK4,BK5-BK4,0) -> 0 | BM5: 4369853.3 | BN5: =IF(BM5>=BM4,BM5-BM4,0) -> 0 | BO5: 457697 | BP5: =IF(BO5>=BO4,BO5-BO4,0) -> 0 | BQ5: 570578 | BR5: =IF(BQ5>=BQ4,BQ5-BQ4,0) -> 0
A6: 1 | C6: =IF(+B6-B5>0,B6-B5,(B6-B5)>0)*800 -> 0 | E6: =IF(+D6-D5>0,D6-D5,(D6-D5)>0)*80 -> 0 | G6: =IF(+F6-F5>0,F6-F5,(F6-F5)>0)*10 -> 0 | H6: 56 | I6: 25998781 | J6: =IF(I6>=I5,I6-I5,0) -> 7543.3333 | K6: =M6+O6 -> 3061.3333 | L6: 407674 | M6: =IF(L6>=L5,L6-L5,0) -> 2948.3333 | N6: 426194 | O6: =IF(N6>=N5,N6-N5,0) -> 113 | P6: 228209 | Q6: =IF(P6>=P5,P6-P5,0)*30 -> 420 | R6: 235116 | S6: =IF(R6>=R5,R6-R5,0) -> 144.66667 | T6: 428793 | U6: =IF(T6>=T5,T6-T5,0) -> 245.33333 | V6: 898350 | W6: =IF(V6>=V5,V6-V5,0)*0.53 -> 1654.13 | X6: 839916 | Y6: =IF(X6>=X5,X6-X5,0)*0.53 -> 0 | Z6: 871759 | AA6: =IF(Z6>=Z5,Z6-Z5,0)*0.53 -> 0 | AB6: 184962 | AC6: =IF(AB6>=AB5,AB6-AB5,0)*0.53 -> 0 | AD6: 863349 | AE6: =IF(AD6>=AD5,AD6-AD5,0)*0.53 -> 26.5 | AF6: 1010964 | AG6: =IF(AF6>=AF5,AF6-AF5,0)*0.53 -> 12.72 | AH6: 445542 | AI6: =IF(AH6>=AH5,AH6-AH5,0)*0.53 -> 63.776667 | AJ6: 778570 | AK6: =IF(AJ6>=AJ5,AJ6-AJ5,0)*0.53 -> 1898.8133 | AL6: 581017 | AM6: =IF(AL6>=AL5,AL6-AL5,0)*0.53 -> 119.07333 | AN6: =W6+Y6+AA6+AC6+AE6+AG6+AI6+AK6+AM6 -> 3775.0133 | AO6: 8238032 | AP6: =IF(AO6>=AO5,AO6-AO5,0)*0.1125 -> 141.8625 | AQ6: 762477 | AR6: =IF(AQ6>=AQ5,AQ6-AQ5,0) -> 187.33333 | AS6: 23253 | AT6: =IF(AS6>=AS5,AS6-AS5,0) -> 138.66667 | AU6: 828537 | AV6: =IF(AU6>=AU5,AU6-AU5,0) -> 43.666667 | AW6: 2932952 | AX6: =IF(AW6>=AW5,AW6-AW5,0) -> 482.33333 | AY6: 235368 | AZ6: =IF(AY6>=AY5,AY6-AY5,0) -> 620 | BA6: 21098398 | BB6: =IF(BA6>=BA5,BA6-BA5,0) -> 4326.3333 | BC6: 653711 | BD6: =IF(BC6>=BC5,BC6-BC5,0) -> 232 | BE6: 47737 | BF6: =IF(BE6>=BE5,BE6-BE5,0) -> 37 | BG6: 26518250 | BH6: =IF(BG6>=BG5,BG6-BG5,0)-(0.45*BN6)-(0.45*BP6)-BR6 -> 4955.8 | BI6: =AP6+AR6+AT6+AV6+AX6+AZ6+BB6+BD6+BF6+BH6 -> 11164.996 | BJ6: =BI6+AN6 -> 14940.009 | BK6: 1508727 | BL6: =IF(BK6>=BK5,BK6-BK5,0) -> 356.33333 | BM6: 4370783 | BN6: =IF(BM6>=BM5,BM6-BM5,0) -> 929.66667 | BO6: 457830 | BP6: =IF(BO6>=BO5,BO6-BO5,0) -> 133 | BQ6: 570699 | BR6: =IF(BQ6>=BQ5,BQ6-BQ5,0) -> 121 | BS6: =J6+Q6+AN6+BI6 -> 22903.342 | BT6: 97 | BU6: =IF(BS6>0,BS6/BT5,0) -> #DIV/0! | BW6: =IF(BS6>0,BS6/BV6,0) -> #DIV/0! | BX6: =((BS6-Q6)*$BZ$1)+(Q6*$BR$1) -> 26527.844 | BY6: =IF(BX6>0,BX6/BT5,0) -> #DIV/0! | BZ6: =IF(BX6>0,BX6/BV6,0) -> #DIV/0!
A7: 2 | I7: 26005990 | J7: =IF(I7>=I6,I7-I6,0) -> 7209 | K7: =M7+O7 -> 6980 | L7: 410354 | M7: =IF(L7>=L6,L7-L6,0) -> 2680 | N7: 430494 | O7: =IF(N7>=N6,N7-N6,0) -> 4300 | P7: 228223 | Q7: =IF(P7>=P6,P7-P6,0)*30 -> 420 | R7: 235264 | S7: =IF(R7>=R6,R7-R6,0) -> 148 | T7: 429047 | U7: =IF(T7>=T6,T7-T6,0) -> 254 | V7: 902401 | W7: =IF(V7>=V6,V7-V6,0)*0.53 -> 2147.03 | X7: 839916 | Y7: =IF(X7>=X6,X7-X6,0)*0.53 -> 0 | Z7: 871759 | AA7: =IF(Z7>=Z6,Z7-Z6,0)*0.53 -> 0 | AB7: 184962 | AC7: =IF(AB7>=AB6,AB7-AB6,0)*0.53 -> 0 | AD7: 863375 | AE7: =IF(AD7>=AD6,AD7-AD6,0)*0.53 -> 13.78 | AF7: 1010988 | AG7: =IF(AF7>=AF6,AF7-AF6,0)*0.53 -> 12.72 | AH7: 445799 | AI7: =IF(AH7>=AH6,AH7-AH6,0)*0.53 -> 136.21 | AJ7: 782467 | AK7: =IF(AJ7>=AJ6,AJ7-AJ6,0)*0.53 -> 2065.41 | AL7: 581252 | AM7: =IF(AL7>=AL6,AL7-AL6,0)*0.53 -> 124.55 | AN7: =W7+Y7+AA7+AC7+AE7+AG7+AI7+AK7+AM7 -> 4499.7 | AO7: 8239349 | AP7: =IF(AO7>=AO6,AO7-AO6,0)*0.1125 -> 148.1625 | AQ7: 762672 | AR7: =IF(AQ7>=AQ6,AQ7-AQ6,0) -> 195 | AS7: 23383 | AT7: =IF(AS7>=AS6,AS7-AS6,0) -> 130 | AU7: 828581 | AV7: =IF(AU7>=AU6,AU7-AU6,0) -> 44 | AW7: 2933631 | AX7: =IF(AW7>=AW6,AW7-AW6,0) -> 679 | AY7: 236003 | AZ7: =IF(AY7>=AY6,AY7-AY6,0) -> 635 | BA7: 21103140 | BB7: =IF(BA7>=BA6,BA7-BA6,0) -> 4742 | BC7: 653888 | BD7: =IF(BC7>=BC6,BC7-BC6,0) -> 177 | BE7: 47776 | BF7: =IF(BE7>=BE6,BE7-BE6,0) -> 39 | BG7: 26524381 | BH7: =IF(BG7>=BG6,BG7-BG6,0)-(0.45*BN7)-(0.45*BP7)-BR7 -> 5478.75 | BI7: =AP7+AR7+AT7+AV7+AX7+AZ7+BB7+BD7+BF7+BH7 -> 12267.913 | BJ7: =BI7+AN7 -> 16767.613 | BK7: 1509016 | BL7: =IF(BK7>=BK6,BK7-BK6,0) -> 289 | BM7: 4371831 | BN7: =IF(BM7>=BM6,BM7-BM6,0) -> 1048 | BO7: 457947 | BP7: =IF(BO7>=BO6,BO7-BO6,0) -> 117 | BQ7: 570827 | BR7: =IF(BQ7>=BQ6,BQ7-BQ6,0) -> 128 | BS7: =J7+Q7+AN7+BI7 -> 24396.613 | BT7: 128 | BU7: =IF(BS7>0,BS7/BT6,0) -> 251.51147 | BW7: =IF(BS7>0,BS7/BV7,0) -> #DIV/0! | BX7: =((BS7-Q7)*$BZ$1)+(Q7*$BR$1) -> 28245.104 | BY7: =IF(BX7>0,BX7/BT6,0) -> 291.18664 | BZ7: =IF(BX7>0,BX7/BV7,0) -> #DIV/0!
A8: 3 | C8: =IF(+B8-B7>0,B8-B7,(B8-B7)>0)*800 -> 0 | E8: =IF(+D8-D7>0,D8-D7,(D8-D7)>0)*80 -> 0 | G8: =IF(+F8-F7>0,F8-F7,(F8-F7)>0)*10 -> 0 | H8: 57 | I8: 26012932 | J8: =IF(I8>=I7,I8-I7,0) -> 6942 | K8: =M8+O8 -> 4568 | L8: 412720 | M8: =IF(L8>=L7,L8-L7,0) -> 2366 | N8: 432696 | O8: =IF(N8>=N7,N8-N7,0) -> 2202 | P8: 228237 | Q8: =IF(P8>=P7,P8-P7,0)*30 -> 420 | R8: 235410 | S8: =IF(R8>=R7,R8-R7,0) -> 146 | T8: 429310 | U8: =IF(T8>=T7,T8-T7,0) -> 263 | V8: 906585 | W8: =IF(V8>=V7,V8-V7,0)*0.53 -> 2217.52 | X8: 839916 | Y8: =IF(X8>=X7,X8-X7,0)*0.53 -> 0 | Z8: 871793 | AA8: =IF(Z8>=Z7,Z8-Z7,0)*0.53 -> 18.02 | AB8: 184962 | AC8: =IF(AB8>=AB7,AB8-AB7,0)*0.53 -> 0 | AD8: 863399 | AE8: =IF(AD8>=AD7,AD8-AD7,0)*0.53 -> 12.72 | AF8: 1011011 | AG8: =IF(AF8>=AF7,AF8-AF7,0)*0.53 -> 12.19 | AH8: 446126 | AI8: =IF(AH8>=AH7,AH8-AH7,0)*0.53 -> 173.31 | AJ8: 786228 | AK8: =IF(AJ8>=AJ7,AJ8-AJ7,0)*0.53 -> 1993.33 | AL8: 581469 | AM8: =IF(AL8>=AL7,AL8-AL7,0)*0.53 -> 115.01 | AN8: =W8+Y8+AA8+AC8+AE8+AG8+AI8+AK8+AM8 -> 4542.1 | AO8: 8240653 | AP8: =IF(AO8>=AO7,AO8-AO7,0)*0.1125 -> 146.7 | AQ8: 762874 | AR8: =IF(AQ8>=AQ7,AQ8-AQ7,0) -> 202 | AS8: 23496 | AT8: =IF(AS8>=AS7,AS8-AS7,0) -> 113 | AU8: 828621 | AV8: =IF(AU8>=AU7,AU8-AU7,0) -> 40 | AW8: 2934274 | AX8: =IF(AW8>=AW7,AW8-AW7,0) -> 643 | AY8: 237043 | AZ8: =IF(AY8>=AY7,AY8-AY7,0) -> 1040 | BA8: 21107948 | BB8: =IF(BA8>=BA7,BA8-BA7,0) -> 4808 | BC8: 654087 | BD8: =IF(BC8>=BC7,BC8-BC7,0) -> 199 | BE8: 47816 | BF8: =IF(BE8>=BE7,BE8-BE7,0) -> 40 | BG8: 26530617 | BH8: =IF(BG8>=BG7,BG8-BG7,0)-(0.45*BN8)-(0.45*BP8)-BR8 -> 5578 | BI8: =AP8+AR8+AT8+AV8+AX8+AZ8+BB8+BD8+BF8+BH8 -> 12809.7 | BJ8: =BI8+AN8 -> 17351.8 | BK8: 1509257 | BL8: =IF(BK8>=BK7,BK8-BK7,0) -> 241 | BM8: 4372833 | BN8: =IF(BM8>=BM7,BM8-BM7,0) -> 1002 | BO8: 458065 | BP8: =IF(BO8>=BO7,BO8-BO7,0) -> 118 | BQ8: 570981 | BR8: =IF(BQ8>=BQ7,BQ8-BQ7,0) -> 154 | BS8: =J8+Q8+AN8+BI8 -> 24713.8 | BT8: 130 | BU8: =IF(BS8>0,BS8/BT7,0) -> 193.07656 | BW8: =IF(BS8>0,BS8/BV8,0) -> #DIV/0! | BX8: =((BS8-Q8)*$BZ$1)+(Q8*$BR$1) -> 28609.87 | BY8: =IF(BX8>0,BX8/BT7,0) -> 223.51461 | BZ8: =IF(BX8>0,BX8/BV8,0) -> #DIV/0!
A9: 4 | C9: =IF(+B9-B8>0,B9-B8,(B9-B8)>0)*800 -> 0 | E9: =IF(+D9-D8>0,D9-D8,(D9-D8)>0)*80 -> 0 | G9: =IF(+F9-F8>0,F9-F8,(F9-F8)>0)*10 -> 0 | I9: 26019851 | J9: =IF(I9>=I8,I9-I8,0) -> 6919 | K9: =M9+O9 -> 4728 | L9: 415074 | M9: =IF(L9>=L8,L9-L8,0) -> 2354 | N9: 435070 | O9: =IF(N9>=N8,N9-N8,0) -> 2374 | P9: 228249 | Q9: =IF(P9>=P8,P9-P8,0)*30 -> 360 | R9: 235552 | S9: =IF(R9>=R8,R9-R8,0) -> 142 | T9: 429563 | U9: =IF(T9>=T8,T9-T8,0) -> 253 | V9: 910669 | W9: =IF(V9>=V8,V9-V8,0)*0.53 -> 2164.52 | X9: 839916 | Y9: =IF(X9>=X8,X9-X8,0)*0.53 -> 0 | Z9: 871793 | AA9: =IF(Z9>=Z8,Z9-Z8,0)*0.53 -> 0 | AB9: 184962 | AC9: =IF(AB9>=AB8,AB9-AB8,0)*0.53 -> 0 | AD9: 863424 | AE9: =IF(AD9>=AD8,AD9-AD8,0)*0.53 -> 13.25 | AF9: 1011035 | AG9: =IF(AF9>=AF8,AF9-AF8,0)*0.53 -> 12.72 | AH9: 446455 | AI9: =IF(AH9>=AH8,AH9-AH8,0)*0.53 -> 174.37 | AJ9: 789983 | AK9: =IF(AJ9>=AJ8,AJ9-AJ8,0)*0.53 -> 1990.15 | AL9: 581683 | AM9: =IF(AL9>=AL8,AL9-AL8,0)*0.53 -> 113.42 | AN9: =W9+Y9+AA9+AC9+AE9+AG9+AI9+AK9+AM9 -> 4468.43 | AO9: 8242035 | AP9: =IF(AO9>=AO8,AO9-AO8,0)*0.1125 -> 155.475 | AQ9: 763076 | AR9: =IF(AQ9>=AQ8,AQ9-AQ8,0) -> 202 | AS9: 23607 | AT9: =IF(AS9>=AS8,AS9-AS8,0) -> 111 | AU9: 828661 | AV9: =IF(AU9>=AU8,AU9-AU8,0) -> 40 | AW9: 2934896 | AX9: =IF(AW9>=AW8,AW9-AW8,0) -> 622 | AY9: 237653 | AZ9: =IF(AY9>=AY8,AY9-AY8,0) -> 610 | BA9: 21112801 | BB9: =IF(BA9>=BA8,BA9-BA8,0) -> 4853 | BC9: 654265 | BD9: =IF(BC9>=BC8,BC9-BC8,0) -> 178 | BE9: 47856 | BF9: =IF(BE9>=BE8,BE9-BE8,0) -> 40 | BG9: 26536642 | BH9: =IF(BG9>=BG8,BG9-BG8,0)-(0.45*BN9)-(0.45*BP9)-BR9 -> 5359.95 | BI9: =AP9+AR9+AT9+AV9+AX9+AZ9+BB9+BD9+BF9+BH9 -> 12171.425 | BJ9: =BI9+AN9 -> 16639.855 | BK9: 1509345 | BL9: =IF(BK9>=BK8,BK9-BK8,0) -> 88 | BM9: 4373844 | BN9: =IF(BM9>=BM8,BM9-BM8,0) -> 1011 | BO9: 458183 | BP9: =IF(BO9>=BO8,BO9-BO8,0) -> 118 | BQ9: 571138 | BR9: =IF(BQ9>=BQ8,BQ9-BQ8,0) -> 157 | BS9: =J9+Q9+AN9+BI9 -> 23918.855 | BT9: 236 | BU9: =IF(BS9>0,BS9/BT8,0) -> 183.99119 | BW9: =IF(BS9>0,BS9/BV9,0) -> #DIV/0! | BX9: =((BS9-Q9)*$BZ$1)+(Q9*$BR$1) -> 27668.683 | BY9: =IF(BX9>0,BX9/BT8,0) -> 212.83602 | BZ9: =IF(BX9>0,BX9/BV9,0) -> #DIV/0!
A10: 5 | C10: =IF(+B10-B9>0,B10-B9,(B10-B9)>0)*800 -> 0 | E10: =IF(+D10-D9>0,D10-D9,(D10-D9)>0)*80 -> 0 | G10: =IF(+F10-F9>0,F10-F9,(F10-F9)>0)*10 -> 0 | H10: 58 | I10: 26026518 | J10: =IF(I10>=I9,I10-I9,0) -> 6667 | K10: =M10+O10 -> 4562.3333 | L10: 417377 | M10: =IF(L10>=L9,L10-L9,0) -> 2303 | N10: 437329.33 | O10: =IF(N10>=N9,N10-N9,0) -> 2259.3333 | P10: 228262 | Q10: =IF(P10>=P9,P10-P9,0)*30 -> 390 | R10: 235693 | S10: =IF(R10>=R9,R10-R9,0) -> 141 | T10: 429810 | U10: =IF(T10>=T9,T10-T9,0) -> 247 | V10: 914309 | W10: =IF(V10>=V9,V10-V9,0)*0.53 -> 1929.2 | X10: 839916 | Y10: =IF(X10>=X9,X10-X9,0)*0.53 -> 0 | Z10: 871793 | AA10: =IF(Z10>=Z9,Z10-Z9,0)*0.53 -> 0 | AB10: 184962 | AC10: =IF(AB10>=AB9,AB10-AB9,0)*0.53 -> 0 | AD10: 863447 | AE10: =IF(AD10>=AD9,AD10-AD9,0)*0.53 -> 12.19 | AF10: 1011058.3 | AG10: =IF(AF10>=AF9,AF10-AF9,0)*0.53 -> 12.366667 | AH10: 446749 | AI10: =IF(AH10>=AH9,AH10-AH9,0)*0.53 -> 155.82 | AJ10: 793536 | AK10: =IF(AJ10>=AJ9,AJ10-AJ9,0)*0.53 -> 1883.09 | AL10: 581899 | AM10: =IF(AL10>=AL9,AL10-AL9,0)*0.53 -> 114.48 | AN10: =W10+Y10+AA10+AC10+AE10+AG10+AI10+AK10+AM10 -> 4107.1467 | AO10: 8243366 | AP10: =IF(AO10>=AO9,AO10-AO9,0)*0.1125 -> 149.7375 | AQ10: 763274 | AR10: =IF(AQ10>=AQ9,AQ10-AQ9,0) -> 198 | AS10: 23728 | AT10: =IF(AS10>=AS9,AS10-AS9,0) -> 121 | AU10: 828701 | AV10: =IF(AU10>=AU9,AU10-AU9,0) -> 40 | AW10: 2935551 | AX10: =IF(AW10>=AW9,AW10-AW9,0) -> 655 | AY10: 238252 | AZ10: =IF(AY10>=AY9,AY10-AY9,0) -> 599 | BA10: 21117407 | BB10: =IF(BA10>=BA9,BA10-BA9,0) -> 4606 | BC10: 654451 | BD10: =IF(BC10>=BC9,BC10-BC9,0) -> 186 | BE10: 47896 | BF10: =IF(BE10>=BE9,BE10-BE9,0) -> 40 | BG10: 26542420 | BH10: =IF(BG10>=BG9,BG10-BG9,0)-(0.45*BN10)-(0.45*BP10)-BR10 -> 5121.25 | BI10: =AP10+AR10+AT10+AV10+AX10+AZ10+BB10+BD10+BF10+BH10 -> 11715.987 | BJ10: =BI10+AN10 -> 15823.134 | BK10: 1509448 | BL10: =IF(BK10>=BK9,BK10-BK9,0) -> 103 | BM10: 4374852 | BN10: =IF(BM10>=BM9,BM10-BM9,0) -> 1008 | BO10: 458290 | BP10: =IF(BO10>=BO9,BO10-BO9,0) -> 107 | BQ10: 571293 | BR10: =IF(BQ10>=BQ9,BQ10-BQ9,0) -> 155 | BS10: =J10+Q10+AN10+BI10 -> 22880.134 | BT10: 237 | BU10: =IF(BS10>0,BS10/BT9,0) -> 96.949721 | BW10: =IF(BS10>0,BS10/BV10,0) -> #DIV/0! | BX10: =((BS10-Q10)*$BZ$1)+(Q10*$BR$1) -> 26487.654 | BY10: =IF(BX10>0,BX10/BT9,0) -> 112.23582 | BZ10: =IF(BX10>0,BX10/BV10,0) -> #DIV/0!
A11: 6 | C11: =IF(+B11-B10>0,B11-B10,(B11-B10)>0)*800 -> 0 | E11: =IF(+D11-D10>0,D11-D10,(D11-D10)>0)*80 -> 0 | G11: =IF(+F11-F10>0,F11-F10,(F11-F10)>0)*10 -> 0 | I11: 26033737 | J11: =IF(I11>=I10,I11-I10,0) -> 7219 | K11: =M11+O11 -> 4924 | L11: 420013 | M11: =IF(L11>=L10,L11-L10,0) -> 2636 | N11: 439617.33 | O11: =IF(N11>=N10,N11-N10,0) -> 2288 | P11: 228277 | Q11: =IF(P11>=P10,P11-P10,0)*30 -> 450 | R11: 235835 | S11: =IF(R11>=R10,R11-R10,0) -> 142 | T11: 430058 | U11: =IF(T11>=T10,T11-T10,0) -> 248 | V11: 916737 | W11: =IF(V11>=V10,V11-V10,0)*0.53 -> 1286.84 | X11: 839916 | Y11: =IF(X11>=X10,X11-X10,0)*0.53 -> 0 | Z11: 871835 | AA11: =IF(Z11>=Z10,Z11-Z10,0)*0.53 -> 22.26 | AB11: 184962 | AC11: =IF(AB11>=AB10,AB11-AB10,0)*0.53 -> 0 | AD11: 863473 | AE11: =IF(AD11>=AD10,AD11-AD10,0)*0.53 -> 13.78 | AF11: 1011082 | AG11: =IF(AF11>=AF10,AF11-AF10,0)*0.53 -> 12.543333 | AH11: 447046 | AI11: =IF(AH11>=AH10,AH11-AH10,0)*0.53 -> 157.41 | AJ11: 796888 | AK11: =IF(AJ11>=AJ10,AJ11-AJ10,0)*0.53 -> 1776.56 | AL11: 582111 | AM11: =IF(AL11>=AL10,AL11-AL10,0)*0.53 -> 112.36 | AN11: =W11+Y11+AA11+AC11+AE11+AG11+AI11+AK11+AM11 -> 3381.7533 | AO11: 8244579 | AP11: =IF(AO11>=AO10,AO11-AO10,0)*0.1125 -> 136.4625 | AQ11: 763471 | AR11: =IF(AQ11>=AQ10,AQ11-AQ10,0) -> 197 | AS11: 23841 | AT11: =IF(AS11>=AS10,AS11-AS10,0) -> 113 | AU11: 828742 | AV11: =IF(AU11>=AU10,AU11-AU10,0) -> 41 | AW11: 2936270 | AX11: =IF(AW11>=AW10,AW11-AW10,0) -> 719 | AY11: 239198 | AZ11: =IF(AY11>=AY10,AY11-AY10,0) -> 946 | BA11: 21121777 | BB11: =IF(BA11>=BA10,BA11-BA10,0) -> 4370 | BC11: 654643 | BD11: =IF(BC11>=BC10,BC11-BC10,0) -> 192 | BE11: 47936 | BF11: =IF(BE11>=BE10,BE11-BE10,0) -> 40 | BG11: 26548144 | BH11: =IF(BG11>=BG10,BG11-BG10,0)-(0.45*BN11)-(0.45*BP11)-BR11 -> 5079.75 | BI11: =AP11+AR11+AT11+AV11+AX11+AZ11+BB11+BD11+BF11+BH11 -> 11834.212 | BJ11: =BI11+AN11 -> 15215.966 | BK11: 1509538 | BL11: =IF(BK11>=BK10,BK11-BK10,0) -> 90 | BM11: 4375830 | BN11: =IF(BM11>=BM10,BM11-BM10,0) -> 978 | BO11: 458397 | BP11: =IF(BO11>=BO10,BO11-BO10,0) -> 107 | BQ11: 571449 | BR11: =IF(BQ11>=BQ10,BQ11-BQ10,0) -> 156 | BS11: =J11+Q11+AN11+BI11 -> 22884.966 | BT11: 196 | BU11: =IF(BS11>0,BS11/BT10,0) -> 96.561037 | BW11: =IF(BS11>0,BS11/BV11,0) -> #DIV/0! | BX11: =((BS11-Q11)*$BZ$1)+(Q11*$BR$1) -> 26520.211 | BY11: =IF(BX11>0,BX11/BT10,0) -> 111.89962 | BZ11: =IF(BX11>0,BX11/BV11,0) -> #DIV/0!
A12: 7 | C12: =IF(+B12-B11>0,B12-B11,(B12-B11)>0)*800 -> 0 | E12: =IF(+D12-D11>0,D12-D11,(D12-D11)>0)*80 -> 0 | G12: =IF(+F12-F11>0,F12-F11,(F12-F11)>0)*10 -> 0 | H12: 59 | I12: 26041103 | J12: =IF(I12>=I11,I12-I11,0) -> 7366 | K12: =M12+O12 -> 5085 | L12: 422810 | M12: =IF(L12>=L11,L12-L11,0) -> 2797 | N12: 441905.33 | O12: =IF(N12>=N11,N12-N11,0) -> 2288 | P12: 228295 | Q12: =IF(P12>=P11,P12-P11,0)*30 -> 540 | R12: 235981 | S12: =IF(R12>=R11,R12-R11,0) -> 146 | T12: 430314 | U12: =IF(T12>=T11,T12-T11,0) -> 256 | V12: 919343 | W12: =IF(V12>=V11,V12-V11,0)*0.53 -> 1381.18 | X12: 839916 | Y12: =IF(X12>=X11,X12-X11,0)*0.53 -> 0 | Z12: 871835 | AA12: =IF(Z12>=Z11,Z12-Z11,0)*0.53 -> 0 | AB12: 184962 | AC12: =IF(AB12>=AB11,AB12-AB11,0)*0.53 -> 0 | AD12: 863498 | AE12: =IF(AD12>=AD11,AD12-AD11,0)*0.53 -> 13.25 | AF12: 1011106 | AG12: =IF(AF12>=AF11,AF12-AF11,0)*0.53 -> 12.72 | AH12: 447286 | AI12: =IF(AH12>=AH11,AH12-AH11,0)*0.53 -> 127.2 | AJ12: 800407 | AK12: =IF(AJ12>=AJ11,AJ12-AJ11,0)*0.53 -> 1865.07 | AL12: 582334 | AM12: =IF(AL12>=AL11,AL12-AL11,0)*0.53 -> 118.19 | AN12: =W12+Y12+AA12+AC12+AE12+AG12+AI12+AK12+AM12 -> 3517.61 | AO12: 8245605 | AP12: =IF(AO12>=AO11,AO12-AO11,0)*0.1125 -> 115.425 | AQ12: 763671 | AR12: =IF(AQ12>=AQ11,AQ12-AQ11,0) -> 200 | AS12: 23971 | AT12: =IF(AS12>=AS11,AS12-AS11,0) -> 130 | AU12: 828784 | AV12: =IF(AU12>=AU11,AU12-AU11,0) -> 42 | AW12: 2937024 | AX12: =IF(AW12>=AW11,AW12-AW11,0) -> 754 | AY12: 239775 | AZ12: =IF(AY12>=AY11,AY12-AY11,0) -> 577 | BA12: 21126209 | BB12: =IF(BA12>=BA11,BA12-BA11,0) -> 4432 | BC12: 654869 | BD12: =IF(BC12>=BC11,BC12-BC11,0) -> 226 | BE12: 47976 | BF12: =IF(BE12>=BE11,BE12-BE11,0) -> 40 | BG12: 26554102 | BH12: =IF(BG12>=BG11,BG12-BG11,0)-(0.45*BN12)-(0.45*BP12)-BR12 -> 5272.35 | BI12: =AP12+AR12+AT12+AV12+AX12+AZ12+BB12+BD12+BF12+BH12 -> 11788.775 | BJ12: =BI12+AN12 -> 15306.385 | BK12: 1509623 | BL12: =IF(BK12>=BK11,BK12-BK11,0) -> 85 | BM12: 4376873 | BN12: =IF(BM12>=BM11,BM12-BM11,0) -> 1043 | BO12: 458511 | BP12: =IF(BO12>=BO11,BO12-BO11,0) -> 114 | BQ12: 571614 | BR12: =IF(BQ12>=BQ11,BQ12-BQ11,0) -> 165 | BS12: =J12+Q12+AN12+BI12 -> 23212.385 | BT12: 163 | BU12: =IF(BS12>0,BS12/BT11,0) -> 118.43054 | BW12: =IF(BS12>0,BS12/BV12,0) -> #DIV/0! | BX12: =((BS12-Q12)*$BZ$1)+(Q12*$BR$1) -> 26937.243 | BY12: =IF(BX12>0,BX12/BT11,0) -> 137.43491 | BZ12: =IF(BX12>0,BX12/BV12,0) -> #DIV/0!
A13: 8 | C13: =IF(+B13-B12>0,B13-B12,(B13-B12)>0)*800 -> 0 | E13: =IF(+D13-D12>0,D13-D12,(D13-D12)>0)*80 -> 0 | G13: =IF(+F13-F12>0,F13-F12,(F13-F12)>0)*10 -> 0 | I13: 26048469 | J13: =IF(I13>=I12,I13-I12,0) -> 7366 | K13: =M13+O13 -> 5113 | L13: 425635 | M13: =IF(L13>=L12,L13-L12,0) -> 2825 | N13: 444193.33 | O13: =IF(N13>=N12,N13-N12,0) -> 2288 | P13: 228310 | Q13: =IF(P13>=P12,P13-P12,0)*30 -> 450 | R13: 236127 | S13: =IF(R13>=R12,R13-R12,0) -> 146 | T13: 430566 | U13: =IF(T13>=T12,T13-T12,0) -> 252 | V13: 921760 | W13: =IF(V13>=V12,V13-V12,0)*0.53 -> 1281.01 | X13: 839916 | Y13: =IF(X13>=X12,X13-X12,0)*0.53 -> 0 | Z13: 871835 | AA13: =IF(Z13>=Z12,Z13-Z12,0)*0.53 -> 0 | AB13: 184962 | AC13: =IF(AB13>=AB12,AB13-AB12,0)*0.53 -> 0 | AD13: 863524 | AE13: =IF(AD13>=AD12,AD13-AD12,0)*0.53 -> 13.78 | AF13: 1011131 | AG13: =IF(AF13>=AF12,AF13-AF12,0)*0.53 -> 13.25 | AH13: 447509 | AI13: =IF(AH13>=AH12,AH13-AH12,0)*0.53 -> 118.19 | AJ13: 803744 | AK13: =IF(AJ13>=AJ12,AJ13-AJ12,0)*0.53 -> 1768.61 | AL13: 582557 | AM13: =IF(AL13>=AL12,AL13-AL12,0)*0.53 -> 118.19 | AN13: =W13+Y13+AA13+AC13+AE13+AG13+AI13+AK13+AM13 -> 3313.03 | AO13: 8246130 | AP13: =IF(AO13>=AO12,AO13-AO12,0)*0.1125 -> 59.0625 | AQ13: 763878 | AR13: =IF(AQ13>=AQ12,AQ13-AQ12,0) -> 207 | AS13: 24070 | AT13: =IF(AS13>=AS12,AS13-AS12,0) -> 99 | AU13: 828825 | AV13: =IF(AU13>=AU12,AU13-AU12,0) -> 41 | AW13: 2937759 | AX13: =IF(AW13>=AW12,AW13-AW12,0) -> 735 | AY13: 240400 | AZ13: =IF(AY13>=AY12,AY13-AY12,0) -> 625 | BA13: 21130949 | BB13: =IF(BA13>=BA12,BA13-BA12,0) -> 4740 | BC13: 655056 | BD13: =IF(BC13>=BC12,BC13-BC12,0) -> 187 | BE13: 48016 | BF13: =IF(BE13>=BE12,BE13-BE12,0) -> 40 | BG13: 26560213 | BH13: =IF(BG13>=BG12,BG13-BG12,0)-(0.45*BN13)-(0.45*BP13)-BR13 -> 5438.5 | BI13: =AP13+AR13+AT13+AV13+AX13+AZ13+BB13+BD13+BF13+BH13 -> 12171.562 | BJ13: =BI13+AN13 -> 15484.593 | BK13: 1509920 | BL13: =IF(BK13>=BK12,BK13-BK12,0) -> 297 | BM13: 4377891 | BN13: =IF(BM13>=BM12,BM13-BM12,0) -> 1018 | BO13: 458623 | BP13: =IF(BO13>=BO12,BO13-BO12,0) -> 112 | BQ13: 571778 | BR13: =IF(BQ13>=BQ12,BQ13-BQ12,0) -> 164 | BS13: =J13+Q13+AN13+BI13 -> 23300.592 | BT13: 149 | BU13: =IF(BS13>0,BS13/BT12,0) -> 142.94842 | BW13: =IF(BS13>0,BS13/BV13,0) -> #DIV/0! | BX13: =((BS13-Q13)*$BZ$1)+(Q13*$BR$1) -> 26998.181 | BY13: =IF(BX13>0,BX13/BT12,0) -> 165.63301 | BZ13: =IF(BX13>0,BX13/BV13,0) -> #DIV/0!
A14: 9 | C14: =IF(+B14-B13>0,B14-B13,(B14-B13)>0)*800 -> 0 | E14: =IF(+D14-D13>0,D14-D13,(D14-D13)>0)*80 -> 0 | G14: =IF(+F14-F13>0,F14-F13,(F14-F13)>0)*10 -> 0 | H14: 60 | I14: 26055788 | J14: =IF(I14>=I13,I14-I13,0) -> 7319 | K14: =M14+O14 -> 5084 | L14: 428431 | M14: =IF(L14>=L13,L14-L13,0) -> 2796 | N14: 446481.33 | O14: =IF(N14>=N13,N14-N13,0) -> 2288 | P14: 228324 | Q14: =IF(P14>=P13,P14-P13,0)*30 -> 420 | R14: 236268 | S14: =IF(R14>=R13,R14-R13,0) -> 141 | T14: 430818 | U14: =IF(T14>=T13,T14-T13,0) -> 252 | V14: 924301 | W14: =IF(V14>=V13,V14-V13,0)*0.53 -> 1346.73 | X14: 839916 | Y14: =IF(X14>=X13,X14-X13,0)*0.53 -> 0 | Z14: 871835 | AA14: =IF(Z14>=Z13,Z14-Z13,0)*0.53 -> 0 | AB14: 184962 | AC14: =IF(AB14>=AB13,AB14-AB13,0)*0.53 -> 0 | AD14: 863549 | AE14: =IF(AD14>=AD13,AD14-AD13,0)*0.53 -> 13.25 | AF14: 1011155 | AG14: =IF(AF14>=AF13,AF14-AF13,0)*0.53 -> 12.72 | AH14: 447736 | AI14: =IF(AH14>=AH13,AH14-AH13,0)*0.53 -> 120.31 | AJ14: 807066 | AK14: =IF(AJ14>=AJ13,AJ14-AJ13,0)*0.53 -> 1760.66 | AL14: 582767 | AM14: =IF(AL14>=AL13,AL14-AL13,0)*0.53 -> 111.3 | AN14: =W14+Y14+AA14+AC14+AE14+AG14+AI14+AK14+AM14 -> 3364.97 | AO14: 8247203 | AP14: =IF(AO14>=AO13,AO14-AO13,0)*0.1125 -> 120.7125 | AQ14: 764081 | AR14: =IF(AQ14>=AQ13,AQ14-AQ13,0) -> 203 | AS14: 24178 | AT14: =IF(AS14>=AS13,AS14-AS13,0) -> 108 | AU14: 828865 | AV14: =IF(AU14>=AU13,AU14-AU13,0) -> 40 | AW14: 2938499 | AX14: =IF(AW14>=AW13,AW14-AW13,0) -> 740 | AY14: 240982 | AZ14: =IF(AY14>=AY13,AY14-AY13,0) -> 582 | BA14: 21135495 | BB14: =IF(BA14>=BA13,BA14-BA13,0) -> 4546 | BC14: 655224 | BD14: =IF(BC14>=BC13,BC14-BC13,0) -> 168 | BE14: 48051 | BF14: =IF(BE14>=BE13,BE14-BE13,0) -> 35 | BG14: 26566079 | BH14: =IF(BG14>=BG13,BG14-BG13,0)-(0.45*BN14)-(0.45*BP14)-BR14 -> 5260 | BI14: =AP14+AR14+AT14+AV14+AX14+AZ14+BB14+BD14+BF14+BH14 -> 11802.712 | BJ14: =BI14+AN14 -> 15167.682 | BK14: 1510187 | BL14: =IF(BK14>=BK13,BK14-BK13,0) -> 267 | BM14: 4378863 | BN14: =IF(BM14>=BM13,BM14-BM13,0) -> 972 | BO14: 458731 | BP14: =IF(BO14>=BO13,BO14-BO13,0) -> 108 | BQ14: 571898 | BR14: =IF(BQ14>=BQ13,BQ14-BQ13,0) -> 120 | BS14: =J14+Q14+AN14+BI14 -> 22906.683 | BT14: 162 | BU14: =IF(BS14>0,BS14/BT13,0) -> 153.73612 | BW14: =IF(BS14>0,BS14/BV14,0) -> #DIV/0! | BX14: =((BS14-Q14)*$BZ$1)+(Q14*$BR$1) -> 26531.685 | BY14: =IF(BX14>0,BX14/BT13,0) -> 178.065 | BZ14: =IF(BX14>0,BX14/BV14,0) -> #DIV/0!
A15: 10 | C15: =IF(+B15-B14>0,B15-B14,(B15-B14)>0)*800 -> 0 | E15: =IF(+D15-D14>0,D15-D14,(D15-D14)>0)*80 -> 0 | G15: =IF(+F15-F14>0,F15-F14,(F15-F14)>0)*10 -> 0 | I15: 26063320 | J15: =IF(I15>=I14,I15-I14,0) -> 7532 | K15: =M15+O15 -> 4924 | L15: 431067 | M15: =IF(L15>=L14,L15-L14,0) -> 2636 | N15: 448769.33 | O15: =IF(N15>=N14,N15-N14,0) -> 2288 | P15: 228340 | Q15: =IF(P15>=P14,P15-P14,0)*30 -> 480 | R15: 236413 | S15: =IF(R15>=R14,R15-R14,0) -> 145 | T15: 431080 | U15: =IF(T15>=T14,T15-T14,0) -> 262 | V15: 926812 | W15: =IF(V15>=V14,V15-V14,0)*0.53 -> 1330.83 | X15: 839916 | Y15: =IF(X15>=X14,X15-X14,0)*0.53 -> 0 | Z15: 871835 | AA15: =IF(Z15>=Z14,Z15-Z14,0)*0.53 -> 0 | AB15: 184962 | AC15: =IF(AB15>=AB14,AB15-AB14,0)*0.53 -> 0 | AD15: 863579 | AE15: =IF(AD15>=AD14,AD15-AD14,0)*0.53 -> 15.9 | AF15: 1011178 | AG15: =IF(AF15>=AF14,AF15-AF14,0)*0.53 -> 12.19 | AH15: 447973 | AI15: =IF(AH15>=AH14,AH15-AH14,0)*0.53 -> 125.61 | AJ15: 809868 | AK15: =IF(AJ15>=AJ14,AJ15-AJ14,0)*0.53 -> 1485.06 | AL15: 582975 | AM15: =IF(AL15>=AL14,AL15-AL14,0)*0.53 -> 110.24 | AN15: =W15+Y15+AA15+AC15+AE15+AG15+AI15+AK15+AM15 -> 3079.83 | AO15: 8248101 | AP15: =IF(AO15>=AO14,AO15-AO14,0)*0.1125 -> 101.025 | AQ15: 764255 | AR15: =IF(AQ15>=AQ14,AQ15-AQ14,0) -> 174 | AS15: 24318 | AT15: =IF(AS15>=AS14,AS15-AS14,0) -> 140 | AU15: 828905 | AV15: =IF(AU15>=AU14,AU15-AU14,0) -> 40 | AW15: 2939239 | AX15: =IF(AW15>=AW14,AW15-AW14,0) -> 740 | AY15: 240992 | AZ15: =IF(AY15>=AY14,AY15-AY14,0) -> 10 | BA15: 21140199 | BB15: =IF(BA15>=BA14,BA15-BA14,0) -> 4704 | BC15: 655400 | BD15: =IF(BC15>=BC14,BC15-BC14,0) -> 176 | BE15: 48086 | BF15: =IF(BE15>=BE14,BE15-BE14,0) -> 35 | BG15: 26572085 | BH15: =IF(BG15>=BG14,BG15-BG14,0)-(0.45*BN15)-(0.45*BP15)-BR15 -> 5358.05 | BI15: =AP15+AR15+AT15+AV15+AX15+AZ15+BB15+BD15+BF15+BH15 -> 11478.075 | BJ15: =BI15+AN15 -> 14557.905 | BK15: 1510464 | BL15: =IF(BK15>=BK14,BK15-BK14,0) -> 277 | BM15: 4379841 | BN15: =IF(BM15>=BM14,BM15-BM14,0) -> 978 | BO15: 458844 | BP15: =IF(BO15>=BO14,BO15-BO14,0) -> 113 | BQ15: 572055 | BR15: =IF(BQ15>=BQ14,BQ15-BQ14,0) -> 157 | BS15: =J15+Q15+AN15+BI15 -> 22569.905 | BT15: 176 | BU15: =IF(BS15>0,BS15/BT14,0) -> 139.3204 | BW15: =IF(BS15>0,BS15/BV15,0) -> #DIV/0! | BX15: =((BS15-Q15)*$BZ$1)+(Q15*$BR$1) -> 26171.391 | BY15: =IF(BX15>0,BX15/BT14,0) -> 161.55179 | BZ15: =IF(BX15>0,BX15/BV15,0) -> #DIV/0!
A16: 11 | C16: =IF(+B16-B15>0,B16-B15,(B16-B15)>0)*800 -> 0 | E16: =IF(+D16-D15>0,D16-D15,(D16-D15)>0)*80 -> 0 | G16: =IF(+F16-F15>0,F16-F15,(F16-F15)>0)*10 -> 0 | H16: 61 | I16: 26070419 | J16: =IF(I16>=I15,I16-I15,0) -> 7099 | K16: =M16+O16 -> 4845 | L16: 433624 | M16: =IF(L16>=L15,L16-L15,0) -> 2557 | N16: 451057.33 | O16: =IF(N16>=N15,N16-N15,0) -> 2288 | P16: 228354 | Q16: =IF(P16>=P15,P16-P15,0)*30 -> 420 | R16: 236550 | S16: =IF(R16>=R15,R16-R15,0) -> 137 | T16: 431328 | U16: =IF(T16>=T15,T16-T15,0) -> 248 | V16: 929828 | W16: =IF(V16>=V15,V16-V15,0)*0.53 -> 1598.48 | X16: 839916 | Y16: =IF(X16>=X15,X16-X15,0)*0.53 -> 0 | Z16: 871835 | AA16: =IF(Z16>=Z15,Z16-Z15,0)*0.53 -> 0 | AB16: 184962 | AC16: =IF(AB16>=AB15,AB16-AB15,0)*0.53 -> 0 | AD16: 863598 | AE16: =IF(AD16>=AD15,AD16-AD15,0)*0.53 -> 10.07 | AF16: 1011202 | AG16: =IF(AF16>=AF15,AF16-AF15,0)*0.53 -> 12.72 | AH16: 448260 | AI16: =IF(AH16>=AH15,AH16-AH15,0)*0.53 -> 152.11 | AJ16: 813241 | AK16: =IF(AJ16>=AJ15,AJ16-AJ15,0)*0.53 -> 1787.69 | AL16: 583186 | AM16: =IF(AL16>=AL15,AL16-AL15,0)*0.53 -> 111.83 | AN16: =W16+Y16+AA16+AC16+AE16+AG16+AI16+AK16+AM16 -> 3672.9 | AO16: 8249117 | AP16: =IF(AO16>=AO15,AO16-AO15,0)*0.1125 -> 114.3 | AQ16: 764442 | AR16: =IF(AQ16>=AQ15,AQ16-AQ15,0) -> 187 | AS16: 24450 | AT16: =IF(AS16>=AS15,AS16-AS15,0) -> 132 | AU16: 828946 | AV16: =IF(AU16>=AU15,AU16-AU15,0) -> 41 | AW16: 2939983 | AX16: =IF(AW16>=AW15,AW16-AW15,0) -> 744 | AY16: 241002 | AZ16: =IF(AY16>=AY15,AY16-AY15,0) -> 10 | BA16: 21144793 | BB16: =IF(BA16>=BA15,BA16-BA15,0) -> 4594 | BC16: 655593 | BD16: =IF(BC16>=BC15,BC16-BC15,0) -> 193 | BE16: 48126 | BF16: =IF(BE16>=BE15,BE16-BE15,0) -> 40 | BG16: 26578049 | BH16: =IF(BG16>=BG15,BG16-BG15,0)-(0.45*BN16)-(0.45*BP16)-BR16 -> 5336.8 | BI16: =AP16+AR16+AT16+AV16+AX16+AZ16+BB16+BD16+BF16+BH16 -> 11392.1 | BJ16: =BI16+AN16 -> 15065 | BK16: 1510733 | BL16: =IF(BK16>=BK15,BK16-BK15,0) -> 269 | BM16: 4380788 | BN16: =IF(BM16>=BM15,BM16-BM15,0) -> 947 | BO16: 458953 | BP16: =IF(BO16>=BO15,BO16-BO15,0) -> 109 | BQ16: 572207 | BR16: =IF(BQ16>=BQ15,BQ16-BQ15,0) -> 152 | BS16: =J16+Q16+AN16+BI16 -> 22584 | BT16: 234 | BU16: =IF(BS16>0,BS16/BT15,0) -> 128.31818 | BW16: =IF(BS16>0,BS16/BV16,0) -> #DIV/0! | BX16: =((BS16-Q16)*$BZ$1)+(Q16*$BR$1) -> 26160.6 | BY16: =IF(BX16>0,BX16/BT15,0) -> 148.63977 | BZ16: =IF(BX16>0,BX16/BV16,0) -> #DIV/0!
A17: 12 | C17: =IF(+B17-B16>0,B17-B16,(B17-B16)>0)*800 -> 0 | E17: =IF(+D17-D16>0,D17-D16,(D17-D16)>0)*80 -> 0 | G17: =IF(+F17-F16>0,F17-F16,(F17-F16)>0)*10 -> 0 | I17: 26079439 | J17: =IF(I17>=I16,I17-I16,0) -> 9020 | K17: =M17+O17 -> 4796 | L17: 436132 | M17: =IF(L17>=L16,L17-L16,0) -> 2508 | N17: 453345.33 | O17: =IF(N17>=N16,N17-N16,0) -> 2288 | P17: 228369 | Q17: =IF(P17>=P16,P17-P16,0)*30 -> 450 | R17: 236705 | S17: =IF(R17>=R16,R17-R16,0) -> 155 | T17: 431596 | U17: =IF(T17>=T16,T17-T16,0) -> 268 | V17: 932736 | W17: =IF(V17>=V16,V17-V16,0)*0.53 -> 1541.24 | X17: 839916 | Y17: =IF(X17>=X16,X17-X16,0)*0.53 -> 0 | Z17: 871835 | AA17: =IF(Z17>=Z16,Z17-Z16,0)*0.53 -> 0 | AB17: 184962 | AC17: =IF(AB17>=AB16,AB17-AB16,0)*0.53 -> 0 | AD17: 863624 | AE17: =IF(AD17>=AD16,AD17-AD16,0)*0.53 -> 13.78 | AF17: 1011226 | AG17: =IF(AF17>=AF16,AF17-AF16,0)*0.53 -> 12.72 | AH17: 448556 | AI17: =IF(AH17>=AH16,AH17-AH16,0)*0.53 -> 156.88 | AJ17: 816762 | AK17: =IF(AJ17>=AJ16,AJ17-AJ16,0)*0.53 -> 1866.13 | AL17: 583405 | AM17: =IF(AL17>=AL16,AL17-AL16,0)*0.53 -> 116.07 | AN17: =W17+Y17+AA17+AC17+AE17+AG17+AI17+AK17+AM17 -> 3706.82 | AO17: 8249636 | AP17: =IF(AO17>=AO16,AO17-AO16,0)*0.1125 -> 58.3875 | AQ17: 764649 | AR17: =IF(AQ17>=AQ16,AQ17-AQ16,0) -> 207 | AS17: 24581 | AT17: =IF(AS17>=AS16,AS17-AS16,0) -> 131 | AU17: 828988 | AV17: =IF(AU17>=AU16,AU17-AU16,0) -> 42 | AW17: 2940737 | AX17: =IF(AW17>=AW16,AW17-AW16,0) -> 754 | AY17: 241013 | AZ17: =IF(AY17>=AY16,AY17-AY16,0) -> 11 | BA17: 21149640 | BB17: =IF(BA17>=BA16,BA17-BA16,0) -> 4847 | BC17: 655845 | BD17: =IF(BC17>=BC16,BC17-BC16,0) -> 252 | BE17: 48166 | BF17: =IF(BE17>=BE16,BE17-BE16,0) -> 40 | BG17: 26584458 | BH17: =IF(BG17>=BG16,BG17-BG16,0)-(0.45*BN17)-(0.45*BP17)-BR17 -> 5740.15 | BI17: =AP17+AR17+AT17+AV17+AX17+AZ17+BB17+BD17+BF17+BH17 -> 12082.538 | BJ17: =BI17+AN17 -> 15789.358 | BK17: 1510942 | BL17: =IF(BK17>=BK16,BK17-BK16,0) -> 209 | BM17: 4381784 | BN17: =IF(BM17>=BM16,BM17-BM16,0) -> 996 | BO17: 459070 | BP17: =IF(BO17>=BO16,BO17-BO16,0) -> 117 | BQ17: 572375 | BR17: =IF(BQ17>=BQ16,BQ17-BQ16,0) -> 168 | BS17: =J17+Q17+AN17+BI17 -> 25259.357 | BT17: 240 | BU17: =IF(BS17>0,BS17/BT16,0) -> 107.94597 | BW17: =IF(BS17>0,BS17/BV17,0) -> #DIV/0! | BX17: =((BS17-Q17)*$BZ$1)+(Q17*$BR$1) -> 29250.761 | BY17: =IF(BX17>0,BX17/BT16,0) -> 125.00325 | BZ17: =IF(BX17>0,BX17/BV17,0) -> #DIV/0!
A18: 13 | C18: =IF(+B18-B17>0,B18-B17,(B18-B17)>0)*800 -> 0 | E18: =IF(+D18-D17>0,D18-D17,(D18-D17)>0)*80 -> 0 | G18: =IF(+F18-F17>0,F18-F17,(F18-F17)>0)*10 -> 0 | H18: 62 | I18: 26084996 | J18: =IF(I18>=I17,I18-I17,0) -> 5557 | K18: =M18+O18 -> 2502 | L18: 438634 | M18: =IF(L18>=L17,L18-L17,0) -> 2502 | N18: 436613 | O18: =IF(N18>=N17,N18-N17,0) -> 0 | P18: 228388 | Q18: =IF(P18>=P17,P18-P17,0)*30 -> 570 | R18: 236843 | S18: =IF(R18>=R17,R18-R17,0) -> 138 | T18: 431833 | U18: =IF(T18>=T17,T18-T17,0) -> 237 | V18: 935595 | W18: =IF(V18>=V17,V18-V17,0)*0.53 -> 1515.27 | X18: 839916 | Y18: =IF(X18>=X17,X18-X17,0)*0.53 -> 0 | Z18: 871835 | AA18: =IF(Z18>=Z17,Z18-Z17,0)*0.53 -> 0 | AB18: 184962 | AC18: =IF(AB18>=AB17,AB18-AB17,0)*0.53 -> 0 | AD18: 863650 | AE18: =IF(AD18>=AD17,AD18-AD17,0)*0.53 -> 13.78 | AF18: 1011250 | AG18: =IF(AF18>=AF17,AF18-AF17,0)*0.53 -> 12.72 | AH18: 448850 | AI18: =IF(AH18>=AH17,AH18-AH17,0)*0.53 -> 155.82 | AJ18: 820516 | AK18: =IF(AJ18>=AJ17,AJ18-AJ17,0)*0.53 -> 1989.62 | AL18: 583613 | AM18: =IF(AL18>=AL17,AL18-AL17,0)*0.53 -> 110.24 | AN18: =W18+Y18+AA18+AC18+AE18+AG18+AI18+AK18+AM18 -> 3797.45 | AO18: 8250487 | AP18: =IF(AO18>=AO17,AO18-AO17,0)*0.1125 -> 95.7375 | AQ18: 764835 | AR18: =IF(AQ18>=AQ17,AQ18-AQ17,0) -> 186 | AS18: 24724 | AT18: =IF(AS18>=AS17,AS18-AS17,0) -> 143 | AU18: 829028 | AV18: =IF(AU18>=AU17,AU18-AU17,0) -> 40 | AW18: 2941422 | AX18: =IF(AW18>=AW17,AW18-AW17,0) -> 685 | AY18: 241023 | AZ18: =IF(AY18>=AY17,AY18-AY17,0) -> 10 | BA18: 21154504 | BB18: =IF(BA18>=BA17,BA18-BA17,0) -> 4864 | BC18: 656113 | BD18: =IF(BC18>=BC17,BC18-BC17,0) -> 268 | BE18: 48240 | BF18: =IF(BE18>=BE17,BE18-BE17,0) -> 74 | BG18: 26590481 | BH18: =IF(BG18>=BG17,BG18-BG17,0)-(0.45*BN18)-(0.45*BP18)-BR18 -> 5377.35 | BI18: =AP18+AR18+AT18+AV18+AX18+AZ18+BB18+BD18+BF18+BH18 -> 11743.087 | BJ18: =BI18+AN18 -> 15540.537 | BK18: 1511139 | BL18: =IF(BK18>=BK17,BK18-BK17,0) -> 197 | BM18: 4382753 | BN18: =IF(BM18>=BM17,BM18-BM17,0) -> 969 | BO18: 459178 | BP18: =IF(BO18>=BO17,BO18-BO17,0) -> 108 | BQ18: 572536 | BR18: =IF(BQ18>=BQ17,BQ18-BQ17,0) -> 161 | BS18: =J18+Q18+AN18+BI18 -> 21667.537 | BT18: 246 | BU18: =IF(BS18>0,BS18/BT17,0) -> 90.281406 | BW18: =IF(BS18>0,BS18/BV18,0) -> #DIV/0! | BX18: =((BS18-Q18)*$BZ$1)+(Q18*$BR$1) -> 25174.168 | BY18: =IF(BX18>0,BX18/BT17,0) -> 104.89237 | BZ18: =IF(BX18>0,BX18/BV18,0) -> #DIV/0!
A19: 14 | C19: =IF(+B19-B18>0,B19-B18,(B19-B18)>0)*800 -> 0 | E19: =IF(+D19-D18>0,D19-D18,(D19-D18)>0)*80 -> 0 | G19: =IF(+F19-F18>0,F19-F18,(F19-F18)>0)*10 -> 0 | I19: 26092740 | J19: =IF(I19>=I18,I19-I18,0) -> 7744 | K19: =M19+O19 -> 4326 | L19: 441232 | M19: =IF(L19>=L18,L19-L18,0) -> 2598 | N19: 438341 | O19: =IF(N19>=N18,N19-N18,0) -> 1728 | P19: 228406 | Q19: =IF(P19>=P18,P19-P18,0)*30 -> 540 | R19: 236987 | S19: =IF(R19>=R18,R19-R18,0) -> 144 | T19: 432084 | U19: =IF(T19>=T18,T19-T18,0) -> 251 | V19: 938453 | W19: =IF(V19>=V18,V19-V18,0)*0.53 -> 1514.74 | X19: 839916 | Y19: =IF(X19>=X18,X19-X18,0)*0.53 -> 0 | Z19: 871835 | AA19: =IF(Z19>=Z18,Z19-Z18,0)*0.53 -> 0 | AB19: 184462 | AC19: =IF(AB19>=AB18,AB19-AB18,0)*0.53 -> 0 | AD19: 863679 | AE19: =IF(AD19>=AD18,AD19-AD18,0)*0.53 -> 15.37 | AF19: 1011277 | AG19: =IF(AF19>=AF18,AF19-AF18,0)*0.53 -> 14.31 | AH19: 449139 | AI19: =IF(AH19>=AH18,AH19-AH18,0)*0.53 -> 153.17 | AJ19: 824228 | AK19: =IF(AJ19>=AJ18,AJ19-AJ18,0)*0.53 -> 1967.36 | AL19: 583834 | AM19: =IF(AL19>=AL18,AL19-AL18,0)*0.53 -> 117.13 | AN19: =W19+Y19+AA19+AC19+AE19+AG19+AI19+AK19+AM19 -> 3782.08 | AO19: 8250897 | AP19: =IF(AO19>=AO18,AO19-AO18,0)*0.1125 -> 46.125 | AQ19: 765028 | AR19: =IF(AQ19>=AQ18,AQ19-AQ18,0) -> 193 | AS19: 24845 | AT19: =IF(AS19>=AS18,AS19-AS18,0) -> 121 | AU19: 829069 | AV19: =IF(AU19>=AU18,AU19-AU18,0) -> 41 | AW19: 2942094 | AX19: =IF(AW19>=AW18,AW19-AW18,0) -> 672 | AY19: 241033 | AZ19: =IF(AY19>=AY18,AY19-AY18,0) -> 10 | BA19: 21158900 | BB19: =IF(BA19>=BA18,BA19-BA18,0) -> 4396 | BC19: 656356 | BD19: =IF(BC19>=BC18,BC19-BC18,0) -> 243 | BE19: 48348 | BF19: =IF(BE19>=BE18,BE19-BE18,0) -> 108 | BG19: 26596553 | BH19: =IF(BG19>=BG18,BG19-BG18,0)-(0.45*BN19)-(0.45*BP19)-BR19 -> 5509.35 | BI19: =AP19+AR19+AT19+AV19+AX19+AZ19+BB19+BD19+BF19+BH19 -> 11339.475 | BJ19: =BI19+AN19 -> 15121.555 | BK19: 1511337 | BL19: =IF(BK19>=BK18,BK19-BK18,0) -> 198 | BM19: 4383625 | BN19: =IF(BM19>=BM18,BM19-BM18,0) -> 872 | BO19: 459283 | BP19: =IF(BO19>=BO18,BO19-BO18,0) -> 105 | BQ19: 572659 | BR19: =IF(BQ19>=BQ18,BQ19-BQ18,0) -> 123 | BS19: =J19+Q19+AN19+BI19 -> 23405.555 | BT19: 252 | BU19: =IF(BS19>0,BS19/BT18,0) -> 95.144533 | BW19: =IF(BS19>0,BS19/BV19,0) -> #DIV/0! | BX19: =((BS19-Q19)*$BZ$1)+(Q19*$BR$1) -> 27159.388 | BY19: =IF(BX19>0,BX19/BT18,0) -> 110.40402 | BZ19: =IF(BX19>0,BX19/BV19,0) -> #DIV/0!
A20: 15 | C20: =IF(+B20-B19>0,B20-B19,(B20-B19)>0)*800 -> 0 | E20: =IF(+D20-D19>0,D20-D19,(D20-D19)>0)*80 -> 0 | G20: =IF(+F20-F19>0,F20-F19,(F20-F19)>0)*10 -> 0 | H20: 63 | I20: 26099853 | J20: =IF(I20>=I19,I20-I19,0) -> 7113 | K20: =M20+O20 -> 4164 | L20: 443743 | M20: =IF(L20>=L19,L20-L19,0) -> 2511 | N20: 439994 | O20: =IF(N20>=N19,N20-N19,0) -> 1653 | P20: 228424 | Q20: =IF(P20>=P19,P20-P19,0)*30 -> 540 | R20: 237127 | S20: =IF(R20>=R19,R20-R19,0) -> 140 | T20: 432323 | U20: =IF(T20>=T19,T20-T19,0) -> 239 | V20: 941264 | W20: =IF(V20>=V19,V20-V19,0)*0.53 -> 1489.83 | X20: 839916 | Y20: =IF(X20>=X19,X20-X19,0)*0.53 -> 0 | Z20: 871835 | AA20: =IF(Z20>=Z19,Z20-Z19,0)*0.53 -> 0 | AB20: 184462 | AC20: =IF(AB20>=AB19,AB20-AB19,0)*0.53 -> 0 | AD20: 863702 | AE20: =IF(AD20>=AD19,AD20-AD19,0)*0.53 -> 12.19 | AF20: 1011299 | AG20: =IF(AF20>=AF19,AF20-AF19,0)*0.53 -> 11.66 | AH20: 449418 | AI20: =IF(AH20>=AH19,AH20-AH19,0)*0.53 -> 147.87 | AJ20: 827806 | AK20: =IF(AJ20>=AJ19,AJ20-AJ19,0)*0.53 -> 1896.34 | AL20: 584044 | AM20: =IF(AL20>=AL19,AL20-AL19,0)*0.53 -> 111.3 | AN20: =W20+Y20+AA20+AC20+AE20+AG20+AI20+AK20+AM20 -> 3669.19 | AO20: 8251266 | AP20: =IF(AO20>=AO19,AO20-AO19,0)*0.1125 -> 41.5125 | AQ20: 765217 | AR20: =IF(AQ20>=AQ19,AQ20-AQ19,0) -> 189 | AS20: 24972 | AT20: =IF(AS20>=AS19,AS20-AS19,0) -> 127 | AU20: 829109 | AV20: =IF(AU20>=AU19,AU20-AU19,0) -> 40 | AW20: 2942743 | AX20: =IF(AW20>=AW19,AW20-AW19,0) -> 649 | AY20: 241044 | AZ20: =IF(AY20>=AY19,AY20-AY19,0) -> 11 | BA20: 21164439 | BB20: =IF(BA20>=BA19,BA20-BA19,0) -> 5539 | BC20: 656556 | BD20: =IF(BC20>=BC19,BC20-BC19,0) -> 200 | BE20: 48393 | BF20: =IF(BE20>=BE19,BE20-BE19,0) -> 45 | BG20: 26602589 | BH20: =IF(BG20>=BG19,BG20-BG19,0)-(0.45*BN20)-(0.45*BP20)-BR20 -> 5438.85 | BI20: =AP20+AR20+AT20+AV20+AX20+AZ20+BB20+BD20+BF20+BH20 -> 12280.362 | BJ20: =BI20+AN20 -> 15949.552 | BK20: 1511580 | BL20: =IF(BK20>=BK19,BK20-BK19,0) -> 243 | BM20: 4384561 | BN20: =IF(BM20>=BM19,BM20-BM19,0) -> 936 | BO20: 459394 | BP20: =IF(BO20>=BO19,BO20-BO19,0) -> 111 | BQ20: 572785 | BR20: =IF(BQ20>=BQ19,BQ20-BQ19,0) -> 126 | BS20: =J20+Q20+AN20+BI20 -> 23602.552 | BT20: 196 | BU20: =IF(BS20>0,BS20/BT20,0) -> 120.42119 | BW20: =IF(BS20>0,BS20/BV20,0) -> #DIV/0! | BX20: =((BS20-Q20)*$BZ$1)+(Q20*$BR$1) -> 27385.935 | BY20: =IF(BX20>0,BX20/BT20,0) -> 139.72416 | BZ20: =IF(BX20>0,BX20/BV20,0) -> #DIV/0!
