Workbook

Sheet TOTAL
A1: Site Name | B1: Day | C1: Month | D1: Year | E1: Total Electricity Kwh | F1: Electricity Tariff ($/Kwh) | G1: LPG (Kg) | H1: LPG $/Kg | I1: Water Utility Supply (m3) m3 | J1: Water Utility Supply (m3) $/m3 | K1: Room Nights | N1: Water Tanks | O1: Cost of Water Tanks Rs | P1: Water Utility Supply (m3) Rs/m3 | Q1: Electricity Tariff (Rs/Kwh) | R1: LPG Rs/Kg | S1: Exchange Rate | T1: Total LPG Cost | U1: Total Water Cost
A2: Mauritius at Anahita | B2: 1 | C2: 1 | D2: 2023 | E2: =HOTEL!E4 -> 26115 | F2: 6.25 | G2: =HOTEL!CV4 -> 55250 | H2: 76.45 | I2: =HOTEL!Z4+HOTEL!AF4 -> 398 | J2: =P2 -> 34 | K2: =HOTEL!EP4 -> 0.766 | N2: =HOTEL!AD4 -> 0 | O2: =N2*4000 -> 0 | P2: =IFERROR(((((HOTEL!Z4*34))+(N2*2500))/(I2+N2*40)),0) -> 34 | Q2: 6.21 | R2: 67.25 | S2: 33.88 | T2: =G2*H2 -> 4223862.5 | U2: =I2*P2 -> 13532
A3: Mauritius at Anahita | B3: =B2+1 -> 2 | C3: 1 | D3: 2023 | E3: =HOTEL!E5 -> 28694 | F3: 6.25 | G3: =HOTEL!CV5 -> 55288 | H3: 76.45 | I3: =HOTEL!Z5+HOTEL!AF5 -> 411 | J3: =P3 -> 34 | K3: =HOTEL!EP5 -> 0.633 | N3: =HOTEL!AD5 -> 0 | O3: =N3*4000 -> 0 | P3: =IFERROR(((((HOTEL!Z5*34))+(N3*2500))/(I3+N3*40)),0) -> 34 | Q3: 6.21 | R3: 67.25 | S3: 33.88 | T3: =G3*H3 -> 4226767.6 | U3: =I3*P3 -> 13974
A4: Mauritius at Anahita | B4: =B3+1 -> 3 | C4: 1 | D4: 2023 | E4: =HOTEL!E6 -> 28493 | F4: 6.25 | G4: =HOTEL!CV6 -> 55325 | H4: 76.45 | I4: =HOTEL!Z6+HOTEL!AF6 -> 378 | J4: =P4 -> 34 | K4: =HOTEL!EP6 -> 0.81 | N4: =HOTEL!AD6 -> 0 | O4: =N4*4000 -> 0 | P4: =IFERROR(((((HOTEL!Z6*34))+(N4*2500))/(I4+N4*40)),0) -> 34 | Q4: 6.21 | R4: 67.25 | S4: 33.88 | T4: =G4*H4 -> 4229596.2 | U4: =I4*P4 -> 12852
A5: Mauritius at Anahita | B5: =B4+1 -> 4 | C5: 1 | D5: 2023 | E5: =HOTEL!E7 -> 25885 | F5: 6.25 | G5: =HOTEL!CV7 -> 55362 | H5: 76.45 | I5: =HOTEL!Z7+HOTEL!AF7 -> 440 | J5: =P5 -> 34 | K5: =HOTEL!EP7 -> 0.93 | N5: =HOTEL!AD7 -> 0 | O5: =N5*4000 -> 0 | P5: =IFERROR(((((HOTEL!Z7*34))+(N5*2500))/(I5+N5*40)),0) -> 34 | Q5: 6.21 | R5: 67.25 | S5: 33.88 | T5: =G5*H5 -> 4232424.9 | U5: =I5*P5 -> 14960
A6: Mauritius at Anahita | B6: =B5+1 -> 5 | C6: 1 | D6: 2023 | E6: =HOTEL!E8 -> 27430 | F6: 6.25 | G6: =HOTEL!CV8 -> 55396 | H6: 76.45 | I6: =HOTEL!Z8+HOTEL!AF8 -> 352 | J6: =P6 -> 34 | K6: =HOTEL!EP8 -> 0.95 | N6: =HOTEL!AD8 -> 0 | O6: =N6*4000 -> 0 | P6: =IFERROR(((((HOTEL!Z8*34))+(N6*2500))/(I6+N6*40)),0) -> 34 | Q6: 6.21 | R6: 67.25 | S6: 33.88 | T6: =G6*H6 -> 4235024.2 | U6: =I6*P6 -> 11968
A7: Mauritius at Anahita | B7: =B6+1 -> 6 | C7: 1 | D7: 2023 | E7: =HOTEL!E9 -> 23664 | F7: 6.25 | G7: =HOTEL!CV9 -> 55435 | H7: 76.45 | I7: =HOTEL!Z9+HOTEL!AF9 -> 368 | J7: =P7 -> 34 | K7: =HOTEL!EP9 -> 0.83 | N7: =HOTEL!AD9 -> 0 | O7: =N7*4000 -> 0 | P7: =IFERROR(((((HOTEL!Z9*34))+(N7*2500))/(I7+N7*40)),0) -> 34 | Q7: 6.21 | R7: 67.25 | S7: 33.88 | T7: =G7*H7 -> 4238005.8 | U7: =I7*P7 -> 12512
A8: Mauritius at Anahita | B8: =B7+1 -> 7 | C8: 1 | D8: 2023 | E8: =HOTEL!E10 -> 25687 | F8: 6.25 | G8: =HOTEL!CV10 -> 55475 | H8: 76.45 | I8: =HOTEL!Z10+HOTEL!AF10 -> 405 | J8: =P8 -> 34 | K8: =HOTEL!EP10 -> 0.85 | N8: =HOTEL!AD10 -> 0 | O8: =N8*4000 -> 0 | P8: =IFERROR(((((HOTEL!Z10*34))+(N8*2500))/(I8+N8*40)),0) -> 34 | Q8: 6.21 | R8: 67.25 | S8: 33.88 | T8: =G8*H8 -> 4241063.8 | U8: =I8*P8 -> 13770
A9: Mauritius at Anahita | B9: =B8+1 -> 8 | C9: 1 | D9: 2023 | E9: =HOTEL!E11 -> 27920 | F9: 6.25 | G9: =HOTEL!CV11 -> 55516 | H9: 76.45 | I9: =HOTEL!Z11+HOTEL!AF11 -> 400 | J9: =P9 -> 34 | K9: =HOTEL!EP11 -> 0.83 | N9: =HOTEL!AD11 -> 0 | O9: =N9*4000 -> 0 | P9: =IFERROR(((((HOTEL!Z11*34))+(N9*2500))/(I9+N9*40)),0) -> 34 | Q9: 6.21 | R9: 67.25 | S9: 33.88 | T9: =G9*H9 -> 4244198.2 | U9: =I9*P9 -> 13600
A10: Mauritius at Anahita | B10: =B9+1 -> 9 | C10: 1 | D10: 2023 | E10: =HOTEL!E12 -> 28121 | F10: 6.25 | G10: =HOTEL!CV12 -> 55562 | H10: 76.45 | I10: =HOTEL!Z12+HOTEL!AF12 -> 399 | J10: =P10 -> 34 | K10: =HOTEL!EP12 -> 0.72 | N10: =HOTEL!AD12 -> 0 | O10: =N10*4000 -> 0 | P10: =IFERROR(((((HOTEL!Z12*34))+(N10*2500))/(I10+N10*40)),0) -> 34 | Q10: 6.21 | R10: 67.25 | S10: 33.93 | T10: =G10*H10 -> 4247714.9 | U10: =I10*P10 -> 13566
A11: Mauritius at Anahita | B11: =B10+1 -> 10 | C11: 1 | D11: 2023 | E11: =HOTEL!E13 -> 24976 | F11: 6.25 | G11: =HOTEL!CV13 -> 55596 | H11: 76.45 | I11: =HOTEL!Z13+HOTEL!AF13 -> 372 | J11: =P11 -> 34 | K11: =HOTEL!EP13 -> 0.63 | N11: =HOTEL!AD13 -> 0 | O11: =N11*4000 -> 0 | P11: =IFERROR(((((HOTEL!Z13*34))+(N11*2500))/(I11+N11*40)),0) -> 34 | Q11: 6.21 | R11: 67.25 | S11: 33.93 | T11: =G11*H11 -> 4250314.2 | U11: =I11*P11 -> 12648
A12: Mauritius at Anahita | B12: =B11+1 -> 11 | C12: 1 | D12: 2023 | E12: =HOTEL!E14 -> 27584 | F12: 6.25 | G12: =HOTEL!CV14 -> 55637 | H12: 76.45 | I12: =HOTEL!Z14+HOTEL!AF14 -> 259 | J12: =P12 -> 34 | K12: =HOTEL!EP14 -> 0.61 | N12: =HOTEL!AD14 -> 0 | O12: =N12*4000 -> 0 | P12: =IFERROR(((((HOTEL!Z14*34))+(N12*2500))/(I12+N12*40)),0) -> 34 | Q12: 6.21 | R12: 67.25 | S12: 33.93 | T12: =G12*H12 -> 4253448.7 | U12: =I12*P12 -> 8806
A13: Mauritius at Anahita | B13: =B12+1 -> 12 | C13: 1 | D13: 2023 | E13: =HOTEL!E15 -> 28151 | F13: 6.25 | G13: =HOTEL!CV15 -> 55670 | H13: 76.45 | I13: =HOTEL!Z15+HOTEL!AF15 -> 581 | J13: =P13 -> 35.075452 | K13: =HOTEL!EP15 -> 0.8 | N13: =HOTEL!AD15 -> 9 | O13: =N13*4000 -> 36000 | P13: =IFERROR(((((HOTEL!Z15*34))+(N13*2500))/(I13+N13*40)),0) -> 35.075452 | Q13: 6.21 | R13: 67.25 | S13: 33.93 | T13: =G13*H13 -> 4255971.5 | U13: =I13*P13 -> 20378.837
A14: Mauritius at Anahita | B14: =B13+1 -> 13 | C14: 1 | D14: 2023 | E14: =HOTEL!E16 -> 26038 | F14: 6.25 | G14: =HOTEL!CV16 -> 55708 | H14: 76.45 | I14: =HOTEL!Z16+HOTEL!AF16 -> 450 | J14: =P14 -> 21.457778 | K14: =HOTEL!EP16 -> 0.82 | N14: =HOTEL!AD16 -> 0 | O14: =N14*4000 -> 0 | P14: =IFERROR(((((HOTEL!Z16*34))+(N14*2500))/(I14+N14*40)),0) -> 21.457778 | Q14: 6.21 | R14: 67.25 | S14: 33.93 | T14: =G14*H14 -> 4258876.6 | U14: =I14*P14 -> 9656
... A32: Mauritius at Anahita | B32: =B31+1 -> 31 | C32: 1 | D32: 2023 | E32: =HOTEL!E34 -> 0 | F32: 6.25 | G32: =HOTEL!CV34 -> 0 | H32: 76.45 | I32: =HOTEL!Z34+HOTEL!AF34 -> 67 | J32: =P32 -> 34.013605 | K32: =HOTEL!EP34 -> 0.77 | N32: =HOTEL!AD34 -> 2 | O32: =N32*4000 -> 8000 | P32: =IFERROR(((((HOTEL!Z34*34))+(N32*2500))/(I32+N32*40)),0) -> 34.013605 | Q32: 6.21 | R32: 67.25 | S32: 35.93 | T32: =G32*H32 -> 0 | U32: =I32*P32 -> 2278.9116

Sheet Submetering
A1: Site Name | B1: Day | C1: Month | D1: Year | E1: Hotel (KWh) | F1: Vacoas (KWh) | G1: Laundry (KWh) | H1: Villa 145 (KWh) | I1: Villa 146 (KWh) | J1: Villa 111 (KWh) | K1: Villa 128 (KWh) | L1: Hotel (m3) | M1: Bamboo Pool (m3) | N1: Island (m3) | O1: Main Building (m3) | P1: Pantry A (m3) | Q1: Pantry B (m3) | R1: Pantry C (m3) | S1: Pantry D (m3) | T1: Pantry E (m3) | U1: Pantry F (m3) | V1: Pantry G (m3) | W1: North Parcel (m3) | X1: South Parcel (m3) | Y1: Beau champ (Kg) | Z1: Acquapazza (Kg) | AA1: Bamboo (Kg) | AB1: Steam Boiler (Kg) | AC1: Laundry (Kg) | AD1: Pantry A (Kg) | AE1: Pantry B (Kg) | AF1: Pantry C (Kg) | AG1: Pantry D (Kg) | AH1: Pantry E (Kg) | AI1: Pantry F (Kg) | AJ1: Pantry G (Kg) | AK1: Room Nights
A2: Mauritius at Anahita | B2: =TOTAL!B2 -> 1 | C2: 3 | D2: 2023 | E2: =TOTAL!E2 -> 26115 | F2: =HOTEL!V4 -> 598 | G2: =HOTEL!X4 -> 480 | H2: =HOTEL!EI4 -> 0 | I2: =HOTEL!EK4 -> 0 | J2: =HOTEL!EM4 -> 0 | K2: =HOTEL!EO4 -> 171 | L2: =N2+W2+X2 -> 78 | M2: =HOTEL!AL4 -> 7 | N2: =HOTEL!AT4 -> 28 | O2: =HOTEL!AX4 -> 2 | P2: =HOTEL!AZ4 -> 2 | Q2: =HOTEL!BB4 -> 8 | R2: =HOTEL!BD4 -> 3 | S2: =HOTEL!BF4 -> 2 | T2: =HOTEL!BH4 -> 3 | U2: =HOTEL!BJ4 -> 1 | V2: =HOTEL!BL4 -> 4 | W2: =HOTEL!BX4 -> 0 | X2: =HOTEL!CE4 -> 50 | Y2: =HOTEL!CZ4 -> 3 | Z2: =HOTEL!DC3 -> 11 | AA2: =HOTEL!DF4 -> 89 | AB2: =HOTEL!DI4 -> 10 | AC2: =HOTEL!DL4 -> 7 | AD2: =HOTEL!DO4 -> 6 | AE2: =HOTEL!DR4 -> 1 | AF2: =HOTEL!DU4 -> 9 | AG2: =HOTEL!DX4 -> 6 | AH2: =HOTEL!EA4 -> 7 | AI2: =HOTEL!ED4 -> 9 | AJ2: =HOTEL!EG4 -> 0 | AK2: =TOTAL!K2 -> 0.766
A3: Mauritius at Anahita | B3: =TOTAL!B3 -> 2 | C3: 3 | D3: 2023 | E3: =TOTAL!E3 -> 28694 | F3: =HOTEL!V5 -> 621 | G3: =HOTEL!X5 -> 539 | H3: =HOTEL!EI5 -> 0 | I3: =HOTEL!EK5 -> 0 | J3: =HOTEL!EM5 -> 0 | K3: =HOTEL!EO5 -> 114 | L3: =N3+W3+X3 -> 86 | M3: =HOTEL!AL5 -> 14 | N3: =HOTEL!AT5 -> 24 | O3: =HOTEL!AX5 -> 2 | P3: =HOTEL!AZ5 -> 3 | Q3: =HOTEL!BB5 -> 9 | R3: =HOTEL!BD5 -> 4 | S3: =HOTEL!BF5 -> 2 | T3: =HOTEL!BH5 -> 2 | U3: =HOTEL!BJ5 -> 1 | V3: =HOTEL!BL5 -> 4 | W3: =HOTEL!BX5 -> 0 | X3: =HOTEL!CE5 -> 62 | Y3: =HOTEL!CZ5 -> 3 | Z3: =HOTEL!DC4 -> 12 | AA3: =HOTEL!DF5 -> 104 | AB3: =HOTEL!DI5 -> 15 | AC3: =HOTEL!DL5 -> 8 | AD3: =HOTEL!DO5 -> 6 | AE3: =HOTEL!DR5 -> 2 | AF3: =HOTEL!DU5 -> 10 | AG3: =HOTEL!DX5 -> 7 | AH3: =HOTEL!EA5 -> 9 | AI3: =HOTEL!ED5 -> 10 | AJ3: =HOTEL!EG5 -> 0 | AK3: =TOTAL!K3 -> 0.633
A4: Mauritius at Anahita | B4: =TOTAL!B4 -> 3 | C4: 3 | D4: 2023 | E4: =TOTAL!E4 -> 28493 | F4: =HOTEL!V6 -> 943 | G4: =HOTEL!X6 -> 455 | H4: =HOTEL!EI6 -> 0 | I4: =HOTEL!EK6 -> 0 | J4: =HOTEL!EM6 -> 0 | K4: =HOTEL!EO6 -> 218 | L4: =N4+W4+X4 -> 67 | M4: =HOTEL!AL6 -> 7 | N4: =HOTEL!AT6 -> 22 | O4: =HOTEL!AX6 -> 1 | P4: =HOTEL!AZ6 -> 0 | Q4: =HOTEL!BB6 -> 8 | R4: =HOTEL!BD6 -> 3 | S4: =HOTEL!BF6 -> 2 | T4: =HOTEL!BH6 -> 3 | U4: =HOTEL!BJ6 -> 1 | V4: =HOTEL!BL6 -> 2 | W4: =HOTEL!BX6 -> 0 | X4: =HOTEL!CE6 -> 45 | Y4: =HOTEL!CZ6 -> 2 | Z4: =HOTEL!DC5 -> 14 | AA4: =HOTEL!DF6 -> 81 | AB4: =HOTEL!DI6 -> 9 | AC4: =HOTEL!DL6 -> 13 | AD4: =HOTEL!DO6 -> 6 | AE4: =HOTEL!DR6 -> 2 | AF4: =HOTEL!DU6 -> 9 | AG4: =HOTEL!DX6 -> 7 | AH4: =HOTEL!EA6 -> 8 | AI4: =HOTEL!ED6 -> 10 | AJ4: =HOTEL!EG6 -> 0 | AK4: =TOTAL!K4 -> 0.81
A5: Mauritius at Anahita | B5: =TOTAL!B5 -> 4 | C5: 3 | D5: 2023 | E5: =TOTAL!E5 -> 25885 | F5: =HOTEL!V7 -> 654 | G5: =HOTEL!X7 -> 499 | H5: =HOTEL!EI7 -> 0 | I5: =HOTEL!EK7 -> 0 | J5: =HOTEL!EM7 -> 0 | K5: =HOTEL!EO7 -> 262 | L5: =N5+W5+X5 -> 80 | M5: =HOTEL!AL7 -> 8 | N5: =HOTEL!AT7 -> 22 | O5: =HOTEL!AX7 -> 3 | P5: =HOTEL!AZ7 -> 2 | Q5: =HOTEL!BB7 -> 8 | R5: =HOTEL!BD7 -> 5 | S5: =HOTEL!BF7 -> 2 | T5: =HOTEL!BH7 -> 3 | U5: =HOTEL!BJ7 -> 2 | V5: =HOTEL!BL7 -> 4 | W5: =HOTEL!BX7 -> 0 | X5: =HOTEL!CE7 -> 58 | Y5: =HOTEL!CZ7 -> 3 | Z5: =HOTEL!DC6 -> 12 | AA5: =HOTEL!DF7 -> 93 | AB5: =HOTEL!DI7 -> 11 | AC5: =HOTEL!DL7 -> 1 | AD5: =HOTEL!DO7 -> 6 | AE5: =HOTEL!DR7 -> 1 | AF5: =HOTEL!DU7 -> 8 | AG5: =HOTEL!DX7 -> 4 | AH5: =HOTEL!EA7 -> 7 | AI5: =HOTEL!ED7 -> 9 | AJ5: =HOTEL!EG7 -> 0 | AK5: =TOTAL!K5 -> 0.93
A6: Mauritius at Anahita | B6: =TOTAL!B6 -> 5 | C6: 3 | D6: 2023 | E6: =TOTAL!E6 -> 27430 | F6: =HOTEL!V8 -> 1030 | G6: =HOTEL!X8 -> 569 | H6: =HOTEL!EI8 -> 0 | I6: =HOTEL!EK8 -> 0 | J6: =HOTEL!EM8 -> 0 | K6: =HOTEL!EO8 -> 261 | L6: =N6+W6+X6 -> 98 | M6: =HOTEL!AL8 -> 0 | N6: =HOTEL!AT8 -> 27 | O6: =HOTEL!AX8 -> 3 | P6: =HOTEL!AZ8 -> 2 | Q6: =HOTEL!BB8 -> 5 | R6: =HOTEL!BD8 -> 6 | S6: =HOTEL!BF8 -> 3 | T6: =HOTEL!BH8 -> 3 | U6: =HOTEL!BJ8 -> 0 | V6: =HOTEL!BL8 -> 2 | W6: =HOTEL!BX8 -> 0 | X6: =HOTEL!CE8 -> 71 | Y6: =HOTEL!CZ8 -> 0 | Z6: =HOTEL!DC7 -> 17 | AA6: =HOTEL!DF8 -> 97 | AB6: =HOTEL!DI8 -> 17 | AC6: =HOTEL!DL8 -> 1 | AD6: =HOTEL!DO8 -> 4 | AE6: =HOTEL!DR8 -> 1 | AF6: =HOTEL!DU8 -> 10 | AG6: =HOTEL!DX8 -> 7 | AH6: =HOTEL!EA8 -> 8 | AI6: =HOTEL!ED8 -> 9 | AJ6: =HOTEL!EG8 -> 0 | AK6: =TOTAL!K6 -> 0.95
A7: Mauritius at Anahita | B7: =TOTAL!B7 -> 6 | C7: 3 | D7: 2023 | E7: =TOTAL!E7 -> 23664 | F7: =HOTEL!V9 -> 590 | G7: =HOTEL!X9 -> 541 | H7: =HOTEL!EI9 -> 0 | I7: =HOTEL!EK9 -> 0 | J7: =HOTEL!EM9 -> 0 | K7: =HOTEL!EO9 -> 247 | L7: =N7+W7+X7 -> 85 | M7: =HOTEL!AL9 -> 0 | N7: =HOTEL!AT9 -> 34 | O7: =HOTEL!AX9 -> 4 | P7: =HOTEL!AZ9 -> 1 | Q7: =HOTEL!BB9 -> 7 | R7: =HOTEL!BD9 -> 4 | S7: =HOTEL!BF9 -> 2 | T7: =HOTEL!BH9 -> 4 | U7: =HOTEL!BJ9 -> 1 | V7: =HOTEL!BL9 -> 5 | W7: =HOTEL!BX9 -> 0 | X7: =HOTEL!CE9 -> 51 | Y7: =HOTEL!CZ9 -> 0 | Z7: =HOTEL!DC8 -> 14 | AA7: =HOTEL!DF9 -> 71 | AB7: =HOTEL!DI9 -> 9 | AC7: =HOTEL!DL9 -> 4 | AD7: =HOTEL!DO9 -> 7 | AE7: =HOTEL!DR9 -> 2 | AF7: =HOTEL!DU9 -> 11 | AG7: =HOTEL!DX9 -> 7 | AH7: =HOTEL!EA9 -> 8 | AI7: =HOTEL!ED9 -> 10 | AJ7: =HOTEL!EG9 -> 0 | AK7: =TOTAL!K7 -> 0.83
A8: Mauritius at Anahita | B8: =TOTAL!B8 -> 7 | C8: 3 | D8: 2023 | E8: =TOTAL!E8 -> 25687 | F8: =HOTEL!V10 -> 656 | G8: =HOTEL!X10 -> 529 | H8: =HOTEL!EI10 -> 0 | I8: =HOTEL!EK10 -> 0 | J8: =HOTEL!EM10 -> 0 | K8: =HOTEL!EO10 -> 242 | L8: =N8+W8+X8 -> 81 | M8: =HOTEL!AL10 -> 13 | N8: =HOTEL!AT10 -> 24 | O8: =HOTEL!AX10 -> 2 | P8: =HOTEL!AZ10 -> 1 | Q8: =HOTEL!BB10 -> 6 | R8: =HOTEL!BD10 -> 3 | S8: =HOTEL!BF10 -> 2 | T8: =HOTEL!BH10 -> 4 | U8: =HOTEL!BJ10 -> 2 | V8: =HOTEL!BL10 -> 3 | W8: =HOTEL!BX10 -> 0 | X8: =HOTEL!CE10 -> 57 | Y8: =HOTEL!CZ10 -> 3 | Z8: =HOTEL!DC9 -> 14 | AA8: =HOTEL!DF10 -> 70 | AB8: =HOTEL!DI10 -> 12 | AC8: =HOTEL!DL10 -> 7 | AD8: =HOTEL!DO10 -> 6 | AE8: =HOTEL!DR10 -> 1 | AF8: =HOTEL!DU10 -> 8 | AG8: =HOTEL!DX10 -> 6 | AH8: =HOTEL!EA10 -> 9 | AI8: =HOTEL!ED10 -> 11 | AJ8: =HOTEL!EG10 -> 0 | AK8: =TOTAL!K8 -> 0.85
A9: Mauritius at Anahita | B9: =TOTAL!B9 -> 8 | C9: 3 | D9: 2023 | E9: =TOTAL!E9 -> 27920 | F9: =HOTEL!V11 -> 835 | G9: =HOTEL!X11 -> 590 | H9: =HOTEL!EI11 -> 0 | I9: =HOTEL!EK11 -> 0 | J9: =HOTEL!EM11 -> 0 | K9: =HOTEL!EO11 -> 250 | L9: =N9+W9+X9 -> 102 | M9: =HOTEL!AL11 -> 7 | N9: =HOTEL!AT11 -> 12 | O9: =HOTEL!AX11 -> 3 | P9: =HOTEL!AZ11 -> 2 | Q9: =HOTEL!BB11 -> 8 | R9: =HOTEL!BD11 -> 4 | S9: =HOTEL!BF11 -> 3 | T9: =HOTEL!BH11 -> 5 | U9: =HOTEL!BJ11 -> 1 | V9: =HOTEL!BL11 -> 4 | W9: =HOTEL!BX11 -> 0 | X9: =HOTEL!CE11 -> 90 | Y9: =HOTEL!CZ11 -> 5 | Z9: =HOTEL!DC10 -> 13 | AA9: =HOTEL!DF11 -> 84 | AB9: =HOTEL!DI11 -> 19 | AC9: =HOTEL!DL11 -> 7 | AD9: =HOTEL!DO11 -> 7 | AE9: =HOTEL!DR11 -> 2 | AF9: =HOTEL!DU11 -> 9 | AG9: =HOTEL!DX11 -> 6 | AH9: =HOTEL!EA11 -> 8 | AI9: =HOTEL!ED11 -> 10 | AJ9: =HOTEL!EG11 -> 0 | AK9: =TOTAL!K9 -> 0.83
A10: Mauritius at Anahita | B10: =TOTAL!B10 -> 9 | C10: 3 | D10: 2023 | E10: =TOTAL!E10 -> 28121 | F10: =HOTEL!V12 -> 1106 | G10: =HOTEL!X12 -> 518 | H10: =HOTEL!EI12 -> 0 | I10: =HOTEL!EK12 -> 0 | J10: =HOTEL!EM12 -> 0 | K10: =HOTEL!EO12 -> 209 | L10: =N10+W10+X10 -> 78 | M10: =HOTEL!AL12 -> 6 | N10: =HOTEL!AT12 -> 12 | O10: =HOTEL!AX12 -> 2 | P10: =HOTEL!AZ12 -> 2 | Q10: =HOTEL!BB12 -> 9 | R10: =HOTEL!BD12 -> 5 | S10: =HOTEL!BF12 -> 2 | T10: =HOTEL!BH12 -> 3 | U10: =HOTEL!BJ12 -> 1 | V10: =HOTEL!BL12 -> 4 | W10: =HOTEL!BX12 -> 0 | X10: =HOTEL!CE12 -> 66 | Y10: =HOTEL!CZ12 -> 4 | Z10: =HOTEL!DC11 -> 17 | AA10: =HOTEL!DF12 -> 74 | AB10: =HOTEL!DI12 -> 13 | AC10: =HOTEL!DL12 -> 7 | AD10: =HOTEL!DO12 -> 6 | AE10: =HOTEL!DR12 -> 1 | AF10: =HOTEL!DU12 -> 11 | AG10: =HOTEL!DX12 -> 8 | AH10: =HOTEL!EA12 -> 9 | AI10: =HOTEL!ED12 -> 11 | AJ10: =HOTEL!EG12 -> 0 | AK10: =TOTAL!K10 -> 0.72
A11: Mauritius at Anahita | B11: =TOTAL!B11 -> 10 | C11: 3 | D11: 2023 | E11: =TOTAL!E11 -> 24976 | F11: =HOTEL!V13 -> 1668 | G11: =HOTEL!X13 -> 511 | H11: =HOTEL!EI13 -> 0 | I11: =HOTEL!EK13 -> 0 | J11: =HOTEL!EM13 -> 0 | K11: =HOTEL!EO13 -> 172 | L11: =N11+W11+X11 -> 96 | M11: =HOTEL!AL13 -> 0 | N11: =HOTEL!AT13 -> 27 | O11: =HOTEL!AX13 -> 3 | P11: =HOTEL!AZ13 -> 1 | Q11: =HOTEL!BB13 -> 6 | R11: =HOTEL!BD13 -> 2 | S11: =HOTEL!BF13 -> 2 | T11: =HOTEL!BH13 -> 5 | U11: =HOTEL!BJ13 -> 1 | V11: =HOTEL!BL13 -> 2 | W11: =HOTEL!BX13 -> 0 | X11: =HOTEL!CE13 -> 69 | Y11: =HOTEL!CZ13 -> 3 | Z11: =HOTEL!DC12 -> 16 | AA11: =HOTEL!DF13 -> 77 | AB11: =HOTEL!DI13 -> 10 | AC11: =HOTEL!DL13 -> 7 | AD11: =HOTEL!DO13 -> 6 | AE11: =HOTEL!DR13 -> 2 | AF11: =HOTEL!DU13 -> 10 | AG11: =HOTEL!DX13 -> 7 | AH11: =HOTEL!EA13 -> 8 | AI11: =HOTEL!ED13 -> 10 | AJ11: =HOTEL!EG13 -> 0 | AK11: =TOTAL!K11 -> 0.63
A12: Mauritius at Anahita | B12: =TOTAL!B12 -> 11 | C12: 3 | D12: 2023 | E12: =TOTAL!E12 -> 27584 | F12: =HOTEL!V14 -> 1132 | G12: =HOTEL!X14 -> 555 | H12: =HOTEL!EI14 -> 0 | I12: =HOTEL!EK14 -> 0 | J12: =HOTEL!EM14 -> 0 | K12: =HOTEL!EO14 -> 165 | L12: =N12+W12+X12 -> 89 | M12: =HOTEL!AL14 -> 6 | N12: =HOTEL!AT14 -> 21 | O12: =HOTEL!AX14 -> 2 | P12: =HOTEL!AZ14 -> 2 | Q12: =HOTEL!BB14 -> 9 | R12: =HOTEL!BD14 -> 3 | S12: =HOTEL!BF14 -> 1 | T12: =HOTEL!BH14 -> 5 | U12: =HOTEL!BJ14 -> 1 | V12: =HOTEL!BL14 -> 3 | W12: =HOTEL!BX14 -> 0 | X12: =HOTEL!CE14 -> 68 | Y12: =HOTEL!CZ14 -> 2 | Z12: =HOTEL!DC13 -> 16 | AA12: =HOTEL!DF14 -> 139 | AB12: =HOTEL!DI14 -> 14 | AC12: =HOTEL!DL14 -> 6 | AD12: =HOTEL!DO14 -> 6 | AE12: =HOTEL!DR14 -> 1 | AF12: =HOTEL!DU14 -> 7 | AG12: =HOTEL!DX14 -> 5 | AH12: =HOTEL!EA14 -> 9 | AI12: =HOTEL!ED14 -> 10 | AJ12: =HOTEL!EG14 -> 0 | AK12: =TOTAL!K12 -> 0.61
A13: Mauritius at Anahita | B13: =TOTAL!B13 -> 12 | C13: 3 | D13: 2023 | E13: =TOTAL!E13 -> 28151 | F13: =HOTEL!V15 -> 700 | G13: =HOTEL!X15 -> 565 | H13: =HOTEL!EI15 -> 0 | I13: =HOTEL!EK15 -> 0 | J13: =HOTEL!EM15 -> 0 | K13: =HOTEL!EO15 -> 228 | L13: =N13+W13+X13 -> 103 | M13: =HOTEL!AL15 -> 14 | N13: =HOTEL!AT15 -> 32 | O13: =HOTEL!AX15 -> 2 | P13: =HOTEL!AZ15 -> 2 | Q13: =HOTEL!BB15 -> 6 | R13: =HOTEL!BD15 -> 4 | S13: =HOTEL!BF15 -> 2 | T13: =HOTEL!BH15 -> 5 | U13: =HOTEL!BJ15 -> 1 | V13: =HOTEL!BL15 -> 0 | W13: =HOTEL!BX15 -> 0 | X13: =HOTEL!CE15 -> 71 | Y13: =HOTEL!CZ15 -> 0 | Z13: =HOTEL!DC14 -> 14 | AA13: =HOTEL!DF15 -> 32 | AB13: =HOTEL!DI15 -> 14 | AC13: =HOTEL!DL15 -> 7 | AD13: =HOTEL!DO15 -> 8 | AE13: =HOTEL!DR15 -> 2 | AF13: =HOTEL!DU15 -> 11 | AG13: =HOTEL!DX15 -> 7 | AH13: =HOTEL!EA15 -> 9 | AI13: =HOTEL!ED15 -> 11 | AJ13: =HOTEL!EG15 -> 0 | AK13: =TOTAL!K13 -> 0.8
... A32: Mauritius at Anahita | B32: =TOTAL!B32 -> 31 | C32: 3 | D32: 2023 | E32: =TOTAL!E32 -> 0 | F32: =HOTEL!V34 -> 0 | G32: =HOTEL!X34 -> 0 | H32: =HOTEL!EI34 -> 0 | I32: =HOTEL!EK34 -> 0 | J32: =HOTEL!EM34 -> 0 | K32: =HOTEL!EO34 -> 163 | L32: =N32+W32+X32 -> 0 | M32: =HOTEL!AL34 -> 0 | N32: =HOTEL!AT34 -> 0 | O32: =HOTEL!AX34 -> 0 | P32: =HOTEL!AZ34 -> 0 | Q32: =HOTEL!BB34 -> 0 | R32: =HOTEL!BD34 -> 0 | S32: =HOTEL!BF34 -> 0 | T32: =HOTEL!BH34 -> 0 | U32: =HOTEL!BJ34 -> 0 | V32: =HOTEL!BL34 -> 0 | W32: =HOTEL!BX34 -> 0 | X32: =HOTEL!CE34 -> 0 | Y32: =HOTEL!CZ34 -> 0 | Z32: =HOTEL!DC33 -> 0 | AA32: =HOTEL!DF34 -> 0 | AB32: =HOTEL!DI34 -> 0 | AC32: =HOTEL!DL34 -> 0 | AD32: =HOTEL!DO34 -> 0 | AE32: =HOTEL!DR34 -> 0 | AF32: =HOTEL!DU34 -> 0 | AG32: =HOTEL!DX34 -> 0 | AH32: =HOTEL!EA34 -> 0 | AI32: =HOTEL!ED34 -> 0 | AJ32: =HOTEL!EG34 -> 0 | AK32: =TOTAL!K32 -> 0.77

Sheet HOTEL
B1: Hotel Electricity | I1: Gen 01 | M1: Gen 02 | Q1: MB & Island | R1: CONS | S1: North & South | T1: CONS | U1: Vacoas KW | V1: CONS | W1: Laundry (KWh) | X1: CONS | Y1: Hotel | AB1: % Water Available | AC1: Water reservoir, 400 m3 | AD1: Water truck trip | AI1: Water Softener | AK1: bamboo pool | AM1: CWA (FS) | AN1: CONS | AP1: CONS | AQ1: Island | AS1: Island Sub | AU1: Main Building | AW1: Pantry A | AY1: Pantry B | BA1: Pantry C | BC1: Pantry D | BE1: Pantry E | BG1: Pantry F | BI1: Pantry G | BU1: North | BW1: North Sub | BY1: South | CA1: South Sub | CF1: Diesel | CJ1: Gas | DE1: Steam Boiler( Laundry) | DH1: Main Building ( boiler) | DK1: Pantry A | DN1: Pantry B | DQ1: Pantry C | DT1: Pantry D | DW1: Pantry E | DZ1: Pantry F | EC1: Pantry G | EQ1: Pool Temperature | ET1: BEVERAGE STORE
A2: Date | B2: KVAH | C2: CONS | D2: KWH | E2: CONS | F2: PF | G2: KVA | H2: KVA max | I2: KWH | J2: CONS | K2: Hrs | L2: CONS | M2: KWH | N2: CONS | O2: Hrs | P2: CONS | Q2: KWH | R2: CONS | S2: KWH | T2: CONS | U2: KWH | V2: CONS | W2: KWH | X2: CONS | Y2: CWA23 | Z2: CONS | AE2: Truck Meter | AF2: Cons | AG2: UV reading | AI2: chiller | AJ2: CONS | AL2: CONS | AQ2: island | AR2: cons | AU2: M.Buil | AV2: Cons | AW2: Pantry A | AX2: Cons | AY2: Pantry B | AZ2: Cons | BA2: Pantry C | BB2: cons | BC2: Pantry D | BD2: cons | BE2: Pantry E | BF2: cons | BG2: Pantry F | BH2: cons | BI2: Pantry G | BJ2: Cons | BK2: Main Kitchen | BL2: Cons | BM2: Bamboo CW | BN2: Cons | BO2: Bamboo HW | BP2: Cons | BQ2: cyclon bridge | BR2: cons | BS2: Island - Hot | BT2: Island Cold | BU2: north | BV2: cons | BY2: south | BZ2: cons | CC2: south | CD2: Total water consump | CE2: Total HW consump | CF2: DIESEL( cm) | CG2: stock | CH2: Del | CI2: CONS | CJ2: Meter | CK2: cons | CL2: Kg | CM2: LPG 1 | CN2: stock | CO2: LPG 2 | CP2: stock | CQ2: LPG 3 | CR2: stock | CS2: total stock | CT2: cons | CU2: del | CV2: Beau champ ( Main kit) | CW2: cons(Litres) | CX2: Cons(Kg) | CY2: Acquapazza | CZ2: cons(Litres) | DA2: Cons(Kg) | DB2: Bamboo | DC2: cons(Litres) | DD2: Cons(Kg) | DF2: cons(Litres) | DG2: Cons(Kg) | DI2: cons(Litres) | DJ2: Cons(Kg) | DL2: cons(Litres) | DM2: Cons(Kg) | DO2: cons(Litres) | DP2: Cons(Kg) | DR2: cons(Litres) | DS2: Cons(Kg) | DU2: cons(Litres) | DV2: Cons(Kg) | DX2: cons(Litres) | DY2: Cons(Kg) | EA2: cons(Litres) | EB2: Cons(Kg) | ED2: cons(Litres) | EE2: Cons(Kg) | EF2: 145 | EG2: CONS | EH2: 146 | EI2: CONS | EJ2: Villa 111 | EK2: CONS | EL2: Villa 128 | EM2: CONS | EN2: Room Nights | EO2: Bed Nights | EP2: % OCC | EQ2: California | ER2: Infiniti | ES2: Fitness | ET2: 0.75 | EU2: 0 | EV2: 0.25
A3: 44985 | B3: 9862912 | C3: 23536 | D3: 8708003 | E3: 23191 | F3: 0.99 | G3: 1324 | H3: 1278 | I3: 296394 | J3: 0 | K3: 822 | L3: 0 | M3: 652202 | N3: 0 | O3: 1052 | P3: 0 | Q3: 5825600 | R3: 15200 | S3: 5282600 | T3: 15200 | U3: 3183406 | V3: 736 | W3: 2439424 | X3: 543 | Y3: 14953 | Z3: 368 | AB3: 0.92 | AC3: 367 | AD3: 2 | AE3: 3556 | AF3: 67 | AG3: 643820 | AH3: 400 | AI3: 91 | AJ3: 0 | AK3: 7262 | AL3: 7 | AM3: 115993 | AN3: 310 | AP3: 0 | AQ3: 682890 | AR3: 160 | AS3: 12659 | AT3: 25 | AU3: 2963 | AV3: 26 | AW3: 9834 | AX3: 1 | AY3: 11720 | AZ3: 1 | BA3: 21947 | BB3: 7 | BC3: 22595 | BD3: 1 | BE3: 261 | BF3: 2 | BG3: 15568 | BH3: 3 | BI3: 7122 | BJ3: 0 | BK3: 29490 | BL3: 3 | BM3: 7015 | BN3: 3 | BO3: 46242 | BP3: 49 | BQ3: 3641 | BR3: 0 | BS3: 10 | BT3: 150 | BU3: 694470 | BV3: 120 | BY3: 900070 | BZ3: 260 | CC3: 100 | CD3: 380 | CE3: 42 | CF3: 161 | CG3: 21035.52 | CI3: 0 | CJ3: 3179378 | CK3: 1984 | CL3: 11328.64 | CM3: 41 | CN3: 4418 | CO3: 84 | CP3: 9051 | CQ3: 54 | CR3: 5819 | CS3: 19287 | CT3: 1078 | CV3: 55217 | CW3: 40 | CX3: 228.4 | CY3: 36941 | CZ3: 3 | DA3: 17.13 | DB3: 18491 | DC3: 11 | DD3: 62.81 | DE3: 878924 | DF3: 109 | DG3: 622.39 | DH3: 14287 | DI3: 11 | DJ3: 62.81 | DK3: 12992 | DL3: 12 | DM3: 68.52 | DN3: 8137 | DO3: 6 | DP3: 34.26 | DQ3: 2654 | DR3: 2 | DS3: 11.42 | DT3: 10465 | DU3: 8 | DV3: 45.68 | DW3: 9123 | DX3: 5 | DY3: 28.55 | DZ3: 9843 | EA3: 8 | EB3: 45.68 | EC3: 10055 | ED3: 10 | EE3: 57.1 | EG3: 0 | EI3: 0 | EK3: 0 | EM3: 0 | EN3: 50 | EO3: 114 | EP3: 0.594
A4: 44986 | B4: 9889974 | C4: 27062 | D4: 8734118 | E4: 26115 | F4: 0.97 | G4: 1324 | H4: 1278 | I4: 296394 | J4: 0 | K4: 822 | L4: 0 | M4: 652202 | N4: 0 | O4: 1052 | P4: 0 | Q4: 5839900 | R4: 14300 | S4: 5294100 | T4: 11500 | U4: 3184004 | V4: 598 | W4: 2439904 | X4: 480 | Y4: 15351 | Z4: 398 | AB4: 0.92 | AC4: 367 | AD4: 0 | AE4: 3556 | AF4: 0 | AG4: 644180 | AH4: 360 | AI4: 91 | AJ4: 0 | AK4: 7269 | AL4: 7 | AM4: 116293 | AN4: 300 | AP4: 0 | AQ4: 683060 | AR4: 170 | AS4: 12687 | AT4: 28 | AU4: 2990 | AV4: 27 | AW4: 9836 | AX4: 2 | AY4: 11722 | AZ4: 2 | BA4: 21955 | BB4: 8 | BC4: 22598 | BD4: 3 | BE4: 263 | BF4: 2 | BG4: 15571 | BH4: 3 | BI4: 7123 | BJ4: 1 | BK4: 29494 | BL4: 4 | BM4: 7017 | BN4: 2 | BO4: 46292 | BP4: 50 | BQ4: 3641 | BR4: 0 | BS4: 13 | BT4: 157 | BU4: 694580 | BV4: 110 | BY4: 900320 | BZ4: 250 | CC4: 80 | CD4: 360 | CE4: 50 | CF4: 161 | CG4: 21035.52 | CI4: 0 | CJ4: 3180830 | CK4: 1452 | CL4: 8290.92 | CM4: 39 | CN4: 4202 | CO4: 85 | CP4: 9159 | CQ4: 54 | CR4: 5819 | CS4: 19180 | CT4: 108 | CV4: 55250 | CW4: 33 | CX4: 188.43 | CY4: 36944 | CZ4: 3 | DA4: 17.13 | DB4: 18503 | DC4: 12 | DD4: 68.52 | DE4: 879013 | DF4: 89 | DG4: 508.19 | DH4: 14297 | DI4: 10 | DJ4: 57.1 | DK4: 12999 | DL4: 7 | DM4: 39.97 | DN4: 8143 | DO4: 6 | DP4: 34.26 | DQ4: 2655 | DR4: 1 | DS4: 5.71 | DT4: 10474 | DU4: 9 | DV4: 51.39 | DW4: 9129 | DX4: 6 | DY4: 34.26 | DZ4: 9850 | EA4: 7 | EB4: 39.97 | EC4: 10064 | ED4: 9 | EE4: 51.39 | EG4: 0 | EI4: 0 | EK4: 0 | EM4: 0 | EN4: 74 | EO4: 171 | EP4: 0.766
A5: 44987 | B5: 9919780 | C5: 29806 | D5: 8762812 | E5: 28694 | F5: 0.96 | G5: 1324 | H5: 1330 | I5: 296394 | J5: 0 | K5: 823 | L5: 1 | M5: 652202 | N5: 0 | O5: 1052 | P5: 0 | Q5: 5855700 | R5: 15800 | S5: 5301000 | T5: 6900 | U5: 3184625 | V5: 621 | W5: 2440443 | X5: 539 | Y5: 15762 | Z5: 411 | AB5: 0.94 | AC5: 378 | AE5: 3556 | AF5: 0 | AG5: 644580 | AH5: 400 | AI5: 92 | AJ5: 1 | AK5: 7283 | AL5: 14 | AM5: 116784 | AN5: 491 | AP5: 0 | AQ5: 683250 | AR5: 190 | AS5: 12711 | AT5: 24 | AU5: 3025 | AV5: 35 | AW5: 9838 | AX5: 2 | AY5: 11725 | AZ5: 3 | BA5: 21964 | BB5: 9 | BC5: 22602 | BD5: 4 | BE5: 265 | BF5: 2 | BG5: 15573 | BH5: 2 | BI5: 7124 | BJ5: 1 | BK5: 29498 | BL5: 4 | BM5: 7021 | BN5: 4 | BO5: 46349 | BP5: 57 | BQ5: 3641 | BR5: 0 | BS5: 13 | BT5: 177 | BU5: 694700 | BV5: 120 | BY5: 900600 | BZ5: 280 | CC5: 90 | CD5: 400 | CE5: 62 | CF5: 161 | CG5: 21035.52 | CI5: 0 | CJ5: 3183053 | CK5: 2223 | CL5: 12693.33 | CM5: 85 | CN5: 9159 | CO5: 75 | CP5: 8081 | CQ5: 79 | CR5: 8512 | CS5: 25752 | CT5: -6573 | CV5: 55288 | CW5: 38 | CX5: 216.98 | CY5: 36947 | CZ5: 3 | DA5: 17.13 | DB5: 18517 | DC5: 14 | DD5: 79.94 | DE5: 879117 | DF5: 104 | DG5: 593.84 | DH5: 14312 | DI5: 15 | DJ5: 85.65 | DK5: 13007 | DL5: 8 | DM5: 45.68 | DN5: 8149 | DO5: 6 | DP5: 34.26 | DQ5: 2657 | DR5: 2 | DS5: 11.42 | DT5: 10484 | DU5: 10 | DV5: 57.1 | DW5: 9136 | DX5: 7 | DY5: 39.97 | DZ5: 9859 | EA5: 9 | EB5: 51.39 | EC5: 10074 | ED5: 10 | EE5: 57.1 | EG5: 0 | EI5: 0 | EK5: 0 | EM5: 0 | EN5: 50 | EO5: 114 | EP5: 0.633
A6: 44988 | B6: 9949405 | C6: 29625 | D6: 8791305 | E6: 28493 | F6: 0.96 | G6: 1324 | H6: 1324 | I6: 296394 | J6: 0 | K6: 823 | L6: 0 | M6: 652202 | N6: 0 | O6: 1052 | P6: 0 | Q6: 5871300 | R6: 15600 | S6: 5310700 | T6: 9700 | U6: 3185568 | V6: 943 | W6: 2440898 | X6: 455 | Y6: 16140 | Z6: 378 | AB6: 0.86 | AC6: 344 | AE6: 3556 | AF6: 0 | AG6: 645020 | AH6: 440 | AI6: 92 | AJ6: 0 | AK6: 7290 | AL6: 7 | AM6: 117148 | AN6: 364 | AP6: 0 | AQ6: 683440 | AR6: 190 | AS6: 12733 | AT6: 22 | AU6: 3049 | AV6: 24 | AW6: 9839 | AX6: 1 | AY6: 11725 | AZ6: 0 | BA6: 21972 | BB6: 8 | BC6: 22605 | BD6: 3 | BE6: 267 | BF6: 2 | BG6: 15576 | BH6: 3 | BI6: 7125 | BJ6: 1 | BK6: 29500 | BL6: 2 | BM6: 7024 | BN6: 3 | BO6: 46399 | BP6: 50 | BQ6: 3641 | BR6: 0 | BS6: 13 | BT6: 177 | BU6: 694840 | BV6: 140 | BY6: 900900 | BZ6: 300 | CC6: 110 | CD6: 440 | CE6: 45 | CF6: 160.5 | CG6: 20963.43 | CI6: 72.08 | CJ6: 3184675 | CK6: 1622 | CL6: 9261.62 | CM6: 0 | CN6: 0 | CO6: 70 | CP6: 7543 | CQ6: 79 | CR6: 8512 | CS6: 16055 | CT6: 9698 | CV6: 55325 | CW6: 37 | CX6: 211.27 | CY6: 36949 | CZ6: 2 | DA6: 11.42 | DB6: 18529 | DC6: 12 | DD6: 68.52 | DE6: 879198 | DF6: 81 | DG6: 462.51 | DH6: 14321 | DI6: 9 | DJ6: 51.39 | DK6: 13020 | DL6: 13 | DM6: 74.23 | DN6: 8155 | DO6: 6 | DP6: 34.26 | DQ6: 2659 | DR6: 2 | DS6: 11.42 | DT6: 10493 | DU6: 9 | DV6: 51.39 | DW6: 9143 | DX6: 7 | DY6: 39.97 | DZ6: 9867 | EA6: 8 | EB6: 45.68 | EC6: 10084 | ED6: 10 | EE6: 57.1 | EG6: 0 | EI6: 0 | EK6: 0 | EM6: 0 | EN6: 82 | EO6: 218 | EP6: 0.81
A7: 44989 | B7: 9976348 | C7: 26943 | D7: 8817190 | E7: 25885 | F7: 0.96 | G7: 1338 | H7: 1324 | I7: 296394 | J7: 0 | K7: 823 | L7: 0 | M7: 652202 | N7: 0 | O7: 1052 | P7: 0 | Q7: 5885600 | R7: 14300 | S7: 5319400 | T7: 8700 | U7: 3186222 | V7: 654 | W7: 2441397 | X7: 499 | Y7: 16580 | Z7: 440 | AB7: 0.89 | AC7: 356 | AE7: 3556 | AF7: 0 | AG7: 645380 | AH7: 360 | AI7: 92 | AJ7: 0 | AK7: 7298 | AL7: 8 | AM7: 117542 | AN7: 394 | AP7: 0 | AQ7: 683600 | AR7: 160 | AS7: 12755 | AT7: 22 | AU7: 3077 | AV7: 28 | AW7: 9842 | AX7: 3 | AY7: 11727 | AZ7: 2 | BA7: 21980 | BB7: 8 | BC7: 22610 | BD7: 5 | BE7: 269 | BF7: 2 | BG7: 15579 | BH7: 3 | BI7: 7127 | BJ7: 2 | BK7: 29504 | BL7: 4 | BM7: 7029 | BN7: 5 | BO7: 46445 | BP7: 46 | BQ7: 3641 | BR7: 0 | BS7: 13 | BT7: 147 | BU7: 694950 | BV7: 110 | BY7: 901140 | BZ7: 240 | CC7: 80 | CD7: 350 | CE7: 58 | CF7: 160.5 | CG7: 20963.43 | CI7: 0 | CJ7: 3186904 | CK7: 2229 | CL7: 12727.59 | CM7: 0 | CN7: 0 | CO7: 60 | CP7: 6465 | CQ7: 75 | CR7: 8081 | CS7: 14546 | CT7: 1509 | CV7: 55362 | CW7: 37 | CX7: 211.27 | CY7: 36952 | CZ7: 3 | DA7: 17.13 | DB7: 18546 | DC7: 17 | DD7: 97.07 | DE7: 879291 | DF7: 93 | DG7: 531.03 | DH7: 14332 | DI7: 11 | DJ7: 62.81 | DK7: 13021 | DL7: 1 | DM7: 5.71 | DN7: 8161 | DO7: 6 | DP7: 34.26 | DQ7: 2660 | DR7: 1 | DS7: 5.71 | DT7: 10501 | DU7: 8 | DV7: 45.68 | DW7: 9147 | DX7: 4 | DY7: 22.84 | DZ7: 9874 | EA7: 7 | EB7: 39.97 | EC7: 10093 | ED7: 9 | EE7: 51.39 | EG7: 0 | EI7: 0 | EK7: 0 | EM7: 0 | EN7: 102 | EO7: 262 | EP7: 0.93
A8: 44990 | B8: 4867 | C8: 0 | D8: 8844620 | E8: 27430 | F8: #DIV/0! | G8: 1338 | H8: 1324 | I8: 296394 | J8: 0 | K8: 823 | L8: 0 | M8: 652202 | N8: 0 | O8: 1052 | P8: 0 | Q8: 5901100 | R8: 15500 | S8: 5328200 | T8: 8800 | U8: 3187252 | V8: 1030 | W8: 2441966 | X8: 569 | Y8: 16932 | Z8: 352 | AB8: 0.94 | AC8: 378 | AE8: 3556 | AF8: 0 | AG8: 645740 | AH8: 360 | AI8: 92 | AJ8: 0 | AK8: 7296 | AL8: 0 | AM8: 117933 | AN8: 391 | AP8: 0 | AQ8: 683740 | AR8: 140 | AS8: 12782 | AT8: 27 | AU8: 3121 | AV8: 44 | AW8: 9845 | AX8: 3 | AY8: 11729 | AZ8: 2 | BA8: 21985 | BB8: 5 | BC8: 22616 | BD8: 6 | BE8: 272 | BF8: 3 | BG8: 15582 | BH8: 3 | BI8: 7127 | BJ8: 0 | BK8: 29506 | BL8: 2 | BM8: 7034 | BN8: 5 | BO8: 46497 | BP8: 52 | BQ8: 3641 | BR8: 0 | BS8: 11 | BT8: 129 | BU8: 695070 | BV8: 120 | BY8: 901370 | BZ8: 230 | CC8: 90 | CD8: 350 | CE8: 71 | CF8: 160.5 | CG8: 20963.43 | CI8: 0 | CJ8: 3188613 | CK8: 1709 | CL8: 9758.39 | CM8: 0 | CN8: 0 | CO8: 55 | CP8: 5926 | CQ8: 71 | CR8: 7650 | CS8: 13577 | CT8: 970 | CV8: 55396 | CW8: 34 | CX8: 194.14 | CY8: 36952 | CZ8: 0 | DA8: 0 | DB8: 18560 | DC8: 14 | DD8: 79.94 | DE8: 879388 | DF8: 97 | DG8: 553.87 | DH8: 14349 | DI8: 17 | DJ8: 97.07 | DK8: 13022 | DL8: 1 | DM8: 5.71 | DN8: 8165 | DO8: 4 | DP8: 22.84 | DQ8: 2661 | DR8: 1 | DS8: 5.71 | DT8: 10511 | DU8: 10 | DV8: 57.1 | DW8: 9154 | DX8: 7 | DY8: 39.97 | DZ8: 9882 | EA8: 8 | EB8: 45.68 | EC8: 10102 | ED8: 9 | EE8: 51.39 | EG8: 0 | EI8: 0 | EK8: 0 | EM8: 0 | EN8: 95 | EO8: 261 | EP8: 0.95
A9: 44991 | B9: 29456 | C9: 24589 | D9: 8868284 | E9: 23664 | F9: 0.96 | G9: 1338 | H9: 1324 | I9: 296394 | J9: 0 | K9: 823 | L9: 0 | M9: 652202 | N9: 0 | O9: 1052 | P9: 0 | Q9: 5914600 | R9: 13500 | S9: 5335600 | T9: 7400 | U9: 3187842 | V9: 590 | W9: 2442507 | X9: 541 | Y9: 17300 | Z9: 368 | AB9: 0.94 | AC9: 378 | AE9: 3556 | AF9: 0 | AG9: 646100 | AH9: 360 | AI9: 92 | AJ9: 0 | AK9: 7296 | AL9: 0 | AM9: 118324 | AN9: 391 | AP9: 0 | AQ9: 683900 | AR9: 160 | AS9: 12816 | AT9: 34 | AU9: 3145 | AV9: 24 | AW9: 9849 | AX9: 4 | AY9: 11730 | AZ9: 1 | BA9: 21992 | BB9: 7 | BC9: 22620 | BD9: 4 | BE9: 274 | BF9: 2 | BG9: 15586 | BH9: 4 | BI9: 7128 | BJ9: 1 | BK9: 29511 | BL9: 5 | BM9: 7038 | BN9: 4 | BO9: 46560 | BP9: 63 | BQ9: 3641 | BR9: 0 | BS9: 13 | BT9: 147 | BU9: 695200 | BV9: 130 | BY9: 901590 | BZ9: 220 | CC9: 60 | CD9: 350 | CE9: 51 | CF9: 160.5 | CG9: 20963.43 | CI9: 0 | CJ9: 3190230 | CK9: 1617 | CL9: 9233.07 | CM9: 0 | CN9: 0 | CO9: 50 | CP9: 5388 | CQ9: 69 | CR9: 7435 | CS9: 12822 | CT9: 754 | CV9: 55435 | CW9: 39 | CX9: 222.69 | CY9: 36952 | CZ9: 0 | DA9: 0 | DB9: 18574 | DC9: 14 | DD9: 79.94 | DE9: 879459 | DF9: 71 | DG9: 405.41 | DH9: 14358 | DI9: 9 | DJ9: 51.39 | DK9: 13026 | DL9: 4 | DM9: 22.84 | DN9: 8172 | DO9: 7 | DP9: 39.97 | DQ9: 2663 | DR9: 2 | DS9: 11.42 | DT9: 10522 | DU9: 11 | DV9: 62.81 | DW9: 9161 | DX9: 7 | DY9: 39.97 | DZ9: 9890 | EA9: 8 | EB9: 45.68 | EC9: 10112 | ED9: 10 | EE9: 57.1 | EG9: 0 | EI9: 0 | EK9: 0 | EM9: 0 | EN9: 96 | EO9: 247 | EP9: 0.83
A10: 44992 | B10: 56156 | C10: 26700 | D10: 8893971 | E10: 25687 | F10: 0.96 | G10: 1338 | H10: 1324 | I10: 296394 | J10: 0 | K10: 823 | L10: 0 | M10: 652202 | N10: 0 | O10: 1052 | P10: 0 | Q10: 5929300 | R10: 14700 | S10: 5343500 | T10: 7900 | U10: 3188498 | V10: 656 | W10: 2443036 | X10: 529 | Y10: 17705 | Z10: 405 | AB10: 0.86 | AC10: 344 | AE10: 3556 | AF10: 0 | AG10: 646510 | AH10: 410 | AI10: 92 | AJ10: 0 | AK10: 7309 | AL10: 13 | AM10: 118635 | AN10: 311 | AP10: 0 | AQ10: 684030 | AR10: 130 | AS10: 12840 | AT10: 24 | AU10: 3179 | AV10: 34 | AW10: 9851 | AX10: 2 | AY10: 11731 | AZ10: 1 | BA10: 21998 | BB10: 6 | BC10: 22623 | BD10: 3 | BE10: 276 | BF10: 2 | BG10: 15590 | BH10: 4 | BI10: 7130 | BJ10: 2 | BK10: 29514 | BL10: 3 | BM10: 7041 | BN10: 3 | BO10: 46602 | BP10: 42 | BQ10: 3641 | BR10: 0 | BS10: 12 | BT10: 118 | BU10: 695330 | BV10: 130 | BY10: 901850 | BZ10: 260 | CC10: 130 | CD10: 390 | CE10: 57 | CF10: 160.5 | CG10: 20963.43 | CI10: 0 | CJ10: 3191590 | CK10: 1360 | CL10: 7765.6 | CM10: 75 | CN10: 8081 | CO10: 75 | CP10: 8081 | CQ10: 69 | CR10: 7435 | CS10: 23597 | CT10: -10775 | CV10: 55475 | CW10: 40 | CX10: 228.4 | CY10: 36955 | CZ10: 3 | DA10: 17.13 | DB10: 18587 | DC10: 13 | DD10: 74.23 | DE10: 879529 | DF10: 70 | DG10: 399.7 | DH10: 14370 | DI10: 12 | DJ10: 68.52 | DK10: 13033 | DL10: 7 | DM10: 39.97 | DN10: 8178 | DO10: 6 | DP10: 34.26 | DQ10: 2664 | DR10: 1 | DS10: 5.71 | DT10: 10530 | DU10: 8 | DV10: 45.68 | DW10: 9167 | DX10: 6 | DY10: 34.26 | DZ10: 9899 | EA10: 9 | EB10: 51.39 | EC10: 10123 | ED10: 11 | EE10: 62.81 | EG10: 0 | EI10: 0 | EK10: 0 | EM10: 0 | EN10: 96 | EO10: 242 | EP10: 0.85
A11: 44993 | B11: 85152 | C11: 28996 | D11: 8921891 | E11: 27920 | F11: 0.96 | G11: 1338 | H11: 1324 | I11: 296394 | J11: 0 | K11: 823 | L11: 0 | M11: 652202 | N11: 0 | O11: 1052 | P11: 0 | Q11: 5945000 | R11: 15700 | S11: 5352500 | T11: 9000 | U11: 3189333 | V11: 835 | W11: 2443626 | X11: 590 | Y11: 18105 | Z11: 400 | AB11: 0.83 | AC11: 333 | AE11: 3556 | AF11: 0 | AG11: 646970 | AH11: 460 | AI11: 92 | AJ11: 0 | AK11: 7316 | AL11: 7 | AM11: 119059 | AN11: 424 | AP11: 0 | AQ11: 684230 | AR11: 200 | AS11: 12852 | AT11: 12 | AU11: 3240 | AV11: 61 | AW11: 9854 | AX11: 3 | AY11: 11733 | AZ11: 2 | BA11: 22006 | BB11: 8 | BC11: 22627 | BD11: 4 | BE11: 279 | BF11: 3 | BG11: 15595 | BH11: 5 | BI11: 7131 | BJ11: 1 | BK11: 29518 | BL11: 4 | BM11: 7044 | BN11: 3 | BO11: 46650 | BP11: 48 | BQ11: 3641 | BR11: 0 | BS11: 16 | BT11: 184 | BU11: 695500 | BV11: 170 | BY11: 902140 | BZ11: 290 | CC11: 90 | CD11: 460 | CE11: 90 | CF11: 160.5 | CG11: 20963.43 | CI11: 0 | CJ11: 3193895 | CK11: 2305 | CL11: 13161.55 | CM11: 65 | CN11: 7004 | CO11: 74 | CP11: 7974 | CQ11: 69 | CR11: 7435 | CS11: 22412 | CT11: 1185 | CV11: 55516 | CW11: 41 | CX11: 234.11 | CY11: 36960 | CZ11: 5 | DA11: 28.55 | DB11: 18604 | DC11: 17 | DD11: 97.07 | DE11: 879613 | DF11: 84 | DG11: 479.64 | DH11: 14389 | DI11: 19 | DJ11: 108.49 | DK11: 13040 | DL11: 7 | DM11: 39.97 | DN11: 8185 | DO11: 7 | DP11: 39.97 | DQ11: 2666 | DR11: 2 | DS11: 11.42 | DT11: 10539 | DU11: 9 | DV11: 51.39 | DW11: 9173 | DX11: 6 | DY11: 34.26 | DZ11: 9907 | EA11: 8 | EB11: 45.68 | EC11: 10133 | ED11: 10 | EE11: 57.1 | EG11: 0 | EI11: 0 | EK11: 0 | EM11: 0 | EN11: 95 | EO11: 250 | EP11: 0.83
A12: 44994 | B12: 114345 | C12: 29193 | D12: 8950012 | E12: 28121 | F12: 0.96 | G12: 1338 | H12: 1324 | I12: 296394 | J12: 0 | K12: 823 | L12: 0 | M12: 652202 | N12: 0 | O12: 1052 | P12: 0 | Q12: 5960600 | R12: 15600 | S12: 5361900 | T12: 9400 | U12: 3190439 | V12: 1106 | W12: 2444144 | X12: 518 | Y12: 18504 | Z12: 399 | AB12: 0.83 | AC12: 333 | AE12: 3556 | AF12: 0 | AG12: 647380 | AH12: 410 | AI12: 92 | AJ12: 0 | AK12: 7322 | AL12: 6 | AN12: 0 | AP12: 0 | AQ12: 684380 | AR12: 150 | AS12: 12864 | AT12: 12 | AU12: 3277 | AV12: 37 | AW12: 9856 | AX12: 2 | AY12: 11735 | AZ12: 2 | BA12: 22015 | BB12: 9 | BC12: 22632 | BD12: 5 | BE12: 281 | BF12: 2 | BG12: 15598 | BH12: 3 | BI12: 7132 | BJ12: 1 | BK12: 29522 | BL12: 4 | BM12: 7049 | BN12: 5 | BO12: 46704 | BP12: 54 | BQ12: 3641 | BR12: 0 | BS12: 14 | BT12: 136 | BU12: 695650 | BV12: 150 | BY12: 902600 | BZ12: 460 | CC12: 310 | CD12: 610 | CE12: 66 | CF12: 160.5 | CG12: 20963.43 | CI12: 0 | CJ12: 3195284 | CK12: 1389 | CL12: 7931.19 | CM12: 60 | CN12: 6465 | CO12: 70 | CP12: 7543 | CQ12: 70 | CR12: 7543 | CS12: 21550 | CT12: 862 | CV12: 55562 | CW12: 46 | CX12: 262.66 | CY12: 36964 | CZ12: 4 | DA12: 22.84 | DB12: 18620 | DC12: 16 | DD12: 91.36 | DE12: 879687 | DF12: 74 | DG12: 422.54 | DH12: 14402 | DI12: 13 | DJ12: 74.23 | DK12: 13047 | DL12: 7 | DM12: 39.97 | DN12: 8191 | DO12: 6 | DP12: 34.26 | DQ12: 2667 | DR12: 1 | DS12: 5.71 | DT12: 10550 | DU12: 11 | DV12: 62.81 | DW12: 9181 | DX12: 8 | DY12: 45.68 | DZ12: 9916 | EA12: 9 | EB12: 51.39 | EC12: 10144 | ED12: 11 | EE12: 62.81 | EG12: 0 | EI12: 0 | EK12: 0 | EM12: 0 | EN12: 80 | EO12: 209 | EP12: 0.72
A13: 44995 | B13: 10140262 | C13: 25917 | D13: 8974988 | E13: 24976 | F13: 0.96369179 | G13: 1338 | H13: 1324 | I13: 296394 | J13: 0 | K13: 823 | L13: 0 | M13: 652202 | N13: 0 | O13: 1052 | P13: 0 | Q13: 5974500 | R13: 13900 | S13: 5370100 | T13: 8200 | U13: 3192107 | V13: 1668 | W13: 2444655 | X13: 511 | Y13: 18876 | Z13: 372 | AB13: 0.83333333 | AC13: 333.33333 | AE13: 3556 | AF13: 0 | AG13: 647730 | AH13: 350 | AI13: 92 | AJ13: 0 | AK13: 7322 | AL13: 0 | AM13: 119709 | AN13: 226 | AP13: 0 | AQ13: 684500 | AR13: 120 | AS13: 12891 | AT13: 27 | AU13: 3322 | AV13: 45 | AW13: 9859 | AX13: 3 | AY13: 11736 | AZ13: 1 | BA13: 22021 | BB13: 6 | BC13: 22634 | BD13: 2 | BE13: 283 | BF13: 2 | BG13: 15603 | BH13: 5 | BI13: 7133 | BJ13: 1 | BK13: 29524 | BL13: 2 | BM13: 7053 | BN13: 4 | BO13: 46760 | BP13: 56 | BQ13: 3641 | BR13: 0 | BS13: 13 | BT13: 107 | BU13: 695790 | BV13: 140 | BY13: 902950 | BZ13: 350 | CC13: 230 | CD13: 490 | CE13: 69 | CF13: 160.5 | CG13: 20963.433 | CI13: 0 | CJ13: 3197030 | CK13: 1746 | CL13: 9969.66 | CM13: 52 | CN13: 5603 | CO13: 69 | CP13: 7434.75 | CQ13: 69 | CR13: 7434.75 | CS13: 20472.5 | CT13: 1077.5 | CV13: 55596 | CW13: 34 | CX13: 194.14 | CY13: 36967 | CZ13: 3 | DA13: 17.13 | DB13: 18636 | DC13: 16 | DD13: 91.36 | DE13: 879764 | DF13: 77 | DG13: 439.67 | DH13: 14412 | DI13: 10 | DJ13: 57.1 | DK13: 13054 | DL13: 7 | DM13: 39.97 | DN13: 8197 | DO13: 6 | DP13: 34.26 | DQ13: 2669 | DR13: 2 | DS13: 11.42 | DT13: 10560 | DU13: 10 | DV13: 57.1 | DW13: 9188 | DX13: 7 | DY13: 39.97 | DZ13: 9924 | EA13: 8 | EB13: 45.68 | EC13: 10154 | ED13: 10 | EE13: 57.1 | EG13: 0 | EI13: 0 | EK13: 0 | EM13: 0 | EN13: 68 | EO13: 172 | EP13: 0.63
A14: 44996 | B14: 10168931 | C14: 28669 | D14: 9002572 | E14: 27584 | F14: 0.96215424 | G14: 1338 | H14: 1324 | I14: 296394 | J14: 0 | K14: 823 | L14: 0 | M14: 652202 | N14: 0 | O14: 1052 | P14: 0 | Q14: 5990000 | R14: 15500 | S14: 5379000 | T14: 8900 | U14: 3193239 | V14: 1132 | W14: 2445210 | X14: 555 | Y14: 19135 | Z14: 259 | AB14: 0.55555556 | AC14: 222.22222 | AE14: 3556 | AF14: 0 | AG14: 648130 | AH14: 400 | AI14: 92 | AJ14: 0 | AK14: 7328 | AL14: 6 | AM14: 120042 | AN14: 333 | AP14: 0 | AQ14: 684660 | AR14: 160 | AS14: 12912 | AT14: 21 | AU14: 3365 | AV14: 43 | AW14: 9861 | AX14: 2 | AY14: 11738 | AZ14: 2 | BA14: 22030 | BB14: 9 | BC14: 22637 | BD14: 3 | BE14: 284 | BF14: 1 | BG14: 15608 | BH14: 5 | BI14: 7134 | BJ14: 1 | BK14: 29527 | BL14: 3 | BM14: 7055 | BN14: 2 | BO14: 46801 | BP14: 41 | BQ14: 3641 | BR14: 0 | BS14: 15 | BT14: 145 | BU14: 695940 | BV14: 150 | BY14: 903050 | BZ14: 100 | CC14: -60 | CD14: 250 | CE14: 68 | CF14: 160.5 | CG14: 20963.433 | CI14: 0 | CJ14: 3199890 | CK14: 2860 | CL14: 16330.6 | CM14: 44 | CN14: 4741 | CO14: 61 | CP14: 6572.75 | CQ14: 70 | CR14: 7542.5 | CS14: 18856.25 | CT14: 1616.25 | CV14: 55637 | CW14: 41 | CX14: 234.11 | CY14: 36969 | CZ14: 2 | DA14: 11.42 | DB14: 18650 | DC14: 14 | DD14: 79.94 | DE14: 879903 | DF14: 139 | DG14: 793.69 | DH14: 14426 | DI14: 14 | DJ14: 79.94 | DK14: 13060 | DL14: 6 | DM14: 34.26 | DN14: 8203 | DO14: 6 | DP14: 34.26 | DQ14: 2670 | DR14: 1 | DS14: 5.71 | DT14: 10567 | DU14: 7 | DV14: 39.97 | DW14: 9193 | DX14: 5 | DY14: 28.55 | DZ14: 9933 | EA14: 9 | EB14: 51.39 | EC14: 10164 | ED14: 10 | EE14: 57.1 | EG14: 0 | EI14: 0 | EK14: 0 | EM14: 0 | EN14: 66 | EO14: 165 | EP14: 0.61
A15: 44997 | B15: 10193004 | C15: 24073 | D15: 9030723 | E15: 28151 | F15: 1.1694014 | G15: 1338 | H15: 1324 | I15: 296394 | J15: 0 | K15: 823 | L15: 0 | M15: 652202 | N15: 0 | O15: 1053 | P15: 1 | Q15: 6005700 | R15: 15700 | S15: 5388200 | T15: 9200 | U15: 3193939 | V15: 700 | W15: 2445775 | X15: 565 | Y15: 19444 | Z15: 309 | AB15: 0.83333333 | AC15: 333.33333 | AD15: 9 | AE15: 3828 | AF15: 272 | AG15: 648520 | AH15: 390 | AI15: 92 | AJ15: 0 | AK15: 7342 | AL15: 14 | AM15: 120380 | AN15: 338 | AP15: 0 | AQ15: 684850 | AR15: 190 | AS15: 12944 | AT15: 32 | AU15: 3409 | AV15: 44 | AW15: 9863 | AX15: 2 | AY15: 11740 | AZ15: 2 | BA15: 22036 | BB15: 6 | BC15: 22641 | BD15: 4 | BE15: 286 | BF15: 2 | BG15: 15613 | BH15: 5 | BI15: 7135 | BJ15: 1 | BK15: 29332 | BL15: 0 | BM15: 7060 | BN15: 5 | BO15: 46861 | BP15: 60 | BQ15: 3641 | BR15: 0 | BS15: 13 | BT15: 177 | BU15: 696090 | BV15: 150 | BY15: 903180 | BZ15: 130 | CC15: -60 | CD15: 280 | CE15: 71 | CF15: 160.5 | CG15: 20963.433 | CI15: 0 | CJ15: 3202137 | CK15: 2247 | CL15: 12830.37 | CM15: 39 | CN15: 4202.25 | CO15: 58 | CP15: 6249.5 | CQ15: 66 | CR15: 7111.5 | CS15: 17563.25 | CT15: 1293 | CV15: 55670 | CW15: 33 | CX15: 188.43 | CY15: 36969 | CZ15: 0 | DA15: 0 | DB15: 18666 | DC15: 16 | DD15: 91.36 | DE15: 879935 | DF15: 32 | DG15: 182.72 | DH15: 14440 | DI15: 14 | DJ15: 79.94 | DK15: 13067 | DL15: 7 | DM15: 39.97 | DN15: 8211 | DO15: 8 | DP15: 45.68 | DQ15: 2672 | DR15: 2 | DS15: 11.42 | DT15: 10578 | DU15: 11 | DV15: 62.81 | DW15: 9200 | DX15: 7 | DY15: 39.97 | DZ15: 9942 | EA15: 9 | EB15: 51.39 | EC15: 10175 | ED15: 11 | EE15: 62.81 | EG15: 0 | EI15: 0 | EK15: 0 | EM15: 0 | EN15: 95 | EO15: 228 | EP15: 0.8
A16: 44998 | B16: 10225353 | C16: 32349 | D16: 9056761 | E16: 26038 | F16: 0.80490896 | G16: 1338 | H16: 1324 | I16: 296394 | J16: 0 | K16: 823 | L16: 0 | M16: 652202 | N16: 0 | O16: 1053 | P16: 0 | Q16: 6020200 | R16: 14500 | S16: 5396900 | T16: 8700 | U16: 3195506 | V16: 1567 | W16: 2446344 | X16: 569 | Y16: 19728 | Z16: 284 | AB16: 0.86111111 | AC16: 344.44444 | AE16: 3994 | AF16: 166 | AG16: 648970 | AH16: 450 | AI16: 92 | AJ16: 0 | AK16: 7349 | AL16: 7 | AM16: 120617 | AN16: 237 | AP16: 0 | AQ16: 684990 | AR16: 140 | AS16: 12971 | AT16: 27 | AU16: 3443 | AV16: 34 | AW16: 9865 | AX16: 2 | AY16: 11742 | AZ16: 2 | BA16: 22041 | BB16: 5 | BC16: 22645 | BD16: 4 | BE16: 289 | BF16: 3 | BG16: 15618 | BH16: 5 | BI16: 7136 | BJ16: 1 | BK16: 29536 | BL16: 204 | BM16: 7064 | BN16: 4 | BO16: 46905 | BP16: 44 | BQ16: 3641 | BR16: 0 | BS16: 13 | BT16: 127 | BU16: 696240 | BV16: 150 | BY16: 903370 | BZ16: 190 | CC16: 50 | CD16: 340 | CE16: 60 | CF16: 160.5 | CG16: 20963.433 | CI16: 0 | CJ16: 3203883 | CK16: 1746 | CL16: 9969.66 | CM16: 35 | CN16: 3771.25 | CO16: 54 | CP16: 5818.5 | CQ16: 65 | CR16: 7003.75 | CS16: 16593.5 | CT16: 969.75 | CU16: 11609 | CV16: 55708 | CW16: 38 | CX16: 216.98 | CY16: 36969 | CZ16: 0 | DA16: 0 | DB16: 18678 | DC16: 12 | DD16: 68.52 | DE16: 880165 | DF16: 230 | DG16: 1313.3 | DH16: 14453 | DI16: 13 | DJ16: 74.23 | DK16: 13074 | DL16: 7 | DM16: 39.97 | DN16: 8217 | DO16: 6 | DP16: 34.26 | DQ16: 2673 | DR16: 1 | DS16: 5.71 | DT16: 10586 | DU16: 8 | DV16: 45.68 | DW16: 9206 | DX16: 6 | DY16: 34.26 | DZ16: 9950 | EA16: 8 | EB16: 45.68 | EC16: 10185 | ED16: 10 | EE16: 57.1 | EG16: 0 | EI16: 0 | EK16: 0 | EM16: 0 | EN16: 103 | EO16: 234 | EP16: 0.82
A17: 44999 | B17: 10252896 | C17: 27543 | D17: 9083276 | E17: 26515 | F17: 0.96267654 | G17: 1338 | H17: 1324 | I17: 296394 | J17: 0 | K17: 823 | L17: 0 | M17: 652202 | N17: 0 | O17: 1053 | P17: 0 | Q17: 6034800 | R17: 14600 | S17: 5405900 | T17: 9000 | U17: 3196458 | V17: 952 | W17: 2446872 | X17: 528 | Y17: 19975 | Z17: 247 | AB17: 0.66666667 | AC17: 266.66667 | AE17: 3994 | AF17: 0 | AG17: 649370 | AH17: 400 | AI17: 92 | AJ17: 0 | AK17: 7359 | AL17: 10 | AM17: 120854 | AN17: 237 | AP17: 0 | AQ17: 685180 | AR17: 190 | AS17: 13003 | AT17: 32 | AU17: 3476 | AV17: 33 | AW17: 9868 | AX17: 3 | AY17: 11744 | AZ17: 2 | BA17: 22049 | BB17: 8 | BC17: 22648 | BD17: 3 | BE17: 292 | BF17: 3 | BG17: 15624 | BH17: 6 | BI17: 7137 | BJ17: 1 | BK17: 29541 | BL17: 5 | BM17: 7068 | BN17: 4 | BO17: 46954 | BP17: 49 | BQ17: 3641 | BR17: 0 | BS17: 17 | BT17: 173 | BU17: 696370 | BV17: 130 | BY17: 903620 | BZ17: 250 | CC17: 60 | CD17: 380 | CE17: 63 | CF17: 160.5 | CG17: 20963.433 | CI17: 0 | CJ17: 3206560 | CK17: 2677 | CL17: 15285.67 | CM17: 80 | CN17: 8620 | CO17: 85 | CP17: 9158.75 | CQ17: 77 | CR17: 8296.75 | CS17: 26075.5 | CT17: 2127 | CV17: 55743 | CW17: 35 | CX17: 199.85 | CY17: 36972 | CZ17: 3 | DA17: 17.13 | DB17: 18690 | DC17: 12 | DD17: 68.52 | DE17: 880895 | DF17: 730 | DG17: 4168.3 | DH17: 14466 | DI17: 13 | DJ17: 74.23 | DK17: 13079 | DL17: 5 | DM17: 28.55 | DN17: 8222 | DO17: 5 | DP17: 28.55 | DQ17: 2675 | DR17: 2 | DS17: 11.42 | DT17: 10595 | DU17: 9 | DV17: 51.39 | DW17: 9959 | DX17: 753 | DY17: 4299.63 | DZ17: 9959 | EA17: 9 | EB17: 51.39 | EC17: 10194 | ED17: 9 | EE17: 51.39 | EG17: 0 | EI17: 0 | EK17: 0 | EM17: 0 | EN17: 102 | EO17: 233 | EP17: 0.83
A18: 45000 | B18: 10281827 | C18: 28931 | D18: 9111097 | E18: 27821 | F18: 0.96163285 | G18: 1338 | H18: 1324 | I18: 296394 | J18: 0 | K18: 823 | L18: 0 | M18: 652202 | N18: 0 | O18: 1053 | P18: 0 | Q18: 6050300 | R18: 15500 | S18: 5415000 | T18: 9100 | U18: 3197363 | V18: 905 | W18: 2447440 | X18: 568 | Y18: 20317 | Z18: 342 | AB18: 0.80555556 | AC18: 322.22222 | AE18: 4178 | AF18: 184 | AG18: 649760 | AH18: 390 | AI18: 92 | AJ18: 0 | AK18: 7368 | AL18: 9 | AM18: 121207 | AN18: 353 | AP18: 0 | AQ18: 685350 | AR18: 170 | AS18: 13035 | AT18: 32 | AU18: 3513 | AV18: 37 | AW18: 9870 | AX18: 2 | AY18: 11746 | AZ18: 2 | BA18: 22058 | BB18: 9 | BC18: 22652 | BD18: 4 | BE18: 295 | BF18: 3 | BG18: 15630 | BH18: 6 | BI18: 7137 | BJ18: 0 | BK18: 29543 | BL18: 2 | BM18: 7071 | BN18: 3 | BO18: 47005 | BP18: 51 | BQ18: 3641 | BR18: 0 | BS18: 18 | BT18: 152 | BU18: 696530 | BV18: 160 | BY18: 903850 | BZ18: 230 | CC18: 60 | CD18: 390 | CE18: 66 | CF18: 160.5 | CG18: 20963.433 | CI18: 0 | CJ18: 3208829 | CK18: 2269 | CL18: 12955.99 | CM18: 75 | CN18: 8081.25 | CO18: 80 | CP18: 8620 | CQ18: 76 | CR18: 8189 | CS18: 24890.25 | CT18: 1185.25 | CV18: 55779 | CW18: 36 | CX18: 205.56 | CY18: 36975 | CZ18: 3 | DA18: 17.13 | DB18: 18706 | DC18: 16 | DD18: 91.36 | DE18: 880432 | DF18: 0 | DG18: 0 | DH18: 14479 | DI18: 13 | DJ18: 74.23 | DK18: 13086 | DL18: 7 | DM18: 39.97 | DN18: 8229 | DO18: 7 | DP18: 39.97 | DQ18: 2676 | DR18: 1 | DS18: 5.71 | DT18: 10600 | DU18: 5 | DV18: 28.55 | DW18: 9219 | DX18: 0 | DY18: 0 | DZ18: 9967 | EA18: 8 | EB18: 45.68 | EC18: 10203 | ED18: 9 | EE18: 51.39 | EG18: 0 | EI18: 0 | EK18: 0 | EM18: 0 | EN18: 93 | EO18: 200 | EP18: 0.8
A19: 45001 | B19: 10307360 | C19: 25533 | D19: 9135856 | E19: 24759 | F19: 0.96968629 | G19: 1338 | H19: 1324 | I19: 296394 | J19: 0 | K19: 823 | L19: 0 | M19: 652202 | N19: 0 | O19: 1053 | P19: 0 | Q19: 6063200 | R19: 12900 | S19: 5424100 | T19: 9100 | U19: 3198112 | V19: 749 | W19: 2447944 | X19: 504 | Y19: 20690 | Z19: 373 | AB19: 0.94444444 | AC19: 377.77778 | AE19: 4262 | AF19: 84 | AG19: 650120 | AH19: 360 | AI19: 93 | AJ19: 1 | AK19: 7376 | AL19: 8 | AM19: 121612 | AN19: 405 | AP19: 0 | AQ19: 685520 | AR19: 170 | AS19: 13068 | AT19: 33 | AU19: 3539 | AV19: 26 | AW19: 9873 | AX19: 3 | AY19: 11748 | AZ19: 2 | BA19: 22071 | BB19: 13 | BC19: 22658 | BD19: 6 | BE19: 298 | BF19: 3 | BG19: 15636 | BH19: 6 | BI19: 7138 | BJ19: 1 | BK19: 29548 | BL19: 5 | BM19: 7075 | BN19: 4 | BO19: 47062 | BP19: 57 | BQ19: 3641 | BR19: 0 | BS19: 22 | BT19: 148 | BU19: 696670 | BV19: 140 | BY19: 904070 | BZ19: 220 | CC19: 50 | CD19: 360 | CE19: 64 | CF19: 160.5 | CG19: 20963.433 | CI19: 0 | CJ19: 3210375 | CK19: 1546 | CL19: 8827.66 | CM19: 70 | CN19: 7542.5 | CO19: 78 | CP19: 8404.5 | CQ19: 75 | CR19: 8081.25 | CS19: 24028.25 | CT19: 862 | CV19: 55808 | CW19: 29 | CX19: 165.59 | CY19: 36978 | CZ19: 3 | DA19: 17.13 | DB19: 18719 | DC19: 13 | DD19: 74.23 | DE19: 880549 | DF19: 117 | DG19: 668.07 | DH19: 14490 | DI19: 11 | DJ19: 62.81 | DK19: 13093 | DL19: 7 | DM19: 39.97 | DN19: 8235 | DO19: 6 | DP19: 34.26 | DQ19: 2678 | DR19: 2 | DS19: 11.42 | DT19: 10608 | DU19: 8 | DV19: 45.68 | DW19: 9227 | DX19: 8 | DY19: 45.68 | DZ19: 9976 | EA19: 9 | EB19: 51.39 | EC19: 10213 | ED19: 10 | EE19: 57.1 | EG19: 0 | EI19: 0 | EK19: 0 | EM19: 0 | EN19: 100 | EO19: 200 | EP19: 0.8
A20: 45002 | C20: 0 | E20: 0 | F20: #DIV/0! | J20: 0 | L20: 0 | N20: 0 | P20: 0 | R20: 0 | T20: 0 | V20: 0 | X20: 0 | Z20: 0 | AC20: 0 | AF20: 0 | AH20: 0 | AJ20: 0 | AL20: 0 | AN20: 0 | AP20: 0 | AR20: 0 | AT20: 0 | AV20: 0 | AX20: 0 | AZ20: 0 | BB20: 0 | BD20: 0 | BF20: 0 | BH20: 0 | BJ20: 0 | BL20: 0 | BN20: 0 | BP20: 0 | BR20: 0 | BS20: 0 | BT20: 0 | BV20: 0 | BZ20: 0 | CC20: 0 | CD20: 0 | CE20: 0 | CG20: 0 | CI20: 0 | CK20: 0 | CL20: 0 | CN20: 0 | CP20: 0 | CR20: 0 | CS20: 0 | CT20: 0 | CW20: 0 | CX20: 0 | CZ20: 0 | DA20: 0 | DC20: 0 | DD20: 0 | DF20: 0 | DG20: 0 | DI20: 0 | DJ20: 0 | DL20: 0 | DM20: 0 | DO20: 0 | DP20: 0 | DR20: 0 | DS20: 0 | DU20: 0 | DV20: 0 | DX20: 0 | DY20: 0 | EA20: 0 | EB20: 0 | ED20: 0 | EE20: 0 | EG20: 0 | EI20: 0 | EK20: 0 | EM20: 0
A21: 45003 | C21: 0 | E21: 0 | F21: #DIV/0! | J21: 0 | L21: 0 | N21: 0 | P21: 0 | R21: 0 | T21: 0 | V21: 0 | X21: 0 | Z21: 0 | AC21: 0 | AF21: 0 | AH21: 0 | AJ21: 0 | AL21: 0 | AN21: 0 | AP21: 0 | AR21: 0 | AT21: 0 | AV21: 0 | AX21: 0 | AZ21: 0 | BB21: 0 | BD21: 0 | BF21: 0 | BH21: 0 | BJ21: 0 | BL21: 0 | BN21: 0 | BP21: 0 | BR21: 0 | BS21: 0 | BT21: 0 | BV21: 0 | BZ21: 0 | CC21: 0 | CD21: 0 | CE21: 0 | CG21: 0 | CI21: 0 | CK21: 0 | CL21: 0 | CN21: 0 | CP21: 0 | CR21: 0 | CS21: 0 | CT21: 0 | CW21: 0 | CX21: 0 | CZ21: 0 | DA21: 0 | DC21: 0 | DD21: 0 | DF21: 0 | DG21: 0 | DI21: 0 | DJ21: 0 | DL21: 0 | DM21: 0 | DO21: 0 | DP21: 0 | DR21: 0 | DS21: 0 | DU21: 0 | DV21: 0 | DX21: 0 | DY21: 0 | EA21: 0 | EB21: 0 | ED21: 0 | EE21: 0 | EG21: 0 | EI21: 0 | EK21: 0 | EM21: 0
A22: 45004 | C22: 0 | E22: 0 | F22: #DIV/0! | J22: 0 | L22: 0 | N22: 0 | P22: 0 | R22: 0 | T22: 0 | V22: 0 | X22: 0 | Z22: 0 | AC22: 0 | AF22: 0 | AH22: 0 | AJ22: 0 | AL22: 0 | AN22: 0 | AP22: 0 | AR22: 0 | AT22: 0 | AV22: 0 | AX22: 0 | AZ22: 0 | BB22: 0 | BD22: 0 | BF22: 0 | BH22: 0 | BJ22: 0 | BL22: 0 | BN22: 0 | BP22: 0 | BR22: 0 | BS22: 0 | BT22: 0 | BV22: 0 | BZ22: 0 | CC22: 0 | CD22: 0 | CE22: 0 | CG22: 0 | CI22: 0 | CK22: 0 | CL22: 0 | CN22: 0 | CP22: 0 | CR22: 0 | CS22: 0 | CT22: 0 | CW22: 0 | CX22: 0 | CZ22: 0 | DA22: 0 | DC22: 0 | DD22: 0 | DF22: 0 | DG22: 0 | DI22: 0 | DJ22: 0 | DL22: 0 | DM22: 0 | DO22: 0 | DP22: 0 | DR22: 0 | DS22: 0 | DU22: 0 | DV22: 0 | DX22: 0 | DY22: 0 | EA22: 0 | EB22: 0 | ED22: 0 | EE22: 0 | EG22: 0 | EI22: 0 | EK22: 0 | EM22: 0
A23: 45005 | C23: 0 | E23: 0 | F23: #DIV/0! | J23: 0 | L23: 0 | N23: 0 | P23: 0 | R23: 0 | T23: 0 | V23: 0 | X23: 0 | Z23: 0 | AC23: 0 | AF23: 0 | AH23: 0 | AJ23: 0 | AL23: 0 | AN23: 0 | AP23: 0 | AR23: 0 | AT23: 0 | AV23: 0 | AX23: 0 | AZ23: 0 | BB23: 0 | BD23: 0 | BF23: 0 | BH23: 0 | BJ23: 0 | BL23: 0 | BN23: 0 | BP23: 0 | BR23: 0 | BS23: 0 | BT23: 0 | BV23: 0 | BZ23: 0 | CC23: 0 | CD23: 0 | CE23: 0 | CG23: 0 | CI23: 0 | CK23: 0 | CL23: 0 | CN23: 0 | CP23: 0 | CR23: 0 | CS23: 0 | CT23: 0 | CW23: 0 | CX23: 0 | CZ23: 0 | DA23: 0 | DC23: 0 | DD23: 0 | DF23: 0 | DG23: 0 | DI23: 0 | DJ23: 0 | DL23: 0 | DM23: 0 | DO23: 0 | DP23: 0 | DR23: 0 | DS23: 0 | DU23: 0 | DV23: 0 | DX23: 0 | DY23: 0 | EA23: 0 | EB23: 0 | ED23: 0 | EE23: 0 | EG23: 0 | EI23: 0 | EK23: 0 | EM23: 0
A24: 45006 | C24: 0 | E24: 0 | F24: #DIV/0! | J24: 0 | L24: 0 | N24: 0 | P24: 0 | R24: 0 | T24: 0 | V24: 0 | X24: 0 | Z24: 0 | AC24: 0 | AF24: 0 | AH24: 0 | AJ24: 0 | AL24: 0 | AN24: 0 | AP24: 0 | AR24: 0 | AT24: 0 | AV24: 0 | AX24: 0 | AZ24: 0 | BB24: 0 | BD24: 0 | BF24: 0 | BH24: 0 | BJ24: 0 | BL24: 0 | BN24: 0 | BP24: 0 | BR24: 0 | BS24: 0 | BT24: 0 | BV24: 0 | BZ24: 0 | CC24: 0 | CD24: 0 | CE24: 0 | CG24: 0 | CI24: 0 | CK24: 0 | CL24: 0 | CN24: 0 | CP24: 0 | CR24: 0 | CS24: 0 | CT24: 0 | CW24: 0 | CX24: 0 | CZ24: 0 | DA24: 0 | DC24: 0 | DD24: 0 | DF24: 0 | DG24: 0 | DI24: 0 | DJ24: 0 | DL24: 0 | DM24: 0 | DO24: 0 | DP24: 0 | DR24: 0 | DS24: 0 | DU24: 0 | DV24: 0 | DX24: 0 | DY24: 0 | EA24: 0 | EB24: 0 | ED24: 0 | EE24: 0 | EG24: 0 | EI24: 0 | EK24: 0 | EM24: 0
A25: 45007 | C25: 0 | E25: 0 | F25: #DIV/0! | J25: 0 | L25: 0 | N25: 0 | P25: 0 | R25: 0 | T25: 0 | V25: 0 | X25: 0 | Z25: 0 | AC25: 0 | AD25: 4 | AF25: 0 | AH25: 0 | AJ25: 0 | AL25: 0 | AN25: 0 | AP25: 0 | AR25: 0 | AT25: 0 | AV25: 0 | AX25: 0 | AZ25: 0 | BB25: 0 | BD25: 0 | BF25: 0 | BH25: 0 | BJ25: 0 | BL25: 0 | BN25: 0 | BP25: 0 | BR25: 0 | BS25: 0 | BT25: 0 | BV25: 0 | BZ25: 0 | CC25: 0 | CD25: 0 | CE25: 0 | CG25: 0 | CI25: 0 | CK25: 0 | CL25: 0 | CN25: 0 | CP25: 0 | CR25: 0 | CS25: 0 | CT25: 0 | CW25: 0 | CX25: 0 | CZ25: 0 | DA25: 0 | DC25: 0 | DD25: 0 | DF25: 0 | DG25: 0 | DI25: 0 | DJ25: 0 | DL25: 0 | DM25: 0 | DO25: 0 | DP25: 0 | DR25: 0 | DS25: 0 | DU25: 0 | DV25: 0 | DX25: 0 | DY25: 0 | EA25: 0 | EB25: 0 | ED25: 0 | EE25: 0 | EG25: 0 | EI25: 0 | EK25: 0 | EM25: 0
A26: 45008 | C26: 0 | E26: 0 | F26: #DIV/0! | J26: 0 | L26: 0 | N26: 0 | P26: 0 | R26: 0 | T26: 0 | V26: 0 | X26: 0 | Z26: 0 | AC26: 0 | AD26: 8 | AF26: 0 | AH26: 0 | AJ26: 0 | AL26: 0 | AN26: 0 | AP26: 0 | AR26: 0 | AT26: 0 | AV26: 0 | AX26: 0 | AZ26: 0 | BB26: 0 | BD26: 0 | BF26: 0 | BH26: 0 | BJ26: 0 | BL26: 0 | BN26: 0 | BP26: 0 | BR26: 0 | BS26: 0 | BT26: 0 | BV26: 0 | BZ26: 0 | CC26: 0 | CD26: 0 | CE26: 0 | CG26: 0 | CI26: 0 | CK26: 0 | CL26: 0 | CN26: 0 | CP26: 0 | CR26: 0 | CS26: 0 | CT26: 0 | CW26: 0 | CX26: 0 | CZ26: 0 | DA26: 0 | DC26: 0 | DD26: 0 | DF26: 0 | DG26: 0 | DI26: 0 | DJ26: 0 | DL26: 0 | DM26: 0 | DO26: 0 | DP26: 0 | DR26: 0 | DS26: 0 | DU26: 0 | DV26: 0 | DX26: 0 | DY26: 0 | EA26: 0 | EB26: 0 | ED26: 0 | EE26: 0 | EG26: 0 | EI26: 0 | EK26: 0 | EM26: 0
A27: 45009 | C27: 0 | E27: 0 | F27: #DIV/0! | J27: 0 | L27: 0 | N27: 0 | P27: 0 | R27: 0 | T27: 0 | V27: 0 | X27: 0 | Z27: 0 | AC27: 0 | AF27: 0 | AH27: 0 | AJ27: 0 | AL27: 0 | AN27: 0 | AP27: 0 | AR27: 0 | AT27: 0 | AV27: 0 | AX27: 0 | AZ27: 0 | BB27: 0 | BD27: 0 | BF27: 0 | BH27: 0 | BJ27: 0 | BL27: 0 | BN27: 0 | BP27: 0 | BR27: 0 | BS27: 0 | BT27: 0 | BV27: 0 | BZ27: 0 | CC27: 0 | CD27: 0 | CE27: 0 | CG27: 0 | CI27: 0 | CK27: 0 | CL27: 0 | CN27: 0 | CP27: 0 | CR27: 0 | CS27: 0 | CT27: 0 | CW27: 0 | CX27: 0 | CZ27: 0 | DA27: 0 | DC27: 0 | DD27: 0 | DF27: 0 | DG27: 0 | DI27: 0 | DJ27: 0 | DL27: 0 | DM27: 0 | DO27: 0 | DP27: 0 | DR27: 0 | DS27: 0 | DU27: 0 | DV27: 0 | DX27: 0 | DY27: 0 | EA27: 0 | EB27: 0 | ED27: 0 | EE27: 0 | EG27: 0 | EI27: 0 | EK27: 0 | EM27: 0
A28: 45010 | C28: 0 | E28: 0 | F28: #DIV/0! | J28: 0 | L28: 0 | N28: 0 | P28: 0 | R28: 0 | T28: 0 | V28: 0 | X28: 0 | Z28: 0 | AC28: 0 | AF28: 0 | AH28: 0 | AJ28: 0 | AL28: 0 | AN28: 0 | AP28: 0 | AR28: 0 | AT28: 0 | AV28: 0 | AX28: 0 | AZ28: 0 | BB28: 0 | BD28: 0 | BF28: 0 | BH28: 0 | BJ28: 0 | BL28: 0 | BN28: 0 | BP28: 0 | BR28: 0 | BS28: 0 | BT28: 0 | BV28: 0 | BZ28: 0 | CC28: 0 | CD28: 0 | CE28: 0 | CG28: 0 | CI28: 0 | CK28: 0 | CL28: 0 | CN28: 0 | CP28: 0 | CR28: 0 | CS28: 0 | CT28: 0 | CW28: 0 | CX28: 0 | CZ28: 0 | DA28: 0 | DC28: 0 | DD28: 0 | DF28: 0 | DG28: 0 | DI28: 0 | DJ28: 0 | DL28: 0 | DM28: 0 | DO28: 0 | DP28: 0 | DR28: 0 | DS28: 0 | DU28: 0 | DV28: 0 | DX28: 0 | DY28: 0 | EA28: 0 | EB28: 0 | ED28: 0 | EE28: 0 | EG28: 0 | EI28: 0 | EK28: 0 | EM28: 0
A29: 45011 | C29: 0 | AC29: 0
A30: 45012 | C30: 0 | AC30: 0
A31: 45013 | C31: 0 | AC31: 0
A32: 45014 | C32: 0 | E32: 0 | F32: #DIV/0! | J32: 0 | K32: 822 | L32: 822 | N32: 0 | P32: 0 | R32: 0 | T32: 0 | V32: 0 | X32: 0 | Z32: 0 | AC32: 0 | AE32: 3220 | AF32: 3220 | AH32: 0 | AJ32: 0 | AL32: 0 | AN32: 0 | AP32: 0 | AR32: 0 | AT32: 0 | AV32: 0 | AX32: 0 | AZ32: 0 | BB32: 0 | BD32: 0 | BF32: 0 | BH32: 0 | BJ32: 0 | BL32: 0 | BN32: 0 | BP32: 0 | BR32: 0 | BS32: 0 | BT32: 0 | BV32: 0 | BZ32: 0 | CC32: 0 | CD32: 0 | CE32: 0 | CG32: 0 | CI32: 0 | CK32: 0 | CL32: 0 | CN32: 0 | CP32: 0 | CR32: 0 | CS32: 0 | CT32: 0 | CW32: 0 | CX32: 0 | CZ32: 0 | DA32: 0 | DC32: 0 | DD32: 0 | DF32: 0 | DG32: 0 | DI32: 0 | DJ32: 0 | DL32: 0 | DM32: 0 | DO32: 0 | DP32: 0 | DR32: 0 | DS32: 0 | DU32: 0 | DV32: 0 | DX32: 0 | DY32: 0 | EA32: 0 | EB32: 0 | ED32: 0 | EE32: 0 | EG32: 0 | EI32: 0 | EK32: 0 | EM32: 0 | EN32: 76 | EO32: 191 | EP32: 0.72
A33: 45015 | C33: 0 | E33: 0 | F33: #DIV/0! | J33: 0 | K33: 822 | L33: 0 | N33: 0 | P33: 0 | R33: 0 | T33: 0 | V33: 0 | X33: 0 | Z33: 0 | AC33: 0 | AD33: 8 | AE33: 3489 | AF33: 269 | AH33: 0 | AJ33: 0 | AL33: 0 | AN33: 0 | AP33: 0 | AR33: 0 | AT33: 0 | AV33: 0 | AX33: 0 | AZ33: 0 | BB33: 0 | BD33: 0 | BF33: 0 | BH33: 0 | BJ33: 0 | BL33: 0 | BN33: 0 | BP33: 0 | BR33: 0 | BS33: 0 | BT33: 0 | BV33: 0 | BZ33: 0 | CC33: 0 | CD33: 0 | CE33: 0 | CG33: 0 | CI33: 0 | CK33: 0 | CL33: 0 | CN33: 0 | CP33: 0 | CR33: 0 | CS33: 0 | CT33: 0 | CW33: 0 | CX33: 0 | CZ33: 0 | DA33: 0 | DC33: 0 | DD33: 0 | DF33: 0 | DG33: 0 | DI33: 0 | DJ33: 0 | DL33: 0 | DM33: 0 | DO33: 0 | DP33: 0 | DR33: 0 | DS33: 0 | DU33: 0 | DV33: 0 | DX33: 0 | DY33: 0 | EA33: 0 | EB33: 0 | ED33: 0 | EE33: 0 | EG33: 0 | EI33: 0 | EK33: 0 | EM33: 0 | EN33: 73 | EO33: 180 | EP33: 0.738
A34: 45016 | C34: 0 | E34: 0 | F34: #DIV/0! | J34: 0 | K34: 822 | L34: 0 | N34: 0 | P34: 0 | R34: 0 | T34: 0 | V34: 0 | X34: 0 | Z34: 0 | AC34: 0 | AD34: 2 | AE34: 3556 | AF34: 67 | AH34: 0 | AJ34: 0 | AL34: 0 | AN34: 0 | AP34: 0 | AR34: 0 | AT34: 0 | AV34: 0 | AX34: 0 | AZ34: 0 | BB34: 0 | BD34: 0 | BF34: 0 | BH34: 0 | BJ34: 0 | BL34: 0 | BN34: 0 | BP34: 0 | BR34: 0 | BS34: 0 | BT34: 0 | BV34: 0 | BZ34: 0 | CC34: 0 | CD34: 0 | CE34: 0 | CG34: 0 | CI34: 0 | CK34: 0 | CL34: 0 | CN34: 0 | CP34: 0 | CR34: 0 | CS34: 0 | CT34: 0 | CW34: 0 | CX34: 0 | CZ34: 0 | DA34: 0 | DC34: 0 | DD34: 0 | DF34: 0 | DG34: 0 | DI34: 0 | DJ34: 0 | DL34: 0 | DM34: 0 | DO34: 0 | DP34: 0 | DR34: 0 | DS34: 0 | DU34: 0 | DV34: 0 | DX34: 0 | DY34: 0 | EA34: 0 | EB34: 0 | ED34: 0 | EE34: 0 | EG34: 0 | EI34: 0 | EK34: 0 | EM34: 0 | EN34: 70 | EO34: 163 | EP34: 0.77

Sheet Sheet1
N3: ='[1]Sep 2019'!R3 -> 2054945
N4: ='[1]Sep 2019'!R4 -> 2055440
N5: ='[1]Sep 2019'!R5 -> 2056149
N6: ='[1]Sep 2019'!R6 -> 2056651
N7: ='[1]Sep 2019'!R7 -> 2057174
N8: ='[1]Sep 2019'!R8 -> 2057715
N9: ='[1]Sep 2019'!R9 -> 2058246
N10: ='[1]Sep 2019'!R10 -> 2058780
N11: ='[1]Sep 2019'!R11 -> 2059332
N12: ='[1]Sep 2019'!R12 -> 2059908
N13: ='[1]Sep 2019'!R13 -> 2060432
N14: ='[1]Sep 2019'!R14 -> 2061086
... N17: ='[1]Sep 2019'!R17 -> 2062731
N18: ='[1]Sep 2019'!R18 -> 2063291 | S18: ='[1]Sep 2019'!W18 -> 7 | DU18: ='[1]Sep 2019'!EA18 -> 0.67
N19: ='[1]Sep 2019'!R19 -> 2063914 | S19: ='[1]Sep 2019'!W19 -> 7 | DU19: ='[1]Sep 2019'!EA19 -> 0.63
N20: ='[1]Sep 2019'!R20 -> 2064501 | S20: ='[1]Sep 2019'!W20 -> 8 | DU20: ='[1]Sep 2019'!EA20 -> 0.69
N21: ='[1]Sep 2019'!R21 -> 2065035 | P21: ='[1]Sep 2019'!T21 -> 426545 | S21: ='[1]Sep 2019'!W21 -> 8 | DU21: ='[1]Sep 2019'!EA21 -> 0.7
B22: ='[1]Sep 2019'!B22 -> 9576003 | D22: ='[1]Sep 2019'!D22 -> 9185016 | G22: ='[1]Sep 2019'!G22 -> 1264 | H22: ='[1]Sep 2019'!$J$22 -> 729 | I22: ='[1]Sep 2019'!I22 -> 0 | J22: 729 | L22: 2321595 | N22: ='[1]Sep 2019'!R22 -> 2065573 | P22: ='[1]Sep 2019'!T22 -> 426720 | R22: ='[1]Sep 2019'!V22 -> 61.7 | S22: ='[1]Sep 2019'!W22 -> 14 | T22: ='[1]Sep 2019'!X22 -> 114723.6 | V22: ='[1]Sep 2019'!BO22 -> 20498 | X22: ='[1]Sep 2019'!Z22 -> 961 | Z22: ='[1]Sep 2019'!AB22 -> 2535 | AD22: ='[1]Sep 2019'!AF22 -> 542040 | AF22: ='[1]Sep 2019'!AH22 -> 48870 | AH22: ='[1]Sep 2019'!AJ22 -> 8302 | CA22: ='[1]Sep 2019'!CG22 -> 24323 | CD22: ='[1]Sep 2019'!CJ22 -> 32962 | CG22: ='[1]Sep 2019'!CM22 -> 6797 | CJ22: ='[1]Sep 2019'!CP22 -> 82233 | CM22: ='[1]Sep 2019'!CS22 -> 4366 | CP22: ='[1]Sep 2019'!CV22 -> 5316 | CS22: ='[1]Sep 2019'!CY22 -> 2440 | CV22: ='[1]Sep 2019'!DB22 -> 1679 | CY22: ='[1]Sep 2019'!DE22 -> 3575 | DB22: ='[1]Sep 2019'!DH22 -> 3444 | DE22: ='[1]Sep 2019'!DK22 -> 3861 | DH22: ='[1]Sep 2019'!DN22 -> 3171 | DK22: ='[1]Sep 2019'!DQ22 -> 112173 | DM22: ='[1]Sep 2019'!DS22 -> 52938 | DO22: ='[1]Sep 2019'!DU22 -> 15019 | DQ22: ='[1]Sep 2019'!DW22 -> 22622 | DU22: ='[1]Sep 2019'!EA22 -> 0.79
