Workbook

Sheet TOTAL
A1: Site Name | B1: Day | C1: Month | D1: Year | E1: Total Electricity Kwh | F1: Electricity Tariff ($/Kwh) | G1: Natual Gas (m3) | H1: Natural Gas $/m3 | I1: Water Utility Supply (m3) | J1: Water Utility Supply ($/m3) | K1: Room Nights
A2: Cairo at Nile Plaza | B2: 1 | C2: 2 | D2: 2023 | E2: =(((Submetering!O2+Submetering!P2)*0.842284+Submetering!Q2+(Submetering!M2+Submetering!N2+Submetering!Y2)*0.7362)+(Submetering!O2+Submetering!P2+Submetering!Q2)*0.1488+(Submetering!M2+Submetering!N2+Submetering!Y2)*0.1167+(Submetering!K2+Submetering!L2-Submetering!Z2-Submetering!AA2-Submetering!AB2-Submetering!AC2-Submetering!Q2)+(Submetering!M2+Submetering!N2+Submetering!Y2)*0.1139) -> 64232.126 | F2: 1.27 | G2: =Gas!C3*0.9147 -> 2165.0949 | H2: 3.78 | I2: =Submetering!H2+Submetering!AD2+Submetering!AE2 -> 766 | J2: 9.13 | K2: =ELECT.!B3 -> 305
A3: Cairo at Nile Plaza | B3: =B2+1 -> 2 | C3: 2 | D3: 2023 | E3: =(((Submetering!O3+Submetering!P3)*0.842284+Submetering!Q3+(Submetering!M3+Submetering!N3+Submetering!Y3)*0.7362)+(Submetering!O3+Submetering!P3+Submetering!Q3)*0.1488+(Submetering!M3+Submetering!N3+Submetering!Y3)*0.1167+(Submetering!K3+Submetering!L3-Submetering!Z3-Submetering!AA3-Submetering!AB3-Submetering!AC3-Submetering!Q3)+(Submetering!M3+Submetering!N3+Submetering!Y3)*0.1139) -> 34321.858 | F3: 1.27 | G3: =Gas!C4*0.9147 -> 1797.3855 | H3: 3.78 | I3: =Submetering!H3+Submetering!AD3+Submetering!AE3 -> 636 | J3: 9.13 | K3: =ELECT.!B4 -> 295
A4: Cairo at Nile Plaza | B4: =B3+1 -> 3 | C4: 2 | D4: 2023 | E4: =(((Submetering!O4+Submetering!P4)*0.842284+Submetering!Q4+(Submetering!M4+Submetering!N4+Submetering!Y4)*0.7362)+(Submetering!O4+Submetering!P4+Submetering!Q4)*0.1488+(Submetering!M4+Submetering!N4+Submetering!Y4)*0.1167+(Submetering!K4+Submetering!L4-Submetering!Z4-Submetering!AA4-Submetering!AB4-Submetering!AC4-Submetering!Q4)+(Submetering!M4+Submetering!N4+Submetering!Y4)*0.1139) -> 55949.283 | F4: 1.27 | G4: =Gas!C5*0.9147 -> 2065.3926 | H4: 3.78 | I4: =Submetering!H4+Submetering!AD4+Submetering!AE4 -> 446 | J4: 9.13 | K4: =ELECT.!B5 -> 294
A5: Cairo at Nile Plaza | B5: =B4+1 -> 4 | C5: 2 | D5: 2023 | E5: =(((Submetering!O5+Submetering!P5)*0.842284+Submetering!Q5+(Submetering!M5+Submetering!N5+Submetering!Y5)*0.7362)+(Submetering!O5+Submetering!P5+Submetering!Q5)*0.1488+(Submetering!M5+Submetering!N5+Submetering!Y5)*0.1167+(Submetering!K5+Submetering!L5-Submetering!Z5-Submetering!AA5-Submetering!AB5-Submetering!AC5-Submetering!Q5)+(Submetering!M5+Submetering!N5+Submetering!Y5)*0.1139) -> 49099.67 | F5: 1.27 | G5: =Gas!C6*0.9147 -> 2112.0423 | H5: 3.78 | I5: =Submetering!H5+Submetering!AD5+Submetering!AE5 -> 486 | J5: 9.13 | K5: =ELECT.!B6 -> 310
A6: Cairo at Nile Plaza | B6: =B5+1 -> 5 | C6: 2 | D6: 2023 | E6: =(((Submetering!O6+Submetering!P6)*0.842284+Submetering!Q6+(Submetering!M6+Submetering!N6+Submetering!Y6)*0.7362)+(Submetering!O6+Submetering!P6+Submetering!Q6)*0.1488+(Submetering!M6+Submetering!N6+Submetering!Y6)*0.1167+(Submetering!K6+Submetering!L6-Submetering!Z6-Submetering!AA6-Submetering!AB6-Submetering!AC6-Submetering!Q6)+(Submetering!M6+Submetering!N6+Submetering!Y6)*0.1139) -> 59330.284 | F6: 1.27 | G6: =Gas!C7*0.9147 -> 1904.4054 | H6: 3.78 | I6: =Submetering!H6+Submetering!AD6+Submetering!AE6 -> 566 | J6: 9.13 | K6: =ELECT.!B7 -> 318
A7: Cairo at Nile Plaza | B7: =B6+1 -> 6 | C7: 2 | D7: 2023 | E7: =(((Submetering!O7+Submetering!P7)*0.842284+Submetering!Q7+(Submetering!M7+Submetering!N7+Submetering!Y7)*0.7362)+(Submetering!O7+Submetering!P7+Submetering!Q7)*0.1488+(Submetering!M7+Submetering!N7+Submetering!Y7)*0.1167+(Submetering!K7+Submetering!L7-Submetering!Z7-Submetering!AA7-Submetering!AB7-Submetering!AC7-Submetering!Q7)+(Submetering!M7+Submetering!N7+Submetering!Y7)*0.1139) -> 38078.816 | F7: 1.27 | G7: =Gas!C8*0.9147 -> 1780.9209 | H7: 3.78 | I7: =Submetering!H7+Submetering!AD7+Submetering!AE7 -> 476 | J7: 9.13 | K7: =ELECT.!B8 -> 317
A8: Cairo at Nile Plaza | B8: =B7+1 -> 7 | C8: 2 | D8: 2023 | E8: =(((Submetering!O8+Submetering!P8)*0.842284+Submetering!Q8+(Submetering!M8+Submetering!N8+Submetering!Y8)*0.7362)+(Submetering!O8+Submetering!P8+Submetering!Q8)*0.1488+(Submetering!M8+Submetering!N8+Submetering!Y8)*0.1167+(Submetering!K8+Submetering!L8-Submetering!Z8-Submetering!AA8-Submetering!AB8-Submetering!AC8-Submetering!Q8)+(Submetering!M8+Submetering!N8+Submetering!Y8)*0.1139) -> 65367.366 | F8: 1.27 | G8: =Gas!C9*0.9147 -> 2235.5268 | H8: 3.78 | I8: =Submetering!H8+Submetering!AD8+Submetering!AE8 -> 546 | J8: 9.13 | K8: =ELECT.!B9 -> 319
A9: Cairo at Nile Plaza | B9: =B8+1 -> 8 | C9: 2 | D9: 2023 | E9: =(((Submetering!O9+Submetering!P9)*0.842284+Submetering!Q9+(Submetering!M9+Submetering!N9+Submetering!Y9)*0.7362)+(Submetering!O9+Submetering!P9+Submetering!Q9)*0.1488+(Submetering!M9+Submetering!N9+Submetering!Y9)*0.1167+(Submetering!K9+Submetering!L9-Submetering!Z9-Submetering!AA9-Submetering!AB9-Submetering!AC9-Submetering!Q9)+(Submetering!M9+Submetering!N9+Submetering!Y9)*0.1139) -> 43295.225 | F9: 1.27 | G9: =Gas!C10*0.9147 -> 1773.6033 | H9: 3.78 | I9: =Submetering!H9+Submetering!AD9+Submetering!AE9 -> 486 | J9: 9.13 | K9: =ELECT.!B10 -> 309
A10: Cairo at Nile Plaza | B10: =B9+1 -> 9 | C10: 2 | D10: 2023 | E10: =(((Submetering!O10+Submetering!P10)*0.842284+Submetering!Q10+(Submetering!M10+Submetering!N10+Submetering!Y10)*0.7362)+(Submetering!O10+Submetering!P10+Submetering!Q10)*0.1488+(Submetering!M10+Submetering!N10+Submetering!Y10)*0.1167+(Submetering!K10+Submetering!L10-Submetering!Z10-Submetering!AA10-Submetering!AB10-Submetering!AC10-Submetering!Q10)+(Submetering!M10+Submetering!N10+Submetering!Y10)*0.1139) -> 45313.952 | F10: 1.27 | G10: =Gas!C11*0.9147 -> 1875.135 | H10: 3.78 | I10: =Submetering!H10+Submetering!AD10+Submetering!AE10 -> 586 | J10: 9.13 | K10: =ELECT.!B11 -> 312
A11: Cairo at Nile Plaza | B11: =B10+1 -> 10 | C11: 2 | D11: 2023 | E11: =(((Submetering!O11+Submetering!P11)*0.842284+Submetering!Q11+(Submetering!M11+Submetering!N11+Submetering!Y11)*0.7362)+(Submetering!O11+Submetering!P11+Submetering!Q11)*0.1488+(Submetering!M11+Submetering!N11+Submetering!Y11)*0.1167+(Submetering!K11+Submetering!L11-Submetering!Z11-Submetering!AA11-Submetering!AB11-Submetering!AC11-Submetering!Q11)+(Submetering!M11+Submetering!N11+Submetering!Y11)*0.1139) -> 59430.96 | F11: 1.27 | G11: =Gas!C12*0.9147 -> 1730.6124 | H11: 3.78 | I11: =Submetering!H11+Submetering!AD11+Submetering!AE11 -> 436 | J11: 9.13 | K11: =ELECT.!B12 -> 320
A12: Cairo at Nile Plaza | B12: =B11+1 -> 11 | C12: 2 | D12: 2023 | E12: =(((Submetering!O12+Submetering!P12)*0.842284+Submetering!Q12+(Submetering!M12+Submetering!N12+Submetering!Y12)*0.7362)+(Submetering!O12+Submetering!P12+Submetering!Q12)*0.1488+(Submetering!M12+Submetering!N12+Submetering!Y12)*0.1167+(Submetering!K12+Submetering!L12-Submetering!Z12-Submetering!AA12-Submetering!AB12-Submetering!AC12-Submetering!Q12)+(Submetering!M12+Submetering!N12+Submetering!Y12)*0.1139) -> 50606.891 | F12: 1.27 | G12: =Gas!C13*0.9147 -> 1828.4853 | H12: 3.78 | I12: =Submetering!H12+Submetering!AD12+Submetering!AE12 -> 566 | J12: 9.13 | K12: =ELECT.!B13 -> 310
A13: Cairo at Nile Plaza | B13: =B12+1 -> 12 | C13: 2 | D13: 2023 | E13: =(((Submetering!O13+Submetering!P13)*0.842284+Submetering!Q13+(Submetering!M13+Submetering!N13+Submetering!Y13)*0.7362)+(Submetering!O13+Submetering!P13+Submetering!Q13)*0.1488+(Submetering!M13+Submetering!N13+Submetering!Y13)*0.1167+(Submetering!K13+Submetering!L13-Submetering!Z13-Submetering!AA13-Submetering!AB13-Submetering!AC13-Submetering!Q13)+(Submetering!M13+Submetering!N13+Submetering!Y13)*0.1139) -> 55600.665 | F13: 1.27 | G13: =Gas!C14*0.9147 -> 2075.4543 | H13: 3.78 | I13: =Submetering!H13+Submetering!AD13+Submetering!AE13 -> 516 | J13: 9.13 | K13: =ELECT.!B14 -> 321
A14: Cairo at Nile Plaza | B14: =B13+1 -> 13 | C14: 2 | D14: 2023 | E14: =(((Submetering!O14+Submetering!P14)*0.842284+Submetering!Q14+(Submetering!M14+Submetering!N14+Submetering!Y14)*0.7362)+(Submetering!O14+Submetering!P14+Submetering!Q14)*0.1488+(Submetering!M14+Submetering!N14+Submetering!Y14)*0.1167+(Submetering!K14+Submetering!L14-Submetering!Z14-Submetering!AA14-Submetering!AB14-Submetering!AC14-Submetering!Q14)+(Submetering!M14+Submetering!N14+Submetering!Y14)*0.1139) -> 61007.48 | F14: 1.27 | G14: =Gas!C15*0.9147 -> 1798.3002 | H14: 3.78 | I14: =Submetering!H14+Submetering!AD14+Submetering!AE14 -> 576 | J14: 9.13 | K14: =ELECT.!B15 -> 308
... A32: Cairo at Nile Plaza | B32: =B31+1 -> 31 | C32: 2 | D32: 2023 | E32: =(((Submetering!O32+Submetering!P32)*0.842284+Submetering!Q32+(Submetering!M32+Submetering!N32+Submetering!Y32)*0.7362)+(Submetering!O32+Submetering!P32+Submetering!Q32)*0.1488+(Submetering!M32+Submetering!N32+Submetering!Y32)*0.1167+(Submetering!K32+Submetering!L32-Submetering!Z32-Submetering!AA32-Submetering!AB32-Submetering!AC32-Submetering!Q32)+(Submetering!M32+Submetering!N32+Submetering!Y32)*0.1139) -> 0 | F32: 4.27 | G32: =Gas!C33*0.9147 -> 0 | H32: 6.78 | I32: =Submetering!H32+Submetering!AD32+Submetering!AE32 -> -194 | J32: 12.13 | K32: =ELECT.!B33 -> 0

Sheet Submetering
A1: Site Name | B1: Day | C1: Month | D1: Year | E1: Main (m3) | F1: Podium (m3) | G1: Hotel (m3) | H1: Large (m3) | I1: Feeder 1 (KWh) | J1: Feeder 2 (KWh) | K1: T1 (KWh) | L1: T2 (KWh) | M1: T3 (KWh) | N1: T4 (KWh) | O1: T5 (KWh) | P1: T7 (KWh) | Q1: New Chiller (KWh) | R1: Hotel (BTU) | S1: B.S (BTU) | T1: LS (BTU) | U1: Mall (BTU) | V1: AHU#25 (BTU) | W1: AHU#9 (BTU) | X1: Room Nights | Y1: Loss (KWH) | Z1: Mall (KWH) | AA1: Citadel (KWH) | AB1: Rotana (KWH) | AC1: CIB (KWH) | AD1: Plaza suits water consumption (M3) | AE1: Hotel water consumption (M3)
A2: Cairo at Nile Plaza | B2: 1 | C2: 2 | D2: 2023 | E2: =Water!C3 -> 960 | F2: =Water!E3 -> 620 | G2: =Water!G3 -> 348.3 | H2: =Water!I3 -> 4.725 | I2: =ELECT.!F3 -> 9718 | J2: =ELECT.!H3 -> 56821 | K2: =ELECT.!K3 -> 11476 | L2: =ELECT.!M3 -> 6559 | M2: =ELECT.!O3 -> 2980 | N2: =ELECT.!Q3 -> 11726 | O2: =ELECT.!S3 -> 13602 | P2: =ELECT.!W3*2 -> 24606 | Q2: =ELECT.!D3 -> 320 | R2: =BTU!C3 -> 3.828 | S2: =BTU!F3 -> 1.156 | T2: =BTU!I3 -> 5 | U2: =BTU!O3 -> 3.008 | V2: =BTU!L3 -> 0.96 | W2: =BTU!R3 -> 0 | X2: =ELECT.!B3 -> 305 | Y2: =I2+J2-(K2+L2+M2+N2+O2+P2) -> -4410 | Z2: ='Mall, Citadel, Rotana'!C3+'Mall, Citadel, Rotana'!E3+'Mall, Citadel, Rotana'!G3+'Mall, Citadel, Rotana'!I3 -> 1196 | AA2: ='Mall, Citadel, Rotana'!K3+'Mall, Citadel, Rotana'!M3 -> 240 | AB2: ='Mall, Citadel, Rotana'!O3 -> 116 | AC2: ='Mall, Citadel, Rotana'!Q3+'Mall, Citadel, Rotana'!S3 -> 120 | AD2: =(E2-H2-194)*0.1318 -> 100.33604 | AE2: =E2-H2-AD2-194 -> 660.93895
A3: Cairo at Nile Plaza | B3: =B2+1 -> 2 | C3: 2 | D3: 2023 | E3: =Water!C4 -> 830 | F3: =Water!E4 -> 420 | G3: =Water!G4 -> 469.8 | H3: =Water!I4 -> 5.211 | I3: =ELECT.!F4 -> 5083 | J3: =ELECT.!H4 -> 31019 | K3: =ELECT.!K4 -> 6634 | L3: =ELECT.!M4 -> 3639 | M3: =ELECT.!O4 -> 1974 | N3: =ELECT.!Q4 -> 6107 | O3: =ELECT.!S4 -> 7385 | P3: =ELECT.!W4*2 -> 13450 | Q3: =ELECT.!D4 -> 480 | R3: =BTU!C4 -> 4.428 | S3: =BTU!F4 -> 1.526 | T3: =BTU!I4 -> 4 | U3: =BTU!O4 -> 3.511 | V3: =BTU!L4 -> 0.56 | W3: =BTU!R4 -> 0.4 | X3: =ELECT.!B4 -> 295 | Y3: =I3+J3-(K3+L3+M3+N3+O3+P3) -> -3087 | Z3: ='Mall, Citadel, Rotana'!C4+'Mall, Citadel, Rotana'!E4+'Mall, Citadel, Rotana'!G4+'Mall, Citadel, Rotana'!I4 -> 1035 | AA3: ='Mall, Citadel, Rotana'!K4+'Mall, Citadel, Rotana'!M4 -> 180 | AB3: ='Mall, Citadel, Rotana'!O4 -> 165 | AC3: ='Mall, Citadel, Rotana'!Q4+'Mall, Citadel, Rotana'!S4 -> 120 | AD3: =(E3-H3-194)*0.1318 -> 83.13799 | AE3: =E3-H3-AD3-194 -> 547.65101
A4: Cairo at Nile Plaza | B4: =B3+1 -> 3 | C4: 2 | D4: 2023 | E4: =Water!C5 -> 640 | F4: =Water!E5 -> 370 | G4: =Water!G5 -> 313.2 | H4: =Water!I5 -> 4.455 | I4: =ELECT.!F5 -> 8452 | J4: =ELECT.!H5 -> 49587 | K4: =ELECT.!K5 -> 9222 | L4: =ELECT.!M5 -> 5839 | M4: =ELECT.!O5 -> 1792 | N4: =ELECT.!Q5 -> 9916 | O4: =ELECT.!S5 -> 11903 | P4: =ELECT.!W5*2 -> 22298 | Q4: =ELECT.!D5 -> 320 | R4: =BTU!C5 -> 3.599 | S4: =BTU!F5 -> 0.591 | T4: =BTU!I5 -> 4 | U4: =BTU!O5 -> 2.662 | V4: =BTU!L5 -> 0 | W4: =BTU!R5 -> 0.13 | X4: =ELECT.!B5 -> 294 | Y4: =I4+J4-(K4+L4+M4+N4+O4+P4) -> -2931 | Z4: ='Mall, Citadel, Rotana'!C5+'Mall, Citadel, Rotana'!E5+'Mall, Citadel, Rotana'!G5+'Mall, Citadel, Rotana'!I5 -> 1178 | AA4: ='Mall, Citadel, Rotana'!K5+'Mall, Citadel, Rotana'!M5 -> 180 | AB4: ='Mall, Citadel, Rotana'!O5 -> 62 | AC4: ='Mall, Citadel, Rotana'!Q5+'Mall, Citadel, Rotana'!S5 -> 121 | AD4: =(E4-H4-194)*0.1318 -> 58.195631 | AE4: =E4-H4-AD4-194 -> 383.34937
A5: Cairo at Nile Plaza | B5: =B4+1 -> 4 | C5: 2 | D5: 2023 | E5: =Water!C6 -> 680 | F5: =Water!E6 -> 380 | G5: =Water!G6 -> 324 | H5: =Water!I6 -> 5.076 | I5: =ELECT.!F6 -> 7450 | J5: =ELECT.!H6 -> 43673 | K5: =ELECT.!K6 -> 8130 | L5: =ELECT.!M6 -> 5174 | M5: =ELECT.!O6 -> 2124 | N5: =ELECT.!Q6 -> 9209 | O5: =ELECT.!S6 -> 10403 | P5: =ELECT.!W6*2 -> 19108 | Q5: =ELECT.!D6 -> 320 | R5: =BTU!C6 -> 5.637 | S5: =BTU!F6 -> 1.076 | T5: =BTU!I6 -> 6 | U5: =BTU!O6 -> 4.191 | V5: =BTU!L6 -> 1.6 | W5: =BTU!R6 -> 0.13 | X5: =ELECT.!B6 -> 310 | Y5: =I5+J5-(K5+L5+M5+N5+O5+P5) -> -3025 | Z5: ='Mall, Citadel, Rotana'!C6+'Mall, Citadel, Rotana'!E6+'Mall, Citadel, Rotana'!G6+'Mall, Citadel, Rotana'!I6 -> 1175 | AA5: ='Mall, Citadel, Rotana'!K6+'Mall, Citadel, Rotana'!M6 -> 120 | AB5: ='Mall, Citadel, Rotana'!O6 -> 119 | AC5: ='Mall, Citadel, Rotana'!Q6+'Mall, Citadel, Rotana'!S6 -> 118 | AD5: =(E5-H5-194)*0.1318 -> 63.385783 | AE5: =E5-H5-AD5-194 -> 417.53822
A6: Cairo at Nile Plaza | B6: =B5+1 -> 5 | C6: 2 | D6: 2023 | E6: =Water!C7 -> 760 | F6: =Water!E7 -> 430 | G6: =Water!G7 -> 364.5 | H6: =Water!I7 -> 4.86 | I6: =ELECT.!F7 -> 9121 | J6: =ELECT.!H7 -> 52240 | K6: =ELECT.!K7 -> 10406 | L6: =ELECT.!M7 -> 6556 | M6: =ELECT.!O7 -> 2382 | N6: =ELECT.!Q7 -> 10675 | O6: =ELECT.!S7 -> 12361 | P6: =ELECT.!W7*2 -> 22918 | Q6: =ELECT.!D7 -> 320 | R6: =BTU!C7 -> 3.263 | S6: =BTU!F7 -> 1.128 | T6: =BTU!I7 -> 4 | U6: =BTU!O7 -> 2.32 | V6: =BTU!L7 -> 1.01 | W6: =BTU!R7 -> 0.13 | X6: =ELECT.!B7 -> 318 | Y6: =I6+J6-(K6+L6+M6+N6+O6+P6) -> -3937 | Z6: ='Mall, Citadel, Rotana'!C7+'Mall, Citadel, Rotana'!E7+'Mall, Citadel, Rotana'!G7+'Mall, Citadel, Rotana'!I7 -> 1053 | AA6: ='Mall, Citadel, Rotana'!K7+'Mall, Citadel, Rotana'!M7 -> 180 | AB6: ='Mall, Citadel, Rotana'!O7 -> 108 | AC6: ='Mall, Citadel, Rotana'!Q7+'Mall, Citadel, Rotana'!S7 -> 120 | AD6: =(E6-H6-194)*0.1318 -> 73.958252 | AE6: =E6-H6-AD6-194 -> 487.18175
A7: Cairo at Nile Plaza | B7: =B6+1 -> 6 | C7: 2 | D7: 2023 | E7: =Water!C8 -> 670 | F7: =Water!E8 -> 370 | G7: =Water!G8 -> 332.1 | H7: =Water!I8 -> 4.347 | I7: =ELECT.!F8 -> 6038 | J7: =ELECT.!H8 -> 33916 | K7: =ELECT.!K8 -> 5826 | L7: =ELECT.!M8 -> 4473 | M7: =ELECT.!O8 -> 1444 | N7: =ELECT.!Q8 -> 6902 | O7: =ELECT.!S8 -> 8094 | P7: =ELECT.!W8*2 -> 14956 | Q7: =ELECT.!D8 -> 320 | R7: =BTU!C8 -> 4.931 | S7: =BTU!F8 -> 1.817 | T7: =BTU!I8 -> 5 | U7: =BTU!O8 -> 3.039 | V7: =BTU!L8 -> 1.42 | W7: =BTU!R8 -> 0.33 | X7: =ELECT.!B8 -> 317 | Y7: =I7+J7-(K7+L7+M7+N7+O7+P7) -> -1741 | Z7: ='Mall, Citadel, Rotana'!C8+'Mall, Citadel, Rotana'!E8+'Mall, Citadel, Rotana'!G8+'Mall, Citadel, Rotana'!I8 -> 1080 | AA7: ='Mall, Citadel, Rotana'!K8+'Mall, Citadel, Rotana'!M8 -> 240 | AB7: ='Mall, Citadel, Rotana'!O8 -> 59 | AC7: ='Mall, Citadel, Rotana'!Q8+'Mall, Citadel, Rotana'!S8 -> 119 | AD7: =(E7-H7-194)*0.1318 -> 62.163865 | AE7: =E7-H7-AD7-194 -> 409.48913
A8: Cairo at Nile Plaza | B8: =B7+1 -> 7 | C8: 2 | D8: 2023 | E8: =Water!C9 -> 740 | F8: =Water!E9 -> 380 | G8: =Water!G9 -> 364.5 | H8: =Water!I9 -> 6.021 | I8: =ELECT.!F9 -> 9735 | J8: =ELECT.!H9 -> 58356 | K8: =ELECT.!K9 -> 12276 | L8: =ELECT.!M9 -> 7275 | M8: =ELECT.!O9 -> 2272 | N8: =ELECT.!Q9 -> 11570 | O8: =ELECT.!S9 -> 13519 | P8: =ELECT.!W9*2 -> 26362 | Q8: =ELECT.!D9 -> 480 | R8: =BTU!C9 -> 3.298 | S8: =BTU!F9 -> 1.112 | T8: =BTU!I9 -> 4 | U8: =BTU!O9 -> 2.606 | V8: =BTU!L9 -> 1.27 | W8: =BTU!R9 -> 0.12 | X8: =ELECT.!B9 -> 319 | Y8: =I8+J8-(K8+L8+M8+N8+O8+P8) -> -5183 | Z8: ='Mall, Citadel, Rotana'!C9+'Mall, Citadel, Rotana'!E9+'Mall, Citadel, Rotana'!G9+'Mall, Citadel, Rotana'!I9 -> 1681 | AA8: ='Mall, Citadel, Rotana'!K9+'Mall, Citadel, Rotana'!M9 -> 180 | AB8: ='Mall, Citadel, Rotana'!O9 -> 110 | AC8: ='Mall, Citadel, Rotana'!Q9+'Mall, Citadel, Rotana'!S9 -> 181 | AD8: =(E8-H8-194)*0.1318 -> 71.169232 | AE8: =E8-H8-AD8-194 -> 468.80977
A9: Cairo at Nile Plaza | B9: =B8+1 -> 8 | C9: 2 | D9: 2023 | E9: =Water!C10 -> 680 | F9: =Water!E10 -> 360 | G9: =Water!G10 -> 359.1 | H9: =Water!I10 -> 5.589 | I9: =ELECT.!F10 -> 7045 | J9: =ELECT.!H10 -> 38093 | K9: =ELECT.!K10 -> 7946 | L9: =ELECT.!M10 -> 5072 | M9: =ELECT.!O10 -> 1560 | N9: =ELECT.!Q10 -> 7496 | O9: =ELECT.!S10 -> 8754 | P9: =ELECT.!W10*2 -> 17138 | Q9: =ELECT.!D10 -> 960 | R9: =BTU!C10 -> 3.562 | S9: =BTU!F10 -> 1.279 | T9: =BTU!I10 -> 5 | U9: =BTU!O10 -> 3.113 | V9: =BTU!L10 -> 1.77 | W9: =BTU!R10 -> 0.17 | X9: =ELECT.!B10 -> 309 | Y9: =I9+J9-(K9+L9+M9+N9+O9+P9) -> -2828 | Z9: ='Mall, Citadel, Rotana'!C10+'Mall, Citadel, Rotana'!E10+'Mall, Citadel, Rotana'!G10+'Mall, Citadel, Rotana'!I10 -> 1193 | AA9: ='Mall, Citadel, Rotana'!K10+'Mall, Citadel, Rotana'!M10 -> 240 | AB9: ='Mall, Citadel, Rotana'!O10 -> 115 | AC9: ='Mall, Citadel, Rotana'!Q10+'Mall, Citadel, Rotana'!S10 -> 0 | AD9: =(E9-H9-194)*0.1318 -> 63.31817 | AE9: =E9-H9-AD9-194 -> 417.09283
A10: Cairo at Nile Plaza | B10: =B9+1 -> 9 | C10: 2 | D10: 2023 | E10: =Water!C11 -> 780 | F10: =Water!E11 -> 420 | G10: =Water!G11 -> 359.1 | H10: =Water!I11 -> 5.157 | I10: =ELECT.!F11 -> 6784 | J10: =ELECT.!H11 -> 40987 | K10: =ELECT.!K11 -> 8088 | L10: =ELECT.!M11 -> 5143 | M10: =ELECT.!O11 -> 1774 | N10: =ELECT.!Q11 -> 8254 | O10: =ELECT.!S11 -> 9211 | P10: =ELECT.!W11*2 -> 18678 | Q10: =ELECT.!D11 -> 480 | R10: =BTU!C11 -> 3.518 | S10: =BTU!F11 -> 1.407 | T10: =BTU!I11 -> 4 | U10: =BTU!O11 -> 3.174 | V10: =BTU!L11 -> 1.72 | W10: =BTU!R11 -> 0.28 | X10: =ELECT.!B11 -> 312 | Y10: =I10+J10-(K10+L10+M10+N10+O10+P10) -> -3377 | Z10: ='Mall, Citadel, Rotana'!C11+'Mall, Citadel, Rotana'!E11+'Mall, Citadel, Rotana'!G11+'Mall, Citadel, Rotana'!I11 -> 1373 | AA10: ='Mall, Citadel, Rotana'!K11+'Mall, Citadel, Rotana'!M11 -> 240 | AB10: ='Mall, Citadel, Rotana'!O11 -> 153 | AC10: ='Mall, Citadel, Rotana'!Q11+'Mall, Citadel, Rotana'!S11 -> 293 | AD10: =(E10-H10-194)*0.1318 -> 76.555107 | AE10: =E10-H10-AD10-194 -> 504.28789
A11: Cairo at Nile Plaza | B11: =B10+1 -> 10 | C11: 2 | D11: 2023 | E11: =Water!C12 -> 630 | F11: =Water!E12 -> 320 | G11: =Water!G12 -> 369.9 | H11: =Water!I12 -> 3.78 | I11: =ELECT.!F12 -> 8779 | J11: =ELECT.!H12 -> 52887 | K11: =ELECT.!K12 -> 9548 | L11: =ELECT.!M12 -> 6241 | M11: =ELECT.!O12 -> 2362 | N11: =ELECT.!Q12 -> 11017 | O11: =ELECT.!S12 -> 12360 | P11: =ELECT.!W12*2 -> 23740 | Q11: =ELECT.!D12 -> 480 | R11: =BTU!C12 -> 3.998 | S11: =BTU!F12 -> 1.03 | T11: =BTU!I12 -> 5 | U11: =BTU!O12 -> 3.264 | V11: =BTU!L12 -> 1.7 | W11: =BTU!R12 -> 0.33 | X11: =ELECT.!B12 -> 320 | Y11: =I11+J11-(K11+L11+M11+N11+O11+P11) -> -3602 | Z11: ='Mall, Citadel, Rotana'!C12+'Mall, Citadel, Rotana'!E12+'Mall, Citadel, Rotana'!G12+'Mall, Citadel, Rotana'!I12 -> 1349 | AA11: ='Mall, Citadel, Rotana'!K12+'Mall, Citadel, Rotana'!M12 -> 120 | AB11: ='Mall, Citadel, Rotana'!O12 -> 46 | AC11: ='Mall, Citadel, Rotana'!Q12+'Mall, Citadel, Rotana'!S12 -> 145 | AD11: =(E11-H11-194)*0.1318 -> 56.966596 | AE11: =E11-H11-AD11-194 -> 375.2534
A12: Cairo at Nile Plaza | B12: =B11+1 -> 11 | C12: 2 | D12: 2023 | E12: =Water!C13 -> 760 | F12: =Water!E13 -> 360 | G12: =Water!G13 -> 423.9 | H12: =Water!I13 -> 4.536 | I12: =ELECT.!F13 -> 7685 | J12: =ELECT.!H13 -> 44951 | K12: =ELECT.!K13 -> 8412 | L12: =ELECT.!M13 -> 5458 | M12: =ELECT.!O13 -> 2066 | N12: =ELECT.!Q13 -> 9703 | O12: =ELECT.!S13 -> 9843 | P12: =ELECT.!W13*2 -> 20362 | Q12: =ELECT.!D13 -> 480 | R12: =BTU!C13 -> 4.747 | S12: =BTU!F13 -> 0.974 | T12: =BTU!I13 -> 5 | U12: =BTU!O13 -> 3.258 | V12: =BTU!L13 -> 1.77 | W12: =BTU!R13 -> 0.43 | X12: =ELECT.!B13 -> 310 | Y12: =I12+J12-(K12+L12+M12+N12+O12+P12) -> -3208 | Z12: ='Mall, Citadel, Rotana'!C13+'Mall, Citadel, Rotana'!E13+'Mall, Citadel, Rotana'!G13+'Mall, Citadel, Rotana'!I13 -> 1217 | AA12: ='Mall, Citadel, Rotana'!K13+'Mall, Citadel, Rotana'!M13 -> 120 | AB12: ='Mall, Citadel, Rotana'!O13 -> 98 | AC12: ='Mall, Citadel, Rotana'!Q13+'Mall, Citadel, Rotana'!S13 -> 112 | AD12: =(E12-H12-194)*0.1318 -> 74.000955 | AE12: =E12-H12-AD12-194 -> 487.46304
A13: Cairo at Nile Plaza | B13: =B12+1 -> 12 | C13: 2 | D13: 2023 | E13: =Water!C14 -> 710 | F13: =Water!E14 -> 400 | G13: =Water!G14 -> 410.4 | H13: =Water!I14 -> 5.049 | I13: =ELECT.!F14 -> 8544 | J13: =ELECT.!H14 -> 49095 | K13: =ELECT.!K14 -> 10780 | L13: =ELECT.!M14 -> 6092 | M13: =ELECT.!O14 -> 2290 | N13: =ELECT.!Q14 -> 10693 | O13: =ELECT.!S14 -> 11115 | P13: =ELECT.!W14*2 -> 21734 | Q13: =ELECT.!D14 -> 480 | R13: =BTU!C14 -> 4.906 | S13: =BTU!F14 -> 1.299 | T13: =BTU!I14 -> 5 | U13: =BTU!O14 -> 3.413 | V13: =BTU!L14 -> 1.62 | W13: =BTU!R14 -> 0.4 | X13: =ELECT.!B14 -> 321 | Y13: =I13+J13-(K13+L13+M13+N13+O13+P13) -> -5065 | Z13: ='Mall, Citadel, Rotana'!C14+'Mall, Citadel, Rotana'!E14+'Mall, Citadel, Rotana'!G14+'Mall, Citadel, Rotana'!I14 -> 1192 | AA13: ='Mall, Citadel, Rotana'!K14+'Mall, Citadel, Rotana'!M14 -> 240 | AB13: ='Mall, Citadel, Rotana'!O14 -> 122 | AC13: ='Mall, Citadel, Rotana'!Q14+'Mall, Citadel, Rotana'!S14 -> 0 | AD13: =(E13-H13-194)*0.1318 -> 67.343342 | AE13: =E13-H13-AD13-194 -> 443.60766
A14: Cairo at Nile Plaza | B14: =B13+1 -> 13 | C14: 2 | D14: 2023 | E14: =Water!C15 -> 770 | F14: =Water!E15 -> 360 | G14: =Water!G15 -> 380.7 | H14: =Water!I15 -> 4.86 | I14: =ELECT.!F15 -> 9477 | J14: =ELECT.!H15 -> 54089 | K14: =ELECT.!K15 -> 8552 | L14: =ELECT.!M15 -> 6643 | M14: =ELECT.!O15 -> 2660 | N14: =ELECT.!Q15 -> 11414 | O14: =ELECT.!S15 -> 12641 | P14: =ELECT.!W15*2 -> 23884 | Q14: =ELECT.!D15 -> 480 | R14: =BTU!C15 -> 4.877 | S14: =BTU!F15 -> 1.648 | T14: =BTU!I15 -> 5 | U14: =BTU!O15 -> 3.057 | V14: =BTU!L15 -> 1.56 | W14: =BTU!R15 -> 0.43 | X14: =ELECT.!B15 -> 308 | Y14: =I14+J14-(K14+L14+M14+N14+O14+P14) -> -2228 | Z14: ='Mall, Citadel, Rotana'!C15+'Mall, Citadel, Rotana'!E15+'Mall, Citadel, Rotana'!G15+'Mall, Citadel, Rotana'!I15 -> 1354 | AA14: ='Mall, Citadel, Rotana'!K15+'Mall, Citadel, Rotana'!M15 -> 180 | AB14: ='Mall, Citadel, Rotana'!O15 -> 116 | AC14: ='Mall, Citadel, Rotana'!Q15+'Mall, Citadel, Rotana'!S15 -> 261 | AD14: =(E14-H14-194)*0.1318 -> 75.276252 | AE14: =E14-H14-AD14-194 -> 495.86375
... A32: Cairo at Nile Plaza | B32: =B31+1 -> 31 | C32: 2 | D32: 2023 | E32: =Water!C33 -> 0 | F32: =Water!E33 -> 0 | G32: =Water!G33 -> 0 | H32: =Water!I33 -> 0 | I32: =ELECT.!F33 -> 0 | J32: =ELECT.!H33 -> 0 | K32: =ELECT.!K33 -> 0 | L32: =ELECT.!M33 -> 0 | M32: =ELECT.!O33 -> 0 | N32: =ELECT.!Q33 -> 0 | O32: =ELECT.!S33 -> 0 | P32: =ELECT.!W33*2 -> 0 | Q32: =ELECT.!D33 -> 0 | R32: =BTU!C33 -> 0 | S32: =BTU!F33 -> 0 | T32: =BTU!I33 -> 0 | U32: =BTU!O33 -> 0 | V32: =BTU!L33 -> 0 | W32: =BTU!R33 -> 0 | X32: =ELECT.!B33 -> 0 | Y32: =I32+J32-(K32+L32+M32+N32+O32+P32) -> 0 | Z32: ='Mall, Citadel, Rotana'!C33+'Mall, Citadel, Rotana'!E33+'Mall, Citadel, Rotana'!G33+'Mall, Citadel, Rotana'!I33 -> 0 | AA32: ='Mall, Citadel, Rotana'!K33+'Mall, Citadel, Rotana'!M33 -> 0 | AB32: ='Mall, Citadel, Rotana'!O33 -> 0 | AC32: ='Mall, Citadel, Rotana'!Q33+'Mall, Citadel, Rotana'!S33 -> 0 | AD32: =(E32-H32-194)*0.1318 -> -25.5692 | AE32: =E32-H32-AD32-194 -> -168.4308

Sheet Mall, Citadel, Rotana
A1: Day | B1: R1 | C1: Cons | D1: R2 | E1: Cons | F1: R3 | G1: Cons | H1: R4 | I1: Cons | J1: RO1 | K1: Cons | L1: RO2 | M1: Cons | N1: ROE | O1: Cons | P1: CIB. 1 | Q1: Cons | R1: CIB. E | S1: Cons | T1: Co | U1: Cons
A2: 44985 | B2: 48315 | D2: 41451 | F2: 22651 | H2: 262062 | J2: 349512 | L2: 27001 | N2: 233490 | P2: 191923 | R2: 55047 | T2: 4197
A3: 44986 | B3: 48319 | C3: =(B3-B2)*800/5 -> 640 | D3: 41454 | E3: =(D3-D2)*800/5 -> 480 | F3: 22654 | G3: =(F3-F2)*100/5 -> 60 | H3: 262078 | I3: =(H3-H2) -> 16 | J3: 349512 | K3: =(J3-J2) -> 0 | L3: 27005 | M3: =(L3-L2)*300/5 -> 240 | N3: 233606 | O3: =N3-N2 -> 116 | P3: 192043 | Q3: =P3-P2 -> 120 | R3: =R2 -> 55047 | S3: 0 | T3: 4199 | U3: =(T3-T2)*800/5 -> 320
A4: 44987 | B4: 48323 | C4: =(B4-B3)*800/5 -> 640 | D4: 41456 | E4: =(D4-D3)*800/5 -> 320 | F4: 22657 | G4: =(F4-F3)*100/5 -> 60 | H4: 262093 | I4: =(H4-H3) -> 15 | J4: 349512 | K4: =(J4-J3) -> 0 | L4: 27008 | M4: =(L4-L3)*300/5 -> 180 | N4: 233771 | O4: =N4-N3 -> 165 | P4: 192163 | Q4: =P4-P3 -> 120 | R4: =R3 -> 55047 | S4: 0 | T4: 4200 | U4: =(T4-T3)*800/5 -> 160
A5: 44988 | B5: 48327 | C5: =(B5-B4)*800/5 -> 640 | D5: 41459 | E5: =(D5-D4)*800/5 -> 480 | F5: 22659 | G5: =(F5-F4)*100/5 -> 40 | H5: 262111 | I5: =(H5-H4) -> 18 | J5: 349512 | K5: =(J5-J4) -> 0 | L5: 27011 | M5: =(L5-L4)*300/5 -> 180 | N5: 233833 | O5: =N5-N4 -> 62 | P5: 192284 | Q5: =P5-P4 -> 121 | R5: 55047 | S5: =R5-R4 -> 0 | T5: 4201 | U5: =(T5-T4)*800/5 -> 160
A6: 44989 | B6: 48331 | C6: =(B6-B5)*800/5 -> 640 | D6: 41462 | E6: =(D6-D5)*800/5 -> 480 | F6: 22661 | G6: =(F6-F5)*100/5 -> 40 | H6: 262126 | I6: =(H6-H5) -> 15 | J6: 349512 | K6: =(J6-J5) -> 0 | L6: 27013 | M6: =(L6-L5)*300/5 -> 120 | N6: 233952 | O6: =N6-N5 -> 119 | P6: 192402 | Q6: =P6-P5 -> 118 | R6: 55047 | S6: 0 | T6: 4202 | U6: =(T6-T5)*800/5 -> 160
A7: 44990 | B7: 48334 | C7: =(B7-B6)*800/5 -> 480 | D7: 41465 | E7: =(D7-D6)*800/5 -> 480 | F7: 22665 | G7: =(F7-F6)*100/5 -> 80 | H7: 262139 | I7: =(H7-H6) -> 13 | J7: 349512 | K7: =(J7-J6) -> 0 | L7: 27016 | M7: =(L7-L6)*300/5 -> 180 | N7: 234060 | O7: =N7-N6 -> 108 | P7: 192522 | Q7: =P7-P6 -> 120 | R7: 55047 | S7: 0 | T7: 4203 | U7: =(T7-T6)*800/5 -> 160
A8: 44991 | B8: 48338 | C8: =(B8-B7)*800/5 -> 640 | D8: 41467 | E8: =(D8-D7)*800/5 -> 320 | F8: 22671 | G8: =(F8-F7)*100/5 -> 120 | H8: 262139 | I8: =(H8-H7) -> 0 | J8: 349512 | K8: =(J8-J7) -> 0 | L8: 27020 | M8: =(L8-L7)*300/5 -> 240 | N8: 234119 | O8: =N8-N7 -> 59 | P8: 192641 | Q8: =P8-P7 -> 119 | R8: 55047 | S8: =R8-R7 -> 0 | T8: 4204 | U8: =(T8-T7)*800/5 -> 160
A9: 44992 | B9: 48345 | C9: =(B9-B8)*800/5 -> 1120 | D9: 41470 | E9: =(D9-D8)*800/5 -> 480 | F9: 22674 | G9: =(F9-F8)*100/5 -> 60 | H9: 262160 | I9: =(H9-H8) -> 21 | J9: 349512 | K9: 0 | L9: 27023 | M9: =(L9-L8)*300/5 -> 180 | N9: 234229 | O9: =N9-N8 -> 110 | P9: 192822 | Q9: =P9-P8 -> 181 | R9: =R8 -> 55047 | S9: =R9-R8 -> 0 | T9: 4205 | U9: =(T9-T8)*800/5 -> 160
A10: 44993 | B10: 48349 | C10: =(B10-B9)*800/5 -> 640 | D10: 41473 | E10: =(D10-D9)*800/5 -> 480 | F10: 22677 | G10: =(F10-F9)*100/5 -> 60 | H10: 262173 | I10: =(H10-H9) -> 13 | J10: 349512 | K10: =(J10-J9) -> 0 | L10: 27027 | M10: =(L10-L9)*300/5 -> 240 | N10: 234344 | O10: =N10-N9 -> 115 | P10: 192822 | Q10: =P10-P9 -> 0 | R10: =R9 -> 55047 | S10: =R10-R9 -> 0 | T10: 4208 | U10: =(T10-T9)*800/5 -> 480
A11: 44994 | B11: 48354 | C11: =(B11-B10)*800/5 -> 800 | D11: 41476 | E11: =(D11-D10)*800/5 -> 480 | F11: 22681 | G11: =(F11-F10)*100/5 -> 80 | H11: 262186 | I11: =(H11-H10) -> 13 | J11: 349512 | K11: =(J11-J10) -> 0 | L11: 27031 | M11: =(L11-L10)*300/5 -> 240 | N11: 234497 | O11: =N11-N10 -> 153 | P11: 193115 | Q11: =P11-P10 -> 293 | R11: =R10 -> 55047 | S11: =R11-R10 -> 0 | T11: 4209 | U11: =(T11-T10)*800/5 -> 160
A12: 44995 | B12: 48359 | C12: =(B12-B11)*800/5 -> 800 | D12: 41479 | E12: =(D12-D11)*800/5 -> 480 | F12: 22684 | G12: =(F12-F11)*100/5 -> 60 | H12: 262195 | I12: =(H12-H11) -> 9 | J12: 349512 | K12: =(J12-J11) -> 0 | L12: 27033 | M12: =(L12-L11)*300/5 -> 120 | N12: 234543 | O12: =N12-N11 -> 46 | P12: 193260 | Q12: =P12-P11 -> 145 | R12: =R11 -> 55047 | S12: =R12-R11 -> 0 | T12: 4210 | U12: =(T12-T11)*800/5 -> 160
A13: 44996 | B13: 48363 | C13: =(B13-B12)*800/5 -> 640 | D13: 41482 | E13: =(D13-D12)*800/5 -> 480 | F13: 22688 | G13: =(F13-F12)*100/5 -> 80 | H13: 262212 | I13: =(H13-H12) -> 17 | J13: 349512 | K13: =(J13-J12) -> 0 | L13: 27035 | M13: =(L13-L12)*300/5 -> 120 | N13: 234641 | O13: =N13-N12 -> 98 | P13: 193372 | Q13: =P13-P12 -> 112 | R13: =R12 -> 55047 | S13: =R13-R12 -> 0 | T13: 4211 | U13: =(T13-T12)*800/5 -> 160
A14: 44997 | B14: 48368 | C14: =(B14-B13)*800/5 -> 800 | D14: 41484 | E14: =(D14-D13)*800/5 -> 320 | F14: 22691 | G14: =(F14-F13)*100/5 -> 60 | H14: 262224 | I14: =(H14-H13) -> 12 | J14: 349512 | K14: =(J14-J13) -> 0 | L14: 27039 | M14: =(L14-L13)*300/5 -> 240 | N14: 234763 | O14: =N14-N13 -> 122 | P14: =P13 -> 193372 | Q14: =P14-P13 -> 0 | R14: =R13 -> 55047 | S14: 0 | T14: 4213 | U14: =(T14-T13)*800/5 -> 320
A15: 44998 | B15: 48373 | C15: =(B15-B14)*800/5 -> 800 | D15: 41487 | E15: =(D15-D14)*800/5 -> 480 | F15: 22694 | G15: =(F15-F14)*100/5 -> 60 | H15: 262238 | I15: =(H15-H14) -> 14 | J15: 349512 | K15: =(J15-J14) -> 0 | L15: 27042 | M15: =(L15-L14)*300/5 -> 180 | N15: 234879 | O15: =N15-N14 -> 116 | P15: 193633 | Q15: =P15-P14 -> 261 | R15: 55047 | S15: 0 | T15: 4214 | U15: =(T15-T14)*800/5 -> 160
A16: 44999 | B16: 48377 | C16: =(B16-B15)*800/5 -> 640 | D16: 41490 | E16: =(D16-D15)*800/5 -> 480 | F16: 22697 | G16: =(F16-F15)*100/5 -> 60 | H16: 262255 | I16: =(H16-H15) -> 17 | J16: 349512 | K16: =(J16-J15) -> 0 | L16: 27045 | M16: =(L16-L15)*300/5 -> 180 | N16: 235000 | O16: =N16-N15 -> 121 | P16: =P15 -> 193633 | Q16: =P16-P15 -> 0 | R16: =R15 -> 55047 | S16: =R16-R15 -> 0 | T16: 4215 | U16: =(T16-T15)*800/5 -> 160
A17: 45000 | B17: 48382 | C17: =(B17-B16)*800/5 -> 800 | D17: 41493 | E17: =(D17-D16)*800/5 -> 480 | F17: 22701 | G17: =(F17-F16)*100/5 -> 80 | H17: 262271 | I17: =(H17-H16) -> 16 | J17: 349512 | K17: =(J17-J16) -> 0 | L17: 27049 | M17: =(L17-L16)*300/5 -> 240 | N17: 235121 | O17: =N17-N16 -> 121 | P17: 193857 | Q17: =P17-P16 -> 224 | R17: =R16 -> 55047 | S17: =S16 -> 0 | T17: 4217 | U17: =(T17-T16)*800/5 -> 320
A18: 45001 | B18: 48386 | C18: =(B18-B17)*800/5 -> 640 | D18: 41496 | E18: =(D18-D17)*800/5 -> 480 | F18: 22705 | G18: =(F18-F17)*100/5 -> 80 | H18: 262293 | I18: =(H18-H17) -> 22 | J18: 349512 | K18: =(J18-J17) -> 0 | L18: 27052 | M18: =(L18-L17)*300/5 -> 180 | N18: 235235 | O18: =N18-N17 -> 114 | P18: =P17 -> 193857 | Q18: =P18-P17 -> 0 | R18: =R17 -> 55047 | S18: =R18-R17 -> 0 | T18: 4218 | U18: =(T18-T17)*800/5 -> 160
A19: 45002 | B19: 48391 | C19: =(B19-B18)*800/5 -> 800 | D19: 41499 | E19: =(D19-D18)*800/5 -> 480 | F19: 22708 | G19: =(F19-F18)*100/5 -> 60 | H19: 262304 | I19: =(H19-H18) -> 11 | J19: 349512 | K19: =(J19-J18) -> 0 | L19: 27054 | M19: =(L19-L18)*300/5 -> 120 | N19: 235318 | O19: =N19-N18 -> 83 | P19: =P18 -> 193857 | Q19: =P19-P18 -> 0 | R19: =R18 -> 55047 | S19: =R19-R18 -> 0 | T19: 4219 | U19: =(T19-T18)*800/5 -> 160
A20: 45003 | B20: 48395 | C20: =(B20-B19)*800/5 -> 640 | D20: 41502 | E20: =(D20-D19)*800/5 -> 480 | F20: 22712 | G20: =(F20-F19)*100/5 -> 80 | H20: 262323 | I20: =(H20-H19) -> 19 | J20: =J19 -> 349512 | K20: =(J20-J19) -> 0 | L20: 27056 | M20: =(L20-L19)*300/5 -> 120 | N20: 235395 | O20: =N20-N19 -> 77 | P20: 194275 | Q20: =P20-P19 -> 418 | R20: 55047 | S20: =R20-R19 -> 0 | T20: 4220 | U20: =(T20-T19)*800/5 -> 160
A21: 45004 | B21: 48399 | C21: =(B21-B20)*800/5 -> 640 | D21: 41505 | E21: =(D21-D20)*800/5 -> 480 | F21: 22715 | G21: =(F21-F20)*100/5 -> 60 | H21: 262333 | I21: =(H21-H20) -> 10 | J21: 349512 | K21: =(J21-J20) -> 0 | L21: 27060 | M21: =(L21-L20)*300/5 -> 240 | N21: 235516 | O21: =N21-N20 -> 121 | P21: =P20 -> 194275 | Q21: =P21-P20 -> 0 | R21: 55047 | S21: =R21-R20 -> 0 | T21: 4222 | U21: =(T21-T20)*800/5 -> 320
A22: 45005 | B22: 48404 | C22: =(B22-B21)*800/5 -> 800 | D22: 41508 | E22: =(D22-D21)*800/5 -> 480 | F22: 22718 | G22: =(F22-F21)*100/5 -> 60 | H22: 262355 | I22: =(H22-H21) -> 22 | J22: 349512 | K22: =(J22-J21) -> 0 | L22: 27064 | M22: =(L22-L21)*300/5 -> 240 | N22: 235643 | O22: =N22-N21 -> 127 | P22: =P21 -> 194275 | Q22: =P22-P21 -> 0 | R22: =R21 -> 55047 | S22: =R22-R21 -> 0 | T22: 4223 | U22: =(T22-T21)*800/5 -> 160
A23: 45006 | B23: =B22 -> 48404 | C23: =(B23-B22)*800/5 -> 0 | D23: =D22 -> 41508 | E23: =(D23-D22)*800/5 -> 0 | F23: =F22 -> 22718 | G23: =(F23-F22)*100/5 -> 0 | H23: =H22 -> 262355 | I23: =(H23-H22) -> 0 | J23: =J22 -> 349512 | K23: =(J23-J22) -> 0 | L23: =L22 -> 27064 | M23: =(L23-L22)*300/5 -> 0 | N23: =N22 -> 235643 | O23: =N23-N22 -> 0 | P23: =P22 -> 194275 | Q23: =P23-P22 -> 0 | R23: =R22 -> 55047 | S23: =R23-R22 -> 0 | T23: =T22 -> 4223 | U23: =(T23-T22)*800/5 -> 0
A24: 45007 | B24: =B23 -> 48404 | C24: =(B24-B23)*800/5 -> 0 | D24: =D23 -> 41508 | E24: =(D24-D23)*800/5 -> 0 | F24: =F23 -> 22718 | G24: =(F24-F23)*100/5 -> 0 | H24: =H23 -> 262355 | I24: =(H24-H23) -> 0 | J24: =J23 -> 349512 | K24: =(J24-J23) -> 0 | L24: =L23 -> 27064 | M24: =(L24-L23)*300/5 -> 0 | N24: =N23 -> 235643 | O24: =N24-N23 -> 0 | P24: =P23 -> 194275 | Q24: =P24-P23 -> 0 | R24: =R23 -> 55047 | S24: =R24-R23 -> 0 | T24: =T23 -> 4223 | U24: =(T24-T23)*800/5 -> 0
A25: 45008 | B25: =B24 -> 48404 | C25: =(B25-B24)*800/5 -> 0 | D25: =D24 -> 41508 | E25: =(D25-D24)*800/5 -> 0 | F25: =F24 -> 22718 | G25: =(F25-F24)*100/5 -> 0 | H25: =H24 -> 262355 | I25: =(H25-H24) -> 0 | J25: =J24 -> 349512 | K25: =(J25-J24) -> 0 | L25: =L24 -> 27064 | M25: =(L25-L24)*300/5 -> 0 | N25: =N24 -> 235643 | O25: =N25-N24 -> 0 | P25: =P24 -> 194275 | Q25: =P25-P24 -> 0 | R25: =R24 -> 55047 | S25: =R25-R24 -> 0 | T25: =T24 -> 4223 | U25: =(T25-T24)*800/5 -> 0
A26: 45009 | B26: =B25 -> 48404 | C26: =(B26-B25)*800/5 -> 0 | D26: =D25 -> 41508 | E26: =(D26-D25)*800/5 -> 0 | F26: =F25 -> 22718 | G26: =(F26-F25)*100/5 -> 0 | H26: =H25 -> 262355 | I26: =(H26-H25) -> 0 | J26: =J25 -> 349512 | K26: =(J26-J25) -> 0 | L26: =L25 -> 27064 | M26: =(L26-L25)*300/5 -> 0 | N26: =N25 -> 235643 | O26: =N26-N25 -> 0 | P26: =P25 -> 194275 | Q26: =P26-P25 -> 0 | R26: =R25 -> 55047 | S26: =R26-R25 -> 0 | T26: =T25 -> 4223 | U26: =(T26-T25)*800/5 -> 0
A27: 45010 | B27: =B26 -> 48404 | C27: =(B27-B26)*800/5 -> 0 | D27: =D26 -> 41508 | E27: =(D27-D26)*800/5 -> 0 | F27: =F26 -> 22718 | G27: =(F27-F26)*100/5 -> 0 | H27: =H26 -> 262355 | I27: =(H27-H26) -> 0 | J27: =J26 -> 349512 | K27: =(J27-J26) -> 0 | L27: =L26 -> 27064 | M27: =(L27-L26)*300/5 -> 0 | N27: =N26 -> 235643 | O27: =N27-N26 -> 0 | P27: =P26 -> 194275 | Q27: =P27-P26 -> 0 | R27: =R26 -> 55047 | S27: =R27-R26 -> 0 | T27: =T26 -> 4223 | U27: =(T27-T26)*800/5 -> 0
A28: 45011 | B28: =B27 -> 48404 | C28: =(B28-B27)*800/5 -> 0 | D28: =D27 -> 41508 | E28: =(D28-D27)*800/5 -> 0 | F28: =F27 -> 22718 | G28: =(F28-F27)*100/5 -> 0 | H28: =H27 -> 262355 | I28: =(H28-H27) -> 0 | J28: =J27 -> 349512 | K28: =(J28-J27) -> 0 | L28: =L27 -> 27064 | M28: =(L28-L27)*300/5 -> 0 | N28: =N27 -> 235643 | O28: =N28-N27 -> 0 | P28: =P27 -> 194275 | Q28: =P28-P27 -> 0 | R28: =R27 -> 55047 | S28: =R28-R27 -> 0 | T28: =T27 -> 4223 | U28: =(T28-T27)*800/5 -> 0
A29: 45012 | B29: =B28 -> 48404 | C29: =(B29-B28)*800/5 -> 0 | D29: =D28 -> 41508 | E29: =(D29-D28)*800/5 -> 0 | F29: =F28 -> 22718 | G29: =(F29-F28)*100/5 -> 0 | H29: =H28 -> 262355 | I29: =(H29-H28) -> 0 | J29: =J28 -> 349512 | K29: =(J29-J28) -> 0 | L29: =L28 -> 27064 | M29: =(L29-L28)*300/5 -> 0 | N29: =N28 -> 235643 | O29: =N29-N28 -> 0 | P29: =P28 -> 194275 | Q29: =P29-P28 -> 0 | R29: 55047 | S29: =R29-R28 -> 0 | T29: =T28 -> 4223 | U29: =(T29-T28)*800/5 -> 0
A30: 45013 | B30: =B29 -> 48404 | C30: =(B30-B29)*800/5 -> 0 | D30: =D29 -> 41508 | E30: =(D30-D29)*800/5 -> 0 | F30: =F29 -> 22718 | G30: =(F30-F29)*100/5 -> 0 | H30: =H29 -> 262355 | I30: =(H30-H29) -> 0 | J30: =J29 -> 349512 | K30: =(J30-J29) -> 0 | L30: =L29 -> 27064 | M30: =(L30-L29)*300/5 -> 0 | N30: =N29 -> 235643 | O30: =N30-N29 -> 0 | P30: =P29 -> 194275 | Q30: =P30-P29 -> 0 | R30: =R29 -> 55047 | S30: =R30-R29 -> 0 | T30: =T29 -> 4223 | U30: =(T30-T29)*800/5 -> 0
A31: 45014 | B31: =B30 -> 48404 | C31: =(B31-B30)*800/5 -> 0 | D31: =D30 -> 41508 | E31: =(D31-D30)*800/5 -> 0 | F31: =F30 -> 22718 | G31: =(F31-F30)*100/5 -> 0 | H31: =H30 -> 262355 | I31: =(H31-H30) -> 0 | J31: =J30 -> 349512 | K31: =(J31-J30) -> 0 | L31: =L30 -> 27064 | M31: =(L31-L30)*300/5 -> 0 | N31: =N30 -> 235643 | O31: =N31-N30 -> 0 | P31: =P30 -> 194275 | Q31: =P31-P30 -> 0 | R31: =R30 -> 55047 | S31: =R31-R30 -> 0 | T31: =T30 -> 4223 | U31: =(T31-T30)*800/5 -> 0
A32: 45015 | B32: =B31 -> 48404 | C32: =(B32-B31)*800/5 -> 0 | D32: =D31 -> 41508 | E32: =(D32-D31)*800/5 -> 0 | F32: =F31 -> 22718 | G32: =(F32-F31)*100/5 -> 0 | H32: =H31 -> 262355 | I32: =(H32-H31) -> 0 | J32: =J31 -> 349512 | K32: =(J32-J31) -> 0 | L32: =L31 -> 27064 | M32: =(L32-L31)*300/5 -> 0 | N32: =N31 -> 235643 | O32: =N32-N31 -> 0 | P32: =P31 -> 194275 | Q32: =P32-P31 -> 0 | R32: =R31 -> 55047 | S32: =R32-R31 -> 0 | T32: =T31 -> 4223 | U32: =(T32-T31)*800/5 -> 0
A33: 45016 | B33: =B32 -> 48404 | C33: =(B33-B32)*800/5 -> 0 | D33: =D32 -> 41508 | E33: =(D33-D32)*800/5 -> 0 | F33: =F32 -> 22718 | G33: =(F33-F32)*100/5 -> 0 | H33: =H32 -> 262355 | I33: =(H33-H32) -> 0 | J33: =J32 -> 349512 | K33: =(J33-J32) -> 0 | L33: =L32 -> 27064 | M33: =(L33-L32)*300/5 -> 0 | N33: =N32 -> 235643 | O33: =N33-N32 -> 0 | P33: =P32 -> 194275 | Q33: =P33-P32 -> 0 | R33: =R32 -> 55047 | S33: =R33-R32 -> 0 | T33: =T32 -> 4223 | U33: =(T33-T32)*800/5 -> 0
A34: Total | C34: =SUM(C3:C33) -> 14240 | E34: =SUM(E3:E33) -> 9120 | G34: =SUM(G3:G33) -> 1340 | I34: =SUM(I3:I33) -> 293 | K34: =SUM(K3:K33) -> 0 | M34: =SUM(M3:M33) -> 3780 | O34: =SUM(O3:O33) -> 2153 | Q34: =SUM(Q3:Q33) -> 2352 | S34: =SUM(S3:S33) -> 0 | U34: =SUM(U3:U33) -> 4160

Sheet ELECT.
A1: Day | B1: Rooms Sold | C1: New Chillers | D1: Cons | E1: F-1 | F1: Cons. | G1: F-2 | H1: Cons. | I1: Total | J1: T-1 | K1: Cons. | L1: T-2 | M1: Cons. | N1: T-3 | O1: Cons. | P1: T-4 | Q1: Cons. | R1: T-5 | S1: Cons. | T1: T-6 | U1: Cons. | V1: T-7 | W1: Cons. | X1: Total | Y1: Diff | Z1: Daily Money Value | AA1: MTD Total Money
A2: 44985 | B2: 272 | C2: 20588 | E2: 35988211 | G2: 13096752 | I2: =F2+H2 -> 0 | J2: 1431498 | L2: 1764229 | N2: 8229214 | P2: 9311652 | R2: 24164694 | V2: 2180893 | X2: =K2+M2+O2+Q2+S2+U2+W2 -> 0 | Y2: =I2-X2 -> 0 | Z2: =(0.93352*(W2+S2)+0.5568*(Q2+O2))*0.26 -> 0
A3: 44986 | B3: 305 | C3: 20590 | D3: =IF((C3-C2)<0,"0",(C3-C2))*160 -> 320 | E3: 35997929 | F3: =IF((E3-E2)<0,"0",(E3-E2)) -> 9718 | G3: 13153573 | H3: =IF((G3-G2)<0,"0",(G3-G2)) -> 56821 | I3: =F3+H3 -> 66539 | J3: 1437236 | K3: =(IF((J3-J2)<L86,"0",(J3-J2)))*2 -> 11476 | L3: 1770788 | M3: =IF((L3-L2)<0,"0",(L3-L2)) -> 6559 | N3: 8230704 | O3: =(IF((N3-N2)<P86,"0",(N3-N2)))*2 -> 2980 | P3: 9323378 | Q3: =IF((P3-P2)<0,"0",(P3-P2)) -> 11726 | R3: 24178296 | S3: =IF((R3-R2)<0,"0",(R3-R2)) -> 13602 | V3: 2193196 | W3: =IF((V3-V2)<0,"0",(V3-V2)) -> 12303 | X3: =K3+M3+O3+Q3+S3+U3+W3 -> 58646 | Y3: =I3-X3 -> 7893 | Z3: =(0.93352*(W3+S3)+0.5568*(Q3+O3))*0.26 -> 8416.4955 | AA3: =SUM(Z1:Z3) -> 8416.4955
A4: 44987 | B4: 295 | C4: 20593 | D4: =IF((C4-C3)<0,"0",(C4-C3))*160 -> 480 | E4: 36003012 | F4: =IF((E4-E3)<0,"0",(E4-E3)) -> 5083 | G4: 13184592 | H4: =IF((G4-G3)<0,"0",(G4-G3)) -> 31019 | I4: =F4+H4 -> 36102 | J4: 1440553 | K4: =(IF((J4-J3)<L88,"0",(J4-J3)))*2 -> 6634 | L4: 1774427 | M4: =IF((L4-L3)<0,"0",(L4-L3)) -> 3639 | N4: 8231691 | O4: =(IF((N4-N3)<P88,"0",(N4-N3)))*2 -> 1974 | P4: 9329485 | Q4: =IF((P4-P3)<0,"0",(P4-P3)) -> 6107 | R4: 24185681 | S4: =IF((R4-R3)<0,"0",(R4-R3)) -> 7385 | V4: 2199921 | W4: =IF((V4-V3)<0,"0",(V4-V3)) -> 6725 | X4: =K4+M4+O4+Q4+S4+U4+W4 -> 32464 | Y4: =I4-X4 -> 3638 | Z4: =(0.93352*(W4+S4)+0.5568*(Q4+O4))*0.26 -> 4594.5817 | AA4: =SUM(Z1:Z4) -> 13011.077
A5: 44988 | B5: 294 | C5: 20595 | D5: =IF((C5-C4)<0,"0",(C5-C4))*160 -> 320 | E5: 36011464 | F5: =IF((E5-E4)<0,"0",(E5-E4)) -> 8452 | G5: 13234179 | H5: =IF((G5-G4)<0,"0",(G5-G4)) -> 49587 | I5: =F5+H5 -> 58039 | J5: 1445164 | K5: =(IF((J5-J4)<0,"0",(J5-J4)))*2 -> 9222 | L5: 1780266 | M5: =IF((L5-L4)<0,"0",(L5-L4)) -> 5839 | N5: 8232587 | O5: =(IF((N5-N4)<0,"0",(N5-N4)))*2 -> 1792 | P5: 9339401 | Q5: =IF((P5-P4)<0,"0",(P5-P4)) -> 9916 | R5: 24197584 | S5: =IF((R5-R4)<0,"0",(R5-R4)) -> 11903 | V5: 2211070 | W5: =IF((V5-V4)<0,"0",(V5-V4)) -> 11149 | X5: =K5+M5+O5+Q5+S5+U5+W5 -> 49821 | Y5: =I5-X5 -> 8218 | Z5: =(0.93352*(W5+S5)+0.5568*(Q5+O5))*0.26 -> 7290.0145 | AA5: =SUM(Z1:Z5) -> 20301.092
A6: 44989 | B6: 310 | C6: 20597 | D6: =IF((C6-C5)<0,"0",(C6-C5))*160 -> 320 | E6: 36018914 | F6: =IF((E6-E5)<0,"0",(E6-E5)) -> 7450 | G6: 13277852 | H6: =IF((G6-G5)<0,"0",(G6-G5)) -> 43673 | I6: =F6+H6 -> 51123 | J6: 1449229 | K6: =(IF((J6-J5)<0,"0",(J6-J5)))*2 -> 8130 | L6: 1785440 | M6: =IF((L6-L5)<0,"0",(L6-L5)) -> 5174 | N6: 8233649 | O6: =(IF((N6-N5)<0,"0",(N6-N5)))*2 -> 2124 | P6: 9348610 | Q6: =IF((P6-P5)<0,"0",(P6-P5)) -> 9209 | R6: 24207987 | S6: =IF((R6-R5)<0,"0",(R6-R5)) -> 10403 | V6: 2220624 | W6: =IF((V6-V5)<0,"0",(V6-V5)) -> 9554 | X6: =K6+M6+O6+Q6+S6+U6+W6 -> 44594 | Y6: =I6-X6 -> 6529 | Z6: =(0.93352*(W6+S6)+0.5568*(Q6+O6))*0.26 -> 6484.523 | AA6: =SUM(Z1:Z6) -> 26785.615
A7: 44990 | B7: 318 | C7: 20599 | D7: =IF((C7-C6)<0,"0",(C7-C6))*160 -> 320 | E7: 36028035 | F7: =IF((E7-E6)<0,"0",(E7-E6)) -> 9121 | G7: 13330092 | H7: =IF((G7-G6)<0,"0",(G7-G6)) -> 52240 | I7: =F7+H7 -> 61361 | J7: 1454432 | K7: =(IF((J7-J6)<0,"0",(J7-J6)))*2 -> 10406 | L7: 1791996 | M7: =IF((L7-L6)<0,"0",(L7-L6)) -> 6556 | N7: 8234840 | O7: =(IF((N7-N6)<0,"0",(N7-N6)))*2 -> 2382 | P7: 9359285 | Q7: =IF((P7-P6)<0,"0",(P7-P6)) -> 10675 | R7: 24220348 | S7: =IF((R7-R6)<0,"0",(R7-R6)) -> 12361 | V7: 2232083 | W7: =IF((V7-V6)<0,"0",(V7-V6)) -> 11459 | X7: =K7+M7+O7+Q7+S7+U7+W7 -> 53839 | Y7: =Y6 -> 6529 | Z7: =(0.93352*(W7+S7)+0.5568*(Q7+O7))*0.26 -> 7671.7118 | AA7: =SUM(Z1:Z7) -> 34457.327
A8: 44991 | B8: 317 | C8: 20601 | D8: =IF((C8-C7)<0,"0",(C8-C7))*160 -> 320 | E8: 36034073 | F8: =IF((E8-E7)<0,"0",(E8-E7)) -> 6038 | G8: 13364008 | H8: =IF((G8-G7)<0,"0",(G8-G7)) -> 33916 | I8: =F8+H8 -> 39954 | J8: 1457345 | K8: =(IF((J8-J7)<0,"0",(J8-J7)))*2 -> 5826 | L8: 1796469 | M8: =IF((L8-L7)<0,"0",(L8-L7)) -> 4473 | N8: 8235562 | O8: =(IF((N8-N7)<0,"0",(N8-N7)))*2 -> 1444 | P8: 9366187 | Q8: =IF((P8-P7)<0,"0",(P8-P7)) -> 6902 | R8: 24228442 | S8: =IF((R8-R7)<0,"0",(R8-R7)) -> 8094 | V8: 2239561 | W8: =IF((V8-V7)<0,"0",(V8-V7)) -> 7478 | X8: =K8+M8+O8+Q8+S8+U8+W8 -> 34217 | Y8: =I8-X8 -> 5737 | Z8: =(0.93352*(W8+S8)+0.5568*(Q8+O8))*0.26 -> 4987.7948 | AA8: =SUM(Z1:Z8) -> 39445.121
A9: 44992 | B9: 319 | C9: 20604 | D9: =IF((C9-C8)<0,"0",(C9-C8))*160 -> 480 | E9: 36043808 | F9: =IF((E9-E8)<0,"0",(E9-E8)) -> 9735 | G9: 13422364 | H9: =IF((G9-G8)<0,"0",(G9-G8)) -> 58356 | I9: =F9+H9 -> 68091 | J9: 1463483 | K9: =(IF((J9-J8)<0,"0",(J9-J8)))*2 -> 12276 | L9: 1803744 | M9: =IF((L9-L8)<0,"0",(L9-L8)) -> 7275 | N9: 8236698 | O9: =(IF((N9-N8)<0,"0",(N9-N8)))*2 -> 2272 | P9: 9377757 | Q9: =IF((P9-P8)<0,"0",(P9-P8)) -> 11570 | R9: 24241961 | S9: =IF((R9-R8)<0,"0",(R9-R8)) -> 13519 | V9: 2252742 | W9: =IF((V9-V8)<0,"0",(V9-V8)) -> 13181 | X9: =K9+M9+O9+Q9+S9+U9+W9 -> 60093 | Y9: =I9-X9 -> 7998 | Z9: =(0.93352*(W9+S9)+0.5568*(Q9+O9))*0.26 -> 8484.3745 | AA9: =SUM(Z1:Z9) -> 47929.496
A10: 44993 | B10: 309 | C10: 20610 | D10: =IF((C10-C9)<0,"0",(C10-C9))*160 -> 960 | E10: 36050853 | F10: =IF((E10-E9)<0,"0",(E10-E9)) -> 7045 | G10: 13460457 | H10: =IF((G10-G9)<0,"0",(G10-G9)) -> 38093 | I10: =F10+H10 -> 45138 | J10: 1467456 | K10: =(IF((J10-J9)<0,"0",(J10-J9)))*2 -> 7946 | L10: 1808816 | M10: =IF((L10-L9)<0,"0",(L10-L9)) -> 5072 | N10: 8237478 | O10: =(IF((N10-N9)<0,"0",(N10-N9)))*2 -> 1560 | P10: 9385253 | Q10: =IF((P10-P9)<0,"0",(P10-P9)) -> 7496 | R10: 24250715 | S10: =IF((R10-R9)<0,"0",(R10-R9)) -> 8754 | V10: 2261311 | W10: =IF((V10-V9)<0,"0",(V10-V9)) -> 8569 | X10: =K10+M10+O10+Q10+S10+U10+W10 -> 39397 | Y10: =I10-X10 -> 5741 | Z10: =(0.93352*(W10+S10)+0.5568*(Q10+O10))*0.26 -> 5515.5744 | AA10: =SUM(Z1:Z10) -> 53445.07
A11: 44994 | B11: 312 | C11: 20613 | D11: =IF((C11-C10)<0,"0",(C11-C10))*160 -> 480 | E11: 36057637 | F11: =IF((E11-E10)<0,"0",(E11-E10)) -> 6784 | G11: 13501444 | H11: =IF((G11-G10)<0,"0",(G11-G10)) -> 40987 | I11: =F11+H11 -> 47771 | J11: 1471500 | K11: =(IF((J11-J10)<0,"0",(J11-J10)))*2 -> 8088 | L11: 1813959 | M11: =IF((L11-L10)<0,"0",(L11-L10)) -> 5143 | N11: 8238365 | O11: =(IF((N11-N10)<0,"0",(N11-N10)))*2 -> 1774 | P11: 9393507 | Q11: =IF((P11-P10)<0,"0",(P11-P10)) -> 8254 | R11: 24259926 | S11: =IF((R11-R10)<0,"0",(R11-R10)) -> 9211 | V11: 2270650 | W11: =IF((V11-V10)<0,"0",(V11-V10)) -> 9339 | X11: =K11+M11+O11+Q11+S11+U11+W11 -> 41809 | Y11: =I11-X11 -> 5962 | Z11: =(0.93352*(W11+S11)+0.5568*(Q11+O11))*0.26 -> 5954.1005 | AA11: =SUM(Z1:Z11) -> 59399.171
A12: 44995 | B12: 320 | C12: 20616 | D12: =IF((C12-C11)<0,"0",(C12-C11))*160 -> 480 | E12: 36066416 | F12: =IF((E12-E11)<0,"0",(E12-E11)) -> 8779 | G12: 13554331 | H12: =IF((G12-G11)<0,"0",(G12-G11)) -> 52887 | I12: =F12+H12 -> 61666 | J12: 1476274 | K12: =(IF((J12-J11)<0,"0",(J12-J11)))*2 -> 9548 | L12: 1820200 | M12: =IF((L12-L11)<0,"0",(L12-L11)) -> 6241 | N12: 8239546 | O12: =(IF((N12-N11)<0,"0",(N12-N11)))*2 -> 2362 | P12: 9404524 | Q12: =IF((P12-P11)<0,"0",(P12-P11)) -> 11017 | R12: 24272286 | S12: =IF((R12-R11)<0,"0",(R12-R11)) -> 12360 | V12: 2282520 | W12: =IF((V12-V11)<0,"0",(V12-V11)) -> 11870 | X12: =K12+M12+O12+Q12+S12+U12+W12 -> 53398 | Y12: =I12-X12 -> 8268 | Z12: =(0.93352*(W12+S12)+0.5568*(Q12+O12))*0.26 -> 7817.8404 | AA12: =SUM(Z1:Z12) -> 67217.011
A13: 44996 | B13: 310 | C13: 20619 | D13: =IF((C13-C12)<0,"0",(C13-C12))*160 -> 480 | E13: 36074101 | F13: =IF((E13-E12)<0,"0",(E13-E12)) -> 7685 | G13: 13599282 | H13: =IF((G13-G12)<0,"0",(G13-G12)) -> 44951 | I13: =F13+H13 -> 52636 | J13: 1480480 | K13: =(IF((J13-J12)<0,"0",(J13-J12)))*2 -> 8412 | L13: 1825658 | M13: =IF((L13-L12)<0,"0",(L13-L12)) -> 5458 | N13: 8240579 | O13: =(IF((N13-N12)<0,"0",(N13-N12)))*2 -> 2066 | P13: 9414227 | Q13: =IF((P13-P12)<0,"0",(P13-P12)) -> 9703 | R13: 24282129 | S13: =IF((R13-R12)<0,"0",(R13-R12)) -> 9843 | V13: 2292701 | W13: =IF((V13-V12)<0,"0",(V13-V12)) -> 10181 | X13: =K13+M13+O13+Q13+S13+U13+W13 -> 45663 | Y13: =I13-X13 -> 6973 | Z13: =(0.93352*(W13+S13)+0.5568*(Q13+O13))*0.26 -> 6563.9038 | AA13: =SUM(Z1:Z13) -> 73780.915
A14: 44997 | B14: 321 | C14: 20622 | D14: =IF((C14-C13)<0,"0",(C14-C13))*160 -> 480 | E14: 36082645 | F14: =IF((E14-E13)<0,"0",(E14-E13)) -> 8544 | G14: 13648377 | H14: =IF((G14-G13)<0,"0",(G14-G13)) -> 49095 | I14: =F14+H14 -> 57639 | J14: 1485870 | K14: =(IF((J14-J13)<0,"0",(J14-J13)))*2 -> 10780 | L14: 1831750 | M14: =IF((L14-L13)<0,"0",(L14-L13)) -> 6092 | N14: 8241724 | O14: =(IF((N14-N13)<0,"0",(N14-N13)))*2 -> 2290 | P14: 9424920 | Q14: =IF((P14-P13)<0,"0",(P14-P13)) -> 10693 | R14: 24293244 | S14: =IF((R14-R13)<0,"0",(R14-R13)) -> 11115 | V14: 2303568 | W14: =IF((V14-V13)<0,"0",(V14-V13)) -> 10867 | X14: =K14+M14+O14+Q14+S14+U14+W14 -> 51837 | Y14: =I14-X14 -> 5802 | Z14: =(0.93352*(W14+S14)+0.5568*(Q14+O14))*0.26 -> 7214.8885 | AA14: =SUM(Z1:Z14) -> 80995.803
A15: 44998 | B15: 308 | C15: 20625 | D15: =IF((C15-C14)<0,"0",(C15-C14))*160 -> 480 | E15: 36092122 | F15: =IF((E15-E14)<0,"0",(E15-E14)) -> 9477 | G15: 13702466 | H15: =IF((G15-G14)<0,"0",(G15-G14)) -> 54089 | I15: =F15+H15 -> 63566 | J15: 1490146 | K15: =(IF((J15-J14)<0,"0",(J15-J14)))*2 -> 8552 | L15: 1838393 | M15: =IF((L15-L14)<0,"0",(L15-L14)) -> 6643 | N15: 8243054 | O15: =(IF((N15-N14)<0,"0",(N15-N14)))*2 -> 2660 | P15: 9436334 | Q15: =IF((P15-P14)<0,"0",(P15-P14)) -> 11414 | R15: 24305885 | S15: =IF((R15-R14)<0,"0",(R15-R14)) -> 12641 | V15: 2315510 | W15: =IF((V15-V14)<0,"0",(V15-V14)) -> 11942 | X15: =K15+M15+O15+Q15+S15+U15+W15 -> 53852 | Y15: =I15-X15 -> 9714 | Z15: =(0.93352*(W15+S15)+0.5568*(Q15+O15))*0.26 -> 8004.1326 | AA15: =SUM(Z1:Z15) -> 88999.936
A16: 44999 | B16: 328 | C16: 20628 | D16: =IF((C16-C15)<0,"0",(C16-C15))*160 -> 480 | E16: 36099613 | F16: =IF((E16-E15)<0,"0",(E16-E15)) -> 7491 | G16: 13742060 | H16: =IF((G16-G15)<0,"0",(G16-G15)) -> 39594 | I16: =F16+H16 -> 47085 | J16: 1494029 | K16: =(IF((J16-J15)<0,"0",(J16-J15)))*2 -> 7766 | L16: 1843556 | M16: =IF((L16-L15)<0,"0",(L16-L15)) -> 5163 | N16: 8244145 | O16: =(IF((N16-N15)<0,"0",(N16-N15)))*2 -> 2182 | P16: 9443898 | Q16: =IF((P16-P15)<0,"0",(P16-P15)) -> 7564 | R16: 24315260 | S16: =IF((R16-R15)<0,"0",(R16-R15)) -> 9375 | V16: 2324483 | W16: =IF((V16-V15)<0,"0",(V16-V15)) -> 8973 | X16: =K16+M16+O16+Q16+S16+U16+W16 -> 41023 | Y16: =I16-X16 -> 6062 | Z16: =(0.93352*(W16+S16)+0.5568*(Q16+O16))*0.26 -> 5864.2474 | AA16: =SUM(Z1:Z16) -> 94864.183
A17: 45000 | B17: 391 | C17: 20631 | D17: =IF((C17-C16)<0,"0",(C17-C16))*160 -> 480 | E17: 36108650 | F17: =IF((E17-E16)<0,"0",(E17-E16)) -> 9037 | G17: 13797167 | H17: =IF((G17-G16)<0,"0",(G17-G16)) -> 55107 | I17: =F17+H17 -> 64144 | J17: 1499326 | K17: =(IF((J17-J16)<0,"0",(J17-J16)))*2 -> 10594 | L17: 1850155 | M17: =IF((L17-L16)<0,"0",(L17-L16)) -> 6599 | N17: 8245272 | O17: =(IF((N17-N16)<0,"0",(N17-N16)))*2 -> 2254 | P17: 9454462 | Q17: =IF((P17-P16)<0,"0",(P17-P16)) -> 10564 | R17: 24328189 | S17: =IF((R17-R16)<0,"0",(R17-R16)) -> 12929 | V17: 2337070 | W17: =IF((V17-V16)<0,"0",(V17-V16)) -> 12587 | X17: =K17+M17+O17+Q17+S17+U17+W17 -> 55527 | Y17: =I17-X17 -> 8617 | Z17: =(0.93352*(W17+S17)+0.5568*(Q17+O17))*0.26 -> 8048.7573 | AA17: =SUM(Z1:Z17) -> 102912.94
A18: 45001 | B18: 344 | C18: 20634 | D18: =IF((C18-C17)<0,"0",(C18-C17))*160 -> 480 | E18: 36114575 | F18: =IF((E18-E17)<0,"0",(E18-E17)) -> 5925 | G18: 13831835 | H18: =IF((G18-G17)<0,"0",(G18-G17)) -> 34668 | I18: =F18+H18 -> 40593 | J18: 1502689 | K18: =(IF((J18-J17)<0,"0",(J18-J17)))*2 -> 6726 | L18: 1854527 | M18: =IF((L18-L17)<0,"0",(L18-L17)) -> 4372 | N18: 8245988 | O18: =(IF((N18-N17)<0,"0",(N18-N17)))*2 -> 1432 | P18: 9461305 | Q18: =IF((P18-P17)<0,"0",(P18-P17)) -> 6843 | R18: 24336192 | S18: =IF((R18-R17)<0,"0",(R18-R17)) -> 8003 | V18: 2344951 | W18: =IF((V18-V17)<0,"0",(V18-V17)) -> 7881 | X18: =K18+M18+O18+Q18+S18+U18+W18 -> 35257 | Y18: =I18-X18 -> 5336 | Z18: =(0.93352*(W18+S18)+0.5568*(Q18+O18))*0.26 -> 5053.2434 | AA18: =SUM(Z1:Z18) -> 107966.18
A19: 45002 | B19: 187 | C19: 20636 | D19: =IF((C19-C18)<0,"0",(C19-C18))*160 -> 320 | E19: 36123078 | F19: =IF((E19-E18)<0,"0",(E19-E18)) -> 8503 | G19: 13883106 | H19: =IF((G19-G18)<0,"0",(G19-G18)) -> 51271 | I19: =F19+H19 -> 59774 | J19: 1507136 | K19: =(IF((J19-J18)<0,"0",(J19-J18)))*2 -> 8894 | L19: 1860571 | M19: =IF((L19-L18)<0,"0",(L19-L18)) -> 6044 | N19: 8247120 | O19: =(IF((N19-N18)<0,"0",(N19-N18)))*2 -> 2264 | P19: 9471918 | Q19: =IF((P19-P18)<0,"0",(P19-P18)) -> 10613 | R19: 24347968 | S19: =IF((R19-R18)<0,"0",(R19-R18)) -> 11776 | V19: 2356647 | W19: =IF((V19-V18)<0,"0",(V19-V18)) -> 11696 | X19: =K19+M19+O19+Q19+S19+U19+W19 -> 51287 | Y19: =I19-X19 -> 8487 | Z19: =(0.93352*(W19+S19)+0.5568*(Q19+O19))*0.26 -> 7561.1887 | AA19: =SUM(Z1:Z19) -> 115527.37
A20: 45003 | B20: 316 | C20: 20638 | D20: =IF((C20-C19)<0,"0",(C20-C19))*160 -> 320 | E20: 36128651 | F20: =IF((E20-E19)<0,"0",(E20-E19)) -> 5573 | G20: 13919101 | H20: =IF((G20-G19)<0,"0",(G20-G19)) -> 35995 | I20: =F20+H20 -> 41568 | J20: 1510486 | K20: =(IF((J20-J19)<0,"0",(J20-J19)))*2 -> 6700 | L20: 1864524 | M20: =IF((L20-L19)<0,"0",(L20-L19)) -> 3953 | N20: 8247871 | O20: =(IF((N20-N19)<0,"0",(N20-N19)))*2 -> 1502 | P20: 9479172 | Q20: =IF((P20-P19)<0,"0",(P20-P19)) -> 7254 | R20: 24356405 | S20: =IF((R20-R19)<0,"0",(R20-R19)) -> 8437 | V20: 2364743 | W20: =IF((V20-V19)<0,"0",(V20-V19)) -> 8096 | X20: =K20+M20+O20+Q20+S20+U20+W20 -> 35942 | Y20: =I20-X20 -> 5626 | Z20: =(0.93352*(W20+S20)+0.5568*(Q20+O20))*0.26 -> 5280.399 | AA20: =SUM(Z1:Z20) -> 120807.77
A21: 45004 | B21: 287 | C21: 20641 | D21: =IF((C21-C20)<0,"0",(C21-C20))*160 -> 480 | E21: 36139084 | F21: =IF((E21-E20)<0,"0",(E21-E20)) -> 10433 | G21: 13974312 | H21: =IF((G21-G20)<0,"0",(G21-G20)) -> 55211 | I21: =F21+H21 -> 65644 | J21: 1516150 | K21: =(IF((J21-J20)<0,"0",(J21-J20)))*2 -> 11328 | L21: 1871739 | M21: =IF((L21-L20)<0,"0",(L21-L20)) -> 7215 | N21: 8249382 | O21: =(IF((N21-N20)<0,"0",(N21-N20)))*2 -> 3022 | P21: 9489086 | Q21: =IF((P21-P20)<0,"0",(P21-P20)) -> 9914 | R21: 24369367 | S21: =IF((R21-R20)<0,"0",(R21-R20)) -> 12962 | V21: 2374839 | W21: =IF((V21-V20)<0,"0",(V21-V20)) -> 10096 | X21: =K21+M21+O21+Q21+S21+U21+W21 -> 54537 | Y21: =I21-X21 -> 11107 | Z21: =(0.93352*(W21+S21)+0.5568*(Q21+O21))*0.26 -> 7469.2459 | AA21: =SUM(Z1:Z21) -> 128277.02
A22: 45005 | B22: 253 | C22: 20644 | D22: =IF((C22-C21)<0,"0",(C22-C21))*160 -> 480 | E22: 36145640 | F22: =IF((E22-E21)<0,"0",(E22-E21)) -> 6556 | G22: 14011796 | H22: =IF((G22-G21)<0,"0",(G22-G21)) -> 37484 | I22: =F22+H22 -> 44040 | J22: 1520130 | K22: =(IF((J22-J21)<0,"0",(J22-J21)))*2 -> 7960 | L22: 1876731 | M22: =IF((L22-L21)<0,"0",(L22-L21)) -> 4992 | N22: 8250094 | O22: =(IF((N22-N21)<0,"0",(N22-N21)))*2 -> 1424 | P22: 9496296 | Q22: =IF((P22-P21)<0,"0",(P22-P21)) -> 7210 | R22: 24377913 | S22: =IF((R22-R21)<0,"0",(R22-R21)) -> 8546 | V22: 2385973 | W22: =IF((V22-V21)<0,"0",(V22-V21)) -> 11134 | X22: =K22+M22+O22+Q22+S22+U22+W22 -> 41266 | Y22: =I22-X22 -> 2774 | Z22: =(0.93352*(W22+S22)+0.5568*(Q22+O22))*0.26 -> 6026.562 | AA22: =SUM(Z1:Z22) -> 134303.58
A23: 45006 | C23: =C22 -> 20644 | D23: =IF((C23-C22)<0,"0",(C23-C22))*160 -> 0 | E23: =E22 -> 36145640 | F23: =IF((E23-E22)<0,"0",(E23-E22)) -> 0 | G23: =G22 -> 14011796 | H23: =IF((G23-G22)<0,"0",(G23-G22)) -> 0 | I23: =F23+H23 -> 0 | J23: =J22 -> 1520130 | K23: =(IF((J23-J22)<0,"0",(J23-J22)))*2 -> 0 | L23: =L22 -> 1876731 | M23: =IF((L23-L22)<0,"0",(L23-L22)) -> 0 | N23: =N22 -> 8250094 | O23: =(IF((N23-N22)<0,"0",(N23-N22)))*2 -> 0 | P23: =P22 -> 9496296 | Q23: =IF((P23-P22)<0,"0",(P23-P22)) -> 0 | R23: =R22 -> 24377913 | S23: =IF((R23-R22)<0,"0",(R23-R22)) -> 0 | V23: =V22 -> 2385973 | W23: =IF((V23-V22)<0,"0",(V23-V22)) -> 0 | X23: =K23+M23+O23+Q23+S23+U23+W23 -> 0 | Y23: =I23-X23 -> 0 | Z23: =(0.93352*(W23+S23)+0.5568*(Q23+O23))*0.26 -> 0 | AA23: =SUM(Z1:Z23) -> 134303.58
A24: 45007 | C24: =C23 -> 20644 | D24: =IF((C24-C23)<0,"0",(C24-C23))*160 -> 0 | E24: =E23 -> 36145640 | F24: =IF((E24-E23)<0,"0",(E24-E23)) -> 0 | G24: =G23 -> 14011796 | H24: =IF((G24-G23)<0,"0",(G24-G23)) -> 0 | I24: =F24+H24 -> 0 | J24: =J23 -> 1520130 | K24: =(IF((J24-J23)<0,"0",(J24-J23)))*2 -> 0 | L24: =L23 -> 1876731 | M24: =IF((L24-L23)<0,"0",(L24-L23)) -> 0 | N24: =N23 -> 8250094 | O24: =(IF((N24-N23)<0,"0",(N24-N23)))*2 -> 0 | P24: =P23 -> 9496296 | Q24: =IF((P24-P23)<0,"0",(P24-P23)) -> 0 | R24: =R23 -> 24377913 | S24: =IF((R24-R23)<0,"0",(R24-R23)) -> 0 | V24: =V23 -> 2385973 | W24: =IF((V24-V23)<0,"0",(V24-V23)) -> 0 | X24: =K24+M24+O24+Q24+S24+U24+W24 -> 0 | Y24: =I24-X24 -> 0 | Z24: =(0.93352*(W24+S24)+0.5568*(Q24+O24))*0.26 -> 0 | AA24: =SUM(Z1:Z24) -> 134303.58
A25: 45008 | C25: =C24 -> 20644 | D25: =IF((C25-C24)<0,"0",(C25-C24))*160 -> 0 | E25: =E24 -> 36145640 | F25: =IF((E25-E24)<0,"0",(E25-E24)) -> 0 | G25: =G24 -> 14011796 | H25: =IF((G25-G24)<0,"0",(G25-G24)) -> 0 | I25: =F25+H25 -> 0 | J25: =J24 -> 1520130 | K25: =(IF((J25-J24)<0,"0",(J25-J24)))*2 -> 0 | L25: =L24 -> 1876731 | M25: =IF((L25-L24)<0,"0",(L25-L24)) -> 0 | N25: =N24 -> 8250094 | O25: =(IF((N25-N24)<0,"0",(N25-N24)))*2 -> 0 | P25: =P24 -> 9496296 | Q25: =IF((P25-P24)<0,"0",(P25-P24)) -> 0 | R25: =R24 -> 24377913 | S25: =IF((R25-R24)<0,"0",(R25-R24)) -> 0 | V25: =V24 -> 2385973 | W25: =IF((V25-V24)<0,"0",(V25-V24)) -> 0 | X25: =K25+M25+O25+Q25+S25+U25+W25 -> 0 | Y25: =I25-X25 -> 0 | Z25: =(0.93352*(W25+S25)+0.5568*(Q25+O25))*0.26 -> 0 | AA25: =SUM(Z1:Z25) -> 134303.58
A26: 45009 | C26: =C25 -> 20644 | D26: =IF((C26-C25)<0,"0",(C26-C25))*160 -> 0 | E26: =E25 -> 36145640 | F26: =IF((E26-E25)<0,"0",(E26-E25)) -> 0 | G26: =G25 -> 14011796 | H26: =IF((G26-G25)<0,"0",(G26-G25)) -> 0 | I26: =F26+H26 -> 0 | J26: =J25 -> 1520130 | K26: =(IF((J26-J25)<0,"0",(J26-J25)))*2 -> 0 | L26: =L25 -> 1876731 | M26: =IF((L26-L25)<0,"0",(L26-L25)) -> 0 | N26: =N25 -> 8250094 | O26: =(IF((N26-N25)<0,"0",(N26-N25)))*2 -> 0 | P26: =P25 -> 9496296 | Q26: =IF((P26-P25)<0,"0",(P26-P25)) -> 0 | R26: =R25 -> 24377913 | S26: =IF((R26-R25)<0,"0",(R26-R25)) -> 0 | V26: =V25 -> 2385973 | W26: =IF((V26-V25)<0,"0",(V26-V25)) -> 0 | X26: =K26+M26+O26+Q26+S26+U26+W26 -> 0 | Y26: =I26-X26 -> 0 | Z26: =(0.93352*(W26+S26)+0.5568*(Q26+O26))*0.26 -> 0 | AA26: =SUM(Z1:Z26) -> 134303.58
A27: 45010 | C27: =C26 -> 20644 | D27: =IF((C27-C26)<0,"0",(C27-C26))*160 -> 0 | E27: =E26 -> 36145640 | F27: =IF((E27-E26)<0,"0",(E27-E26)) -> 0 | G27: =G26 -> 14011796 | H27: =IF((G27-G26)<0,"0",(G27-G26)) -> 0 | I27: =F27+H27 -> 0 | J27: =J26 -> 1520130 | K27: =(IF((J27-J26)<0,"0",(J27-J26)))*2 -> 0 | L27: =L26 -> 1876731 | M27: =IF((L27-L26)<0,"0",(L27-L26)) -> 0 | N27: =N26 -> 8250094 | O27: =(IF((N27-N26)<0,"0",(N27-N26)))*2 -> 0 | P27: =P26 -> 9496296 | Q27: =IF((P27-P26)<0,"0",(P27-P26)) -> 0 | R27: =R26 -> 24377913 | S27: =IF((R27-R26)<0,"0",(R27-R26)) -> 0 | V27: =V26 -> 2385973 | W27: =IF((V27-V26)<0,"0",(V27-V26)) -> 0 | X27: =K27+M27+O27+Q27+S27+U27+W27 -> 0 | Y27: =I27-X27 -> 0 | Z27: =(0.93352*(W27+S27)+0.5568*(Q27+O27))*0.26 -> 0 | AA27: =SUM(Z1:Z27) -> 134303.58
A28: 45011 | C28: =C27 -> 20644 | D28: =IF((C28-C27)<0,"0",(C28-C27))*160 -> 0 | E28: =E27 -> 36145640 | F28: =IF((E28-E27)<0,"0",(E28-E27)) -> 0 | G28: =G27 -> 14011796 | H28: =IF((G28-G27)<0,"0",(G28-G27)) -> 0 | I28: =F28+H28 -> 0 | J28: =J27 -> 1520130 | K28: =(IF((J28-J27)<0,"0",(J28-J27)))*2 -> 0 | L28: =L27 -> 1876731 | M28: =IF((L28-L27)<0,"0",(L28-L27)) -> 0 | N28: =N27 -> 8250094 | O28: =(IF((N28-N27)<0,"0",(N28-N27)))*2 -> 0 | P28: =P27 -> 9496296 | Q28: =IF((P28-P27)<0,"0",(P28-P27)) -> 0 | R28: =R27 -> 24377913 | S28: =IF((R28-R27)<0,"0",(R28-R27)) -> 0 | V28: =V27 -> 2385973 | W28: =IF((V28-V27)<0,"0",(V28-V27)) -> 0 | X28: =K28+M28+O28+Q28+S28+U28+W28 -> 0 | Y28: =I28-X28 -> 0 | Z28: =(0.93352*(W28+S28)+0.5568*(Q28+O28))*0.26 -> 0 | AA28: =SUM(Z1:Z28) -> 134303.58
A29: 45012 | C29: =C28 -> 20644 | D29: =IF((C29-C28)<0,"0",(C29-C28))*160 -> 0 | E29: =E28 -> 36145640 | F29: =IF((E29-E28)<0,"0",(E29-E28)) -> 0 | G29: =G28 -> 14011796 | H29: =IF((G29-G28)<0,"0",(G29-G28)) -> 0 | I29: =F29+H29 -> 0 | J29: =J28 -> 1520130 | K29: =(IF((J29-J28)<0,"0",(J29-J28)))*2 -> 0 | L29: =L28 -> 1876731 | M29: =IF((L29-L28)<0,"0",(L29-L28)) -> 0 | N29: =N28 -> 8250094 | O29: =(IF((N29-N28)<0,"0",(N29-N28)))*2 -> 0 | P29: =P28 -> 9496296 | Q29: =IF((P29-P28)<0,"0",(P29-P28)) -> 0 | R29: =R28 -> 24377913 | S29: =IF((R29-R28)<0,"0",(R29-R28)) -> 0 | V29: =V28 -> 2385973 | W29: =IF((V29-V28)<0,"0",(V29-V28)) -> 0 | X29: =K29+M29+O29+Q29+S29+U29+W29 -> 0 | Y29: =I29-X29 -> 0 | Z29: =(0.93352*(W29+S29)+0.5568*(Q29+O29))*0.26 -> 0 | AA29: =SUM(Z1:Z29) -> 134303.58
A30: 45013 | C30: =C29 -> 20644 | D30: =IF((C30-C29)<0,"0",(C30-C29))*160 -> 0 | E30: =E29 -> 36145640 | F30: =IF((E30-E29)<0,"0",(E30-E29)) -> 0 | G30: =G29 -> 14011796 | H30: =IF((G30-G29)<0,"0",(G30-G29)) -> 0 | I30: =F30+H30 -> 0 | J30: =J29 -> 1520130 | K30: =(IF((J30-J29)<0,"0",(J30-J29)))*2 -> 0 | L30: =L29 -> 1876731 | M30: =IF((L30-L29)<0,"0",(L30-L29)) -> 0 | N30: =N29 -> 8250094 | O30: =(IF((N30-N29)<0,"0",(N30-N29)))*2 -> 0 | P30: =P29 -> 9496296 | Q30: =IF((P30-P29)<0,"0",(P30-P29)) -> 0 | R30: =R29 -> 24377913 | S30: =IF((R30-R29)<0,"0",(R30-R29)) -> 0 | V30: =V29 -> 2385973 | W30: =IF((V30-V29)<0,"0",(V30-V29)) -> 0 | X30: =K30+M30+O30+Q30+S30+U30+W30 -> 0 | Y30: =I30-X30 -> 0 | Z30: =(0.93352*(W30+S30)+0.5568*(Q30+O30))*0.26 -> 0 | AA30: =SUM(Z1:Z30) -> 134303.58
