Workbook

Sheet TOTAL
A1: Site Name | B1: Day | C1: Month | D1: Year | E1: Total Electricity Kwh | F1: Electricity Tariff ($/Kwh) | G1: LPG (Kg) | H1: LPG $/Kg | I1: Water Utility Supply (m3) m3 | J1: Water Utility Supply (m3) $/m3 | K1: Irrigation Water (m3) m3 | L1: Irrigation water $/m3 | M1: Room Nights | N1: Total Guests
A2: Dubai at Jumeirah Beach | B2: 1 | C2: 3 | D2: 2023 | E2: =SUM(Submetering!M2:V2)-SUM(Submetering!AU2:AY2,Submetering!BS2) -> 37075.86 | F2: 0.44448 | G2: =Submetering!Z2+Submetering!AA2+Submetering!AB2+Submetering!AD2+Submetering!AE2+Submetering!AF2+Submetering!AG2+Submetering!AH2+Submetering!AI2 -> 927.99 | H2: =1.62/0.52 -> 3.1153846 | I2: =Submetering!G2-SUM(Submetering!AJ2:AS2,Submetering!BM2:BR2) -> 386.858 | J2: 13.83 | K2: =Submetering!BL2-Submetering!AT2 -> 1 | L2: 1.2 | M2: =Submetering!E2 -> 184.86 | N2: =Submetering!F2 -> 366
A3: Dubai at Jumeirah Beach | B3: =B2+1 -> 2 | C3: 3 | D3: 2023 | E3: =SUM(Submetering!M3:V3)-SUM(Submetering!AU3:AY3,Submetering!BS3) -> 34474.04 | F3: 0.44448 | G3: =Submetering!Z3+Submetering!AA3+Submetering!AB3+Submetering!AD3+Submetering!AE3+Submetering!AF3+Submetering!AG3+Submetering!AH3+Submetering!AI3 -> 824.04 | H3: =1.62/0.52 -> 3.1153846 | I3: =Submetering!G3-SUM(Submetering!AJ3:AS3,Submetering!BM3:BR3) -> 386.115 | J3: 13.83 | K3: =Submetering!BL3 -> 210 | L3: 1.2 | M3: =Submetering!E3 -> 218.04 | N3: =Submetering!F3 -> 413
A4: Dubai at Jumeirah Beach | B4: =B3+1 -> 3 | C4: 3 | D4: 2023 | E4: =SUM(Submetering!M4:V4)-SUM(Submetering!AU4:AY4,Submetering!BS4) -> 42713.22 | F4: 0.44448 | G4: =Submetering!Z4+Submetering!AA4+Submetering!AB4+Submetering!AD4+Submetering!AE4+Submetering!AF4+Submetering!AG4+Submetering!AH4+Submetering!AI4 -> 846.72 | H4: =1.62/0.52 -> 3.1153846 | I4: =Submetering!G4-SUM(Submetering!AJ4:AS4,Submetering!BM4:BR4) -> 449.655 | J4: 13.83 | K4: =Submetering!BL4 -> 356 | L4: 1.2 | M4: =Submetering!E4 -> 206.19 | N4: =Submetering!F4 -> 411
A5: Dubai at Jumeirah Beach | B5: =B4+1 -> 4 | C5: 3 | D5: 2023 | E5: =SUM(Submetering!M5:V5)-SUM(Submetering!AU5:AY5,Submetering!BS5) -> 38471.1 | F5: 0.44448 | G5: =Submetering!Z5+Submetering!AA5+Submetering!AB5+Submetering!AD5+Submetering!AE5+Submetering!AF5+Submetering!AG5+Submetering!AH5+Submetering!AI5 -> 1120.77 | H5: =1.62/0.52 -> 3.1153846 | I5: =Submetering!G5-SUM(Submetering!AJ5:AS5,Submetering!BM5:BR5) -> 441.07 | J5: 13.83 | K5: =Submetering!BL5 -> 328 | L5: 1.2 | M5: =Submetering!E5 -> 215.67 | N5: =Submetering!F5 -> 401
A6: Dubai at Jumeirah Beach | B6: =B5+1 -> 5 | C6: 3 | D6: 2023 | E6: =SUM(Submetering!M6:V6)-SUM(Submetering!AU6:AY6,Submetering!BS6) -> 35732.9 | F6: 0.44448 | G6: =Submetering!Z6+Submetering!AA6+Submetering!AB6+Submetering!AD6+Submetering!AE6+Submetering!AF6+Submetering!AG6+Submetering!AH6+Submetering!AI6 -> 699.3 | H6: =1.62/0.52 -> 3.1153846 | I6: =Submetering!G6-SUM(Submetering!AJ6:AS6,Submetering!BM6:BR6) -> 393.788 | J6: 13.83 | K6: =Submetering!BL6 -> 182 | L6: 1.2 | M6: =Submetering!E6 -> 201.45 | N6: =Submetering!F6 -> 364
A7: Dubai at Jumeirah Beach | B7: =B6+1 -> 6 | C7: 3 | D7: 2023 | E7: =SUM(Submetering!M7:V7)-SUM(Submetering!AU7:AY7,Submetering!BS7) -> 38439.2 | F7: 0.44448 | G7: =Submetering!Z7+Submetering!AA7+Submetering!AB7+Submetering!AD7+Submetering!AE7+Submetering!AF7+Submetering!AG7+Submetering!AH7+Submetering!AI7 -> 997.92 | H7: =1.62/0.52 -> 3.1153846 | I7: =Submetering!G7-SUM(Submetering!AJ7:AS7,Submetering!BM7:BR7) -> 333.6369 | J7: 13.83 | K7: =Submetering!BL7 -> 285 | L7: 1.2 | M7: =Submetering!E7 -> 210.93 | N7: =Submetering!F7 -> 354
A8: Dubai at Jumeirah Beach | B8: =B7+1 -> 7 | C8: 3 | D8: 2023 | E8: =SUM(Submetering!M8:V8)-SUM(Submetering!AU8:AY8,Submetering!BS8) -> 29548.44 | F8: 0.44448 | G8: =Submetering!Z8+Submetering!AA8+Submetering!AB8+Submetering!AD8+Submetering!AE8+Submetering!AF8+Submetering!AG8+Submetering!AH8+Submetering!AI8 -> 670.95 | H8: =1.62/0.52 -> 3.1153846 | I8: =Submetering!G8-SUM(Submetering!AJ8:AS8,Submetering!BM8:BR8) -> 366.9981 | J8: 13.83 | K8: =Submetering!BL8 -> 198 | L8: 1.2 | M8: =Submetering!E8 -> 215.67 | N8: =Submetering!F8 -> 377
A9: Dubai at Jumeirah Beach | B9: =B8+1 -> 8 | C9: 3 | D9: 2023 | E9: =SUM(Submetering!M9:V9)-SUM(Submetering!AU9:AY9,Submetering!BS9) -> 37300.62 | F9: 0.44448 | G9: =Submetering!Z9+Submetering!AA9+Submetering!AB9+Submetering!AD9+Submetering!AE9+Submetering!AF9+Submetering!AG9+Submetering!AH9+Submetering!AI9 -> 767.34 | H9: =1.62/0.52 -> 3.1153846 | I9: =Submetering!G9-SUM(Submetering!AJ9:AS9,Submetering!BM9:BR9) -> 425.17 | J9: 13.83 | K9: =Submetering!BL9 -> 152 | L9: 1.2 | M9: =Submetering!E9 -> 180.12 | N9: =Submetering!F9 -> 350
A10: Dubai at Jumeirah Beach | B10: =B9+1 -> 9 | C10: 3 | D10: 2023 | E10: =SUM(Submetering!M10:V10)-SUM(Submetering!AU10:AY10,Submetering!BS10) -> 36088.54 | F10: 0.44448 | G10: =Submetering!Z10+Submetering!AA10+Submetering!AB10+Submetering!AD10+Submetering!AE10+Submetering!AF10+Submetering!AG10+Submetering!AH10+Submetering!AI10 -> 835.38 | H10: =1.62/0.52 -> 3.1153846 | I10: =Submetering!G10-SUM(Submetering!AJ10:AS10,Submetering!BM10:BR10) -> 356.122 | J10: 13.83 | K10: =Submetering!BL10 -> 270 | L10: 1.2 | M10: =Submetering!E10 -> 203.82 | N10: =Submetering!F10 -> 344
A11: Dubai at Jumeirah Beach | B11: =B10+1 -> 10 | C11: 3 | D11: 2023 | E11: =SUM(Submetering!M11:V11)-SUM(Submetering!AU11:AY11,Submetering!BS11) -> 36099.08 | F11: 0.44448 | G11: =Submetering!Z11+Submetering!AA11+Submetering!AB11+Submetering!AD11+Submetering!AE11+Submetering!AF11+Submetering!AG11+Submetering!AH11+Submetering!AI11 -> 954.45 | H11: =1.62/0.52 -> 3.1153846 | I11: =Submetering!G11-SUM(Submetering!AJ11:AS11,Submetering!BM11:BR11) -> 425.346 | J11: 13.83 | K11: =Submetering!BL11 -> 275 | L11: 1.2 | M11: =Submetering!E11 -> 201.45 | N11: =Submetering!F11 -> 360
A12: Dubai at Jumeirah Beach | B12: =B11+1 -> 11 | C12: 3 | D12: 2023 | E12: =SUM(Submetering!M12:V12)-SUM(Submetering!AU12:AY12,Submetering!BS12) -> 39008.86 | F12: 0.44448 | G12: =Submetering!Z12+Submetering!AA12+Submetering!AB12+Submetering!AD12+Submetering!AE12+Submetering!AF12+Submetering!AG12+Submetering!AH12+Submetering!AI12 -> 812.7 | H12: =1.62/0.52 -> 3.1153846 | I12: =Submetering!G12-SUM(Submetering!AJ12:AS12,Submetering!BM12:BR12) -> 418.314 | J12: 13.83 | K12: =Submetering!BL12 -> 307 | L12: 1.2 | M12: =Submetering!E12 -> 194.34 | N12: =Submetering!F12 -> 373
A13: Dubai at Jumeirah Beach | B13: =B12+1 -> 12 | C13: 3 | D13: 2023 | E13: =SUM(Submetering!M13:V13)-SUM(Submetering!AU13:AY13,Submetering!BS13) -> 35795.86 | F13: 0.44448 | G13: =Submetering!Z13+Submetering!AA13+Submetering!AB13+Submetering!AD13+Submetering!AE13+Submetering!AF13+Submetering!AG13+Submetering!AH13+Submetering!AI13 -> 795.69 | H13: =1.62/0.52 -> 3.1153846 | I13: =Submetering!G13-SUM(Submetering!AJ13:AS13,Submetering!BM13:BR13) -> 422.125 | J13: 13.83 | K13: =Submetering!BL13 -> 255 | L13: 1.2 | M13: =Submetering!E13 -> 180.12 | N13: =Submetering!F13 -> 339
A14: Dubai at Jumeirah Beach | B14: =B13+1 -> 13 | C14: 3 | D14: 2023 | E14: =SUM(Submetering!M14:V14)-SUM(Submetering!AU14:AY14,Submetering!BS14) -> 36865.12 | F14: 0.44448 | G14: =Submetering!Z14+Submetering!AA14+Submetering!AB14+Submetering!AD14+Submetering!AE14+Submetering!AF14+Submetering!AG14+Submetering!AH14+Submetering!AI14 -> 841.05 | H14: =1.62/0.52 -> 3.1153846 | I14: =Submetering!G14-SUM(Submetering!AJ14:AS14,Submetering!BM14:BR14) -> 408.116 | J14: 13.83 | K14: =Submetering!BL14 -> 291 | L14: 1.2 | M14: =Submetering!E14 -> 196.71 | N14: =Submetering!F14 -> 348
... A32: Dubai at Jumeirah Beach | B32: =B31+1 -> 31 | C32: 3 | D32: 2023 | E32: =SUM(Submetering!M32:V32)-SUM(Submetering!AU32:AY32,Submetering!BS32) -> 0 | F32: 0.44448 | G32: =Submetering!Z32+Submetering!AA32+Submetering!AB32+Submetering!AD32+Submetering!AE32+Submetering!AF32+Submetering!AG32+Submetering!AH32+Submetering!AI32 -> 0 | H32: =1.62/0.52 -> 3.1153846 | I32: =Submetering!G32-SUM(Submetering!AJ32:AS32,Submetering!BM32:BR32) -> 0 | J32: 13.83 | K32: =Submetering!BL32 -> 0 | L32: 1.2 | M32: =Submetering!E32 -> 0 | N32: =Submetering!F32 -> 0

Sheet Submetering
A1: Site Name | B1: Day | C1: Month | D1: Year | E1: Room Nights | F1: Total Guests | G1: Potable Water -IG (m3) | H1: Resort Water (m3) | I1: Irrigation Water (m3) | J1: Domestic Water for Irrigation (m3) | K1: Cooling Tower Water (m3) | L1: Cooling Tower Blowdown (m3) | M1: EMDB-1 All Pumps (KWh) | N1: EMDB-2 Elevators (KWh) | O1: MDB-1 Chiller #1 (KWh) | P1: MDB-2 Chiller #2 (KWh) | Q1: MDB-3 Chiller #3(KWh) | R1: MDB-4 North Riser (KWh) | S1: MDB-5 North Riser (KWh) | T1: MDB-6 Main Kitchen (KWh) | U1: MDB-7 South Riser (KWh) | V1: MDB-8 F&B (KWh) | W1: Chiller 1 (Kwh cooling) | X1: Chiller 2 (Kwh cooling) | Y1: Chiller 3 (Kwh cooling) | Z1: Steam Boiler LPG (Kg) | AA1: Solar Hot Water Boiler LPG (Kg) | AB1: Low Temp Hot Water Boiler LPG (Kg) | AC1: Steam Boiler Steam (Kg) | AD1: Ird Kitchen (Kg) | AE1: Suq Kitchen (Kg) | AF1: Bakery Kitchen (Kg) | AG1: Shai Saloon Kitchen (kg) | AH1: Banquet Kitchen (Kg) | AI1: Sea Fu Kitchen (Kg) | AJ1: Jean George Cold Water (m³) | AK1: Jean George Hot Water (m³) | AL1: Coya Cold Water (m³) | AM1: Coya Hot Water (m³) | AN1: Nusrat Cold Water (m³) | AO1: Nusrat Hot Water (m³) | AP1: Provocateur Cold Water (m³) | AQ1: Provocateur Hot Water (m³) | AR1: Scalini Cold Water (m³) | AS1: Scalini Hot Water (m³) | AT1: F&B V Irrigation (m³) | AU1: MDB Coya (KWh) | AV1: MDB Jean Georges (KWh) | AW1: MDB Nusrat(KWh) | AX1: SMDB Provocateur (KWh) | AY1: SMDB Scalini (KWh) | AZ1: Common ESMDB (KWh) | BA1: Chilled Water Coya (Kwh) | BB1: Chilled Water Coya Cold Room (Kwh) | BC1: Chilled Water Jean Georges (Kwh) | BD1: Chilled Water Nusrat (Kwh) | BE1: Chilled Water Provocateur A (Kwh) | BF1: Chilled Water Provocateur B (Kwh) | BG1: Coya LPG (Kg) | BH1: Nusrat LPG (Kg) | BI1: Jean Georges LPG (Kg) | BJ1: Provocateur LPG (Kg) | BK1: Scalini LPG (Kg) | BL1: TSE Irrigation (m3) | BM1: Nammos Main Waterline (m3) | BN1: Nammos Water 1 (m3) | BO1: Nammos Water 2 (m3) | BP1: Nammos Water 3 (m3) | BQ1: Nammos Water 4 (m3) | BR1: Pavilion (m3) | BS1: Pavilion (kwh)
A2: Dubai at Jumeirah Beach | B2: 1 | C2: 3 | D2: 2023 | E2: =237*0.78 -> 184.86 | F2: =322+44 -> 366 | G2: ='DJB Daily Readings'!C10-'DJB Daily Readings'!C9 -> 606 | H2: ='DJB Daily Readings'!F10-'DJB Daily Readings'!F9 -> 453 | I2: ='DJB Daily Readings'!L9 -> 116 | J2: ='DJB Daily Readings'!N9 -> 0 | K2: ='DJB Daily Readings'!O10-'DJB Daily Readings'!O9 -> 99 | L2: ='DJB Daily Readings'!R10-'DJB Daily Readings'!R9 -> 17 | M2: ='DJB Daily Readings'!U10-'DJB Daily Readings'!U9 -> 1997.52 | N2: ='DJB Daily Readings'!X10-'DJB Daily Readings'!X9 -> 4774.56 | O2: ='DJB Daily Readings'!AA10-'DJB Daily Readings'!AA9 -> 8233.68 | P2: ='DJB Daily Readings'!AD10-'DJB Daily Readings'!AD9 -> 2630.88 | Q2: ='DJB Daily Readings'!AG10-'DJB Daily Readings'!AG9 -> 633.36 | R2: ='DJB Daily Readings'!AJ10-'DJB Daily Readings'!AJ9 -> 5748.96 | S2: ='DJB Daily Readings'!AM10-'DJB Daily Readings'!AM9 -> 3897.6 | T2: ='DJB Daily Readings'!AP10-'DJB Daily Readings'!AP9 -> 4482.24 | U2: ='DJB Daily Readings'!AS10-'DJB Daily Readings'!AS9 -> 3118.08 | V2: ='DJB Daily Readings'!AV10-'DJB Daily Readings'!AV9 -> 5797.68 | W2: ='DJB Daily Readings'!AZ10-'DJB Daily Readings'!AZ9 -> 49400 | X2: ='DJB Daily Readings'!BC10-'DJB Daily Readings'!BC9 -> 5900 | Y2: ='DJB Daily Readings'!BF10-'DJB Daily Readings'!BF9 -> 0 | Z2: =('DJB Daily Readings'!CK10-'DJB Daily Readings'!CK9)*1.89 -> 156.87 | AA2: =('DJB Daily Readings'!CN10-'DJB Daily Readings'!CN9)*1.89 -> 224.91 | AB2: =('DJB Daily Readings'!CQ10-'DJB Daily Readings'!CQ9)*1.89 -> 351.54 | AC2: ='DJB Daily Readings'!CT10-'DJB Daily Readings'!CT9 -> 184 | AD2: =('DJB Daily Readings'!BY10-'DJB Daily Readings'!BY9)*1.89 -> 34.02 | AE2: =('DJB Daily Readings'!CA10-'DJB Daily Readings'!CA9)*1.89 -> 39.69 | AF2: =('DJB Daily Readings'!CC10-'DJB Daily Readings'!CC9)*1.89 -> 11.34 | AG2: =('DJB Daily Readings'!CE10-'DJB Daily Readings'!CE9)*1.89 -> 17.01 | AH2: =('DJB Daily Readings'!CG10-'DJB Daily Readings'!CG9)*1.89 -> 28.35 | AI2: =('DJB Daily Readings'!CI10-'DJB Daily Readings'!CI9)*1.89 -> 64.26 | AJ2: ='DJB Daily Readings'!CY10-'DJB Daily Readings'!CY9 -> 8 | AK2: ='DJB Daily Readings'!CW10-'DJB Daily Readings'!CW9 -> 10 | AL2: ='DJB Daily Readings'!DC10-'DJB Daily Readings'!DC9 -> 14 | AM2: ='DJB Daily Readings'!DA10-'DJB Daily Readings'!DA9 -> 19 | AN2: ='DJB Daily Readings'!DG10-'DJB Daily Readings'!DG9 -> 5 | AO2: ='DJB Daily Readings'!DE10-'DJB Daily Readings'!DE9 -> 10 | AP2: ='DJB Daily Readings'!DK10-'DJB Daily Readings'!DK9 -> 7 | AQ2: ='DJB Daily Readings'!DI10-'DJB Daily Readings'!DI9 -> 11 | AR2: ='DJB Daily Readings'!DO10-'DJB Daily Readings'!DO9 -> 9 | AS2: ='DJB Daily Readings'!DM10-'DJB Daily Readings'!DM9 -> 4 | AT2: ='DJB Daily Readings'!DQ10-'DJB Daily Readings'!DQ9 -> 3 | AU2: =('DJB Daily Readings'!DT10-'DJB Daily Readings'!DT9)*100 -> 1140 | AV2: =('DJB Daily Readings'!DV10-'DJB Daily Readings'!DV9)*100 -> 920 | AW2: =('DJB Daily Readings'!DX10-'DJB Daily Readings'!DX9)*100 -> 660 | AX2: =('DJB Daily Readings'!DZ10-'DJB Daily Readings'!DZ9)*100 -> 650 | AY2: ='DJB Daily Readings'!EB10-'DJB Daily Readings'!EB9 -> 619 | AZ2: ='DJB Daily Readings'!ED10-'DJB Daily Readings'!ED9 -> 159.1 | BA2: ='DJB Daily Readings'!EG10-'DJB Daily Readings'!EG9 -> 4600 | BB2: ='DJB Daily Readings'!EI10-'DJB Daily Readings'!EI9 -> 290 | BC2: ='DJB Daily Readings'!EQ10-'DJB Daily Readings'!EQ9 -> 3700 | BD2: ='DJB Daily Readings'!EK10-'DJB Daily Readings'!EK9 -> 1100 | BE2: ='DJB Daily Readings'!EM10-'DJB Daily Readings'!EM9 -> 500 | BF2: ='DJB Daily Readings'!EO10-'DJB Daily Readings'!EO9 -> 720 | BG2: =('DJB Daily Readings'!ET10-'DJB Daily Readings'!ET9)*1.89 -> 26.46 | BH2: =('DJB Daily Readings'!EV10-'DJB Daily Readings'!EV9)*1.89 -> 22.68 | BI2: =('DJB Daily Readings'!EZ10-'DJB Daily Readings'!EZ9)*1.89 -> 18.9 | BJ2: =('DJB Daily Readings'!EX10-'DJB Daily Readings'!EX9)*1.89 -> 15.12 | BK2: =('DJB Daily Readings'!FB10-'DJB Daily Readings'!FB9)*1.89 -> 69.93 | BL2: ='DJB Daily Readings'!J9 -> 4 | BM2: ='DJB Daily Readings'!FF9 -> 107.112 | BN2: ='DJB Daily Readings'!FH9 -> 0 | BO2: ='DJB Daily Readings'!FJ9 -> 7 | BP2: ='DJB Daily Readings'!FL9 -> 5 | BQ2: ='DJB Daily Readings'!FN9 -> 3 | BR2: ='DJB Daily Readings'!FP9 -> 0.03 | BS2: ='DJB Daily Readings'!FR9 -> 249.7
A3: Dubai at Jumeirah Beach | B3: =B2+1 -> 2 | C3: 3 | D3: 2023 | E3: =237*0.92 -> 218.04 | F3: =365+48 -> 413 | G3: ='DJB Daily Readings'!C11-'DJB Daily Readings'!C10 -> 641 | H3: ='DJB Daily Readings'!F11-'DJB Daily Readings'!F10 -> 443 | I3: ='DJB Daily Readings'!L10 -> 0 | J3: ='DJB Daily Readings'!N10 -> 0 | K3: ='DJB Daily Readings'!O11-'DJB Daily Readings'!O10 -> 106 | L3: ='DJB Daily Readings'!R11-'DJB Daily Readings'!R10 -> 16 | M3: ='DJB Daily Readings'!U11-'DJB Daily Readings'!U10 -> 1997.52 | N3: ='DJB Daily Readings'!X11-'DJB Daily Readings'!X10 -> 4287.36 | O3: ='DJB Daily Readings'!AA11-'DJB Daily Readings'!AA10 -> 0 | P3: ='DJB Daily Readings'!AD11-'DJB Daily Readings'!AD10 -> 8672.16 | Q3: ='DJB Daily Readings'!AG11-'DJB Daily Readings'!AG10 -> 1900.08 | R3: ='DJB Daily Readings'!AJ11-'DJB Daily Readings'!AJ10 -> 5164.32 | S3: ='DJB Daily Readings'!AM11-'DJB Daily Readings'!AM10 -> 3848.88 | T3: ='DJB Daily Readings'!AP11-'DJB Daily Readings'!AP10 -> 4092.48 | U3: ='DJB Daily Readings'!AS11-'DJB Daily Readings'!AS10 -> 3020.64 | V3: ='DJB Daily Readings'!AV11-'DJB Daily Readings'!AV10 -> 5359.2 | W3: ='DJB Daily Readings'!AZ11-'DJB Daily Readings'!AZ10 -> 0 | X3: ='DJB Daily Readings'!BC11-'DJB Daily Readings'!BC10 -> 49700 | Y3: ='DJB Daily Readings'!BF11-'DJB Daily Readings'!BF10 -> 6000 | Z3: =('DJB Daily Readings'!CK11-'DJB Daily Readings'!CK10)*1.89 -> 134.19 | AA3: =('DJB Daily Readings'!CN11-'DJB Daily Readings'!CN10)*1.89 -> 207.9 | AB3: =('DJB Daily Readings'!CQ11-'DJB Daily Readings'!CQ10)*1.89 -> 313.74 | AC3: ='DJB Daily Readings'!CT11-'DJB Daily Readings'!CT10 -> 158 | AD3: =('DJB Daily Readings'!BY11-'DJB Daily Readings'!BY10)*1.89 -> 28.35 | AE3: =('DJB Daily Readings'!CA11-'DJB Daily Readings'!CA10)*1.89 -> 32.13 | AF3: =('DJB Daily Readings'!CC11-'DJB Daily Readings'!CC10)*1.89 -> 13.23 | AG3: =('DJB Daily Readings'!CE11-'DJB Daily Readings'!CE10)*1.89 -> 18.9 | AH3: =('DJB Daily Readings'!CG11-'DJB Daily Readings'!CG10)*1.89 -> 11.34 | AI3: =('DJB Daily Readings'!CI11-'DJB Daily Readings'!CI10)*1.89 -> 64.26 | AJ3: ='DJB Daily Readings'!CY11-'DJB Daily Readings'!CY10 -> 8 | AK3: ='DJB Daily Readings'!CW11-'DJB Daily Readings'!CW10 -> 9 | AL3: ='DJB Daily Readings'!DC11-'DJB Daily Readings'!DC10 -> 13 | AM3: ='DJB Daily Readings'!DA11-'DJB Daily Readings'!DA10 -> 20 | AN3: ='DJB Daily Readings'!DG11-'DJB Daily Readings'!DG10 -> 4 | AO3: ='DJB Daily Readings'!DE11-'DJB Daily Readings'!DE10 -> 9 | AP3: ='DJB Daily Readings'!DK11-'DJB Daily Readings'!DK10 -> 6 | AQ3: ='DJB Daily Readings'!DI11-'DJB Daily Readings'!DI10 -> 11 | AR3: ='DJB Daily Readings'!DO11-'DJB Daily Readings'!DO10 -> 8 | AS3: ='DJB Daily Readings'!DM11-'DJB Daily Readings'!DM10 -> 4 | AT3: ='DJB Daily Readings'!DQ11-'DJB Daily Readings'!DQ10 -> 7 | AU3: =('DJB Daily Readings'!DT11-'DJB Daily Readings'!DT10)*100 -> 1020 | AV3: =('DJB Daily Readings'!DV11-'DJB Daily Readings'!DV10)*100 -> 810 | AW3: =('DJB Daily Readings'!DX11-'DJB Daily Readings'!DX10)*100 -> 600 | AX3: =('DJB Daily Readings'!DZ11-'DJB Daily Readings'!DZ10)*100 -> 610 | AY3: ='DJB Daily Readings'!EB11-'DJB Daily Readings'!EB10 -> 594 | AZ3: ='DJB Daily Readings'!ED11-'DJB Daily Readings'!ED10 -> 139.9 | BA3: ='DJB Daily Readings'!EG11-'DJB Daily Readings'!EG10 -> 4100 | BB3: ='DJB Daily Readings'!EI11-'DJB Daily Readings'!EI10 -> 230 | BC3: ='DJB Daily Readings'!EQ11-'DJB Daily Readings'!EQ10 -> 2900 | BD3: ='DJB Daily Readings'!EK11-'DJB Daily Readings'!EK10 -> 1200 | BE3: ='DJB Daily Readings'!EM11-'DJB Daily Readings'!EM10 -> 700 | BF3: ='DJB Daily Readings'!EO11-'DJB Daily Readings'!EO10 -> 670 | BG3: =('DJB Daily Readings'!ET11-'DJB Daily Readings'!ET10)*1.89 -> 26.46 | BH3: =('DJB Daily Readings'!EV11-'DJB Daily Readings'!EV10)*1.89 -> 18.9 | BI3: =('DJB Daily Readings'!EZ11-'DJB Daily Readings'!EZ10)*1.89 -> 41.58 | BJ3: =('DJB Daily Readings'!EX11-'DJB Daily Readings'!EX10)*1.89 -> 17.01 | BK3: =('DJB Daily Readings'!FB11-'DJB Daily Readings'!FB10)*1.89 -> 62.37 | BL3: ='DJB Daily Readings'!J11 -> 210 | BM3: ='DJB Daily Readings'!FF11 -> 148.855 | BN3: ='DJB Daily Readings'!FH11 -> 0 | BO3: ='DJB Daily Readings'!FJ11 -> 5 | BP3: ='DJB Daily Readings'!FL11 -> 4 | BQ3: ='DJB Daily Readings'!FN11 -> 5 | BR3: ='DJB Daily Readings'!FP11 -> 0.03 | BS3: ='DJB Daily Readings'!FR11 -> 234.6
A4: Dubai at Jumeirah Beach | B4: =B3+1 -> 3 | C4: 3 | D4: 2023 | E4: =237*0.87 -> 206.19 | F4: =357+54 -> 411 | G4: ='DJB Daily Readings'!C12-'DJB Daily Readings'!C11 -> 721 | H4: ='DJB Daily Readings'!F12-'DJB Daily Readings'!F11 -> 532 | I4: ='DJB Daily Readings'!L11 -> 210 | J4: ='DJB Daily Readings'!N11 -> 0 | K4: ='DJB Daily Readings'!O12-'DJB Daily Readings'!O11 -> 115 | L4: ='DJB Daily Readings'!R12-'DJB Daily Readings'!R11 -> 17 | M4: ='DJB Daily Readings'!U12-'DJB Daily Readings'!U11 -> 2046.24 | N4: ='DJB Daily Readings'!X12-'DJB Daily Readings'!X11 -> 6677.12 | O4: ='DJB Daily Readings'!AA12-'DJB Daily Readings'!AA11 -> 0 | P4: ='DJB Daily Readings'!AD12-'DJB Daily Readings'!AD11 -> 4289.84 | Q4: ='DJB Daily Readings'!AG12-'DJB Daily Readings'!AG11 -> 10523.52 | R4: ='DJB Daily Readings'!AJ12-'DJB Daily Readings'!AJ11 -> 5554.08 | S4: ='DJB Daily Readings'!AM12-'DJB Daily Readings'!AM11 -> 4336.08 | T4: ='DJB Daily Readings'!AP12-'DJB Daily Readings'!AP11 -> 4482.24 | U4: ='DJB Daily Readings'!AS12-'DJB Daily Readings'!AS11 -> 3215.52 | V4: ='DJB Daily Readings'!AV12-'DJB Daily Readings'!AV11 -> 5797.68 | W4: ='DJB Daily Readings'!AZ12-'DJB Daily Readings'!AZ11 -> 0 | X4: ='DJB Daily Readings'!BC12-'DJB Daily Readings'!BC11 -> 6400 | Y4: ='DJB Daily Readings'!BF12-'DJB Daily Readings'!BF11 -> 56100 | Z4: =('DJB Daily Readings'!CK12-'DJB Daily Readings'!CK11)*1.89 -> 151.2 | AA4: =('DJB Daily Readings'!CN12-'DJB Daily Readings'!CN11)*1.89 -> 219.24 | AB4: =('DJB Daily Readings'!CQ12-'DJB Daily Readings'!CQ11)*1.89 -> 279.72 | AC4: ='DJB Daily Readings'!CT12-'DJB Daily Readings'!CT11 -> 176 | AD4: =('DJB Daily Readings'!BY12-'DJB Daily Readings'!BY11)*1.89 -> 34.02 | AE4: =('DJB Daily Readings'!CA12-'DJB Daily Readings'!CA11)*1.89 -> 37.8 | AF4: =('DJB Daily Readings'!CC12-'DJB Daily Readings'!CC11)*1.89 -> 15.12 | AG4: =('DJB Daily Readings'!CE12-'DJB Daily Readings'!CE11)*1.89 -> 17.01 | AH4: =('DJB Daily Readings'!CG12-'DJB Daily Readings'!CG11)*1.89 -> 24.57 | AI4: =('DJB Daily Readings'!CI12-'DJB Daily Readings'!CI11)*1.89 -> 68.04 | AJ4: ='DJB Daily Readings'!CY12-'DJB Daily Readings'!CY11 -> 8 | AK4: ='DJB Daily Readings'!CW12-'DJB Daily Readings'!CW11 -> 9 | AL4: ='DJB Daily Readings'!DC12-'DJB Daily Readings'!DC11 -> 14 | AM4: ='DJB Daily Readings'!DA12-'DJB Daily Readings'!DA11 -> 21 | AN4: ='DJB Daily Readings'!DG12-'DJB Daily Readings'!DG11 -> 6 | AO4: ='DJB Daily Readings'!DE12-'DJB Daily Readings'!DE11 -> 10 | AP4: ='DJB Daily Readings'!DK12-'DJB Daily Readings'!DK11 -> 11 | AQ4: ='DJB Daily Readings'!DI12-'DJB Daily Readings'!DI11 -> 14 | AR4: ='DJB Daily Readings'!DO12-'DJB Daily Readings'!DO11 -> 8 | AS4: ='DJB Daily Readings'!DM12-'DJB Daily Readings'!DM11 -> 4 | AT4: ='DJB Daily Readings'!DQ12-'DJB Daily Readings'!DQ11 -> 6 | AU4: =('DJB Daily Readings'!DT12-'DJB Daily Readings'!DT11)*100 -> 1100 | AV4: =('DJB Daily Readings'!DV12-'DJB Daily Readings'!DV11)*100 -> 900 | AW4: =('DJB Daily Readings'!DX12-'DJB Daily Readings'!DX11)*100 -> 670 | AX4: =('DJB Daily Readings'!DZ12-'DJB Daily Readings'!DZ11)*100 -> 720 | AY4: ='DJB Daily Readings'!EB12-'DJB Daily Readings'!EB11 -> 658 | AZ4: ='DJB Daily Readings'!ED12-'DJB Daily Readings'!ED11 -> 152 | BA4: ='DJB Daily Readings'!EG12-'DJB Daily Readings'!EG11 -> 4800 | BB4: ='DJB Daily Readings'!EI12-'DJB Daily Readings'!EI11 -> 330 | BC4: ='DJB Daily Readings'!EQ12-'DJB Daily Readings'!EQ11 -> 4800 | BD4: ='DJB Daily Readings'!EK12-'DJB Daily Readings'!EK11 -> 1500 | BE4: ='DJB Daily Readings'!EM12-'DJB Daily Readings'!EM11 -> 700 | BF4: ='DJB Daily Readings'!EO12-'DJB Daily Readings'!EO11 -> 810 | BG4: =('DJB Daily Readings'!ET12-'DJB Daily Readings'!ET11)*1.89 -> 32.13 | BH4: =('DJB Daily Readings'!EV12-'DJB Daily Readings'!EV11)*1.89 -> 24.57 | BI4: =('DJB Daily Readings'!EZ12-'DJB Daily Readings'!EZ11)*1.89 -> 30.24 | BJ4: =('DJB Daily Readings'!EX12-'DJB Daily Readings'!EX11)*1.89 -> 24.57 | BK4: =('DJB Daily Readings'!FB12-'DJB Daily Readings'!FB11)*1.89 -> 60.48 | BL4: ='DJB Daily Readings'!J12 -> 356 | BM4: ='DJB Daily Readings'!FF12 -> 152.295 | BN4: ='DJB Daily Readings'!FH12 -> 0 | BO4: ='DJB Daily Readings'!FJ12 -> 6 | BP4: ='DJB Daily Readings'!FL12 -> 5 | BQ4: ='DJB Daily Readings'!FN12 -> 3 | BR4: ='DJB Daily Readings'!FP12 -> 0.05 | BS4: ='DJB Daily Readings'!FR12 -> 161.1
A5: Dubai at Jumeirah Beach | B5: =B4+1 -> 4 | C5: 3 | D5: 2023 | E5: =237*0.91 -> 215.67 | F5: =354+47 -> 401 | G5: ='DJB Daily Readings'!C13-'DJB Daily Readings'!C12 -> 739 | H5: ='DJB Daily Readings'!F13-'DJB Daily Readings'!F12 -> 618 | I5: ='DJB Daily Readings'!L12 -> 276 | J5: ='DJB Daily Readings'!N12 -> 0 | K5: ='DJB Daily Readings'!O13-'DJB Daily Readings'!O12 -> 120 | L5: ='DJB Daily Readings'!R13-'DJB Daily Readings'!R12 -> 23 | M5: ='DJB Daily Readings'!U13-'DJB Daily Readings'!U12 -> 3410.4 | N5: ='DJB Daily Readings'!X13-'DJB Daily Readings'!X12 -> 3554.08 | O5: ='DJB Daily Readings'!AA13-'DJB Daily Readings'!AA12 -> 0 | P5: ='DJB Daily Readings'!AD13-'DJB Daily Readings'!AD12 -> 6813.36 | Q5: ='DJB Daily Readings'!AG13-'DJB Daily Readings'!AG12 -> 1315.44 | R5: ='DJB Daily Readings'!AJ13-'DJB Daily Readings'!AJ12 -> 6723.36 | S5: ='DJB Daily Readings'!AM13-'DJB Daily Readings'!AM12 -> 5018.16 | T5: ='DJB Daily Readings'!AP13-'DJB Daily Readings'!AP12 -> 5748.96 | U5: ='DJB Daily Readings'!AS13-'DJB Daily Readings'!AS12 -> 3848.88 | V5: ='DJB Daily Readings'!AV13-'DJB Daily Readings'!AV12 -> 7210.56 | W5: ='DJB Daily Readings'!AZ13-'DJB Daily Readings'!AZ12 -> 0 | X5: ='DJB Daily Readings'!BC13-'DJB Daily Readings'!BC12 -> 59700 | Y5: ='DJB Daily Readings'!BF13-'DJB Daily Readings'!BF12 -> 0 | Z5: =('DJB Daily Readings'!CK13-'DJB Daily Readings'!CK12)*1.89 -> 179.55 | AA5: =('DJB Daily Readings'!CN13-'DJB Daily Readings'!CN12)*1.89 -> 260.82 | AB5: =('DJB Daily Readings'!CQ13-'DJB Daily Readings'!CQ12)*1.89 -> 427.14 | AC5: ='DJB Daily Readings'!CT13-'DJB Daily Readings'!CT12 -> 213 | AD5: =('DJB Daily Readings'!BY13-'DJB Daily Readings'!BY12)*1.89 -> 39.69 | AE5: =('DJB Daily Readings'!CA13-'DJB Daily Readings'!CA12)*1.89 -> 43.47 | AF5: =('DJB Daily Readings'!CC13-'DJB Daily Readings'!CC12)*1.89 -> 18.9 | AG5: =('DJB Daily Readings'!CE13-'DJB Daily Readings'!CE12)*1.89 -> 24.57 | AH5: =('DJB Daily Readings'!CG13-'DJB Daily Readings'!CG12)*1.89 -> 37.8 | AI5: =('DJB Daily Readings'!CI13-'DJB Daily Readings'!CI12)*1.89 -> 88.83 | AJ5: ='DJB Daily Readings'!CY13-'DJB Daily Readings'!CY12 -> 9 | AK5: ='DJB Daily Readings'!CW13-'DJB Daily Readings'!CW12 -> 10 | AL5: ='DJB Daily Readings'!DC13-'DJB Daily Readings'!DC12 -> 14 | AM5: ='DJB Daily Readings'!DA13-'DJB Daily Readings'!DA12 -> 27 | AN5: ='DJB Daily Readings'!DG13-'DJB Daily Readings'!DG12 -> 5 | AO5: ='DJB Daily Readings'!DE13-'DJB Daily Readings'!DE12 -> 11 | AP5: ='DJB Daily Readings'!DK13-'DJB Daily Readings'!DK12 -> 8 | AQ5: ='DJB Daily Readings'!DI13-'DJB Daily Readings'!DI12 -> 11 | AR5: ='DJB Daily Readings'!DO13-'DJB Daily Readings'!DO12 -> 13 | AS5: ='DJB Daily Readings'!DM13-'DJB Daily Readings'!DM12 -> 6 | AT5: ='DJB Daily Readings'!DQ13-'DJB Daily Readings'!DQ12 -> 7 | AU5: =('DJB Daily Readings'!DT13-'DJB Daily Readings'!DT12)*100 -> 1320 | AV5: =('DJB Daily Readings'!DV13-'DJB Daily Readings'!DV12)*100 -> 1060 | AW5: =('DJB Daily Readings'!DX13-'DJB Daily Readings'!DX12)*100 -> 790 | AX5: =('DJB Daily Readings'!DZ13-'DJB Daily Readings'!DZ12)*100 -> 980 | AY5: ='DJB Daily Readings'!EB13-'DJB Daily Readings'!EB12 -> 765 | AZ5: ='DJB Daily Readings'!ED13-'DJB Daily Readings'!ED12 -> 181.6 | BA5: ='DJB Daily Readings'!EG13-'DJB Daily Readings'!EG12 -> 5900 | BB5: ='DJB Daily Readings'!EI13-'DJB Daily Readings'!EI12 -> 380 | BC5: ='DJB Daily Readings'!EQ13-'DJB Daily Readings'!EQ12 -> 7000 | BD5: ='DJB Daily Readings'!EK13-'DJB Daily Readings'!EK12 -> 1700 | BE5: ='DJB Daily Readings'!EM13-'DJB Daily Readings'!EM12 -> 800 | BF5: ='DJB Daily Readings'!EO13-'DJB Daily Readings'!EO12 -> 870 | BG5: =('DJB Daily Readings'!ET13-'DJB Daily Readings'!ET12)*1.89 -> 37.8 | BH5: =('DJB Daily Readings'!EV13-'DJB Daily Readings'!EV12)*1.89 -> 28.35 | BI5: =('DJB Daily Readings'!EZ13-'DJB Daily Readings'!EZ12)*1.89 -> 30.24 | BJ5: =('DJB Daily Readings'!EX13-'DJB Daily Readings'!EX12)*1.89 -> 32.13 | BK5: =('DJB Daily Readings'!FB13-'DJB Daily Readings'!FB12)*1.89 -> 85.05 | BL5: ='DJB Daily Readings'!J13 -> 328 | BM5: ='DJB Daily Readings'!FF13 -> 166.26 | BN5: ='DJB Daily Readings'!FH13 -> 0 | BO5: ='DJB Daily Readings'!FJ13 -> 5 | BP5: ='DJB Daily Readings'!FL13 -> 8 | BQ5: ='DJB Daily Readings'!FN13 -> 4 | BR5: ='DJB Daily Readings'!FP13 -> 0.67 | BS5: ='DJB Daily Readings'!FR13 -> 257.1
A6: Dubai at Jumeirah Beach | B6: =B5+1 -> 5 | C6: 3 | D6: 2023 | E6: =237*0.85 -> 201.45 | F6: =328+36 -> 364 | G6: ='DJB Daily Readings'!C14-'DJB Daily Readings'!C13 -> 607 | H6: ='DJB Daily Readings'!F14-'DJB Daily Readings'!F13 -> 387 | I6: ='DJB Daily Readings'!L13 -> 265 | J6: ='DJB Daily Readings'!N13 -> 0 | K6: ='DJB Daily Readings'!O14-'DJB Daily Readings'!O13 -> 104 | L6: ='DJB Daily Readings'!R14-'DJB Daily Readings'!R13 -> 15 | M6: ='DJB Daily Readings'!U14-'DJB Daily Readings'!U13 -> 3046.24 | N6: ='DJB Daily Readings'!X14-'DJB Daily Readings'!X13 -> 4507.84 | O6: ='DJB Daily Readings'!AA14-'DJB Daily Readings'!AA13 -> 0 | P6: ='DJB Daily Readings'!AD14-'DJB Daily Readings'!AD13 -> 13600.32 | Q6: ='DJB Daily Readings'!AG14-'DJB Daily Readings'!AG13 -> 535.92 | R6: ='DJB Daily Readings'!AJ14-'DJB Daily Readings'!AJ13 -> 4238.64 | S6: ='DJB Daily Readings'!AM14-'DJB Daily Readings'!AM13 -> 3069.36 | T6: ='DJB Daily Readings'!AP14-'DJB Daily Readings'!AP13 -> 3264.24 | U6: ='DJB Daily Readings'!AS14-'DJB Daily Readings'!AS13 -> 2338.56 | V6: ='DJB Daily Readings'!AV14-'DJB Daily Readings'!AV13 -> 4336.08 | W6: ='DJB Daily Readings'!AZ14-'DJB Daily Readings'!AZ13 -> 0 | X6: ='DJB Daily Readings'!BC14-'DJB Daily Readings'!BC13 -> 55500 | Y6: ='DJB Daily Readings'!BF14-'DJB Daily Readings'!BF13 -> 0 | Z6: =('DJB Daily Readings'!CK14-'DJB Daily Readings'!CK13)*1.89 -> 122.85 | AA6: =('DJB Daily Readings'!CN14-'DJB Daily Readings'!CN13)*1.89 -> 170.1 | AB6: =('DJB Daily Readings'!CQ14-'DJB Daily Readings'!CQ13)*1.89 -> 251.37 | AC6: ='DJB Daily Readings'!CT14-'DJB Daily Readings'!CT13 -> 144 | AD6: =('DJB Daily Readings'!BY14-'DJB Daily Readings'!BY13)*1.89 -> 24.57 | AE6: =('DJB Daily Readings'!CA14-'DJB Daily Readings'!CA13)*1.89 -> 30.24 | AF6: =('DJB Daily Readings'!CC14-'DJB Daily Readings'!CC13)*1.89 -> 11.34 | AG6: =('DJB Daily Readings'!CE14-'DJB Daily Readings'!CE13)*1.89 -> 13.23 | AH6: =('DJB Daily Readings'!CG14-'DJB Daily Readings'!CG13)*1.89 -> 18.9 | AI6: =('DJB Daily Readings'!CI14-'DJB Daily Readings'!CI13)*1.89 -> 56.7 | AJ6: ='DJB Daily Readings'!CY14-'DJB Daily Readings'!CY13 -> 3 | AK6: ='DJB Daily Readings'!CW14-'DJB Daily Readings'!CW13 -> 3 | AL6: ='DJB Daily Readings'!DC14-'DJB Daily Readings'!DC13 -> 11 | AM6: ='DJB Daily Readings'!DA14-'DJB Daily Readings'!DA13 -> 13 | AN6: ='DJB Daily Readings'!DG14-'DJB Daily Readings'!DG13 -> 5 | AO6: ='DJB Daily Readings'!DE14-'DJB Daily Readings'!DE13 -> 7 | AP6: ='DJB Daily Readings'!DK14-'DJB Daily Readings'!DK13 -> 21 | AQ6: ='DJB Daily Readings'!DI14-'DJB Daily Readings'!DI13 -> 7 | AR6: ='DJB Daily Readings'!DO14-'DJB Daily Readings'!DO13 -> 6 | AS6: ='DJB Daily Readings'!DM14-'DJB Daily Readings'!DM13 -> 4 | AT6: ='DJB Daily Readings'!DQ14-'DJB Daily Readings'!DQ13 -> 6 | AU6: =('DJB Daily Readings'!DT14-'DJB Daily Readings'!DT13)*100 -> 830 | AV6: =('DJB Daily Readings'!DV14-'DJB Daily Readings'!DV13)*100 -> 660 | AW6: =('DJB Daily Readings'!DX14-'DJB Daily Readings'!DX13)*100 -> 490 | AX6: =('DJB Daily Readings'!DZ14-'DJB Daily Readings'!DZ13)*100 -> 620 | AY6: ='DJB Daily Readings'!EB14-'DJB Daily Readings'!EB13 -> 496 | AZ6: ='DJB Daily Readings'!ED14-'DJB Daily Readings'!ED13 -> 120.1 | BA6: ='DJB Daily Readings'!EG14-'DJB Daily Readings'!EG13 -> 2600 | BB6: ='DJB Daily Readings'!EI14-'DJB Daily Readings'!EI13 -> 200 | BC6: ='DJB Daily Readings'!EQ14-'DJB Daily Readings'!EQ13 -> 3000 | BD6: ='DJB Daily Readings'!EK14-'DJB Daily Readings'!EK13 -> 500 | BE6: ='DJB Daily Readings'!EM14-'DJB Daily Readings'!EM13 -> 500 | BF6: ='DJB Daily Readings'!EO14-'DJB Daily Readings'!EO13 -> 430 | BG6: =('DJB Daily Readings'!ET14-'DJB Daily Readings'!ET13)*1.89 -> 20.79 | BH6: =('DJB Daily Readings'!EV14-'DJB Daily Readings'!EV13)*1.89 -> 17.01 | BI6: =('DJB Daily Readings'!EZ14-'DJB Daily Readings'!EZ13)*1.89 -> 24.57 | BJ6: =('DJB Daily Readings'!EX14-'DJB Daily Readings'!EX13)*1.89 -> 15.12 | BK6: =('DJB Daily Readings'!FB14-'DJB Daily Readings'!FB13)*1.89 -> 39.69 | BL6: ='DJB Daily Readings'!J14 -> 182 | BM6: ='DJB Daily Readings'!FF14 -> 117.182 | BN6: ='DJB Daily Readings'!FH14 -> 0 | BO6: ='DJB Daily Readings'!FJ14 -> 8 | BP6: ='DJB Daily Readings'!FL14 -> 4 | BQ6: ='DJB Daily Readings'!FN14 -> 4 | BR6: ='DJB Daily Readings'!FP14 -> 0.03 | BS6: ='DJB Daily Readings'!FR14 -> 108.3
A7: Dubai at Jumeirah Beach | B7: =B6+1 -> 6 | C7: 3 | D7: 2023 | E7: =237*0.89 -> 210.93 | F7: =319+35 -> 354 | G7: ='DJB Daily Readings'!C15-'DJB Daily Readings'!C14 -> 608 | H7: ='DJB Daily Readings'!F15-'DJB Daily Readings'!F14 -> 504 | I7: ='DJB Daily Readings'!L14 -> 210 | J7: ='DJB Daily Readings'!N14 -> 0 | K7: ='DJB Daily Readings'!O15-'DJB Daily Readings'!O14 -> 103 | L7: ='DJB Daily Readings'!R15-'DJB Daily Readings'!R14 -> 13 | M7: ='DJB Daily Readings'!U15-'DJB Daily Readings'!U14 -> 2215.52 | N7: ='DJB Daily Readings'!X15-'DJB Daily Readings'!X14 -> 4456.64 | O7: ='DJB Daily Readings'!AA15-'DJB Daily Readings'!AA14 -> 194.88 | P7: ='DJB Daily Readings'!AD15-'DJB Daily Readings'!AD14 -> 7792.72 | Q7: ='DJB Daily Readings'!AG15-'DJB Daily Readings'!AG14 -> 2143.68 | R7: ='DJB Daily Readings'!AJ15-'DJB Daily Readings'!AJ14 -> 6577.2 | S7: ='DJB Daily Readings'!AM15-'DJB Daily Readings'!AM14 -> 4628.4 | T7: ='DJB Daily Readings'!AP15-'DJB Daily Readings'!AP14 -> 4969.44 | U7: ='DJB Daily Readings'!AS15-'DJB Daily Readings'!AS14 -> 3605.28 | V7: ='DJB Daily Readings'!AV15-'DJB Daily Readings'!AV14 -> 6187.44 | W7: ='DJB Daily Readings'!AZ15-'DJB Daily Readings'!AZ14 -> 0 | X7: ='DJB Daily Readings'!BC15-'DJB Daily Readings'!BC14 -> 53200 | Y7: ='DJB Daily Readings'!BF15-'DJB Daily Readings'!BF14 -> 0 | Z7: =('DJB Daily Readings'!CK15-'DJB Daily Readings'!CK14)*1.89 -> 175.77 | AA7: =('DJB Daily Readings'!CN15-'DJB Daily Readings'!CN14)*1.89 -> 232.47 | AB7: =('DJB Daily Readings'!CQ15-'DJB Daily Readings'!CQ14)*1.89 -> 351.54 | AC7: ='DJB Daily Readings'!CT15-'DJB Daily Readings'!CT14 -> 207 | AD7: =('DJB Daily Readings'!BY15-'DJB Daily Readings'!BY14)*1.89 -> 39.69 | AE7: =('DJB Daily Readings'!CA15-'DJB Daily Readings'!CA14)*1.89 -> 43.47 | AF7: =('DJB Daily Readings'!CC15-'DJB Daily Readings'!CC14)*1.89 -> 18.9 | AG7: =('DJB Daily Readings'!CE15-'DJB Daily Readings'!CE14)*1.89 -> 18.9 | AH7: =('DJB Daily Readings'!CG15-'DJB Daily Readings'!CG14)*1.89 -> 37.8 | AI7: =('DJB Daily Readings'!CI15-'DJB Daily Readings'!CI14)*1.89 -> 79.38 | AJ7: ='DJB Daily Readings'!CY15-'DJB Daily Readings'!CY14 -> 5 | AK7: ='DJB Daily Readings'!CW15-'DJB Daily Readings'!CW14 -> 6 | AL7: ='DJB Daily Readings'!DC15-'DJB Daily Readings'!DC14 -> 16 | AM7: ='DJB Daily Readings'!DA15-'DJB Daily Readings'!DA14 -> 19 | AN7: ='DJB Daily Readings'!DG15-'DJB Daily Readings'!DG14 -> 5 | AO7: ='DJB Daily Readings'!DE15-'DJB Daily Readings'!DE14 -> 9 | AP7: ='DJB Daily Readings'!DK15-'DJB Daily Readings'!DK14 -> 5 | AQ7: ='DJB Daily Readings'!DI15-'DJB Daily Readings'!DI14 -> 9 | AR7: ='DJB Daily Readings'!DO15-'DJB Daily Readings'!DO14 -> 9 | AS7: ='DJB Daily Readings'!DM15-'DJB Daily Readings'!DM14 -> 4 | AT7: ='DJB Daily Readings'!DQ15-'DJB Daily Readings'!DQ14 -> 6 | AU7: =('DJB Daily Readings'!DT15-'DJB Daily Readings'!DT14)*100 -> 1190 | AV7: =('DJB Daily Readings'!DV15-'DJB Daily Readings'!DV14)*100 -> 810 | AW7: =('DJB Daily Readings'!DX15-'DJB Daily Readings'!DX14)*100 -> 720 | AX7: =('DJB Daily Readings'!DZ15-'DJB Daily Readings'!DZ14)*100 -> 690 | AY7: ='DJB Daily Readings'!EB15-'DJB Daily Readings'!EB14 -> 672 | AZ7: ='DJB Daily Readings'!ED15-'DJB Daily Readings'!ED14 -> 176.1 | BA7: ='DJB Daily Readings'!EG15-'DJB Daily Readings'!EG14 -> 4600 | BB7: ='DJB Daily Readings'!EI15-'DJB Daily Readings'!EI14 -> 310 | BC7: ='DJB Daily Readings'!EQ15-'DJB Daily Readings'!EQ14 -> 5400 | BD7: ='DJB Daily Readings'!EK15-'DJB Daily Readings'!EK14 -> 1200 | BE7: ='DJB Daily Readings'!EM15-'DJB Daily Readings'!EM14 -> 600 | BF7: ='DJB Daily Readings'!EO15-'DJB Daily Readings'!EO14 -> 720 | BG7: =('DJB Daily Readings'!ET15-'DJB Daily Readings'!ET14)*1.89 -> 39.69 | BH7: =('DJB Daily Readings'!EV15-'DJB Daily Readings'!EV14)*1.89 -> 24.57 | BI7: =('DJB Daily Readings'!EZ15-'DJB Daily Readings'!EZ14)*1.89 -> 24.57 | BJ7: =('DJB Daily Readings'!EX15-'DJB Daily Readings'!EX14)*1.89 -> 15.12 | BK7: =('DJB Daily Readings'!FB15-'DJB Daily Readings'!FB14)*1.89 -> 68.04 | BL7: ='DJB Daily Readings'!J15 -> 285 | BM7: ='DJB Daily Readings'!FF15 -> 162.1311 | BN7: ='DJB Daily Readings'!FH15 -> 10 | BO7: ='DJB Daily Readings'!FJ15 -> 7 | BP7: ='DJB Daily Readings'!FL15 -> 4 | BQ7: ='DJB Daily Readings'!FN15 -> 3 | BR7: ='DJB Daily Readings'!FP15 -> 1.232 | BS7: ='DJB Daily Readings'!FR15 -> 250
A8: Dubai at Jumeirah Beach | B8: =B7+1 -> 7 | C8: 3 | D8: 2023 | E8: =237*0.91 -> 215.67 | F8: =339+38 -> 377 | G8: ='DJB Daily Readings'!C16-'DJB Daily Readings'!C15 -> 618 | H8: ='DJB Daily Readings'!F16-'DJB Daily Readings'!F15 -> 390 | I8: ='DJB Daily Readings'!L15 -> 255 | J8: ='DJB Daily Readings'!N15 -> 0 | K8: ='DJB Daily Readings'!O16-'DJB Daily Readings'!O15 -> 103 | L8: ='DJB Daily Readings'!R16-'DJB Daily Readings'!R15 -> 16 | M8: ='DJB Daily Readings'!U16-'DJB Daily Readings'!U15 -> 2143.68 | N8: ='DJB Daily Readings'!X16-'DJB Daily Readings'!X15 -> 3800.16 | O8: ='DJB Daily Readings'!AA16-'DJB Daily Readings'!AA15 -> 8574.72 | P8: ='DJB Daily Readings'!AD16-'DJB Daily Readings'!AD15 -> 48.72 | Q8: ='DJB Daily Readings'!AG16-'DJB Daily Readings'!AG15 -> 682.08 | R8: ='DJB Daily Readings'!AJ16-'DJB Daily Readings'!AJ15 -> 4384.8 | S8: ='DJB Daily Readings'!AM16-'DJB Daily Readings'!AM15 -> 3069.36 | T8: ='DJB Daily Readings'!AP16-'DJB Daily Readings'!AP15 -> 3312.96 | U8: ='DJB Daily Readings'!AS16-'DJB Daily Readings'!AS15 -> 2387.28 | V8: ='DJB Daily Readings'!AV16-'DJB Daily Readings'!AV15 -> 4579.68 | W8: ='DJB Daily Readings'!AZ16-'DJB Daily Readings'!AZ15 -> 46000 | X8: ='DJB Daily Readings'!BC16-'DJB Daily Readings'!BC15 -> 2300 | Y8: ='DJB Daily Readings'!BF16-'DJB Daily Readings'!BF15 -> 6300 | Z8: =('DJB Daily Readings'!CK16-'DJB Daily Readings'!CK15)*1.89 -> 124.74 | AA8: =('DJB Daily Readings'!CN16-'DJB Daily Readings'!CN15)*1.89 -> 168.21 | AB8: =('DJB Daily Readings'!CQ16-'DJB Daily Readings'!CQ15)*1.89 -> 211.68 | AC8: ='DJB Daily Readings'!CT16-'DJB Daily Readings'!CT15 -> 147 | AD8: =('DJB Daily Readings'!BY16-'DJB Daily Readings'!BY15)*1.89 -> 30.24 | AE8: =('DJB Daily Readings'!CA16-'DJB Daily Readings'!CA15)*1.89 -> 35.91 | AF8: =('DJB Daily Readings'!CC16-'DJB Daily Readings'!CC15)*1.89 -> 11.34 | AG8: =('DJB Daily Readings'!CE16-'DJB Daily Readings'!CE15)*1.89 -> 15.12 | AH8: =('DJB Daily Readings'!CG16-'DJB Daily Readings'!CG15)*1.89 -> 18.9 | AI8: =('DJB Daily Readings'!CI16-'DJB Daily Readings'!CI15)*1.89 -> 54.81 | AJ8: ='DJB Daily Readings'!CY16-'DJB Daily Readings'!CY15 -> 8 | AK8: ='DJB Daily Readings'!CW16-'DJB Daily Readings'!CW15 -> 8 | AL8: ='DJB Daily Readings'!DC16-'DJB Daily Readings'!DC15 -> 14 | AM8: ='DJB Daily Readings'!DA16-'DJB Daily Readings'!DA15 -> 16 | AN8: ='DJB Daily Readings'!DG16-'DJB Daily Readings'!DG15 -> 5 | AO8: ='DJB Daily Readings'!DE16-'DJB Daily Readings'!DE15 -> 6 | AP8: ='DJB Daily Readings'!DK16-'DJB Daily Readings'!DK15 -> 7 | AQ8: ='DJB Daily Readings'!DI16-'DJB Daily Readings'!DI15 -> 8 | AR8: ='DJB Daily Readings'!DO16-'DJB Daily Readings'!DO15 -> 7 | AS8: ='DJB Daily Readings'!DM16-'DJB Daily Readings'!DM15 -> 4 | AT8: ='DJB Daily Readings'!DQ16-'DJB Daily Readings'!DQ15 -> 7 | AU8: =('DJB Daily Readings'!DT16-'DJB Daily Readings'!DT15)*100 -> 840 | AV8: =('DJB Daily Readings'!DV16-'DJB Daily Readings'!DV15)*100 -> 800 | AW8: =('DJB Daily Readings'!DX16-'DJB Daily Readings'!DX15)*100 -> 500 | AX8: =('DJB Daily Readings'!DZ16-'DJB Daily Readings'!DZ15)*100 -> 590 | AY8: ='DJB Daily Readings'!EB16-'DJB Daily Readings'!EB15 -> 465 | AZ8: ='DJB Daily Readings'!ED16-'DJB Daily Readings'!ED15 -> 123 | BA8: ='DJB Daily Readings'!EG16-'DJB Daily Readings'!EG15 -> 3200 | BB8: ='DJB Daily Readings'!EI16-'DJB Daily Readings'!EI15 -> 240 | BC8: ='DJB Daily Readings'!EQ16-'DJB Daily Readings'!EQ15 -> 4100 | BD8: ='DJB Daily Readings'!EK16-'DJB Daily Readings'!EK15 -> 800 | BE8: ='DJB Daily Readings'!EM16-'DJB Daily Readings'!EM15 -> 600 | BF8: ='DJB Daily Readings'!EO16-'DJB Daily Readings'!EO15 -> 360 | BG8: =('DJB Daily Readings'!ET16-'DJB Daily Readings'!ET15)*1.89 -> 26.46 | BH8: =('DJB Daily Readings'!EV16-'DJB Daily Readings'!EV15)*1.89 -> 15.12 | BI8: =('DJB Daily Readings'!EZ16-'DJB Daily Readings'!EZ15)*1.89 -> 24.57 | BJ8: =('DJB Daily Readings'!EX16-'DJB Daily Readings'!EX15)*1.89 -> 17.01 | BK8: =('DJB Daily Readings'!FB16-'DJB Daily Readings'!FB15)*1.89 -> 41.58 | BL8: ='DJB Daily Readings'!J16 -> 198 | BM8: ='DJB Daily Readings'!FF16 -> 148.7739 | BN8: ='DJB Daily Readings'!FH16 -> 4 | BO8: ='DJB Daily Readings'!FJ16 -> 4 | BP8: ='DJB Daily Readings'!FL16 -> 6 | BQ8: ='DJB Daily Readings'!FN16 -> 4 | BR8: ='DJB Daily Readings'!FP16 -> 1.228 | BS8: ='DJB Daily Readings'!FR16 -> 240
A9: Dubai at Jumeirah Beach | B9: =B8+1 -> 8 | C9: 3 | D9: 2023 | E9: =237*0.76 -> 180.12 | F9: =307+43 -> 350 | G9: ='DJB Daily Readings'!C17-'DJB Daily Readings'!C16 -> 627 | H9: ='DJB Daily Readings'!F17-'DJB Daily Readings'!F16 -> 480 | I9: ='DJB Daily Readings'!L16 -> 237 | J9: ='DJB Daily Readings'!N16 -> 0 | K9: ='DJB Daily Readings'!O17-'DJB Daily Readings'!O16 -> 112 | L9: ='DJB Daily Readings'!R17-'DJB Daily Readings'!R16 -> 16 | M9: ='DJB Daily Readings'!U17-'DJB Daily Readings'!U16 -> 2777.04 | N9: ='DJB Daily Readings'!X17-'DJB Daily Readings'!X16 -> 4677.12 | O9: ='DJB Daily Readings'!AA17-'DJB Daily Readings'!AA16 -> 10523.52 | P9: ='DJB Daily Readings'!AD17-'DJB Daily Readings'!AD16 -> 48.72 | Q9: ='DJB Daily Readings'!AG17-'DJB Daily Readings'!AG16 -> 925.68 | R9: ='DJB Daily Readings'!AJ17-'DJB Daily Readings'!AJ16 -> 5505.36 | S9: ='DJB Daily Readings'!AM17-'DJB Daily Readings'!AM16 -> 3897.6 | T9: ='DJB Daily Readings'!AP17-'DJB Daily Readings'!AP16 -> 4384.8 | U9: ='DJB Daily Readings'!AS17-'DJB Daily Readings'!AS16 -> 2971.92 | V9: ='DJB Daily Readings'!AV17-'DJB Daily Readings'!AV16 -> 5748.96 | W9: ='DJB Daily Readings'!AZ17-'DJB Daily Readings'!AZ16 -> 57400 | X9: ='DJB Daily Readings'!BC17-'DJB Daily Readings'!BC16 -> 0 | Y9: ='DJB Daily Readings'!BF17-'DJB Daily Readings'!BF16 -> 0 | Z9: =('DJB Daily Readings'!CK17-'DJB Daily Readings'!CK16)*1.89 -> 151.2 | AA9: =('DJB Daily Readings'!CN17-'DJB Daily Readings'!CN16)*1.89 -> 185.22 | AB9: =('DJB Daily Readings'!CQ17-'DJB Daily Readings'!CQ16)*1.89 -> 247.59 | AC9: ='DJB Daily Readings'!CT17-'DJB Daily Readings'!CT16 -> 176 | AD9: =('DJB Daily Readings'!BY17-'DJB Daily Readings'!BY16)*1.89 -> 26.46 | AE9: =('DJB Daily Readings'!CA17-'DJB Daily Readings'!CA16)*1.89 -> 35.91 | AF9: =('DJB Daily Readings'!CC17-'DJB Daily Readings'!CC16)*1.89 -> 11.34 | AG9: =('DJB Daily Readings'!CE17-'DJB Daily Readings'!CE16)*1.89 -> 15.12 | AH9: =('DJB Daily Readings'!CG17-'DJB Daily Readings'!CG16)*1.89 -> 28.35 | AI9: =('DJB Daily Readings'!CI17-'DJB Daily Readings'!CI16)*1.89 -> 66.15 | AJ9: ='DJB Daily Readings'!CY17-'DJB Daily Readings'!CY16 -> 5 | AK9: ='DJB Daily Readings'!CW17-'DJB Daily Readings'!CW16 -> 3 | AL9: ='DJB Daily Readings'!DC17-'DJB Daily Readings'!DC16 -> 17 | AM9: ='DJB Daily Readings'!DA17-'DJB Daily Readings'!DA16 -> 19 | AN9: ='DJB Daily Readings'!DG17-'DJB Daily Readings'!DG16 -> 6 | AO9: ='DJB Daily Readings'!DE17-'DJB Daily Readings'!DE16 -> 7 | AP9: ='DJB Daily Readings'!DK17-'DJB Daily Readings'!DK16 -> 12 | AQ9: ='DJB Daily Readings'!DI17-'DJB Daily Readings'!DI16 -> 8 | AR9: ='DJB Daily Readings'!DO17-'DJB Daily Readings'!DO16 -> 9 | AS9: ='DJB Daily Readings'!DM17-'DJB Daily Readings'!DM16 -> 4 | AT9: ='DJB Daily Readings'!DQ17-'DJB Daily Readings'!DQ16 -> 3 | AU9: =('DJB Daily Readings'!DT17-'DJB Daily Readings'!DT16)*100 -> 1120 | AV9: =('DJB Daily Readings'!DV17-'DJB Daily Readings'!DV16)*100 -> 860 | AW9: =('DJB Daily Readings'!DX17-'DJB Daily Readings'!DX16)*100 -> 640 | AX9: =('DJB Daily Readings'!DZ17-'DJB Daily Readings'!DZ16)*100 -> 670 | AY9: ='DJB Daily Readings'!EB17-'DJB Daily Readings'!EB16 -> 593 | AZ9: ='DJB Daily Readings'!ED17-'DJB Daily Readings'!ED16 -> 154.4 | BA9: ='DJB Daily Readings'!EG17-'DJB Daily Readings'!EG16 -> 4300 | BB9: ='DJB Daily Readings'!EI17-'DJB Daily Readings'!EI16 -> 300 | BC9: ='DJB Daily Readings'!EQ17-'DJB Daily Readings'!EQ16 -> 5400 | BD9: ='DJB Daily Readings'!EK17-'DJB Daily Readings'!EK16 -> 1100 | BE9: ='DJB Daily Readings'!EM17-'DJB Daily Readings'!EM16 -> 700 | BF9: ='DJB Daily Readings'!EO17-'DJB Daily Readings'!EO16 -> 570 | BG9: =('DJB Daily Readings'!ET17-'DJB Daily Readings'!ET16)*1.89 -> 30.24 | BH9: =('DJB Daily Readings'!EV17-'DJB Daily Readings'!EV16)*1.89 -> 20.79 | BI9: =('DJB Daily Readings'!EZ17-'DJB Daily Readings'!EZ16)*1.89 -> 30.24 | BJ9: =('DJB Daily Readings'!EX17-'DJB Daily Readings'!EX16)*1.89 -> 18.9 | BK9: =('DJB Daily Readings'!FB17-'DJB Daily Readings'!FB16)*1.89 -> 64.26 | BL9: ='DJB Daily Readings'!J17 -> 152 | BM9: ='DJB Daily Readings'!FF17 -> 92.602 | BN9: ='DJB Daily Readings'!FH17 -> 2 | BO9: ='DJB Daily Readings'!FJ17 -> 5 | BP9: ='DJB Daily Readings'!FL17 -> 6 | BQ9: ='DJB Daily Readings'!FN17 -> 4 | BR9: ='DJB Daily Readings'!FP17 -> 2.228 | BS9: ='DJB Daily Readings'!FR17 -> 277.1
A10: Dubai at Jumeirah Beach | B10: =B9+1 -> 9 | C10: 3 | D10: 2023 | E10: =237*0.86 -> 203.82 | F10: =309+35 -> 344 | G10: ='DJB Daily Readings'!C18-'DJB Daily Readings'!C17 -> 585 | H10: ='DJB Daily Readings'!F18-'DJB Daily Readings'!F17 -> 485 | I10: ='DJB Daily Readings'!L17 -> 148 | J10: ='DJB Daily Readings'!N17 -> 0 | K10: ='DJB Daily Readings'!O18-'DJB Daily Readings'!O17 -> 113 | L10: ='DJB Daily Readings'!R18-'DJB Daily Readings'!R17 -> 17 | M10: ='DJB Daily Readings'!U18-'DJB Daily Readings'!U17 -> 2728.32 | N10: ='DJB Daily Readings'!X18-'DJB Daily Readings'!X17 -> 4579.68 | O10: ='DJB Daily Readings'!AA18-'DJB Daily Readings'!AA17 -> 9987.6 | P10: ='DJB Daily Readings'!AD18-'DJB Daily Readings'!AD17 -> 48.72 | Q10: ='DJB Daily Readings'!AG18-'DJB Daily Readings'!AG17 -> 828.24 | R10: ='DJB Daily Readings'!AJ18-'DJB Daily Readings'!AJ17 -> 5456.64 | S10: ='DJB Daily Readings'!AM18-'DJB Daily Readings'!AM17 -> 3946.32 | T10: ='DJB Daily Readings'!AP18-'DJB Daily Readings'!AP17 -> 4238.64 | U10: ='DJB Daily Readings'!AS18-'DJB Daily Readings'!AS17 -> 2825.76 | V10: ='DJB Daily Readings'!AV18-'DJB Daily Readings'!AV17 -> 5407.92 | W10: ='DJB Daily Readings'!AZ18-'DJB Daily Readings'!AZ17 -> 56700 | X10: ='DJB Daily Readings'!BC18-'DJB Daily Readings'!BC17 -> 0 | Y10: ='DJB Daily Readings'!BF18-'DJB Daily Readings'!BF17 -> 0 | Z10: =('DJB Daily Readings'!CK18-'DJB Daily Readings'!CK17)*1.89 -> 154.98 | AA10: =('DJB Daily Readings'!CN18-'DJB Daily Readings'!CN17)*1.89 -> 213.57 | AB10: =('DJB Daily Readings'!CQ18-'DJB Daily Readings'!CQ17)*1.89 -> 283.5 | AC10: ='DJB Daily Readings'!CT18-'DJB Daily Readings'!CT17 -> 183 | AD10: =('DJB Daily Readings'!BY18-'DJB Daily Readings'!BY17)*1.89 -> 26.46 | AE10: =('DJB Daily Readings'!CA18-'DJB Daily Readings'!CA17)*1.89 -> 35.91 | AF10: =('DJB Daily Readings'!CC18-'DJB Daily Readings'!CC17)*1.89 -> 11.34 | AG10: =('DJB Daily Readings'!CE18-'DJB Daily Readings'!CE17)*1.89 -> 15.12 | AH10: =('DJB Daily Readings'!CG18-'DJB Daily Readings'!CG17)*1.89 -> 30.24 | AI10: =('DJB Daily Readings'!CI18-'DJB Daily Readings'!CI17)*1.89 -> 64.26 | AJ10: ='DJB Daily Readings'!CY18-'DJB Daily Readings'!CY17 -> 6 | AK10: ='DJB Daily Readings'!CW18-'DJB Daily Readings'!CW17 -> 3 | AL10: ='DJB Daily Readings'!DC18-'DJB Daily Readings'!DC17 -> 12 | AM10: ='DJB Daily Readings'!DA18-'DJB Daily Readings'!DA17 -> 17 | AN10: ='DJB Daily Readings'!DG18-'DJB Daily Readings'!DG17 -> 6 | AO10: ='DJB Daily Readings'!DE18-'DJB Daily Readings'!DE17 -> 8 | AP10: ='DJB Daily Readings'!DK18-'DJB Daily Readings'!DK17 -> 7 | AQ10: ='DJB Daily Readings'!DI18-'DJB Daily Readings'!DI17 -> 10 | AR10: ='DJB Daily Readings'!DO18-'DJB Daily Readings'!DO17 -> 8 | AS10: ='DJB Daily Readings'!DM18-'DJB Daily Readings'!DM17 -> 4 | AT10: ='DJB Daily Readings'!DQ18-'DJB Daily Readings'!DQ17 -> 3 | AU10: =('DJB Daily Readings'!DT18-'DJB Daily Readings'!DT17)*100 -> 1020 | AV10: =('DJB Daily Readings'!DV18-'DJB Daily Readings'!DV17)*100 -> 890 | AW10: =('DJB Daily Readings'!DX18-'DJB Daily Readings'!DX17)*100 -> 620 | AX10: =('DJB Daily Readings'!DZ18-'DJB Daily Readings'!DZ17)*100 -> 640 | AY10: ='DJB Daily Readings'!EB18-'DJB Daily Readings'!EB17 -> 628 | AZ10: ='DJB Daily Readings'!ED18-'DJB Daily Readings'!ED17 -> 150.5 | BA10: ='DJB Daily Readings'!EG18-'DJB Daily Readings'!EG17 -> 4000 | BB10: ='DJB Daily Readings'!EI18-'DJB Daily Readings'!EI17 -> 260 | BC10: ='DJB Daily Readings'!EQ18-'DJB Daily Readings'!EQ17 -> 5100 | BD10: ='DJB Daily Readings'!EK18-'DJB Daily Readings'!EK17 -> 1200 | BE10: ='DJB Daily Readings'!EM18-'DJB Daily Readings'!EM17 -> 500 | BF10: ='DJB Daily Readings'!EO18-'DJB Daily Readings'!EO17 -> 670 | BG10: =('DJB Daily Readings'!ET18-'DJB Daily Readings'!ET17)*1.89 -> 22.68 | BH10: =('DJB Daily Readings'!EV18-'DJB Daily Readings'!EV17)*1.89 -> 22.68 | BI10: =('DJB Daily Readings'!EZ18-'DJB Daily Readings'!EZ17)*1.89 -> 30.24 | BJ10: =('DJB Daily Readings'!EX18-'DJB Daily Readings'!EX17)*1.89 -> 17.01 | BK10: =('DJB Daily Readings'!FB18-'DJB Daily Readings'!FB17)*1.89 -> 60.48 | BL10: ='DJB Daily Readings'!J18 -> 270 | BM10: ='DJB Daily Readings'!FF18 -> 120.856 | BN10: ='DJB Daily Readings'!FH18 -> 9 | BO10: ='DJB Daily Readings'!FJ18 -> 6 | BP10: ='DJB Daily Readings'!FL18 -> 6 | BQ10: ='DJB Daily Readings'!FN18 -> 4 | BR10: ='DJB Daily Readings'!FP18 -> 2.022 | BS10: ='DJB Daily Readings'!FR18 -> 161.3
A11: Dubai at Jumeirah Beach | B11: =B10+1 -> 10 | C11: 3 | D11: 2023 | E11: =237*0.85 -> 201.45 | F11: =311+49 -> 360 | G11: ='DJB Daily Readings'!C19-'DJB Daily Readings'!C18 -> 681 | H11: ='DJB Daily Readings'!F19-'DJB Daily Readings'!F18 -> 523 | I11: ='DJB Daily Readings'!L18 -> 263 | J11: ='DJB Daily Readings'!N18 -> 0 | K11: ='DJB Daily Readings'!O19-'DJB Daily Readings'!O18 -> 103 | L11: ='DJB Daily Readings'!R19-'DJB Daily Readings'!R18 -> 10 | M11: ='DJB Daily Readings'!U19-'DJB Daily Readings'!U18 -> 2874.48 | N11: ='DJB Daily Readings'!X19-'DJB Daily Readings'!X18 -> 4628.4 | O11: ='DJB Daily Readings'!AA19-'DJB Daily Readings'!AA18 -> 7210.56 | P11: ='DJB Daily Readings'!AD19-'DJB Daily Readings'!AD18 -> 779.52 | Q11: ='DJB Daily Readings'!AG19-'DJB Daily Readings'!AG18 -> 2046.24 | R11: ='DJB Daily Readings'!AJ19-'DJB Daily Readings'!AJ18 -> 5602.8 | S11: ='DJB Daily Readings'!AM19-'DJB Daily Readings'!AM18 -> 4043.76 | T11: ='DJB Daily Readings'!AP19-'DJB Daily Readings'!AP18 -> 4530.96 | U11: ='DJB Daily Readings'!AS19-'DJB Daily Readings'!AS18 -> 2874.48 | V11: ='DJB Daily Readings'!AV19-'DJB Daily Readings'!AV18 -> 5554.08 | W11: ='DJB Daily Readings'!AZ19-'DJB Daily Readings'!AZ18 -> 43000 | X11: ='DJB Daily Readings'!BC19-'DJB Daily Readings'!BC18 -> 4000 | Y11: ='DJB Daily Readings'!BF19-'DJB Daily Readings'!BF18 -> 5700 | Z11: =('DJB Daily Readings'!CK19-'DJB Daily Readings'!CK18)*1.89 -> 153.09 | AA11: =('DJB Daily Readings'!CN19-'DJB Daily Readings'!CN18)*1.89 -> 224.91 | AB11: =('DJB Daily Readings'!CQ19-'DJB Daily Readings'!CQ18)*1.89 -> 381.78 | AC11: ='DJB Daily Readings'!CT19-'DJB Daily Readings'!CT18 -> 180 | AD11: =('DJB Daily Readings'!BY19-'DJB Daily Readings'!BY18)*1.89 -> 34.02 | AE11: =('DJB Daily Readings'!CA19-'DJB Daily Readings'!CA18)*1.89 -> 30.24 | AF11: =('DJB Daily Readings'!CC19-'DJB Daily Readings'!CC18)*1.89 -> 11.34 | AG11: =('DJB Daily Readings'!CE19-'DJB Daily Readings'!CE18)*1.89 -> 17.01 | AH11: =('DJB Daily Readings'!CG19-'DJB Daily Readings'!CG18)*1.89 -> 28.35 | AI11: =('DJB Daily Readings'!CI19-'DJB Daily Readings'!CI18)*1.89 -> 73.71 | AJ11: ='DJB Daily Readings'!CY19-'DJB Daily Readings'!CY18 -> 5 | AK11: ='DJB Daily Readings'!CW19-'DJB Daily Readings'!CW18 -> 3 | AL11: ='DJB Daily Readings'!DC19-'DJB Daily Readings'!DC18 -> 15 | AM11: ='DJB Daily Readings'!DA19-'DJB Daily Readings'!DA18 -> 19 | AN11: ='DJB Daily Readings'!DG19-'DJB Daily Readings'!DG18 -> 7 | AO11: ='DJB Daily Readings'!DE19-'DJB Daily Readings'!DE18 -> 8 | AP11: ='DJB Daily Readings'!DK19-'DJB Daily Readings'!DK18 -> 11 | AQ11: ='DJB Daily Readings'!DI19-'DJB Daily Readings'!DI18 -> 10 | AR11: ='DJB Daily Readings'!DO19-'DJB Daily Readings'!DO18 -> 9 | AS11: ='DJB Daily Readings'!DM19-'DJB Daily Readings'!DM18 -> 4 | AT11: ='DJB Daily Readings'!DQ19-'DJB Daily Readings'!DQ18 -> 3 | AU11: =('DJB Daily Readings'!DT19-'DJB Daily Readings'!DT18)*100 -> 1040 | AV11: =('DJB Daily Readings'!DV19-'DJB Daily Readings'!DV18)*100 -> 880 | AW11: =('DJB Daily Readings'!DX19-'DJB Daily Readings'!DX18)*100 -> 570 | AX11: =('DJB Daily Readings'!DZ19-'DJB Daily Readings'!DZ18)*100 -> 750 | AY11: ='DJB Daily Readings'!EB19-'DJB Daily Readings'!EB18 -> 645 | AZ11: ='DJB Daily Readings'!ED19-'DJB Daily Readings'!ED18 -> 151.4 | BA11: ='DJB Daily Readings'!EG19-'DJB Daily Readings'!EG18 -> 3500 | BB11: ='DJB Daily Readings'!EI19-'DJB Daily Readings'!EI18 -> 260 | BC11: ='DJB Daily Readings'!EQ19-'DJB Daily Readings'!EQ18 -> 4300 | BD11: ='DJB Daily Readings'!EK19-'DJB Daily Readings'!EK18 -> 1200 | BE11: ='DJB Daily Readings'!EM19-'DJB Daily Readings'!EM18 -> 600 | BF11: ='DJB Daily Readings'!EO19-'DJB Daily Readings'!EO18 -> 690 | BG11: =('DJB Daily Readings'!ET19-'DJB Daily Readings'!ET18)*1.89 -> 26.46 | BH11: =('DJB Daily Readings'!EV19-'DJB Daily Readings'!EV18)*1.89 -> 22.68 | BI11: =('DJB Daily Readings'!EZ19-'DJB Daily Readings'!EZ18)*1.89 -> 30.24 | BJ11: =('DJB Daily Readings'!EX19-'DJB Daily Readings'!EX18)*1.89 -> 22.68 | BK11: =('DJB Daily Readings'!FB19-'DJB Daily Readings'!FB18)*1.89 -> 66.15 | BL11: ='DJB Daily Readings'!J19 -> 275 | BM11: ='DJB Daily Readings'!FF19 -> 138.614 | BN11: ='DJB Daily Readings'!FH19 -> 9 | BO11: ='DJB Daily Readings'!FJ19 -> 6 | BP11: ='DJB Daily Readings'!FL19 -> 6 | BQ11: ='DJB Daily Readings'!FN19 -> 5 | BR11: ='DJB Daily Readings'!FP19 -> 0.04 | BS11: ='DJB Daily Readings'!FR19 -> 161.2
A12: Dubai at Jumeirah Beach | B12: =B11+1 -> 11 | C12: 3 | D12: 2023 | E12: =237*0.82 -> 194.34 | F12: =321+52 -> 373 | G12: ='DJB Daily Readings'!C20-'DJB Daily Readings'!C19 -> 673 | H12: ='DJB Daily Readings'!F20-'DJB Daily Readings'!F19 -> 511 | I12: ='DJB Daily Readings'!L19 -> 266 | J12: ='DJB Daily Readings'!N19 -> 0 | K12: ='DJB Daily Readings'!O20-'DJB Daily Readings'!O19 -> 109 | L12: ='DJB Daily Readings'!R20-'DJB Daily Readings'!R19 -> 15 | M12: ='DJB Daily Readings'!U20-'DJB Daily Readings'!U19 -> 2923.2 | N12: ='DJB Daily Readings'!X20-'DJB Daily Readings'!X19 -> 4872 | O12: ='DJB Daily Readings'!AA20-'DJB Daily Readings'!AA19 -> 1656.48 | P12: ='DJB Daily Readings'!AD20-'DJB Daily Readings'!AD19 -> 876.96 | Q12: ='DJB Daily Readings'!AG20-'DJB Daily Readings'!AG19 -> 9451.68 | R12: ='DJB Daily Readings'!AJ20-'DJB Daily Readings'!AJ19 -> 5651.52 | S12: ='DJB Daily Readings'!AM20-'DJB Daily Readings'!AM19 -> 4092.48 | T12: ='DJB Daily Readings'!AP20-'DJB Daily Readings'!AP19 -> 4628.4 | U12: ='DJB Daily Readings'!AS20-'DJB Daily Readings'!AS19 -> 3069.36 | V12: ='DJB Daily Readings'!AV20-'DJB Daily Readings'!AV19 -> 6041.28 | W12: ='DJB Daily Readings'!AZ20-'DJB Daily Readings'!AZ19 -> 5700 | X12: ='DJB Daily Readings'!BC20-'DJB Daily Readings'!BC19 -> 0 | Y12: ='DJB Daily Readings'!BF20-'DJB Daily Readings'!BF19 -> 50200 | Z12: =('DJB Daily Readings'!CK20-'DJB Daily Readings'!CK19)*1.89 -> 154.98 | AA12: =('DJB Daily Readings'!CN20-'DJB Daily Readings'!CN19)*1.89 -> 215.46 | AB12: =('DJB Daily Readings'!CQ20-'DJB Daily Readings'!CQ19)*1.89 -> 240.03 | AC12: ='DJB Daily Readings'!CT20-'DJB Daily Readings'!CT19 -> 182 | AD12: =('DJB Daily Readings'!BY20-'DJB Daily Readings'!BY19)*1.89 -> 34.02 | AE12: =('DJB Daily Readings'!CA20-'DJB Daily Readings'!CA19)*1.89 -> 39.69 | AF12: =('DJB Daily Readings'!CC20-'DJB Daily Readings'!CC19)*1.89 -> 13.23 | AG12: =('DJB Daily Readings'!CE20-'DJB Daily Readings'!CE19)*1.89 -> 18.9 | AH12: =('DJB Daily Readings'!CG20-'DJB Daily Readings'!CG19)*1.89 -> 30.24 | AI12: =('DJB Daily Readings'!CI20-'DJB Daily Readings'!CI19)*1.89 -> 66.15 | AJ12: ='DJB Daily Readings'!CY20-'DJB Daily Readings'!CY19 -> 3 | AK12: ='DJB Daily Readings'!CW20-'DJB Daily Readings'!CW19 -> 3 | AL12: ='DJB Daily Readings'!DC20-'DJB Daily Readings'!DC19 -> 13 | AM12: ='DJB Daily Readings'!DA20-'DJB Daily Readings'!DA19 -> 19 | AN12: ='DJB Daily Readings'!DG20-'DJB Daily Readings'!DG19 -> 5 | AO12: ='DJB Daily Readings'!DE20-'DJB Daily Readings'!DE19 -> 9 | AP12: ='DJB Daily Readings'!DK20-'DJB Daily Readings'!DK19 -> 9 | AQ12: ='DJB Daily Readings'!DI20-'DJB Daily Readings'!DI19 -> 9 | AR12: ='DJB Daily Readings'!DO20-'DJB Daily Readings'!DO19 -> 11 | AS12: ='DJB Daily Readings'!DM20-'DJB Daily Readings'!DM19 -> 5 | AT12: ='DJB Daily Readings'!DQ20-'DJB Daily Readings'!DQ19 -> 4 | AU12: =('DJB Daily Readings'!DT20-'DJB Daily Readings'!DT19)*100 -> 1090 | AV12: =('DJB Daily Readings'!DV20-'DJB Daily Readings'!DV19)*100 -> 890 | AW12: =('DJB Daily Readings'!DX20-'DJB Daily Readings'!DX19)*100 -> 600 | AX12: =('DJB Daily Readings'!DZ20-'DJB Daily Readings'!DZ19)*100 -> 740 | AY12: ='DJB Daily Readings'!EB20-'DJB Daily Readings'!EB19 -> 685 | AZ12: ='DJB Daily Readings'!ED20-'DJB Daily Readings'!ED19 -> 152.3 | BA12: ='DJB Daily Readings'!EG20-'DJB Daily Readings'!EG19 -> 4300 | BB12: ='DJB Daily Readings'!EI20-'DJB Daily Readings'!EI19 -> 300 | BC12: ='DJB Daily Readings'!EQ20-'DJB Daily Readings'!EQ19 -> 5000 | BD12: ='DJB Daily Readings'!EK20-'DJB Daily Readings'!EK19 -> 1300 | BE12: ='DJB Daily Readings'!EM20-'DJB Daily Readings'!EM19 -> 500 | BF12: ='DJB Daily Readings'!EO20-'DJB Daily Readings'!EO19 -> 790 | BG12: =('DJB Daily Readings'!ET20-'DJB Daily Readings'!ET19)*1.89 -> 30.24 | BH12: =('DJB Daily Readings'!EV20-'DJB Daily Readings'!EV19)*1.89 -> 22.68 | BI12: =('DJB Daily Readings'!EZ20-'DJB Daily Readings'!EZ19)*1.89 -> 32.13 | BJ12: =('DJB Daily Readings'!EX20-'DJB Daily Readings'!EX19)*1.89 -> 24.57 | BK12: =('DJB Daily Readings'!FB20-'DJB Daily Readings'!FB19)*1.89 -> 69.93 | BL12: ='DJB Daily Readings'!J20 -> 307 | BM12: ='DJB Daily Readings'!FF20 -> 142.086 | BN12: ='DJB Daily Readings'!FH20 -> 8 | BO12: ='DJB Daily Readings'!FJ20 -> 8 | BP12: ='DJB Daily Readings'!FL20 -> 6 | BQ12: ='DJB Daily Readings'!FN20 -> 4 | BR12: ='DJB Daily Readings'!FP20 -> 0.6 | BS12: ='DJB Daily Readings'!FR20 -> 249.5
