Workbook

Sheet Total
A1: Site Name | B1: Day | C1: Month | D1: Year | E1: Total Electricity Kwh | F1: Electricity Tariff ($/Kwh) | G1: LPG (Liters) | H1: LPG $/Liters | I1: Water Utility Supply (IG) IG | J1: Water Utility Supply (IG) IG/m3 | K1: Room Nights | L1: Total Guests
A2: 25hours Dubai One Central | B2: 1 | C2: 1 | D2: 2024 | E2: =Submetering!E2+Submetering!F2+Submetering!G2+Submetering!H2+Submetering!I2+Submetering!J2 -> 16896 | F2: =IF(E2=0,"0",(2000*0.23+2000*0.28+2000*0.32+(E2-6000)*0.38+0.065*E2)/E2) -> 0.40830492 | G2: =Submetering!M2 -> 550.56 | H2: 2.5 | I2: =Submetering!L2 -> 48613.149 | J2: =IF(I2=0,"0",(10000*0.035+10000*0.04+(I2-20000)*0.046+0.005*I2+0.01*I2)/I2) -> 0.057503004 | K2: =INT('Daily Meter'!O6*434/100) -> 264
A3: 25hours Dubai One Central | B3: =B2+1 -> 2 | C3: 1 | D3: 2024 | E3: =Submetering!E3+Submetering!F3+Submetering!G3+Submetering!H3+Submetering!I3+Submetering!J3 -> 16224 | F3: =IF(E3=0,"0",(2000*0.23+2000*0.28+2000*0.32+(E3-6000)*0.38+0.065*E3)/E3) -> 0.40678501 | G3: =Submetering!M3 -> 480.26 | H3: 2.5 | I3: =Submetering!L3 -> 43113.924 | J3: =IF(I3=0,"0",(10000*0.035+10000*0.04+(I3-20000)*0.046+0.005*I3+0.01*I3)/I3) -> 0.057056958 | K3: =INT('Daily Meter'!O7*434/100) -> 239
A4: 25hours Dubai One Central | B4: =B3+1 -> 3 | C4: 1 | D4: 2024 | E4: =Submetering!E4+Submetering!F4+Submetering!G4+Submetering!H4+Submetering!I4+Submetering!J4 -> 15936 | F4: =IF(E4=0,"0",(2000*0.23+2000*0.28+2000*0.32+(E4-6000)*0.38+0.065*E4)/E4) -> 0.40609438 | G4: =Submetering!M4 -> 443.26 | H4: 2.5 | I4: =Submetering!L4 -> 36514.854 | J4: =IF(I4=0,"0",(10000*0.035+10000*0.04+(I4-20000)*0.046+0.005*I4+0.01*I4)/I4) -> 0.05634436 | K4: =INT('Daily Meter'!O8*434/100) -> 232
A5: 25hours Dubai One Central | B5: =B4+1 -> 4 | C5: 1 | D5: 2024 | E5: =Submetering!E5+Submetering!F5+Submetering!G5+Submetering!H5+Submetering!I5+Submetering!J5 -> 15408 | F5: =IF(E5=0,"0",(2000*0.23+2000*0.28+2000*0.32+(E5-6000)*0.38+0.065*E5)/E5) -> 0.40476116 | G5: =Submetering!M5 -> 454.73 | H5: 2.5 | I5: =Submetering!L5 -> 37614.699 | J5: =IF(I5=0,"0",(10000*0.035+10000*0.04+(I5-20000)*0.046+0.005*I5+0.01*I5)/I5) -> 0.05648049 | K5: =INT('Daily Meter'!O9*434/100) -> 233
A6: 25hours Dubai One Central | B6: =B5+1 -> 5 | C6: 1 | D6: 2024 | E6: =Submetering!E6+Submetering!F6+Submetering!G6+Submetering!H6+Submetering!I6+Submetering!J6 -> 15552 | F6: =IF(E6=0,"0",(2000*0.23+2000*0.28+2000*0.32+(E6-6000)*0.38+0.065*E6)/E6) -> 0.40513374 | G6: =Submetering!M6 -> 452.14 | H6: 2.5 | I6: =Submetering!L6 -> 26176.311 | J6: =IF(I6=0,"0",(10000*0.035+10000*0.04+(I6-20000)*0.046+0.005*I6+0.01*I6)/I6) -> 0.054505578 | K6: =INT('Daily Meter'!O10*434/100) -> 227
A7: 25hours Dubai One Central | B7: =B6+1 -> 6 | C7: 1 | D7: 2024 | E7: =Submetering!E7+Submetering!F7+Submetering!G7+Submetering!H7+Submetering!I7+Submetering!J7 -> 15792 | F7: =IF(E7=0,"0",(2000*0.23+2000*0.28+2000*0.32+(E7-6000)*0.38+0.065*E7)/E7) -> 0.40573961 | G7: =Submetering!M7 -> 452.14 | H7: 2.5 | I7: =Submetering!L7 -> 48393.18 | J7: =IF(I7=0,"0",(10000*0.035+10000*0.04+(I7-20000)*0.046+0.005*I7+0.01*I7)/I7) -> 0.057487108 | K7: =INT('Daily Meter'!O11*434/100) -> 214
A8: 25hours Dubai One Central | B8: =B7+1 -> 7 | C8: 1 | D8: 2024 | E8: =Submetering!E8+Submetering!F8+Submetering!G8+Submetering!H8+Submetering!I8+Submetering!J8 -> 16464 | F8: =IF(E8=0,"0",(2000*0.23+2000*0.28+2000*0.32+(E8-6000)*0.38+0.065*E8)/E8) -> 0.40734208 | G8: =Submetering!M8 -> 441.78 | H8: 2.5 | I8: =Submetering!L8 -> 51912.684 | J8: =IF(I8=0,"0",(10000*0.035+10000*0.04+(I8-20000)*0.046+0.005*I8+0.01*I8)/I8) -> 0.05772527 | K8: =INT('Daily Meter'!O12*434/100) -> 171
A9: 25hours Dubai One Central | B9: =B8+1 -> 8 | C9: 1 | D9: 2024 | E9: =Submetering!E9+Submetering!F9+Submetering!G9+Submetering!H9+Submetering!I9+Submetering!J9 -> 15744 | F9: =IF(E9=0,"0",(2000*0.23+2000*0.28+2000*0.32+(E9-6000)*0.38+0.065*E9)/E9) -> 0.40561992 | G9: =Submetering!M9 -> 419.21 | H9: 2.5 | I9: =Submetering!L9 -> 35634.978 | J9: =IF(I9=0,"0",(10000*0.035+10000*0.04+(I9-20000)*0.046+0.005*I9+0.01*I9)/I9) -> 0.056229406 | K9: =INT('Daily Meter'!O13*434/100) -> 308
A10: 25hours Dubai One Central | B10: =B9+1 -> 9 | C10: 1 | D10: 2024 | E10: =Submetering!E10+Submetering!F10+Submetering!G10+Submetering!H10+Submetering!I10+Submetering!J10 -> 15984 | F10: =IF(E10=0,"0",(2000*0.23+2000*0.28+2000*0.32+(E10-6000)*0.38+0.065*E10)/E10) -> 0.40621121 | G10: =Submetering!M10 -> 444.74 | H10: 2.5 | I10: =Submetering!L10 -> 28815.939 | J10: =IF(I10=0,"0",(10000*0.035+10000*0.04+(I10-20000)*0.046+0.005*I10+0.01*I10)/I10) -> 0.055100487 | K10: =INT('Daily Meter'!O14*434/100) -> 343
A11: 25hours Dubai One Central | B11: =B10+1 -> 10 | C11: 1 | D11: 2024 | E11: =Submetering!E11+Submetering!F11+Submetering!G11+Submetering!H11+Submetering!I11+Submetering!J11 -> 16176 | F11: =IF(E11=0,"0",(2000*0.23+2000*0.28+2000*0.32+(E11-6000)*0.38+0.065*E11)/E11) -> 0.40667161 | G11: =Submetering!M11 -> 473.6 | H11: 2.5 | I11: =Submetering!L11 -> 49053.087 | J11: =IF(I11=0,"0",(10000*0.035+10000*0.04+(I11-20000)*0.046+0.005*I11+0.01*I11)/I11) -> 0.057534367 | K11: =INT('Daily Meter'!O15*434/100) -> 376
A12: 25hours Dubai One Central | B12: =B11+1 -> 11 | C12: 1 | D12: 2024 | E12: =Submetering!E12+Submetering!F12+Submetering!G12+Submetering!H12+Submetering!I12+Submetering!J12 -> 16176 | F12: =IF(E12=0,"0",(2000*0.23+2000*0.28+2000*0.32+(E12-6000)*0.38+0.065*E12)/E12) -> 0.40667161 | G12: =Submetering!M12 -> 397.75 | H12: 2.5 | I12: =Submetering!L12 -> 18917.334 | J12: =IF(I12=0,"0",(10000*0.035+10000*0.04+(I12-20000)*0.046+0.005*I12+0.01*I12)/I12) -> 0.052013533 | K12: =INT('Daily Meter'!O16*434/100) -> 303
A13: 25hours Dubai One Central | B13: =B12+1 -> 12 | C13: 1 | D13: 2024 | E13: =Submetering!E13+Submetering!F13+Submetering!G13+Submetering!H13+Submetering!I13+Submetering!J13 -> 16512 | F13: =IF(E13=0,"0",(2000*0.23+2000*0.28+2000*0.32+(E13-6000)*0.38+0.065*E13)/E13) -> 0.40745155 | G13: =Submetering!M13 -> 651.94 | H13: 2.5 | I13: =Submetering!L13 -> 66870.576 | J13: =IF(I13=0,"0",(10000*0.035+10000*0.04+(I13-20000)*0.046+0.005*I13+0.01*I13)/I13) -> 0.058457776 | K13: =INT('Daily Meter'!O17*434/100) -> 242
A14: 25hours Dubai One Central | B14: =B13+1 -> 13 | C14: 1 | D14: 2024 | E14: =Submetering!E14+Submetering!F14+Submetering!G14+Submetering!H14+Submetering!I14+Submetering!J14 -> 16656 | F14: =IF(E14=0,"0",(2000*0.23+2000*0.28+2000*0.32+(E14-6000)*0.38+0.065*E14)/E14) -> 0.40777618 | G14: =Submetering!M14 -> 589.78 | H14: 2.5 | I14: =Submetering!L14 -> 55652.157 | J14: =IF(I14=0,"0",(10000*0.035+10000*0.04+(I14-20000)*0.046+0.005*I14+0.01*I14)/I14) -> 0.057945312 | K14: =INT('Daily Meter'!O18*434/100) -> 192
... A27: 25hours Dubai One Central | B27: =B26+1 -> 26 | C27: 1 | D27: 2024 | E27: =Submetering!E27+Submetering!F27+Submetering!G27+Submetering!H27+Submetering!I27+Submetering!J27 -> 16704 | F27: =IF(E27=0,"0",(2000*0.23+2000*0.28+2000*0.32+(E27-6000)*0.38+0.065*E27)/E27) -> 0.40788314 | G27: =Submetering!M27 -> 494.32 | H27: 2.5 | I27: =Submetering!L27 -> 37174.761 | J27: =IF(I27=0,"0",(10000*0.035+10000*0.04+(I27-20000)*0.046+0.005*I27+0.01*I27)/I27) -> 0.056427005 | K27: =INT('Daily Meter'!O31*434/100) -> 0

Sheet Submetering
A1: Site Name | B1: Day | C1: Month | D1: Year | E1: Meter 1 - 06065253 | F1: Meter 2 - 06065255 | G1: Meter 3 - 06065259 | H1: Meter 4 - 06065262 | I1: Meter 6 - 06065269 | J1: Meter 7 - 06065283 | K1: District Cooling | L1: Water | M1: Gas | N1: Room Nights | O1: Total Guests
A2: 25hours Dubai One Central | B2: 1 | C2: 1 | D2: 2024 | E2: =IF(('Daily Meter'!H6-'1'!D13)<0,"0",'Daily Meter'!H6-'1'!D13)*480 -> 3360 | F2: =IF(('Daily Meter'!I6-'1'!D14)<0,"0",'Daily Meter'!I6-'1'!D14)*480 -> 1968 | G2: =IF(('Daily Meter'!J6-'1'!D15)<0,"0",'Daily Meter'!J6-'1'!D15)*480 -> 2256 | H2: =IF(('Daily Meter'!K6-'1'!D16)<0,"0",'Daily Meter'!K6-'1'!D16)*480 -> 1440 | I2: =IF(('Daily Meter'!L6-'1'!D17)<0,"0",'Daily Meter'!L6-'1'!D17)*480 -> 2208 | J2: =IF(('Daily Meter'!M6-'1'!D18)<0,"0",'Daily Meter'!M6-'1'!D18)*480 -> 5664 | K2: =IF(('Daily Meter'!B6-'1'!D7)<0,"0",'Daily Meter'!B6-'1'!D7)*284.34 -> 8672.37 | L2: =IF(('Daily Meter'!C6-'1'!D10)<0,"0",'Daily Meter'!C6-'1'!D10)*219.969 -> 48613.149 | M2: =IF(('Daily Meter'!N6-'1'!D22)<0,"0",'Daily Meter'!N6-'1'!D22)*3.7 -> 550.56 | N2: =Total!K2 -> 264
A3: 25hours Dubai One Central | B3: =B2+1 -> 2 | C3: 1 | D3: 2024 | E3: =IF(('Daily Meter'!H7-'Daily Meter'!H6)<0,"0",'Daily Meter'!H7-'Daily Meter'!H6)*480 -> 3456 | F3: =IF(('Daily Meter'!I7-'Daily Meter'!I6)<0,"0",'Daily Meter'!I7-'Daily Meter'!I6)*480 -> 1776 | G3: =IF(('Daily Meter'!J7-'Daily Meter'!J6)<0,"0",'Daily Meter'!J7-'Daily Meter'!J6)*480 -> 2064 | H3: =IF(('Daily Meter'!K7-'Daily Meter'!K6)<0,"0",'Daily Meter'!K7-'Daily Meter'!K6)*480 -> 1248 | I3: =IF(('Daily Meter'!L7-'Daily Meter'!L6)<0,"0",'Daily Meter'!L7-'Daily Meter'!L6)*480 -> 2112 | J3: =IF(('Daily Meter'!M7-'Daily Meter'!M6)<0,"0",'Daily Meter'!M7-'Daily Meter'!M6)*480 -> 5568 | K3: =IF(('Daily Meter'!B7-'Daily Meter'!B6)<0,"0",'Daily Meter'!B7-'Daily Meter'!B6)*284.34 -> 7933.086 | L3: =IF(('Daily Meter'!C7-'Daily Meter'!C6)<0,"0",'Daily Meter'!C7-'Daily Meter'!C6)*219.969 -> 43113.924 | M3: =IF(('Daily Meter'!N7-'Daily Meter'!N6)<0,"0",'Daily Meter'!N7-'Daily Meter'!N6)*3.7 -> 480.26 | N3: =Total!K3 -> 239
A4: 25hours Dubai One Central | B4: =B3+1 -> 3 | C4: 1 | D4: 2024 | E4: =IF(('Daily Meter'!H8-'Daily Meter'!H7)<0,"0",'Daily Meter'!H8-'Daily Meter'!H7)*480 -> 3312 | F4: =IF(('Daily Meter'!I8-'Daily Meter'!I7)<0,"0",'Daily Meter'!I8-'Daily Meter'!I7)*480 -> 1824 | G4: =IF(('Daily Meter'!J8-'Daily Meter'!J7)<0,"0",'Daily Meter'!J8-'Daily Meter'!J7)*480 -> 2016 | H4: =IF(('Daily Meter'!K8-'Daily Meter'!K7)<0,"0",'Daily Meter'!K8-'Daily Meter'!K7)*480 -> 1248 | I4: =IF(('Daily Meter'!L8-'Daily Meter'!L7)<0,"0",'Daily Meter'!L8-'Daily Meter'!L7)*480 -> 2112 | J4: =IF(('Daily Meter'!M8-'Daily Meter'!M7)<0,"0",'Daily Meter'!M8-'Daily Meter'!M7)*480 -> 5424 | K4: =IF(('Daily Meter'!B8-'Daily Meter'!B7)<0,"0",'Daily Meter'!B8-'Daily Meter'!B7)*284.34 -> 6852.594 | L4: =IF(('Daily Meter'!C8-'Daily Meter'!C7)<0,"0",'Daily Meter'!C8-'Daily Meter'!C7)*219.969 -> 36514.854 | M4: =IF(('Daily Meter'!N8-'Daily Meter'!N7)<0,"0",'Daily Meter'!N8-'Daily Meter'!N7)*3.7 -> 443.26 | N4: =Total!K4 -> 232
A5: 25hours Dubai One Central | B5: =B4+1 -> 4 | C5: 1 | D5: 2024 | E5: =IF(('Daily Meter'!H9-'Daily Meter'!H8)<0,"0",'Daily Meter'!H9-'Daily Meter'!H8)*480 -> 3168 | F5: =IF(('Daily Meter'!I9-'Daily Meter'!I8)<0,"0",'Daily Meter'!I9-'Daily Meter'!I8)*480 -> 1776 | G5: =IF(('Daily Meter'!J9-'Daily Meter'!J8)<0,"0",'Daily Meter'!J9-'Daily Meter'!J8)*480 -> 2112 | H5: =IF(('Daily Meter'!K9-'Daily Meter'!K8)<0,"0",'Daily Meter'!K9-'Daily Meter'!K8)*480 -> 1248 | I5: =IF(('Daily Meter'!L9-'Daily Meter'!L8)<0,"0",'Daily Meter'!L9-'Daily Meter'!L8)*480 -> 2160 | J5: =IF(('Daily Meter'!M9-'Daily Meter'!M8)<0,"0",'Daily Meter'!M9-'Daily Meter'!M8)*480 -> 4944 | K5: =IF(('Daily Meter'!B9-'Daily Meter'!B8)<0,"0",'Daily Meter'!B9-'Daily Meter'!B8)*284.34 -> 6397.65 | L5: =IF(('Daily Meter'!C9-'Daily Meter'!C8)<0,"0",'Daily Meter'!C9-'Daily Meter'!C8)*219.969 -> 37614.699 | M5: =IF(('Daily Meter'!N9-'Daily Meter'!N8)<0,"0",'Daily Meter'!N9-'Daily Meter'!N8)*3.7 -> 454.73 | N5: =Total!K5 -> 233
A6: 25hours Dubai One Central | B6: =B5+1 -> 5 | C6: 1 | D6: 2024 | E6: =IF(('Daily Meter'!H10-'Daily Meter'!H9)<0,"0",'Daily Meter'!H10-'Daily Meter'!H9)*480 -> 3168 | F6: =IF(('Daily Meter'!I10-'Daily Meter'!I9)<0,"0",'Daily Meter'!I10-'Daily Meter'!I9)*480 -> 1776 | G6: =IF(('Daily Meter'!J10-'Daily Meter'!J9)<0,"0",'Daily Meter'!J10-'Daily Meter'!J9)*480 -> 2160 | H6: =IF(('Daily Meter'!K10-'Daily Meter'!K9)<0,"0",'Daily Meter'!K10-'Daily Meter'!K9)*480 -> 1248 | I6: =IF(('Daily Meter'!L10-'Daily Meter'!L9)<0,"0",'Daily Meter'!L10-'Daily Meter'!L9)*480 -> 2112 | J6: =IF(('Daily Meter'!M10-'Daily Meter'!M9)<0,"0",'Daily Meter'!M10-'Daily Meter'!M9)*480 -> 5088 | K6: =IF(('Daily Meter'!B10-'Daily Meter'!B9)<0,"0",'Daily Meter'!B10-'Daily Meter'!B9)*284.34 -> 6397.65 | L6: =IF(('Daily Meter'!C10-'Daily Meter'!C9)<0,"0",'Daily Meter'!C10-'Daily Meter'!C9)*219.969 -> 26176.311 | M6: =IF(('Daily Meter'!N10-'Daily Meter'!N9)<0,"0",'Daily Meter'!N10-'Daily Meter'!N9)*3.7 -> 452.14 | N6: =Total!K6 -> 227
A7: 25hours Dubai One Central | B7: =B6+1 -> 6 | C7: 1 | D7: 2024 | E7: =IF(('Daily Meter'!H11-'Daily Meter'!H10)<0,"0",'Daily Meter'!H11-'Daily Meter'!H10)*480 -> 3216 | F7: =IF(('Daily Meter'!I11-'Daily Meter'!I10)<0,"0",'Daily Meter'!I11-'Daily Meter'!I10)*480 -> 1776 | G7: =IF(('Daily Meter'!J11-'Daily Meter'!J10)<0,"0",'Daily Meter'!J11-'Daily Meter'!J10)*480 -> 2160 | H7: =IF(('Daily Meter'!K11-'Daily Meter'!K10)<0,"0",'Daily Meter'!K11-'Daily Meter'!K10)*480 -> 1248 | I7: =IF(('Daily Meter'!L11-'Daily Meter'!L10)<0,"0",'Daily Meter'!L11-'Daily Meter'!L10)*480 -> 2112 | J7: =IF(('Daily Meter'!M11-'Daily Meter'!M10)<0,"0",'Daily Meter'!M11-'Daily Meter'!M10)*480 -> 5280 | K7: =IF(('Daily Meter'!B11-'Daily Meter'!B10)<0,"0",'Daily Meter'!B11-'Daily Meter'!B10)*284.34 -> 6028.008 | L7: =IF(('Daily Meter'!C11-'Daily Meter'!C10)<0,"0",'Daily Meter'!C11-'Daily Meter'!C10)*219.969 -> 48393.18 | M7: =IF(('Daily Meter'!N11-'Daily Meter'!N10)<0,"0",'Daily Meter'!N11-'Daily Meter'!N10)*3.7 -> 452.14 | N7: =Total!K7 -> 214
A8: 25hours Dubai One Central | B8: =B7+1 -> 7 | C8: 1 | D8: 2024 | E8: =IF(('Daily Meter'!H12-'Daily Meter'!H11)<0,"0",'Daily Meter'!H12-'Daily Meter'!H11)*480 -> 3216 | F8: =IF(('Daily Meter'!I12-'Daily Meter'!I11)<0,"0",'Daily Meter'!I12-'Daily Meter'!I11)*480 -> 1728 | G8: =IF(('Daily Meter'!J12-'Daily Meter'!J11)<0,"0",'Daily Meter'!J12-'Daily Meter'!J11)*480 -> 2256 | H8: =IF(('Daily Meter'!K12-'Daily Meter'!K11)<0,"0",'Daily Meter'!K12-'Daily Meter'!K11)*480 -> 1440 | I8: =IF(('Daily Meter'!L12-'Daily Meter'!L11)<0,"0",'Daily Meter'!L12-'Daily Meter'!L11)*480 -> 2160 | J8: =IF(('Daily Meter'!M12-'Daily Meter'!M11)<0,"0",'Daily Meter'!M12-'Daily Meter'!M11)*480 -> 5664 | K8: =IF(('Daily Meter'!B12-'Daily Meter'!B11)<0,"0",'Daily Meter'!B12-'Daily Meter'!B11)*284.34 -> 6028.008 | L8: =IF(('Daily Meter'!C12-'Daily Meter'!C11)<0,"0",'Daily Meter'!C12-'Daily Meter'!C11)*219.969 -> 51912.684 | M8: =IF(('Daily Meter'!N12-'Daily Meter'!N11)<0,"0",'Daily Meter'!N12-'Daily Meter'!N11)*3.7 -> 441.78 | N8: =Total!K8 -> 171
A9: 25hours Dubai One Central | B9: =B8+1 -> 8 | C9: 1 | D9: 2024 | E9: =IF(('Daily Meter'!H13-'Daily Meter'!H12)<0,"0",'Daily Meter'!H13-'Daily Meter'!H12)*480 -> 3216 | F9: =IF(('Daily Meter'!I13-'Daily Meter'!I12)<0,"0",'Daily Meter'!I13-'Daily Meter'!I12)*480 -> 1680 | G9: =IF(('Daily Meter'!J13-'Daily Meter'!J12)<0,"0",'Daily Meter'!J13-'Daily Meter'!J12)*480 -> 2208 | H9: =IF(('Daily Meter'!K13-'Daily Meter'!K12)<0,"0",'Daily Meter'!K13-'Daily Meter'!K12)*480 -> 1200 | I9: =IF(('Daily Meter'!L13-'Daily Meter'!L12)<0,"0",'Daily Meter'!L13-'Daily Meter'!L12)*480 -> 2064 | J9: =IF(('Daily Meter'!M13-'Daily Meter'!M12)<0,"0",'Daily Meter'!M13-'Daily Meter'!M12)*480 -> 5376 | K9: =IF(('Daily Meter'!B13-'Daily Meter'!B12)<0,"0",'Daily Meter'!B13-'Daily Meter'!B12)*284.34 -> 5402.46 | L9: =IF(('Daily Meter'!C13-'Daily Meter'!C12)<0,"0",'Daily Meter'!C13-'Daily Meter'!C12)*219.969 -> 35634.978 | M9: =IF(('Daily Meter'!N13-'Daily Meter'!N12)<0,"0",'Daily Meter'!N13-'Daily Meter'!N12)*3.7 -> 419.21 | N9: =Total!K9 -> 308
A10: 25hours Dubai One Central | B10: =B9+1 -> 9 | C10: 1 | D10: 2024 | E10: =IF(('Daily Meter'!H14-'Daily Meter'!H13)<0,"0",'Daily Meter'!H14-'Daily Meter'!H13)*480 -> 3264 | F10: =IF(('Daily Meter'!I14-'Daily Meter'!I13)<0,"0",'Daily Meter'!I14-'Daily Meter'!I13)*480 -> 1776 | G10: =IF(('Daily Meter'!J14-'Daily Meter'!J13)<0,"0",'Daily Meter'!J14-'Daily Meter'!J13)*480 -> 2208 | H10: =IF(('Daily Meter'!K14-'Daily Meter'!K13)<0,"0",'Daily Meter'!K14-'Daily Meter'!K13)*480 -> 1296 | I10: =IF(('Daily Meter'!L14-'Daily Meter'!L13)<0,"0",'Daily Meter'!L14-'Daily Meter'!L13)*480 -> 2112 | J10: =IF(('Daily Meter'!M14-'Daily Meter'!M13)<0,"0",'Daily Meter'!M14-'Daily Meter'!M13)*480 -> 5328 | K10: =IF(('Daily Meter'!B14-'Daily Meter'!B13)<0,"0",'Daily Meter'!B14-'Daily Meter'!B13)*284.34 -> 5914.272 | L10: =IF(('Daily Meter'!C14-'Daily Meter'!C13)<0,"0",'Daily Meter'!C14-'Daily Meter'!C13)*219.969 -> 28815.939 | M10: =IF(('Daily Meter'!N14-'Daily Meter'!N13)<0,"0",'Daily Meter'!N14-'Daily Meter'!N13)*3.7 -> 444.74 | N10: =Total!K10 -> 343
A11: 25hours Dubai One Central | B11: =B10+1 -> 10 | C11: 1 | D11: 2024 | E11: =IF(('Daily Meter'!H15-'Daily Meter'!H14)<0,"0",'Daily Meter'!H15-'Daily Meter'!H14)*480 -> 3264 | F11: =IF(('Daily Meter'!I15-'Daily Meter'!I14)<0,"0",'Daily Meter'!I15-'Daily Meter'!I14)*480 -> 1968 | G11: =IF(('Daily Meter'!J15-'Daily Meter'!J14)<0,"0",'Daily Meter'!J15-'Daily Meter'!J14)*480 -> 2256 | H11: =IF(('Daily Meter'!K15-'Daily Meter'!K14)<0,"0",'Daily Meter'!K15-'Daily Meter'!K14)*480 -> 1344 | I11: =IF(('Daily Meter'!L15-'Daily Meter'!L14)<0,"0",'Daily Meter'!L15-'Daily Meter'!L14)*480 -> 2112 | J11: =IF(('Daily Meter'!M15-'Daily Meter'!M14)<0,"0",'Daily Meter'!M15-'Daily Meter'!M14)*480 -> 5232 | K11: =IF(('Daily Meter'!B15-'Daily Meter'!B14)<0,"0",'Daily Meter'!B15-'Daily Meter'!B14)*284.34 -> 5942.706 | L11: =IF(('Daily Meter'!C15-'Daily Meter'!C14)<0,"0",'Daily Meter'!C15-'Daily Meter'!C14)*219.969 -> 49053.087 | M11: =IF(('Daily Meter'!N15-'Daily Meter'!N14)<0,"0",'Daily Meter'!N15-'Daily Meter'!N14)*3.7 -> 473.6 | N11: =Total!K11 -> 376
A12: 25hours Dubai One Central | B12: =B11+1 -> 11 | C12: 1 | D12: 2024 | E12: =IF(('Daily Meter'!H16-'Daily Meter'!H15)<0,"0",'Daily Meter'!H16-'Daily Meter'!H15)*480 -> 3264 | F12: =IF(('Daily Meter'!I16-'Daily Meter'!I15)<0,"0",'Daily Meter'!I16-'Daily Meter'!I15)*480 -> 1920 | G12: =IF(('Daily Meter'!J16-'Daily Meter'!J15)<0,"0",'Daily Meter'!J16-'Daily Meter'!J15)*480 -> 2208 | H12: =IF(('Daily Meter'!K16-'Daily Meter'!K15)<0,"0",'Daily Meter'!K16-'Daily Meter'!K15)*480 -> 1296 | I12: =IF(('Daily Meter'!L16-'Daily Meter'!L15)<0,"0",'Daily Meter'!L16-'Daily Meter'!L15)*480 -> 2160 | J12: =IF(('Daily Meter'!M16-'Daily Meter'!M15)<0,"0",'Daily Meter'!M16-'Daily Meter'!M15)*480 -> 5328 | K12: =IF(('Daily Meter'!B16-'Daily Meter'!B15)<0,"0",'Daily Meter'!B16-'Daily Meter'!B15)*284.34 -> 5828.97 | L12: =IF(('Daily Meter'!C16-'Daily Meter'!C15)<0,"0",'Daily Meter'!C16-'Daily Meter'!C15)*219.969 -> 18917.334 | M12: =IF(('Daily Meter'!N16-'Daily Meter'!N15)<0,"0",'Daily Meter'!N16-'Daily Meter'!N15)*3.7 -> 397.75 | N12: =Total!K12 -> 303
A13: 25hours Dubai One Central | B13: =B12+1 -> 12 | C13: 1 | D13: 2024 | E13: =IF(('Daily Meter'!H17-'Daily Meter'!H16)<0,"0",'Daily Meter'!H17-'Daily Meter'!H16)*480 -> 3408 | F13: =IF(('Daily Meter'!I17-'Daily Meter'!I16)<0,"0",'Daily Meter'!I17-'Daily Meter'!I16)*480 -> 1872 | G13: =IF(('Daily Meter'!J17-'Daily Meter'!J16)<0,"0",'Daily Meter'!J17-'Daily Meter'!J16)*480 -> 2304 | H13: =IF(('Daily Meter'!K17-'Daily Meter'!K16)<0,"0",'Daily Meter'!K17-'Daily Meter'!K16)*480 -> 1344 | I13: =IF(('Daily Meter'!L17-'Daily Meter'!L16)<0,"0",'Daily Meter'!L17-'Daily Meter'!L16)*480 -> 2160 | J13: =IF(('Daily Meter'!M17-'Daily Meter'!M16)<0,"0",'Daily Meter'!M17-'Daily Meter'!M16)*480 -> 5424 | K13: =IF(('Daily Meter'!B17-'Daily Meter'!B16)<0,"0",'Daily Meter'!B17-'Daily Meter'!B16)*284.34 -> 5345.592 | L13: =IF(('Daily Meter'!C17-'Daily Meter'!C16)<0,"0",'Daily Meter'!C17-'Daily Meter'!C16)*219.969 -> 66870.576 | M13: =IF(('Daily Meter'!N17-'Daily Meter'!N16)<0,"0",'Daily Meter'!N17-'Daily Meter'!N16)*3.7 -> 651.94 | N13: =Total!K13 -> 242
A14: 25hours Dubai One Central | B14: =B13+1 -> 13 | C14: 1 | D14: 2024 | E14: =IF(('Daily Meter'!H18-'Daily Meter'!H17)<0,"0",'Daily Meter'!H18-'Daily Meter'!H17)*480 -> 3456 | F14: =IF(('Daily Meter'!I18-'Daily Meter'!I17)<0,"0",'Daily Meter'!I18-'Daily Meter'!I17)*480 -> 1824 | G14: =IF(('Daily Meter'!J18-'Daily Meter'!J17)<0,"0",'Daily Meter'!J18-'Daily Meter'!J17)*480 -> 2352 | H14: =IF(('Daily Meter'!K18-'Daily Meter'!K17)<0,"0",'Daily Meter'!K18-'Daily Meter'!K17)*480 -> 1344 | I14: =IF(('Daily Meter'!L18-'Daily Meter'!L17)<0,"0",'Daily Meter'!L18-'Daily Meter'!L17)*480 -> 2208 | J14: =IF(('Daily Meter'!M18-'Daily Meter'!M17)<0,"0",'Daily Meter'!M18-'Daily Meter'!M17)*480 -> 5472 | K14: =IF(('Daily Meter'!B18-'Daily Meter'!B17)<0,"0",'Daily Meter'!B18-'Daily Meter'!B17)*284.34 -> 5288.724 | L14: =IF(('Daily Meter'!C18-'Daily Meter'!C17)<0,"0",'Daily Meter'!C18-'Daily Meter'!C17)*219.969 -> 55652.157 | M14: =IF(('Daily Meter'!N18-'Daily Meter'!N17)<0,"0",'Daily Meter'!N18-'Daily Meter'!N17)*3.7 -> 589.78 | N14: =Total!K14 -> 192
... A32: 25hours Dubai One Central | B32: =B31+1 -> 31 | C32: 1 | D32: 2024 | E32: =IF(('Daily Meter'!H36-'Daily Meter'!H35)<0,"0",'Daily Meter'!H36-'Daily Meter'!H35)*480 -> 0 | F32: =IF(('Daily Meter'!I36-'Daily Meter'!I35)<0,"0",'Daily Meter'!I36-'Daily Meter'!I35)*480 -> 0 | G32: =IF(('Daily Meter'!J36-'Daily Meter'!J35)<0,"0",'Daily Meter'!J36-'Daily Meter'!J35)*480 -> 0 | H32: =IF(('Daily Meter'!K36-'Daily Meter'!K35)<0,"0",'Daily Meter'!K36-'Daily Meter'!K35)*480 -> 0 | I32: =IF(('Daily Meter'!L36-'Daily Meter'!L35)<0,"0",'Daily Meter'!L36-'Daily Meter'!L35)*480 -> 0 | J32: =IF(('Daily Meter'!M36-'Daily Meter'!M35)<0,"0",'Daily Meter'!M36-'Daily Meter'!M35)*480 -> 0 | K32: =IF(('Daily Meter'!B36-'Daily Meter'!B35)<0,"0",'Daily Meter'!B36-'Daily Meter'!B35)*284.34 -> 0 | L32: =IF(('Daily Meter'!C36-'Daily Meter'!C35)<0,"0",'Daily Meter'!C36-'Daily Meter'!C35)*219.969 -> 0 | M32: =IF(('Daily Meter'!N36-'Daily Meter'!N35)<0,"0",'Daily Meter'!N36-'Daily Meter'!N35)*3.7 -> 0 | N32: =Total!K32 -> 0

Sheet Daily Meter
A1: JANUARY 2024 UTILITY READING | Q1: 1st
B2: CHILLED WATER | C2: WATER | H2: ELECTRICITY | N2: GAS | O2: OCC.
A3: Date | B3: BTU Meter | C3: Meter 1 | D3: Meter 2 | F3: Meter 3 | H3: Meter 1 | I3: Meter 2 | J3: Meter 3 | K3: Meter 4 | L3: Meter 6 | M3: Meter 7
B4: P103FF043BC | C4: 18E0300032 | D4: 18E0300060 | F4: 18E0300057 | H4: 6065253 | I4: 6065255 | J4: 6065259 | K4: 6065262 | L4: 6065269 | M4: 6065283 | N4: 77092321/2019 | O4: %
B5: 4am | C5: 4am | D5: 4am | E5: 4am | F5: 4am | G5: 4am | H5: 4am | I5: 4am | J5: 4am | K5: 4am | L5: 4am | M5: 4am | N5: 4am | O5: DAILY
A6: 1 | B6: 53476.8 | C6: 203658 | H6: 6566.3 | I6: 3970.2 | J6: 4233.6 | K6: 2361.9 | L6: 5573.8 | M6: 15022.4 | N6: 90136.2 | O6: 60.83
A7: 2 | B7: 53504.7 | C7: 203854 | H7: 6573.5 | I7: 3973.9 | J7: 4237.9 | K7: 2364.5 | L7: 5578.2 | M7: 15034 | N7: 90266 | O7: 55.07
A8: 3 | B8: 53528.8 | C8: 204020 | H8: 6580.4 | I8: 3977.7 | J8: 4242.1 | K8: 2367.1 | L8: 5582.6 | M8: 15045.3 | N8: 90385.8 | O8: 53.46
A9: 4 | B9: 53551.3 | C9: 204191 | H9: 6587 | I9: 3981.4 | J9: 4246.5 | K9: 2369.7 | L9: 5587.1 | M9: 15055.6 | N9: 90508.7 | O9: 53.69
A10: 5 | B10: 53573.8 | C10: 204310 | H10: 6593.6 | I10: 3985.1 | J10: 4251 | K10: 2372.3 | L10: 5591.5 | M10: 15066.2 | N10: 90630.9 | O10: 52.53
A11: 6 | B11: 53595 | C11: 204530 | H11: 6600.3 | I11: 3988.8 | J11: 4255.5 | K11: 2374.9 | L11: 5595.9 | M11: 15077.2 | N11: 90753.1 | O11: 49.31
A12: 7 | B12: 53616.2 | C12: 204766 | H12: 6607 | I12: 3992.4 | J12: 4260.2 | K12: 2377.9 | L12: 5600.4 | M12: 15089 | N12: 90872.5 | O12: 39.63
A13: 8 | B13: 53635.2 | C13: 204928 | H13: 6613.7 | I13: 3995.9 | J13: 4264.8 | K13: 2380.4 | L13: 5604.7 | M13: 15100.2 | N13: 90985.8 | O13: 70.97
A14: 9 | B14: 53656 | C14: 205059 | H14: 6620.5 | I14: 3999.6 | J14: 4269.4 | K14: 2383.1 | L14: 5609.1 | M14: 15111.3 | N14: 91106 | O14: 79.26
A15: 10 | B15: 53676.9 | C15: 205282 | H15: 6627.3 | I15: 4003.7 | J15: 4274.1 | K15: 2385.9 | L15: 5613.5 | M15: 15122.2 | N15: 91234 | O15: 86.67
A16: 11 | B16: 53697.4 | C16: 205368 | H16: 6634.1 | I16: 4007.7 | J16: 4278.7 | K16: 2388.6 | L16: 5618 | M16: 15133.3 | N16: 91341.5 | O16: 69.82
A17: 12 | B17: 53716.2 | C17: 205672 | H17: 6641.2 | I17: 4011.6 | J17: 4283.5 | K17: 2391.4 | L17: 5622.5 | M17: 15144.6 | N17: 91517.7 | O17: 55.99
... A30: 25 | B30: 53979.8 | C30: 208093 | H30: 6731.5 | I30: 4062.2 | J30: 4341.4 | K30: 2428.3 | L30: 5681 | M30: 15284.7 | N30: 93278.7 | O30: 93.78
A31: 26 | B31: 54000.1 | C31: 208262 | H31: 6738.4 | I31: 4066.3 | J31: 4345.8 | K31: 2431.4 | L31: 5685.5 | M31: 15296.5 | N31: 93412.3
A32: 27
A33: 28
A34: 29
A35: 30
A36: 31
O37: =AVERAGE(O6:O34) -> 69.4396
Q38: engr123.

Sheet 1
A1: ENGINEERING DEPARTMENT | H1: daily reading
A2: UTILITY CONSUMPTION SHEET
B3: JANUARY 2024 | C3: 1 | D3: % OCCUPANCY: | E3: ='Daily Meter'!O6 -> 60.83
A4: SR.NO | B4: ITEM MEASURED | D4: Previous Reading | E4: 4 AM Reading | F4: 24hrs CONSUMPTION | G4: Cost
D5: DECEMBER 31
A6: 1 | B6: DISTRICT COOLING PLANT
B7: Chilled Water | C7: MWH | D7: 53446.3 | E7: ='Daily Meter'!B6 -> 53476.8 | F7: =E7-D7 -> 30.5
C8: TR | F8: =F7*284.34 -> 8672.37 | G8: =F8*0.63 -> 5463.5931
A9: III | B9: WATER METERS
B10: Main DEWA Meter | C10: m3 | D10: 203437 | E10: ='Daily Meter'!C6 -> 203658 | F10: =E10-D10 -> 221
B11: Imperial Gallon = m³ x 219.969 | C11: IG | F11: =F10*219.969 -> 48613.149 | G11: =F11*0.06 -> 2916.7889
A12: IV | B12: ELECTRICAL METERS
A13: 1 | B13: Meter 1 - 06065253 | C13: kW x 480 | D13: 6559.3 | E13: ='Daily Meter'!H6 -> 6566.3 | F13: =(E13-D13)*480 -> 3360
A14: 2 | B14: Meter 2 - 06065255 | C14: kW x 480 | D14: 3966.1 | E14: ='Daily Meter'!I6 -> 3970.2 | F14: =(E14-D14)*480 -> 1968
A15: 3 | B15: Meter 3 - 06065259 | C15: kW x 480 | D15: 4228.9 | E15: ='Daily Meter'!J6 -> 4233.6 | F15: =(E15-D15)*480 -> 2256
A16: 4 | B16: Meter 4 - 06065262 | C16: kW x 480 | D16: 2358.9 | E16: ='Daily Meter'!K6 -> 2361.9 | F16: =(E16-D16)*480 -> 1440
A17: 5 | B17: Meter 6 - 06065269 | C17: kW x 480 | D17: 5569.2 | E17: ='Daily Meter'!L6 -> 5573.8 | F17: =(E17-D17)*480 -> 2208
A18: 6 | B18: Meter 7 - 06065283 | C18: kW x 480 | D18: 15010.6 | E18: ='Daily Meter'!M6 -> 15022.4 | F18: =(E18-D18)*480 -> 5664
B19: TOTAL ELECTRICAL CONS.(kWh) | F19: =SUM(F13:F18) -> 16896 | G19: =F19*0.43 -> 7265.28
A21: V | B21: GAS CONSUMPTION
A22: 1 | B22: MAIN LPG METER | C22: M3 | D22: 89987.4 | E22: ='Daily Meter'!N6 -> 90136.2 | F22: =E22-D22 -> 148.8
B23: L = m³ x 3.70 | C23: L | F23: =F22*3.7 -> 550.56 | G23: =F23*2.5 -> 1376.4
D26: Summary of Daily Hotel consumption
D27: Item measured | E27: Units | F27: Consumption | G27: AED
D28: Chilled water | E28: TR | F28: =F8 -> 8672.37 | G28: =G8 -> 5463.5931
D29: DEWA Water | E29: imp. Gallon | F29: =F11 -> 48613.149 | G29: =G11 -> 2916.7889
D30: Electricity | E30: kwh | F30: =F19 -> 16896 | G30: =G19 -> 7265.28
D31: Gas | E31: m3 | F31: =F22 -> 148.8 | G31: =G23 -> 1376.4
F32: Total cost | G32: =SUM(G28:G31) -> 17022.062

Sheet 2
A1: ENGINEERING DEPARTMENT | H1: daily reading
A2: UTILITY CONSUMPTION SHEET
B3: ='1'!B3 -> JANUARY 2024 | C3: 2 | D3: % OCCUPANCY: | E3: ='Daily Meter'!O6 -> 60.83
A4: SR.NO | B4: ITEM MEASURED | D4: Previous Reading | E4: 4 AM Reading | F4: 24hrs CONSUMPTION | G4: Cost
A6: 1 | B6: DISTRICT COOLING PLANT
B7: Chilled Water | C7: MWH | D7: ='1'!E7 -> 53476.8 | E7: ='Daily Meter'!B7 -> 53504.7 | F7: =E7-D7 -> 27.9
C8: TR | F8: =F7*284.34 -> 7933.086 | G8: =F8*0.63 -> 4997.8442
A9: III | B9: WATER METERS
B10: Main DEWA Meter | C10: m3 | D10: ='1'!E10 -> 203658 | E10: ='Daily Meter'!C7 -> 203854 | F10: =E10-D10 -> 196
B11: Imperial Gallon = m³ x 219.969 | C11: IG | F11: =F10*219.969 -> 43113.924 | G11: =F11*0.06 -> 2586.8354
A12: IV | B12: ELECTRICAL METERS
A13: 1 | B13: Meter 1 - 06065253 | C13: kW x 480 | D13: ='1'!E13 -> 6566.3 | E13: ='Daily Meter'!H7 -> 6573.5 | F13: =(E13-D13)*480 -> 3456
A14: 2 | B14: Meter 2 - 06065255 | C14: kW x 480 | D14: ='1'!E14 -> 3970.2 | E14: ='Daily Meter'!I7 -> 3973.9 | F14: =(E14-D14)*480 -> 1776
A15: 3 | B15: Meter 3 - 06065259 | C15: kW x 480 | D15: ='1'!E15 -> 4233.6 | E15: ='Daily Meter'!J7 -> 4237.9 | F15: =(E15-D15)*480 -> 2064
A16: 4 | B16: Meter 4 - 06065262 | C16: kW x 480 | D16: ='1'!E16 -> 2361.9 | E16: ='Daily Meter'!K7 -> 2364.5 | F16: =(E16-D16)*480 -> 1248
A17: 5 | B17: Meter 6 - 06065269 | C17: kW x 480 | D17: ='1'!E17 -> 5573.8 | E17: ='Daily Meter'!L7 -> 5578.2 | F17: =(E17-D17)*480 -> 2112
A18: 6 | B18: Meter 7 - 06065283 | C18: kW x 480 | D18: ='1'!E18 -> 15022.4 | E18: ='Daily Meter'!M7 -> 15034 | F18: =(E18-D18)*480 -> 5568
B19: TOTAL ELECTRICAL CONS.(kWh) | F19: =SUM(F13:F18) -> 16224 | G19: =F19*0.43 -> 6976.32
A21: V | B21: GAS CONSUMPTION
A22: 1 | B22: MAIN LPG METER | C22: M3 | D22: ='1'!E22 -> 90136.2 | E22: ='Daily Meter'!N7 -> 90266 | F22: =E22-D22 -> 129.8
B23: L = m³ x 3.70 | C23: L | F23: =F22*3.7 -> 480.26 | G23: =F23*2.5 -> 1200.65
D26: Summary of Daily Hotel consumption
D27: Item measured | E27: Units | F27: Consumption | G27: AED
D28: Chilled water | E28: TR | F28: =F8 -> 7933.086 | G28: =G8 -> 4997.8442
D29: DEWA Water | E29: imp. Gallon | F29: =F11 -> 43113.924 | G29: =G11 -> 2586.8354
D30: Electricity | E30: kwh | F30: =F19 -> 16224 | G30: =G19 -> 6976.32
D31: Gas | E31: m3 | F31: =F22 -> 129.8 | G31: =G23 -> 1200.65
F32: Total cost | G32: =SUM(G28:G31) -> 15761.65

Sheet 3
A1: ENGINEERING DEPARTMENT | H1: daily reading
A2: UTILITY CONSUMPTION SHEET
B3: ='1'!B3 -> JANUARY 2024 | C3: 3 | D3: % OCCUPANCY: | E3: ='Daily Meter'!O8 -> 53.46
A4: SR.NO | B4: ITEM MEASURED | D4: Previous Reading | E4: 4 AM Reading | F4: 24hrs CONSUMPTION | G4: Cost
A6: 1 | B6: DISTRICT COOLING PLANT
B7: Chilled Water | C7: MWH | D7: ='2'!E7 -> 53504.7 | E7: ='Daily Meter'!B8 -> 53528.8 | F7: =E7-D7 -> 24.1
C8: TR | F8: =F7*284.34 -> 6852.594 | G8: =F8*0.63 -> 4317.1342
A9: III | B9: WATER METERS
B10: Main DEWA Meter | C10: m3 | D10: ='2'!E10 -> 203854 | E10: ='Daily Meter'!C8 -> 204020 | F10: =E10-D10 -> 166
B11: Imperial Gallon = m³ x 219.969 | C11: IG | F11: =F10*219.969 -> 36514.854 | G11: =F11*0.06 -> 2190.8912
A12: IV | B12: ELECTRICAL METERS
A13: 1 | B13: Meter 1 - 06065253 | C13: kW x 480 | D13: ='2'!E13 -> 6573.5 | E13: ='Daily Meter'!H8 -> 6580.4 | F13: =(E13-D13)*480 -> 3312
A14: 2 | B14: Meter 2 - 06065255 | C14: kW x 480 | D14: ='2'!E14 -> 3973.9 | E14: ='Daily Meter'!I8 -> 3977.7 | F14: =(E14-D14)*480 -> 1824
A15: 3 | B15: Meter 3 - 06065259 | C15: kW x 480 | D15: ='2'!E15 -> 4237.9 | E15: ='Daily Meter'!J8 -> 4242.1 | F15: =(E15-D15)*480 -> 2016
A16: 4 | B16: Meter 4 - 06065262 | C16: kW x 480 | D16: ='2'!E16 -> 2364.5 | E16: ='Daily Meter'!K8 -> 2367.1 | F16: =(E16-D16)*480 -> 1248
A17: 5 | B17: Meter 6 - 06065269 | C17: kW x 480 | D17: ='2'!E17 -> 5578.2 | E17: ='Daily Meter'!L8 -> 5582.6 | F17: =(E17-D17)*480 -> 2112
A18: 6 | B18: Meter 7 - 06065283 | C18: kW x 480 | D18: ='2'!E18 -> 15034 | E18: ='Daily Meter'!M8 -> 15045.3 | F18: =(E18-D18)*480 -> 5424
B19: TOTAL ELECTRICAL CONS.(kWh) | F19: =SUM(F13:F18) -> 15936 | G19: =F19*0.43 -> 6852.48
A21: V | B21: GAS CONSUMPTION
A22: 1 | B22: MAIN LPG METER | C22: M3 | D22: ='2'!E22 -> 90266 | E22: ='Daily Meter'!N8 -> 90385.8 | F22: =E22-D22 -> 119.8
B23: L = m³ x 3.70 | C23: L | F23: =F22*3.7 -> 443.26 | G23: =F23*2.5 -> 1108.15
D26: Summary of Daily Hotel consumption
D27: Item measured | E27: Units | F27: Consumption | G27: AED
D28: Chilled water | E28: TR | F28: =F8 -> 6852.594 | G28: =G8 -> 4317.1342
D29: DEWA Water | E29: imp. Gallon | F29: =F11 -> 36514.854 | G29: =G11 -> 2190.8912
D30: Electricity | E30: kwh | F30: =F19 -> 15936 | G30: =G19 -> 6852.48
D31: Gas | E31: m3 | F31: =F22 -> 119.8 | G31: =G23 -> 1108.15
F32: Total cost | G32: =SUM(G28:G31) -> 14468.655

Sheet 4
A1: ENGINEERING DEPARTMENT | H1: daily reading
A2: UTILITY CONSUMPTION SHEET
B3: ='1'!B3 -> JANUARY 2024 | C3: 4 | D3: % OCCUPANCY: | E3: ='Daily Meter'!O9 -> 53.69
A4: SR.NO | B4: ITEM MEASURED | D4: Previous Reading | E4: 4 AM Reading | F4: 24hrs CONSUMPTION | G4: Cost
A6: 1 | B6: DISTRICT COOLING PLANT
B7: Chilled Water | C7: MWH | D7: ='3'!E7 -> 53528.8 | E7: ='Daily Meter'!B9 -> 53551.3 | F7: =E7-D7 -> 22.5
C8: TR | F8: =F7*284.34 -> 6397.65 | G8: =F8*0.63 -> 4030.5195
A9: III | B9: WATER METERS
B10: Main DEWA Meter | C10: m3 | D10: ='3'!E10 -> 204020 | E10: ='Daily Meter'!C9 -> 204191 | F10: =E10-D10 -> 171
B11: Imperial Gallon = m³ x 219.969 | C11: IG | F11: =F10*219.969 -> 37614.699 | G11: =F11*0.06 -> 2256.8819
A12: IV | B12: ELECTRICAL METERS
A13: 1 | B13: Meter 1 - 06065253 | C13: kW x 480 | D13: ='3'!E13 -> 6580.4 | E13: ='Daily Meter'!H9 -> 6587 | F13: =(E13-D13)*480 -> 3168
A14: 2 | B14: Meter 2 - 06065255 | C14: kW x 480 | D14: ='3'!E14 -> 3977.7 | E14: ='Daily Meter'!I9 -> 3981.4 | F14: =(E14-D14)*480 -> 1776
A15: 3 | B15: Meter 3 - 06065259 | C15: kW x 480 | D15: ='3'!E15 -> 4242.1 | E15: ='Daily Meter'!J9 -> 4246.5 | F15: =(E15-D15)*480 -> 2112
A16: 4 | B16: Meter 4 - 06065262 | C16: kW x 480 | D16: ='3'!E16 -> 2367.1 | E16: ='Daily Meter'!K9 -> 2369.7 | F16: =(E16-D16)*480 -> 1248
A17: 5 | B17: Meter 6 - 06065269 | C17: kW x 480 | D17: ='3'!E17 -> 5582.6 | E17: ='Daily Meter'!L9 -> 5587.1 | F17: =(E17-D17)*480 -> 2160
A18: 6 | B18: Meter 7 - 06065283 | C18: kW x 480 | D18: ='3'!E18 -> 15045.3 | E18: ='Daily Meter'!M9 -> 15055.6 | F18: =(E18-D18)*480 -> 4944
B19: TOTAL ELECTRICAL CONS.(kWh) | F19: =SUM(F13:F18) -> 15408 | G19: =F19*0.43 -> 6625.44
A21: V | B21: GAS CONSUMPTION
A22: 1 | B22: MAIN LPG METER | C22: M3 | D22: ='3'!E22 -> 90385.8 | E22: ='Daily Meter'!N9 -> 90508.7 | F22: =E22-D22 -> 122.9
B23: L = m³ x 3.70 | C23: L | F23: =F22*3.7 -> 454.73 | G23: =F23*2.5 -> 1136.825
D26: Summary of Daily Hotel consumption
D27: Item measured | E27: Units | F27: Consumption | G27: AED
D28: Chilled water | E28: TR | F28: =F8 -> 6397.65 | G28: =G8 -> 4030.5195
D29: DEWA Water | E29: imp. Gallon | F29: =F11 -> 37614.699 | G29: =G11 -> 2256.8819
D30: Electricity | E30: kwh | F30: =F19 -> 15408 | G30: =G19 -> 6625.44
D31: Gas | E31: m3 | F31: =F22 -> 122.9 | G31: =G23 -> 1136.825
F32: Total cost | G32: =SUM(G28:G31) -> 14049.666

Sheet 5
A1: ENGINEERING DEPARTMENT | H1: daily reading
A2: UTILITY CONSUMPTION SHEET
B3: ='1'!B3 -> JANUARY 2024 | C3: 5 | D3: % OCCUPANCY: | E3: ='Daily Meter'!O10 -> 52.53
A4: SR.NO | B4: ITEM MEASURED | D4: Previous Reading | E4: 4 AM Reading | F4: 24hrs CONSUMPTION | G4: Cost
A6: 1 | B6: DISTRICT COOLING PLANT
B7: Chilled Water | C7: MWH | D7: ='4'!E7 -> 53551.3 | E7: ='Daily Meter'!B10 -> 53573.8 | F7: =E7-D7 -> 22.5
C8: TR | F8: =F7*284.34 -> 6397.65 | G8: =F8*0.63 -> 4030.5195
A9: III | B9: WATER METERS
B10: Main DEWA Meter | C10: m3 | D10: ='4'!E10 -> 204191 | E10: ='Daily Meter'!C10 -> 204310 | F10: =E10-D10 -> 119
B11: Imperial Gallon = m³ x 219.969 | C11: IG | F11: =F10*219.969 -> 26176.311 | G11: =F11*0.06 -> 1570.5787
A12: IV | B12: ELECTRICAL METERS
A13: 1 | B13: Meter 1 - 06065253 | C13: kW x 480 | D13: ='4'!E13 -> 6587 | E13: ='Daily Meter'!H10 -> 6593.6 | F13: =(E13-D13)*480 -> 3168
A14: 2 | B14: Meter 2 - 06065255 | C14: kW x 480 | D14: ='4'!E14 -> 3981.4 | E14: ='Daily Meter'!I10 -> 3985.1 | F14: =(E14-D14)*480 -> 1776
A15: 3 | B15: Meter 3 - 06065259 | C15: kW x 480 | D15: ='4'!E15 -> 4246.5 | E15: ='Daily Meter'!J10 -> 4251 | F15: =(E15-D15)*480 -> 2160
A16: 4 | B16: Meter 4 - 06065262 | C16: kW x 480 | D16: ='4'!E16 -> 2369.7 | E16: ='Daily Meter'!K10 -> 2372.3 | F16: =(E16-D16)*480 -> 1248
A17: 5 | B17: Meter 6 - 06065269 | C17: kW x 480 | D17: ='4'!E17 -> 5587.1 | E17: ='Daily Meter'!L10 -> 5591.5 | F17: =(E17-D17)*480 -> 2112
A18: 6 | B18: Meter 7 - 06065283 | C18: kW x 480 | D18: ='4'!E18 -> 15055.6 | E18: ='Daily Meter'!M10 -> 15066.2 | F18: =(E18-D18)*480 -> 5088
B19: TOTAL ELECTRICAL CONS.(kWh) | F19: =SUM(F13:F18) -> 15552 | G19: =F19*0.43 -> 6687.36
A21: V | B21: GAS CONSUMPTION
A22: 1 | B22: MAIN LPG METER | C22: M3 | D22: ='4'!E22 -> 90508.7 | E22: ='Daily Meter'!N10 -> 90630.9 | F22: =E22-D22 -> 122.2
B23: L = m³ x 3.70 | C23: L | F23: =F22*3.7 -> 452.14 | G23: =F23*2.5 -> 1130.35
D26: Summary of Daily Hotel consumption
D27: Item measured | E27: Units | F27: Consumption | G27: AED
D28: Chilled water | E28: TR | F28: =F8 -> 6397.65 | G28: =G8 -> 4030.5195
D29: DEWA Water | E29: imp. Gallon | F29: =F11 -> 26176.311 | G29: =G11 -> 1570.5787
D30: Electricity | E30: kwh | F30: =F19 -> 15552 | G30: =G19 -> 6687.36
D31: Gas | E31: m3 | F31: =F22 -> 122.2 | G31: =G23 -> 1130.35
F32: Total cost | G32: =SUM(G28:G31) -> 13418.808

Sheet 6
A1: ENGINEERING DEPARTMENT | H1: daily reading
A2: UTILITY CONSUMPTION SHEET
B3: ='1'!B3 -> JANUARY 2024 | C3: 6 | D3: % OCCUPANCY: | E3: ='Daily Meter'!O11 -> 49.31
A4: SR.NO | B4: ITEM MEASURED | D4: Previous Reading | E4: 4 AM Reading | F4: 24hrs CONSUMPTION | G4: Cost
A6: 1 | B6: DISTRICT COOLING PLANT
B7: Chilled Water | C7: MWH | D7: ='5'!E7 -> 53573.8 | E7: ='Daily Meter'!B11 -> 53595 | F7: =E7-D7 -> 21.2
C8: TR | F8: =F7*284.34 -> 6028.008 | G8: =F8*0.63 -> 3797.645
A9: III | B9: WATER METERS
B10: Main DEWA Meter | C10: m3 | D10: ='5'!E10 -> 204310 | E10: ='Daily Meter'!C11 -> 204530 | F10: =E10-D10 -> 220
B11: Imperial Gallon = m³ x 219.969 | C11: IG | F11: =F10*219.969 -> 48393.18 | G11: =F11*0.06 -> 2903.5908
A12: IV | B12: ELECTRICAL METERS
A13: 1 | B13: Meter 1 - 06065253 | C13: kW x 480 | D13: ='5'!E13 -> 6593.6 | E13: ='Daily Meter'!H11 -> 6600.3 | F13: =(E13-D13)*480 -> 3216
A14: 2 | B14: Meter 2 - 06065255 | C14: kW x 480 | D14: ='5'!E14 -> 3985.1 | E14: ='Daily Meter'!I11 -> 3988.8 | F14: =(E14-D14)*480 -> 1776
A15: 3 | B15: Meter 3 - 06065259 | C15: kW x 480 | D15: ='5'!E15 -> 4251 | E15: ='Daily Meter'!J11 -> 4255.5 | F15: =(E15-D15)*480 -> 2160
A16: 4 | B16: Meter 4 - 06065262 | C16: kW x 480 | D16: ='5'!E16 -> 2372.3 | E16: ='Daily Meter'!K11 -> 2374.9 | F16: =(E16-D16)*480 -> 1248
A17: 5 | B17: Meter 6 - 06065269 | C17: kW x 480 | D17: ='5'!E17 -> 5591.5 | E17: ='Daily Meter'!L11 -> 5595.9 | F17: =(E17-D17)*480 -> 2112
A18: 6 | B18: Meter 7 - 06065283 | C18: kW x 480 | D18: ='5'!E18 -> 15066.2 | E18: ='Daily Meter'!M11 -> 15077.2 | F18: =(E18-D18)*480 -> 5280
B19: TOTAL ELECTRICAL CONS.(kWh) | F19: =SUM(F13:F18) -> 15792 | G19: =F19*0.43 -> 6790.56
A21: V | B21: GAS CONSUMPTION
A22: 1 | B22: MAIN LPG METER | C22: M3 | D22: ='5'!E22 -> 90630.9 | E22: ='Daily Meter'!N11 -> 90753.1 | F22: =E22-D22 -> 122.2
B23: L = m³ x 3.70 | C23: L | F23: =F22*3.7 -> 452.14 | G23: =F23*2.5 -> 1130.35
D26: Summary of Daily Hotel consumption
D27: Item measured | E27: Units | F27: Consumption | G27: AED
D28: Chilled water | E28: TR | F28: =F8 -> 6028.008 | G28: =G8 -> 3797.645
D29: DEWA Water | E29: imp. Gallon | F29: =F11 -> 48393.18 | G29: =G11 -> 2903.5908
D30: Electricity | E30: kwh | F30: =F19 -> 15792 | G30: =G19 -> 6790.56
D31: Gas | E31: m3 | F31: =F22 -> 122.2 | G31: =G23 -> 1130.35
F32: Total cost | G32: =SUM(G28:G31) -> 14622.146

Sheet 7
A1: ENGINEERING DEPARTMENT | H1: daily reading
A2: UTILITY CONSUMPTION SHEET
B3: ='1'!B3 -> JANUARY 2024 | C3: 7 | D3: % OCCUPANCY: | E3: ='Daily Meter'!O12 -> 39.63
A4: SR.NO | B4: ITEM MEASURED | D4: Previous Reading | E4: 4 AM Reading | F4: 24hrs CONSUMPTION | G4: Cost
A6: 1 | B6: DISTRICT COOLING PLANT
B7: Chilled Water | C7: MWH | D7: ='6'!E7 -> 53595 | E7: ='Daily Meter'!B12 -> 53616.2 | F7: =E7-D7 -> 21.2
C8: TR | F8: =F7*284.34 -> 6028.008 | G8: =F8*0.63 -> 3797.645
A9: III | B9: WATER METERS
B10: Main DEWA Meter | C10: m3 | D10: ='6'!E10 -> 204530 | E10: ='Daily Meter'!C12 -> 204766 | F10: =E10-D10 -> 236
B11: Imperial Gallon = m³ x 219.969 | C11: IG | F11: =F10*219.969 -> 51912.684 | G11: =F11*0.06 -> 3114.761
A12: IV | B12: ELECTRICAL METERS
A13: 1 | B13: Meter 1 - 06065253 | C13: kW x 480 | D13: ='6'!E13 -> 6600.3 | E13: ='Daily Meter'!H12 -> 6607 | F13: =(E13-D13)*480 -> 3216
A14: 2 | B14: Meter 2 - 06065255 | C14: kW x 480 | D14: ='6'!E14 -> 3988.8 | E14: ='Daily Meter'!I12 -> 3992.4 | F14: =(E14-D14)*480 -> 1728
A15: 3 | B15: Meter 3 - 06065259 | C15: kW x 480 | D15: ='6'!E15 -> 4255.5 | E15: ='Daily Meter'!J12 -> 4260.2 | F15: =(E15-D15)*480 -> 2256
A16: 4 | B16: Meter 4 - 06065262 | C16: kW x 480 | D16: ='6'!E16 -> 2374.9 | E16: ='Daily Meter'!K12 -> 2377.9 | F16: =(E16-D16)*480 -> 1440
A17: 5 | B17: Meter 6 - 06065269 | C17: kW x 480 | D17: ='6'!E17 -> 5595.9 | E17: ='Daily Meter'!L12 -> 5600.4 | F17: =(E17-D17)*480 -> 2160
A18: 6 | B18: Meter 7 - 06065283 | C18: kW x 480 | D18: ='6'!E18 -> 15077.2 | E18: ='Daily Meter'!M12 -> 15089 | F18: =(E18-D18)*480 -> 5664
B19: TOTAL ELECTRICAL CONS.(kWh) | F19: =SUM(F13:F18) -> 16464 | G19: =F19*0.43 -> 7079.52
A21: V | B21: GAS CONSUMPTION
A22: 1 | B22: MAIN LPG METER | C22: M3 | D22: ='6'!E22 -> 90753.1 | E22: ='Daily Meter'!N12 -> 90872.5 | F22: =E22-D22 -> 119.4
B23: L = m³ x 3.70 | C23: L | F23: =F22*3.7 -> 441.78 | G23: =F23*2.5 -> 1104.45
D26: Summary of Daily Hotel consumption
D27: Item measured | E27: Units | F27: Consumption | G27: AED
D28: Chilled water | E28: TR | F28: =F8 -> 6028.008 | G28: =G8 -> 3797.645
D29: DEWA Water | E29: imp. Gallon | F29: =F11 -> 51912.684 | G29: =G11 -> 3114.761
D30: Electricity | E30: kwh | F30: =F19 -> 16464 | G30: =G19 -> 7079.52
D31: Gas | E31: m3 | F31: =F22 -> 119.4 | G31: =G23 -> 1104.45
F32: Total cost | G32: =SUM(G28:G31) -> 15096.376

Sheet 8
A1: ENGINEERING DEPARTMENT | H1: daily reading
A2: UTILITY CONSUMPTION SHEET
B3: ='1'!B3 -> JANUARY 2024 | C3: 8 | D3: % OCCUPANCY: | E3: ='Daily Meter'!O13 -> 70.97
A4: SR.NO | B4: ITEM MEASURED | D4: Previous Reading | E4: 4 AM Reading | F4: 24hrs CONSUMPTION | G4: Cost
A6: 1 | B6: DISTRICT COOLING PLANT
B7: Chilled Water | C7: MWH | D7: ='7'!E7 -> 53616.2 | E7: ='Daily Meter'!B13 -> 53635.2 | F7: =E7-D7 -> 19
C8: TR | F8: =F7*284.34 -> 5402.46 | G8: =F8*0.63 -> 3403.5498
A9: III | B9: WATER METERS
B10: Main DEWA Meter | C10: m3 | D10: ='7'!E10 -> 204766 | E10: ='Daily Meter'!C13 -> 204928 | F10: =E10-D10 -> 162
B11: Imperial Gallon = m³ x 219.969 | C11: IG | F11: =F10*219.969 -> 35634.978 | G11: =F11*0.06 -> 2138.0987
A12: IV | B12: ELECTRICAL METERS
A13: 1 | B13: Meter 1 - 06065253 | C13: kW x 480 | D13: ='7'!E13 -> 6607 | E13: ='Daily Meter'!H13 -> 6613.7 | F13: =(E13-D13)*480 -> 3216
A14: 2 | B14: Meter 2 - 06065255 | C14: kW x 480 | D14: ='7'!E14 -> 3992.4 | E14: ='Daily Meter'!I13 -> 3995.9 | F14: =(E14-D14)*480 -> 1680
A15: 3 | B15: Meter 3 - 06065259 | C15: kW x 480 | D15: ='7'!E15 -> 4260.2 | E15: ='Daily Meter'!J13 -> 4264.8 | F15: =(E15-D15)*480 -> 2208
A16: 4 | B16: Meter 4 - 06065262 | C16: kW x 480 | D16: ='7'!E16 -> 2377.9 | E16: ='Daily Meter'!K13 -> 2380.4 | F16: =(E16-D16)*480 -> 1200
A17: 5 | B17: Meter 6 - 06065269 | C17: kW x 480 | D17: ='7'!E17 -> 5600.4 | E17: ='Daily Meter'!L13 -> 5604.7 | F17: =(E17-D17)*480 -> 2064
A18: 6 | B18: Meter 7 - 06065283 | C18: kW x 480 | D18: ='7'!E18 -> 15089 | E18: ='Daily Meter'!M13 -> 15100.2 | F18: =(E18-D18)*480 -> 5376
B19: TOTAL ELECTRICAL CONS.(kWh) | F19: =SUM(F13:F18) -> 15744 | G19: =F19*0.43 -> 6769.92
A21: V | B21: GAS CONSUMPTION
A22: 1 | B22: MAIN LPG METER | C22: M3 | D22: ='7'!E22 -> 90872.5 | E22: ='Daily Meter'!N13 -> 90985.8 | F22: =E22-D22 -> 113.3
B23: L = m³ x 3.70 | C23: L | F23: =F22*3.7 -> 419.21 | G23: =F23*2.5 -> 1048.025
D26: Summary of Daily Hotel consumption
D27: Item measured | E27: Units | F27: Consumption | G27: AED
D28: Chilled water | E28: TR | F28: =F8 -> 5402.46 | G28: =G8 -> 3403.5498
D29: DEWA Water | E29: imp. Gallon | F29: =F11 -> 35634.978 | G29: =G11 -> 2138.0987
D30: Electricity | E30: kwh | F30: =F19 -> 15744 | G30: =G19 -> 6769.92
D31: Gas | E31: m3 | F31: =F22 -> 113.3 | G31: =G23 -> 1048.025
F32: Total cost | G32: =SUM(G28:G31) -> 13359.593

Sheet 9
A1: ENGINEERING DEPARTMENT | H1: daily reading
A2: UTILITY CONSUMPTION SHEET
B3: ='1'!B3 -> JANUARY 2024 | C3: 9 | D3: % OCCUPANCY: | E3: ='Daily Meter'!O14 -> 79.26
A4: SR.NO | B4: ITEM MEASURED | D4: Previous Reading | E4: 4 AM Reading | F4: 24hrs CONSUMPTION | G4: Cost
A6: 1 | B6: DISTRICT COOLING PLANT
B7: Chilled Water | C7: MWH | D7: ='8'!E7 -> 53635.2 | E7: ='Daily Meter'!B14 -> 53656 | F7: =E7-D7 -> 20.8
C8: TR | F8: =F7*284.34 -> 5914.272 | G8: =F8*0.63 -> 3725.9914
A9: III | B9: WATER METERS
B10: Main DEWA Meter | C10: m3 | D10: ='8'!E10 -> 204928 | E10: ='Daily Meter'!C14 -> 205059 | F10: =E10-D10 -> 131
B11: Imperial Gallon = m³ x 219.969 | C11: IG | F11: =F10*219.969 -> 28815.939 | G11: =F11*0.06 -> 1728.9563
A12: IV | B12: ELECTRICAL METERS
A13: 1 | B13: Meter 1 - 06065253 | C13: kW x 480 | D13: ='8'!E13 -> 6613.7 | E13: ='Daily Meter'!H14 -> 6620.5 | F13: =(E13-D13)*480 -> 3264
A14: 2 | B14: Meter 2 - 06065255 | C14: kW x 480 | D14: ='8'!E14 -> 3995.9 | E14: ='Daily Meter'!I14 -> 3999.6 | F14: =(E14-D14)*480 -> 1776
A15: 3 | B15: Meter 3 - 06065259 | C15: kW x 480 | D15: ='8'!E15 -> 4264.8 | E15: ='Daily Meter'!J14 -> 4269.4 | F15: =(E15-D15)*480 -> 2208
A16: 4 | B16: Meter 4 - 06065262 | C16: kW x 480 | D16: ='8'!E16 -> 2380.4 | E16: ='Daily Meter'!K14 -> 2383.1 | F16: =(E16-D16)*480 -> 1296
A17: 5 | B17: Meter 6 - 06065269 | C17: kW x 480 | D17: ='8'!E17 -> 5604.7 | E17: ='Daily Meter'!L14 -> 5609.1 | F17: =(E17-D17)*480 -> 2112
A18: 6 | B18: Meter 7 - 06065283 | C18: kW x 480 | D18: ='8'!E18 -> 15100.2 | E18: ='Daily Meter'!M14 -> 15111.3 | F18: =(E18-D18)*480 -> 5328
B19: TOTAL ELECTRICAL CONS.(kWh) | F19: =SUM(F13:F18) -> 15984 | G19: =F19*0.43 -> 6873.12
A21: V | B21: GAS CONSUMPTION
A22: 1 | B22: MAIN LPG METER | C22: M3 | D22: ='8'!E22 -> 90985.8 | E22: ='Daily Meter'!N14 -> 91106 | F22: =E22-D22 -> 120.2
B23: L = m³ x 3.70 | C23: L | F23: =F22*3.7 -> 444.74 | G23: =F23*2.5 -> 1111.85
D26: Summary of Daily Hotel consumption
D27: Item measured | E27: Units | F27: Consumption | G27: AED
D28: Chilled water | E28: TR | F28: =F8 -> 5914.272 | G28: =G8 -> 3725.9914
D29: DEWA Water | E29: imp. Gallon | F29: =F11 -> 28815.939 | G29: =G11 -> 1728.9563
D30: Electricity | E30: kwh | F30: =F19 -> 15984 | G30: =G19 -> 6873.12
D31: Gas | E31: m3 | F31: =F22 -> 120.2 | G31: =G23 -> 1111.85
F32: Total cost | G32: =SUM(G28:G31) -> 13439.918

Sheet 10
A1: ENGINEERING DEPARTMENT | H1: daily reading
A2: UTILITY CONSUMPTION SHEET
B3: ='1'!B3 -> JANUARY 2024 | C3: 10 | D3: % OCCUPANCY: | E3: ='Daily Meter'!O15 -> 86.67
A4: SR.NO | B4: ITEM MEASURED | D4: Previous Reading | E4: 4 AM Reading | F4: 24hrs CONSUMPTION | G4: Cost
A6: 1 | B6: DISTRICT COOLING PLANT
B7: Chilled Water | C7: MWH | D7: ='9'!E7 -> 53656 | E7: ='Daily Meter'!B15 -> 53676.9 | F7: =E7-D7 -> 20.9
C8: TR | F8: =F7*284.34 -> 5942.706 | G8: =F8*0.63 -> 3743.9048
A9: III | B9: WATER METERS
B10: Main DEWA Meter | C10: m3 | D10: ='9'!E10 -> 205059 | E10: ='Daily Meter'!C15 -> 205282 | F10: =E10-D10 -> 223
B11: Imperial Gallon = m³ x 219.969 | C11: IG | F11: =F10*219.969 -> 49053.087 | G11: =F11*0.06 -> 2943.1852
A12: IV | B12: ELECTRICAL METERS
A13: 1 | B13: Meter 1 - 06065253 | C13: kW x 480 | D13: ='9'!E13 -> 6620.5 | E13: ='Daily Meter'!H15 -> 6627.3 | F13: =(E13-D13)*480 -> 3264
A14: 2 | B14: Meter 2 - 06065255 | C14: kW x 480 | D14: ='9'!E14 -> 3999.6 | E14: ='Daily Meter'!I15 -> 4003.7 | F14: =(E14-D14)*480 -> 1968
A15: 3 | B15: Meter 3 - 06065259 | C15: kW x 480 | D15: ='9'!E15 -> 4269.4 | E15: ='Daily Meter'!J15 -> 4274.1 | F15: =(E15-D15)*480 -> 2256
A16: 4 | B16: Meter 4 - 06065262 | C16: kW x 480 | D16: ='9'!E16 -> 2383.1 | E16: ='Daily Meter'!K15 -> 2385.9 | F16: =(E16-D16)*480 -> 1344
A17: 5 | B17: Meter 6 - 06065269 | C17: kW x 480 | D17: ='9'!E17 -> 5609.1 | E17: ='Daily Meter'!L15 -> 5613.5 | F17: =(E17-D17)*480 -> 2112
A18: 6 | B18: Meter 7 - 06065283 | C18: kW x 480 | D18: ='9'!E18 -> 15111.3 | E18: ='Daily Meter'!M15 -> 15122.2 | F18: =(E18-D18)*480 -> 5232
B19: TOTAL ELECTRICAL CONS.(kWh) | F19: =SUM(F13:F18) -> 16176 | G19: =F19*0.43 -> 6955.68
A21: V | B21: GAS CONSUMPTION
A22: 1 | B22: MAIN LPG METER | C22: M3 | D22: ='9'!E22 -> 91106 | E22: ='Daily Meter'!N15 -> 91234 | F22: =E22-D22 -> 128
B23: L = m³ x 3.70 | C23: L | F23: =F22*3.7 -> 473.6 | G23: =F23*2.5 -> 1184
D26: Summary of Daily Hotel consumption
D27: Item measured | E27: Units | F27: Consumption | G27: AED
D28: Chilled water | E28: TR | F28: =F8 -> 5942.706 | G28: =G8 -> 3743.9048
D29: DEWA Water | E29: imp. Gallon | F29: =F11 -> 49053.087 | G29: =G11 -> 2943.1852
D30: Electricity | E30: kwh | F30: =F19 -> 16176 | G30: =G19 -> 6955.68
D31: Gas | E31: m3 | F31: =F22 -> 128 | G31: =G23 -> 1184
F32: Total cost | G32: =SUM(G28:G31) -> 14826.77

Sheet 11
A1: ENGINEERING DEPARTMENT | H1: daily reading
A2: UTILITY CONSUMPTION SHEET
B3: ='1'!B3 -> JANUARY 2024 | C3: 11 | D3: % OCCUPANCY: | E3: ='Daily Meter'!O16 -> 69.82
A4: SR.NO | B4: ITEM MEASURED | D4: Previous Reading | E4: 4 AM Reading | F4: 24hrs CONSUMPTION | G4: Cost
A6: 1 | B6: DISTRICT COOLING PLANT
B7: Chilled Water | C7: MWH | D7: ='10'!E7 -> 53676.9 | E7: ='Daily Meter'!B16 -> 53697.4 | F7: =E7-D7 -> 20.5
C8: TR | F8: =F7*284.34 -> 5828.97 | G8: =F8*0.63 -> 3672.2511
A9: III | B9: WATER METERS
B10: Main DEWA Meter | C10: m3 | D10: ='10'!E10 -> 205282 | E10: ='Daily Meter'!C16 -> 205368 | F10: =E10-D10 -> 86
B11: Imperial Gallon = m³ x 219.969 | C11: IG | F11: =F10*219.969 -> 18917.334 | G11: =F11*0.06 -> 1135.04
A12: IV | B12: ELECTRICAL METERS
A13: 1 | B13: Meter 1 - 06065253 | C13: kW x 480 | D13: ='10'!E13 -> 6627.3 | E13: ='Daily Meter'!H16 -> 6634.1 | F13: =(E13-D13)*480 -> 3264
A14: 2 | B14: Meter 2 - 06065255 | C14: kW x 480 | D14: ='10'!E14 -> 4003.7 | E14: ='Daily Meter'!I16 -> 4007.7 | F14: =(E14-D14)*480 -> 1920
A15: 3 | B15: Meter 3 - 06065259 | C15: kW x 480 | D15: ='10'!E15 -> 4274.1 | E15: ='Daily Meter'!J16 -> 4278.7 | F15: =(E15-D15)*480 -> 2208
A16: 4 | B16: Meter 4 - 06065262 | C16: kW x 480 | D16: ='10'!E16 -> 2385.9 | E16: ='Daily Meter'!K16 -> 2388.6 | F16: =(E16-D16)*480 -> 1296
A17: 5 | B17: Meter 6 - 06065269 | C17: kW x 480 | D17: ='10'!E17 -> 5613.5 | E17: ='Daily Meter'!L16 -> 5618 | F17: =(E17-D17)*480 -> 2160
A18: 6 | B18: Meter 7 - 06065283 | C18: kW x 480 | D18: ='10'!E18 -> 15122.2 | E18: ='Daily Meter'!M16 -> 15133.3 | F18: =(E18-D18)*480 -> 5328
B19: TOTAL ELECTRICAL CONS.(kWh) | F19: =SUM(F13:F18) -> 16176 | G19: =F19*0.43 -> 6955.68
A21: V | B21: GAS CONSUMPTION
A22: 1 | B22: MAIN LPG METER | C22: M3 | D22: ='10'!E22 -> 91234 | E22: ='Daily Meter'!N16 -> 91341.5 | F22: =E22-D22 -> 107.5
B23: L = m³ x 3.70 | C23: L | F23: =F22*3.7 -> 397.75 | G23: =F23*2.5 -> 994.375
D26: Summary of Daily Hotel consumption
D27: Item measured | E27: Units | F27: Consumption | G27: AED
D28: Chilled water | E28: TR | F28: =F8 -> 5828.97 | G28: =G8 -> 3672.2511
D29: DEWA Water | E29: imp. Gallon | F29: =F11 -> 18917.334 | G29: =G11 -> 1135.04
D30: Electricity | E30: kwh | F30: =F19 -> 16176 | G30: =G19 -> 6955.68
D31: Gas | E31: m3 | F31: =F22 -> 107.5 | G31: =G23 -> 994.375
F32: Total cost | G32: =SUM(G28:G31) -> 12757.346

Sheet 12
A1: ENGINEERING DEPARTMENT | H1: daily reading
A2: UTILITY CONSUMPTION SHEET
B3: ='1'!B3 -> JANUARY 2024 | C3: 12 | D3: % OCCUPANCY: | E3: ='Daily Meter'!O17 -> 55.99
A4: SR.NO | B4: ITEM MEASURED | D4: Previous Reading | E4: 4 AM Reading | F4: 24hrs CONSUMPTION | G4: Cost
A6: 1 | B6: DISTRICT COOLING PLANT
B7: Chilled Water | C7: MWH | D7: ='11'!E7 -> 53697.4 | E7: ='Daily Meter'!B17 -> 53716.2 | F7: =E7-D7 -> 18.8
C8: TR | F8: =F7*284.34 -> 5345.592 | G8: =F8*0.63 -> 3367.723
A9: III | B9: WATER METERS
B10: Main DEWA Meter | C10: m3 | D10: ='11'!E10 -> 205368 | E10: ='Daily Meter'!C17 -> 205672 | F10: =E10-D10 -> 304
B11: Imperial Gallon = m³ x 219.969 | C11: IG | F11: =F10*219.969 -> 66870.576 | G11: =F11*0.06 -> 4012.2346
A12: IV | B12: ELECTRICAL METERS
A13: 1 | B13: Meter 1 - 06065253 | C13: kW x 480 | D13: ='11'!E13 -> 6634.1 | E13: ='Daily Meter'!H17 -> 6641.2 | F13: =(E13-D13)*480 -> 3408
A14: 2 | B14: Meter 2 - 06065255 | C14: kW x 480 | D14: ='11'!E14 -> 4007.7 | E14: ='Daily Meter'!I17 -> 4011.6 | F14: =(E14-D14)*480 -> 1872
A15: 3 | B15: Meter 3 - 06065259 | C15: kW x 480 | D15: ='11'!E15 -> 4278.7 | E15: ='Daily Meter'!J17 -> 4283.5 | F15: =(E15-D15)*480 -> 2304
A16: 4 | B16: Meter 4 - 06065262 | C16: kW x 480 | D16: ='11'!E16 -> 2388.6 | E16: ='Daily Meter'!K17 -> 2391.4 | F16: =(E16-D16)*480 -> 1344
A17: 5 | B17: Meter 6 - 06065269 | C17: kW x 480 | D17: ='11'!E17 -> 5618 | E17: ='Daily Meter'!L17 -> 5622.5 | F17: =(E17-D17)*480 -> 2160
A18: 6 | B18: Meter 7 - 06065283 | C18: kW x 480 | D18: ='11'!E18 -> 15133.3 | E18: ='Daily Meter'!M17 -> 15144.6 | F18: =(E18-D18)*480 -> 5424
B19: TOTAL ELECTRICAL CONS.(kWh) | F19: =SUM(F13:F18) -> 16512 | G19: =F19*0.43 -> 7100.16
A21: V | B21: GAS CONSUMPTION
A22: 1 | B22: MAIN LPG METER | C22: M3 | D22: ='11'!E22 -> 91341.5 | E22: ='Daily Meter'!N17 -> 91517.7 | F22: =E22-D22 -> 176.2
B23: L = m³ x 3.70 | C23: L | F23: =F22*3.7 -> 651.94 | G23: =F23*2.5 -> 1629.85
D26: Summary of Daily Hotel consumption
D27: Item measured | E27: Units | F27: Consumption | G27: AED
D28: Chilled water | E28: TR | F28: =F8 -> 5345.592 | G28: =G8 -> 3367.723
D29: DEWA Water | E29: imp. Gallon | F29: =F11 -> 66870.576 | G29: =G11 -> 4012.2346
D30: Electricity | E30: kwh | F30: =F19 -> 16512 | G30: =G19 -> 7100.16
D31: Gas | E31: m3 | F31: =F22 -> 176.2 | G31: =G23 -> 1629.85
F32: Total cost | G32: =SUM(G28:G31) -> 16109.968

Sheet 13
A1: ENGINEERING DEPARTMENT | H1: daily reading
A2: UTILITY CONSUMPTION SHEET
B3: ='1'!B3 -> JANUARY 2024 | C3: 13 | D3: % OCCUPANCY: | E3: ='Daily Meter'!O18 -> 44.24
A4: SR.NO | B4: ITEM MEASURED | D4: Previous Reading | E4: 4 AM Reading | F4: 24hrs CONSUMPTION | G4: Cost
A6: 1 | B6: DISTRICT COOLING PLANT
B7: Chilled Water | C7: MWH | D7: ='12'!E7 -> 53716.2 | E7: ='Daily Meter'!B18 -> 53734.8 | F7: =E7-D7 -> 18.6
C8: TR | F8: =F7*284.34 -> 5288.724 | G8: =F8*0.63 -> 3331.8961
A9: III | B9: WATER METERS
B10: Main DEWA Meter | C10: m3 | D10: ='12'!E10 -> 205672 | E10: ='Daily Meter'!C18 -> 205925 | F10: =E10-D10 -> 253
B11: Imperial Gallon = m³ x 219.969 | C11: IG | F11: =F10*219.969 -> 55652.157 | G11: =F11*0.06 -> 3339.1294
A12: IV | B12: ELECTRICAL METERS
A13: 1 | B13: Meter 1 - 06065253 | C13: kW x 480 | D13: ='12'!E13 -> 6641.2 | E13: ='Daily Meter'!H18 -> 6648.4 | F13: =(E13-D13)*480 -> 3456
A14: 2 | B14: Meter 2 - 06065255 | C14: kW x 480 | D14: ='12'!E14 -> 4011.6 | E14: ='Daily Meter'!I18 -> 4015.4 | F14: =(E14-D14)*480 -> 1824
A15: 3 | B15: Meter 3 - 06065259 | C15: kW x 480 | D15: ='12'!E15 -> 4283.5 | E15: ='Daily Meter'!J18 -> 4288.4 | F15: =(E15-D15)*480 -> 2352
A16: 4 | B16: Meter 4 - 06065262 | C16: kW x 480 | D16: ='12'!E16 -> 2391.4 | E16: ='Daily Meter'!K18 -> 2394.2 | F16: =(E16-D16)*480 -> 1344
A17: 5 | B17: Meter 6 - 06065269 | C17: kW x 480 | D17: ='12'!E17 -> 5622.5 | E17: ='Daily Meter'!L18 -> 5627.1 | F17: =(E17-D17)*480 -> 2208
A18: 6 | B18: Meter 7 - 06065283 | C18: kW x 480 | D18: ='12'!E18 -> 15144.6 | E18: ='Daily Meter'!M18 -> 15156 | F18: =(E18-D18)*480 -> 5472
B19: TOTAL ELECTRICAL CONS.(kWh) | F19: =SUM(F13:F18) -> 16656 | G19: =F19*0.43 -> 7162.08
A21: V | B21: GAS CONSUMPTION
A22: 1 | B22: MAIN LPG METER | C22: M3 | D22: ='12'!E22 -> 91517.7 | E22: ='Daily Meter'!N18 -> 91677.1 | F22: =E22-D22 -> 159.4
B23: L = m³ x 3.70 | C23: L | F23: =F22*3.7 -> 589.78 | G23: =F23*2.5 -> 1474.45
D26: Summary of Daily Hotel consumption
D27: Item measured | E27: Units | F27: Consumption | G27: AED
D28: Chilled water | E28: TR | F28: =F8 -> 5288.724 | G28: =G8 -> 3331.8961
D29: DEWA Water | E29: imp. Gallon | F29: =F11 -> 55652.157 | G29: =G11 -> 3339.1294
D30: Electricity | E30: kwh | F30: =F19 -> 16656 | G30: =G19 -> 7162.08
D31: Gas | E31: m3 | F31: =F22 -> 159.4 | G31: =G23 -> 1474.45
F32: Total cost | G32: =SUM(G28:G31) -> 15307.556

Sheet 14
A1: ENGINEERING DEPARTMENT | H1: daily reading
A2: UTILITY CONSUMPTION SHEET
B3: ='1'!B3 -> JANUARY 2024 | C3: 14 | D3: % OCCUPANCY: | E3: ='Daily Meter'!O19 -> 52.07
A4: SR.NO | B4: ITEM MEASURED | D4: Previous Reading | E4: 4 AM Reading | F4: 24hrs CONSUMPTION | G4: Cost
A6: 1 | B6: DISTRICT COOLING PLANT
B7: Chilled Water | C7: MWH | D7: ='13'!E7 -> 53734.8 | E7: ='Daily Meter'!B19 -> 53753.3 | F7: =E7-D7 -> 18.5
C8: TR | F8: =F7*284.34 -> 5260.29 | G8: =F8*0.63 -> 3313.9827
A9: III | B9: WATER METERS
B10: Main DEWA Meter | C10: m3 | D10: ='13'!E10 -> 205925 | E10: ='Daily Meter'!C19 -> 206117 | F10: =E10-D10 -> 192
B11: Imperial Gallon = m³ x 219.969 | C11: IG | F11: =F10*219.969 -> 42234.048 | G11: =F11*0.06 -> 2534.0429
A12: IV | B12: ELECTRICAL METERS
A13: 1 | B13: Meter 1 - 06065253 | C13: kW x 480 | D13: ='13'!E13 -> 6648.4 | E13: ='Daily Meter'!H19 -> 6655.3 | F13: =(E13-D13)*480 -> 3312
A14: 2 | B14: Meter 2 - 06065255 | C14: kW x 480 | D14: ='13'!E14 -> 4015.4 | E14: ='Daily Meter'!I19 -> 4018.9 | F14: =(E14-D14)*480 -> 1680
A15: 3 | B15: Meter 3 - 06065259 | C15: kW x 480 | D15: ='13'!E15 -> 4288.4 | E15: ='Daily Meter'!J19 -> 4293 | F15: =(E15-D15)*480 -> 2208
A16: 4 | B16: Meter 4 - 06065262 | C16: kW x 480 | D16: ='13'!E16 -> 2394.2 | E16: ='Daily Meter'!K19 -> 2396.9 | F16: =(E16-D16)*480 -> 1296
A17: 5 | B17: Meter 6 - 06065269 | C17: kW x 480 | D17: ='13'!E17 -> 5627.1 | E17: ='Daily Meter'!L19 -> 5631.5 | F17: =(E17-D17)*480 -> 2112
A18: 6 | B18: Meter 7 - 06065283 | C18: kW x 480 | D18: ='13'!E18 -> 15156 | E18: ='Daily Meter'!M19 -> 15166.7 | F18: =(E18-D18)*480 -> 5136
B19: TOTAL ELECTRICAL CONS.(kWh) | F19: =SUM(F13:F18) -> 15744 | G19: =F19*0.43 -> 6769.92
A21: V | B21: GAS CONSUMPTION
A22: 1 | B22: MAIN LPG METER | C22: M3 | D22: ='13'!E22 -> 91677.1 | E22: ='Daily Meter'!N19 -> 91814.2 | F22: =E22-D22 -> 137.1
B23: L = m³ x 3.70 | C23: L | F23: =F22*3.7 -> 507.27 | G23: =F23*2.5 -> 1268.175
D26: Summary of Daily Hotel consumption
D27: Item measured | E27: Units | F27: Consumption | G27: AED
D28: Chilled water | E28: TR | F28: =F8 -> 5260.29 | G28: =G8 -> 3313.9827
D29: DEWA Water | E29: imp. Gallon | F29: =F11 -> 42234.048 | G29: =G11 -> 2534.0429
D30: Electricity | E30: kwh | F30: =F19 -> 15744 | G30: =G19 -> 6769.92
D31: Gas | E31: m3 | F31: =F22 -> 137.1 | G31: =G23 -> 1268.175
F32: Total cost | G32: =SUM(G28:G31) -> 13886.121

Sheet 15
A1: ENGINEERING DEPARTMENT | H1: daily reading
A2: UTILITY CONSUMPTION SHEET
B3: ='1'!B3 -> JANUARY 2024 | C3: 15 | D3: % OCCUPANCY: | E3: ='Daily Meter'!O20 -> 82.72
A4: SR.NO | B4: ITEM MEASURED | D4: Previous Reading | E4: 4 AM Reading | F4: 24hrs CONSUMPTION | G4: Cost
A6: 1 | B6: DISTRICT COOLING PLANT
B7: Chilled Water | C7: MWH | D7: ='14'!E7 -> 53753.3 | E7: ='Daily Meter'!B20 -> 53772.3 | F7: =E7-D7 -> 19
C8: TR | F8: =F7*284.34 -> 5402.46 | G8: =F8*0.63 -> 3403.5498
A9: III | B9: WATER METERS
B10: Main DEWA Meter | C10: m3 | D10: ='14'!E10 -> 206117 | E10: ='Daily Meter'!C20 -> 206290 | F10: =E10-D10 -> 173
B11: Imperial Gallon = m³ x 219.969 | C11: IG | F11: =F10*219.969 -> 38054.637 | G11: =F11*0.06 -> 2283.2782
A12: IV | B12: ELECTRICAL METERS
A13: 1 | B13: Meter 1 - 06065253 | C13: kW x 480 | D13: ='14'!E13 -> 6655.3 | E13: ='Daily Meter'!H20 -> 6662 | F13: =(E13-D13)*480 -> 3216
A14: 2 | B14: Meter 2 - 06065255 | C14: kW x 480 | D14: ='14'!E14 -> 4018.9 | E14: ='Daily Meter'!I20 -> 4022.85 | F14: =(E14-D14)*480 -> 1896
A15: 3 | B15: Meter 3 - 06065259 | C15: kW x 480 | D15: ='14'!E15 -> 4293 | E15: ='Daily Meter'!J20 -> 4297.3 | F15: =(E15-D15)*480 -> 2064
A16: 4 | B16: Meter 4 - 06065262 | C16: kW x 480 | D16: ='14'!E16 -> 2396.9 | E16: ='Daily Meter'!K20 -> 2399.5 | F16: =(E16-D16)*480 -> 1248
A17: 5 | B17: Meter 6 - 06065269 | C17: kW x 480 | D17: ='14'!E17 -> 5631.5 | E17: ='Daily Meter'!L20 -> 5635.9 | F17: =(E17-D17)*480 -> 2112
A18: 6 | B18: Meter 7 - 06065283 | C18: kW x 480 | D18: ='14'!E18 -> 15166.7 | E18: ='Daily Meter'!M20 -> 15176.3 | F18: =(E18-D18)*480 -> 4608
B19: TOTAL ELECTRICAL CONS.(kWh) | F19: =SUM(F13:F18) -> 15144 | G19: =F19*0.43 -> 6511.92
A21: V | B21: GAS CONSUMPTION
A22: 1 | B22: MAIN LPG METER | C22: M3 | D22: ='14'!E22 -> 91814.2 | E22: ='Daily Meter'!N20 -> 91928.7 | F22: =E22-D22 -> 114.5
B23: L = m³ x 3.70 | C23: L | F23: =F22*3.7 -> 423.65 | G23: =F23*2.5 -> 1059.125
D26: Summary of Daily Hotel consumption
D27: Item measured | E27: Units | F27: Consumption | G27: AED
D28: Chilled water | E28: TR | F28: =F8 -> 5402.46 | G28: =G8 -> 3403.5498
