Workbook

Sheet 1
A1: ENGINEERING DEPARTMENT | H1: daily reading
A2: UTILITY CONSUMPTION SHEET
B3: JANUARY 2024 | C3: 1 | D3: % OCCUPANCY: | E3: ='Daily Meter'!O6 -> 60.83
A4: SR.NO | B4: ITEM MEASURED | D4: Previous Reading | E4: 4 AM Reading | F4: 24hrs CONSUMPTION | G4: Cost
D5: DECEMBER 31
A6: 1 | B6: DISTRICT COOLING PLANT
B7: Chilled Water | C7: MWH | D7: 53446.3 | E7: ='Daily Meter'!B6 -> 53476.8 | F7: =E7-D7 -> 30.5
C8: TR | F8: =F7*284.34 -> 8672.37 | G8: =F8*0.63 -> 5463.5931
A9: III | B9: WATER METERS
B10: Main DEWA Meter | C10: m3 | D10: 203437 | E10: ='Daily Meter'!C6 -> 203658 | F10: =E10-D10 -> 221
B11: Imperial Gallon = m³ x 219.969 | C11: IG | F11: =F10*219.969 -> 48613.149 | G11: =F11*0.06 -> 2916.7889
A12: IV | B12: ELECTRICAL METERS
A13: 1 | B13: Meter 1 - 06065253 | C13: kW x 480 | D13: 6559.3 | E13: ='Daily Meter'!H6 -> 6566.3 | F13: =(E13-D13)*480 -> 3360
A14: 2 | B14: Meter 2 - 06065255 | C14: kW x 480 | D14: 3966.1 | E14: ='Daily Meter'!I6 -> 3970.2 | F14: =(E14-D14)*480 -> 1968
A15: 3 | B15: Meter 3 - 06065259 | C15: kW x 480 | D15: 4228.9 | E15: ='Daily Meter'!J6 -> 4233.6 | F15: =(E15-D15)*480 -> 2256
A16: 4 | B16: Meter 4 - 06065262 | C16: kW x 480 | D16: 2358.9 | E16: ='Daily Meter'!K6 -> 2361.9 | F16: =(E16-D16)*480 -> 1440
A17: 5 | B17: Meter 6 - 06065269 | C17: kW x 480 | D17: 5569.2 | E17: ='Daily Meter'!L6 -> 5573.8 | F17: =(E17-D17)*480 -> 2208
A18: 6 | B18: Meter 7 - 06065283 | C18: kW x 480 | D18: 15010.6 | E18: ='Daily Meter'!M6 -> 15022.4 | F18: =(E18-D18)*480 -> 5664
B19: TOTAL ELECTRICAL CONS.(kWh) | F19: =SUM(F13:F18) -> 16896 | G19: =F19*0.43 -> 7265.28
A21: V | B21: GAS CONSUMPTION
A22: 1 | B22: MAIN LPG METER | C22: M3 | D22: 89987.4 | E22: ='Daily Meter'!N6 -> 90136.2 | F22: =E22-D22 -> 148.8
B23: L = m³ x 3.70 | C23: L | F23: =F22*3.7 -> 550.56 | G23: =F23*2.5 -> 1376.4
D26: Summary of Daily Hotel consumption
D27: Item measured | E27: Units | F27: Consumption | G27: AED
D28: Chilled water | E28: TR | F28: =F8 -> 8672.37 | G28: =G8 -> 5463.5931
D29: DEWA Water | E29: imp. Gallon | F29: =F11 -> 48613.149 | G29: =G11 -> 2916.7889
D30: Electricity | E30: kwh | F30: =F19 -> 16896 | G30: =G19 -> 7265.28
D31: Gas | E31: m3 | F31: =F22 -> 148.8 | G31: =G23 -> 1376.4
F32: Total cost | G32: =SUM(G28:G31) -> 17022.062

Sheet 2
A1: ENGINEERING DEPARTMENT | H1: daily reading
A2: UTILITY CONSUMPTION SHEET
B3: ='1'!B3 -> JANUARY 2024 | C3: 2 | D3: % OCCUPANCY: | E3: ='Daily Meter'!O6 -> 60.83
A4: SR.NO | B4: ITEM MEASURED | D4: Previous Reading | E4: 4 AM Reading | F4: 24hrs CONSUMPTION | G4: Cost
A6: 1 | B6: DISTRICT COOLING PLANT
B7: Chilled Water | C7: MWH | D7: ='1'!E7 -> 53476.8 | E7: ='Daily Meter'!B7 -> 53504.7 | F7: =E7-D7 -> 27.9
C8: TR | F8: =F7*284.34 -> 7933.086 | G8: =F8*0.63 -> 4997.8442
A9: III | B9: WATER METERS
B10: Main DEWA Meter | C10: m3 | D10: ='1'!E10 -> 203658 | E10: ='Daily Meter'!C7 -> 203854 | F10: =E10-D10 -> 196
B11: Imperial Gallon = m³ x 219.969 | C11: IG | F11: =F10*219.969 -> 43113.924 | G11: =F11*0.06 -> 2586.8354
A12: IV | B12: ELECTRICAL METERS
A13: 1 | B13: Meter 1 - 06065253 | C13: kW x 480 | D13: ='1'!E13 -> 6566.3 | E13: ='Daily Meter'!H7 -> 6573.5 | F13: =(E13-D13)*480 -> 3456
A14: 2 | B14: Meter 2 - 06065255 | C14: kW x 480 | D14: ='1'!E14 -> 3970.2 | E14: ='Daily Meter'!I7 -> 3973.9 | F14: =(E14-D14)*480 -> 1776
A15: 3 | B15: Meter 3 - 06065259 | C15: kW x 480 | D15: ='1'!E15 -> 4233.6 | E15: ='Daily Meter'!J7 -> 4237.9 | F15: =(E15-D15)*480 -> 2064
A16: 4 | B16: Meter 4 - 06065262 | C16: kW x 480 | D16: ='1'!E16 -> 2361.9 | E16: ='Daily Meter'!K7 -> 2364.5 | F16: =(E16-D16)*480 -> 1248
A17: 5 | B17: Meter 6 - 06065269 | C17: kW x 480 | D17: ='1'!E17 -> 5573.8 | E17: ='Daily Meter'!L7 -> 5578.2 | F17: =(E17-D17)*480 -> 2112
A18: 6 | B18: Meter 7 - 06065283 | C18: kW x 480 | D18: ='1'!E18 -> 15022.4 | E18: ='Daily Meter'!M7 -> 15034 | F18: =(E18-D18)*480 -> 5568
B19: TOTAL ELECTRICAL CONS.(kWh) | F19: =SUM(F13:F18) -> 16224 | G19: =F19*0.43 -> 6976.32
A21: V | B21: GAS CONSUMPTION
A22: 1 | B22: MAIN LPG METER | C22: M3 | D22: ='1'!E22 -> 90136.2 | E22: ='Daily Meter'!N7 -> 90266 | F22: =E22-D22 -> 129.8
B23: L = m³ x 3.70 | C23: L | F23: =F22*3.7 -> 480.26 | G23: =F23*2.5 -> 1200.65
D26: Summary of Daily Hotel consumption
D27: Item measured | E27: Units | F27: Consumption | G27: AED
D28: Chilled water | E28: TR | F28: =F8 -> 7933.086 | G28: =G8 -> 4997.8442
D29: DEWA Water | E29: imp. Gallon | F29: =F11 -> 43113.924 | G29: =G11 -> 2586.8354
D30: Electricity | E30: kwh | F30: =F19 -> 16224 | G30: =G19 -> 6976.32
D31: Gas | E31: m3 | F31: =F22 -> 129.8 | G31: =G23 -> 1200.65
F32: Total cost | G32: =SUM(G28:G31) -> 15761.65

Sheet 3
A1: ENGINEERING DEPARTMENT | H1: daily reading
A2: UTILITY CONSUMPTION SHEET
B3: ='1'!B3 -> JANUARY 2024 | C3: 3 | D3: % OCCUPANCY: | E3: ='Daily Meter'!O8 -> 53.46
A4: SR.NO | B4: ITEM MEASURED | D4: Previous Reading | E4: 4 AM Reading | F4: 24hrs CONSUMPTION | G4: Cost
A6: 1 | B6: DISTRICT COOLING PLANT
B7: Chilled Water | C7: MWH | D7: ='2'!E7 -> 53504.7 | E7: ='Daily Meter'!B8 -> 53528.8 | F7: =E7-D7 -> 24.1
C8: TR | F8: =F7*284.34 -> 6852.594 | G8: =F8*0.63 -> 4317.1342
A9: III | B9: WATER METERS
B10: Main DEWA Meter | C10: m3 | D10: ='2'!E10 -> 203854 | E10: ='Daily Meter'!C8 -> 204020 | F10: =E10-D10 -> 166
B11: Imperial Gallon = m³ x 219.969 | C11: IG | F11: =F10*219.969 -> 36514.854 | G11: =F11*0.06 -> 2190.8912
A12: IV | B12: ELECTRICAL METERS
A13: 1 | B13: Meter 1 - 06065253 | C13: kW x 480 | D13: ='2'!E13 -> 6573.5 | E13: ='Daily Meter'!H8 -> 6580.4 | F13: =(E13-D13)*480 -> 3312
A14: 2 | B14: Meter 2 - 06065255 | C14: kW x 480 | D14: ='2'!E14 -> 3973.9 | E14: ='Daily Meter'!I8 -> 3977.7 | F14: =(E14-D14)*480 -> 1824
A15: 3 | B15: Meter 3 - 06065259 | C15: kW x 480 | D15: ='2'!E15 -> 4237.9 | E15: ='Daily Meter'!J8 -> 4242.1 | F15: =(E15-D15)*480 -> 2016
A16: 4 | B16: Meter 4 - 06065262 | C16: kW x 480 | D16: ='2'!E16 -> 2364.5 | E16: ='Daily Meter'!K8 -> 2367.1 | F16: =(E16-D16)*480 -> 1248
A17: 5 | B17: Meter 6 - 06065269 | C17: kW x 480 | D17: ='2'!E17 -> 5578.2 | E17: ='Daily Meter'!L8 -> 5582.6 | F17: =(E17-D17)*480 -> 2112
A18: 6 | B18: Meter 7 - 06065283 | C18: kW x 480 | D18: ='2'!E18 -> 15034 | E18: ='Daily Meter'!M8 -> 15045.3 | F18: =(E18-D18)*480 -> 5424
B19: TOTAL ELECTRICAL CONS.(kWh) | F19: =SUM(F13:F18) -> 15936 | G19: =F19*0.43 -> 6852.48
A21: V | B21: GAS CONSUMPTION
A22: 1 | B22: MAIN LPG METER | C22: M3 | D22: ='2'!E22 -> 90266 | E22: ='Daily Meter'!N8 -> 90385.8 | F22: =E22-D22 -> 119.8
B23: L = m³ x 3.70 | C23: L | F23: =F22*3.7 -> 443.26 | G23: =F23*2.5 -> 1108.15
D26: Summary of Daily Hotel consumption
D27: Item measured | E27: Units | F27: Consumption | G27: AED
D28: Chilled water | E28: TR | F28: =F8 -> 6852.594 | G28: =G8 -> 4317.1342
D29: DEWA Water | E29: imp. Gallon | F29: =F11 -> 36514.854 | G29: =G11 -> 2190.8912
D30: Electricity | E30: kwh | F30: =F19 -> 15936 | G30: =G19 -> 6852.48
D31: Gas | E31: m3 | F31: =F22 -> 119.8 | G31: =G23 -> 1108.15
F32: Total cost | G32: =SUM(G28:G31) -> 14468.655

Sheet 4
A1: ENGINEERING DEPARTMENT | H1: daily reading
A2: UTILITY CONSUMPTION SHEET
B3: ='1'!B3 -> JANUARY 2024 | C3: 4 | D3: % OCCUPANCY: | E3: ='Daily Meter'!O9 -> 53.69
A4: SR.NO | B4: ITEM MEASURED | D4: Previous Reading | E4: 4 AM Reading | F4: 24hrs CONSUMPTION | G4: Cost
A6: 1 | B6: DISTRICT COOLING PLANT
B7: Chilled Water | C7: MWH | D7: ='3'!E7 -> 53528.8 | E7: ='Daily Meter'!B9 -> 53551.3 | F7: =E7-D7 -> 22.5
C8: TR | F8: =F7*284.34 -> 6397.65 | G8: =F8*0.63 -> 4030.5195
A9: III | B9: WATER METERS
B10: Main DEWA Meter | C10: m3 | D10: ='3'!E10 -> 204020 | E10: ='Daily Meter'!C9 -> 204191 | F10: =E10-D10 -> 171
B11: Imperial Gallon = m³ x 219.969 | C11: IG | F11: =F10*219.969 -> 37614.699 | G11: =F11*0.06 -> 2256.8819
A12: IV | B12: ELECTRICAL METERS
A13: 1 | B13: Meter 1 - 06065253 | C13: kW x 480 | D13: ='3'!E13 -> 6580.4 | E13: ='Daily Meter'!H9 -> 6587 | F13: =(E13-D13)*480 -> 3168
A14: 2 | B14: Meter 2 - 06065255 | C14: kW x 480 | D14: ='3'!E14 -> 3977.7 | E14: ='Daily Meter'!I9 -> 3981.4 | F14: =(E14-D14)*480 -> 1776
A15: 3 | B15: Meter 3 - 06065259 | C15: kW x 480 | D15: ='3'!E15 -> 4242.1 | E15: ='Daily Meter'!J9 -> 4246.5 | F15: =(E15-D15)*480 -> 2112
A16: 4 | B16: Meter 4 - 06065262 | C16: kW x 480 | D16: ='3'!E16 -> 2367.1 | E16: ='Daily Meter'!K9 -> 2369.7 | F16: =(E16-D16)*480 -> 1248
A17: 5 | B17: Meter 6 - 06065269 | C17: kW x 480 | D17: ='3'!E17 -> 5582.6 | E17: ='Daily Meter'!L9 -> 5587.1 | F17: =(E17-D17)*480 -> 2160
A18: 6 | B18: Meter 7 - 06065283 | C18: kW x 480 | D18: ='3'!E18 -> 15045.3 | E18: ='Daily Meter'!M9 -> 15055.6 | F18: =(E18-D18)*480 -> 4944
B19: TOTAL ELECTRICAL CONS.(kWh) | F19: =SUM(F13:F18) -> 15408 | G19: =F19*0.43 -> 6625.44
A21: V | B21: GAS CONSUMPTION
A22: 1 | B22: MAIN LPG METER | C22: M3 | D22: ='3'!E22 -> 90385.8 | E22: ='Daily Meter'!N9 -> 90508.7 | F22: =E22-D22 -> 122.9
B23: L = m³ x 3.70 | C23: L | F23: =F22*3.7 -> 454.73 | G23: =F23*2.5 -> 1136.825
D26: Summary of Daily Hotel consumption
D27: Item measured | E27: Units | F27: Consumption | G27: AED
D28: Chilled water | E28: TR | F28: =F8 -> 6397.65 | G28: =G8 -> 4030.5195
D29: DEWA Water | E29: imp. Gallon | F29: =F11 -> 37614.699 | G29: =G11 -> 2256.8819
D30: Electricity | E30: kwh | F30: =F19 -> 15408 | G30: =G19 -> 6625.44
D31: Gas | E31: m3 | F31: =F22 -> 122.9 | G31: =G23 -> 1136.825
F32: Total cost | G32: =SUM(G28:G31) -> 14049.666

Sheet 5
A1: ENGINEERING DEPARTMENT | H1: daily reading
A2: UTILITY CONSUMPTION SHEET
B3: ='1'!B3 -> JANUARY 2024 | C3: 5 | D3: % OCCUPANCY: | E3: ='Daily Meter'!O10 -> 52.53
A4: SR.NO | B4: ITEM MEASURED | D4: Previous Reading | E4: 4 AM Reading | F4: 24hrs CONSUMPTION | G4: Cost
A6: 1 | B6: DISTRICT COOLING PLANT
B7: Chilled Water | C7: MWH | D7: ='4'!E7 -> 53551.3 | E7: ='Daily Meter'!B10 -> 53573.8 | F7: =E7-D7 -> 22.5
C8: TR | F8: =F7*284.34 -> 6397.65 | G8: =F8*0.63 -> 4030.5195
A9: III | B9: WATER METERS
B10: Main DEWA Meter | C10: m3 | D10: ='4'!E10 -> 204191 | E10: ='Daily Meter'!C10 -> 204310 | F10: =E10-D10 -> 119
B11: Imperial Gallon = m³ x 219.969 | C11: IG | F11: =F10*219.969 -> 26176.311 | G11: =F11*0.06 -> 1570.5787
A12: IV | B12: ELECTRICAL METERS
A13: 1 | B13: Meter 1 - 06065253 | C13: kW x 480 | D13: ='4'!E13 -> 6587 | E13: ='Daily Meter'!H10 -> 6593.6 | F13: =(E13-D13)*480 -> 3168
A14: 2 | B14: Meter 2 - 06065255 | C14: kW x 480 | D14: ='4'!E14 -> 3981.4 | E14: ='Daily Meter'!I10 -> 3985.1 | F14: =(E14-D14)*480 -> 1776
A15: 3 | B15: Meter 3 - 06065259 | C15: kW x 480 | D15: ='4'!E15 -> 4246.5 | E15: ='Daily Meter'!J10 -> 4251 | F15: =(E15-D15)*480 -> 2160
A16: 4 | B16: Meter 4 - 06065262 | C16: kW x 480 | D16: ='4'!E16 -> 2369.7 | E16: ='Daily Meter'!K10 -> 2372.3 | F16: =(E16-D16)*480 -> 1248
A17: 5 | B17: Meter 6 - 06065269 | C17: kW x 480 | D17: ='4'!E17 -> 5587.1 | E17: ='Daily Meter'!L10 -> 5591.5 | F17: =(E17-D17)*480 -> 2112
A18: 6 | B18: Meter 7 - 06065283 | C18: kW x 480 | D18: ='4'!E18 -> 15055.6 | E18: ='Daily Meter'!M10 -> 15066.2 | F18: =(E18-D18)*480 -> 5088
B19: TOTAL ELECTRICAL CONS.(kWh) | F19: =SUM(F13:F18) -> 15552 | G19: =F19*0.43 -> 6687.36
A21: V | B21: GAS CONSUMPTION
A22: 1 | B22: MAIN LPG METER | C22: M3 | D22: ='4'!E22 -> 90508.7 | E22: ='Daily Meter'!N10 -> 90630.9 | F22: =E22-D22 -> 122.2
B23: L = m³ x 3.70 | C23: L | F23: =F22*3.7 -> 452.14 | G23: =F23*2.5 -> 1130.35
D26: Summary of Daily Hotel consumption
D27: Item measured | E27: Units | F27: Consumption | G27: AED
D28: Chilled water | E28: TR | F28: =F8 -> 6397.65 | G28: =G8 -> 4030.5195
D29: DEWA Water | E29: imp. Gallon | F29: =F11 -> 26176.311 | G29: =G11 -> 1570.5787
D30: Electricity | E30: kwh | F30: =F19 -> 15552 | G30: =G19 -> 6687.36
D31: Gas | E31: m3 | F31: =F22 -> 122.2 | G31: =G23 -> 1130.35
F32: Total cost | G32: =SUM(G28:G31) -> 13418.808

Sheet 6
A1: ENGINEERING DEPARTMENT | H1: daily reading
A2: UTILITY CONSUMPTION SHEET
B3: ='1'!B3 -> JANUARY 2024 | C3: 6 | D3: % OCCUPANCY: | E3: ='Daily Meter'!O11 -> 49.31
A4: SR.NO | B4: ITEM MEASURED | D4: Previous Reading | E4: 4 AM Reading | F4: 24hrs CONSUMPTION | G4: Cost
A6: 1 | B6: DISTRICT COOLING PLANT
B7: Chilled Water | C7: MWH | D7: ='5'!E7 -> 53573.8 | E7: ='Daily Meter'!B11 -> 53595 | F7: =E7-D7 -> 21.2
C8: TR | F8: =F7*284.34 -> 6028.008 | G8: =F8*0.63 -> 3797.645
A9: III | B9: WATER METERS
B10: Main DEWA Meter | C10: m3 | D10: ='5'!E10 -> 204310 | E10: ='Daily Meter'!C11 -> 204530 | F10: =E10-D10 -> 220
B11: Imperial Gallon = m³ x 219.969 | C11: IG | F11: =F10*219.969 -> 48393.18 | G11: =F11*0.06 -> 2903.5908
A12: IV | B12: ELECTRICAL METERS
A13: 1 | B13: Meter 1 - 06065253 | C13: kW x 480 | D13: ='5'!E13 -> 6593.6 | E13: ='Daily Meter'!H11 -> 6600.3 | F13: =(E13-D13)*480 -> 3216
A14: 2 | B14: Meter 2 - 06065255 | C14: kW x 480 | D14: ='5'!E14 -> 3985.1 | E14: ='Daily Meter'!I11 -> 3988.8 | F14: =(E14-D14)*480 -> 1776
A15: 3 | B15: Meter 3 - 06065259 | C15: kW x 480 | D15: ='5'!E15 -> 4251 | E15: ='Daily Meter'!J11 -> 4255.5 | F15: =(E15-D15)*480 -> 2160
A16: 4 | B16: Meter 4 - 06065262 | C16: kW x 480 | D16: ='5'!E16 -> 2372.3 | E16: ='Daily Meter'!K11 -> 2374.9 | F16: =(E16-D16)*480 -> 1248
A17: 5 | B17: Meter 6 - 06065269 | C17: kW x 480 | D17: ='5'!E17 -> 5591.5 | E17: ='Daily Meter'!L11 -> 5595.9 | F17: =(E17-D17)*480 -> 2112
A18: 6 | B18: Meter 7 - 06065283 | C18: kW x 480 | D18: ='5'!E18 -> 15066.2 | E18: ='Daily Meter'!M11 -> 15077.2 | F18: =(E18-D18)*480 -> 5280
B19: TOTAL ELECTRICAL CONS.(kWh) | F19: =SUM(F13:F18) -> 15792 | G19: =F19*0.43 -> 6790.56
A21: V | B21: GAS CONSUMPTION
A22: 1 | B22: MAIN LPG METER | C22: M3 | D22: ='5'!E22 -> 90630.9 | E22: ='Daily Meter'!N11 -> 90753.1 | F22: =E22-D22 -> 122.2
B23: L = m³ x 3.70 | C23: L | F23: =F22*3.7 -> 452.14 | G23: =F23*2.5 -> 1130.35
D26: Summary of Daily Hotel consumption
D27: Item measured | E27: Units | F27: Consumption | G27: AED
D28: Chilled water | E28: TR | F28: =F8 -> 6028.008 | G28: =G8 -> 3797.645
D29: DEWA Water | E29: imp. Gallon | F29: =F11 -> 48393.18 | G29: =G11 -> 2903.5908
D30: Electricity | E30: kwh | F30: =F19 -> 15792 | G30: =G19 -> 6790.56
D31: Gas | E31: m3 | F31: =F22 -> 122.2 | G31: =G23 -> 1130.35
F32: Total cost | G32: =SUM(G28:G31) -> 14622.146

Sheet 7
A1: ENGINEERING DEPARTMENT | H1: daily reading
A2: UTILITY CONSUMPTION SHEET
B3: ='1'!B3 -> JANUARY 2024 | C3: 7 | D3: % OCCUPANCY: | E3: ='Daily Meter'!O12 -> 39.63
A4: SR.NO | B4: ITEM MEASURED | D4: Previous Reading | E4: 4 AM Reading | F4: 24hrs CONSUMPTION | G4: Cost
A6: 1 | B6: DISTRICT COOLING PLANT
B7: Chilled Water | C7: MWH | D7: ='6'!E7 -> 53595 | E7: ='Daily Meter'!B12 -> 53616.2 | F7: =E7-D7 -> 21.2
C8: TR | F8: =F7*284.34 -> 6028.008 | G8: =F8*0.63 -> 3797.645
A9: III | B9: WATER METERS
B10: Main DEWA Meter | C10: m3 | D10: ='6'!E10 -> 204530 | E10: ='Daily Meter'!C12 -> 204766 | F10: =E10-D10 -> 236
B11: Imperial Gallon = m³ x 219.969 | C11: IG | F11: =F10*219.969 -> 51912.684 | G11: =F11*0.06 -> 3114.761
A12: IV | B12: ELECTRICAL METERS
A13: 1 | B13: Meter 1 - 06065253 | C13: kW x 480 | D13: ='6'!E13 -> 6600.3 | E13: ='Daily Meter'!H12 -> 6607 | F13: =(E13-D13)*480 -> 3216
A14: 2 | B14: Meter 2 - 06065255 | C14: kW x 480 | D14: ='6'!E14 -> 3988.8 | E14: ='Daily Meter'!I12 -> 3992.4 | F14: =(E14-D14)*480 -> 1728
A15: 3 | B15: Meter 3 - 06065259 | C15: kW x 480 | D15: ='6'!E15 -> 4255.5 | E15: ='Daily Meter'!J12 -> 4260.2 | F15: =(E15-D15)*480 -> 2256
A16: 4 | B16: Meter 4 - 06065262 | C16: kW x 480 | D16: ='6'!E16 -> 2374.9 | E16: ='Daily Meter'!K12 -> 2377.9 | F16: =(E16-D16)*480 -> 1440
A17: 5 | B17: Meter 6 - 06065269 | C17: kW x 480 | D17: ='6'!E17 -> 5595.9 | E17: ='Daily Meter'!L12 -> 5600.4 | F17: =(E17-D17)*480 -> 2160
A18: 6 | B18: Meter 7 - 06065283 | C18: kW x 480 | D18: ='6'!E18 -> 15077.2 | E18: ='Daily Meter'!M12 -> 15089 | F18: =(E18-D18)*480 -> 5664
B19: TOTAL ELECTRICAL CONS.(kWh) | F19: =SUM(F13:F18) -> 16464 | G19: =F19*0.43 -> 7079.52
A21: V | B21: GAS CONSUMPTION
A22: 1 | B22: MAIN LPG METER | C22: M3 | D22: ='6'!E22 -> 90753.1 | E22: ='Daily Meter'!N12 -> 90872.5 | F22: =E22-D22 -> 119.4
B23: L = m³ x 3.70 | C23: L | F23: =F22*3.7 -> 441.78 | G23: =F23*2.5 -> 1104.45
D26: Summary of Daily Hotel consumption
D27: Item measured | E27: Units | F27: Consumption | G27: AED
D28: Chilled water | E28: TR | F28: =F8 -> 6028.008 | G28: =G8 -> 3797.645
D29: DEWA Water | E29: imp. Gallon | F29: =F11 -> 51912.684 | G29: =G11 -> 3114.761
D30: Electricity | E30: kwh | F30: =F19 -> 16464 | G30: =G19 -> 7079.52
D31: Gas | E31: m3 | F31: =F22 -> 119.4 | G31: =G23 -> 1104.45
F32: Total cost | G32: =SUM(G28:G31) -> 15096.376

Sheet 8
A1: ENGINEERING DEPARTMENT | H1: daily reading
A2: UTILITY CONSUMPTION SHEET
B3: ='1'!B3 -> JANUARY 2024 | C3: 8 | D3: % OCCUPANCY: | E3: ='Daily Meter'!O13 -> 70.97
A4: SR.NO | B4: ITEM MEASURED | D4: Previous Reading | E4: 4 AM Reading | F4: 24hrs CONSUMPTION | G4: Cost
A6: 1 | B6: DISTRICT COOLING PLANT
B7: Chilled Water | C7: MWH | D7: ='7'!E7 -> 53616.2 | E7: ='Daily Meter'!B13 -> 53635.2 | F7: =E7-D7 -> 19
C8: TR | F8: =F7*284.34 -> 5402.46 | G8: =F8*0.63 -> 3403.5498
A9: III | B9: WATER METERS
B10: Main DEWA Meter | C10: m3 | D10: ='7'!E10 -> 204766 | E10: ='Daily Meter'!C13 -> 204928 | F10: =E10-D10 -> 162
B11: Imperial Gallon = m³ x 219.969 | C11: IG | F11: =F10*219.969 -> 35634.978 | G11: =F11*0.06 -> 2138.0987
A12: IV | B12: ELECTRICAL METERS
A13: 1 | B13: Meter 1 - 06065253 | C13: kW x 480 | D13: ='7'!E13 -> 6607 | E13: ='Daily Meter'!H13 -> 6613.7 | F13: =(E13-D13)*480 -> 3216
A14: 2 | B14: Meter 2 - 06065255 | C14: kW x 480 | D14: ='7'!E14 -> 3992.4 | E14: ='Daily Meter'!I13 -> 3995.9 | F14: =(E14-D14)*480 -> 1680
A15: 3 | B15: Meter 3 - 06065259 | C15: kW x 480 | D15: ='7'!E15 -> 4260.2 | E15: ='Daily Meter'!J13 -> 4264.8 | F15: =(E15-D15)*480 -> 2208
A16: 4 | B16: Meter 4 - 06065262 | C16: kW x 480 | D16: ='7'!E16 -> 2377.9 | E16: ='Daily Meter'!K13 -> 2380.4 | F16: =(E16-D16)*480 -> 1200
A17: 5 | B17: Meter 6 - 06065269 | C17: kW x 480 | D17: ='7'!E17 -> 5600.4 | E17: ='Daily Meter'!L13 -> 5604.7 | F17: =(E17-D17)*480 -> 2064
A18: 6 | B18: Meter 7 - 06065283 | C18: kW x 480 | D18: ='7'!E18 -> 15089 | E18: ='Daily Meter'!M13 -> 15100.2 | F18: =(E18-D18)*480 -> 5376
B19: TOTAL ELECTRICAL CONS.(kWh) | F19: =SUM(F13:F18) -> 15744 | G19: =F19*0.43 -> 6769.92
A21: V | B21: GAS CONSUMPTION
A22: 1 | B22: MAIN LPG METER | C22: M3 | D22: ='7'!E22 -> 90872.5 | E22: ='Daily Meter'!N13 -> 90985.8 | F22: =E22-D22 -> 113.3
B23: L = m³ x 3.70 | C23: L | F23: =F22*3.7 -> 419.21 | G23: =F23*2.5 -> 1048.025
D26: Summary of Daily Hotel consumption
D27: Item measured | E27: Units | F27: Consumption | G27: AED
D28: Chilled water | E28: TR | F28: =F8 -> 5402.46 | G28: =G8 -> 3403.5498
D29: DEWA Water | E29: imp. Gallon | F29: =F11 -> 35634.978 | G29: =G11 -> 2138.0987
D30: Electricity | E30: kwh | F30: =F19 -> 15744 | G30: =G19 -> 6769.92
D31: Gas | E31: m3 | F31: =F22 -> 113.3 | G31: =G23 -> 1048.025
F32: Total cost | G32: =SUM(G28:G31) -> 13359.593

Sheet 9
A1: ENGINEERING DEPARTMENT | H1: daily reading
A2: UTILITY CONSUMPTION SHEET
B3: ='1'!B3 -> JANUARY 2024 | C3: 9 | D3: % OCCUPANCY: | E3: ='Daily Meter'!O14 -> 79.26
A4: SR.NO | B4: ITEM MEASURED | D4: Previous Reading | E4: 4 AM Reading | F4: 24hrs CONSUMPTION | G4: Cost
A6: 1 | B6: DISTRICT COOLING PLANT
B7: Chilled Water | C7: MWH | D7: ='8'!E7 -> 53635.2 | E7: ='Daily Meter'!B14 -> 53656 | F7: =E7-D7 -> 20.8
C8: TR | F8: =F7*284.34 -> 5914.272 | G8: =F8*0.63 -> 3725.9914
A9: III | B9: WATER METERS
B10: Main DEWA Meter | C10: m3 | D10: ='8'!E10 -> 204928 | E10: ='Daily Meter'!C14 -> 205059 | F10: =E10-D10 -> 131
B11: Imperial Gallon = m³ x 219.969 | C11: IG | F11: =F10*219.969 -> 28815.939 | G11: =F11*0.06 -> 1728.9563
A12: IV | B12: ELECTRICAL METERS
A13: 1 | B13: Meter 1 - 06065253 | C13: kW x 480 | D13: ='8'!E13 -> 6613.7 | E13: ='Daily Meter'!H14 -> 6620.5 | F13: =(E13-D13)*480 -> 3264
A14: 2 | B14: Meter 2 - 06065255 | C14: kW x 480 | D14: ='8'!E14 -> 3995.9 | E14: ='Daily Meter'!I14 -> 3999.6 | F14: =(E14-D14)*480 -> 1776
A15: 3 | B15: Meter 3 - 06065259 | C15: kW x 480 | D15: ='8'!E15 -> 4264.8 | E15: ='Daily Meter'!J14 -> 4269.4 | F15: =(E15-D15)*480 -> 2208
A16: 4 | B16: Meter 4 - 06065262 | C16: kW x 480 | D16: ='8'!E16 -> 2380.4 | E16: ='Daily Meter'!K14 -> 2383.1 | F16: =(E16-D16)*480 -> 1296
A17: 5 | B17: Meter 6 - 06065269 | C17: kW x 480 | D17: ='8'!E17 -> 5604.7 | E17: ='Daily Meter'!L14 -> 5609.1 | F17: =(E17-D17)*480 -> 2112
A18: 6 | B18: Meter 7 - 06065283 | C18: kW x 480 | D18: ='8'!E18 -> 15100.2 | E18: ='Daily Meter'!M14 -> 15111.3 | F18: =(E18-D18)*480 -> 5328
B19: TOTAL ELECTRICAL CONS.(kWh) | F19: =SUM(F13:F18) -> 15984 | G19: =F19*0.43 -> 6873.12
A21: V | B21: GAS CONSUMPTION
A22: 1 | B22: MAIN LPG METER | C22: M3 | D22: ='8'!E22 -> 90985.8 | E22: ='Daily Meter'!N14 -> 91106 | F22: =E22-D22 -> 120.2
B23: L = m³ x 3.70 | C23: L | F23: =F22*3.7 -> 444.74 | G23: =F23*2.5 -> 1111.85
D26: Summary of Daily Hotel consumption
D27: Item measured | E27: Units | F27: Consumption | G27: AED
D28: Chilled water | E28: TR | F28: =F8 -> 5914.272 | G28: =G8 -> 3725.9914
D29: DEWA Water | E29: imp. Gallon | F29: =F11 -> 28815.939 | G29: =G11 -> 1728.9563
D30: Electricity | E30: kwh | F30: =F19 -> 15984 | G30: =G19 -> 6873.12
D31: Gas | E31: m3 | F31: =F22 -> 120.2 | G31: =G23 -> 1111.85
F32: Total cost | G32: =SUM(G28:G31) -> 13439.918

Sheet 10
A1: ENGINEERING DEPARTMENT | H1: daily reading
A2: UTILITY CONSUMPTION SHEET
B3: ='1'!B3 -> JANUARY 2024 | C3: 10 | D3: % OCCUPANCY: | E3: ='Daily Meter'!O15 -> 86.67
A4: SR.NO | B4: ITEM MEASURED | D4: Previous Reading | E4: 4 AM Reading | F4: 24hrs CONSUMPTION | G4: Cost
A6: 1 | B6: DISTRICT COOLING PLANT
B7: Chilled Water | C7: MWH | D7: ='9'!E7 -> 53656 | E7: ='Daily Meter'!B15 -> 53676.9 | F7: =E7-D7 -> 20.9
C8: TR | F8: =F7*284.34 -> 5942.706 | G8: =F8*0.63 -> 3743.9048
A9: III | B9: WATER METERS
B10: Main DEWA Meter | C10: m3 | D10: ='9'!E10 -> 205059 | E10: ='Daily Meter'!C15 -> 205282 | F10: =E10-D10 -> 223
B11: Imperial Gallon = m³ x 219.969 | C11: IG | F11: =F10*219.969 -> 49053.087 | G11: =F11*0.06 -> 2943.1852
A12: IV | B12: ELECTRICAL METERS
A13: 1 | B13: Meter 1 - 06065253 | C13: kW x 480 | D13: ='9'!E13 -> 6620.5 | E13: ='Daily Meter'!H15 -> 6627.3 | F13: =(E13-D13)*480 -> 3264
A14: 2 | B14: Meter 2 - 06065255 | C14: kW x 480 | D14: ='9'!E14 -> 3999.6 | E14: ='Daily Meter'!I15 -> 4003.7 | F14: =(E14-D14)*480 -> 1968
A15: 3 | B15: Meter 3 - 06065259 | C15: kW x 480 | D15: ='9'!E15 -> 4269.4 | E15: ='Daily Meter'!J15 -> 4274.1 | F15: =(E15-D15)*480 -> 2256
A16: 4 | B16: Meter 4 - 06065262 | C16: kW x 480 | D16: ='9'!E16 -> 2383.1 | E16: ='Daily Meter'!K15 -> 2385.9 | F16: =(E16-D16)*480 -> 1344
A17: 5 | B17: Meter 6 - 06065269 | C17: kW x 480 | D17: ='9'!E17 -> 5609.1 | E17: ='Daily Meter'!L15 -> 5613.5 | F17: =(E17-D17)*480 -> 2112
A18: 6 | B18: Meter 7 - 06065283 | C18: kW x 480 | D18: ='9'!E18 -> 15111.3 | E18: ='Daily Meter'!M15 -> 15122.2 | F18: =(E18-D18)*480 -> 5232
B19: TOTAL ELECTRICAL CONS.(kWh) | F19: =SUM(F13:F18) -> 16176 | G19: =F19*0.43 -> 6955.68
A21: V | B21: GAS CONSUMPTION
A22: 1 | B22: MAIN LPG METER | C22: M3 | D22: ='9'!E22 -> 91106 | E22: ='Daily Meter'!N15 -> 91234 | F22: =E22-D22 -> 128
B23: L = m³ x 3.70 | C23: L | F23: =F22*3.7 -> 473.6 | G23: =F23*2.5 -> 1184
D26: Summary of Daily Hotel consumption
D27: Item measured | E27: Units | F27: Consumption | G27: AED
D28: Chilled water | E28: TR | F28: =F8 -> 5942.706 | G28: =G8 -> 3743.9048
D29: DEWA Water | E29: imp. Gallon | F29: =F11 -> 49053.087 | G29: =G11 -> 2943.1852
D30: Electricity | E30: kwh | F30: =F19 -> 16176 | G30: =G19 -> 6955.68
D31: Gas | E31: m3 | F31: =F22 -> 128 | G31: =G23 -> 1184
F32: Total cost | G32: =SUM(G28:G31) -> 14826.77

Sheet 11
A1: ENGINEERING DEPARTMENT | H1: daily reading
A2: UTILITY CONSUMPTION SHEET
B3: ='1'!B3 -> JANUARY 2024 | C3: 11 | D3: % OCCUPANCY: | E3: ='Daily Meter'!O16 -> 69.82
A4: SR.NO | B4: ITEM MEASURED | D4: Previous Reading | E4: 4 AM Reading | F4: 24hrs CONSUMPTION | G4: Cost
A6: 1 | B6: DISTRICT COOLING PLANT
B7: Chilled Water | C7: MWH | D7: ='10'!E7 -> 53676.9 | E7: ='Daily Meter'!B16 -> 53697.4 | F7: =E7-D7 -> 20.5
C8: TR | F8: =F7*284.34 -> 5828.97 | G8: =F8*0.63 -> 3672.2511
A9: III | B9: WATER METERS
B10: Main DEWA Meter | C10: m3 | D10: ='10'!E10 -> 205282 | E10: ='Daily Meter'!C16 -> 205368 | F10: =E10-D10 -> 86
B11: Imperial Gallon = m³ x 219.969 | C11: IG | F11: =F10*219.969 -> 18917.334 | G11: =F11*0.06 -> 1135.04
A12: IV | B12: ELECTRICAL METERS
A13: 1 | B13: Meter 1 - 06065253 | C13: kW x 480 | D13: ='10'!E13 -> 6627.3 | E13: ='Daily Meter'!H16 -> 6634.1 | F13: =(E13-D13)*480 -> 3264
A14: 2 | B14: Meter 2 - 06065255 | C14: kW x 480 | D14: ='10'!E14 -> 4003.7 | E14: ='Daily Meter'!I16 -> 4007.7 | F14: =(E14-D14)*480 -> 1920
A15: 3 | B15: Meter 3 - 06065259 | C15: kW x 480 | D15: ='10'!E15 -> 4274.1 | E15: ='Daily Meter'!J16 -> 4278.7 | F15: =(E15-D15)*480 -> 2208
A16: 4 | B16: Meter 4 - 06065262 | C16: kW x 480 | D16: ='10'!E16 -> 2385.9 | E16: ='Daily Meter'!K16 -> 2388.6 | F16: =(E16-D16)*480 -> 1296
A17: 5 | B17: Meter 6 - 06065269 | C17: kW x 480 | D17: ='10'!E17 -> 5613.5 | E17: ='Daily Meter'!L16 -> 5618 | F17: =(E17-D17)*480 -> 2160
A18: 6 | B18: Meter 7 - 06065283 | C18: kW x 480 | D18: ='10'!E18 -> 15122.2 | E18: ='Daily Meter'!M16 -> 15133.3 | F18: =(E18-D18)*480 -> 5328
B19: TOTAL ELECTRICAL CONS.(kWh) | F19: =SUM(F13:F18) -> 16176 | G19: =F19*0.43 -> 6955.68
A21: V | B21: GAS CONSUMPTION
A22: 1 | B22: MAIN LPG METER | C22: M3 | D22: ='10'!E22 -> 91234 | E22: ='Daily Meter'!N16 -> 91341.5 | F22: =E22-D22 -> 107.5
B23: L = m³ x 3.70 | C23: L | F23: =F22*3.7 -> 397.75 | G23: =F23*2.5 -> 994.375
D26: Summary of Daily Hotel consumption
D27: Item measured | E27: Units | F27: Consumption | G27: AED
D28: Chilled water | E28: TR | F28: =F8 -> 5828.97 | G28: =G8 -> 3672.2511
D29: DEWA Water | E29: imp. Gallon | F29: =F11 -> 18917.334 | G29: =G11 -> 1135.04
D30: Electricity | E30: kwh | F30: =F19 -> 16176 | G30: =G19 -> 6955.68
D31: Gas | E31: m3 | F31: =F22 -> 107.5 | G31: =G23 -> 994.375
F32: Total cost | G32: =SUM(G28:G31) -> 12757.346

Sheet 12
A1: ENGINEERING DEPARTMENT | H1: daily reading
A2: UTILITY CONSUMPTION SHEET
B3: ='1'!B3 -> JANUARY 2024 | C3: 12 | D3: % OCCUPANCY: | E3: ='Daily Meter'!O17 -> 55.99
A4: SR.NO | B4: ITEM MEASURED | D4: Previous Reading | E4: 4 AM Reading | F4: 24hrs CONSUMPTION | G4: Cost
A6: 1 | B6: DISTRICT COOLING PLANT
B7: Chilled Water | C7: MWH | D7: ='11'!E7 -> 53697.4 | E7: ='Daily Meter'!B17 -> 53716.2 | F7: =E7-D7 -> 18.8
C8: TR | F8: =F7*284.34 -> 5345.592 | G8: =F8*0.63 -> 3367.723
A9: III | B9: WATER METERS
B10: Main DEWA Meter | C10: m3 | D10: ='11'!E10 -> 205368 | E10: ='Daily Meter'!C17 -> 205672 | F10: =E10-D10 -> 304
B11: Imperial Gallon = m³ x 219.969 | C11: IG | F11: =F10*219.969 -> 66870.576 | G11: =F11*0.06 -> 4012.2346
A12: IV | B12: ELECTRICAL METERS
A13: 1 | B13: Meter 1 - 06065253 | C13: kW x 480 | D13: ='11'!E13 -> 6634.1 | E13: ='Daily Meter'!H17 -> 6641.2 | F13: =(E13-D13)*480 -> 3408
A14: 2 | B14: Meter 2 - 06065255 | C14: kW x 480 | D14: ='11'!E14 -> 4007.7 | E14: ='Daily Meter'!I17 -> 4011.6 | F14: =(E14-D14)*480 -> 1872
A15: 3 | B15: Meter 3 - 06065259 | C15: kW x 480 | D15: ='11'!E15 -> 4278.7 | E15: ='Daily Meter'!J17 -> 4283.5 | F15: =(E15-D15)*480 -> 2304
A16: 4 | B16: Meter 4 - 06065262 | C16: kW x 480 | D16: ='11'!E16 -> 2388.6 | E16: ='Daily Meter'!K17 -> 2391.4 | F16: =(E16-D16)*480 -> 1344
A17: 5 | B17: Meter 6 - 06065269 | C17: kW x 480 | D17: ='11'!E17 -> 5618 | E17: ='Daily Meter'!L17 -> 5622.5 | F17: =(E17-D17)*480 -> 2160
A18: 6 | B18: Meter 7 - 06065283 | C18: kW x 480 | D18: ='11'!E18 -> 15133.3 | E18: ='Daily Meter'!M17 -> 15144.6 | F18: =(E18-D18)*480 -> 5424
B19: TOTAL ELECTRICAL CONS.(kWh) | F19: =SUM(F13:F18) -> 16512 | G19: =F19*0.43 -> 7100.16
A21: V | B21: GAS CONSUMPTION
A22: 1 | B22: MAIN LPG METER | C22: M3 | D22: ='11'!E22 -> 91341.5 | E22: ='Daily Meter'!N17 -> 91517.7 | F22: =E22-D22 -> 176.2
B23: L = m³ x 3.70 | C23: L | F23: =F22*3.7 -> 651.94 | G23: =F23*2.5 -> 1629.85
D26: Summary of Daily Hotel consumption
D27: Item measured | E27: Units | F27: Consumption | G27: AED
D28: Chilled water | E28: TR | F28: =F8 -> 5345.592 | G28: =G8 -> 3367.723
D29: DEWA Water | E29: imp. Gallon | F29: =F11 -> 66870.576 | G29: =G11 -> 4012.2346
D30: Electricity | E30: kwh | F30: =F19 -> 16512 | G30: =G19 -> 7100.16
D31: Gas | E31: m3 | F31: =F22 -> 176.2 | G31: =G23 -> 1629.85
F32: Total cost | G32: =SUM(G28:G31) -> 16109.968

Sheet 13
A1: ENGINEERING DEPARTMENT | H1: daily reading
A2: UTILITY CONSUMPTION SHEET
B3: ='1'!B3 -> JANUARY 2024 | C3: 13 | D3: % OCCUPANCY: | E3: ='Daily Meter'!O18 -> 44.24
A4: SR.NO | B4: ITEM MEASURED | D4: Previous Reading | E4: 4 AM Reading | F4: 24hrs CONSUMPTION | G4: Cost
A6: 1 | B6: DISTRICT COOLING PLANT
B7: Chilled Water | C7: MWH | D7: ='12'!E7 -> 53716.2 | E7: ='Daily Meter'!B18 -> 53734.8 | F7: =E7-D7 -> 18.6
C8: TR | F8: =F7*284.34 -> 5288.724 | G8: =F8*0.63 -> 3331.8961
A9: III | B9: WATER METERS
B10: Main DEWA Meter | C10: m3 | D10: ='12'!E10 -> 205672 | E10: ='Daily Meter'!C18 -> 205925 | F10: =E10-D10 -> 253
B11: Imperial Gallon = m³ x 219.969 | C11: IG | F11: =F10*219.969 -> 55652.157 | G11: =F11*0.06 -> 3339.1294
A12: IV | B12: ELECTRICAL METERS
A13: 1 | B13: Meter 1 - 06065253 | C13: kW x 480 | D13: ='12'!E13 -> 6641.2 | E13: ='Daily Meter'!H18 -> 6648.4 | F13: =(E13-D13)*480 -> 3456
A14: 2 | B14: Meter 2 - 06065255 | C14: kW x 480 | D14: ='12'!E14 -> 4011.6 | E14: ='Daily Meter'!I18 -> 4015.4 | F14: =(E14-D14)*480 -> 1824
A15: 3 | B15: Meter 3 - 06065259 | C15: kW x 480 | D15: ='12'!E15 -> 4283.5 | E15: ='Daily Meter'!J18 -> 4288.4 | F15: =(E15-D15)*480 -> 2352
A16: 4 | B16: Meter 4 - 06065262 | C16: kW x 480 | D16: ='12'!E16 -> 2391.4 | E16: ='Daily Meter'!K18 -> 2394.2 | F16: =(E16-D16)*480 -> 1344
A17: 5 | B17: Meter 6 - 06065269 | C17: kW x 480 | D17: ='12'!E17 -> 5622.5 | E17: ='Daily Meter'!L18 -> 5627.1 | F17: =(E17-D17)*480 -> 2208
A18: 6 | B18: Meter 7 - 06065283 | C18: kW x 480 | D18: ='12'!E18 -> 15144.6 | E18: ='Daily Meter'!M18 -> 15156 | F18: =(E18-D18)*480 -> 5472
B19: TOTAL ELECTRICAL CONS.(kWh) | F19: =SUM(F13:F18) -> 16656 | G19: =F19*0.43 -> 7162.08
A21: V | B21: GAS CONSUMPTION
A22: 1 | B22: MAIN LPG METER | C22: M3 | D22: ='12'!E22 -> 91517.7 | E22: ='Daily Meter'!N18 -> 91677.1 | F22: =E22-D22 -> 159.4
B23: L = m³ x 3.70 | C23: L | F23: =F22*3.7 -> 589.78 | G23: =F23*2.5 -> 1474.45
D26: Summary of Daily Hotel consumption
D27: Item measured | E27: Units | F27: Consumption | G27: AED
D28: Chilled water | E28: TR | F28: =F8 -> 5288.724 | G28: =G8 -> 3331.8961
D29: DEWA Water | E29: imp. Gallon | F29: =F11 -> 55652.157 | G29: =G11 -> 3339.1294
D30: Electricity | E30: kwh | F30: =F19 -> 16656 | G30: =G19 -> 7162.08
D31: Gas | E31: m3 | F31: =F22 -> 159.4 | G31: =G23 -> 1474.45
F32: Total cost | G32: =SUM(G28:G31) -> 15307.556

Sheet 14
A1: ENGINEERING DEPARTMENT | H1: daily reading
A2: UTILITY CONSUMPTION SHEET
B3: ='1'!B3 -> JANUARY 2024 | C3: 14 | D3: % OCCUPANCY: | E3: ='Daily Meter'!O19 -> 52.07
A4: SR.NO | B4: ITEM MEASURED | D4: Previous Reading | E4: 4 AM Reading | F4: 24hrs CONSUMPTION | G4: Cost
A6: 1 | B6: DISTRICT COOLING PLANT
B7: Chilled Water | C7: MWH | D7: ='13'!E7 -> 53734.8 | E7: ='Daily Meter'!B19 -> 53753.3 | F7: =E7-D7 -> 18.5
C8: TR | F8: =F7*284.34 -> 5260.29 | G8: =F8*0.63 -> 3313.9827
A9: III | B9: WATER METERS
B10: Main DEWA Meter | C10: m3 | D10: ='13'!E10 -> 205925 | E10: ='Daily Meter'!C19 -> 206117 | F10: =E10-D10 -> 192
B11: Imperial Gallon = m³ x 219.969 | C11: IG | F11: =F10*219.969 -> 42234.048 | G11: =F11*0.06 -> 2534.0429
A12: IV | B12: ELECTRICAL METERS
A13: 1 | B13: Meter 1 - 06065253 | C13: kW x 480 | D13: ='13'!E13 -> 6648.4 | E13: ='Daily Meter'!H19 -> 6655.3 | F13: =(E13-D13)*480 -> 3312
A14: 2 | B14: Meter 2 - 06065255 | C14: kW x 480 | D14: ='13'!E14 -> 4015.4 | E14: ='Daily Meter'!I19 -> 4018.9 | F14: =(E14-D14)*480 -> 1680
A15: 3 | B15: Meter 3 - 06065259 | C15: kW x 480 | D15: ='13'!E15 -> 4288.4 | E15: ='Daily Meter'!J19 -> 4293 | F15: =(E15-D15)*480 -> 2208
A16: 4 | B16: Meter 4 - 06065262 | C16: kW x 480 | D16: ='13'!E16 -> 2394.2 | E16: ='Daily Meter'!K19 -> 2396.9 | F16: =(E16-D16)*480 -> 1296
A17: 5 | B17: Meter 6 - 06065269 | C17: kW x 480 | D17: ='13'!E17 -> 5627.1 | E17: ='Daily Meter'!L19 -> 5631.5 | F17: =(E17-D17)*480 -> 2112
A18: 6 | B18: Meter 7 - 06065283 | C18: kW x 480 | D18: ='13'!E18 -> 15156 | E18: ='Daily Meter'!M19 -> 15166.7 | F18: =(E18-D18)*480 -> 5136
B19: TOTAL ELECTRICAL CONS.(kWh) | F19: =SUM(F13:F18) -> 15744 | G19: =F19*0.43 -> 6769.92
A21: V | B21: GAS CONSUMPTION
A22: 1 | B22: MAIN LPG METER | C22: M3 | D22: ='13'!E22 -> 91677.1 | E22: ='Daily Meter'!N19 -> 91814.2 | F22: =E22-D22 -> 137.1
B23: L = m³ x 3.70 | C23: L | F23: =F22*3.7 -> 507.27 | G23: =F23*2.5 -> 1268.175
D26: Summary of Daily Hotel consumption
D27: Item measured | E27: Units | F27: Consumption | G27: AED
D28: Chilled water | E28: TR | F28: =F8 -> 5260.29 | G28: =G8 -> 3313.9827
D29: DEWA Water | E29: imp. Gallon | F29: =F11 -> 42234.048 | G29: =G11 -> 2534.0429
D30: Electricity | E30: kwh | F30: =F19 -> 15744 | G30: =G19 -> 6769.92
D31: Gas | E31: m3 | F31: =F22 -> 137.1 | G31: =G23 -> 1268.175
F32: Total cost | G32: =SUM(G28:G31) -> 13886.121

Sheet 15
A1: ENGINEERING DEPARTMENT | H1: daily reading
A2: UTILITY CONSUMPTION SHEET
B3: ='1'!B3 -> JANUARY 2024 | C3: 15 | D3: % OCCUPANCY: | E3: ='Daily Meter'!O20 -> 82.72
A4: SR.NO | B4: ITEM MEASURED | D4: Previous Reading | E4: 4 AM Reading | F4: 24hrs CONSUMPTION | G4: Cost
A6: 1 | B6: DISTRICT COOLING PLANT
B7: Chilled Water | C7: MWH | D7: ='14'!E7 -> 53753.3 | E7: ='Daily Meter'!B20 -> 53772.3 | F7: =E7-D7 -> 19
C8: TR | F8: =F7*284.34 -> 5402.46 | G8: =F8*0.63 -> 3403.5498
A9: III | B9: WATER METERS
B10: Main DEWA Meter | C10: m3 | D10: ='14'!E10 -> 206117 | E10: ='Daily Meter'!C20 -> 206290 | F10: =E10-D10 -> 173
B11: Imperial Gallon = m³ x 219.969 | C11: IG | F11: =F10*219.969 -> 38054.637 | G11: =F11*0.06 -> 2283.2782
A12: IV | B12: ELECTRICAL METERS
A13: 1 | B13: Meter 1 - 06065253 | C13: kW x 480 | D13: ='14'!E13 -> 6655.3 | E13: ='Daily Meter'!H20 -> 6662 | F13: =(E13-D13)*480 -> 3216
A14: 2 | B14: Meter 2 - 06065255 | C14: kW x 480 | D14: ='14'!E14 -> 4018.9 | E14: ='Daily Meter'!I20 -> 4022.85 | F14: =(E14-D14)*480 -> 1896
A15: 3 | B15: Meter 3 - 06065259 | C15: kW x 480 | D15: ='14'!E15 -> 4293 | E15: ='Daily Meter'!J20 -> 4297.3 | F15: =(E15-D15)*480 -> 2064
A16: 4 | B16: Meter 4 - 06065262 | C16: kW x 480 | D16: ='14'!E16 -> 2396.9 | E16: ='Daily Meter'!K20 -> 2399.5 | F16: =(E16-D16)*480 -> 1248
A17: 5 | B17: Meter 6 - 06065269 | C17: kW x 480 | D17: ='14'!E17 -> 5631.5 | E17: ='Daily Meter'!L20 -> 5635.9 | F17: =(E17-D17)*480 -> 2112
A18: 6 | B18: Meter 7 - 06065283 | C18: kW x 480 | D18: ='14'!E18 -> 15166.7 | E18: ='Daily Meter'!M20 -> 15176.3 | F18: =(E18-D18)*480 -> 4608
B19: TOTAL ELECTRICAL CONS.(kWh) | F19: =SUM(F13:F18) -> 15144 | G19: =F19*0.43 -> 6511.92
A21: V | B21: GAS CONSUMPTION
A22: 1 | B22: MAIN LPG METER | C22: M3 | D22: ='14'!E22 -> 91814.2 | E22: ='Daily Meter'!N20 -> 91928.7 | F22: =E22-D22 -> 114.5
B23: L = m³ x 3.70 | C23: L | F23: =F22*3.7 -> 423.65 | G23: =F23*2.5 -> 1059.125
D26: Summary of Daily Hotel consumption
D27: Item measured | E27: Units | F27: Consumption | G27: AED
D28: Chilled water | E28: TR | F28: =F8 -> 5402.46 | G28: =G8 -> 3403.5498
D29: DEWA Water | E29: imp. Gallon | F29: =F11 -> 38054.637 | G29: =G11 -> 2283.2782
D30: Electricity | E30: kwh | F30: =F19 -> 15144 | G30: =G19 -> 6511.92
D31: Gas | E31: m3 | F31: =F22 -> 114.5 | G31: =G23 -> 1059.125
F32: Total cost | G32: =SUM(G28:G31) -> 13257.873

Sheet 16
A1: ENGINEERING DEPARTMENT | H1: daily reading
A2: UTILITY CONSUMPTION SHEET
B3: ='1'!B3 -> JANUARY 2024 | C3: 16 | D3: % OCCUPANCY: | E3: ='Daily Meter'!O21 -> 98.16
A4: SR.NO | B4: ITEM MEASURED | D4: Previous Reading | E4: 4 AM Reading | F4: 24hrs CONSUMPTION | G4: Cost
A6: 1 | B6: DISTRICT COOLING PLANT
B7: Chilled Water | C7: MWH | D7: ='15'!E7 -> 53772.3 | E7: ='Daily Meter'!B21 -> 53791.7 | F7: =E7-D7 -> 19.4
C8: TR | F8: =F7*284.34 -> 5516.196 | G8: =F8*0.63 -> 3475.2035
A9: III | B9: WATER METERS
B10: Main DEWA Meter | C10: m3 | D10: ='15'!E10 -> 206290 | E10: ='Daily Meter'!C21 -> 206462 | F10: =E10-D10 -> 172
B11: Imperial Gallon = m³ x 219.969 | C11: IG | F11: =F10*219.969 -> 37834.668 | G11: =F11*0.06 -> 2270.0801
A12: IV | B12: ELECTRICAL METERS
A13: 1 | B13: Meter 1 - 06065253 | C13: kW x 480 | D13: ='15'!E13 -> 6662 | E13: ='Daily Meter'!H21 -> 6668.7 | F13: =(E13-D13)*480 -> 3216
A14: 2 | B14: Meter 2 - 06065255 | C14: kW x 480 | D14: ='15'!E14 -> 4022.85 | E14: ='Daily Meter'!I21 -> 4026.3 | F14: =(E14-D14)*480 -> 1656
A15: 3 | B15: Meter 3 - 06065259 | C15: kW x 480 | D15: ='15'!E15 -> 4297.3 | E15: ='Daily Meter'!J21 -> 4301.7 | F15: =(E15-D15)*480 -> 2112
A16: 4 | B16: Meter 4 - 06065262 | C16: kW x 480 | D16: ='15'!E16 -> 2399.5 | E16: ='Daily Meter'!K21 -> 2402.2 | F16: =(E16-D16)*480 -> 1296
A17: 5 | B17: Meter 6 - 06065269 | C17: kW x 480 | D17: ='15'!E17 -> 5635.9 | E17: ='Daily Meter'!L21 -> 5640.4 | F17: =(E17-D17)*480 -> 2160
A18: 6 | B18: Meter 7 - 06065283 | C18: kW x 480 | D18: ='15'!E18 -> 15176.3 | E18: ='Daily Meter'!M21 -> 15185.6 | F18: =(E18-D18)*480 -> 4464
B19: TOTAL ELECTRICAL CONS.(kWh) | F19: =SUM(F13:F18) -> 14904 | G19: =F19*0.43 -> 6408.72
A21: V | B21: GAS CONSUMPTION
A22: 1 | B22: MAIN LPG METER | C22: M3 | D22: ='15'!E22 -> 91928.7 | E22: ='Daily Meter'!N21 -> 92046 | F22: =E22-D22 -> 117.3
B23: L = m³ x 3.70 | C23: L | F23: =F22*3.7 -> 434.01 | G23: =F23*2.5 -> 1085.025
D26: Summary of Daily Hotel consumption
D27: Item measured | E27: Units | F27: Consumption | G27: AED
D28: Chilled water | E28: TR | F28: =F8 -> 5516.196 | G28: =G8 -> 3475.2035
D29: DEWA Water | E29: imp. Gallon | F29: =F11 -> 37834.668 | G29: =G11 -> 2270.0801
D30: Electricity | E30: kwh | F30: =F19 -> 14904 | G30: =G19 -> 6408.72
D31: Gas | E31: m3 | F31: =F22 -> 117.3 | G31: =G23 -> 1085.025
F32: Total cost | G32: =SUM(G28:G31) -> 13239.029

Sheet 17
A1: ENGINEERING DEPARTMENT | H1: daily reading
A2: UTILITY CONSUMPTION SHEET
B3: ='1'!B3 -> JANUARY 2024 | C3: 17 | D3: % OCCUPANCY: | E3: ='Daily Meter'!O22 -> 99.08
A4: SR.NO | B4: ITEM MEASURED | D4: Previous Reading | E4: 4 AM Reading | F4: 24hrs CONSUMPTION | G4: Cost
A6: 1 | B6: DISTRICT COOLING PLANT
B7: Chilled Water | C7: MWH | D7: ='16'!E7 -> 53791.7 | E7: ='Daily Meter'!B22 -> 53814.5 | F7: =E7-D7 -> 22.8
C8: TR | F8: =F7*284.34 -> 6482.952 | G8: =F8*0.63 -> 4084.2598
A9: III | B9: WATER METERS
B10: Main DEWA Meter | C10: m3 | D10: ='16'!E10 -> 206462 | E10: ='Daily Meter'!C22 -> 206662 | F10: =E10-D10 -> 200
B11: Imperial Gallon = m³ x 219.969 | C11: IG | F11: =F10*219.969 -> 43993.8 | G11: =F11*0.06 -> 2639.628
A12: IV | B12: ELECTRICAL METERS
A13: 1 | B13: Meter 1 - 06065253 | C13: kW x 480 | D13: ='16'!E13 -> 6668.7 | E13: ='Daily Meter'!H22 -> 6675.6 | F13: =(E13-D13)*480 -> 3312
A14: 2 | B14: Meter 2 - 06065255 | C14: kW x 480 | D14: ='16'!E14 -> 4026.3 | E14: ='Daily Meter'!I22 -> 4030.3 | F14: =(E14-D14)*480 -> 1920
A15: 3 | B15: Meter 3 - 06065259 | C15: kW x 480 | D15: ='16'!E15 -> 4301.7 | E15: ='Daily Meter'!J22 -> 4305.8 | F15: =(E15-D15)*480 -> 1968
A16: 4 | B16: Meter 4 - 06065262 | C16: kW x 480 | D16: ='16'!E16 -> 2402.2 | E16: ='Daily Meter'!K22 -> 2405.1 | F16: =(E16-D16)*480 -> 1392
A17: 5 | B17: Meter 6 - 06065269 | C17: kW x 480 | D17: ='16'!E17 -> 5640.4 | E17: ='Daily Meter'!L22 -> 5644.9 | F17: =(E17-D17)*480 -> 2160
A18: 6 | B18: Meter 7 - 06065283 | C18: kW x 480 | D18: ='16'!E18 -> 15185.6 | E18: ='Daily Meter'!M22 -> 15194.6 | F18: =(E18-D18)*480 -> 4320
B19: TOTAL ELECTRICAL CONS.(kWh) | F19: =SUM(F13:F18) -> 15072 | G19: =F19*0.43 -> 6480.96
A21: V | B21: GAS CONSUMPTION
A22: 1 | B22: MAIN LPG METER | C22: M3 | D22: ='16'!E22 -> 92046 | E22: ='Daily Meter'!N22 -> 92194.2 | F22: =E22-D22 -> 148.2
B23: L = m³ x 3.70 | C23: L | F23: =F22*3.7 -> 548.34 | G23: =F23*2.5 -> 1370.85
D26: Summary of Daily Hotel consumption
D27: Item measured | E27: Units | F27: Consumption | G27: AED
D28: Chilled water | E28: TR | F28: =F8 -> 6482.952 | G28: =G8 -> 4084.2598
D29: DEWA Water | E29: imp. Gallon | F29: =F11 -> 43993.8 | G29: =G11 -> 2639.628
D30: Electricity | E30: kwh | F30: =F19 -> 15072 | G30: =G19 -> 6480.96
D31: Gas | E31: m3 | F31: =F22 -> 148.2 | G31: =G23 -> 1370.85
F32: Total cost | G32: =SUM(G28:G31) -> 14575.698

Sheet 18
A1: ENGINEERING DEPARTMENT | H1: daily reading
A2: UTILITY CONSUMPTION SHEET
B3: ='1'!B3 -> JANUARY 2024 | C3: 18 | D3: % OCCUPANCY: | E3: ='Daily Meter'!O23 -> 86.64
A4: SR.NO | B4: ITEM MEASURED | D4: Previous Reading | E4: 4 AM Reading | F4: 24hrs CONSUMPTION | G4: Cost
A6: 1 | B6: DISTRICT COOLING PLANT
B7: Chilled Water | C7: MWH | D7: ='17'!E7 -> 53814.5 | E7: ='Daily Meter'!B23 -> 53836.1 | F7: =E7-D7 -> 21.6
C8: TR | F8: =F7*284.34 -> 6141.744 | G8: =F8*0.63 -> 3869.2987
A9: III | B9: WATER METERS
B10: Main DEWA Meter | C10: m3 | D10: ='17'!E10 -> 206662 | E10: ='Daily Meter'!C23 -> 206868 | F10: =E10-D10 -> 206
B11: Imperial Gallon = m³ x 219.969 | C11: IG | F11: =F10*219.969 -> 45313.614 | G11: =F11*0.06 -> 2718.8168
A12: IV | B12: ELECTRICAL METERS
A13: 1 | B13: Meter 1 - 06065253 | C13: kW x 480 | D13: ='17'!E13 -> 6675.6 | E13: ='Daily Meter'!H23 -> 6682.5 | F13: =(E13-D13)*480 -> 3312
A14: 2 | B14: Meter 2 - 06065255 | C14: kW x 480 | D14: ='17'!E14 -> 4030.3 | E14: ='Daily Meter'!I23 -> 4034.2 | F14: =(E14-D14)*480 -> 1872
A15: 3 | B15: Meter 3 - 06065259 | C15: kW x 480 | D15: ='17'!E15 -> 4305.8 | E15: ='Daily Meter'!J23 -> 4310.4 | F15: =(E15-D15)*480 -> 2208
A16: 4 | B16: Meter 4 - 06065262 | C16: kW x 480 | D16: ='17'!E16 -> 2405.1 | E16: ='Daily Meter'!K23 -> 2407.9 | F16: =(E16-D16)*480 -> 1344
A17: 5 | B17: Meter 6 - 06065269 | C17: kW x 480 | D17: ='17'!E17 -> 5644.9 | E17: ='Daily Meter'!L23 -> 5649.4 | F17: =(E17-D17)*480 -> 2160
A18: 6 | B18: Meter 7 - 06065283 | C18: kW x 480 | D18: ='17'!E18 -> 15194.6 | E18: ='Daily Meter'!M23 -> 15204 | F18: =(E18-D18)*480 -> 4512
B19: TOTAL ELECTRICAL CONS.(kWh) | F19: =SUM(F13:F18) -> 15408 | G19: =F19*0.43 -> 6625.44
A21: V | B21: GAS CONSUMPTION
A22: 1 | B22: MAIN LPG METER | C22: M3 | D22: ='17'!E22 -> 92194.2 | E22: ='Daily Meter'!N23 -> 92341.5 | F22: =E22-D22 -> 147.3
B23: L = m³ x 3.70 | C23: L | F23: =F22*3.7 -> 545.01 | G23: =F23*2.5 -> 1362.525
D26: Summary of Daily Hotel consumption
D27: Item measured | E27: Units | F27: Consumption | G27: AED
D28: Chilled water | E28: TR | F28: =F8 -> 6141.744 | G28: =G8 -> 3869.2987
D29: DEWA Water | E29: imp. Gallon | F29: =F11 -> 45313.614 | G29: =G11 -> 2718.8168
D30: Electricity | E30: kwh | F30: =F19 -> 15408 | G30: =G19 -> 6625.44
D31: Gas | E31: m3 | F31: =F22 -> 147.3 | G31: =G23 -> 1362.525
F32: Total cost | G32: =SUM(G28:G31) -> 14576.081

Sheet 19
A1: ENGINEERING DEPARTMENT | H1: daily reading
A2: UTILITY CONSUMPTION SHEET
B3: ='1'!B3 -> JANUARY 2024 | C3: 19 | D3: % OCCUPANCY: | E3: ='Daily Meter'!O24 -> 71.89
A4: SR.NO | B4: ITEM MEASURED | D4: Previous Reading | E4: 4 AM Reading | F4: 24hrs CONSUMPTION | G4: Cost
A6: 1 | B6: DISTRICT COOLING PLANT
B7: Chilled Water | C7: MWH | D7: ='18'!E7 -> 53836.1 | E7: ='Daily Meter'!B24 -> 53856.4 | F7: =E7-D7 -> 20.3
C8: TR | F8: =F7*284.34 -> 5772.102 | G8: =F8*0.63 -> 3636.4243
A9: III | B9: WATER METERS
B10: Main DEWA Meter | C10: m3 | D10: ='18'!E10 -> 206868 | E10: ='Daily Meter'!C24 -> 207060 | F10: =E10-D10 -> 192
B11: Imperial Gallon = m³ x 219.969 | C11: IG | F11: =F10*219.969 -> 42234.048 | G11: =F11*0.06 -> 2534.0429
A12: IV | B12: ELECTRICAL METERS
A13: 1 | B13: Meter 1 - 06065253 | C13: kW x 480 | D13: ='18'!E13 -> 6682.5 | E13: ='Daily Meter'!H24 -> 6689.3 | F13: =(E13-D13)*480 -> 3264
A14: 2 | B14: Meter 2 - 06065255 | C14: kW x 480 | D14: ='18'!E14 -> 4034.2 | E14: ='Daily Meter'!I24 -> 4038.2 | F14: =(E14-D14)*480 -> 1920
A15: 3 | B15: Meter 3 - 06065259 | C15: kW x 480 | D15: ='18'!E15 -> 4310.4 | E15: ='Daily Meter'!J24 -> 4314.9 | F15: =(E15-D15)*480 -> 2160
A16: 4 | B16: Meter 4 - 06065262 | C16: kW x 480 | D16: ='18'!E16 -> 2407.9 | E16: ='Daily Meter'!K24 -> 2410.9 | F16: =(E16-D16)*480 -> 1440
A17: 5 | B17: Meter 6 - 06065269 | C17: kW x 480 | D17: ='18'!E17 -> 5649.4 | E17: ='Daily Meter'!L24 -> 5653.9 | F17: =(E17-D17)*480 -> 2160
A18: 6 | B18: Meter 7 - 06065283 | C18: kW x 480 | D18: ='18'!E18 -> 15204 | E18: ='Daily Meter'!M24 -> 15214 | F18: =(E18-D18)*480 -> 4800
B19: TOTAL ELECTRICAL CONS.(kWh) | F19: =SUM(F13:F18) -> 15744 | G19: =F19*0.43 -> 6769.92
A21: V | B21: GAS CONSUMPTION
A22: 1 | B22: MAIN LPG METER | C22: M3 | D22: ='18'!E22 -> 92341.5 | E22: ='Daily Meter'!N24 -> 92486.1 | F22: =E22-D22 -> 144.6
B23: L = m³ x 3.70 | C23: L | F23: =F22*3.7 -> 535.02 | G23: =F23*2.5 -> 1337.55
D26: Summary of Daily Hotel consumption
D27: Item measured | E27: Units | F27: Consumption | G27: AED
D28: Chilled water | E28: TR | F28: =F8 -> 5772.102 | G28: =G8 -> 3636.4243
D29: DEWA Water | E29: imp. Gallon | F29: =F11 -> 42234.048 | G29: =G11 -> 2534.0429
D30: Electricity | E30: kwh | F30: =F19 -> 15744 | G30: =G19 -> 6769.92
D31: Gas | E31: m3 | F31: =F22 -> 144.6 | G31: =G23 -> 1337.55
F32: Total cost | G32: =SUM(G28:G31) -> 14277.937

Sheet 20
A1: ENGINEERING DEPARTMENT | H1: daily reading
A2: UTILITY CONSUMPTION SHEET
B3: ='1'!B3 -> JANUARY 2024 | C3: 20 | D3: % OCCUPANCY: | E3: ='Daily Meter'!O25 -> 65.44
A4: SR.NO | B4: ITEM MEASURED | D4: Previous Reading | E4: 4 AM Reading | F4: 24hrs CONSUMPTION | G4: Cost
A6: 1 | B6: DISTRICT COOLING PLANT
B7: Chilled Water | C7: MWH | D7: ='19'!E7 -> 53856.4 | E7: ='Daily Meter'!B25 -> 53877.3 | F7: =E7-D7 -> 20.9
C8: TR | F8: =F7*284.34 -> 5942.706 | G8: =F8*0.63 -> 3743.9048
A9: III | B9: WATER METERS
B10: Main DEWA Meter | C10: m3 | D10: ='19'!E10 -> 207060 | E10: ='Daily Meter'!C25 -> 207241 | F10: =E10-D10 -> 181
B11: Imperial Gallon = m³ x 219.969 | C11: IG | F11: =F10*219.969 -> 39814.389 | G11: =F11*0.06 -> 2388.8633
A12: IV | B12: ELECTRICAL METERS
A13: 1 | B13: Meter 1 - 06065253 | C13: kW x 480 | D13: ='19'!E13 -> 6689.3 | E13: ='Daily Meter'!H25 -> 6696.6 | F13: =(E13-D13)*480 -> 3504
A14: 2 | B14: Meter 2 - 06065255 | C14: kW x 480 | D14: ='19'!E14 -> 4038.2 | E14: ='Daily Meter'!I25 -> 4042.2 | F14: =(E14-D14)*480 -> 1920
A15: 3 | B15: Meter 3 - 06065259 | C15: kW x 480 | D15: ='19'!E15 -> 4314.9 | E15: ='Daily Meter'!J25 -> 4319.3 | F15: =(E15-D15)*480 -> 2112
A16: 4 | B16: Meter 4 - 06065262 | C16: kW x 480 | D16: ='19'!E16 -> 2410.9 | E16: ='Daily Meter'!K25 -> 2413.7 | F16: =(E16-D16)*480 -> 1344
A17: 5 | B17: Meter 6 - 06065269 | C17: kW x 480 | D17: ='19'!E17 -> 5653.9 | E17: ='Daily Meter'!L25 -> 5658.4 | F17: =(E17-D17)*480 -> 2160
A18: 6 | B18: Meter 7 - 06065283 | C18: kW x 480 | D18: ='19'!E18 -> 15214 | E18: ='Daily Meter'!M25 -> 15225.5 | F18: =(E18-D18)*480 -> 5520
B19: TOTAL ELECTRICAL CONS.(kWh) | F19: =SUM(F13:F18) -> 16560 | G19: =F19*0.43 -> 7120.8
A21: V | B21: GAS CONSUMPTION
A22: 1 | B22: MAIN LPG METER | C22: M3 | D22: ='19'!E22 -> 92486.1 | E22: ='Daily Meter'!N25 -> 92625.4 | F22: =E22-D22 -> 139.3
B23: L = m³ x 3.70 | C23: L | F23: =F22*3.7 -> 515.41 | G23: =F23*2.5 -> 1288.525
D26: Summary of Daily Hotel consumption
D27: Item measured | E27: Units | F27: Consumption | G27: AED
D28: Chilled water | E28: TR | F28: =F8 -> 5942.706 | G28: =G8 -> 3743.9048
D29: DEWA Water | E29: imp. Gallon | F29: =F11 -> 39814.389 | G29: =G11 -> 2388.8633
D30: Electricity | E30: kwh | F30: =F19 -> 16560 | G30: =G19 -> 7120.8
D31: Gas | E31: m3 | F31: =F22 -> 139.3 | G31: =G23 -> 1288.525
F32: Total cost | G32: =SUM(G28:G31) -> 14542.093

Sheet 21
A1: ENGINEERING DEPARTMENT | H1: daily reading
A2: UTILITY CONSUMPTION SHEET
B3: ='1'!B3 -> JANUARY 2024 | C3: 21 | D3: % OCCUPANCY: | E3: ='Daily Meter'!O26 -> 67.74
A4: SR.NO | B4: ITEM MEASURED | D4: Previous Reading | E4: 4 AM Reading | F4: 24hrs CONSUMPTION | G4: Cost
A6: 1 | B6: DISTRICT COOLING PLANT
B7: Chilled Water | C7: MWH | D7: ='20'!E7 -> 53877.3 | E7: ='Daily Meter'!B26 -> 53898.5 | F7: =E7-D7 -> 21.2
C8: TR | F8: =F7*284.34 -> 6028.008 | G8: =F8*0.63 -> 3797.645
A9: III | B9: WATER METERS
B10: Main DEWA Meter | C10: m3 | D10: ='20'!E10 -> 207241 | E10: ='Daily Meter'!C26 -> 207416 | F10: =E10-D10 -> 175
B11: Imperial Gallon = m³ x 219.969 | C11: IG | F11: =F10*219.969 -> 38494.575 | G11: =F11*0.06 -> 2309.6745
A12: IV | B12: ELECTRICAL METERS
A13: 1 | B13: Meter 1 - 06065253 | C13: kW x 480 | D13: ='20'!E13 -> 6696.6 | E13: ='Daily Meter'!H26 -> 6703.7 | F13: =(E13-D13)*480 -> 3408
A14: 2 | B14: Meter 2 - 06065255 | C14: kW x 480 | D14: ='20'!E14 -> 4042.2 | E14: ='Daily Meter'!I26 -> 4046 | F14: =(E14-D14)*480 -> 1824
A15: 3 | B15: Meter 3 - 06065259 | C15: kW x 480 | D15: ='20'!E15 -> 4319.3 | E15: ='Daily Meter'!J26 -> 4323.7 | F15: =(E15-D15)*480 -> 2112
A16: 4 | B16: Meter 4 - 06065262 | C16: kW x 480 | D16: ='20'!E16 -> 2413.7 | E16: ='Daily Meter'!K26 -> 2416.6 | F16: =(E16-D16)*480 -> 1392
A17: 5 | B17: Meter 6 - 06065269 | C17: kW x 480 | D17: ='20'!E17 -> 5658.4 | E17: ='Daily Meter'!L26 -> 5663 | F17: =(E17-D17)*480 -> 2208
A18: 6 | B18: Meter 7 - 06065283 | C18: kW x 480 | D18: ='20'!E18 -> 15225.5 | E18: ='Daily Meter'!M26 -> 15237.4 | F18: =(E18-D18)*480 -> 5712
B19: TOTAL ELECTRICAL CONS.(kWh) | F19: =SUM(F13:F18) -> 16656 | G19: =F19*0.43 -> 7162.08
A21: V | B21: GAS CONSUMPTION
A22: 1 | B22: MAIN LPG METER | C22: M3 | D22: ='20'!E22 -> 92625.4 | E22: ='Daily Meter'!N26 -> 92758.4 | F22: =E22-D22 -> 133
B23: L = m³ x 3.70 | C23: L | F23: =F22*3.7 -> 492.1 | G23: =F23*2.5 -> 1230.25
D26: Summary of Daily Hotel consumption
D27: Item measured | E27: Units | F27: Consumption | G27: AED
D28: Chilled water | E28: TR | F28: =F8 -> 6028.008 | G28: =G8 -> 3797.645
D29: DEWA Water | E29: imp. Gallon | F29: =F11 -> 38494.575 | G29: =G11 -> 2309.6745
D30: Electricity | E30: kwh | F30: =F19 -> 16656 | G30: =G19 -> 7162.08
D31: Gas | E31: m3 | F31: =F22 -> 133 | G31: =G23 -> 1230.25
F32: Total cost | G32: =SUM(G28:G31) -> 14499.65

Sheet 22
A1: ENGINEERING DEPARTMENT | H1: daily reading
A2: UTILITY CONSUMPTION SHEET
B3: ='1'!B3 -> JANUARY 2024 | C3: 22 | D3: % OCCUPANCY: | E3: ='Daily Meter'!O27 -> 80.18
A4: SR.NO | B4: ITEM MEASURED | D4: Previous Reading | E4: 4 AM Reading | F4: 24hrs CONSUMPTION | G4: Cost
A6: 1 | B6: DISTRICT COOLING PLANT
B7: Chilled Water | C7: MWH | D7: ='21'!E7 -> 53898.5 | E7: ='Daily Meter'!B27 -> 53918.4 | F7: =E7-D7 -> 19.9
C8: TR | F8: =F7*284.34 -> 5658.366 | G8: =F8*0.63 -> 3564.7706
A9: III | B9: WATER METERS
B10: Main DEWA Meter | C10: m3 | D10: ='21'!E10 -> 207416 | E10: ='Daily Meter'!C27 -> 207537 | F10: =E10-D10 -> 121
B11: Imperial Gallon = m³ x 219.969 | C11: IG | F11: =F10*219.969 -> 26616.249 | G11: =F11*0.06 -> 1596.9749
A12: IV | B12: ELECTRICAL METERS
A13: 1 | B13: Meter 1 - 06065253 | C13: kW x 480 | D13: ='21'!E13 -> 6703.7 | E13: ='Daily Meter'!H27 -> 6710.5 | F13: =(E13-D13)*480 -> 3264
A14: 2 | B14: Meter 2 - 06065255 | C14: kW x 480 | D14: ='21'!E14 -> 4046 | E14: ='Daily Meter'!I27 -> 4049.8 | F14: =(E14-D14)*480 -> 1824
A15: 3 | B15: Meter 3 - 06065259 | C15: kW x 480 | D15: ='21'!E15 -> 4323.7 | E15: ='Daily Meter'!J27 -> 4328.1 | F15: =(E15-D15)*480 -> 2112
A16: 4 | B16: Meter 4 - 06065262 | C16: kW x 480 | D16: ='21'!E16 -> 2416.6 | E16: ='Daily Meter'!K27 -> 2419.3 | F16: =(E16-D16)*480 -> 1296
A17: 5 | B17: Meter 6 - 06065269 | C17: kW x 480 | D17: ='21'!E17 -> 5663 | E17: ='Daily Meter'!L27 -> 5667.4 | F17: =(E17-D17)*480 -> 2112
A18: 6 | B18: Meter 7 - 06065283 | C18: kW x 480 | D18: ='21'!E18 -> 15237.4 | E18: ='Daily Meter'!M27 -> 15248.9 | F18: =(E18-D18)*480 -> 5520
B19: TOTAL ELECTRICAL CONS.(kWh) | F19: =SUM(F13:F18) -> 16128 | G19: =F19*0.43 -> 6935.04
A21: V | B21: GAS CONSUMPTION
A22: 1 | B22: MAIN LPG METER | C22: M3 | D22: ='21'!E22 -> 92758.4 | E22: ='Daily Meter'!N27 -> 92881.5 | F22: =E22-D22 -> 123.1
B23: L = m³ x 3.70 | C23: L | F23: =F22*3.7 -> 455.47 | G23: =F23*2.5 -> 1138.675
D26: Summary of Daily Hotel consumption
D27: Item measured | E27: Units | F27: Consumption | G27: AED
D28: Chilled water | E28: TR | F28: =F8 -> 5658.366 | G28: =G8 -> 3564.7706
D29: DEWA Water | E29: imp. Gallon | F29: =F11 -> 26616.249 | G29: =G11 -> 1596.9749
D30: Electricity | E30: kwh | F30: =F19 -> 16128 | G30: =G19 -> 6935.04
D31: Gas | E31: m3 | F31: =F22 -> 123.1 | G31: =G23 -> 1138.675
F32: Total cost | G32: =SUM(G28:G31) -> 13235.461

Sheet 23
A1: ENGINEERING DEPARTMENT | H1: daily reading
A2: UTILITY CONSUMPTION SHEET
B3: ='1'!B3 -> JANUARY 2024 | C3: 23 | D3: % OCCUPANCY: | E3: ='Daily Meter'!O28 -> 82.26
A4: SR.NO | B4: ITEM MEASURED | D4: Previous Reading | E4: 4 AM Reading | F4: 24hrs CONSUMPTION | G4: Cost
A6: 1 | B6: DISTRICT COOLING PLANT
B7: Chilled Water | C7: MWH | D7: ='22'!E7 -> 53918.4 | E7: ='Daily Meter'!B28 -> 53939.1 | F7: =E7-D7 -> 20.7
C8: TR | F8: =F7*284.34 -> 5885.838 | G8: =F8*0.63 -> 3708.0779
A9: III | B9: WATER METERS
B10: Main DEWA Meter | C10: m3 | D10: ='22'!E10 -> 207537 | E10: ='Daily Meter'!C28 -> 207739 | F10: =E10-D10 -> 202
B11: Imperial Gallon = m³ x 219.969 | C11: IG | F11: =F10*219.969 -> 44433.738 | G11: =F11*0.06 -> 2666.0243
A12: IV | B12: ELECTRICAL METERS
A13: 1 | B13: Meter 1 - 06065253 | C13: kW x 480 | D13: ='22'!E13 -> 6710.5 | E13: ='Daily Meter'!H28 -> 6717.5 | F13: =(E13-D13)*480 -> 3360
A14: 2 | B14: Meter 2 - 06065255 | C14: kW x 480 | D14: ='22'!E14 -> 4049.8 | E14: ='Daily Meter'!I28 -> 4053.8 | F14: =(E14-D14)*480 -> 1920
A15: 3 | B15: Meter 3 - 06065259 | C15: kW x 480 | D15: ='22'!E15 -> 4328.1 | E15: ='Daily Meter'!J28 -> 4332.4 | F15: =(E15-D15)*480 -> 2064
A16: 4 | B16: Meter 4 - 06065262 | C16: kW x 480 | D16: ='22'!E16 -> 2419.3 | E16: ='Daily Meter'!K28 -> 2422.1 | F16: =(E16-D16)*480 -> 1344
A17: 5 | B17: Meter 6 - 06065269 | C17: kW x 480 | D17: ='22'!E17 -> 5667.4 | E17: ='Daily Meter'!L28 -> 5671.9 | F17: =(E17-D17)*480 -> 2160
A18: 6 | B18: Meter 7 - 06065283 | C18: kW x 480 | D18: ='22'!E18 -> 15248.9 | E18: ='Daily Meter'!M28 -> 15260.8 | F18: =(E18-D18)*480 -> 5712
B19: TOTAL ELECTRICAL CONS.(kWh) | F19: =SUM(F13:F18) -> 16560 | G19: =F19*0.43 -> 7120.8
A21: V | B21: GAS CONSUMPTION
A22: 1 | B22: MAIN LPG METER | C22: M3 | D22: ='22'!E22 -> 92881.5 | E22: ='Daily Meter'!N28 -> 93014.8 | F22: =E22-D22 -> 133.3
B23: L = m³ x 3.70 | C23: L | F23: =F22*3.7 -> 493.21 | G23: =F23*2.5 -> 1233.025
D26: Summary of Daily Hotel consumption
D27: Item measured | E27: Units | F27: Consumption | G27: AED
D28: Chilled water | E28: TR | F28: =F8 -> 5885.838 | G28: =G8 -> 3708.0779
D29: DEWA Water | E29: imp. Gallon | F29: =F11 -> 44433.738 | G29: =G11 -> 2666.0243
D30: Electricity | E30: kwh | F30: =F19 -> 16560 | G30: =G19 -> 7120.8
D31: Gas | E31: m3 | F31: =F22 -> 133.3 | G31: =G23 -> 1233.025
F32: Total cost | G32: =SUM(G28:G31) -> 14727.927

Sheet 24
A1: ENGINEERING DEPARTMENT | H1: daily reading
A2: UTILITY CONSUMPTION SHEET
B3: ='1'!B3 -> JANUARY 2024 | C3: 24 | D3: % OCCUPANCY: | E3: ='Daily Meter'!O29 -> 84.56
A4: SR.NO | B4: ITEM MEASURED | D4: Previous Reading | E4: 4 AM Reading | F4: 24hrs CONSUMPTION | G4: Cost
A6: 1 | B6: DISTRICT COOLING PLANT
B7: Chilled Water | C7: MWH | D7: ='23'!E7 -> 53939.1 | E7: ='Daily Meter'!B29 -> 53960.7 | F7: =E7-D7 -> 21.6
C8: TR | F8: =F7*284.34 -> 6141.744 | G8: =F8*0.63 -> 3869.2987
A9: III | B9: WATER METERS
B10: Main DEWA Meter | C10: m3 | D10: ='23'!E10 -> 207739 | E10: ='Daily Meter'!C29 -> 207921 | F10: =E10-D10 -> 182
B11: Imperial Gallon = m³ x 219.969 | C11: IG | F11: =F10*219.969 -> 40034.358 | G11: =F11*0.06 -> 2402.0615
A12: IV | B12: ELECTRICAL METERS
A13: 1 | B13: Meter 1 - 06065253 | C13: kW x 480 | D13: ='23'!E13 -> 6717.5 | E13: ='Daily Meter'!H29 -> 6724.5 | F13: =(E13-D13)*480 -> 3360
A14: 2 | B14: Meter 2 - 06065255 | C14: kW x 480 | D14: ='23'!E14 -> 4053.8 | E14: ='Daily Meter'!I29 -> 4058 | F14: =(E14-D14)*480 -> 2016
A15: 3 | B15: Meter 3 - 06065259 | C15: kW x 480 | D15: ='23'!E15 -> 4332.4 | E15: ='Daily Meter'!J29 -> 4336.9 | F15: =(E15-D15)*480 -> 2160
A16: 4 | B16: Meter 4 - 06065262 | C16: kW x 480 | D16: ='23'!E16 -> 2422.1 | E16: ='Daily Meter'!K29 -> 2425.3 | F16: =(E16-D16)*480 -> 1536
A17: 5 | B17: Meter 6 - 06065269 | C17: kW x 480 | D17: ='23'!E17 -> 5671.9 | E17: ='Daily Meter'!L29 -> 5676.5 | F17: =(E17-D17)*480 -> 2208
A18: 6 | B18: Meter 7 - 06065283 | C18: kW x 480 | D18: ='23'!E18 -> 15260.8 | E18: ='Daily Meter'!M29 -> 15272.9 | F18: =(E18-D18)*480 -> 5808
B19: TOTAL ELECTRICAL CONS.(kWh) | F19: =SUM(F13:F18) -> 17088 | G19: =F19*0.43 -> 7347.84
A21: V | B21: GAS CONSUMPTION
A22: 1 | B22: MAIN LPG METER | C22: M3 | D22: ='23'!E22 -> 93014.8 | E22: ='Daily Meter'!N29 -> 93151.1 | F22: =E22-D22 -> 136.3
B23: L = m³ x 3.70 | C23: L | F23: =F22*3.7 -> 504.31 | G23: =F23*2.5 -> 1260.775
D26: Summary of Daily Hotel consumption
D27: Item measured | E27: Units | F27: Consumption | G27: AED
D28: Chilled water | E28: TR | F28: =F8 -> 6141.744 | G28: =G8 -> 3869.2987
D29: DEWA Water | E29: imp. Gallon | F29: =F11 -> 40034.358 | G29: =G11 -> 2402.0615
D30: Electricity | E30: kwh | F30: =F19 -> 17088 | G30: =G19 -> 7347.84
D31: Gas | E31: m3 | F31: =F22 -> 136.3 | G31: =G23 -> 1260.775
F32: Total cost | G32: =SUM(G28:G31) -> 14879.975

Sheet 25
A1: ENGINEERING DEPARTMENT | H1: daily reading
A2: UTILITY CONSUMPTION SHEET
B3: ='1'!B3 -> JANUARY 2024 | C3: 25 | D3: % OCCUPANCY: | E3: ='Daily Meter'!O30 -> 93.78
A4: SR.NO | B4: ITEM MEASURED | D4: Previous Reading | E4: 4 AM Reading | F4: 24hrs CONSUMPTION | G4: Cost
A6: 1 | B6: DISTRICT COOLING PLANT
B7: Chilled Water | C7: MWH | D7: ='24'!E7 -> 53960.7 | E7: ='Daily Meter'!B30 -> 53979.8 | F7: =E7-D7 -> 19.1
C8: TR | F8: =F7*284.34 -> 5430.894 | G8: =F8*0.63 -> 3421.4632
A9: III | B9: WATER METERS
B10: Main DEWA Meter | C10: m3 | D10: ='24'!E10 -> 207921 | E10: ='Daily Meter'!C30 -> 208093 | F10: =E10-D10 -> 172
B11: Imperial Gallon = m³ x 219.969 | C11: IG | F11: =F10*219.969 -> 37834.668 | G11: =F11*0.06 -> 2270.0801
A12: IV | B12: ELECTRICAL METERS
A13: 1 | B13: Meter 1 - 06065253 | C13: kW x 480 | D13: ='24'!E13 -> 6724.5 | E13: ='Daily Meter'!H30 -> 6731.5 | F13: =(E13-D13)*480 -> 3360
A14: 2 | B14: Meter 2 - 06065255 | C14: kW x 480 | D14: ='24'!E14 -> 4058 | E14: ='Daily Meter'!I30 -> 4062.2 | F14: =(E14-D14)*480 -> 2016
A15: 3 | B15: Meter 3 - 06065259 | C15: kW x 480 | D15: ='24'!E15 -> 4336.9 | E15: ='Daily Meter'!J30 -> 4341.4 | F15: =(E15-D15)*480 -> 2160
A16: 4 | B16: Meter 4 - 06065262 | C16: kW x 480 | D16: ='24'!E16 -> 2425.3 | E16: ='Daily Meter'!K30 -> 2428.3 | F16: =(E16-D16)*480 -> 1440
A17: 5 | B17: Meter 6 - 06065269 | C17: kW x 480 | D17: ='24'!E17 -> 5676.5 | E17: ='Daily Meter'!L30 -> 5681 | F17: =(E17-D17)*480 -> 2160
A18: 6 | B18: Meter 7 - 06065283 | C18: kW x 480 | D18: ='24'!E18 -> 15272.9 | E18: ='Daily Meter'!M30 -> 15284.7 | F18: =(E18-D18)*480 -> 5664
B19: TOTAL ELECTRICAL CONS.(kWh) | F19: =SUM(F13:F18) -> 16800 | G19: =F19*0.43 -> 7224
A21: V | B21: GAS CONSUMPTION
A22: 1 | B22: MAIN LPG METER | C22: M3 | D22: ='24'!E22 -> 93151.1 | E22: ='Daily Meter'!N30 -> 93278.7 | F22: =E22-D22 -> 127.6
B23: L = m³ x 3.70 | C23: L | F23: =F22*3.7 -> 472.12 | G23: =F23*2.5 -> 1180.3
D26: Summary of Daily Hotel consumption
D27: Item measured | E27: Units | F27: Consumption | G27: AED
D28: Chilled water | E28: TR | F28: =F8 -> 5430.894 | G28: =G8 -> 3421.4632
D29: DEWA Water | E29: imp. Gallon | F29: =F11 -> 37834.668 | G29: =G11 -> 2270.0801
D30: Electricity | E30: kwh | F30: =F19 -> 16800 | G30: =G19 -> 7224
D31: Gas | E31: m3 | F31: =F22 -> 127.6 | G31: =G23 -> 1180.3
F32: Total cost | G32: =SUM(G28:G31) -> 14095.843

Sheet 26
