Workbook

Sheet Sheet2
A1: Site Name | B1: Day | C1: Month | D1: Year | E1: Total Electricity Kwh | F1: Electricity Tariff ($/Kwh) | G1: LPG (Liters) | H1: LPG $/Liters | I1: Water Utility Supply (IG) IG | J1: Water Utility Supply (IG) $/IG | K1: District Energy Cooling RTH | L1: District Energy Cooling $/RTH | M1: Room Nights | N1: Total Guests
A2: 25hours Dubai One Central | B2: 1 | C2: 1 | D2: 2023 | E2: =('Daily Meter'!K6+'Daily Meter'!M6+'Daily Meter'!O6+'Daily Meter'!Q6+'Daily Meter'!S6+'Daily Meter'!U6-'1'!D20)*480 -> 13872 | F2: 0.44 | G2: ='Daily Meter'!W6-'1'!D23 -> 122.5 | H2: 2.5 | I2: =('Daily Meter'!E6-'1'!D11)*219.969 -> 36074.916 | J2: 0.06 | K2: =('Daily Meter'!C6-'1'!D8)*284.34 -> 4833.78 | L2: =0.568+0.075 -> 0.643 | M2: =INT('Daily Meter'!X6*434/100) -> 326
A3: 25hours Dubai One Central | B3: =B2+1 -> 2 | C3: 1 | D3: 2023 | E3: =('Daily Meter'!K7-'Daily Meter'!K6+'Daily Meter'!M7-'Daily Meter'!M6+'Daily Meter'!O7-'Daily Meter'!O6+'Daily Meter'!Q7-'Daily Meter'!Q6+'Daily Meter'!S7-'Daily Meter'!S6+'Daily Meter'!U7-'Daily Meter'!U6)*480 -> 17232 | F3: 0.44 | G3: ='Daily Meter'!W7-'Daily Meter'!W6 -> 136.1 | H3: 2.5 | I3: =('Daily Meter'!E7-'Daily Meter'!E6)*219.969 -> 47953.242 | J3: 0.06 | K3: =('Daily Meter'!C7-'Daily Meter'!C6)*284.34 -> 5715.234 | L3: =0.568+0.075 -> 0.643 | M3: =INT('Daily Meter'!X7*434/100) -> 272
A4: 25hours Dubai One Central | B4: =B3+1 -> 3 | C4: 1 | D4: 2023 | E4: =('Daily Meter'!K8-'Daily Meter'!K7+'Daily Meter'!M8-'Daily Meter'!M7+'Daily Meter'!O8-'Daily Meter'!O7+'Daily Meter'!Q8-'Daily Meter'!Q7+'Daily Meter'!S8-'Daily Meter'!S7+'Daily Meter'!U8-'Daily Meter'!U7)*480 -> 17232 | F4: 0.44 | G4: ='Daily Meter'!W8-'Daily Meter'!W7 -> 140.8 | H4: 2.5 | I4: =('Daily Meter'!E8-'Daily Meter'!E7)*219.969 -> 30135.753 | J4: 0.06 | K4: =('Daily Meter'!C8-'Daily Meter'!C7)*284.34 -> 5516.196 | L4: =0.568+0.075 -> 0.643 | M4: =INT('Daily Meter'!X8*434/100) -> 283
A5: 25hours Dubai One Central | B5: =B4+1 -> 4 | C5: 1 | D5: 2023 | E5: =('Daily Meter'!K9-'Daily Meter'!K8+'Daily Meter'!M9-'Daily Meter'!M8+'Daily Meter'!O9-'Daily Meter'!O8+'Daily Meter'!Q9-'Daily Meter'!Q8+'Daily Meter'!S9-'Daily Meter'!S8+'Daily Meter'!U9-'Daily Meter'!U8)*480 -> 17136 | F5: 0.44 | G5: ='Daily Meter'!W9-'Daily Meter'!W8 -> 135.3 | H5: 2.5 | I5: =('Daily Meter'!E9-'Daily Meter'!E8)*219.969 -> 80288.685 | J5: 0.06 | K5: =('Daily Meter'!C9-'Daily Meter'!C8)*284.34 -> 5601.498 | L5: =0.568+0.075 -> 0.643 | M5: =INT('Daily Meter'!X9*434/100) -> 278
A6: 25hours Dubai One Central | B6: =B5+1 -> 5 | C6: 1 | D6: 2023 | E6: =('Daily Meter'!K10-'Daily Meter'!K9+'Daily Meter'!M10-'Daily Meter'!M9+'Daily Meter'!O10-'Daily Meter'!O9+'Daily Meter'!Q10-'Daily Meter'!Q9+'Daily Meter'!S10-'Daily Meter'!S9+'Daily Meter'!U10-'Daily Meter'!U9)*480 -> 16512 | F6: 0.44 | G6: ='Daily Meter'!W10-'Daily Meter'!W9 -> 127.5 | H6: 2.5 | I6: =('Daily Meter'!E10-'Daily Meter'!E9)*219.969 -> 71929.863 | J6: 0.06 | K6: =('Daily Meter'!C10-'Daily Meter'!C9)*284.34 -> 5715.234 | L6: =0.568+0.075 -> 0.643 | M6: =INT('Daily Meter'!X10*434/100) -> 270
A7: 25hours Dubai One Central | B7: =B6+1 -> 6 | C7: 1 | D7: 2023 | E7: =('Daily Meter'!K11-'Daily Meter'!K10+'Daily Meter'!M11-'Daily Meter'!M10+'Daily Meter'!O11-'Daily Meter'!O10+'Daily Meter'!Q11-'Daily Meter'!Q10+'Daily Meter'!S11-'Daily Meter'!S10+'Daily Meter'!U11-'Daily Meter'!U10)*480 -> 18720 | F7: 0.44 | G7: ='Daily Meter'!W11-'Daily Meter'!W10 -> 156 | H7: 2.5 | I7: =('Daily Meter'!E11-'Daily Meter'!E10)*219.969 -> 66430.638 | J7: 0.06 | K7: =('Daily Meter'!C11-'Daily Meter'!C10)*284.34 -> 6852.594 | L7: =0.568+0.075 -> 0.643 | M7: =INT('Daily Meter'!X11*434/100) -> 264
A8: 25hours Dubai One Central | B8: =B7+1 -> 7 | C8: 1 | D8: 2023 | E8: =('Daily Meter'!K12-'Daily Meter'!K11+'Daily Meter'!M12-'Daily Meter'!M11+'Daily Meter'!O12-'Daily Meter'!O11+'Daily Meter'!Q12-'Daily Meter'!Q11+'Daily Meter'!S12-'Daily Meter'!S11+'Daily Meter'!U12-'Daily Meter'!U11)*480 -> 17424 | F8: 0.44 | G8: ='Daily Meter'!W12-'Daily Meter'!W11 -> 153 | H8: 2.5 | I8: =('Daily Meter'!E12-'Daily Meter'!E11)*219.969 -> 43113.924 | J8: 0.06 | K8: =('Daily Meter'!C12-'Daily Meter'!C11)*284.34 -> 5715.234 | L8: =0.568+0.075 -> 0.643 | M8: =INT('Daily Meter'!X12*434/100) -> 223
A9: 25hours Dubai One Central | B9: =B8+1 -> 8 | C9: 1 | D9: 2023 | E9: =('Daily Meter'!K13-'Daily Meter'!K12+'Daily Meter'!M13-'Daily Meter'!M12+'Daily Meter'!O13-'Daily Meter'!O12+'Daily Meter'!Q13-'Daily Meter'!Q12+'Daily Meter'!S13-'Daily Meter'!S12+'Daily Meter'!U13-'Daily Meter'!U12)*480 -> 13440 | F9: 0.44 | G9: ='Daily Meter'!W13-'Daily Meter'!W12 -> 113.4 | H9: 2.5 | I9: =('Daily Meter'!E13-'Daily Meter'!E12)*219.969 -> 60491.475 | J9: 0.06 | K9: =('Daily Meter'!C13-'Daily Meter'!C12)*284.34 -> 4151.364 | L9: =0.568+0.075 -> 0.643 | M9: =INT('Daily Meter'!X13*434/100) -> 161
A10: 25hours Dubai One Central | B10: =B9+1 -> 9 | C10: 1 | D10: 2023 | E10: =('Daily Meter'!K14-'Daily Meter'!K13+'Daily Meter'!M14-'Daily Meter'!M13+'Daily Meter'!O14-'Daily Meter'!O13+'Daily Meter'!Q14-'Daily Meter'!Q13+'Daily Meter'!S14-'Daily Meter'!S13+'Daily Meter'!U14-'Daily Meter'!U13)*480 -> 18192 | F10: 0.44 | G10: ='Daily Meter'!W14-'Daily Meter'!W13 -> 135.1 | H10: 2.5 | I10: =('Daily Meter'!E14-'Daily Meter'!E13)*219.969 -> 13858.047 | J10: 0.06 | K10: =('Daily Meter'!C14-'Daily Meter'!C13)*284.34 -> 4776.912 | L10: =0.568+0.075 -> 0.643 | M10: =INT('Daily Meter'!X14*434/100) -> 310
A11: 25hours Dubai One Central | B11: =B10+1 -> 10 | C11: 1 | D11: 2023 | E11: =('Daily Meter'!K15-'Daily Meter'!K14+'Daily Meter'!M15-'Daily Meter'!M14+'Daily Meter'!O15-'Daily Meter'!O14+'Daily Meter'!Q15-'Daily Meter'!Q14+'Daily Meter'!S15-'Daily Meter'!S14+'Daily Meter'!U15-'Daily Meter'!U14)*480 -> 16512 | F11: 0.44 | G11: ='Daily Meter'!W15-'Daily Meter'!W14 -> 150.2 | H11: 2.5 | I11: =('Daily Meter'!E15-'Daily Meter'!E14)*219.969 -> 46193.49 | J11: 0.06 | K11: =('Daily Meter'!C15-'Daily Meter'!C14)*284.34 -> 6369.216 | L11: =0.568+0.075 -> 0.643 | M11: =INT('Daily Meter'!X15*434/100) -> 365
A12: 25hours Dubai One Central | B12: =B11+1 -> 11 | C12: 1 | D12: 2023 | E12: =('Daily Meter'!K16-'Daily Meter'!K15+'Daily Meter'!M16-'Daily Meter'!M15+'Daily Meter'!O16-'Daily Meter'!O15+'Daily Meter'!Q16-'Daily Meter'!Q15+'Daily Meter'!S16-'Daily Meter'!S15+'Daily Meter'!U16-'Daily Meter'!U15)*480 -> 17040 | F12: 0.44 | G12: ='Daily Meter'!W16-'Daily Meter'!W15 -> 151 | H12: 2.5 | I12: =('Daily Meter'!E16-'Daily Meter'!E15)*219.969 -> 64230.948 | J12: 0.06 | K12: =('Daily Meter'!C16-'Daily Meter'!C15)*284.34 -> 6056.442 | L12: =0.568+0.075 -> 0.643 | M12: =INT('Daily Meter'!X16*434/100) -> 365
A13: 25hours Dubai One Central | B13: =B12+1 -> 12 | C13: 1 | D13: 2023 | E13: =('Daily Meter'!K17-'Daily Meter'!K16+'Daily Meter'!M17-'Daily Meter'!M16+'Daily Meter'!O17-'Daily Meter'!O16+'Daily Meter'!Q17-'Daily Meter'!Q16+'Daily Meter'!S17-'Daily Meter'!S16+'Daily Meter'!U17-'Daily Meter'!U16)*480 -> 17232 | F13: 0.44 | G13: ='Daily Meter'!W17-'Daily Meter'!W16 -> 145.8 | H13: 2.5 | I13: =('Daily Meter'!E17-'Daily Meter'!E16)*219.969 -> 68410.359 | J13: 0.06 | K13: =('Daily Meter'!C17-'Daily Meter'!C16)*284.34 -> 5032.818 | L13: =0.568+0.075 -> 0.643 | M13: =INT('Daily Meter'!X17*434/100) -> 290
A14: 25hours Dubai One Central | B14: =B13+1 -> 13 | C14: 1 | D14: 2023 | E14: =('Daily Meter'!K18-'Daily Meter'!K17+'Daily Meter'!M18-'Daily Meter'!M17+'Daily Meter'!O18-'Daily Meter'!O17+'Daily Meter'!Q18-'Daily Meter'!Q17+'Daily Meter'!S18-'Daily Meter'!S17+'Daily Meter'!U18-'Daily Meter'!U17)*480 -> 17376 | F14: 0.44 | G14: ='Daily Meter'!W18-'Daily Meter'!W17 -> 140.5 | H14: 2.5 | I14: =('Daily Meter'!E18-'Daily Meter'!E17)*219.969 -> 50812.839 | J14: 0.06 | K14: =('Daily Meter'!C18-'Daily Meter'!C17)*284.34 -> 4634.742 | L14: =0.568+0.075 -> 0.643 | M14: =INT('Daily Meter'!X18*434/100) -> 304
... A32: 25hours Dubai One Central | B32: =B31+1 -> 31 | C32: 1 | D32: 2023 | E32: =('Daily Meter'!K36-'Daily Meter'!K35+'Daily Meter'!M36-'Daily Meter'!M35+'Daily Meter'!O36-'Daily Meter'!O35+'Daily Meter'!Q36-'Daily Meter'!Q35+'Daily Meter'!S36-'Daily Meter'!S35+'Daily Meter'!U36-'Daily Meter'!U35)*480 -> 16368 | F32: 0.44 | G32: ='Daily Meter'!W36-'Daily Meter'!W35 -> 145.3 | H32: 2.5 | I32: =('Daily Meter'!E36-'Daily Meter'!E35)*219.969 -> 89307.414 | J32: 0.06 | K32: =('Daily Meter'!C36-'Daily Meter'!C35)*284.34 -> 4435.704 | L32: =0.568+0.075 -> 0.643 | M32: =INT('Daily Meter'!X36*434/100) -> 425

Sheet Sheet1
A1: Site Name | B1: Day | C1: Month | D1: Year | E1: Meter 1 - 06065253 | F1: Meter 2 - 06065255 | G1: Meter 3 - 06065259 | H1: Meter 4 - 06065262 | I1: Meter 6 - 06065269 | J1: Meter 7 - 06065283 | K1: District Cooling | L1: Water | M1: Gas | N1: Room Nights | O1: Total Guests
A2: 25hours Dubai One Central | B2: 1 | C2: 1 | D2: 2023 | N2: =Sheet2!M2 -> 326
A3: 25hours Dubai One Central | B3: =B2+1 -> 2 | C3: 1 | D3: 2023 | N3: =Sheet2!M3 -> 272
A4: 25hours Dubai One Central | B4: =B3+1 -> 3 | C4: 1 | D4: 2023 | N4: =Sheet2!M4 -> 283
A5: 25hours Dubai One Central | B5: =B4+1 -> 4 | C5: 1 | D5: 2023 | N5: =Sheet2!M5 -> 278
A6: 25hours Dubai One Central | B6: =B5+1 -> 5 | C6: 1 | D6: 2023 | N6: =Sheet2!M6 -> 270
A7: 25hours Dubai One Central | B7: =B6+1 -> 6 | C7: 1 | D7: 2023 | N7: =Sheet2!M7 -> 264
A8: 25hours Dubai One Central | B8: =B7+1 -> 7 | C8: 1 | D8: 2023 | N8: =Sheet2!M8 -> 223
A9: 25hours Dubai One Central | B9: =B8+1 -> 8 | C9: 1 | D9: 2023 | N9: =Sheet2!M9 -> 161
A10: 25hours Dubai One Central | B10: =B9+1 -> 9 | C10: 1 | D10: 2023 | N10: =Sheet2!M10 -> 310
A11: 25hours Dubai One Central | B11: =B10+1 -> 10 | C11: 1 | D11: 2023 | N11: =Sheet2!M11 -> 365
A12: 25hours Dubai One Central | B12: =B11+1 -> 11 | C12: 1 | D12: 2023 | N12: =Sheet2!M12 -> 365
A13: 25hours Dubai One Central | B13: =B12+1 -> 12 | C13: 1 | D13: 2023 | N13: =Sheet2!M13 -> 290
A14: 25hours Dubai One Central | B14: =B13+1 -> 13 | C14: 1 | D14: 2023 | N14: =Sheet2!M14 -> 304
... A32: 25hours Dubai One Central | B32: =B31+1 -> 31 | C32: 1 | D32: 2023 | N32: =Sheet2!M32 -> 425

Sheet Daily Meter
A1: JANUARY 2023 UTILITY READING | Z1: 1st
B2: Chilled Water | D2: Water | J2: Electric | V2: Gas | X2: OCC.
A3: Date | B3: BTU Meter | D3: Meter 1 | F3: Meter 2 | H3: Meter 3 | J3: Meter 1 | L3: Meter 2 | N3: Meter 3 | P3: Meter 4 | R3: Meter 6 | T3: Meter 7 | V3: Gas
B4: P103FF043BC | D4: 18E0300032 | F4: 18E0300060 | H4: 18E0300057 | J4: 6065253 | L4: 6065255 | N4: 6065259 | P4: 6065262 | R4: 6065269 | T4: 6065283 | V4: 77092321/2019 | X4: %
B5: 9am | C5: 5pm | D5: 9am | E5: 5pm | F5: 5AM | G5: 5pm | H5: 5AM | I5: 5pm | J5: 9am | K5: 5pm | L5: 9am | M5: 5pm | N5: 9am | O5: 5pm | P5: 9am | Q5: 5pm | R5: 9am | S5: 5pm | T5: 9am | U5: 5pm | V5: 9am | W5: 5pm | X5: DAILY
A6: 1 | B6: 36057.7 | C6: 36065.5 | D6: 115374 | E6: 115376 | J6: 4028.1 | K6: 4030.7 | L6: 2422.9 | M6: 2424.6 | N6: 2580.3 | O6: 2581.8 | P6: 1282.6 | Q6: 1283.4 | R6: 3860.6 | S6: 3862.3 | T6: 10211 | U6: 10215.9 | V6: 47434.7 | W6: 47492.8 | X6: 75.12
A7: 2 | B7: 36076.8 | C7: 36085.6 | D7: 115550 | E7: 115594 | J7: 4034.9 | K7: 4037.7 | L7: 2426.7 | M7: 2428.5 | N7: 2584.1 | O7: 2586.4 | P7: 1285.1 | Q7: 1286.1 | R7: 3865 | S7: 3867 | T7: 10223.5 | U7: 10228.9 | V7: 47571.5 | W7: 47628.9 | X7: 62.9
A8: 3 | B8: 36097.6 | C8: 36105 | D8: 115665 | E8: 115731 | J8: 4042 | K8: 4044.9 | L8: 2430.5 | M8: 2432.3 | N8: 2589.4 | O8: 2591.1 | P8: 1287.8 | Q8: 1288.9 | R8: 3869.8 | S8: 3871.7 | T8: 10236.6 | U8: 10241.6 | V8: 47713.1 | W8: 47769.7 | X8: 65.21
A9: 4 | B9: 36116.4 | C9: 36124.7 | D9: 116022 | E9: 116096 | J9: 4048.8 | K9: 4051.6 | L9: 2434.5 | M9: 2436.4 | N9: 2594 | O9: 2595.8 | P9: 1290.9 | Q9: 1291.9 | R9: 3874.4 | S9: 3876.3 | T9: 10249 | U9: 10254.2 | V9: 47849.1 | W9: 47905 | X9: 64.06
A10: 5 | B10: 36136 | C10: 36144.8 | D10: 116354 | E10: 116423 | J10: 4055.4 | K10: 4058.2 | L10: 2438.4 | M10: 2440.1 | N10: 2598.7 | O10: 2600.4 | P10: 1293.5 | Q10: 1294.6 | R10: 3879 | S10: 3880.8 | T10: 10261.4 | U10: 10266.5 | V10: 47978.7 | W10: 48032.5 | X10: 62.44
A11: 6 | B11: 36157.8 | C11: 36168.9 | D11: 116668 | E11: 116725 | J11: 4062.1 | K11: 4065.7 | L11: 2442.1 | M11: 2444.3 | N11: 2603.2 | O11: 2605.5 | P11: 1296.1 | Q11: 1297.6 | R11: 3883.6 | S11: 3885.9 | T11: 10274.2 | U11: 10280.6 | V11: 48115.2 | W11: 48188.5 | X11: 60.83
A12: 7 | B12: 36178.8 | C12: 36189 | D12: 116858 | E12: 116921 | J12: 4068.8 | K12: 4072.7 | L12: 2445.9 | M12: 2448.3 | N12: 2607.9 | O12: 2610.4 | P12: 1298.9 | Q12: 1300.2 | R12: 3888.1 | S12: 3890.6 | T12: 10286.6 | U12: 10293.7 | V12: 48257.4 | W12: 48341.5 | X12: 51.61
A13: 8 | B13: 36196.5 | C13: 36203.6 | D13: 117131 | E13: 117196 | J13: 4075.5 | K13: 4077.9 | L13: 2449.8 | M13: 2451.4 | N13: 2612.5 | O13: 2614.1 | P13: 1301.5 | Q13: 1302.3 | R13: 3892.6 | S13: 3894.3 | T13: 10299 | U13: 10303.9 | V13: 48400.9 | W13: 48454.9 | X13: 37.1
A14: 9 | B14: 36214.4 | C14: 36220.4 | D14: 117239 | E14: 117259 | J14: 4082 | K14: 4085.1 | L14: 2453.6 | M14: 2455.6 | N14: 2617.1 | O14: 2619.1 | P14: 1304 | Q14: 1305.4 | R14: 3897.1 | S14: 3899.2 | T14: 10311.7 | U14: 10317.4 | V14: 48535.8 | W14: 48590 | X14: 71.43
A15: 10 | B15: 36233.7 | C15: 36242.8 | D15: 117466 | E15: 117469 | J15: 4088.8 | K15: 4091.5 | L15: 2457.8 | M15: 2459.6 | N15: 2621.9 | O15: 2623.7 | P15: 1309 | Q15: 1308.1 | R15: 3901.9 | S15: 3903.6 | T15: 10324.8 | U15: 10329.7 | V15: 48679.8 | W15: 48740.2 | X15: 84.33
A16: 11 | B16: 36256.9 | C16: 36264.1 | D16: 117648 | E16: 117761 | J16: 4095.6 | K16: 4098.3 | L16: 2461.9 | M16: 2463.7 | N16: 2626.7 | O16: 2628.3 | P16: 1309.8 | Q16: 1310.8 | R16: 3906.5 | S16: 3908.2 | T16: 10337.7 | U16: 10342.4 | V16: 48831 | W16: 48891.2 | X16: 84.33
A17: 12 | B17: 36275.9 | C17: 36281.8 | D17: 117985 | E17: 118072 | J17: 4102.4 | K17: 4104.9 | L17: 2466.2 | M17: 2467.9 | N17: 2631.7 | O17: 2633.3 | P17: 1312.6 | Q17: 1313.6 | R17: 3911.2 | S17: 3912.9 | T17: 10350.7 | U17: 10355 | V17: 48983.2 | W17: 49037 | X17: 67.05
... A36: 31 | B36: 36578.3 | C36: 36588.1 | D36: 122563 | E36: 122881 | J36: 4230.7 | K36: 4235.1 | L36: 2541.2 | M36: 2544 | N36: 2724.5 | O36: 2727.4 | P36: 1365 | Q36: 1366.8 | R36: 4000.3 | S36: 4003.3 | T36: 10581.8 | U36: 10588.2 | V36: 51727.9 | W36: 51820.1 | X36: 97.93

Sheet 1
A1: ENGINEERING DEPARTMENT | J1: daily reading
A3: UTILITY CONSUMPTION SHEET
B4: JANUARY | C4: 1
A5: SR.NO | B5: ITEM MEASURED | D5: Previous Reading | E5: 1st Reading (5am) | F5: 2nd Reading (5pm) | G5: 12hrs CONSUMPTION | H5: 24hrs CONSUMPTION | I5: Cost
A7: 1 | B7: DISTRICT COOLING PLANT
B8: Chilled Water | C8: MWH | D8: 36048.5 | E8: ='Daily Meter'!B6 -> 36057.7 | F8: ='Daily Meter'!C6 -> 36065.5 | G8: =F8-E8 -> 7.8 | H8: =F8-D8 -> 17
C9: TR | G9: =G8*284.34 -> 2217.852 | H9: =H8*284.34 -> 4833.78 | I9: =H9*0.63 -> 3045.2814
A10: III | B10: WATER METERS
B11: Main DEWA Meter | C11: mᶟ | D11: 115212 | E11: ='Daily Meter'!D6 -> 115374 | F11: ='Daily Meter'!E6 -> 115376 | G11: =F11-E11 -> 2 | H11: =F11-D11 -> 164
B12: Imperial Gallon = m³ x 219.969 | C12: IG | G12: =G11*219.969 -> 439.938 | H12: =H11*219.969 -> 36074.916 | I12: =H12*0.06 -> 2164.495
A13: IV | B13: ELECTRICAL METERS
A14: 1 | B14: Meter 1 - 06065253 | C14: kW x 480 | D14: 4025.2 | E14: ='Daily Meter'!J6 -> 4028.1 | F14: ='Daily Meter'!K6 -> 4030.7 | G14: =(F14-E14)*480 -> 1248 | H14: =(F14-D14)*480 -> 2640
A15: 2 | B15: Meter 2 - 06065255 | C15: kW x 480 | D15: 2421.5 | E15: ='Daily Meter'!L6 -> 2422.9 | F15: ='Daily Meter'!M6 -> 2424.6 | G15: =(F15-E15)*480 -> 816 | H15: =(F15-D15)*480 -> 1488
A16: 3 | B16: Meter 3 - 06065259 | C16: kW x 480 | D16: 2578.1 | E16: ='Daily Meter'!N6 -> 2580.3 | F16: ='Daily Meter'!O6 -> 2581.8 | G16: =(F16-E16)*480 -> 720 | H16: =(F16-D16)*480 -> 1776
A17: 4 | B17: Meter 4 - 06065262 | C17: kW x 480 | D17: 1281.3 | E17: ='Daily Meter'!P6 -> 1282.6 | F17: ='Daily Meter'!Q6 -> 1283.4 | G17: =(F17-E17)*480 -> 384 | H17: =(F17-D17)*480 -> 1008
A18: 5 | B18: Meter 6 - 06065269 | C18: kW x 480 | D18: 3858.5 | E18: ='Daily Meter'!R6 -> 3860.6 | F18: ='Daily Meter'!S$6 -> 3862.3 | G18: =(F18-E18)*480 -> 816 | H18: =(F18-D18)*480 -> 1824
A19: 6 | B19: Meter 7 - 06065283 | C19: kW x 480 | D19: 10205.2 | E19: ='Daily Meter'!T6 -> 10211 | F19: ='Daily Meter'!U6 -> 10215.9 | G19: =(F19-E19)*480 -> 2352 | H19: =(F19-D19)*480 -> 5136
B20: TOTAL ELECTRICAL CONS.(kWh) | D20: =SUM(D14:D19) -> 24369.8 | G20: =SUM(G14:G19) -> 6336 | H20: =SUM(H14:H19) -> 13872 | I20: =H20*0.43 -> 5964.96
A22: V | B22: GAS CONSUMPTION
A23: 1 | B23: MAIN LPG METER | C23: mᶟ | D23: 47370.3 | E23: ='Daily Meter'!V6 -> 47434.7 | F23: ='Daily Meter'!W6 -> 47492.8 | G23: =F23-E23 -> 58.1 | H23: =F23-D23 -> 122.5
C24: L | H24: =H23*3.7 -> 453.25 | I24: =H24*1.79 -> 811.3175
D27: Summary of Daily Hotel consumption
D28: Item measured | E28: Units | F28: Consumption | G28: AED
D29: Chilled water | E29: TR | F29: =H9 -> 4833.78 | G29: =F29*0.63 -> 3045.2814
D30: DEWA Water | E30: imp. Gallon | F30: =H12 -> 36074.916 | G30: =F30*0.06 -> 2164.495
D31: Electricity | E31: kwh | F31: =H20 -> 13872 | G31: =F31*0.43 -> 5964.96
D32: Gas | E32: m3 | F32: =H23 -> 122.5 | G32: =I24 -> 811.3175
F33: Total cost | G33: =SUM(G29:G32) -> 11986.054

Sheet 2
A1: ENGINEERING DEPARTMENT | J1: daily reading
A3: UTILITY CONSUMPTION SHEET
B4: ='1'!B4 -> JANUARY | C4: 2
A5: SR.NO | B5: ITEM MEASURED | D5: Previous Reading | E5: 1st Reading (5am) | F5: 2nd Reading (5pm) | G5: 12hrs CONSUMPTION | H5: 24hrs CONSUMPTION | I5: Cost
A7: 1 | B7: DISTRICT COOLING PLANT
B8: Chilled Water | C8: MWH | D8: ='1'!F8 -> 36065.5 | E8: ='Daily Meter'!B7 -> 36076.8 | F8: ='Daily Meter'!C7 -> 36085.6 | G8: =F8-E8 -> 8.8 | H8: =F8-D8 -> 20.1
C9: TR | G9: =G8*284.34 -> 2502.192 | H9: =H8*284.34 -> 5715.234 | I9: =H9*0.63 -> 3600.5974
A10: III | B10: WATER METERS
B11: Main DEWA Meter | C11: mᶟ | D11: ='1'!F11 -> 115376 | E11: ='Daily Meter'!D7 -> 115550 | F11: ='Daily Meter'!E7 -> 115594 | G11: =F11-E11 -> 44 | H11: =F11-D11 -> 218
B12: Imperial Gallon = m³ x 219.969 | C12: IG | G12: =G11*219.969 -> 9678.636 | H12: =H11*219.969 -> 47953.242 | I12: =H12*0.06 -> 2877.1945
A13: IV | B13: ELECTRICAL METERS
A14: 1 | B14: Meter 1 - 06065253 | C14: kW x 480 | D14: ='1'!F14 -> 4030.7 | E14: ='Daily Meter'!J7 -> 4034.9 | F14: ='Daily Meter'!K7 -> 4037.7 | G14: =(F14-E14)*480 -> 1344 | H14: =(F14-D14)*480 -> 3360
A15: 2 | B15: Meter 2 - 06065255 | C15: kW x 480 | D15: ='1'!F15 -> 2424.6 | E15: ='Daily Meter'!L7 -> 2426.7 | F15: ='Daily Meter'!M7 -> 2428.5 | G15: =(F15-E15)*480 -> 864 | H15: =(F15-D15)*480 -> 1872
A16: 3 | B16: Meter 3 - 06065259 | C16: kW x 480 | D16: ='1'!F16 -> 2581.8 | E16: ='Daily Meter'!N7 -> 2584.1 | F16: ='Daily Meter'!O7 -> 2586.4 | G16: =(F16-E16)*480 -> 1104 | H16: =(F16-D16)*480 -> 2208
A17: 4 | B17: Meter 4 - 06065262 | C17: kW x 480 | D17: ='1'!F17 -> 1283.4 | E17: ='Daily Meter'!P7 -> 1285.1 | F17: ='Daily Meter'!Q7 -> 1286.1 | G17: =(F17-E17)*480 -> 480 | H17: =(F17-D17)*480 -> 1296
A18: 5 | B18: Meter 6 - 06065269 | C18: kW x 480 | D18: ='1'!F18 -> 3862.3 | E18: ='Daily Meter'!R7 -> 3865 | F18: ='Daily Meter'!S7 -> 3867 | G18: =(F18-E18)*480 -> 960 | H18: =(F18-D18)*480 -> 2256
A19: 6 | B19: Meter 7 - 06065283 | C19: kW x 480 | D19: ='1'!F19 -> 10215.9 | E19: ='Daily Meter'!T7 -> 10223.5 | F19: ='Daily Meter'!U7 -> 10228.9 | G19: =(F19-E19)*480 -> 2592 | H19: =(F19-D19)*480 -> 6240
B20: TOTAL ELECTRICAL CONS.(kWh) | G20: =SUM(G14:G19) -> 7344 | H20: =SUM(H14:H19) -> 17232 | I20: =H20*0.43 -> 7409.76
A22: V | B22: GAS CONSUMPTION
A23: 1 | B23: MAIN LPG METER | C23: mᶟ | D23: ='1'!F23 -> 47492.8 | E23: ='Daily Meter'!V7 -> 47571.5 | F23: ='Daily Meter'!W7 -> 47628.9 | G23: =F23-E23 -> 57.4 | H23: =F23-D23 -> 136.1
C24: L | H24: =H23*3.7 -> 503.57 | I24: =H24*1.79 -> 901.3903
D27: Summary of Daily Hotel consumption
D28: Item measured | E28: Units | F28: Consumption | G28: AED
D29: Chilled water | E29: TR | F29: =H9 -> 5715.234 | G29: =F29*0.63 -> 3600.5974
D30: DEWA Water | E30: imp. Gallon | F30: =H12 -> 47953.242 | G30: =F30*0.06 -> 2877.1945
D31: Electricity | E31: kwh | F31: =H20 -> 17232 | G31: =F31*0.43 -> 7409.76
D32: Gas | E32: m3 | F32: =H23 -> 136.1 | G32: =I24 -> 901.3903
F33: Total cost | G33: =SUM(G29:G32) -> 14788.942

Sheet 3
A1: ENGINEERING DEPARTMENT | J1: daily reading
A3: UTILITY CONSUMPTION SHEET
B4: ='1'!B4 -> JANUARY | C4: 3
A5: SR.NO | B5: ITEM MEASURED | D5: Previous Reading | E5: 1st Reading (5am) | F5: 2nd Reading (5pm) | G5: 12hrs CONSUMPTION | H5: 24hrs CONSUMPTION | I5: Cost
A7: 1 | B7: DISTRICT COOLING PLANT
B8: Chilled Water | C8: MWH | D8: ='2'!F8 -> 36085.6 | E8: ='Daily Meter'!B8 -> 36097.6 | F8: ='Daily Meter'!C8 -> 36105 | G8: =F8-E8 -> 7.4 | H8: =F8-D8 -> 19.4
C9: TR | G9: =G8*284.34 -> 2104.116 | H9: =H8*284.34 -> 5516.196 | I9: =H9*0.63 -> 3475.2035
A10: III | B10: WATER METERS
B11: Main DEWA Meter | C11: mᶟ | D11: ='2'!F11 -> 115594 | E11: ='Daily Meter'!D8 -> 115665 | F11: ='Daily Meter'!E8 -> 115731 | G11: =F11-E11 -> 66 | H11: =F11-D11 -> 137
B12: Imperial Gallon = m³ x 219.969 | C12: IG | G12: =G11*219.969 -> 14517.954 | H12: =H11*219.969 -> 30135.753 | I12: =H12*0.06 -> 1808.1452
A13: IV | B13: ELECTRICAL METERS
A14: 1 | B14: Meter 1 - 06065253 | C14: kW x 480 | D14: ='2'!F14 -> 4037.7 | E14: ='Daily Meter'!J8 -> 4042 | F14: ='Daily Meter'!K8 -> 4044.9 | G14: =(F14-E14)*480 -> 1392 | H14: =(F14-D14)*480 -> 3456
A15: 2 | B15: Meter 2 - 06065255 | C15: kW x 480 | D15: ='2'!F15 -> 2428.5 | E15: ='Daily Meter'!L8 -> 2430.5 | F15: ='Daily Meter'!M8 -> 2432.3 | G15: =(F15-E15)*480 -> 864 | H15: =(F15-D15)*480 -> 1824
A16: 3 | B16: Meter 3 - 06065259 | C16: kW x 480 | D16: ='2'!F16 -> 2586.4 | E16: ='Daily Meter'!N8 -> 2589.4 | F16: ='Daily Meter'!O8 -> 2591.1 | G16: =(F16-E16)*480 -> 816 | H16: =(F16-D16)*480 -> 2256
A17: 4 | B17: Meter 4 - 06065262 | C17: kW x 480 | D17: ='2'!F17 -> 1286.1 | E17: ='Daily Meter'!P8 -> 1287.8 | F17: ='Daily Meter'!Q8 -> 1288.9 | G17: =(F17-E17)*480 -> 528 | H17: =(F17-D17)*480 -> 1344
A18: 5 | B18: Meter 6 - 06065269 | C18: kW x 480 | D18: ='2'!F18 -> 3867 | E18: ='Daily Meter'!R8 -> 3869.8 | F18: ='Daily Meter'!S8 -> 3871.7 | G18: =(F18-E18)*480 -> 912 | H18: =(F18-D18)*480 -> 2256
A19: 6 | B19: Meter 7 - 06065283 | C19: kW x 480 | D19: ='2'!F19 -> 10228.9 | E19: ='Daily Meter'!T8 -> 10236.6 | F19: ='Daily Meter'!U8 -> 10241.6 | G19: =(F19-E19)*480 -> 2400 | H19: =(F19-D19)*480 -> 6096
B20: TOTAL ELECTRICAL CONS.(kWh) | G20: =SUM(G14:G19) -> 6912 | H20: =SUM(H14:H19) -> 17232 | I20: =H20*0.43 -> 7409.76
A22: V | B22: GAS CONSUMPTION
A23: 1 | B23: MAIN LPG METER | C23: mᶟ | D23: ='2'!F23 -> 47628.9 | E23: ='Daily Meter'!V8 -> 47713.1 | F23: ='Daily Meter'!W8 -> 47769.7 | G23: =F23-E23 -> 56.6 | H23: =F23-D23 -> 140.8
C24: L | H24: =H23*3.7 -> 520.96 | I24: =H24*1.79 -> 932.5184
D27: Summary of Daily Hotel consumption
D28: Item measured | E28: Units | F28: Consumption | G28: AED
D29: Chilled water | E29: TR | F29: =H9 -> 5516.196 | G29: =F29*0.63 -> 3475.2035
D30: DEWA Water | E30: imp. Gallon | F30: =H12 -> 30135.753 | G30: =F30*0.06 -> 1808.1452
D31: Electricity | E31: kwh | F31: =H20 -> 17232 | G31: =F31*0.43 -> 7409.76
D32: Gas | E32: m3 | F32: =H23 -> 140.8 | G32: =I24 -> 932.5184
F33: Total cost | G33: =SUM(G29:G32) -> 13625.627

Sheet 4
A1: ENGINEERING DEPARTMENT | J1: daily reading
A3: UTILITY CONSUMPTION SHEET
B4: ='1'!B4 -> JANUARY | C4: 4
A5: SR.NO | B5: ITEM MEASURED | D5: Previous Reading | E5: 1st Reading (5am) | F5: 2nd Reading (5pm) | G5: 12hrs CONSUMPTION | H5: 24hrs CONSUMPTION | I5: Cost
A7: 1 | B7: DISTRICT COOLING PLANT
B8: Chilled Water | C8: MWH | D8: ='3'!F8 -> 36105 | E8: ='Daily Meter'!B9 -> 36116.4 | F8: ='Daily Meter'!C9 -> 36124.7 | G8: =F8-E8 -> 8.3 | H8: =F8-D8 -> 19.7
C9: TR | G9: =G8*284.34 -> 2360.022 | H9: =H8*284.34 -> 5601.498 | I9: =H9*0.63 -> 3528.9437
A10: III | B10: WATER METERS
B11: Main DEWA Meter | C11: mᶟ | D11: ='3'!F11 -> 115731 | E11: ='Daily Meter'!D9 -> 116022 | F11: ='Daily Meter'!E9 -> 116096 | G11: =F11-E11 -> 74 | H11: =F11-D11 -> 365
B12: Imperial Gallon = m³ x 219.969 | C12: IG | G12: =G11*219.969 -> 16277.706 | H12: =H11*219.969 -> 80288.685 | I12: =H12*0.06 -> 4817.3211
A13: IV | B13: ELECTRICAL METERS
A14: 1 | B14: Meter 1 - 06065253 | C14: kW x 480 | D14: ='3'!F14 -> 4044.9 | E14: ='Daily Meter'!J9 -> 4048.8 | F14: ='Daily Meter'!K9 -> 4051.6 | G14: =(F14-E14)*480 -> 1344 | H14: =(F14-D14)*480 -> 3216
A15: 2 | B15: Meter 2 - 06065255 | C15: kW x 480 | D15: ='3'!F15 -> 2432.3 | E15: ='Daily Meter'!L9 -> 2434.5 | F15: ='Daily Meter'!M9 -> 2436.4 | G15: =(F15-E15)*480 -> 912 | H15: =(F15-D15)*480 -> 1968
A16: 3 | B16: Meter 3 - 06065259 | C16: kW x 480 | D16: ='3'!F16 -> 2591.1 | E16: ='Daily Meter'!N9 -> 2594 | F16: ='Daily Meter'!O9 -> 2595.8 | G16: =(F16-E16)*480 -> 864 | H16: =(F16-D16)*480 -> 2256
A17: 4 | B17: Meter 4 - 06065262 | C17: kW x 480 | D17: ='3'!F17 -> 1288.9 | E17: ='Daily Meter'!P9 -> 1290.9 | F17: ='Daily Meter'!Q9 -> 1291.9 | G17: =(F17-E17)*480 -> 480 | H17: =(F17-D17)*480 -> 1440
A18: 5 | B18: Meter 6 - 06065269 | C18: kW x 480 | D18: ='3'!F18 -> 3871.7 | E18: ='Daily Meter'!R9 -> 3874.4 | F18: ='Daily Meter'!S9 -> 3876.3 | G18: =(F18-E18)*480 -> 912 | H18: =(F18-D18)*480 -> 2208
A19: 6 | B19: Meter 7 - 06065283 | C19: kW x 480 | D19: ='3'!F19 -> 10241.6 | E19: ='Daily Meter'!T9 -> 10249 | F19: ='Daily Meter'!U9 -> 10254.2 | G19: =(F19-E19)*480 -> 2496 | H19: =(F19-D19)*480 -> 6048
B20: TOTAL ELECTRICAL CONS.(kWh) | G20: =SUM(G14:G19) -> 7008 | H20: =SUM(H14:H19) -> 17136 | I20: =H20*0.43 -> 7368.48
A22: V | B22: GAS CONSUMPTION
A23: 1 | B23: MAIN LPG METER | C23: mᶟ | D23: ='3'!F23 -> 47769.7 | E23: ='Daily Meter'!V9 -> 47849.1 | F23: ='Daily Meter'!W9 -> 47905 | G23: =F23-E23 -> 55.9 | H23: =F23-D23 -> 135.3
C24: L | H24: =H23*3.7 -> 500.61 | I24: =H24*1.79 -> 896.0919
D27: Summary of Daily Hotel consumption
D28: Item measured | E28: Units | F28: Consumption | G28: AED
D29: Chilled water | E29: TR | F29: =H9 -> 5601.498 | G29: =F29*0.63 -> 3528.9437
D30: DEWA Water | E30: imp. Gallon | F30: =H12 -> 80288.685 | G30: =F30*0.06 -> 4817.3211
D31: Electricity | E31: kwh | F31: =H20 -> 17136 | G31: =F31*0.43 -> 7368.48
D32: Gas | E32: m3 | F32: =H23 -> 135.3 | G32: =I24 -> 896.0919
F33: Total cost | G33: =SUM(G29:G32) -> 16610.837

Sheet 5
A1: ENGINEERING DEPARTMENT | J1: daily reading
A3: UTILITY CONSUMPTION SHEET
B4: ='1'!B4 -> JANUARY | C4: 5
A5: SR.NO | B5: ITEM MEASURED | D5: Previous Reading | E5: 1st Reading (5am) | F5: 2nd Reading (5pm) | G5: 12hrs CONSUMPTION | H5: 24hrs CONSUMPTION | I5: Cost
A7: 1 | B7: DISTRICT COOLING PLANT
B8: Chilled Water | C8: MWH | D8: ='4'!F8 -> 36124.7 | E8: ='Daily Meter'!B10 -> 36136 | F8: ='Daily Meter'!C10 -> 36144.8 | G8: =F8-E8 -> 8.8 | H8: =F8-D8 -> 20.1
C9: TR | G9: =G8*284.34 -> 2502.192 | H9: =H8*284.34 -> 5715.234 | I9: =H9*0.63 -> 3600.5974
A10: III | B10: WATER METERS
B11: Main DEWA Meter | C11: mᶟ | D11: ='4'!F11 -> 116096 | E11: ='Daily Meter'!D10 -> 116354 | F11: ='Daily Meter'!E10 -> 116423 | G11: =F11-E11 -> 69 | H11: =F11-D11 -> 327
B12: Imperial Gallon = m³ x 219.969 | C12: IG | G12: =G11*219.969 -> 15177.861 | H12: =H11*219.969 -> 71929.863 | I12: =H12*0.06 -> 4315.7918
A13: IV | B13: ELECTRICAL METERS
A14: 1 | B14: Meter 1 - 06065253 | C14: kW x 480 | D14: ='4'!F14 -> 4051.6 | E14: ='Daily Meter'!J10 -> 4055.4 | F14: ='Daily Meter'!K10 -> 4058.2 | G14: =(F14-E14)*480 -> 1344 | H14: =(F14-D14)*480 -> 3168
A15: 2 | B15: Meter 2 - 06065255 | C15: kW x 480 | D15: ='4'!F15 -> 2436.4 | E15: ='Daily Meter'!L10 -> 2438.4 | F15: ='Daily Meter'!M10 -> 2440.1 | G15: =(F15-E15)*480 -> 816 | H15: =(F15-D15)*480 -> 1776
A16: 3 | B16: Meter 3 - 06065259 | C16: kW x 480 | D16: ='4'!F16 -> 2595.8 | E16: ='Daily Meter'!N10 -> 2598.7 | F16: ='Daily Meter'!O10 -> 2600.4 | G16: =(F16-E16)*480 -> 816 | H16: =(F16-D16)*480 -> 2208
A17: 4 | B17: Meter 4 - 06065262 | C17: kW x 480 | D17: ='4'!F17 -> 1291.9 | E17: ='Daily Meter'!P10 -> 1293.5 | F17: ='Daily Meter'!Q10 -> 1294.6 | G17: =(F17-E17)*480 -> 528 | H17: =(F17-D17)*480 -> 1296
A18: 5 | B18: Meter 6 - 06065269 | C18: kW x 480 | D18: ='4'!F18 -> 3876.3 | E18: ='Daily Meter'!R10 -> 3879 | F18: ='Daily Meter'!S10 -> 3880.8 | G18: =(F18-E18)*480 -> 864 | H18: =(F18-D18)*480 -> 2160
A19: 6 | B19: Meter 7 - 06065283 | C19: kW x 480 | D19: ='4'!F19 -> 10254.2 | E19: ='Daily Meter'!T10 -> 10261.4 | F19: ='Daily Meter'!U10 -> 10266.5 | G19: =(F19-E19)*480 -> 2448 | H19: =(F19-D19)*480 -> 5904
B20: TOTAL ELECTRICAL CONS.(kWh) | G20: =SUM(G14:G19) -> 6816 | H20: =SUM(H14:H19) -> 16512 | I20: =H20*0.43 -> 7100.16
A22: V | B22: GAS CONSUMPTION
A23: 1 | B23: MAIN LPG METER | C23: mᶟ | D23: ='4'!F23 -> 47905 | E23: ='Daily Meter'!V10 -> 47978.7 | F23: ='Daily Meter'!W10 -> 48032.5 | G23: =F23-E23 -> 53.8 | H23: =F23-D23 -> 127.5
C24: L | H24: =H23*3.7 -> 471.75 | I24: =H24*1.79 -> 844.4325
D27: Summary of Daily Hotel consumption
D28: Item measured | E28: Units | F28: Consumption | G28: AED
D29: Chilled water | E29: TR | F29: =H9 -> 5715.234 | G29: =F29*0.63 -> 3600.5974
D30: DEWA Water | E30: imp. Gallon | F30: =H12 -> 71929.863 | G30: =F30*0.06 -> 4315.7918
D31: Electricity | E31: kwh | F31: =H20 -> 16512 | G31: =F31*0.43 -> 7100.16
D32: Gas | E32: m3 | F32: =H23 -> 127.5 | G32: =I24 -> 844.4325
F33: Total cost | G33: =SUM(G29:G32) -> 15860.982

Sheet 6
A1: ENGINEERING DEPARTMENT | J1: daily reading
A3: UTILITY CONSUMPTION SHEET
B4: ='1'!B4 -> JANUARY | C4: 6
A5: SR.NO | B5: ITEM MEASURED | D5: Previous Reading | E5: 1st Reading (5am) | F5: 2nd Reading (5pm) | G5: 12hrs CONSUMPTION | H5: 24hrs CONSUMPTION | I5: Cost
A7: 1 | B7: DISTRICT COOLING PLANT
B8: Chilled Water | C8: MWH | D8: ='5'!F8 -> 36144.8 | E8: ='Daily Meter'!B11 -> 36157.8 | F8: ='Daily Meter'!C11 -> 36168.9 | G8: =F8-E8 -> 11.1 | H8: =F8-D8 -> 24.1
C9: TR | G9: =G8*284.34 -> 3156.174 | H9: =H8*284.34 -> 6852.594 | I9: =H9*0.63 -> 4317.1342
A10: III | B10: WATER METERS
B11: Main DEWA Meter | C11: mᶟ | D11: ='5'!F11 -> 116423 | E11: ='Daily Meter'!D11 -> 116668 | F11: ='Daily Meter'!E11 -> 116725 | G11: =F11-E11 -> 57 | H11: =F11-D11 -> 302
B12: Imperial Gallon = m³ x 219.969 | C12: IG | G12: =G11*219.969 -> 12538.233 | H12: =H11*219.969 -> 66430.638 | I12: =H12*0.06 -> 3985.8383
A13: IV | B13: ELECTRICAL METERS
A14: 1 | B14: Meter 1 - 06065253 | C14: kW x 480 | D14: ='5'!F14 -> 4058.2 | E14: ='Daily Meter'!J11 -> 4062.1 | F14: ='Daily Meter'!K11 -> 4065.7 | G14: =(F14-E14)*480 -> 1728 | H14: =(F14-D14)*480 -> 3600
A15: 2 | B15: Meter 2 - 06065255 | C15: kW x 480 | D15: ='5'!F15 -> 2440.1 | E15: ='Daily Meter'!L11 -> 2442.1 | F15: ='Daily Meter'!M11 -> 2444.3 | G15: =(F15-E15)*480 -> 1056 | H15: =(F15-D15)*480 -> 2016
A16: 3 | B16: Meter 3 - 06065259 | C16: kW x 480 | D16: ='5'!F16 -> 2600.4 | E16: ='Daily Meter'!N11 -> 2603.2 | F16: ='Daily Meter'!O11 -> 2605.5 | G16: =(F16-E16)*480 -> 1104 | H16: =(F16-D16)*480 -> 2448
A17: 4 | B17: Meter 4 - 06065262 | C17: kW x 480 | D17: ='5'!F17 -> 1294.6 | E17: ='Daily Meter'!P11 -> 1296.1 | F17: ='Daily Meter'!Q11 -> 1297.6 | G17: =(F17-E17)*480 -> 720 | H17: =(F17-D17)*480 -> 1440
A18: 5 | B18: Meter 6 - 06065269 | C18: kW x 480 | D18: ='5'!F18 -> 3880.8 | E18: ='Daily Meter'!R11 -> 3883.6 | F18: ='Daily Meter'!S11 -> 3885.9 | G18: =(F18-E18)*480 -> 1104 | H18: =(F18-D18)*480 -> 2448
A19: 6 | B19: Meter 7 - 06065283 | C19: kW x 480 | D19: ='5'!F19 -> 10266.5 | E19: ='Daily Meter'!T11 -> 10274.2 | F19: ='Daily Meter'!U11 -> 10280.6 | G19: =(F19-E19)*480 -> 3072 | H19: =(F19-D19)*480 -> 6768
B20: TOTAL ELECTRICAL CONS.(kWh) | G20: =SUM(G14:G19) -> 8784 | H20: =SUM(H14:H19) -> 18720 | I20: =H20*0.43 -> 8049.6
A22: V | B22: GAS CONSUMPTION
A23: 1 | B23: MAIN LPG METER | C23: mᶟ | D23: ='5'!F23 -> 48032.5 | E23: ='Daily Meter'!V11 -> 48115.2 | F23: ='Daily Meter'!W11 -> 48188.5 | G23: =F23-E23 -> 73.3 | H23: =F23-D23 -> 156
C24: L | H24: =H23*3.7 -> 577.2 | I24: =H24*1.79 -> 1033.188
D27: Summary of Daily Hotel consumption
D28: Item measured | E28: Units | F28: Consumption | G28: AED
D29: Chilled water | E29: TR | F29: =H9 -> 6852.594 | G29: =F29*0.63 -> 4317.1342
D30: DEWA Water | E30: imp. Gallon | F30: =H12 -> 66430.638 | G30: =F30*0.06 -> 3985.8383
D31: Electricity | E31: kwh | F31: =H20 -> 18720 | G31: =F31*0.43 -> 8049.6
D32: Gas | E32: m3 | F32: =H23 -> 156 | G32: =I24 -> 1033.188
F33: Total cost | G33: =SUM(G29:G32) -> 17385.76

Sheet 7
A1: ENGINEERING DEPARTMENT | J1: daily reading
A3: UTILITY CONSUMPTION SHEET
B4: ='1'!B4 -> JANUARY | C4: 7
A5: SR.NO | B5: ITEM MEASURED | D5: Previous Reading | E5: 1st Reading (5am) | F5: 2nd Reading (5pm) | G5: 12hrs CONSUMPTION | H5: 24hrs CONSUMPTION | I5: Cost
A7: 1 | B7: DISTRICT COOLING PLANT
B8: Chilled Water | C8: MWH | D8: ='6'!F8 -> 36168.9 | E8: ='Daily Meter'!B12 -> 36178.8 | F8: ='Daily Meter'!C12 -> 36189 | G8: =F8-E8 -> 10.2 | H8: =F8-D8 -> 20.1
C9: TR | G9: =G8*284.34 -> 2900.268 | H9: =H8*284.34 -> 5715.234 | I9: =H9*0.63 -> 3600.5974
A10: III | B10: WATER METERS
B11: Main DEWA Meter | C11: mᶟ | D11: ='6'!F11 -> 116725 | E11: ='Daily Meter'!D12 -> 116858 | F11: ='Daily Meter'!E12 -> 116921 | G11: =F11-E11 -> 63 | H11: =F11-D11 -> 196
B12: Imperial Gallon = m³ x 219.969 | C12: IG | G12: =G11*219.969 -> 13858.047 | H12: =H11*219.969 -> 43113.924 | I12: =H12*0.06 -> 2586.8354
A13: IV | B13: ELECTRICAL METERS
A14: 1 | B14: Meter 1 - 06065253 | C14: kW x 480 | D14: ='6'!F14 -> 4065.7 | E14: ='Daily Meter'!J12 -> 4068.8 | F14: ='Daily Meter'!K12 -> 4072.7 | G14: =(F14-E14)*480 -> 1872 | H14: =(F14-D14)*480 -> 3360
A15: 2 | B15: Meter 2 - 06065255 | C15: kW x 480 | D15: ='6'!F15 -> 2444.3 | E15: ='Daily Meter'!L12 -> 2445.9 | F15: ='Daily Meter'!M12 -> 2448.3 | G15: =(F15-E15)*480 -> 1152 | H15: =(F15-D15)*480 -> 1920
A16: 3 | B16: Meter 3 - 06065259 | C16: kW x 480 | D16: ='6'!F16 -> 2605.5 | E16: ='Daily Meter'!N12 -> 2607.9 | F16: ='Daily Meter'!O12 -> 2610.4 | G16: =(F16-E16)*480 -> 1200 | H16: =(F16-D16)*480 -> 2352
A17: 4 | B17: Meter 4 - 06065262 | C17: kW x 480 | D17: ='6'!F17 -> 1297.6 | E17: ='Daily Meter'!P12 -> 1298.9 | F17: ='Daily Meter'!Q12 -> 1300.2 | G17: =(F17-E17)*480 -> 624 | H17: =(F17-D17)*480 -> 1248
A18: 5 | B18: Meter 6 - 06065269 | C18: kW x 480 | D18: ='6'!F18 -> 3885.9 | E18: ='Daily Meter'!R12 -> 3888.1 | F18: ='Daily Meter'!S12 -> 3890.6 | G18: =(F18-E18)*480 -> 1200 | H18: =(F18-D18)*480 -> 2256
A19: 6 | B19: Meter 7 - 06065283 | C19: kW x 480 | D19: ='6'!F19 -> 10280.6 | E19: ='Daily Meter'!T12 -> 10286.6 | F19: ='Daily Meter'!U12 -> 10293.7 | G19: =(F19-E19)*480 -> 3408 | H19: =(F19-D19)*480 -> 6288
B20: TOTAL ELECTRICAL CONS.(kWh) | G20: =SUM(G14:G19) -> 9456 | H20: =SUM(H14:H19) -> 17424 | I20: =H20*0.43 -> 7492.32
A22: V | B22: GAS CONSUMPTION
A23: 1 | B23: MAIN LPG METER | C23: mᶟ | D23: ='6'!F23 -> 48188.5 | E23: ='Daily Meter'!V12 -> 48257.4 | F23: ='Daily Meter'!W12 -> 48341.5 | G23: =F23-E23 -> 84.1 | H23: =F23-D23 -> 153
B24: L = m³ x 2.71 | C24: L | H24: =H23*3.7 -> 566.1 | I24: =H24*1.79 -> 1013.319
D27: Summary of Daily Hotel consumption
D28: Item measured | E28: Units | F28: Consumption | G28: AED
D29: Chilled water | E29: TR | F29: =H9 -> 5715.234 | G29: =I9 -> 3600.5974
D30: DEWA Water | E30: imp. Gallon | F30: =H12 -> 43113.924 | G30: =I12 -> 2586.8354
D31: Electricity | E31: kwh | F31: =H20 -> 17424 | G31: =I20 -> 7492.32
D32: Gas | E32: m3 | F32: =H23 -> 153 | G32: =I24 -> 1013.319
F33: Total cost | G33: =SUM(G29:G32) -> 14693.072

Sheet 8
A1: ENGINEERING DEPARTMENT | J1: daily reading
A3: UTILITY CONSUMPTION SHEET
B4: ='1'!B4 -> JANUARY | C4: 8
A5: SR.NO | B5: ITEM MEASURED | D5: Previous Reading | E5: 1st Reading (5am) | F5: 2nd Reading (5pm) | G5: 12hrs CONSUMPTION | H5: 24hrs CONSUMPTION | I5: Cost
A7: 1 | B7: DISTRICT COOLING PLANT
B8: Chilled Water | C8: MWH | D8: ='7'!F8 -> 36189 | E8: ='Daily Meter'!B13 -> 36196.5 | F8: ='Daily Meter'!C13 -> 36203.6 | G8: =F8-E8 -> 7.1 | H8: =F8-D8 -> 14.6
C9: TR | G9: =G8*284.34 -> 2018.814 | H9: =H8*284.34 -> 4151.364 | I9: =H9*0.63 -> 2615.3593
A10: III | B10: WATER METERS
B11: Main DEWA Meter | C11: mᶟ | D11: ='7'!F11 -> 116921 | E11: ='Daily Meter'!D13 -> 117131 | F11: ='Daily Meter'!E13 -> 117196 | G11: =F11-E11 -> 65 | H11: =F11-D11 -> 275
B12: Imperial Gallon = m³ x 219.969 | C12: IG | G12: =G11*219.969 -> 14297.985 | H12: =H11*219.969 -> 60491.475 | I12: =H12*0.06 -> 3629.4885
A13: IV | B13: ELECTRICAL METERS
A14: 1 | B14: Meter 1 - 06065253 | C14: kW x 480 | D14: ='7'!F14 -> 4072.7 | E14: ='Daily Meter'!J13 -> 4075.5 | F14: ='Daily Meter'!K13 -> 4077.9 | G14: =(F14-E14)*480 -> 1152 | H14: =(F14-D14)*480 -> 2496
A15: 2 | B15: Meter 2 - 06065255 | C15: kW x 480 | D15: ='7'!F15 -> 2448.3 | E15: ='Daily Meter'!L13 -> 2449.8 | F15: ='Daily Meter'!M13 -> 2451.4 | G15: =(F15-E15)*480 -> 768 | H15: =(F15-D15)*480 -> 1488
A16: 3 | B16: Meter 3 - 06065259 | C16: kW x 480 | D16: ='7'!F16 -> 2610.4 | E16: ='Daily Meter'!N13 -> 2612.5 | F16: ='Daily Meter'!O13 -> 2614.1 | G16: =(F16-E16)*480 -> 768 | H16: =(F16-D16)*480 -> 1776
A17: 4 | B17: Meter 4 - 06065262 | C17: kW x 480 | D17: ='7'!F17 -> 1300.2 | E17: ='Daily Meter'!P13 -> 1301.5 | F17: ='Daily Meter'!Q13 -> 1302.3 | G17: =(F17-E17)*480 -> 384 | H17: =(F17-D17)*480 -> 1008
A18: 5 | B18: Meter 6 - 06065269 | C18: kW x 480 | D18: ='7'!F18 -> 3890.6 | E18: ='Daily Meter'!R13 -> 3892.6 | F18: ='Daily Meter'!S13 -> 3894.3 | G18: =(F18-E18)*480 -> 816 | H18: =(F18-D18)*480 -> 1776
A19: 6 | B19: Meter 7 - 06065283 | C19: kW x 480 | D19: ='7'!F19 -> 10293.7 | E19: ='Daily Meter'!T13 -> 10299 | F19: ='Daily Meter'!U13 -> 10303.9 | G19: =(F19-E19)*480 -> 2352 | H19: =(F19-D19)*480 -> 4896
B20: TOTAL ELECTRICAL CONS.(kWh) | G20: =SUM(G14:G19) -> 6240 | H20: =SUM(H14:H19) -> 13440 | I20: =H20*0.43 -> 5779.2
A22: V | B22: GAS CONSUMPTION
A23: 1 | B23: MAIN LPG METER | C23: mᶟ | D23: ='7'!F23 -> 48341.5 | E23: ='Daily Meter'!V13 -> 48400.9 | F23: ='Daily Meter'!W13 -> 48454.9 | G23: =F23-E23 -> 54 | H23: =F23-D23 -> 113.4
B24: L = m³ x 3.7 | C24: L | H24: =H23*3.7 -> 419.58 | I24: =H24*1.79 -> 751.0482
D27: Summary of Daily Hotel consumption
D28: Item measured | E28: Units | F28: Consumption | G28: AED
D29: Chilled water | E29: TR | F29: =H9 -> 4151.364 | G29: =I9 -> 2615.3593
D30: DEWA Water | E30: imp. Gallon | F30: =H12 -> 60491.475 | G30: =I12 -> 3629.4885
D31: Electricity | E31: kwh | F31: =H20 -> 13440 | G31: =I20 -> 5779.2
D32: Gas | E32: m3 | F32: =H23 -> 113.4 | G32: =I24 -> 751.0482
F33: Total cost | G33: =SUM(G29:G32) -> 12775.096

Sheet 9
A1: ENGINEERING DEPARTMENT | J1: daily reading
A3: UTILITY CONSUMPTION SHEET
B4: ='1'!B4 -> JANUARY | C4: 9
A5: SR.NO | B5: ITEM MEASURED | D5: Previous Reading | E5: 1st Reading (5am) | F5: 2nd Reading (5pm) | G5: 12hrs CONSUMPTION | H5: 24hrs CONSUMPTION | I5: Cost
A7: 1 | B7: DISTRICT COOLING PLANT
B8: Chilled Water | C8: MWH | D8: ='8'!F8 -> 36203.6 | E8: ='Daily Meter'!B14 -> 36214.4 | F8: ='Daily Meter'!C14 -> 36220.4 | G8: =F8-E8 -> 6 | H8: =F8-D8 -> 16.8
C9: TR | G9: =G8*284.34 -> 1706.04 | H9: =H8*284.34 -> 4776.912 | I9: =H9*0.63 -> 3009.4546
A10: III | B10: WATER METERS
B11: Main DEWA Meter | C11: m3 | D11: ='8'!F11 -> 117196 | E11: ='Daily Meter'!D14 -> 117239 | F11: ='Daily Meter'!E14 -> 117259 | G11: =F11-E11 -> 20 | H11: =F11-D11 -> 63
B12: Imperial Gallon = m³ x 219.969 | C12: IG | G12: =G11*219.969 -> 4399.38 | H12: =H11*219.969 -> 13858.047 | I12: =H12*0.06 -> 831.48282
A13: IV | B13: ELECTRICAL METERS
A14: 1 | B14: Meter 1 - 06065253 | C14: kW x 480 | D14: ='8'!F14 -> 4077.9 | E14: ='Daily Meter'!J14 -> 4082 | F14: ='Daily Meter'!K14 -> 4085.1 | G14: =(F14-E14)*480 -> 1488 | H14: =(F14-D14)*480 -> 3456
A15: 2 | B15: Meter 2 - 06065255 | C15: kW x 480 | D15: ='8'!F15 -> 2451.4 | E15: ='Daily Meter'!L14 -> 2453.6 | F15: ='Daily Meter'!M14 -> 2455.6 | G15: =(F15-E15)*480 -> 960 | H15: =(F15-D15)*480 -> 2016
A16: 3 | B16: Meter 3 - 06065259 | C16: kW x 480 | D16: ='8'!F16 -> 2614.1 | E16: ='Daily Meter'!N14 -> 2617.1 | F16: ='Daily Meter'!O14 -> 2619.1 | G16: =(F16-E16)*480 -> 960 | H16: =(F16-D16)*480 -> 2400
A17: 4 | B17: Meter 4 - 06065262 | C17: kW x 480 | D17: ='8'!F17 -> 1302.3 | E17: ='Daily Meter'!P14 -> 1304 | F17: ='Daily Meter'!Q14 -> 1305.4 | G17: =(F17-E17)*480 -> 672 | H17: =(F17-D17)*480 -> 1488
A18: 5 | B18: Meter 6 - 06065269 | C18: kW x 480 | D18: ='8'!F18 -> 3894.3 | E18: ='Daily Meter'!R14 -> 3897.1 | F18: ='Daily Meter'!S14 -> 3899.2 | G18: =(F18-E18)*480 -> 1008 | H18: =(F18-D18)*480 -> 2352
A19: 6 | B19: Meter 7 - 06065283 | C19: kW x 480 | D19: ='8'!F19 -> 10303.9 | E19: ='Daily Meter'!T14 -> 10311.7 | F19: ='Daily Meter'!U14 -> 10317.4 | G19: =(F19-E19)*480 -> 2736 | H19: =(F19-D19)*480 -> 6480
B20: TOTAL ELECTRICAL CONS.(kWh) | G20: =SUM(G14:G19) -> 7824 | H20: =SUM(H14:H19) -> 18192 | I20: =H20*0.43 -> 7822.56
A22: V | B22: GAS CONSUMPTION
A23: 1 | B23: MAIN LPG METER | C23: M3 | D23: ='8'!F23 -> 48454.9 | E23: ='Daily Meter'!V14 -> 48535.8 | F23: ='Daily Meter'!W14 -> 48590 | G23: =F23-E23 -> 54.2 | H23: =F23-D23 -> 135.1
B24: L = m³ x 3.7 | C24: L | H24: =H23*3.7 -> 499.87 | I24: =H24*1.79 -> 894.7673
D27: Summary of Daily Hotel consumption
D28: Item measured | E28: Units | F28: Consumption | G28: AED
D29: Chilled water | E29: TR | F29: =H9 -> 4776.912 | G29: =I9 -> 3009.4546
D30: DEWA Water | E30: imp. Gallon | F30: =H12 -> 13858.047 | G30: =I12 -> 831.48282
D31: Electricity | E31: kwh | F31: =H20 -> 18192 | G31: =I20 -> 7822.56
D32: Gas | E32: m3 | F32: =H23 -> 135.1 | G32: =I24 -> 894.7673
F33: Total cost | G33: =SUM(G29:G32) -> 12558.265

Sheet 10
A1: ENGINEERING DEPARTMENT | J1: daily reading
A3: UTILITY CONSUMPTION SHEET
B4: NOVEMBER | C4: 10
A5: SR.NO | B5: ITEM MEASURED | C5: ='1'!B4 -> JANUARY | D5: Previous Reading | E5: 1st Reading (5am) | F5: 2nd Reading (5pm) | G5: 12hrs CONSUMPTION | H5: 24hrs CONSUMPTION | I5: Cost
A7: 1 | B7: DISTRICT COOLING PLANT
B8: Chilled Water | C8: MWH | D8: ='9'!F8 -> 36220.4 | E8: ='Daily Meter'!B15 -> 36233.7 | F8: ='Daily Meter'!C15 -> 36242.8 | G8: =F8-E8 -> 9.1 | H8: =F8-D8 -> 22.4
C9: TR | G9: =G8*284.34 -> 2587.494 | H9: =H8*284.34 -> 6369.216 | I9: =H9*0.63 -> 4012.6061
A10: III | B10: WATER METERS
B11: Main DEWA Meter | C11: m3 | D11: ='9'!F11 -> 117259 | E11: ='Daily Meter'!D15 -> 117466 | F11: ='Daily Meter'!E15 -> 117469 | G11: =F11-E11 -> 3 | H11: =F11-D11 -> 210
B12: Imperial Gallon = m³ x 219.969 | C12: IG | G12: =G11*219.969 -> 659.907 | H12: =H11*219.969 -> 46193.49 | I12: =H12*0.06 -> 2771.6094
A13: IV | B13: ELECTRICAL METERS
A14: 1 | B14: Meter 1 - 06065253 | C14: kW x 480 | D14: ='9'!F14 -> 4085.1 | E14: ='Daily Meter'!J15 -> 4088.8 | F14: ='Daily Meter'!K15 -> 4091.5 | G14: =(F14-E14)*480 -> 1296 | H14: =(F14-D14)*480 -> 3072
A15: 2 | B15: Meter 2 - 06065255 | C15: kW x 480 | D15: ='9'!F15 -> 2455.6 | E15: ='Daily Meter'!L15 -> 2457.8 | F15: ='Daily Meter'!M15 -> 2459.6 | G15: =(F15-E15)*480 -> 864 | H15: =(F15-D15)*480 -> 1920
A16: 3 | B16: Meter 3 - 06065259 | C16: kW x 480 | D16: ='9'!F16 -> 2619.1 | E16: ='Daily Meter'!N15 -> 2621.9 | F16: ='Daily Meter'!O15 -> 2623.7 | G16: =(F16-E16)*480 -> 864 | H16: =(F16-D16)*480 -> 2208
A17: 4 | B17: Meter 4 - 06065262 | C17: kW x 480 | D17: ='9'!F17 -> 1305.4 | E17: ='Daily Meter'!P15 -> 1309 | F17: ='Daily Meter'!Q15 -> 1308.1 | G17: =(F17-E17)*480 -> -432 | H17: =(F17-D17)*480 -> 1296
A18: 5 | B18: Meter 6 - 06065269 | C18: kW x 480 | D18: ='9'!F18 -> 3899.2 | E18: ='Daily Meter'!R15 -> 3901.9 | F18: ='Daily Meter'!S15 -> 3903.6 | G18: =(F18-E18)*480 -> 816 | H18: =(F18-D18)*480 -> 2112
A19: 6 | B19: Meter 7 - 06065283 | C19: kW x 480 | D19: ='9'!F19 -> 10317.4 | E19: ='Daily Meter'!T15 -> 10324.8 | F19: ='Daily Meter'!U15 -> 10329.7 | G19: =(F19-E19)*480 -> 2352 | H19: =(F19-D19)*480 -> 5904
B20: TOTAL ELECTRICAL CONS.(kWh) | G20: =SUM(G14:G19) -> 5760 | H20: =SUM(H14:H19) -> 16512 | I20: =H20*0.43 -> 7100.16
A22: V | B22: GAS CONSUMPTION
A23: 1 | B23: MAIN LPG METER | C23: M3 | D23: ='9'!F23 -> 48590 | E23: ='Daily Meter'!V15 -> 48679.8 | F23: ='Daily Meter'!W15 -> 48740.2 | G23: =F23-E23 -> 60.4 | H23: =F23-D23 -> 150.2
B24: L = m³ x 3.7 | C24: L | H24: =H23*3.7 -> 555.74 | I24: =H24*1.79 -> 994.7746
D27: Summary of Daily Hotel consumption
D28: Item measured | E28: Units | F28: Consumption | G28: AED
D29: Chilled water | E29: TR | F29: =H9 -> 6369.216 | G29: =I9 -> 4012.6061
D30: DEWA Water | E30: imp. Gallon | F30: =H12 -> 46193.49 | G30: =I12 -> 2771.6094
D31: Electricity | E31: kwh | F31: =H20 -> 16512 | G31: =I20 -> 7100.16
D32: Gas | E32: m3 | F32: =H23 -> 150.2 | G32: =I24 -> 994.7746
F33: Total cost | G33: =SUM(G29:G32) -> 14879.15

Sheet 11
A1: ENGINEERING DEPARTMENT | K1: daily reading
A3: UTILITY CONSUMPTION SHEET
B4: ='1'!B4 -> JANUARY | C4: 11
A5: SR.NO | B5: ITEM MEASURED | D5: Previous Reading | E5: 1st Reading (5am) | F5: 2nd Reading (5pm) | G5: 12hrs CONSUMPTION | H5: 24hrs CONSUMPTION | I5: Cost
A7: 1 | B7: DISTRICT COOLING PLANT
B8: Chilled Water | C8: MWH | D8: ='10'!F8 -> 36242.8 | E8: ='Daily Meter'!B16 -> 36256.9 | F8: ='Daily Meter'!C16 -> 36264.1 | G8: =F8-E8 -> 7.2 | H8: =F8-D8 -> 21.3
C9: TR | G9: =G8*284.34 -> 2047.248 | H9: =H8*284.34 -> 6056.442 | I9: =H9*0.63 -> 3815.5585
A10: III | B10: WATER METERS
B11: Main DEWA Meter | C11: m3 | D11: ='10'!F11 -> 117469 | E11: ='Daily Meter'!D16 -> 117648 | F11: ='Daily Meter'!E16 -> 117761 | G11: =F11-E11 -> 113 | H11: =F11-D11 -> 292
B12: Imperial Gallon = m³ x 219.969 | C12: IG | G12: =G11*219.969 -> 24856.497 | H12: =H11*219.969 -> 64230.948 | I12: =H12*0.06 -> 3853.8569
A13: IV | B13: ELECTRICAL METERS
A14: 1 | B14: Meter 1 - 06065253 | C14: kW x 480 | D14: ='10'!F14 -> 4091.5 | E14: ='Daily Meter'!J16 -> 4095.6 | F14: ='Daily Meter'!K16 -> 4098.3 | G14: =(F14-E14)*480 -> 1296 | H14: =(F14-D14)*480 -> 3264
A15: 2 | B15: Meter 2 - 06065255 | C15: kW x 480 | D15: ='10'!F15 -> 2459.6 | E15: ='Daily Meter'!L16 -> 2461.9 | F15: ='Daily Meter'!M16 -> 2463.7 | G15: =(F15-E15)*480 -> 864 | H15: =(F15-D15)*480 -> 1968
A16: 3 | B16: Meter 3 - 06065259 | C16: kW x 480 | D16: ='10'!F16 -> 2623.7 | E16: ='Daily Meter'!N16 -> 2626.7 | F16: ='Daily Meter'!O16 -> 2628.3 | G16: =(F16-E16)*480 -> 768 | H16: =(F16-D16)*480 -> 2208
A17: 4 | B17: Meter 4 - 06065262 | C17: kW x 480 | D17: ='10'!F17 -> 1308.1 | E17: ='Daily Meter'!P16 -> 1309.8 | F17: ='Daily Meter'!Q16 -> 1310.8 | G17: =(F17-E17)*480 -> 480 | H17: =(F17-D17)*480 -> 1296
A18: 5 | B18: Meter 6 - 06065269 | C18: kW x 480 | D18: ='10'!F18 -> 3903.6 | E18: ='Daily Meter'!R16 -> 3906.5 | F18: ='Daily Meter'!S16 -> 3908.2 | G18: =(F18-E18)*480 -> 816 | H18: =(F18-D18)*480 -> 2208
A19: 6 | B19: Meter 7 - 06065283 | C19: kW x 480 | D19: ='10'!F19 -> 10329.7 | E19: ='Daily Meter'!T16 -> 10337.7 | F19: ='Daily Meter'!U16 -> 10342.4 | G19: =(F19-E19)*480 -> 2256 | H19: =(F19-D19)*480 -> 6096
B20: TOTAL ELECTRICAL CONS.(kWh) | G20: =SUM(G14:G19) -> 6480 | H20: =SUM(H14:H19) -> 17040 | I20: =H20*0.43 -> 7327.2
A22: V | B22: GAS CONSUMPTION
A23: 1 | B23: MAIN LPG METER | C23: M3 | D23: ='10'!F23 -> 48740.2 | E23: ='Daily Meter'!V16 -> 48831 | F23: ='Daily Meter'!W16 -> 48891.2 | G23: =F23-E23 -> 60.2 | H23: =F23-D23 -> 151
B24: L = m³ x 3.7 | C24: L | H24: =H23*3.7 -> 558.7 | I24: =H24*1.79 -> 1000.073
D27: Summary of Daily Hotel consumption
D28: Item measured | E28: Units | F28: Consumption | G28: AED
D29: Chilled water | E29: TR | F29: =H9 -> 6056.442 | G29: =I9 -> 3815.5585
D30: DEWA Water | E30: imp. Gallon | F30: =H12 -> 64230.948 | G30: =I12 -> 3853.8569
D31: Electricity | E31: kwh | F31: =H20 -> 17040 | G31: =I20 -> 7327.2
D32: Gas | E32: m3 | F32: =H23 -> 151 | G32: =I24 -> 1000.073
F33: Total cost | G33: =SUM(G29:G32) -> 15996.688

Sheet 12
A1: ENGINEERING DEPARTMENT | K1: daily reading
A3: UTILITY CONSUMPTION SHEET
B4: ='1'!B4 -> JANUARY | C4: 12
A5: SR.NO | B5: ITEM MEASURED | D5: Previous Reading | E5: 1st Reading (5am) | F5: 2nd Reading (5pm) | G5: 12hrs CONSUMPTION | H5: 24hrs CONSUMPTION | I5: Cost
A7: 1 | B7: DISTRICT COOLING PLANT
B8: Chilled Water | C8: MWH | D8: ='11'!F8 -> 36264.1 | E8: ='Daily Meter'!B17 -> 36275.9 | F8: ='Daily Meter'!C17 -> 36281.8 | G8: =F8-E8 -> 5.9 | H8: =F8-D8 -> 17.7
C9: TR | G9: =G8*284.34 -> 1677.606 | H9: =H8*284.34 -> 5032.818 | I9: =H9*0.63 -> 3170.6753
A10: III | B10: WATER METERS
B11: Main DEWA Meter | C11: m3 | D11: ='11'!F11 -> 117761 | E11: ='Daily Meter'!D17 -> 117985 | F11: ='Daily Meter'!E17 -> 118072 | G11: =F11-E11 -> 87 | H11: =F11-D11 -> 311
B12: Imperial Gallon = m³ x 219.969 | C12: IG | G12: =G11*219.969 -> 19137.303 | H12: =H11*219.969 -> 68410.359 | I12: =H12*0.06 -> 4104.6215
A13: IV | B13: ELECTRICAL METERS
A14: 1 | B14: Meter 1 - 06065253 | C14: kW x 480 | D14: ='11'!F14 -> 4098.3 | E14: ='Daily Meter'!J17 -> 4102.4 | F14: ='Daily Meter'!K17 -> 4104.9 | G14: =(F14-E14)*480 -> 1200 | H14: =(F14-D14)*480 -> 3168
A15: 2 | B15: Meter 2 - 06065255 | C15: kW x 480 | D15: ='11'!F15 -> 2463.7 | E15: ='Daily Meter'!L17 -> 2466.2 | F15: ='Daily Meter'!M17 -> 2467.9 | G15: =(F15-E15)*480 -> 816 | H15: =(F15-D15)*480 -> 2016
A16: 3 | B16: Meter 3 - 06065259 | C16: kW x 480 | D16: ='11'!F16 -> 2628.3 | E16: ='Daily Meter'!N17 -> 2631.7 | F16: ='Daily Meter'!O17 -> 2633.3 | G16: =(F16-E16)*480 -> 768 | H16: =(F16-D16)*480 -> 2400
A17: 4 | B17: Meter 4 - 06065262 | C17: kW x 480 | D17: ='11'!F17 -> 1310.8 | E17: ='Daily Meter'!P17 -> 1312.6 | F17: ='Daily Meter'!Q17 -> 1313.6 | G17: =(F17-E17)*480 -> 480 | H17: =(F17-D17)*480 -> 1344
A18: 5 | B18: Meter 6 - 06065269 | C18: kW x 480 | D18: ='11'!F18 -> 3908.2 | E18: ='Daily Meter'!R17 -> 3911.2 | F18: ='Daily Meter'!S17 -> 3912.9 | G18: =(F18-E18)*480 -> 816 | H18: =(F18-D18)*480 -> 2256
A19: 6 | B19: Meter 7 - 06065283 | C19: kW x 480 | D19: ='11'!F19 -> 10342.4 | E19: ='Daily Meter'!T17 -> 10350.7 | F19: ='Daily Meter'!U17 -> 10355 | G19: =(F19-E19)*480 -> 2064 | H19: =(F19-D19)*480 -> 6048
B20: TOTAL ELECTRICAL CONS.(kWh) | G20: =SUM(G14:G19) -> 6144 | H20: =SUM(H14:H19) -> 17232 | I20: =H20*0.43 -> 7409.76
A22: V | B22: GAS CONSUMPTION
A23: 1 | B23: MAIN LPG METER | C23: M3 | D23: ='11'!F23 -> 48891.2 | E23: ='Daily Meter'!V17 -> 48983.2 | F23: ='Daily Meter'!W17 -> 49037 | G23: =F23-E23 -> 53.8 | H23: =F23-D23 -> 145.8
B24: L = m³ x 3.7 | C24: L | H24: =H23*3.7 -> 539.46 | I24: =H24*1.79 -> 965.6334
D27: Summary of Daily Hotel consumption
D28: Item measured | E28: Units | F28: Consumption | G28: AED
D29: Chilled water | E29: TR | F29: =H9 -> 5032.818 | G29: =I9 -> 3170.6753
D30: DEWA Water | E30: imp. Gallon | F30: =H12 -> 68410.359 | G30: =I12 -> 4104.6215
D31: Electricity | E31: kwh | F31: =H20 -> 17232 | G31: =I20 -> 7409.76
D32: Gas | E32: m3 | F32: =H23 -> 145.8 | G32: =I24 -> 965.6334
F33: Total cost | G33: =SUM(G29:G32) -> 15650.69

Sheet 13
A1: ENGINEERING DEPARTMENT | K1: daily reading
A3: UTILITY CONSUMPTION SHEET
B4: ='1'!B4 -> JANUARY | C4: 13
A5: SR.NO | B5: ITEM MEASURED | D5: Previous Reading | E5: 1st Reading (5am) | F5: 2nd Reading (5pm) | G5: 12hrs CONSUMPTION | H5: 24hrs CONSUMPTION | I5: Cost
A7: 1 | B7: DISTRICT COOLING PLANT
B8: Chilled Water | C8: MWH | D8: ='12'!F8 -> 36281.8 | E8: ='Daily Meter'!B18 -> 36292.5 | F8: ='Daily Meter'!C18 -> 36298.1 | G8: =F8-E8 -> 5.6 | H8: =F8-D8 -> 16.3
C9: TR | G9: =G8*284.34 -> 1592.304 | H9: =H8*284.34 -> 4634.742 | I9: =H9*0.63 -> 2919.8875
A10: III | B10: WATER METERS
B11: Main DEWA Meter | C11: m3 | D11: ='12'!F11 -> 118072 | E11: ='Daily Meter'!D18 -> 118299 | F11: ='Daily Meter'!E18 -> 118303 | G11: =F11-E11 -> 4 | H11: =F11-D11 -> 231
B12: Imperial Gallon = m³ x 219.969 | C12: IG | G12: =G11*219.969 -> 879.876 | H12: =H11*219.969 -> 50812.839 | I12: =H12*0.06 -> 3048.7703
A13: IV | B13: ELECTRICAL METERS
A14: 1 | B14: Meter 1 - 06065253 | C14: kW x 480 | D14: ='12'!F14 -> 4104.9 | E14: ='Daily Meter'!J18 -> 4109.2 | F14: ='Daily Meter'!K18 -> 4111.9 | G14: =(F14-E14)*480 -> 1296 | H14: =(F14-D14)*480 -> 3360
A15: 2 | B15: Meter 2 - 06065255 | C15: kW x 480 | D15: ='12'!F15 -> 2467.9 | E15: ='Daily Meter'!L18 -> 2470.2 | F15: ='Daily Meter'!M18 -> 2471.9 | G15: =(F15-E15)*480 -> 816 | H15: =(F15-D15)*480 -> 1920
A16: 3 | B16: Meter 3 - 06065259 | C16: kW x 480 | D16: ='12'!F16 -> 2633.3 | E16: ='Daily Meter'!N18 -> 2636.6 | F16: ='Daily Meter'!O18 -> 2638.3 | G16: =(F16-E16)*480 -> 816 | H16: =(F16-D16)*480 -> 2400
A17: 4 | B17: Meter 4 - 06065262 | C17: kW x 480 | D17: ='12'!F17 -> 1313.6 | E17: ='Daily Meter'!P18 -> 1315.6 | F17: ='Daily Meter'!Q18 -> 1316.6 | G17: =(F17-E17)*480 -> 480 | H17: =(F17-D17)*480 -> 1440
A18: 5 | B18: Meter 6 - 06065269 | C18: kW x 480 | D18: ='12'!F18 -> 3912.9 | E18: ='Daily Meter'!R18 -> 3915.9 | F18: ='Daily Meter'!S18 -> 3917.6 | G18: =(F18-E18)*480 -> 816 | H18: =(F18-D18)*480 -> 2256
A19: 6 | B19: Meter 7 - 06065283 | C19: kW x 480 | D19: ='12'!F19 -> 10355 | E19: ='Daily Meter'!T18 -> 10363.1 | F19: ='Daily Meter'!U18 -> 10367.5 | G19: =(F19-E19)*480 -> 2112 | H19: =(F19-D19)*480 -> 6000
B20: TOTAL ELECTRICAL CONS.(kWh) | G20: =SUM(G14:G19) -> 6336 | H20: =SUM(H14:H19) -> 17376 | I20: =H20*0.43 -> 7471.68
A22: V | B22: GAS CONSUMPTION
A23: 1 | B23: MAIN LPG METER | C23: M3 | D23: ='12'!F23 -> 49037 | E23: ='Daily Meter'!V18 -> 49127.3 | F23: ='Daily Meter'!W18 -> 49177.5 | G23: =F23-E23 -> 50.2 | H23: =F23-D23 -> 140.5
B24: L = m³ x 3.7 | C24: L | H24: =H23*3.7 -> 519.85 | I24: =H24*1.79 -> 930.5315
D27: Summary of Daily Hotel consumption
D28: Item measured | E28: Units | F28: Consumption | G28: AED
D29: Chilled water | E29: TR | F29: =H9 -> 4634.742 | G29: =I9 -> 2919.8875
D30: DEWA Water | E30: imp. Gallon | F30: =H12 -> 50812.839 | G30: =I12 -> 3048.7703
D31: Electricity | E31: kwh | F31: =H20 -> 17376 | G31: =I20 -> 7471.68
D32: Gas | E32: m3 | F32: =H23 -> 140.5 | G32: =I24 -> 930.5315
F33: Total cost | G33: =SUM(G29:G32) -> 14370.869

Sheet 14
A1: ENGINEERING DEPARTMENT | J1: daily reading
A3: UTILITY CONSUMPTION SHEET
B4: ='1'!B4 -> JANUARY | C4: 14
A5: SR.NO | B5: ITEM MEASURED | D5: Previous Reading | E5: 1st Reading (5am) | F5: 2nd Reading (5pm) | G5: 12hrs CONSUMPTION | H5: 24hrs CONSUMPTION | I5: Cost
A7: 1 | B7: DISTRICT COOLING PLANT
B8: Chilled Water | C8: MWH | D8: ='13'!F8 -> 36298.1 | E8: ='Daily Meter'!B19 -> 36307.9 | F8: ='Daily Meter'!C19 -> 36313.9 | G8: =F8-E8 -> 6 | H8: =F8-D8 -> 15.8
C9: TR | G9: =G8*284.34 -> 1706.04 | H9: =H8*284.34 -> 4492.572 | I9: =H9*0.63 -> 2830.3204
A10: III | B10: WATER METERS
B11: Main DEWA Meter | C11: m3 | D11: ='13'!F11 -> 118303 | E11: ='Daily Meter'!D19 -> 118479 | F11: ='Daily Meter'!E19 -> 118528 | G11: =F11-E11 -> 49 | H11: =F11-D11 -> 225
B12: Imperial Gallon = m³ x 219.969 | C12: IG | G12: =G11*219.969 -> 10778.481 | H12: =H11*219.969 -> 49493.025 | I12: =H12*0.06 -> 2969.5815
A13: IV | B13: ELECTRICAL METERS
A14: 1 | B14: Meter 1 - 06065253 | C14: kW x 480 | D14: ='13'!F14 -> 4111.9 | E14: ='Daily Meter'!J19 -> 4115.6 | F14: ='Daily Meter'!K19 -> 4118.6 | G14: =(F14-E14)*480 -> 1440 | H14: =(F14-D14)*480 -> 3216
A15: 2 | B15: Meter 2 - 06065255 | C15: kW x 480 | D15: ='13'!F15 -> 2471.9 | E15: ='Daily Meter'!L19 -> 2474.1 | F15: ='Daily Meter'!M19 -> 2475.8 | G15: =(F15-E15)*480 -> 816 | H15: =(F15-D15)*480 -> 1872
A16: 3 | B16: Meter 3 - 06065259 | C16: kW x 480 | D16: ='13'!F16 -> 2638.3 | E16: ='Daily Meter'!N19 -> 2641.4 | F16: ='Daily Meter'!O19 -> 2643.3 | G16: =(F16-E16)*480 -> 912 | H16: =(F16-D16)*480 -> 2400
A17: 4 | B17: Meter 4 - 06065262 | C17: kW x 480 | D17: ='13'!F17 -> 1316.6 | E17: ='Daily Meter'!P19 -> 1318.6 | F17: ='Daily Meter'!Q19 -> 1319.6 | G17: =(F17-E17)*480 -> 480 | H17: =(F17-D17)*480 -> 1440
A18: 5 | B18: Meter 6 - 06065269 | C18: kW x 480 | D18: ='13'!F18 -> 3917.6 | E18: ='Daily Meter'!R19 -> 3920.3 | F18: ='Daily Meter'!S19 -> 3922.3 | G18: =(F18-E18)*480 -> 960 | H18: =(F18-D18)*480 -> 2256
A19: 6 | B19: Meter 7 - 06065283 | C19: kW x 480 | D19: ='13'!F19 -> 10367.5 | E19: ='Daily Meter'!T19 -> 10374.7 | F19: ='Daily Meter'!U19 -> 10379.8 | G19: =(F19-E19)*480 -> 2448 | H19: =(F19-D19)*480 -> 5904
B20: TOTAL ELECTRICAL CONS.(kWh) | G20: =SUM(G14:G19) -> 7056 | H20: =SUM(H14:H19) -> 17088 | I20: =H20*0.43 -> 7347.84
A22: V | B22: GAS CONSUMPTION
A23: 1 | B23: MAIN LPG METER | C23: M3 | D23: ='13'!F23 -> 49177.5 | E23: ='Daily Meter'!V19 -> 49261.6 | F23: ='Daily Meter'!W19 -> 49322.6 | G23: =F23-E23 -> 61 | H23: =F23-D23 -> 145.1
B24: L = m³ x 3.7 | C24: L | H24: =H23*3.7 -> 536.87 | I24: =H24*1.79 -> 960.9973
D27: Summary of Daily Hotel consumption
D28: Item measured | E28: Units | F28: Consumption | G28: AED
D29: Chilled water | E29: TR | F29: =H9 -> 4492.572 | G29: =I9 -> 2830.3204
D30: DEWA Water | E30: imp. Gallon | F30: =H12 -> 49493.025 | G30: =I12 -> 2969.5815
D31: Electricity | E31: kwh | F31: =H20 -> 17088 | G31: =I20 -> 7347.84
D32: Gas | E32: m3 | F32: =H23 -> 145.1 | G32: =I24 -> 960.9973
F33: Total cost | G33: =SUM(G29:G32) -> 14108.739

Sheet 15
A1: ENGINEERING DEPARTMENT | J1: daily reading
A3: UTILITY CONSUMPTION SHEET
B4: ='1'!B4 -> JANUARY | C4: 15
A5: SR.NO | B5: ITEM MEASURED | D5: Previous Reading | E5: 1st Reading (5am) | F5: 2nd Reading (5pm) | G5: 12hrs CONSUMPTION | H5: 24hrs CONSUMPTION | I5: Cost
A7: 1 | B7: DISTRICT COOLING PLANT
B8: Chilled Water | C8: MWH | D8: ='14'!F8 -> 36313.9 | E8: ='Daily Meter'!B20 -> 36323.2 | F8: ='Daily Meter'!C20 -> 36330 | G8: =F8-E8 -> 6.8 | H8: =F8-D8 -> 16.1
C9: TR | G9: =G8*284.34 -> 1933.512 | H9: =H8*284.34 -> 4577.874 | I9: =H9*0.63 -> 2884.0606
A10: III | B10: WATER METERS
B11: Main DEWA Meter | C11: m3 | D11: ='14'!F11 -> 118528 | E11: ='Daily Meter'!D20 -> 118817 | F11: ='Daily Meter'!E20 -> 118825 | G11: =F11-E11 -> 8 | H11: =F11-D11 -> 297
B12: Imperial Gallon = m³ x 219.969 | C12: IG | G12: =G11*219.969 -> 1759.752 | H12: =H11*219.969 -> 65330.793 | I12: =H12*0.06 -> 3919.8476
A13: IV | B13: ELECTRICAL METERS
A14: 1 | B14: Meter 1 - 06065253 | C14: kW x 480 | D14: ='14'!F14 -> 4118.6 | E14: ='Daily Meter'!J20 -> 4122.3 | F14: ='Daily Meter'!K20 -> 4125.2 | G14: =(F14-E14)*480 -> 1392 | H14: =(F14-D14)*480 -> 3168
A15: 2 | B15: Meter 2 - 06065255 | C15: kW x 480 | D15: ='14'!F15 -> 2475.8 | E15: ='Daily Meter'!L20 -> 2477.8 | F15: ='Daily Meter'!M20 -> 2479.5 | G15: =(F15-E15)*480 -> 816 | H15: =(F15-D15)*480 -> 1776
A16: 3 | B16: Meter 3 - 06065259 | C16: kW x 480 | D16: ='14'!F16 -> 2643.3 | E16: ='Daily Meter'!N20 -> 2646 | F16: ='Daily Meter'!O20 -> 2647.9 | G16: =(F16-E16)*480 -> 912 | H16: =(F16-D16)*480 -> 2208
A17: 4 | B17: Meter 4 - 06065262 | C17: kW x 480 | D17: ='14'!F17 -> 1319.6 | E17: ='Daily Meter'!P20 -> 1321.2 | F17: ='Daily Meter'!Q20 -> 1322.4 | G17: =(F17-E17)*480 -> 576 | H17: =(F17-D17)*480 -> 1344
A18: 5 | B18: Meter 6 - 06065269 | C18: kW x 480 | D18: ='14'!F18 -> 3922.3 | E18: ='Daily Meter'!R20 -> 3924.8 | F18: ='Daily Meter'!S20 -> 3926.8 | G18: =(F18-E18)*480 -> 960 | H18: =(F18-D18)*480 -> 2160
A19: 6 | B19: Meter 7 - 06065283 | C19: kW x 480 | D19: ='14'!F19 -> 10379.8 | E19: ='Daily Meter'!T20 -> 10386.2 | F19: ='Daily Meter'!U20 -> 10391.7 | G19: =(F19-E19)*480 -> 2640 | H19: =(F19-D19)*480 -> 5712
B20: TOTAL ELECTRICAL CONS.(kWh) | G20: =SUM(G14:G19) -> 7296 | H20: =SUM(H14:H19) -> 16368 | I20: =H20*0.43 -> 7038.24
A22: V | B22: GAS CONSUMPTION
A23: 1 | B23: MAIN LPG METER | C23: M3 | D23: ='14'!F23 -> 49322.6 | E23: ='Daily Meter'!V20 -> 49402.8 | F23: ='Daily Meter'!W20 -> 49460.3 | G23: =F23-E23 -> 57.5 | H23: =F23-D23 -> 137.7
B24: L = m³ x 3.7 | C24: L | H24: =H23*3.7 -> 509.49 | I24: =H24*1.79 -> 911.9871
D27: Summary of Daily Hotel consumption
D28: Item measured | E28: Units | F28: Consumption | G28: AED
D29: Chilled water | E29: TR | F29: =H9 -> 4577.874 | G29: =I9 -> 2884.0606
D30: DEWA Water | E30: imp. Gallon | F30: =H12 -> 65330.793 | G30: =I12 -> 3919.8476
D31: Electricity | E31: kwh | F31: =H20 -> 16368 | G31: =I20 -> 7038.24
D32: Gas | E32: m3 | F32: =H23 -> 137.7 | G32: =I24 -> 911.9871
F33: Total cost | G33: =SUM(G29:G32) -> 14754.135

Sheet 16
