Workbook

Sheet Total
A1: Site Name | B1: Day | C1: Month | D1: Year | E1: Total Electricity Kwh | F1: Electricity Tariff ($/Kwh) | G1: LPG (Liters) | H1: LPG $/Liters | I1: Water Utility Supply (IG) IG | J1: Water Utility Supply (IG) $/IG | K1: District Energy Cooling RTH | L1: District Energy Cooling $/RTH | M1: Room Nights | N1: Total Guests
A2: 25hours Dubai One Central | B2: 1 | C2: 2 | D2: 2024 | E2: =Submetering!E2+Submetering!F2+Submetering!G2+Submetering!H2+Submetering!I2+Submetering!J2 -> 16704 | F2: 0.44 | G2: =Submetering!M2 -> 15863.38 | H2: 2.5 | I2: =Submetering!L2 -> 100305.86 | J2: 0.06 | K2: =Submetering!K2 -> 12909.036 | L2: =0.568+0.075 -> 0.643 | M2: =INT('Daily Meter'!O6*434/100) -> 330
A3: 25hours Dubai One Central | B3: =B2+1 -> 2 | C3: 2 | D3: 2024 | E3: =Submetering!E3+Submetering!F3+Submetering!G3+Submetering!H3+Submetering!I3+Submetering!J3 -> 16896 | F3: 0.44 | G3: =Submetering!M3 -> 519.11 | H3: 2.5 | I3: =Submetering!L3 -> 36954.792 | J3: 0.06 | K3: =Submetering!K3 -> 6852.594 | L3: =0.568+0.075 -> 0.643 | M3: =INT('Daily Meter'!O7*434/100) -> 236
A4: 25hours Dubai One Central | B4: =B3+1 -> 3 | C4: 2 | D4: 2024 | E4: =Submetering!E4+Submetering!F4+Submetering!G4+Submetering!H4+Submetering!I4+Submetering!J4 -> 17136 | F4: 0.44 | G4: =Submetering!M4 -> 493.58 | H4: 2.5 | I4: =Submetering!L4 -> 38714.544 | J4: 0.06 | K4: =Submetering!K4 -> 5999.574 | L4: =0.568+0.075 -> 0.643 | M4: =INT('Daily Meter'!O8*434/100) -> 209
A5: 25hours Dubai One Central | B5: =B4+1 -> 4 | C5: 2 | D5: 2024 | E5: =Submetering!E5+Submetering!F5+Submetering!G5+Submetering!H5+Submetering!I5+Submetering!J5 -> 17040 | F5: 0.44 | G5: =Submetering!M5 -> 491.36 | H5: 2.5 | I5: =Submetering!L5 -> 38054.637 | J5: 0.06 | K5: =Submetering!K5 -> 5146.554 | L5: =0.568+0.075 -> 0.643 | M5: =INT('Daily Meter'!O9*434/100) -> 306
A6: 25hours Dubai One Central | B6: =B5+1 -> 5 | C6: 2 | D6: 2024 | E6: =Submetering!E6+Submetering!F6+Submetering!G6+Submetering!H6+Submetering!I6+Submetering!J6 -> 16992 | F6: 0.44 | G6: =Submetering!M6 -> 468.42 | H6: 2.5 | I6: =Submetering!L6 -> 36514.854 | J6: 0.06 | K6: =Submetering!K6 -> 4919.082 | L6: =0.568+0.075 -> 0.643 | M6: =INT('Daily Meter'!O10*434/100) -> 0
A7: 25hours Dubai One Central | B7: =B6+1 -> 6 | C7: 2 | D7: 2024 | E7: =Submetering!E7+Submetering!F7+Submetering!G7+Submetering!H7+Submetering!I7+Submetering!J7 -> #VALUE! | F7: 0.44 | G7: =Submetering!M7 -> #VALUE! | H7: 2.5 | I7: =Submetering!L7 -> #VALUE! | J7: 0.06 | K7: =Submetering!K7 -> #VALUE! | L7: =0.568+0.075 -> 0.643 | M7: =INT('Daily Meter'!O11*434/100) -> #VALUE!
A8: 25hours Dubai One Central | B8: =B7+1 -> 7 | C8: 2 | D8: 2024 | E8: =Submetering!E8+Submetering!F8+Submetering!G8+Submetering!H8+Submetering!I8+Submetering!J8 -> #VALUE! | F8: 0.44 | G8: =Submetering!M8 -> #VALUE! | H8: 2.5 | I8: =Submetering!L8 -> #VALUE! | J8: 0.06 | K8: =Submetering!K8 -> #VALUE! | L8: =0.568+0.075 -> 0.643 | M8: =INT('Daily Meter'!O12*434/100) -> #VALUE!
A9: 25hours Dubai One Central | B9: =B8+1 -> 8 | C9: 2 | D9: 2024 | E9: =Submetering!E9+Submetering!F9+Submetering!G9+Submetering!H9+Submetering!I9+Submetering!J9 -> #VALUE! | F9: 0.44 | G9: =Submetering!M9 -> #VALUE! | H9: 2.5 | I9: =Submetering!L9 -> #VALUE! | J9: 0.06 | K9: =Submetering!K9 -> #VALUE! | L9: =0.568+0.075 -> 0.643 | M9: =INT('Daily Meter'!O13*434/100) -> #VALUE!
A10: 25hours Dubai One Central | B10: =B9+1 -> 9 | C10: 2 | D10: 2024 | E10: =Submetering!E10+Submetering!F10+Submetering!G10+Submetering!H10+Submetering!I10+Submetering!J10 -> #VALUE! | F10: 0.44 | G10: =Submetering!M10 -> #VALUE! | H10: 2.5 | I10: =Submetering!L10 -> #VALUE! | J10: 0.06 | K10: =Submetering!K10 -> #VALUE! | L10: =0.568+0.075 -> 0.643 | M10: =INT('Daily Meter'!O14*434/100) -> #VALUE!
A11: 25hours Dubai One Central | B11: =B10+1 -> 10 | C11: 2 | D11: 2024 | E11: =Submetering!E11+Submetering!F11+Submetering!G11+Submetering!H11+Submetering!I11+Submetering!J11 -> #VALUE! | F11: 0.44 | G11: =Submetering!M11 -> #VALUE! | H11: 2.5 | I11: =Submetering!L11 -> #VALUE! | J11: 0.06 | K11: =Submetering!K11 -> #VALUE! | L11: =0.568+0.075 -> 0.643 | M11: =INT('Daily Meter'!O15*434/100) -> #VALUE!
A12: 25hours Dubai One Central | B12: =B11+1 -> 11 | C12: 2 | D12: 2024 | E12: =Submetering!E12+Submetering!F12+Submetering!G12+Submetering!H12+Submetering!I12+Submetering!J12 -> #VALUE! | F12: 0.44 | G12: =Submetering!M12 -> #VALUE! | H12: 2.5 | I12: =Submetering!L12 -> #VALUE! | J12: 0.06 | K12: =Submetering!K12 -> #VALUE! | L12: =0.568+0.075 -> 0.643 | M12: =INT('Daily Meter'!O16*434/100) -> #VALUE!
A13: 25hours Dubai One Central | B13: =B12+1 -> 12 | C13: 2 | D13: 2024 | E13: =Submetering!E13+Submetering!F13+Submetering!G13+Submetering!H13+Submetering!I13+Submetering!J13 -> #VALUE! | F13: 0.44 | G13: =Submetering!M13 -> #VALUE! | H13: 2.5 | I13: =Submetering!L13 -> #VALUE! | J13: 0.06 | K13: =Submetering!K13 -> #VALUE! | L13: =0.568+0.075 -> 0.643 | M13: =INT('Daily Meter'!O17*434/100) -> #VALUE!
A14: 25hours Dubai One Central | B14: =B13+1 -> 13 | C14: 2 | D14: 2024 | E14: =Submetering!E14+Submetering!F14+Submetering!G14+Submetering!H14+Submetering!I14+Submetering!J14 -> #VALUE! | F14: 0.44 | G14: =Submetering!M14 -> #VALUE! | H14: 2.5 | I14: =Submetering!L14 -> #VALUE! | J14: 0.06 | K14: =Submetering!K14 -> #VALUE! | L14: =0.568+0.075 -> 0.643 | M14: =INT('Daily Meter'!O18*434/100) -> #VALUE!
... A30: 25hours Dubai One Central | B30: =B29+1 -> 29 | C30: 2 | D30: 2024 | E30: =Submetering!E30+Submetering!F30+Submetering!G30+Submetering!H30+Submetering!I30+Submetering!J30 -> #VALUE! | F30: 0.44 | G30: =Submetering!M30 -> #VALUE! | H30: 2.5 | I30: =Submetering!L30 -> #VALUE! | J30: 0.06 | K30: =Submetering!K30 -> #VALUE! | L30: =0.568+0.075 -> 0.643 | M30: =INT('Daily Meter'!O34*434/100) -> #VALUE!

Sheet Submetering
A1: Site Name | B1: Day | C1: Month | D1: Year | E1: Meter 1 - 06065253 | F1: Meter 2 - 06065255 | G1: Meter 3 - 06065259 | H1: Meter 4 - 06065262 | I1: Meter 6 - 06065269 | J1: Meter 7 - 06065283 | K1: District Cooling | L1: Water | M1: Gas | N1: Room Nights | O1: Total Guests
A2: 25hours Dubai One Central | B2: 1 | C2: 2 | D2: 2024 | E2: =IF(('Daily Meter'!H6-'1'!D13)<0,"0",'Daily Meter'!H6-'1'!D13)*480 -> 3360 | F2: =IF(('Daily Meter'!I6-'1'!D14)<0,"0",'Daily Meter'!I6-'1'!D14)*480 -> 1968 | G2: =IF(('Daily Meter'!J6-'1'!D15)<0,"0",'Daily Meter'!J6-'1'!D15)*480 -> 2112 | H2: =IF(('Daily Meter'!K6-'1'!D16)<0,"0",'Daily Meter'!K6-'1'!D16)*480 -> 1344 | I2: =IF(('Daily Meter'!L6-'1'!D17)<0,"0",'Daily Meter'!L6-'1'!D17)*480 -> 2208 | J2: =IF(('Daily Meter'!M6-'1'!D18)<0,"0",'Daily Meter'!M6-'1'!D18)*480 -> 5712 | K2: =IF(('Daily Meter'!B6-'1'!D7)<0,"0",'Daily Meter'!B6-'1'!D7)*284.34 -> 12909.036 | L2: =IF(('Daily Meter'!C6-'1'!D10)<0,"0",'Daily Meter'!C6-'1'!D10)*219.969 -> 100305.86 | M2: =IF(('Daily Meter'!N6-'1'!D22)<0,"0",'Daily Meter'!N6-'1'!D22)*3.7 -> 15863.38 | N2: =Total!M2 -> 330
A3: 25hours Dubai One Central | B3: =B2+1 -> 2 | C3: 2 | D3: 2024 | E3: =IF(('Daily Meter'!H7-'Daily Meter'!H6)<0,"0",'Daily Meter'!H7-'Daily Meter'!H6)*480 -> 3360 | F3: =IF(('Daily Meter'!I7-'Daily Meter'!I6)<0,"0",'Daily Meter'!I7-'Daily Meter'!I6)*480 -> 2112 | G3: =IF(('Daily Meter'!J7-'Daily Meter'!J6)<0,"0",'Daily Meter'!J7-'Daily Meter'!J6)*480 -> 2160 | H3: =IF(('Daily Meter'!K7-'Daily Meter'!K6)<0,"0",'Daily Meter'!K7-'Daily Meter'!K6)*480 -> 1344 | I3: =IF(('Daily Meter'!L7-'Daily Meter'!L6)<0,"0",'Daily Meter'!L7-'Daily Meter'!L6)*480 -> 2160 | J3: =IF(('Daily Meter'!M7-'Daily Meter'!M6)<0,"0",'Daily Meter'!M7-'Daily Meter'!M6)*480 -> 5760 | K3: =IF(('Daily Meter'!B7-'Daily Meter'!B6)<0,"0",'Daily Meter'!B7-'Daily Meter'!B6)*284.34 -> 6852.594 | L3: =IF(('Daily Meter'!C7-'Daily Meter'!C6)<0,"0",'Daily Meter'!C7-'Daily Meter'!C6)*219.969 -> 36954.792 | M3: =IF(('Daily Meter'!N7-'Daily Meter'!N6)<0,"0",'Daily Meter'!N7-'Daily Meter'!N6)*3.7 -> 519.11 | N3: =Total!M3 -> 236
A4: 25hours Dubai One Central | B4: =B3+1 -> 3 | C4: 2 | D4: 2024 | E4: =IF(('Daily Meter'!H8-'Daily Meter'!H7)<0,"0",'Daily Meter'!H8-'Daily Meter'!H7)*480 -> 3456 | F4: =IF(('Daily Meter'!I8-'Daily Meter'!I7)<0,"0",'Daily Meter'!I8-'Daily Meter'!I7)*480 -> 2160 | G4: =IF(('Daily Meter'!J8-'Daily Meter'!J7)<0,"0",'Daily Meter'!J8-'Daily Meter'!J7)*480 -> 2256 | H4: =IF(('Daily Meter'!K8-'Daily Meter'!K7)<0,"0",'Daily Meter'!K8-'Daily Meter'!K7)*480 -> 1344 | I4: =IF(('Daily Meter'!L8-'Daily Meter'!L7)<0,"0",'Daily Meter'!L8-'Daily Meter'!L7)*480 -> 2160 | J4: =IF(('Daily Meter'!M8-'Daily Meter'!M7)<0,"0",'Daily Meter'!M8-'Daily Meter'!M7)*480 -> 5760 | K4: =IF(('Daily Meter'!B8-'Daily Meter'!B7)<0,"0",'Daily Meter'!B8-'Daily Meter'!B7)*284.34 -> 5999.574 | L4: =IF(('Daily Meter'!C8-'Daily Meter'!C7)<0,"0",'Daily Meter'!C8-'Daily Meter'!C7)*219.969 -> 38714.544 | M4: =IF(('Daily Meter'!N8-'Daily Meter'!N7)<0,"0",'Daily Meter'!N8-'Daily Meter'!N7)*3.7 -> 493.58 | N4: =Total!M4 -> 209
A5: 25hours Dubai One Central | B5: =B4+1 -> 4 | C5: 2 | D5: 2024 | E5: =IF(('Daily Meter'!H9-'Daily Meter'!H8)<0,"0",'Daily Meter'!H9-'Daily Meter'!H8)*480 -> 3264 | F5: =IF(('Daily Meter'!I9-'Daily Meter'!I8)<0,"0",'Daily Meter'!I9-'Daily Meter'!I8)*480 -> 2064 | G5: =IF(('Daily Meter'!J9-'Daily Meter'!J8)<0,"0",'Daily Meter'!J9-'Daily Meter'!J8)*480 -> 2400 | H5: =IF(('Daily Meter'!K9-'Daily Meter'!K8)<0,"0",'Daily Meter'!K9-'Daily Meter'!K8)*480 -> 1392 | I5: =IF(('Daily Meter'!L9-'Daily Meter'!L8)<0,"0",'Daily Meter'!L9-'Daily Meter'!L8)*480 -> 2160 | J5: =IF(('Daily Meter'!M9-'Daily Meter'!M8)<0,"0",'Daily Meter'!M9-'Daily Meter'!M8)*480 -> 5760 | K5: =IF(('Daily Meter'!B9-'Daily Meter'!B8)<0,"0",'Daily Meter'!B9-'Daily Meter'!B8)*284.34 -> 5146.554 | L5: =IF(('Daily Meter'!C9-'Daily Meter'!C8)<0,"0",'Daily Meter'!C9-'Daily Meter'!C8)*219.969 -> 38054.637 | M5: =IF(('Daily Meter'!N9-'Daily Meter'!N8)<0,"0",'Daily Meter'!N9-'Daily Meter'!N8)*3.7 -> 491.36 | N5: =Total!M5 -> 306
A6: 25hours Dubai One Central | B6: =B5+1 -> 5 | C6: 2 | D6: 2024 | E6: =IF(('Daily Meter'!H10-'Daily Meter'!H9)<0,"0",'Daily Meter'!H10-'Daily Meter'!H9)*480 -> 3264 | F6: =IF(('Daily Meter'!I10-'Daily Meter'!I9)<0,"0",'Daily Meter'!I10-'Daily Meter'!I9)*480 -> 2064 | G6: =IF(('Daily Meter'!J10-'Daily Meter'!J9)<0,"0",'Daily Meter'!J10-'Daily Meter'!J9)*480 -> 2352 | H6: =IF(('Daily Meter'!K10-'Daily Meter'!K9)<0,"0",'Daily Meter'!K10-'Daily Meter'!K9)*480 -> 1392 | I6: =IF(('Daily Meter'!L10-'Daily Meter'!L9)<0,"0",'Daily Meter'!L10-'Daily Meter'!L9)*480 -> 2112 | J6: =IF(('Daily Meter'!M10-'Daily Meter'!M9)<0,"0",'Daily Meter'!M10-'Daily Meter'!M9)*480 -> 5808 | K6: =IF(('Daily Meter'!B10-'Daily Meter'!B9)<0,"0",'Daily Meter'!B10-'Daily Meter'!B9)*284.34 -> 4919.082 | L6: =IF(('Daily Meter'!C10-'Daily Meter'!C9)<0,"0",'Daily Meter'!C10-'Daily Meter'!C9)*219.969 -> 36514.854 | M6: =IF(('Daily Meter'!N10-'Daily Meter'!N9)<0,"0",'Daily Meter'!N10-'Daily Meter'!N9)*3.7 -> 468.42 | N6: =Total!M6 -> 0
A7: 25hours Dubai One Central | B7: =B6+1 -> 6 | C7: 2 | D7: 2024 | E7: =IF(('Daily Meter'!H11-'Daily Meter'!H10)<0,"0",'Daily Meter'!H11-'Daily Meter'!H10)*480 -> #VALUE! | F7: =IF(('Daily Meter'!I11-'Daily Meter'!I10)<0,"0",'Daily Meter'!I11-'Daily Meter'!I10)*480 -> #VALUE! | G7: =IF(('Daily Meter'!J11-'Daily Meter'!J10)<0,"0",'Daily Meter'!J11-'Daily Meter'!J10)*480 -> #VALUE! | H7: =IF(('Daily Meter'!K11-'Daily Meter'!K10)<0,"0",'Daily Meter'!K11-'Daily Meter'!K10)*480 -> #VALUE! | I7: =IF(('Daily Meter'!L11-'Daily Meter'!L10)<0,"0",'Daily Meter'!L11-'Daily Meter'!L10)*480 -> #VALUE! | J7: =IF(('Daily Meter'!M11-'Daily Meter'!M10)<0,"0",'Daily Meter'!M11-'Daily Meter'!M10)*480 -> #VALUE! | K7: =IF(('Daily Meter'!B11-'Daily Meter'!B10)<0,"0",'Daily Meter'!B11-'Daily Meter'!B10)*284.34 -> #VALUE! | L7: =IF(('Daily Meter'!C11-'Daily Meter'!C10)<0,"0",'Daily Meter'!C11-'Daily Meter'!C10)*219.969 -> #VALUE! | M7: =IF(('Daily Meter'!N11-'Daily Meter'!N10)<0,"0",'Daily Meter'!N11-'Daily Meter'!N10)*3.7 -> #VALUE! | N7: =Total!M7 -> #VALUE!
A8: 25hours Dubai One Central | B8: =B7+1 -> 7 | C8: 2 | D8: 2024 | E8: =IF(('Daily Meter'!H12-'Daily Meter'!H11)<0,"0",'Daily Meter'!H12-'Daily Meter'!H11)*480 -> #VALUE! | F8: =IF(('Daily Meter'!I12-'Daily Meter'!I11)<0,"0",'Daily Meter'!I12-'Daily Meter'!I11)*480 -> #VALUE! | G8: =IF(('Daily Meter'!J12-'Daily Meter'!J11)<0,"0",'Daily Meter'!J12-'Daily Meter'!J11)*480 -> #VALUE! | H8: =IF(('Daily Meter'!K12-'Daily Meter'!K11)<0,"0",'Daily Meter'!K12-'Daily Meter'!K11)*480 -> #VALUE! | I8: =IF(('Daily Meter'!L12-'Daily Meter'!L11)<0,"0",'Daily Meter'!L12-'Daily Meter'!L11)*480 -> #VALUE! | J8: =IF(('Daily Meter'!M12-'Daily Meter'!M11)<0,"0",'Daily Meter'!M12-'Daily Meter'!M11)*480 -> #VALUE! | K8: =IF(('Daily Meter'!B12-'Daily Meter'!B11)<0,"0",'Daily Meter'!B12-'Daily Meter'!B11)*284.34 -> #VALUE! | L8: =IF(('Daily Meter'!C12-'Daily Meter'!C11)<0,"0",'Daily Meter'!C12-'Daily Meter'!C11)*219.969 -> #VALUE! | M8: =IF(('Daily Meter'!N12-'Daily Meter'!N11)<0,"0",'Daily Meter'!N12-'Daily Meter'!N11)*3.7 -> #VALUE! | N8: =Total!M8 -> #VALUE!
A9: 25hours Dubai One Central | B9: =B8+1 -> 8 | C9: 2 | D9: 2024 | E9: =IF(('Daily Meter'!H13-'Daily Meter'!H12)<0,"0",'Daily Meter'!H13-'Daily Meter'!H12)*480 -> #VALUE! | F9: =IF(('Daily Meter'!I13-'Daily Meter'!I12)<0,"0",'Daily Meter'!I13-'Daily Meter'!I12)*480 -> #VALUE! | G9: =IF(('Daily Meter'!J13-'Daily Meter'!J12)<0,"0",'Daily Meter'!J13-'Daily Meter'!J12)*480 -> #VALUE! | H9: =IF(('Daily Meter'!K13-'Daily Meter'!K12)<0,"0",'Daily Meter'!K13-'Daily Meter'!K12)*480 -> #VALUE! | I9: =IF(('Daily Meter'!L13-'Daily Meter'!L12)<0,"0",'Daily Meter'!L13-'Daily Meter'!L12)*480 -> #VALUE! | J9: =IF(('Daily Meter'!M13-'Daily Meter'!M12)<0,"0",'Daily Meter'!M13-'Daily Meter'!M12)*480 -> #VALUE! | K9: =IF(('Daily Meter'!B13-'Daily Meter'!B12)<0,"0",'Daily Meter'!B13-'Daily Meter'!B12)*284.34 -> #VALUE! | L9: =IF(('Daily Meter'!C13-'Daily Meter'!C12)<0,"0",'Daily Meter'!C13-'Daily Meter'!C12)*219.969 -> #VALUE! | M9: =IF(('Daily Meter'!N13-'Daily Meter'!N12)<0,"0",'Daily Meter'!N13-'Daily Meter'!N12)*3.7 -> #VALUE! | N9: =Total!M9 -> #VALUE!
A10: 25hours Dubai One Central | B10: =B9+1 -> 9 | C10: 2 | D10: 2024 | E10: =IF(('Daily Meter'!H14-'Daily Meter'!H13)<0,"0",'Daily Meter'!H14-'Daily Meter'!H13)*480 -> #VALUE! | F10: =IF(('Daily Meter'!I14-'Daily Meter'!I13)<0,"0",'Daily Meter'!I14-'Daily Meter'!I13)*480 -> #VALUE! | G10: =IF(('Daily Meter'!J14-'Daily Meter'!J13)<0,"0",'Daily Meter'!J14-'Daily Meter'!J13)*480 -> #VALUE! | H10: =IF(('Daily Meter'!K14-'Daily Meter'!K13)<0,"0",'Daily Meter'!K14-'Daily Meter'!K13)*480 -> #VALUE! | I10: =IF(('Daily Meter'!L14-'Daily Meter'!L13)<0,"0",'Daily Meter'!L14-'Daily Meter'!L13)*480 -> #VALUE! | J10: =IF(('Daily Meter'!M14-'Daily Meter'!M13)<0,"0",'Daily Meter'!M14-'Daily Meter'!M13)*480 -> #VALUE! | K10: =IF(('Daily Meter'!B14-'Daily Meter'!B13)<0,"0",'Daily Meter'!B14-'Daily Meter'!B13)*284.34 -> #VALUE! | L10: =IF(('Daily Meter'!C14-'Daily Meter'!C13)<0,"0",'Daily Meter'!C14-'Daily Meter'!C13)*219.969 -> #VALUE! | M10: =IF(('Daily Meter'!N14-'Daily Meter'!N13)<0,"0",'Daily Meter'!N14-'Daily Meter'!N13)*3.7 -> #VALUE! | N10: =Total!M10 -> #VALUE!
A11: 25hours Dubai One Central | B11: =B10+1 -> 10 | C11: 2 | D11: 2024 | E11: =IF(('Daily Meter'!H15-'Daily Meter'!H14)<0,"0",'Daily Meter'!H15-'Daily Meter'!H14)*480 -> #VALUE! | F11: =IF(('Daily Meter'!I15-'Daily Meter'!I14)<0,"0",'Daily Meter'!I15-'Daily Meter'!I14)*480 -> #VALUE! | G11: =IF(('Daily Meter'!J15-'Daily Meter'!J14)<0,"0",'Daily Meter'!J15-'Daily Meter'!J14)*480 -> #VALUE! | H11: =IF(('Daily Meter'!K15-'Daily Meter'!K14)<0,"0",'Daily Meter'!K15-'Daily Meter'!K14)*480 -> #VALUE! | I11: =IF(('Daily Meter'!L15-'Daily Meter'!L14)<0,"0",'Daily Meter'!L15-'Daily Meter'!L14)*480 -> #VALUE! | J11: =IF(('Daily Meter'!M15-'Daily Meter'!M14)<0,"0",'Daily Meter'!M15-'Daily Meter'!M14)*480 -> #VALUE! | K11: =IF(('Daily Meter'!B15-'Daily Meter'!B14)<0,"0",'Daily Meter'!B15-'Daily Meter'!B14)*284.34 -> #VALUE! | L11: =IF(('Daily Meter'!C15-'Daily Meter'!C14)<0,"0",'Daily Meter'!C15-'Daily Meter'!C14)*219.969 -> #VALUE! | M11: =IF(('Daily Meter'!N15-'Daily Meter'!N14)<0,"0",'Daily Meter'!N15-'Daily Meter'!N14)*3.7 -> #VALUE! | N11: =Total!M11 -> #VALUE!
A12: 25hours Dubai One Central | B12: =B11+1 -> 11 | C12: 2 | D12: 2024 | E12: =IF(('Daily Meter'!H16-'Daily Meter'!H15)<0,"0",'Daily Meter'!H16-'Daily Meter'!H15)*480 -> #VALUE! | F12: =IF(('Daily Meter'!I16-'Daily Meter'!I15)<0,"0",'Daily Meter'!I16-'Daily Meter'!I15)*480 -> #VALUE! | G12: =IF(('Daily Meter'!J16-'Daily Meter'!J15)<0,"0",'Daily Meter'!J16-'Daily Meter'!J15)*480 -> #VALUE! | H12: =IF(('Daily Meter'!K16-'Daily Meter'!K15)<0,"0",'Daily Meter'!K16-'Daily Meter'!K15)*480 -> #VALUE! | I12: =IF(('Daily Meter'!L16-'Daily Meter'!L15)<0,"0",'Daily Meter'!L16-'Daily Meter'!L15)*480 -> #VALUE! | J12: =IF(('Daily Meter'!M16-'Daily Meter'!M15)<0,"0",'Daily Meter'!M16-'Daily Meter'!M15)*480 -> #VALUE! | K12: =IF(('Daily Meter'!B16-'Daily Meter'!B15)<0,"0",'Daily Meter'!B16-'Daily Meter'!B15)*284.34 -> #VALUE! | L12: =IF(('Daily Meter'!C16-'Daily Meter'!C15)<0,"0",'Daily Meter'!C16-'Daily Meter'!C15)*219.969 -> #VALUE! | M12: =IF(('Daily Meter'!N16-'Daily Meter'!N15)<0,"0",'Daily Meter'!N16-'Daily Meter'!N15)*3.7 -> #VALUE! | N12: =Total!M12 -> #VALUE!
A13: 25hours Dubai One Central | B13: =B12+1 -> 12 | C13: 2 | D13: 2024 | E13: =IF(('Daily Meter'!H17-'Daily Meter'!H16)<0,"0",'Daily Meter'!H17-'Daily Meter'!H16)*480 -> #VALUE! | F13: =IF(('Daily Meter'!I17-'Daily Meter'!I16)<0,"0",'Daily Meter'!I17-'Daily Meter'!I16)*480 -> #VALUE! | G13: =IF(('Daily Meter'!J17-'Daily Meter'!J16)<0,"0",'Daily Meter'!J17-'Daily Meter'!J16)*480 -> #VALUE! | H13: =IF(('Daily Meter'!K17-'Daily Meter'!K16)<0,"0",'Daily Meter'!K17-'Daily Meter'!K16)*480 -> #VALUE! | I13: =IF(('Daily Meter'!L17-'Daily Meter'!L16)<0,"0",'Daily Meter'!L17-'Daily Meter'!L16)*480 -> #VALUE! | J13: =IF(('Daily Meter'!M17-'Daily Meter'!M16)<0,"0",'Daily Meter'!M17-'Daily Meter'!M16)*480 -> #VALUE! | K13: =IF(('Daily Meter'!B17-'Daily Meter'!B16)<0,"0",'Daily Meter'!B17-'Daily Meter'!B16)*284.34 -> #VALUE! | L13: =IF(('Daily Meter'!C17-'Daily Meter'!C16)<0,"0",'Daily Meter'!C17-'Daily Meter'!C16)*219.969 -> #VALUE! | M13: =IF(('Daily Meter'!N17-'Daily Meter'!N16)<0,"0",'Daily Meter'!N17-'Daily Meter'!N16)*3.7 -> #VALUE! | N13: =Total!M13 -> #VALUE!
A14: 25hours Dubai One Central | B14: =B13+1 -> 13 | C14: 2 | D14: 2024 | E14: =IF(('Daily Meter'!H18-'Daily Meter'!H17)<0,"0",'Daily Meter'!H18-'Daily Meter'!H17)*480 -> #VALUE! | F14: =IF(('Daily Meter'!I18-'Daily Meter'!I17)<0,"0",'Daily Meter'!I18-'Daily Meter'!I17)*480 -> #VALUE! | G14: =IF(('Daily Meter'!J18-'Daily Meter'!J17)<0,"0",'Daily Meter'!J18-'Daily Meter'!J17)*480 -> #VALUE! | H14: =IF(('Daily Meter'!K18-'Daily Meter'!K17)<0,"0",'Daily Meter'!K18-'Daily Meter'!K17)*480 -> #VALUE! | I14: =IF(('Daily Meter'!L18-'Daily Meter'!L17)<0,"0",'Daily Meter'!L18-'Daily Meter'!L17)*480 -> #VALUE! | J14: =IF(('Daily Meter'!M18-'Daily Meter'!M17)<0,"0",'Daily Meter'!M18-'Daily Meter'!M17)*480 -> #VALUE! | K14: =IF(('Daily Meter'!B18-'Daily Meter'!B17)<0,"0",'Daily Meter'!B18-'Daily Meter'!B17)*284.34 -> #VALUE! | L14: =IF(('Daily Meter'!C18-'Daily Meter'!C17)<0,"0",'Daily Meter'!C18-'Daily Meter'!C17)*219.969 -> #VALUE! | M14: =IF(('Daily Meter'!N18-'Daily Meter'!N17)<0,"0",'Daily Meter'!N18-'Daily Meter'!N17)*3.7 -> #VALUE! | N14: =Total!M14 -> #VALUE!
... A30: 25hours Dubai One Central | B30: =B29+1 -> 29 | C30: 2 | D30: 2024 | E30: =IF(('Daily Meter'!H34-'Daily Meter'!H33)<0,"0",'Daily Meter'!H34-'Daily Meter'!H33)*480 -> #VALUE! | F30: =IF(('Daily Meter'!I34-'Daily Meter'!I33)<0,"0",'Daily Meter'!I34-'Daily Meter'!I33)*480 -> #VALUE! | G30: =IF(('Daily Meter'!J34-'Daily Meter'!J33)<0,"0",'Daily Meter'!J34-'Daily Meter'!J33)*480 -> #VALUE! | H30: =IF(('Daily Meter'!K34-'Daily Meter'!K33)<0,"0",'Daily Meter'!K34-'Daily Meter'!K33)*480 -> #VALUE! | I30: =IF(('Daily Meter'!L34-'Daily Meter'!L33)<0,"0",'Daily Meter'!L34-'Daily Meter'!L33)*480 -> #VALUE! | J30: =IF(('Daily Meter'!M34-'Daily Meter'!M33)<0,"0",'Daily Meter'!M34-'Daily Meter'!M33)*480 -> #VALUE! | K30: =IF(('Daily Meter'!B34-'Daily Meter'!B33)<0,"0",'Daily Meter'!B34-'Daily Meter'!B33)*284.34 -> #VALUE! | L30: =IF(('Daily Meter'!C34-'Daily Meter'!C33)<0,"0",'Daily Meter'!C34-'Daily Meter'!C33)*219.969 -> #VALUE! | M30: =IF(('Daily Meter'!N34-'Daily Meter'!N33)<0,"0",'Daily Meter'!N34-'Daily Meter'!N33)*3.7 -> #VALUE! | N30: =Total!M30 -> #VALUE!

Sheet Daily Meter
A1: February 2024 UTILITY READING | Q1: 1st
B2: CHILLED WATER | C2: WATER | H2: ELECTRICITY | N2: GAS | O2: OCC.
A3: Date | B3: BTU Meter | C3: Meter 1 | D3: Meter 2 | F3: Meter 3 | H3: Meter 1 | I3: Meter 2 | J3: Meter 3 | K3: Meter 4 | L3: Meter 6 | M3: Meter 7
B4: P103FF043BC | C4: 18E0300032 | D4: 18E0300060 | F4: 18E0300057 | H4: 6065253 | I4: 6065255 | J4: 6065259 | K4: 6065262 | L4: 6065269 | M4: 6065283 | N4: 77092321/2019 | O4: %
B5: 4am | C5: 4am | D5: 4am | E5: 4am | F5: 4am | G5: 4am | H5: 4am | I5: 4am | J5: 4am | K5: 4am | L5: 4am | M5: 4am | N5: 4am | O5: DAILY
A6: 1 | B6: 54133.2 | C6: 209451 | H6: 6780 | I6: 4090.6 | J6: 4372.9 | K6: 2449.1 | L6: 5712.9 | M6: 15367.6 | N6: 94274.8 | O6: 76.04
A7: 2 | B7: 54157.3 | C7: 209619 | H7: 6787 | I7: 4095 | J7: 4377.4 | K7: 2451.9 | L7: 5717.4 | M7: 15379.6 | N7: 94415.1 | O7: 54.38
A8: 3 | B8: 54178.4 | C8: 209795 | H8: 6794.2 | I8: 4099.5 | J8: 4382.1 | K8: 2454.7 | L8: 5721.9 | M8: 15391.6 | N8: 94548.5 | O8: 48.16
A9: 4 | B9: 54196.5 | C9: 209968 | H9: 6801 | I9: 4103.8 | J9: 4387.1 | K9: 2457.6 | L9: 5726.4 | M9: 15403.6 | N9: 94681.3 | O9: 70.51
A10: 5 | B10: 54213.8 | C10: 210134 | H10: 6807.8 | I10: 4108.1 | J10: 4392 | K10: 2460.5 | L10: 5730.8 | M10: 15415.7 | N10: 94807.9
A11: 6
A12: 7
A13: 8
A14: 9
A15: 10
A16: 11
A17: 12
A18: 13
A19: 14
A20: 15
A21: 16
A22: 17
... A36: 31
O37: =AVERAGE(O6:O34) -> 62.2725
Q38: engr123.

Sheet 1
A1: ENGINEERING DEPARTMENT | H1: daily reading
A2: UTILITY CONSUMPTION SHEET
B3: February 2024 | C3: 1 | D3: % OCCUPANCY: | E3: ='Daily Meter'!O6 -> 76.04
A4: SR.NO | B4: ITEM MEASURED | D4: Previous Reading | E4: 4 AM Reading | F4: 24hrs CONSUMPTION | G4: Cost
D5: January 31
A6: 1 | B6: DISTRICT COOLING PLANT
B7: Chilled Water | C7: MWH | D7: ='[1]30'!E7 -> 54087.8 | E7: ='Daily Meter'!B6 -> 54133.2 | F7: =E7-D7 -> 45.4
C8: TR | F8: =F7*284.34 -> 12909.036 | G8: =F8*0.63 -> 8132.6927
A9: III | B9: WATER METERS
B10: Main DEWA Meter | C10: m3 | D10: ='[1]30'!E10 -> 208995 | E10: ='Daily Meter'!C6 -> 209451 | F10: =E10-D10 -> 456
B11: Imperial Gallon = m³ x 219.969 | C11: IG | F11: =F10*219.969 -> 100305.86 | G11: =F11*0.06 -> 6018.3518
A12: IV | B12: ELECTRICAL METERS
A13: 1 | B13: Meter 1 - 06065253 | C13: kW x 480 | D13: 6773 | E13: ='Daily Meter'!H6 -> 6780 | F13: =(E13-D13)*480 -> 3360
A14: 2 | B14: Meter 2 - 06065255 | C14: kW x 480 | D14: 4086.5 | E14: ='Daily Meter'!I6 -> 4090.6 | F14: =(E14-D14)*480 -> 1968
A15: 3 | B15: Meter 3 - 06065259 | C15: kW x 480 | D15: 4368.5 | E15: ='Daily Meter'!J6 -> 4372.9 | F15: =(E15-D15)*480 -> 2112
A16: 4 | B16: Meter 4 - 06065262 | C16: kW x 480 | D16: 2446.3 | E16: ='Daily Meter'!K6 -> 2449.1 | F16: =(E16-D16)*480 -> 1344
A17: 5 | B17: Meter 6 - 06065269 | C17: kW x 480 | D17: 5708.3 | E17: ='Daily Meter'!L6 -> 5712.9 | F17: =(E17-D17)*480 -> 2208
A18: 6 | B18: Meter 7 - 06065283 | C18: kW x 480 | D18: 15355.7 | E18: ='Daily Meter'!M6 -> 15367.6 | F18: =(E18-D18)*480 -> 5712
B19: TOTAL ELECTRICAL CONS.(kWh) | F19: =SUM(F13:F18) -> 16704 | G19: =F19*0.43 -> 7182.72
A21: V | B21: GAS CONSUMPTION
A22: 1 | B22: MAIN LPG METER | C22: M3 | D22: 89987.4 | E22: ='Daily Meter'!N6 -> 94274.8 | F22: =E22-D22 -> 4287.4
B23: L = m³ x 3.70 | C23: L | F23: =F22*3.7 -> 15863.38 | G23: =F23*2.5 -> 39658.45
D26: Summary of Daily Hotel consumption
D27: Item measured | E27: Units | F27: Consumption | G27: AED
D28: Chilled water | E28: TR | F28: =F8 -> 12909.036 | G28: =G8 -> 8132.6927
D29: DEWA Water | E29: imp. Gallon | F29: =F11 -> 100305.86 | G29: =G11 -> 6018.3518
D30: Electricity | E30: kwh | F30: =F19 -> 16704 | G30: =G19 -> 7182.72
D31: Gas | E31: m3 | F31: =F22 -> 4287.4 | G31: =G23 -> 39658.45
F32: Total cost | G32: =SUM(G28:G31) -> 60992.215

Sheet 2
A1: ENGINEERING DEPARTMENT | H1: daily reading
A2: UTILITY CONSUMPTION SHEET
B3: ='1'!B3 -> February 2024 | C3: 2 | D3: % OCCUPANCY: | E3: ='Daily Meter'!O6 -> 76.04
A4: SR.NO | B4: ITEM MEASURED | D4: Previous Reading | E4: 4 AM Reading | F4: 24hrs CONSUMPTION | G4: Cost
A6: 1 | B6: DISTRICT COOLING PLANT
B7: Chilled Water | C7: MWH | D7: ='1'!E7 -> 54133.2 | E7: ='Daily Meter'!B7 -> 54157.3 | F7: =E7-D7 -> 24.1
C8: TR | F8: =F7*284.34 -> 6852.594 | G8: =F8*0.63 -> 4317.1342
A9: III | B9: WATER METERS
B10: Main DEWA Meter | C10: m3 | D10: ='1'!E10 -> 209451 | E10: ='Daily Meter'!C7 -> 209619 | F10: =E10-D10 -> 168
B11: Imperial Gallon = m³ x 219.969 | C11: IG | F11: =F10*219.969 -> 36954.792 | G11: =F11*0.06 -> 2217.2875
A12: IV | B12: ELECTRICAL METERS
A13: 1 | B13: Meter 1 - 06065253 | C13: kW x 480 | D13: ='1'!E13 -> 6780 | E13: ='Daily Meter'!H7 -> 6787 | F13: =(E13-D13)*480 -> 3360
A14: 2 | B14: Meter 2 - 06065255 | C14: kW x 480 | D14: ='1'!E14 -> 4090.6 | E14: ='Daily Meter'!I7 -> 4095 | F14: =(E14-D14)*480 -> 2112
A15: 3 | B15: Meter 3 - 06065259 | C15: kW x 480 | D15: ='1'!E15 -> 4372.9 | E15: ='Daily Meter'!J7 -> 4377.4 | F15: =(E15-D15)*480 -> 2160
A16: 4 | B16: Meter 4 - 06065262 | C16: kW x 480 | D16: ='1'!E16 -> 2449.1 | E16: ='Daily Meter'!K7 -> 2451.9 | F16: =(E16-D16)*480 -> 1344
A17: 5 | B17: Meter 6 - 06065269 | C17: kW x 480 | D17: ='1'!E17 -> 5712.9 | E17: ='Daily Meter'!L7 -> 5717.4 | F17: =(E17-D17)*480 -> 2160
A18: 6 | B18: Meter 7 - 06065283 | C18: kW x 480 | D18: ='1'!E18 -> 15367.6 | E18: ='Daily Meter'!M7 -> 15379.6 | F18: =(E18-D18)*480 -> 5760
B19: TOTAL ELECTRICAL CONS.(kWh) | F19: =SUM(F13:F18) -> 16896 | G19: =F19*0.43 -> 7265.28
A21: V | B21: GAS CONSUMPTION
A22: 1 | B22: MAIN LPG METER | C22: M3 | D22: ='1'!E22 -> 94274.8 | E22: ='Daily Meter'!N7 -> 94415.1 | F22: =E22-D22 -> 140.3
B23: L = m³ x 3.70 | C23: L | F23: =F22*3.7 -> 519.11 | G23: =F23*2.5 -> 1297.775
D26: Summary of Daily Hotel consumption
D27: Item measured | E27: Units | F27: Consumption | G27: AED
D28: Chilled water | E28: TR | F28: =F8 -> 6852.594 | G28: =G8 -> 4317.1342
D29: DEWA Water | E29: imp. Gallon | F29: =F11 -> 36954.792 | G29: =G11 -> 2217.2875
D30: Electricity | E30: kwh | F30: =F19 -> 16896 | G30: =G19 -> 7265.28
D31: Gas | E31: m3 | F31: =F22 -> 140.3 | G31: =G23 -> 1297.775
F32: Total cost | G32: =SUM(G28:G31) -> 15097.477

Sheet 3
A1: ENGINEERING DEPARTMENT | H1: daily reading
A2: UTILITY CONSUMPTION SHEET
B3: ='1'!B3 -> February 2024 | C3: 3 | D3: % OCCUPANCY: | E3: ='Daily Meter'!O8 -> 48.16
A4: SR.NO | B4: ITEM MEASURED | D4: Previous Reading | E4: 4 AM Reading | F4: 24hrs CONSUMPTION | G4: Cost
A6: 1 | B6: DISTRICT COOLING PLANT
B7: Chilled Water | C7: MWH | D7: ='2'!E7 -> 54157.3 | E7: ='Daily Meter'!B8 -> 54178.4 | F7: =E7-D7 -> 21.1
C8: TR | F8: =F7*284.34 -> 5999.574 | G8: =F8*0.63 -> 3779.7316
A9: III | B9: WATER METERS
B10: Main DEWA Meter | C10: m3 | D10: ='2'!E10 -> 209619 | E10: ='Daily Meter'!C8 -> 209795 | F10: =E10-D10 -> 176
B11: Imperial Gallon = m³ x 219.969 | C11: IG | F11: =F10*219.969 -> 38714.544 | G11: =F11*0.06 -> 2322.8726
A12: IV | B12: ELECTRICAL METERS
A13: 1 | B13: Meter 1 - 06065253 | C13: kW x 480 | D13: ='2'!E13 -> 6787 | E13: ='Daily Meter'!H8 -> 6794.2 | F13: =(E13-D13)*480 -> 3456
A14: 2 | B14: Meter 2 - 06065255 | C14: kW x 480 | D14: ='2'!E14 -> 4095 | E14: ='Daily Meter'!I8 -> 4099.5 | F14: =(E14-D14)*480 -> 2160
A15: 3 | B15: Meter 3 - 06065259 | C15: kW x 480 | D15: ='2'!E15 -> 4377.4 | E15: ='Daily Meter'!J8 -> 4382.1 | F15: =(E15-D15)*480 -> 2256
A16: 4 | B16: Meter 4 - 06065262 | C16: kW x 480 | D16: ='2'!E16 -> 2451.9 | E16: ='Daily Meter'!K8 -> 2454.7 | F16: =(E16-D16)*480 -> 1344
A17: 5 | B17: Meter 6 - 06065269 | C17: kW x 480 | D17: ='2'!E17 -> 5717.4 | E17: ='Daily Meter'!L8 -> 5721.9 | F17: =(E17-D17)*480 -> 2160
A18: 6 | B18: Meter 7 - 06065283 | C18: kW x 480 | D18: ='2'!E18 -> 15379.6 | E18: ='Daily Meter'!M8 -> 15391.6 | F18: =(E18-D18)*480 -> 5760
B19: TOTAL ELECTRICAL CONS.(kWh) | F19: =SUM(F13:F18) -> 17136 | G19: =F19*0.43 -> 7368.48
A21: V | B21: GAS CONSUMPTION
A22: 1 | B22: MAIN LPG METER | C22: M3 | D22: ='2'!E22 -> 94415.1 | E22: ='Daily Meter'!N8 -> 94548.5 | F22: =E22-D22 -> 133.4
B23: L = m³ x 3.70 | C23: L | F23: =F22*3.7 -> 493.58 | G23: =F23*2.5 -> 1233.95
D26: Summary of Daily Hotel consumption
D27: Item measured | E27: Units | F27: Consumption | G27: AED
D28: Chilled water | E28: TR | F28: =F8 -> 5999.574 | G28: =G8 -> 3779.7316
D29: DEWA Water | E29: imp. Gallon | F29: =F11 -> 38714.544 | G29: =G11 -> 2322.8726
D30: Electricity | E30: kwh | F30: =F19 -> 17136 | G30: =G19 -> 7368.48
D31: Gas | E31: m3 | F31: =F22 -> 133.4 | G31: =G23 -> 1233.95
F32: Total cost | G32: =SUM(G28:G31) -> 14705.034

Sheet 4
A1: ENGINEERING DEPARTMENT | H1: daily reading
A2: UTILITY CONSUMPTION SHEET
B3: ='1'!B3 -> February 2024 | C3: 4 | D3: % OCCUPANCY: | E3: ='Daily Meter'!O9 -> 70.51
A4: SR.NO | B4: ITEM MEASURED | D4: Previous Reading | E4: 4 AM Reading | F4: 24hrs CONSUMPTION | G4: Cost
A6: 1 | B6: DISTRICT COOLING PLANT
B7: Chilled Water | C7: MWH | D7: ='3'!E7 -> 54178.4 | E7: ='Daily Meter'!B9 -> 54196.5 | F7: =E7-D7 -> 18.1
C8: TR | F8: =F7*284.34 -> 5146.554 | G8: =F8*0.63 -> 3242.329
A9: III | B9: WATER METERS
B10: Main DEWA Meter | C10: m3 | D10: ='3'!E10 -> 209795 | E10: ='Daily Meter'!C9 -> 209968 | F10: =E10-D10 -> 173
B11: Imperial Gallon = m³ x 219.969 | C11: IG | F11: =F10*219.969 -> 38054.637 | G11: =F11*0.06 -> 2283.2782
A12: IV | B12: ELECTRICAL METERS
A13: 1 | B13: Meter 1 - 06065253 | C13: kW x 480 | D13: ='3'!E13 -> 6794.2 | E13: ='Daily Meter'!H9 -> 6801 | F13: =(E13-D13)*480 -> 3264
A14: 2 | B14: Meter 2 - 06065255 | C14: kW x 480 | D14: ='3'!E14 -> 4099.5 | E14: ='Daily Meter'!I9 -> 4103.8 | F14: =(E14-D14)*480 -> 2064
A15: 3 | B15: Meter 3 - 06065259 | C15: kW x 480 | D15: ='3'!E15 -> 4382.1 | E15: ='Daily Meter'!J9 -> 4387.1 | F15: =(E15-D15)*480 -> 2400
A16: 4 | B16: Meter 4 - 06065262 | C16: kW x 480 | D16: ='3'!E16 -> 2454.7 | E16: ='Daily Meter'!K9 -> 2457.6 | F16: =(E16-D16)*480 -> 1392
A17: 5 | B17: Meter 6 - 06065269 | C17: kW x 480 | D17: ='3'!E17 -> 5721.9 | E17: ='Daily Meter'!L9 -> 5726.4 | F17: =(E17-D17)*480 -> 2160
A18: 6 | B18: Meter 7 - 06065283 | C18: kW x 480 | D18: ='3'!E18 -> 15391.6 | E18: ='Daily Meter'!M9 -> 15403.6 | F18: =(E18-D18)*480 -> 5760
B19: TOTAL ELECTRICAL CONS.(kWh) | F19: =SUM(F13:F18) -> 17040 | G19: =F19*0.43 -> 7327.2
A21: V | B21: GAS CONSUMPTION
A22: 1 | B22: MAIN LPG METER | C22: M3 | D22: ='3'!E22 -> 94548.5 | E22: ='Daily Meter'!N9 -> 94681.3 | F22: =E22-D22 -> 132.8
B23: L = m³ x 3.70 | C23: L | F23: =F22*3.7 -> 491.36 | G23: =F23*2.5 -> 1228.4
D26: Summary of Daily Hotel consumption
D27: Item measured | E27: Units | F27: Consumption | G27: AED
D28: Chilled water | E28: TR | F28: =F8 -> 5146.554 | G28: =G8 -> 3242.329
D29: DEWA Water | E29: imp. Gallon | F29: =F11 -> 38054.637 | G29: =G11 -> 2283.2782
D30: Electricity | E30: kwh | F30: =F19 -> 17040 | G30: =G19 -> 7327.2
D31: Gas | E31: m3 | F31: =F22 -> 132.8 | G31: =G23 -> 1228.4
F32: Total cost | G32: =SUM(G28:G31) -> 14081.207

Sheet 5
A1: ENGINEERING DEPARTMENT | H1: daily reading
A2: UTILITY CONSUMPTION SHEET
B3: ='1'!B3 -> February 2024 | C3: 5 | D3: % OCCUPANCY: | E3: ='Daily Meter'!O10 -> 0
A4: SR.NO | B4: ITEM MEASURED | D4: Previous Reading | E4: 4 AM Reading | F4: 24hrs CONSUMPTION | G4: Cost
A6: 1 | B6: DISTRICT COOLING PLANT
B7: Chilled Water | C7: MWH | D7: ='4'!E7 -> 54196.5 | E7: ='Daily Meter'!B10 -> 54213.8 | F7: =E7-D7 -> 17.3
C8: TR | F8: =F7*284.34 -> 4919.082 | G8: =F8*0.63 -> 3099.0217
A9: III | B9: WATER METERS
B10: Main DEWA Meter | C10: m3 | D10: ='4'!E10 -> 209968 | E10: ='Daily Meter'!C10 -> 210134 | F10: =E10-D10 -> 166
B11: Imperial Gallon = m³ x 219.969 | C11: IG | F11: =F10*219.969 -> 36514.854 | G11: =F11*0.06 -> 2190.8912
A12: IV | B12: ELECTRICAL METERS
A13: 1 | B13: Meter 1 - 06065253 | C13: kW x 480 | D13: ='4'!E13 -> 6801 | E13: ='Daily Meter'!H10 -> 6807.8 | F13: =(E13-D13)*480 -> 3264
A14: 2 | B14: Meter 2 - 06065255 | C14: kW x 480 | D14: ='4'!E14 -> 4103.8 | E14: ='Daily Meter'!I10 -> 4108.1 | F14: =(E14-D14)*480 -> 2064
A15: 3 | B15: Meter 3 - 06065259 | C15: kW x 480 | D15: ='4'!E15 -> 4387.1 | E15: ='Daily Meter'!J10 -> 4392 | F15: =(E15-D15)*480 -> 2352
A16: 4 | B16: Meter 4 - 06065262 | C16: kW x 480 | D16: ='4'!E16 -> 2457.6 | E16: ='Daily Meter'!K10 -> 2460.5 | F16: =(E16-D16)*480 -> 1392
A17: 5 | B17: Meter 6 - 06065269 | C17: kW x 480 | D17: ='4'!E17 -> 5726.4 | E17: ='Daily Meter'!L10 -> 5730.8 | F17: =(E17-D17)*480 -> 2112
A18: 6 | B18: Meter 7 - 06065283 | C18: kW x 480 | D18: ='4'!E18 -> 15403.6 | E18: ='Daily Meter'!M10 -> 15415.7 | F18: =(E18-D18)*480 -> 5808
B19: TOTAL ELECTRICAL CONS.(kWh) | F19: =SUM(F13:F18) -> 16992 | G19: =F19*0.43 -> 7306.56
A21: V | B21: GAS CONSUMPTION
A22: 1 | B22: MAIN LPG METER | C22: M3 | D22: ='4'!E22 -> 94681.3 | E22: ='Daily Meter'!N10 -> 94807.9 | F22: =E22-D22 -> 126.6
B23: L = m³ x 3.70 | C23: L | F23: =F22*3.7 -> 468.42 | G23: =F23*2.5 -> 1171.05
D26: Summary of Daily Hotel consumption
D27: Item measured | E27: Units | F27: Consumption | G27: AED
D28: Chilled water | E28: TR | F28: =F8 -> 4919.082 | G28: =G8 -> 3099.0217
D29: DEWA Water | E29: imp. Gallon | F29: =F11 -> 36514.854 | G29: =G11 -> 2190.8912
D30: Electricity | E30: kwh | F30: =F19 -> 16992 | G30: =G19 -> 7306.56
D31: Gas | E31: m3 | F31: =F22 -> 126.6 | G31: =G23 -> 1171.05
F32: Total cost | G32: =SUM(G28:G31) -> 13767.523

Sheet 6
A1: ENGINEERING DEPARTMENT | H1: daily reading
A2: UTILITY CONSUMPTION SHEET
B3: ='1'!B3 -> February 2024 | C3: 6 | D3: % OCCUPANCY: | E3: ='Daily Meter'!O11
A4: SR.NO | B4: ITEM MEASURED | D4: Previous Reading | E4: 4 AM Reading | F4: 24hrs CONSUMPTION | G4: Cost
A6: 1 | B6: DISTRICT COOLING PLANT
B7: Chilled Water | C7: MWH | D7: ='5'!E7 -> 54213.8 | E7: ='Daily Meter'!B11 | F7: =E7-D7 -> #VALUE!
C8: TR | F8: =F7*284.34 -> #VALUE! | G8: =F8*0.63 -> #VALUE!
A9: III | B9: WATER METERS
B10: Main DEWA Meter | C10: m3 | D10: ='5'!E10 -> 210134 | E10: ='Daily Meter'!C11 | F10: =E10-D10 -> #VALUE!
B11: Imperial Gallon = m³ x 219.969 | C11: IG | F11: =F10*219.969 -> #VALUE! | G11: =F11*0.06 -> #VALUE!
A12: IV | B12: ELECTRICAL METERS
A13: 1 | B13: Meter 1 - 06065253 | C13: kW x 480 | D13: ='5'!E13 -> 6807.8 | E13: ='Daily Meter'!H11 | F13: =(E13-D13)*480 -> #VALUE!
A14: 2 | B14: Meter 2 - 06065255 | C14: kW x 480 | D14: ='5'!E14 -> 4108.1 | E14: ='Daily Meter'!I11 | F14: =(E14-D14)*480 -> #VALUE!
A15: 3 | B15: Meter 3 - 06065259 | C15: kW x 480 | D15: ='5'!E15 -> 4392 | E15: ='Daily Meter'!J11 | F15: =(E15-D15)*480 -> #VALUE!
A16: 4 | B16: Meter 4 - 06065262 | C16: kW x 480 | D16: ='5'!E16 -> 2460.5 | E16: ='Daily Meter'!K11 | F16: =(E16-D16)*480 -> #VALUE!
A17: 5 | B17: Meter 6 - 06065269 | C17: kW x 480 | D17: ='5'!E17 -> 5730.8 | E17: ='Daily Meter'!L11 | F17: =(E17-D17)*480 -> #VALUE!
A18: 6 | B18: Meter 7 - 06065283 | C18: kW x 480 | D18: ='5'!E18 -> 15415.7 | E18: ='Daily Meter'!M11 | F18: =(E18-D18)*480 -> #VALUE!
B19: TOTAL ELECTRICAL CONS.(kWh) | F19: =SUM(F13:F18) -> #VALUE! | G19: =F19*0.43 -> #VALUE!
A21: V | B21: GAS CONSUMPTION
A22: 1 | B22: MAIN LPG METER | C22: M3 | D22: ='5'!E22 -> 94807.9 | E22: ='Daily Meter'!N11 | F22: =E22-D22 -> #VALUE!
B23: L = m³ x 3.70 | C23: L | F23: =F22*3.7 -> #VALUE! | G23: =F23*2.5 -> #VALUE!
D26: Summary of Daily Hotel consumption
D27: Item measured | E27: Units | F27: Consumption | G27: AED
D28: Chilled water | E28: TR | F28: =F8 -> #VALUE! | G28: =G8 -> #VALUE!
D29: DEWA Water | E29: imp. Gallon | F29: =F11 -> #VALUE! | G29: =G11 -> #VALUE!
D30: Electricity | E30: kwh | F30: =F19 -> #VALUE! | G30: =G19 -> #VALUE!
D31: Gas | E31: m3 | F31: =F22 -> #VALUE! | G31: =G23 -> #VALUE!
F32: Total cost | G32: =SUM(G28:G31) -> #VALUE!

Sheet 7
A1: ENGINEERING DEPARTMENT | H1: daily reading
A2: UTILITY CONSUMPTION SHEET
B3: ='1'!B3 -> February 2024 | C3: 7 | D3: % OCCUPANCY: | E3: ='Daily Meter'!O12
A4: SR.NO | B4: ITEM MEASURED | D4: Previous Reading | E4: 4 AM Reading | F4: 24hrs CONSUMPTION | G4: Cost
A6: 1 | B6: DISTRICT COOLING PLANT
B7: Chilled Water | C7: MWH | D7: ='6'!E7 | E7: ='Daily Meter'!B12 | F7: =E7-D7 -> #VALUE!
C8: TR | F8: =F7*284.34 -> #VALUE! | G8: =F8*0.63 -> #VALUE!
A9: III | B9: WATER METERS
B10: Main DEWA Meter | C10: m3 | D10: ='6'!E10 | E10: ='Daily Meter'!C12 | F10: =E10-D10 -> #VALUE!
B11: Imperial Gallon = m³ x 219.969 | C11: IG | F11: =F10*219.969 -> #VALUE! | G11: =F11*0.06 -> #VALUE!
A12: IV | B12: ELECTRICAL METERS
A13: 1 | B13: Meter 1 - 06065253 | C13: kW x 480 | D13: ='6'!E13 | E13: ='Daily Meter'!H12 | F13: =(E13-D13)*480 -> #VALUE!
A14: 2 | B14: Meter 2 - 06065255 | C14: kW x 480 | D14: ='6'!E14 | E14: ='Daily Meter'!I12 | F14: =(E14-D14)*480 -> #VALUE!
A15: 3 | B15: Meter 3 - 06065259 | C15: kW x 480 | D15: ='6'!E15 | E15: ='Daily Meter'!J12 | F15: =(E15-D15)*480 -> #VALUE!
A16: 4 | B16: Meter 4 - 06065262 | C16: kW x 480 | D16: ='6'!E16 | E16: ='Daily Meter'!K12 | F16: =(E16-D16)*480 -> #VALUE!
A17: 5 | B17: Meter 6 - 06065269 | C17: kW x 480 | D17: ='6'!E17 | E17: ='Daily Meter'!L12 | F17: =(E17-D17)*480 -> #VALUE!
A18: 6 | B18: Meter 7 - 06065283 | C18: kW x 480 | D18: ='6'!E18 | E18: ='Daily Meter'!M12 | F18: =(E18-D18)*480 -> #VALUE!
B19: TOTAL ELECTRICAL CONS.(kWh) | F19: =SUM(F13:F18) -> #VALUE! | G19: =F19*0.43 -> #VALUE!
A21: V | B21: GAS CONSUMPTION
A22: 1 | B22: MAIN LPG METER | C22: M3 | D22: ='6'!E22 | E22: ='Daily Meter'!N12 | F22: =E22-D22 -> #VALUE!
B23: L = m³ x 3.70 | C23: L | F23: =F22*3.7 -> #VALUE! | G23: =F23*2.5 -> #VALUE!
D26: Summary of Daily Hotel consumption
D27: Item measured | E27: Units | F27: Consumption | G27: AED
D28: Chilled water | E28: TR | F28: =F8 -> #VALUE! | G28: =G8 -> #VALUE!
D29: DEWA Water | E29: imp. Gallon | F29: =F11 -> #VALUE! | G29: =G11 -> #VALUE!
D30: Electricity | E30: kwh | F30: =F19 -> #VALUE! | G30: =G19 -> #VALUE!
D31: Gas | E31: m3 | F31: =F22 -> #VALUE! | G31: =G23 -> #VALUE!
F32: Total cost | G32: =SUM(G28:G31) -> #VALUE!

Sheet 8
A1: ENGINEERING DEPARTMENT | H1: daily reading
A2: UTILITY CONSUMPTION SHEET
B3: ='1'!B3 -> February 2024 | C3: 8 | D3: % OCCUPANCY: | E3: ='Daily Meter'!O13
A4: SR.NO | B4: ITEM MEASURED | D4: Previous Reading | E4: 4 AM Reading | F4: 24hrs CONSUMPTION | G4: Cost
A6: 1 | B6: DISTRICT COOLING PLANT
B7: Chilled Water | C7: MWH | D7: ='7'!E7 | E7: ='Daily Meter'!B13 | F7: =E7-D7 -> #VALUE!
C8: TR | F8: =F7*284.34 -> #VALUE! | G8: =F8*0.63 -> #VALUE!
A9: III | B9: WATER METERS
B10: Main DEWA Meter | C10: m3 | D10: ='7'!E10 | E10: ='Daily Meter'!C13 | F10: =E10-D10 -> #VALUE!
B11: Imperial Gallon = m³ x 219.969 | C11: IG | F11: =F10*219.969 -> #VALUE! | G11: =F11*0.06 -> #VALUE!
A12: IV | B12: ELECTRICAL METERS
A13: 1 | B13: Meter 1 - 06065253 | C13: kW x 480 | D13: ='7'!E13 | E13: ='Daily Meter'!H13 | F13: =(E13-D13)*480 -> #VALUE!
A14: 2 | B14: Meter 2 - 06065255 | C14: kW x 480 | D14: ='7'!E14 | E14: ='Daily Meter'!I13 | F14: =(E14-D14)*480 -> #VALUE!
A15: 3 | B15: Meter 3 - 06065259 | C15: kW x 480 | D15: ='7'!E15 | E15: ='Daily Meter'!J13 | F15: =(E15-D15)*480 -> #VALUE!
A16: 4 | B16: Meter 4 - 06065262 | C16: kW x 480 | D16: ='7'!E16 | E16: ='Daily Meter'!K13 | F16: =(E16-D16)*480 -> #VALUE!
A17: 5 | B17: Meter 6 - 06065269 | C17: kW x 480 | D17: ='7'!E17 | E17: ='Daily Meter'!L13 | F17: =(E17-D17)*480 -> #VALUE!
A18: 6 | B18: Meter 7 - 06065283 | C18: kW x 480 | D18: ='7'!E18 | E18: ='Daily Meter'!M13 | F18: =(E18-D18)*480 -> #VALUE!
B19: TOTAL ELECTRICAL CONS.(kWh) | F19: =SUM(F13:F18) -> #VALUE! | G19: =F19*0.43 -> #VALUE!
A21: V | B21: GAS CONSUMPTION
A22: 1 | B22: MAIN LPG METER | C22: M3 | D22: ='7'!E22 | E22: ='Daily Meter'!N13 | F22: =E22-D22 -> #VALUE!
B23: L = m³ x 3.70 | C23: L | F23: =F22*3.7 -> #VALUE! | G23: =F23*2.5 -> #VALUE!
D26: Summary of Daily Hotel consumption
D27: Item measured | E27: Units | F27: Consumption | G27: AED
D28: Chilled water | E28: TR | F28: =F8 -> #VALUE! | G28: =G8 -> #VALUE!
D29: DEWA Water | E29: imp. Gallon | F29: =F11 -> #VALUE! | G29: =G11 -> #VALUE!
D30: Electricity | E30: kwh | F30: =F19 -> #VALUE! | G30: =G19 -> #VALUE!
D31: Gas | E31: m3 | F31: =F22 -> #VALUE! | G31: =G23 -> #VALUE!
F32: Total cost | G32: =SUM(G28:G31) -> #VALUE!

Sheet 9
A1: ENGINEERING DEPARTMENT | H1: daily reading
A2: UTILITY CONSUMPTION SHEET
B3: ='1'!B3 -> February 2024 | C3: 9 | D3: % OCCUPANCY: | E3: ='Daily Meter'!O14
A4: SR.NO | B4: ITEM MEASURED | D4: Previous Reading | E4: 4 AM Reading | F4: 24hrs CONSUMPTION | G4: Cost
A6: 1 | B6: DISTRICT COOLING PLANT
B7: Chilled Water | C7: MWH | D7: ='8'!E7 | E7: ='Daily Meter'!B14 | F7: =E7-D7 -> #VALUE!
C8: TR | F8: =F7*284.34 -> #VALUE! | G8: =F8*0.63 -> #VALUE!
A9: III | B9: WATER METERS
B10: Main DEWA Meter | C10: m3 | D10: ='8'!E10 | E10: ='Daily Meter'!C14 | F10: =E10-D10 -> #VALUE!
B11: Imperial Gallon = m³ x 219.969 | C11: IG | F11: =F10*219.969 -> #VALUE! | G11: =F11*0.06 -> #VALUE!
A12: IV | B12: ELECTRICAL METERS
A13: 1 | B13: Meter 1 - 06065253 | C13: kW x 480 | D13: ='8'!E13 | E13: ='Daily Meter'!H14 | F13: =(E13-D13)*480 -> #VALUE!
A14: 2 | B14: Meter 2 - 06065255 | C14: kW x 480 | D14: ='8'!E14 | E14: ='Daily Meter'!I14 | F14: =(E14-D14)*480 -> #VALUE!
A15: 3 | B15: Meter 3 - 06065259 | C15: kW x 480 | D15: ='8'!E15 | E15: ='Daily Meter'!J14 | F15: =(E15-D15)*480 -> #VALUE!
A16: 4 | B16: Meter 4 - 06065262 | C16: kW x 480 | D16: ='8'!E16 | E16: ='Daily Meter'!K14 | F16: =(E16-D16)*480 -> #VALUE!
A17: 5 | B17: Meter 6 - 06065269 | C17: kW x 480 | D17: ='8'!E17 | E17: ='Daily Meter'!L14 | F17: =(E17-D17)*480 -> #VALUE!
A18: 6 | B18: Meter 7 - 06065283 | C18: kW x 480 | D18: ='8'!E18 | E18: ='Daily Meter'!M14 | F18: =(E18-D18)*480 -> #VALUE!
B19: TOTAL ELECTRICAL CONS.(kWh) | F19: =SUM(F13:F18) -> #VALUE! | G19: =F19*0.43 -> #VALUE!
A21: V | B21: GAS CONSUMPTION
A22: 1 | B22: MAIN LPG METER | C22: M3 | D22: ='8'!E22 | E22: ='Daily Meter'!N14 | F22: =E22-D22 -> #VALUE!
B23: L = m³ x 3.70 | C23: L | F23: =F22*3.7 -> #VALUE! | G23: =F23*2.5 -> #VALUE!
D26: Summary of Daily Hotel consumption
D27: Item measured | E27: Units | F27: Consumption | G27: AED
D28: Chilled water | E28: TR | F28: =F8 -> #VALUE! | G28: =G8 -> #VALUE!
D29: DEWA Water | E29: imp. Gallon | F29: =F11 -> #VALUE! | G29: =G11 -> #VALUE!
D30: Electricity | E30: kwh | F30: =F19 -> #VALUE! | G30: =G19 -> #VALUE!
D31: Gas | E31: m3 | F31: =F22 -> #VALUE! | G31: =G23 -> #VALUE!
F32: Total cost | G32: =SUM(G28:G31) -> #VALUE!

Sheet 10
A1: ENGINEERING DEPARTMENT | H1: daily reading
A2: UTILITY CONSUMPTION SHEET
B3: ='1'!B3 -> February 2024 | C3: 10 | D3: % OCCUPANCY: | E3: ='Daily Meter'!O15
A4: SR.NO | B4: ITEM MEASURED | D4: Previous Reading | E4: 4 AM Reading | F4: 24hrs CONSUMPTION | G4: Cost
A6: 1 | B6: DISTRICT COOLING PLANT
B7: Chilled Water | C7: MWH | D7: ='9'!E7 | E7: ='Daily Meter'!B15 | F7: =E7-D7 -> #VALUE!
C8: TR | F8: =F7*284.34 -> #VALUE! | G8: =F8*0.63 -> #VALUE!
A9: III | B9: WATER METERS
B10: Main DEWA Meter | C10: m3 | D10: ='9'!E10 | E10: ='Daily Meter'!C15 | F10: =E10-D10 -> #VALUE!
B11: Imperial Gallon = m³ x 219.969 | C11: IG | F11: =F10*219.969 -> #VALUE! | G11: =F11*0.06 -> #VALUE!
A12: IV | B12: ELECTRICAL METERS
A13: 1 | B13: Meter 1 - 06065253 | C13: kW x 480 | D13: ='9'!E13 | E13: ='Daily Meter'!H15 | F13: =(E13-D13)*480 -> #VALUE!
A14: 2 | B14: Meter 2 - 06065255 | C14: kW x 480 | D14: ='9'!E14 | E14: ='Daily Meter'!I15 | F14: =(E14-D14)*480 -> #VALUE!
A15: 3 | B15: Meter 3 - 06065259 | C15: kW x 480 | D15: ='9'!E15 | E15: ='Daily Meter'!J15 | F15: =(E15-D15)*480 -> #VALUE!
A16: 4 | B16: Meter 4 - 06065262 | C16: kW x 480 | D16: ='9'!E16 | E16: ='Daily Meter'!K15 | F16: =(E16-D16)*480 -> #VALUE!
A17: 5 | B17: Meter 6 - 06065269 | C17: kW x 480 | D17: ='9'!E17 | E17: ='Daily Meter'!L15 | F17: =(E17-D17)*480 -> #VALUE!
A18: 6 | B18: Meter 7 - 06065283 | C18: kW x 480 | D18: ='9'!E18 | E18: ='Daily Meter'!M15 | F18: =(E18-D18)*480 -> #VALUE!
B19: TOTAL ELECTRICAL CONS.(kWh) | F19: =SUM(F13:F18) -> #VALUE! | G19: =F19*0.43 -> #VALUE!
A21: V | B21: GAS CONSUMPTION
A22: 1 | B22: MAIN LPG METER | C22: M3 | D22: ='9'!E22 | E22: ='Daily Meter'!N15 | F22: =E22-D22 -> #VALUE!
B23: L = m³ x 3.70 | C23: L | F23: =F22*3.7 -> #VALUE! | G23: =F23*2.5 -> #VALUE!
D26: Summary of Daily Hotel consumption
D27: Item measured | E27: Units | F27: Consumption | G27: AED
D28: Chilled water | E28: TR | F28: =F8 -> #VALUE! | G28: =G8 -> #VALUE!
D29: DEWA Water | E29: imp. Gallon | F29: =F11 -> #VALUE! | G29: =G11 -> #VALUE!
D30: Electricity | E30: kwh | F30: =F19 -> #VALUE! | G30: =G19 -> #VALUE!
D31: Gas | E31: m3 | F31: =F22 -> #VALUE! | G31: =G23 -> #VALUE!
F32: Total cost | G32: =SUM(G28:G31) -> #VALUE!

Sheet 11
A1: ENGINEERING DEPARTMENT | H1: daily reading
A2: UTILITY CONSUMPTION SHEET
B3: ='1'!B3 -> February 2024 | C3: 11 | D3: % OCCUPANCY: | E3: ='Daily Meter'!O16
A4: SR.NO | B4: ITEM MEASURED | D4: Previous Reading | E4: 4 AM Reading | F4: 24hrs CONSUMPTION | G4: Cost
A6: 1 | B6: DISTRICT COOLING PLANT
B7: Chilled Water | C7: MWH | D7: ='10'!E7 | E7: ='Daily Meter'!B16 | F7: =E7-D7 -> #VALUE!
C8: TR | F8: =F7*284.34 -> #VALUE! | G8: =F8*0.63 -> #VALUE!
A9: III | B9: WATER METERS
B10: Main DEWA Meter | C10: m3 | D10: ='10'!E10 | E10: ='Daily Meter'!C16 | F10: =E10-D10 -> #VALUE!
B11: Imperial Gallon = m³ x 219.969 | C11: IG | F11: =F10*219.969 -> #VALUE! | G11: =F11*0.06 -> #VALUE!
A12: IV | B12: ELECTRICAL METERS
A13: 1 | B13: Meter 1 - 06065253 | C13: kW x 480 | D13: ='10'!E13 | E13: ='Daily Meter'!H16 | F13: =(E13-D13)*480 -> #VALUE!
A14: 2 | B14: Meter 2 - 06065255 | C14: kW x 480 | D14: ='10'!E14 | E14: ='Daily Meter'!I16 | F14: =(E14-D14)*480 -> #VALUE!
A15: 3 | B15: Meter 3 - 06065259 | C15: kW x 480 | D15: ='10'!E15 | E15: ='Daily Meter'!J16 | F15: =(E15-D15)*480 -> #VALUE!
A16: 4 | B16: Meter 4 - 06065262 | C16: kW x 480 | D16: ='10'!E16 | E16: ='Daily Meter'!K16 | F16: =(E16-D16)*480 -> #VALUE!
A17: 5 | B17: Meter 6 - 06065269 | C17: kW x 480 | D17: ='10'!E17 | E17: ='Daily Meter'!L16 | F17: =(E17-D17)*480 -> #VALUE!
A18: 6 | B18: Meter 7 - 06065283 | C18: kW x 480 | D18: ='10'!E18 | E18: ='Daily Meter'!M16 | F18: =(E18-D18)*480 -> #VALUE!
B19: TOTAL ELECTRICAL CONS.(kWh) | F19: =SUM(F13:F18) -> #VALUE! | G19: =F19*0.43 -> #VALUE!
A21: V | B21: GAS CONSUMPTION
A22: 1 | B22: MAIN LPG METER | C22: M3 | D22: ='10'!E22 | E22: ='Daily Meter'!N16 | F22: =E22-D22 -> #VALUE!
B23: L = m³ x 3.70 | C23: L | F23: =F22*3.7 -> #VALUE! | G23: =F23*2.5 -> #VALUE!
D26: Summary of Daily Hotel consumption
D27: Item measured | E27: Units | F27: Consumption | G27: AED
D28: Chilled water | E28: TR | F28: =F8 -> #VALUE! | G28: =G8 -> #VALUE!
D29: DEWA Water | E29: imp. Gallon | F29: =F11 -> #VALUE! | G29: =G11 -> #VALUE!
D30: Electricity | E30: kwh | F30: =F19 -> #VALUE! | G30: =G19 -> #VALUE!
D31: Gas | E31: m3 | F31: =F22 -> #VALUE! | G31: =G23 -> #VALUE!
F32: Total cost | G32: =SUM(G28:G31) -> #VALUE!

Sheet 12
A1: ENGINEERING DEPARTMENT | H1: daily reading
A2: UTILITY CONSUMPTION SHEET
B3: ='1'!B3 -> February 2024 | C3: 12 | D3: % OCCUPANCY: | E3: ='Daily Meter'!O17
A4: SR.NO | B4: ITEM MEASURED | D4: Previous Reading | E4: 4 AM Reading | F4: 24hrs CONSUMPTION | G4: Cost
A6: 1 | B6: DISTRICT COOLING PLANT
B7: Chilled Water | C7: MWH | D7: ='11'!E7 | E7: ='Daily Meter'!B17 | F7: =E7-D7 -> #VALUE!
C8: TR | F8: =F7*284.34 -> #VALUE! | G8: =F8*0.63 -> #VALUE!
A9: III | B9: WATER METERS
B10: Main DEWA Meter | C10: m3 | D10: ='11'!E10 | E10: ='Daily Meter'!C17 | F10: =E10-D10 -> #VALUE!
B11: Imperial Gallon = m³ x 219.969 | C11: IG | F11: =F10*219.969 -> #VALUE! | G11: =F11*0.06 -> #VALUE!
A12: IV | B12: ELECTRICAL METERS
A13: 1 | B13: Meter 1 - 06065253 | C13: kW x 480 | D13: ='11'!E13 | E13: ='Daily Meter'!H17 | F13: =(E13-D13)*480 -> #VALUE!
A14: 2 | B14: Meter 2 - 06065255 | C14: kW x 480 | D14: ='11'!E14 | E14: ='Daily Meter'!I17 | F14: =(E14-D14)*480 -> #VALUE!
A15: 3 | B15: Meter 3 - 06065259 | C15: kW x 480 | D15: ='11'!E15 | E15: ='Daily Meter'!J17 | F15: =(E15-D15)*480 -> #VALUE!
A16: 4 | B16: Meter 4 - 06065262 | C16: kW x 480 | D16: ='11'!E16 | E16: ='Daily Meter'!K17 | F16: =(E16-D16)*480 -> #VALUE!
A17: 5 | B17: Meter 6 - 06065269 | C17: kW x 480 | D17: ='11'!E17 | E17: ='Daily Meter'!L17 | F17: =(E17-D17)*480 -> #VALUE!
A18: 6 | B18: Meter 7 - 06065283 | C18: kW x 480 | D18: ='11'!E18 | E18: ='Daily Meter'!M17 | F18: =(E18-D18)*480 -> #VALUE!
B19: TOTAL ELECTRICAL CONS.(kWh) | F19: =SUM(F13:F18) -> #VALUE! | G19: =F19*0.43 -> #VALUE!
A21: V | B21: GAS CONSUMPTION
A22: 1 | B22: MAIN LPG METER | C22: M3 | D22: ='11'!E22 | E22: ='Daily Meter'!N17 | F22: =E22-D22 -> #VALUE!
B23: L = m³ x 3.70 | C23: L | F23: =F22*3.7 -> #VALUE! | G23: =F23*2.5 -> #VALUE!
D26: Summary of Daily Hotel consumption
D27: Item measured | E27: Units | F27: Consumption | G27: AED
D28: Chilled water | E28: TR | F28: =F8 -> #VALUE! | G28: =G8 -> #VALUE!
D29: DEWA Water | E29: imp. Gallon | F29: =F11 -> #VALUE! | G29: =G11 -> #VALUE!
D30: Electricity | E30: kwh | F30: =F19 -> #VALUE! | G30: =G19 -> #VALUE!
D31: Gas | E31: m3 | F31: =F22 -> #VALUE! | G31: =G23 -> #VALUE!
F32: Total cost | G32: =SUM(G28:G31) -> #VALUE!

Sheet 13
A1: ENGINEERING DEPARTMENT | H1: daily reading
A2: UTILITY CONSUMPTION SHEET
B3: ='1'!B3 -> February 2024 | C3: 13 | D3: % OCCUPANCY: | E3: ='Daily Meter'!O18
A4: SR.NO | B4: ITEM MEASURED | D4: Previous Reading | E4: 4 AM Reading | F4: 24hrs CONSUMPTION | G4: Cost
A6: 1 | B6: DISTRICT COOLING PLANT
B7: Chilled Water | C7: MWH | D7: ='12'!E7 | E7: ='Daily Meter'!B18 | F7: =E7-D7 -> #VALUE!
C8: TR | F8: =F7*284.34 -> #VALUE! | G8: =F8*0.63 -> #VALUE!
A9: III | B9: WATER METERS
B10: Main DEWA Meter | C10: m3 | D10: ='12'!E10 | E10: ='Daily Meter'!C18 | F10: =E10-D10 -> #VALUE!
B11: Imperial Gallon = m³ x 219.969 | C11: IG | F11: =F10*219.969 -> #VALUE! | G11: =F11*0.06 -> #VALUE!
A12: IV | B12: ELECTRICAL METERS
A13: 1 | B13: Meter 1 - 06065253 | C13: kW x 480 | D13: ='12'!E13 | E13: ='Daily Meter'!H18 | F13: =(E13-D13)*480 -> #VALUE!
A14: 2 | B14: Meter 2 - 06065255 | C14: kW x 480 | D14: ='12'!E14 | E14: ='Daily Meter'!I18 | F14: =(E14-D14)*480 -> #VALUE!
A15: 3 | B15: Meter 3 - 06065259 | C15: kW x 480 | D15: ='12'!E15 | E15: ='Daily Meter'!J18 | F15: =(E15-D15)*480 -> #VALUE!
A16: 4 | B16: Meter 4 - 06065262 | C16: kW x 480 | D16: ='12'!E16 | E16: ='Daily Meter'!K18 | F16: =(E16-D16)*480 -> #VALUE!
A17: 5 | B17: Meter 6 - 06065269 | C17: kW x 480 | D17: ='12'!E17 | E17: ='Daily Meter'!L18 | F17: =(E17-D17)*480 -> #VALUE!
A18: 6 | B18: Meter 7 - 06065283 | C18: kW x 480 | D18: ='12'!E18 | E18: ='Daily Meter'!M18 | F18: =(E18-D18)*480 -> #VALUE!
B19: TOTAL ELECTRICAL CONS.(kWh) | F19: =SUM(F13:F18) -> #VALUE! | G19: =F19*0.43 -> #VALUE!
A21: V | B21: GAS CONSUMPTION
A22: 1 | B22: MAIN LPG METER | C22: M3 | D22: ='12'!E22 | E22: ='Daily Meter'!N18 | F22: =E22-D22 -> #VALUE!
B23: L = m³ x 3.70 | C23: L | F23: =F22*3.7 -> #VALUE! | G23: =F23*2.5 -> #VALUE!
D26: Summary of Daily Hotel consumption
D27: Item measured | E27: Units | F27: Consumption | G27: AED
D28: Chilled water | E28: TR | F28: =F8 -> #VALUE! | G28: =G8 -> #VALUE!
D29: DEWA Water | E29: imp. Gallon | F29: =F11 -> #VALUE! | G29: =G11 -> #VALUE!
D30: Electricity | E30: kwh | F30: =F19 -> #VALUE! | G30: =G19 -> #VALUE!
D31: Gas | E31: m3 | F31: =F22 -> #VALUE! | G31: =G23 -> #VALUE!
F32: Total cost | G32: =SUM(G28:G31) -> #VALUE!

Sheet 14
A1: ENGINEERING DEPARTMENT | H1: daily reading
A2: UTILITY CONSUMPTION SHEET
B3: ='1'!B3 -> February 2024 | C3: 14 | D3: % OCCUPANCY: | E3: ='Daily Meter'!O19
A4: SR.NO | B4: ITEM MEASURED | D4: Previous Reading | E4: 4 AM Reading | F4: 24hrs CONSUMPTION | G4: Cost
A6: 1 | B6: DISTRICT COOLING PLANT
B7: Chilled Water | C7: MWH | D7: ='13'!E7 | E7: ='Daily Meter'!B19 | F7: =E7-D7 -> #VALUE!
C8: TR | F8: =F7*284.34 -> #VALUE! | G8: =F8*0.63 -> #VALUE!
A9: III | B9: WATER METERS
B10: Main DEWA Meter | C10: m3 | D10: ='13'!E10 | E10: ='Daily Meter'!C19 | F10: =E10-D10 -> #VALUE!
B11: Imperial Gallon = m³ x 219.969 | C11: IG | F11: =F10*219.969 -> #VALUE! | G11: =F11*0.06 -> #VALUE!
A12: IV | B12: ELECTRICAL METERS
A13: 1 | B13: Meter 1 - 06065253 | C13: kW x 480 | D13: ='13'!E13 | E13: ='Daily Meter'!H19 | F13: =(E13-D13)*480 -> #VALUE!
A14: 2 | B14: Meter 2 - 06065255 | C14: kW x 480 | D14: ='13'!E14 | E14: ='Daily Meter'!I19 | F14: =(E14-D14)*480 -> #VALUE!
A15: 3 | B15: Meter 3 - 06065259 | C15: kW x 480 | D15: ='13'!E15 | E15: ='Daily Meter'!J19 | F15: =(E15-D15)*480 -> #VALUE!
A16: 4 | B16: Meter 4 - 06065262 | C16: kW x 480 | D16: ='13'!E16 | E16: ='Daily Meter'!K19 | F16: =(E16-D16)*480 -> #VALUE!
A17: 5 | B17: Meter 6 - 06065269 | C17: kW x 480 | D17: ='13'!E17 | E17: ='Daily Meter'!L19 | F17: =(E17-D17)*480 -> #VALUE!
A18: 6 | B18: Meter 7 - 06065283 | C18: kW x 480 | D18: ='13'!E18 | E18: ='Daily Meter'!M19 | F18: =(E18-D18)*480 -> #VALUE!
B19: TOTAL ELECTRICAL CONS.(kWh) | F19: =SUM(F13:F18) -> #VALUE! | G19: =F19*0.43 -> #VALUE!
A21: V | B21: GAS CONSUMPTION
A22: 1 | B22: MAIN LPG METER | C22: M3 | D22: ='13'!E22 | E22: ='Daily Meter'!N19 | F22: =E22-D22 -> #VALUE!
B23: L = m³ x 3.70 | C23: L | F23: =F22*3.7 -> #VALUE! | G23: =F23*2.5 -> #VALUE!
D26: Summary of Daily Hotel consumption
D27: Item measured | E27: Units | F27: Consumption | G27: AED
D28: Chilled water | E28: TR | F28: =F8 -> #VALUE! | G28: =G8 -> #VALUE!
D29: DEWA Water | E29: imp. Gallon | F29: =F11 -> #VALUE! | G29: =G11 -> #VALUE!
D30: Electricity | E30: kwh | F30: =F19 -> #VALUE! | G30: =G19 -> #VALUE!
D31: Gas | E31: m3 | F31: =F22 -> #VALUE! | G31: =G23 -> #VALUE!
F32: Total cost | G32: =SUM(G28:G31) -> #VALUE!

Sheet 15
A1: ENGINEERING DEPARTMENT | H1: daily reading
A2: UTILITY CONSUMPTION SHEET
B3: ='1'!B3 -> February 2024 | C3: 15 | D3: % OCCUPANCY: | E3: ='Daily Meter'!O20
A4: SR.NO | B4: ITEM MEASURED | D4: Previous Reading | E4: 4 AM Reading | F4: 24hrs CONSUMPTION | G4: Cost
A6: 1 | B6: DISTRICT COOLING PLANT
B7: Chilled Water | C7: MWH | D7: ='14'!E7 | E7: ='Daily Meter'!B20 | F7: =E7-D7 -> #VALUE!
C8: TR | F8: =F7*284.34 -> #VALUE! | G8: =F8*0.63 -> #VALUE!
A9: III | B9: WATER METERS
B10: Main DEWA Meter | C10: m3 | D10: ='14'!E10 | E10: ='Daily Meter'!C20 | F10: =E10-D10 -> #VALUE!
B11: Imperial Gallon = m³ x 219.969 | C11: IG | F11: =F10*219.969 -> #VALUE! | G11: =F11*0.06 -> #VALUE!
A12: IV | B12: ELECTRICAL METERS
A13: 1 | B13: Meter 1 - 06065253 | C13: kW x 480 | D13: ='14'!E13 | E13: ='Daily Meter'!H20 | F13: =(E13-D13)*480 -> #VALUE!
A14: 2 | B14: Meter 2 - 06065255 | C14: kW x 480 | D14: ='14'!E14 | E14: ='Daily Meter'!I20 | F14: =(E14-D14)*480 -> #VALUE!
A15: 3 | B15: Meter 3 - 06065259 | C15: kW x 480 | D15: ='14'!E15 | E15: ='Daily Meter'!J20 | F15: =(E15-D15)*480 -> #VALUE!
A16: 4 | B16: Meter 4 - 06065262 | C16: kW x 480 | D16: ='14'!E16 | E16: ='Daily Meter'!K20 | F16: =(E16-D16)*480 -> #VALUE!
A17: 5 | B17: Meter 6 - 06065269 | C17: kW x 480 | D17: ='14'!E17 | E17: ='Daily Meter'!L20 | F17: =(E17-D17)*480 -> #VALUE!
A18: 6 | B18: Meter 7 - 06065283 | C18: kW x 480 | D18: ='14'!E18 | E18: ='Daily Meter'!M20 | F18: =(E18-D18)*480 -> #VALUE!
B19: TOTAL ELECTRICAL CONS.(kWh) | F19: =SUM(F13:F18) -> #VALUE! | G19: =F19*0.43 -> #VALUE!
A21: V | B21: GAS CONSUMPTION
A22: 1 | B22: MAIN LPG METER | C22: M3 | D22: ='14'!E22 | E22: ='Daily Meter'!N20 | F22: =E22-D22 -> #VALUE!
B23: L = m³ x 3.70 | C23: L | F23: =F22*3.7 -> #VALUE! | G23: =F23*2.5 -> #VALUE!
D26: Summary of Daily Hotel consumption
D27: Item measured | E27: Units | F27: Consumption | G27: AED
D28: Chilled water | E28: TR | F28: =F8 -> #VALUE! | G28: =G8 -> #VALUE!
D29: DEWA Water | E29: imp. Gallon | F29: =F11 -> #VALUE! | G29: =G11 -> #VALUE!
D30: Electricity | E30: kwh | F30: =F19 -> #VALUE! | G30: =G19 -> #VALUE!
D31: Gas | E31: m3 | F31: =F22 -> #VALUE! | G31: =G23 -> #VALUE!
F32: Total cost | G32: =SUM(G28:G31) -> #VALUE!

Sheet 16
A1: ENGINEERING DEPARTMENT | H1: daily reading
A2: UTILITY CONSUMPTION SHEET
B3: ='1'!B3 -> February 2024 | C3: 16 | D3: % OCCUPANCY: | E3: ='Daily Meter'!O21
A4: SR.NO | B4: ITEM MEASURED | D4: Previous Reading | E4: 4 AM Reading | F4: 24hrs CONSUMPTION | G4: Cost
A6: 1 | B6: DISTRICT COOLING PLANT
B7: Chilled Water | C7: MWH | D7: ='15'!E7 | E7: ='Daily Meter'!B21 | F7: =E7-D7 -> #VALUE!
C8: TR | F8: =F7*284.34 -> #VALUE! | G8: =F8*0.63 -> #VALUE!
A9: III | B9: WATER METERS
B10: Main DEWA Meter | C10: m3 | D10: ='15'!E10 | E10: ='Daily Meter'!C21 | F10: =E10-D10 -> #VALUE!
B11: Imperial Gallon = m³ x 219.969 | C11: IG | F11: =F10*219.969 -> #VALUE! | G11: =F11*0.06 -> #VALUE!
A12: IV | B12: ELECTRICAL METERS
A13: 1 | B13: Meter 1 - 06065253 | C13: kW x 480 | D13: ='15'!E13 | E13: ='Daily Meter'!H21 | F13: =(E13-D13)*480 -> #VALUE!
A14: 2 | B14: Meter 2 - 06065255 | C14: kW x 480 | D14: ='15'!E14 | E14: ='Daily Meter'!I21 | F14: =(E14-D14)*480 -> #VALUE!
A15: 3 | B15: Meter 3 - 06065259 | C15: kW x 480 | D15: ='15'!E15 | E15: ='Daily Meter'!J21 | F15: =(E15-D15)*480 -> #VALUE!
A16: 4 | B16: Meter 4 - 06065262 | C16: kW x 480 | D16: ='15'!E16 | E16: ='Daily Meter'!K21 | F16: =(E16-D16)*480 -> #VALUE!
A17: 5 | B17: Meter 6 - 06065269 | C17: kW x 480 | D17: ='15'!E17 | E17: ='Daily Meter'!L21 | F17: =(E17-D17)*480 -> #VALUE!
A18: 6 | B18: Meter 7 - 06065283 | C18: kW x 480 | D18: ='15'!E18 | E18: ='Daily Meter'!M21 | F18: =(E18-D18)*480 -> #VALUE!
B19: TOTAL ELECTRICAL CONS.(kWh) | F19: =SUM(F13:F18) -> #VALUE! | G19: =F19*0.43 -> #VALUE!
A21: V | B21: GAS CONSUMPTION
A22: 1 | B22: MAIN LPG METER | C22: M3 | D22: ='15'!E22 | E22: ='Daily Meter'!N21 | F22: =E22-D22 -> #VALUE!
B23: L = m³ x 3.70 | C23: L | F23: =F22*3.7 -> #VALUE! | G23: =F23*2.5 -> #VALUE!
D26: Summary of Daily Hotel consumption
D27: Item measured | E27: Units | F27: Consumption | G27: AED
D28: Chilled water | E28: TR | F28: =F8 -> #VALUE! | G28: =G8 -> #VALUE!
D29: DEWA Water | E29: imp. Gallon | F29: =F11 -> #VALUE! | G29: =G11 -> #VALUE!
D30: Electricity | E30: kwh | F30: =F19 -> #VALUE! | G30: =G19 -> #VALUE!
D31: Gas | E31: m3 | F31: =F22 -> #VALUE! | G31: =G23 -> #VALUE!
F32: Total cost | G32: =SUM(G28:G31) -> #VALUE!

Sheet 17
A1: ENGINEERING DEPARTMENT | H1: daily reading
A2: UTILITY CONSUMPTION SHEET
B3: ='1'!B3 -> February 2024 | C3: 17 | D3: % OCCUPANCY: | E3: ='Daily Meter'!O22
A4: SR.NO | B4: ITEM MEASURED | D4: Previous Reading | E4: 4 AM Reading | F4: 24hrs CONSUMPTION | G4: Cost
A6: 1 | B6: DISTRICT COOLING PLANT
B7: Chilled Water | C7: MWH | D7: ='16'!E7 | E7: ='Daily Meter'!B22 | F7: =E7-D7 -> #VALUE!
C8: TR | F8: =F7*284.34 -> #VALUE! | G8: =F8*0.63 -> #VALUE!
A9: III | B9: WATER METERS
B10: Main DEWA Meter | C10: m3 | D10: ='16'!E10 | E10: ='Daily Meter'!C22 | F10: =E10-D10 -> #VALUE!
B11: Imperial Gallon = m³ x 219.969 | C11: IG | F11: =F10*219.969 -> #VALUE! | G11: =F11*0.06 -> #VALUE!
A12: IV | B12: ELECTRICAL METERS
A13: 1 | B13: Meter 1 - 06065253 | C13: kW x 480 | D13: ='16'!E13 | E13: ='Daily Meter'!H22 | F13: =(E13-D13)*480 -> #VALUE!
A14: 2 | B14: Meter 2 - 06065255 | C14: kW x 480 | D14: ='16'!E14 | E14: ='Daily Meter'!I22 | F14: =(E14-D14)*480 -> #VALUE!
A15: 3 | B15: Meter 3 - 06065259 | C15: kW x 480 | D15: ='16'!E15 | E15: ='Daily Meter'!J22 | F15: =(E15-D15)*480 -> #VALUE!
A16: 4 | B16: Meter 4 - 06065262 | C16: kW x 480 | D16: ='16'!E16 | E16: ='Daily Meter'!K22 | F16: =(E16-D16)*480 -> #VALUE!
A17: 5 | B17: Meter 6 - 06065269 | C17: kW x 480 | D17: ='16'!E17 | E17: ='Daily Meter'!L22 | F17: =(E17-D17)*480 -> #VALUE!
A18: 6 | B18: Meter 7 - 06065283 | C18: kW x 480 | D18: ='16'!E18 | E18: ='Daily Meter'!M22 | F18: =(E18-D18)*480 -> #VALUE!
