Workbook

Sheet Sheet2
A1: Site Name | B1: Day | C1: Month | D1: Year | E1: Total Electricity Kwh | F1: Electricity Tariff ($/Kwh) | G1: LPG (Liters) | H1: LPG $/Liters | I1: Water Utility Supply (IG) IG | J1: Water Utility Supply (IG) $/IG | K1: District Energy Cooling RTH | L1: District Energy Cooling $/RTH | M1: Room Nights | N1: Total Guests
A2: 25hours Dubai One Central | B2: 1 | C2: 2 | D2: 2023 | E2: =Sheet1!E2+Sheet1!F2+Sheet1!G2+Sheet1!H2+Sheet1!I2+Sheet1!J2 -> 11376 | F2: 0.44 | G2: =Sheet1!M2 -> 430.31 | H2: 2.5 | I2: =Sheet1!L2 -> 49053.087 | J2: 0.06 | K2: =Sheet1!K2 -> 3582.684 | L2: =0.568+0.075 -> 0.643 | M2: =Sheet1!N2 -> 422.0216
A3: 25hours Dubai One Central | B3: =B2+1 -> 2 | C3: 2 | D3: 2023 | E3: =Sheet1!E3+Sheet1!F3+Sheet1!G3+Sheet1!H3+Sheet1!I3+Sheet1!J3 -> 12768 | F3: 0.44 | G3: =Sheet1!M3 -> 519.11 | H3: 2.5 | I3: =Sheet1!L3 -> 67750.452 | J3: 0.06 | K3: =Sheet1!K3 -> 5146.554 | L3: =0.568+0.075 -> 0.643 | M3: =Sheet1!N3 -> 343.9884
A4: 25hours Dubai One Central | B4: =B3+1 -> 3 | C4: 2 | D4: 2023 | E4: =Sheet1!E4+Sheet1!F4+Sheet1!G4+Sheet1!H4+Sheet1!I4+Sheet1!J4 -> 18864 | F4: 0.44 | G4: =Sheet1!M4 -> 510.6 | H4: 2.5 | I4: =Sheet1!L4 -> 65770.731 | J4: 0.06 | K4: =Sheet1!K4 -> 6710.424 | L4: =0.568+0.075 -> 0.643 | M4: =Sheet1!N4 -> 287.0042
A5: 25hours Dubai One Central | B5: =B4+1 -> 4 | C5: 2 | D5: 2023 | E5: =Sheet1!E5+Sheet1!F5+Sheet1!G5+Sheet1!H5+Sheet1!I5+Sheet1!J5 -> 13632 | F5: 0.44 | G5: =Sheet1!M5 -> 458.43 | H5: 2.5 | I5: =Sheet1!L5 -> 71709.894 | J5: 0.06 | K5: =Sheet1!K5 -> 4691.61 | L5: =0.568+0.075 -> 0.643 | M5: =Sheet1!N5 -> 294.035
A6: 25hours Dubai One Central | B6: =B5+1 -> 5 | C6: 2 | D6: 2023 | E6: =Sheet1!E6+Sheet1!F6+Sheet1!G6+Sheet1!H6+Sheet1!I6+Sheet1!J6 -> 17088 | F6: 0.44 | G6: =Sheet1!M6 -> 499.13 | H6: 2.5 | I6: =Sheet1!L6 -> 45313.614 | J6: 0.06 | K6: =Sheet1!K6 -> 5174.988 | L6: =0.568+0.075 -> 0.643 | M6: =Sheet1!N6 -> 307.0116
A7: 25hours Dubai One Central | B7: =B6+1 -> 6 | C7: 2 | D7: 2023 | E7: =Sheet1!E7+Sheet1!F7+Sheet1!G7+Sheet1!H7+Sheet1!I7+Sheet1!J7 -> 21216 | F7: 0.44 | G7: =Sheet1!M7 -> 600.51 | H7: 2.5 | I7: =Sheet1!L7 -> 65770.731 | J7: 0.06 | K7: =Sheet1!K7 -> 6994.764 | L7: =0.568+0.075 -> 0.643 | M7: =Sheet1!N7 -> 383.005
A8: 25hours Dubai One Central | B8: =B7+1 -> 7 | C8: 2 | D8: 2023 | E8: =Sheet1!E8+Sheet1!F8+Sheet1!G8+Sheet1!H8+Sheet1!I8+Sheet1!J8 -> 12096 | F8: 0.44 | G8: =Sheet1!M8 -> 372.59 | H8: 2.5 | I8: =Sheet1!L8 -> 56312.064 | J8: 0.06 | K8: =Sheet1!K8 -> 4321.968 | L8: =0.568+0.075 -> 0.643 | M8: =Sheet1!N8 -> 418.9836
A9: 25hours Dubai One Central | B9: =B8+1 -> 8 | C9: 2 | D9: 2023 | E9: =Sheet1!E9+Sheet1!F9+Sheet1!G9+Sheet1!H9+Sheet1!I9+Sheet1!J9 -> 16752 | F9: 0.44 | G9: =Sheet1!M9 -> 507.64 | H9: 2.5 | I9: =Sheet1!L9 -> 50152.932 | J9: 0.06 | K9: =Sheet1!K9 -> 6539.82 | L9: =0.568+0.075 -> 0.643 | M9: =Sheet1!N9 -> 424.018
A10: 25hours Dubai One Central | B10: =B9+1 -> 9 | C10: 2 | D10: 2023 | E10: =Sheet1!E10+Sheet1!F10+Sheet1!G10+Sheet1!H10+Sheet1!I10+Sheet1!J10 -> 16224 | F10: 0.44 | G10: =Sheet1!M10 -> 501.72 | H10: 2.5 | I10: =Sheet1!L10 -> 78968.871 | J10: 0.06 | K10: =Sheet1!K10 -> 5914.272 | L10: =0.568+0.075 -> 0.643 | M10: =Sheet1!N10 -> 366.9904
A11: 25hours Dubai One Central | B11: =B10+1 -> 10 | C11: 2 | D11: 2023 | E11: =Sheet1!E11+Sheet1!F11+Sheet1!G11+Sheet1!H11+Sheet1!I11+Sheet1!J11 -> 17760 | F11: 0.44 | G11: =Sheet1!M11 -> 535.76 | H11: 2.5 | I11: =Sheet1!L11 -> 78748.902 | J11: 0.06 | K11: =Sheet1!K11 -> 5459.328 | L11: =0.568+0.075 -> 0.643 | M11: =Sheet1!N11 -> 352.0174
A12: 25hours Dubai One Central | B12: =B11+1 -> 11 | C12: 2 | D12: 2023 | E12: =Sheet1!E12+Sheet1!F12+Sheet1!G12+Sheet1!H12+Sheet1!I12+Sheet1!J12 -> 18096 | F12: 0.44 | G12: =Sheet1!M12 -> 533.17 | H12: 2.5 | I12: =Sheet1!L12 -> 46193.49 | J12: 0.06 | K12: =Sheet1!K12 -> 5459.328 | L12: =0.568+0.075 -> 0.643 | M12: =Sheet1!N12 -> 300.979
A13: 25hours Dubai One Central | B13: =B12+1 -> 12 | C13: 2 | D13: 2023 | E13: =Sheet1!E13+Sheet1!F13+Sheet1!G13+Sheet1!H13+Sheet1!I13+Sheet1!J13 -> 16080 | F13: 0.44 | G13: =Sheet1!M13 -> 445.11 | H13: 2.5 | I13: =Sheet1!L13 -> 69510.204 | J13: 0.06 | K13: =Sheet1!K13 -> 5032.818 | L13: =0.568+0.075 -> 0.643 | M13: =Sheet1!N13 -> 312.0026
A14: 25hours Dubai One Central | B14: =B13+1 -> 13 | C14: 2 | D14: 2023 | E14: =Sheet1!E14+Sheet1!F14+Sheet1!G14+Sheet1!H14+Sheet1!I14+Sheet1!J14 -> 20112 | F14: 0.44 | G14: =Sheet1!M14 -> 483.59 | H14: 2.5 | I14: =Sheet1!L14 -> 51032.808 | J14: 0.06 | K14: =Sheet1!K14 -> 6767.292 | L14: =0.568+0.075 -> 0.643 | M14: =Sheet1!N14 -> 316.9936
... A30: 25hours Dubai One Central | B30: =B29+1 -> 29 | C30: 2 | D30: 2023 | E30: =Sheet1!E30+Sheet1!F30+Sheet1!G30+Sheet1!H30+Sheet1!I30+Sheet1!J30 -> 0 | F30: 0.44 | G30: =Sheet1!M30 -> 0 | H30: 2.5 | I30: =Sheet1!L30 -> 0 | J30: 0.06 | K30: =Sheet1!K30 -> 0 | L30: =0.568+0.075 -> 0.643 | M30: =Sheet1!N30 -> 0

Sheet Sheet1
A1: Site Name | B1: Day | C1: Month | D1: Year | E1: Meter 1 - 06065253 | F1: Meter 2 - 06065255 | G1: Meter 3 - 06065259 | H1: Meter 4 - 06065262 | I1: Meter 6 - 06065269 | J1: Meter 7 - 06065283 | K1: District Cooling | L1: Water | M1: Gas | N1: Room Nights | O1: Total Guests
A2: 25hours Dubai One Central | B2: 1 | C2: 2 | D2: 2023 | E2: ='1'!G14 -> 2352 | F2: 1440 | G2: 1584 | H2: 912 | I2: 1632 | J2: 3456 | K2: ='1'!H9 -> 3582.684 | L2: ='1'!H12 -> 49053.087 | M2: ='1'!H24 -> 430.31 | N2: ='Daily Meter'!X6*434/100 -> 422.0216
A3: 25hours Dubai One Central | B3: =B2+1 -> 2 | C3: 2 | D3: 2023 | E3: =('Daily Meter'!K7-'Daily Meter'!K6)*480 -> 2448 | F3: =('Daily Meter'!M7-'Daily Meter'!M6)*480 -> 1488 | G3: =('Daily Meter'!O7-'Daily Meter'!O6)*480 -> 1776 | H3: =('Daily Meter'!Q7-'Daily Meter'!Q6)*480 -> 960 | I3: =('Daily Meter'!S7-'Daily Meter'!S6)*480 -> 1824 | J3: =('Daily Meter'!U7-'Daily Meter'!U6)*480 -> 4272 | K3: =('Daily Meter'!C7-'Daily Meter'!C6)*284.34 -> 5146.554 | L3: =('Daily Meter'!E7-'Daily Meter'!E6)*219.969 -> 67750.452 | M3: =('Daily Meter'!W7-'Daily Meter'!W6)*3.7 -> 519.11 | N3: ='Daily Meter'!X7*434/100 -> 343.9884
A4: 25hours Dubai One Central | B4: =B3+1 -> 3 | C4: 2 | D4: 2023 | E4: =('Daily Meter'!K8-'Daily Meter'!K7)*480 -> 3888 | F4: =('Daily Meter'!M8-'Daily Meter'!M7)*480 -> 2160 | G4: =('Daily Meter'!O8-'Daily Meter'!O7)*480 -> 2592 | H4: =('Daily Meter'!Q8-'Daily Meter'!Q7)*480 -> 1632 | I4: =('Daily Meter'!S8-'Daily Meter'!S7)*480 -> 2544 | J4: =('Daily Meter'!U8-'Daily Meter'!U7)*480 -> 6048 | K4: =('Daily Meter'!C8-'Daily Meter'!C7)*284.34 -> 6710.424 | L4: =('Daily Meter'!E8-'Daily Meter'!E7)*219.969 -> 65770.731 | M4: =('Daily Meter'!W8-'Daily Meter'!W7)*3.7 -> 510.6 | N4: ='Daily Meter'!X8*434/100 -> 287.0042
A5: 25hours Dubai One Central | B5: =B4+1 -> 4 | C5: 2 | D5: 2023 | E5: =('Daily Meter'!K9-'Daily Meter'!K8)*480 -> 2640 | F5: =('Daily Meter'!M9-'Daily Meter'!M8)*480 -> 1488 | G5: =('Daily Meter'!O9-'Daily Meter'!O8)*480 -> 1920 | H5: =('Daily Meter'!Q9-'Daily Meter'!Q8)*480 -> 1200 | I5: =('Daily Meter'!S9-'Daily Meter'!S8)*480 -> 1824 | J5: =('Daily Meter'!U9-'Daily Meter'!U8)*480 -> 4560 | K5: =('Daily Meter'!C9-'Daily Meter'!C8)*284.34 -> 4691.61 | L5: =('Daily Meter'!E9-'Daily Meter'!E8)*219.969 -> 71709.894 | M5: =('Daily Meter'!W9-'Daily Meter'!W8)*3.7 -> 458.43 | N5: ='Daily Meter'!X9*434/100 -> 294.035
A6: 25hours Dubai One Central | B6: =B5+1 -> 5 | C6: 2 | D6: 2023 | E6: =('Daily Meter'!K10-'Daily Meter'!K9)*480 -> 3360 | F6: =('Daily Meter'!M10-'Daily Meter'!M9)*480 -> 1776 | G6: =('Daily Meter'!O10-'Daily Meter'!O9)*480 -> 2496 | H6: =('Daily Meter'!Q10-'Daily Meter'!Q9)*480 -> 1488 | I6: =('Daily Meter'!S10-'Daily Meter'!S9)*480 -> 2352 | J6: =('Daily Meter'!U10-'Daily Meter'!U9)*480 -> 5616 | K6: =('Daily Meter'!C10-'Daily Meter'!C9)*284.34 -> 5174.988 | L6: =('Daily Meter'!E10-'Daily Meter'!E9)*219.969 -> 45313.614 | M6: =('Daily Meter'!W10-'Daily Meter'!W9)*3.7 -> 499.13 | N6: ='Daily Meter'!X10*434/100 -> 307.0116
A7: 25hours Dubai One Central | B7: =B6+1 -> 6 | C7: 2 | D7: 2023 | E7: =('Daily Meter'!K11-'Daily Meter'!K10)*480 -> 4080 | F7: =('Daily Meter'!M11-'Daily Meter'!M10)*480 -> 2640 | G7: =('Daily Meter'!O11-'Daily Meter'!O10)*480 -> 2976 | H7: =('Daily Meter'!Q11-'Daily Meter'!Q10)*480 -> 1728 | I7: =('Daily Meter'!S11-'Daily Meter'!S10)*480 -> 2880 | J7: =('Daily Meter'!U11-'Daily Meter'!U10)*480 -> 6912 | K7: =('Daily Meter'!C11-'Daily Meter'!C10)*284.34 -> 6994.764 | L7: =('Daily Meter'!E11-'Daily Meter'!E10)*219.969 -> 65770.731 | M7: =('Daily Meter'!W11-'Daily Meter'!W10)*3.7 -> 600.51 | N7: ='Daily Meter'!X11*434/100 -> 383.005
A8: 25hours Dubai One Central | B8: =B7+1 -> 7 | C8: 2 | D8: 2023 | E8: =('Daily Meter'!K12-'Daily Meter'!K11)*480 -> 2304 | F8: =('Daily Meter'!M12-'Daily Meter'!M11)*480 -> 1344 | G8: =('Daily Meter'!O12-'Daily Meter'!O11)*480 -> 1680 | H8: =('Daily Meter'!Q12-'Daily Meter'!Q11)*480 -> 960 | I8: =('Daily Meter'!S12-'Daily Meter'!S11)*480 -> 1680 | J8: =('Daily Meter'!U12-'Daily Meter'!U11)*480 -> 4128 | K8: =('Daily Meter'!C12-'Daily Meter'!C11)*284.34 -> 4321.968 | L8: =('Daily Meter'!E12-'Daily Meter'!E11)*219.969 -> 56312.064 | M8: =('Daily Meter'!W12-'Daily Meter'!W11)*3.7 -> 372.59 | N8: ='Daily Meter'!X12*434/100 -> 418.9836
A9: 25hours Dubai One Central | B9: =B8+1 -> 8 | C9: 2 | D9: 2023 | E9: =('Daily Meter'!K13-'Daily Meter'!K12)*480 -> 3216 | F9: =('Daily Meter'!M13-'Daily Meter'!M12)*480 -> 1920 | G9: =('Daily Meter'!O13-'Daily Meter'!O12)*480 -> 2304 | H9: =('Daily Meter'!Q13-'Daily Meter'!Q12)*480 -> 1296 | I9: =('Daily Meter'!S13-'Daily Meter'!S12)*480 -> 2304 | J9: =('Daily Meter'!U13-'Daily Meter'!U12)*480 -> 5712 | K9: =('Daily Meter'!C13-'Daily Meter'!C12)*284.34 -> 6539.82 | L9: =('Daily Meter'!E13-'Daily Meter'!E12)*219.969 -> 50152.932 | M9: =('Daily Meter'!W13-'Daily Meter'!W12)*3.7 -> 507.64 | N9: ='Daily Meter'!X13*434/100 -> 424.018
A10: 25hours Dubai One Central | B10: =B9+1 -> 9 | C10: 2 | D10: 2023 | E10: =('Daily Meter'!K14-'Daily Meter'!K13)*480 -> 3072 | F10: =('Daily Meter'!M14-'Daily Meter'!M13)*480 -> 1872 | G10: =('Daily Meter'!O14-'Daily Meter'!O13)*480 -> 2304 | H10: =('Daily Meter'!Q14-'Daily Meter'!Q13)*480 -> 1248 | I10: =('Daily Meter'!S14-'Daily Meter'!S13)*480 -> 2208 | J10: =('Daily Meter'!U14-'Daily Meter'!U13)*480 -> 5520 | K10: =('Daily Meter'!C14-'Daily Meter'!C13)*284.34 -> 5914.272 | L10: =('Daily Meter'!E14-'Daily Meter'!E13)*219.969 -> 78968.871 | M10: =('Daily Meter'!W14-'Daily Meter'!W13)*3.7 -> 501.72 | N10: ='Daily Meter'!X14*434/100 -> 366.9904
A11: 25hours Dubai One Central | B11: =B10+1 -> 10 | C11: 2 | D11: 2023 | E11: =('Daily Meter'!K15-'Daily Meter'!K14)*480 -> 3504 | F11: =('Daily Meter'!M15-'Daily Meter'!M14)*480 -> 1968 | G11: =('Daily Meter'!O15-'Daily Meter'!O14)*480 -> 2784 | H11: =('Daily Meter'!Q15-'Daily Meter'!Q14)*480 -> 1344 | I11: =('Daily Meter'!S15-'Daily Meter'!S14)*480 -> 2400 | J11: =('Daily Meter'!U15-'Daily Meter'!U14)*480 -> 5760 | K11: =('Daily Meter'!C15-'Daily Meter'!C14)*284.34 -> 5459.328 | L11: =('Daily Meter'!E15-'Daily Meter'!E14)*219.969 -> 78748.902 | M11: =('Daily Meter'!W15-'Daily Meter'!W14)*3.7 -> 535.76 | N11: ='Daily Meter'!X15*434/100 -> 352.0174
A12: 25hours Dubai One Central | B12: =B11+1 -> 11 | C12: 2 | D12: 2023 | E12: =('Daily Meter'!K16-'Daily Meter'!K15)*480 -> 3552 | F12: =('Daily Meter'!M16-'Daily Meter'!M15)*480 -> 2064 | G12: =('Daily Meter'!O16-'Daily Meter'!O15)*480 -> 2640 | H12: =('Daily Meter'!Q16-'Daily Meter'!Q15)*480 -> 1536 | I12: =('Daily Meter'!S16-'Daily Meter'!S15)*480 -> 2496 | J12: =('Daily Meter'!U16-'Daily Meter'!U15)*480 -> 5808 | K12: =('Daily Meter'!C16-'Daily Meter'!C15)*284.34 -> 5459.328 | L12: =('Daily Meter'!E16-'Daily Meter'!E15)*219.969 -> 46193.49 | M12: =('Daily Meter'!W16-'Daily Meter'!W15)*3.7 -> 533.17 | N12: ='Daily Meter'!X16*434/100 -> 300.979
A13: 25hours Dubai One Central | B13: =B12+1 -> 12 | C13: 2 | D13: 2023 | E13: =('Daily Meter'!K17-'Daily Meter'!K16)*480 -> 3072 | F13: =('Daily Meter'!M17-'Daily Meter'!M16)*480 -> 1776 | G13: =('Daily Meter'!O17-'Daily Meter'!O16)*480 -> 2256 | H13: =('Daily Meter'!Q17-'Daily Meter'!Q16)*480 -> 1296 | I13: =('Daily Meter'!S17-'Daily Meter'!S16)*480 -> 2256 | J13: =('Daily Meter'!U17-'Daily Meter'!U16)*480 -> 5424 | K13: =('Daily Meter'!C17-'Daily Meter'!C16)*284.34 -> 5032.818 | L13: =('Daily Meter'!E17-'Daily Meter'!E16)*219.969 -> 69510.204 | M13: =('Daily Meter'!W17-'Daily Meter'!W16)*3.7 -> 445.11 | N13: ='Daily Meter'!X17*434/100 -> 312.0026
A14: 25hours Dubai One Central | B14: =B13+1 -> 13 | C14: 2 | D14: 2023 | E14: =('Daily Meter'!K18-'Daily Meter'!K17)*480 -> 3936 | F14: =('Daily Meter'!M18-'Daily Meter'!M17)*480 -> 2208 | G14: =('Daily Meter'!O18-'Daily Meter'!O17)*480 -> 2736 | H14: =('Daily Meter'!Q18-'Daily Meter'!Q17)*480 -> 1632 | I14: =('Daily Meter'!S18-'Daily Meter'!S17)*480 -> 2736 | J14: =('Daily Meter'!U18-'Daily Meter'!U17)*480 -> 6864 | K14: =('Daily Meter'!C18-'Daily Meter'!C17)*284.34 -> 6767.292 | L14: =('Daily Meter'!E18-'Daily Meter'!E17)*219.969 -> 51032.808 | M14: =('Daily Meter'!W18-'Daily Meter'!W17)*3.7 -> 483.59 | N14: ='Daily Meter'!X18*434/100 -> 316.9936
... A29: 25hours Dubai One Central | B29: =B28+1 -> 28 | C29: 2 | D29: 2023 | E29: =('Daily Meter'!K33-'Daily Meter'!K32)*480 -> 2784 | F29: =('Daily Meter'!M33-'Daily Meter'!M32)*480 -> 1680 | G29: =('Daily Meter'!O33-'Daily Meter'!O32)*480 -> 1920 | H29: =('Daily Meter'!Q33-'Daily Meter'!Q32)*480 -> 1152 | I29: =('Daily Meter'!S33-'Daily Meter'!S32)*480 -> 1872 | J29: =('Daily Meter'!U33-'Daily Meter'!U32)*480 -> 5376 | K29: =('Daily Meter'!C33-'Daily Meter'!C32)*284.34 -> 8985.144 | L29: =('Daily Meter'!E33-'Daily Meter'!E32)*219.969 -> 40034.358 | M29: =('Daily Meter'!W33-'Daily Meter'!W32)*3.7 -> 586.45 | N29: ='Daily Meter'!X33*434/100 -> 408.0034

Sheet Daily Meter
A1: FEBRUARY 2023 UTILITY READING | Z1: 1st
B2: Chilled Water | D2: Water | J2: Electric | V2: Gas | X2: OCC.
A3: Date | B3: BTU Meter | D3: Meter 1 | F3: Meter 2 | H3: Meter 3 | J3: Meter 1 | L3: Meter 2 | N3: Meter 3 | P3: Meter 4 | R3: Meter 6 | T3: Meter 7 | V3: Gas
B4: P103FF043BC | D4: 18E0300032 | F4: 18E0300060 | H4: 18E0300057 | J4: 6065253 | L4: 6065255 | N4: 6065259 | P4: 6065262 | R4: 6065269 | T4: 6065283 | V4: 77092321/2019 | X4: %
B5: 9am | C5: 5pm | D5: 9am | E5: 5pm | F5: 5AM | G5: 5pm | H5: 5AM | I5: 5pm | J5: 9am | K5: 5pm | L5: 9am | M5: 5pm | N5: 9am | O5: 5pm | P5: 9am | Q5: 5pm | R5: 9am | S5: 5pm | T5: 9am | U5: 5pm | V5: 9am | W5: 5pm | X5: DAILY
A6: 1 | B6: 36593.2 | C6: 36600.7 | D6: 122980 | E6: 123104 | J6: 4237.1 | K6: 4242 | L6: 2545.1 | M6: 2548.1 | N6: 2729 | O6: 2732.3 | P6: 1367.7 | Q6: 1369.6 | R6: 4004.8 | S6: 4008.2 | T6: 10591.3 | U6: 10598.5 | V6: 51866.5 | W6: 51936.4 | X6: 97.24
A7: 2 | B7: 36611.1 | C7: 36618.8 | D7: 123350 | E7: 123412 | J7: 4244.1 | K7: 4247.1 | L7: 2549.2 | M7: 2551.2 | N7: 2734 | O7: 2736 | P7: 1370.5 | Q7: 1371.6 | R7: 4009.8 | S7: 4012 | T7: 10602.2 | U7: 10607.4 | V7: 52012.3 | W7: 52076.7 | X7: 79.26
A8: 3 | B8: 36630.1 | C8: 36642.4 | D8: 123701 | E8: 123711 | J8: 4250.8 | K8: 4255.2 | L8: 2553.1 | M8: 2555.7 | N8: 2738.7 | O8: 2741.4 | P8: 1373.3 | Q8: 1375 | R8: 4014.5 | S8: 4017.3 | T8: 10613.1 | U8: 10620 | V8: 52150.4 | W8: 52214.7 | X8: 66.13
A9: 4 | B9: 36651 | C9: 36658.9 | D9: 123886 | E9: 124037 | J9: 4257.8 | K9: 4260.7 | L9: 2557.1 | M9: 2558.8 | N9: 2743.5 | O9: 2745.4 | P9: 1376.4 | Q9: 1377.5 | R9: 4019.2 | S9: 4021.1 | T9: 10624.6 | U9: 10629.5 | V9: 52285.9 | W9: 52338.6 | X9: 67.75
A10: 5 | B10: 36669.3 | C10: 36677.1 | D10: 124232 | E10: 124243 | J10: 4264.5 | K10: 4267.7 | L10: 2560.9 | M10: 2562.5 | N10: 2748.4 | O10: 2750.6 | P10: 1379.3 | Q10: 1380.6 | R10: 4023.8 | S10: 4026 | T10: 10635.8 | U10: 10641.2 | V10: 52416.9 | W10: 52473.5 | X10: 70.74
A11: 6 | B11: 36688.3 | C11: 36701.7 | D11: 124397 | E11: 124542 | J11: 4271.5 | K11: 4276.2 | L11: 2565 | M11: 2568 | N11: 2753.7 | O11: 2756.8 | P11: 1382.3 | Q11: 1384.2 | R11: 4028.8 | S11: 4032 | T11: 10647.9 | U11: 10655.6 | V11: 52547.4 | W11: 52635.8 | X11: 88.25
A12: 7 | B12: 36705.1 | C12: 36716.9 | D12: 124738 | E12: 124798 | J12: 4277.2 | K12: 4281 | L12: 2568.5 | M12: 2570.8 | N12: 2757.8 | O12: 2760.3 | P12: 1384.7 | Q12: 1386.2 | R12: 4032.8 | S12: 4035.5 | T12: 10657.6 | U12: 10664.2 | V12: 52660.2 | W12: 52736.5 | X12: 96.54
A13: 8 | B13: 36730.3 | C13: 36739.9 | D13: 124957 | E13: 125026 | J13: 4285.1 | K13: 4287.7 | L13: 2573 | M13: 2574.8 | N13: 2763.4 | O13: 2765.1 | P13: 1387.9 | Q13: 1388.9 | R13: 4038.4 | S13: 4040.3 | T13: 10671.5 | U13: 10676.1 | V13: 52814.8 | W13: 52873.7 | X13: 97.7
A14: 9 | B14: 36753 | C14: 36760.7 | D14: 125304 | E14: 125385 | J14: 4291.7 | K14: 4294.1 | L14: 2577 | M14: 2578.7 | N14: 2768.3 | O14: 2769.9 | P14: 1390.6 | Q14: 1391.5 | R14: 4043.2 | S14: 4044.9 | T14: 10683.2 | U14: 10687.6 | V14: 52951.8 | W14: 53009.3 | X14: 84.56
A15: 10 | B15: 36772.2 | C15: 36779.9 | D15: 125680 | E15: 125743 | J15: 4298.6 | K15: 4301.4 | L15: 2581 | M15: 2582.8 | N15: 2773.6 | O15: 2775.7 | P15: 1393.3 | Q15: 1394.3 | R15: 4048 | S15: 4049.9 | T15: 10694.9 | U15: 10699.6 | V15: 53090.8 | W15: 53154.1 | X15: 81.11
A16: 11 | B16: 36790.5 | C16: 36799.1 | D16: 125890 | E16: 125953 | J16: 4305.6 | K16: 4308.8 | L16: 2585.1 | M16: 2587.1 | N16: 2779.2 | O16: 2781.2 | P16: 1396.3 | Q16: 1397.5 | R16: 4052.8 | S16: 4055.1 | T16: 10706.6 | U16: 10711.7 | V16: 53234.7 | W16: 53298.2 | X16: 69.35
A17: 12 | B17: 36808.7 | C17: 36816.8 | D17: 126261 | E17: 126269 | J17: 4312.3 | K17: 4315.2 | L17: 2589 | M17: 2590.8 | N17: 2784.1 | O17: 2785.9 | P17: 1399.2 | Q17: 1400.2 | R17: 4057.7 | S17: 4059.8 | T17: 10717.9 | U17: 10723 | V17: 53365.7 | W17: 53418.5 | X17: 71.89
... A33: 28 | B33: 37192.4 | C33: 37209.3 | D33: 130538 | E33: 130541 | J33: 4423.6 | K33: 4427.6 | L33: 2652.4 | M33: 2654.9 | N33: 2861.7 | O33: 2864.2 | P33: 1443.9 | Q33: 1445.5 | R33: 4132.3 | S33: 4135 | T33: 10924.7 | U33: 10932.4 | V33: 55467.3 | W33: 55556.6 | X33: 94.01
Z37: engr123.

Sheet 1
A1: ENGINEERING DEPARTMENT | J1: daily reading
A3: UTILITY CONSUMPTION SHEET
B4: FEBRUARY 2023 | C4: 1
A5: SR.NO | B5: ITEM MEASURED | D5: Previous Reading | E5: 1st Reading (5am) | F5: 2nd Reading (5pm) | G5: 12hrs CONSUMPTION | H5: 24hrs CONSUMPTION | I5: Cost
D6: JAN. 31
A7: 1 | B7: DISTRICT COOLING PLANT
B8: Chilled Water | C8: MWH | D8: 36588.1 | E8: ='Daily Meter'!B6 -> 36593.2 | F8: ='Daily Meter'!C6 -> 36600.7 | G8: =F8-E8 -> 7.5 | H8: =F8-D8 -> 12.6
C9: TR | G9: =G8*284.34 -> 2132.55 | H9: =H8*284.34 -> 3582.684 | I9: =H9*0.63 -> 2257.0909
A10: III | B10: WATER METERS
B11: Main DEWA Meter | C11: mᶟ | D11: 122881 | E11: ='Daily Meter'!D6 -> 122980 | F11: ='Daily Meter'!E6 -> 123104 | G11: =F11-E11 -> 124 | H11: =F11-D11 -> 223
B12: Imperial Gallon = m³ x 219.969 | C12: IG | G12: =G11*219.969 -> 27276.156 | H12: =H11*219.969 -> 49053.087 | I12: =H12*0.06 -> 2943.1852
A13: IV | B13: ELECTRICAL METERS
A14: 1 | B14: Meter 1 - 06065253 | C14: kW x 480 | D14: 4235.1 | E14: ='Daily Meter'!J6 -> 4237.1 | F14: ='Daily Meter'!K6 -> 4242 | G14: =(F14-E14)*480 -> 2352 | H14: =(F14-D14)*480 -> 3312
A15: 2 | B15: Meter 2 - 06065255 | C15: kW x 480 | D15: 2544 | E15: ='Daily Meter'!L6 -> 2545.1 | F15: ='Daily Meter'!M6 -> 2548.1 | G15: =(F15-E15)*480 -> 1440 | H15: =(F15-D15)*480 -> 1968
A16: 3 | B16: Meter 3 - 06065259 | C16: kW x 480 | D16: 2727.4 | E16: ='Daily Meter'!N6 -> 2729 | F16: ='Daily Meter'!O6 -> 2732.3 | G16: =(F16-E16)*480 -> 1584 | H16: =(F16-D16)*480 -> 2352
A17: 4 | B17: Meter 4 - 06065262 | C17: kW x 480 | D17: 1366.8 | E17: ='Daily Meter'!P6 -> 1367.7 | F17: ='Daily Meter'!Q6 -> 1369.6 | G17: =(F17-E17)*480 -> 912 | H17: =(F17-D17)*480 -> 1344
A18: 5 | B18: Meter 6 - 06065269 | C18: kW x 480 | D18: 4003.3 | E18: ='Daily Meter'!R6 -> 4004.8 | F18: ='Daily Meter'!S$6 -> 4008.2 | G18: =(F18-E18)*480 -> 1632 | H18: =(F18-D18)*480 -> 2352
A19: 6 | B19: Meter 7 - 06065283 | C19: kW x 480 | D19: 10588.2 | E19: ='Daily Meter'!T6 -> 10591.3 | F19: ='Daily Meter'!U6 -> 10598.5 | G19: =(F19-E19)*480 -> 3456 | H19: =(F19-D19)*480 -> 4944
B20: TOTAL ELECTRICAL CONS.(kWh) | G20: =SUM(G14:G19) -> 11376 | H20: =SUM(H14:H19) -> 16272 | I20: =H20*0.43 -> 6996.96
A22: V | B22: GAS CONSUMPTION
A23: 1 | B23: MAIN LPG METER | C23: mᶟ | D23: 51820.1 | E23: ='Daily Meter'!V6 -> 51866.5 | F23: ='Daily Meter'!W6 -> 51936.4 | G23: =F23-E23 -> 69.9 | H23: =F23-D23 -> 116.3
C24: L | H24: =H23*3.7 -> 430.31 | I24: =H24*2.18 -> 938.0758
D27: Summary of Daily Hotel consumption
D28: Item measured | E28: Units | F28: Consumption | G28: AED
D29: Chilled water | E29: TR | F29: =H9 -> 3582.684 | G29: =F29*0.63 -> 2257.0909
D30: DEWA Water | E30: imp. Gallon | F30: =H12 -> 49053.087 | G30: =F30*0.06 -> 2943.1852
D31: Electricity | E31: kwh | F31: =H20 -> 16272 | G31: =F31*0.43 -> 6996.96
D32: Gas | E32: m3 | F32: =H23 -> 116.3 | G32: =I24 -> 938.0758
F33: Total cost | G33: =SUM(G29:G32) -> 13135.312

Sheet 2
A1: ENGINEERING DEPARTMENT | J1: daily reading
A3: UTILITY CONSUMPTION SHEET
B4: ='1'!B4 -> FEBRUARY 2023 | C4: 2
A5: SR.NO | B5: ITEM MEASURED | D5: Previous Reading | E5: 1st Reading (5am) | F5: 2nd Reading (5pm) | G5: 12hrs CONSUMPTION | H5: 24hrs CONSUMPTION | I5: Cost
A7: 1 | B7: DISTRICT COOLING PLANT
B8: Chilled Water | C8: MWH | D8: ='1'!F8 -> 36600.7 | E8: ='Daily Meter'!B7 -> 36611.1 | F8: ='Daily Meter'!C7 -> 36618.8 | G8: =F8-E8 -> 7.7 | H8: =F8-D8 -> 18.1
C9: TR | G9: =G8*284.34 -> 2189.418 | H9: =H8*284.34 -> 5146.554 | I9: =H9*0.63 -> 3242.329
A10: III | B10: WATER METERS
B11: Main DEWA Meter | C11: mᶟ | D11: ='1'!F11 -> 123104 | E11: ='Daily Meter'!D7 -> 123350 | F11: ='Daily Meter'!E7 -> 123412 | G11: =F11-E11 -> 62 | H11: =F11-D11 -> 308
B12: Imperial Gallon = m³ x 219.969 | C12: IG | G12: =G11*219.969 -> 13638.078 | H12: =H11*219.969 -> 67750.452 | I12: =H12*0.06 -> 4065.0271
A13: IV | B13: ELECTRICAL METERS
A14: 1 | B14: Meter 1 - 06065253 | C14: kW x 480 | D14: ='1'!F14 -> 4242 | E14: ='Daily Meter'!J7 -> 4244.1 | F14: ='Daily Meter'!K7 -> 4247.1 | G14: =(F14-E14)*480 -> 1440 | H14: =(F14-D14)*480 -> 2448
A15: 2 | B15: Meter 2 - 06065255 | C15: kW x 480 | D15: ='1'!F15 -> 2548.1 | E15: ='Daily Meter'!L7 -> 2549.2 | F15: ='Daily Meter'!M7 -> 2551.2 | G15: =(F15-E15)*480 -> 960 | H15: =(F15-D15)*480 -> 1488
A16: 3 | B16: Meter 3 - 06065259 | C16: kW x 480 | D16: ='1'!F16 -> 2732.3 | E16: ='Daily Meter'!N7 -> 2734 | F16: ='Daily Meter'!O7 -> 2736 | G16: =(F16-E16)*480 -> 960 | H16: =(F16-D16)*480 -> 1776
A17: 4 | B17: Meter 4 - 06065262 | C17: kW x 480 | D17: ='1'!F17 -> 1369.6 | E17: ='Daily Meter'!P7 -> 1370.5 | F17: ='Daily Meter'!Q7 -> 1371.6 | G17: =(F17-E17)*480 -> 528 | H17: =(F17-D17)*480 -> 960
A18: 5 | B18: Meter 6 - 06065269 | C18: kW x 480 | D18: ='1'!F18 -> 4008.2 | E18: ='Daily Meter'!R7 -> 4009.8 | F18: ='Daily Meter'!S7 -> 4012 | G18: =(F18-E18)*480 -> 1056 | H18: =(F18-D18)*480 -> 1824
A19: 6 | B19: Meter 7 - 06065283 | C19: kW x 480 | D19: ='1'!F19 -> 10598.5 | E19: ='Daily Meter'!T7 -> 10602.2 | F19: ='Daily Meter'!U7 -> 10607.4 | G19: =(F19-E19)*480 -> 2496 | H19: =(F19-D19)*480 -> 4272
B20: TOTAL ELECTRICAL CONS.(kWh) | G20: =SUM(G14:G19) -> 7440 | H20: =SUM(H14:H19) -> 12768 | I20: =H20*0.43 -> 5490.24
A22: V | B22: GAS CONSUMPTION
A23: 1 | B23: MAIN LPG METER | C23: mᶟ | D23: ='1'!F23 -> 51936.4 | E23: ='Daily Meter'!V7 -> 52012.3 | F23: ='Daily Meter'!W7 -> 52076.7 | G23: =F23-E23 -> 64.4 | H23: =F23-D23 -> 140.3
C24: L | H24: =H23*3.7 -> 519.11 | I24: =H24*2.18 -> 1131.6598
D27: Summary of Daily Hotel consumption
D28: Item measured | E28: Units | F28: Consumption | G28: AED
D29: Chilled water | E29: TR | F29: =H9 -> 5146.554 | G29: =F29*0.63 -> 3242.329
D30: DEWA Water | E30: imp. Gallon | F30: =H12 -> 67750.452 | G30: =F30*0.06 -> 4065.0271
D31: Electricity | E31: kwh | F31: =H20 -> 12768 | G31: =F31*0.43 -> 5490.24
D32: Gas | E32: m3 | F32: =H23 -> 140.3 | G32: =I24 -> 1131.6598
F33: Total cost | G33: =SUM(G29:G32) -> 13929.256

Sheet 3
A1: ENGINEERING DEPARTMENT | J1: daily reading
A3: UTILITY CONSUMPTION SHEET
B4: ='1'!B4 -> FEBRUARY 2023 | C4: 3
A5: SR.NO | B5: ITEM MEASURED | D5: Previous Reading | E5: 1st Reading (5am) | F5: 2nd Reading (5pm) | G5: 12hrs CONSUMPTION | H5: 24hrs CONSUMPTION | I5: Cost
A7: 1 | B7: DISTRICT COOLING PLANT
B8: Chilled Water | C8: MWH | D8: ='2'!F8 -> 36618.8 | E8: ='Daily Meter'!B8 -> 36630.1 | F8: ='Daily Meter'!C8 -> 36642.4 | G8: =F8-E8 -> 12.3 | H8: =F8-D8 -> 23.6
C9: TR | G9: =G8*284.34 -> 3497.382 | H9: =H8*284.34 -> 6710.424 | I9: =H9*0.63 -> 4227.5671
A10: III | B10: WATER METERS
B11: Main DEWA Meter | C11: mᶟ | D11: ='2'!F11 -> 123412 | E11: ='Daily Meter'!D8 -> 123701 | F11: ='Daily Meter'!E8 -> 123711 | G11: =F11-E11 -> 10 | H11: =F11-D11 -> 299
B12: Imperial Gallon = m³ x 219.969 | C12: IG | G12: =G11*219.969 -> 2199.69 | H12: =H11*219.969 -> 65770.731 | I12: =H12*0.06 -> 3946.2439
A13: IV | B13: ELECTRICAL METERS
A14: 1 | B14: Meter 1 - 06065253 | C14: kW x 480 | D14: ='2'!F14 -> 4247.1 | E14: ='Daily Meter'!J8 -> 4250.8 | F14: ='Daily Meter'!K8 -> 4255.2 | G14: =(F14-E14)*480 -> 2112 | H14: =(F14-D14)*480 -> 3888
A15: 2 | B15: Meter 2 - 06065255 | C15: kW x 480 | D15: ='2'!F15 -> 2551.2 | E15: ='Daily Meter'!L8 -> 2553.1 | F15: ='Daily Meter'!M8 -> 2555.7 | G15: =(F15-E15)*480 -> 1248 | H15: =(F15-D15)*480 -> 2160
A16: 3 | B16: Meter 3 - 06065259 | C16: kW x 480 | D16: ='2'!F16 -> 2736 | E16: ='Daily Meter'!N8 -> 2738.7 | F16: ='Daily Meter'!O8 -> 2741.4 | G16: =(F16-E16)*480 -> 1296 | H16: =(F16-D16)*480 -> 2592
A17: 4 | B17: Meter 4 - 06065262 | C17: kW x 480 | D17: ='2'!F17 -> 1371.6 | E17: ='Daily Meter'!P8 -> 1373.3 | F17: ='Daily Meter'!Q8 -> 1375 | G17: =(F17-E17)*480 -> 816 | H17: =(F17-D17)*480 -> 1632
A18: 5 | B18: Meter 6 - 06065269 | C18: kW x 480 | D18: ='2'!F18 -> 4012 | E18: ='Daily Meter'!R8 -> 4014.5 | F18: ='Daily Meter'!S8 -> 4017.3 | G18: =(F18-E18)*480 -> 1344 | H18: =(F18-D18)*480 -> 2544
A19: 6 | B19: Meter 7 - 06065283 | C19: kW x 480 | D19: ='2'!F19 -> 10607.4 | E19: ='Daily Meter'!T8 -> 10613.1 | F19: ='Daily Meter'!U8 -> 10620 | G19: =(F19-E19)*480 -> 3312 | H19: =(F19-D19)*480 -> 6048
B20: TOTAL ELECTRICAL CONS.(kWh) | G20: =SUM(G14:G19) -> 10128 | H20: =SUM(H14:H19) -> 18864 | I20: =H20*0.43 -> 8111.52
A22: V | B22: GAS CONSUMPTION
A23: 1 | B23: MAIN LPG METER | C23: mᶟ | D23: ='2'!F23 -> 52076.7 | E23: ='Daily Meter'!V8 -> 52150.4 | F23: ='Daily Meter'!W8 -> 52214.7 | G23: =F23-E23 -> 64.3 | H23: =F23-D23 -> 138
C24: L | H24: =H23*3.7 -> 510.6 | I24: =H24*2.18 -> 1113.108
D27: Summary of Daily Hotel consumption
D28: Item measured | E28: Units | F28: Consumption | G28: AED
D29: Chilled water | E29: TR | F29: =H9 -> 6710.424 | G29: =F29*0.63 -> 4227.5671
D30: DEWA Water | E30: imp. Gallon | F30: =H12 -> 65770.731 | G30: =F30*0.06 -> 3946.2439
D31: Electricity | E31: kwh | F31: =H20 -> 18864 | G31: =F31*0.43 -> 8111.52
D32: Gas | E32: m3 | F32: =H23 -> 138 | G32: =I24 -> 1113.108
F33: Total cost | G33: =SUM(G29:G32) -> 17398.439

Sheet 4
A1: ENGINEERING DEPARTMENT | J1: daily reading
A3: UTILITY CONSUMPTION SHEET
B4: ='1'!B4 -> FEBRUARY 2023 | C4: 4
A5: SR.NO | B5: ITEM MEASURED | D5: Previous Reading | E5: 1st Reading (5am) | F5: 2nd Reading (5pm) | G5: 12hrs CONSUMPTION | H5: 24hrs CONSUMPTION | I5: Cost
A7: 1 | B7: DISTRICT COOLING PLANT
B8: Chilled Water | C8: MWH | D8: ='3'!F8 -> 36642.4 | E8: ='Daily Meter'!B9 -> 36651 | F8: ='Daily Meter'!C9 -> 36658.9 | G8: =F8-E8 -> 7.9 | H8: =F8-D8 -> 16.5
C9: TR | G9: =G8*284.34 -> 2246.286 | H9: =H8*284.34 -> 4691.61 | I9: =H9*0.63 -> 2955.7143
A10: III | B10: WATER METERS
B11: Main DEWA Meter | C11: mᶟ | D11: ='3'!F11 -> 123711 | E11: ='Daily Meter'!D9 -> 123886 | F11: ='Daily Meter'!E9 -> 124037 | G11: =F11-E11 -> 151 | H11: =F11-D11 -> 326
B12: Imperial Gallon = m³ x 219.969 | C12: IG | G12: =G11*219.969 -> 33215.319 | H12: =H11*219.969 -> 71709.894 | I12: =H12*0.06 -> 4302.5936
A13: IV | B13: ELECTRICAL METERS
A14: 1 | B14: Meter 1 - 06065253 | C14: kW x 480 | D14: ='3'!F14 -> 4255.2 | E14: ='Daily Meter'!J9 -> 4257.8 | F14: ='Daily Meter'!K9 -> 4260.7 | G14: =(F14-E14)*480 -> 1392 | H14: =(F14-D14)*480 -> 2640
A15: 2 | B15: Meter 2 - 06065255 | C15: kW x 480 | D15: ='3'!F15 -> 2555.7 | E15: ='Daily Meter'!L9 -> 2557.1 | F15: ='Daily Meter'!M9 -> 2558.8 | G15: =(F15-E15)*480 -> 816 | H15: =(F15-D15)*480 -> 1488
A16: 3 | B16: Meter 3 - 06065259 | C16: kW x 480 | D16: ='3'!F16 -> 2741.4 | E16: ='Daily Meter'!N9 -> 2743.5 | F16: ='Daily Meter'!O9 -> 2745.4 | G16: =(F16-E16)*480 -> 912 | H16: =(F16-D16)*480 -> 1920
A17: 4 | B17: Meter 4 - 06065262 | C17: kW x 480 | D17: ='3'!F17 -> 1375 | E17: ='Daily Meter'!P9 -> 1376.4 | F17: ='Daily Meter'!Q9 -> 1377.5 | G17: =(F17-E17)*480 -> 528 | H17: =(F17-D17)*480 -> 1200
A18: 5 | B18: Meter 6 - 06065269 | C18: kW x 480 | D18: ='3'!F18 -> 4017.3 | E18: ='Daily Meter'!R9 -> 4019.2 | F18: ='Daily Meter'!S9 -> 4021.1 | G18: =(F18-E18)*480 -> 912 | H18: =(F18-D18)*480 -> 1824
A19: 6 | B19: Meter 7 - 06065283 | C19: kW x 480 | D19: ='3'!F19 -> 10620 | E19: ='Daily Meter'!T9 -> 10624.6 | F19: ='Daily Meter'!U9 -> 10629.5 | G19: =(F19-E19)*480 -> 2352 | H19: =(F19-D19)*480 -> 4560
B20: TOTAL ELECTRICAL CONS.(kWh) | G20: =SUM(G14:G19) -> 6912 | H20: =SUM(H14:H19) -> 13632 | I20: =H20*0.43 -> 5861.76
A22: V | B22: GAS CONSUMPTION
A23: 1 | B23: MAIN LPG METER | C23: mᶟ | D23: ='3'!F23 -> 52214.7 | E23: ='Daily Meter'!V9 -> 52285.9 | F23: ='Daily Meter'!W9 -> 52338.6 | G23: =F23-E23 -> 52.7 | H23: =F23-D23 -> 123.9
C24: L | H24: =H23*3.7 -> 458.43 | I24: =H24*2.18 -> 999.3774
D27: Summary of Daily Hotel consumption
D28: Item measured | E28: Units | F28: Consumption | G28: AED
D29: Chilled water | E29: TR | F29: =H9 -> 4691.61 | G29: =F29*0.63 -> 2955.7143
D30: DEWA Water | E30: imp. Gallon | F30: =H12 -> 71709.894 | G30: =F30*0.06 -> 4302.5936
D31: Electricity | E31: kwh | F31: =H20 -> 13632 | G31: =F31*0.43 -> 5861.76
D32: Gas | E32: m3 | F32: =H23 -> 123.9 | G32: =I24 -> 999.3774
F33: Total cost | G33: =SUM(G29:G32) -> 14119.445

Sheet 5
A1: ENGINEERING DEPARTMENT | J1: daily reading
A3: UTILITY CONSUMPTION SHEET
B4: ='1'!B4 -> FEBRUARY 2023 | C4: 5
A5: SR.NO | B5: ITEM MEASURED | D5: Previous Reading | E5: 1st Reading (5am) | F5: 2nd Reading (5pm) | G5: 12hrs CONSUMPTION | H5: 24hrs CONSUMPTION | I5: Cost
A7: 1 | B7: DISTRICT COOLING PLANT
B8: Chilled Water | C8: MWH | D8: ='4'!F8 -> 36658.9 | E8: ='Daily Meter'!B10 -> 36669.3 | F8: ='Daily Meter'!C10 -> 36677.1 | G8: =F8-E8 -> 7.8 | H8: =F8-D8 -> 18.2
C9: TR | G9: =G8*284.34 -> 2217.852 | H9: =H8*284.34 -> 5174.988 | I9: =H9*0.63 -> 3260.2424
A10: III | B10: WATER METERS
B11: Main DEWA Meter | C11: mᶟ | D11: ='4'!F11 -> 124037 | E11: ='Daily Meter'!D10 -> 124232 | F11: ='Daily Meter'!E10 -> 124243 | G11: =F11-E11 -> 11 | H11: =F11-D11 -> 206
B12: Imperial Gallon = m³ x 219.969 | C12: IG | G12: =G11*219.969 -> 2419.659 | H12: =H11*219.969 -> 45313.614 | I12: =H12*0.06 -> 2718.8168
A13: IV | B13: ELECTRICAL METERS
A14: 1 | B14: Meter 1 - 06065253 | C14: kW x 480 | D14: ='4'!F14 -> 4260.7 | E14: ='Daily Meter'!J10 -> 4264.5 | F14: ='Daily Meter'!K10 -> 4267.7 | G14: =(F14-E14)*480 -> 1536 | H14: =(F14-D14)*480 -> 3360
A15: 2 | B15: Meter 2 - 06065255 | C15: kW x 480 | D15: ='4'!F15 -> 2558.8 | E15: ='Daily Meter'!L10 -> 2560.9 | F15: ='Daily Meter'!M10 -> 2562.5 | G15: =(F15-E15)*480 -> 768 | H15: =(F15-D15)*480 -> 1776
A16: 3 | B16: Meter 3 - 06065259 | C16: kW x 480 | D16: ='4'!F16 -> 2745.4 | E16: ='Daily Meter'!N10 -> 2748.4 | F16: ='Daily Meter'!O10 -> 2750.6 | G16: =(F16-E16)*480 -> 1056 | H16: =(F16-D16)*480 -> 2496
A17: 4 | B17: Meter 4 - 06065262 | C17: kW x 480 | D17: ='4'!F17 -> 1377.5 | E17: ='Daily Meter'!P10 -> 1379.3 | F17: ='Daily Meter'!Q10 -> 1380.6 | G17: =(F17-E17)*480 -> 624 | H17: =(F17-D17)*480 -> 1488
A18: 5 | B18: Meter 6 - 06065269 | C18: kW x 480 | D18: ='4'!F18 -> 4021.1 | E18: ='Daily Meter'!R10 -> 4023.8 | F18: ='Daily Meter'!S10 -> 4026 | G18: =(F18-E18)*480 -> 1056 | H18: =(F18-D18)*480 -> 2352
A19: 6 | B19: Meter 7 - 06065283 | C19: kW x 480 | D19: ='4'!F19 -> 10629.5 | E19: ='Daily Meter'!T10 -> 10635.8 | F19: ='Daily Meter'!U10 -> 10641.2 | G19: =(F19-E19)*480 -> 2592 | H19: =(F19-D19)*480 -> 5616
B20: TOTAL ELECTRICAL CONS.(kWh) | G20: =SUM(G14:G19) -> 7632 | H20: =SUM(H14:H19) -> 17088 | I20: =H20*0.43 -> 7347.84
A22: V | B22: GAS CONSUMPTION
A23: 1 | B23: MAIN LPG METER | C23: mᶟ | D23: ='4'!F23 -> 52338.6 | E23: ='Daily Meter'!V10 -> 52416.9 | F23: ='Daily Meter'!W10 -> 52473.5 | G23: =F23-E23 -> 56.6 | H23: =F23-D23 -> 134.9
C24: L | H24: =H23*3.7 -> 499.13 | I24: =H24*2.18 -> 1088.1034
D27: Summary of Daily Hotel consumption
D28: Item measured | E28: Units | F28: Consumption | G28: AED
D29: Chilled water | E29: TR | F29: =H9 -> 5174.988 | G29: =F29*0.63 -> 3260.2424
D30: DEWA Water | E30: imp. Gallon | F30: =H12 -> 45313.614 | G30: =F30*0.06 -> 2718.8168
D31: Electricity | E31: kwh | F31: =H20 -> 17088 | G31: =F31*0.43 -> 7347.84
D32: Gas | E32: m3 | F32: =H23 -> 134.9 | G32: =I24 -> 1088.1034
F33: Total cost | G33: =SUM(G29:G32) -> 14415.003

Sheet 6
A1: ENGINEERING DEPARTMENT | J1: daily reading
A3: UTILITY CONSUMPTION SHEET
B4: ='1'!B4 -> FEBRUARY 2023 | C4: 6
A5: SR.NO | B5: ITEM MEASURED | D5: Previous Reading | E5: 1st Reading (5am) | F5: 2nd Reading (5pm) | G5: 12hrs CONSUMPTION | H5: 24hrs CONSUMPTION | I5: Cost
A7: 1 | B7: DISTRICT COOLING PLANT
B8: Chilled Water | C8: MWH | D8: ='5'!F8 -> 36677.1 | E8: ='Daily Meter'!B11 -> 36688.3 | F8: ='Daily Meter'!C11 -> 36701.7 | G8: =F8-E8 -> 13.4 | H8: =F8-D8 -> 24.6
C9: TR | G9: =G8*284.34 -> 3810.156 | H9: =H8*284.34 -> 6994.764 | I9: =H9*0.63 -> 4406.7013
A10: III | B10: WATER METERS
B11: Main DEWA Meter | C11: mᶟ | D11: ='5'!F11 -> 124243 | E11: ='Daily Meter'!D11 -> 124397 | F11: ='Daily Meter'!E11 -> 124542 | G11: =F11-E11 -> 145 | H11: =F11-D11 -> 299
B12: Imperial Gallon = m³ x 219.969 | C12: IG | G12: =G11*219.969 -> 31895.505 | H12: =H11*219.969 -> 65770.731 | I12: =H12*0.06 -> 3946.2439
A13: IV | B13: ELECTRICAL METERS
A14: 1 | B14: Meter 1 - 06065253 | C14: kW x 480 | D14: ='5'!F14 -> 4267.7 | E14: ='Daily Meter'!J11 -> 4271.5 | F14: ='Daily Meter'!K11 -> 4276.2 | G14: =(F14-E14)*480 -> 2256 | H14: =(F14-D14)*480 -> 4080
A15: 2 | B15: Meter 2 - 06065255 | C15: kW x 480 | D15: ='5'!F15 -> 2562.5 | E15: ='Daily Meter'!L11 -> 2565 | F15: ='Daily Meter'!M11 -> 2568 | G15: =(F15-E15)*480 -> 1440 | H15: =(F15-D15)*480 -> 2640
A16: 3 | B16: Meter 3 - 06065259 | C16: kW x 480 | D16: ='5'!F16 -> 2750.6 | E16: ='Daily Meter'!N11 -> 2753.7 | F16: ='Daily Meter'!O11 -> 2756.8 | G16: =(F16-E16)*480 -> 1488 | H16: =(F16-D16)*480 -> 2976
A17: 4 | B17: Meter 4 - 06065262 | C17: kW x 480 | D17: ='5'!F17 -> 1380.6 | E17: ='Daily Meter'!P11 -> 1382.3 | F17: ='Daily Meter'!Q11 -> 1384.2 | G17: =(F17-E17)*480 -> 912 | H17: =(F17-D17)*480 -> 1728
A18: 5 | B18: Meter 6 - 06065269 | C18: kW x 480 | D18: ='5'!F18 -> 4026 | E18: ='Daily Meter'!R11 -> 4028.8 | F18: ='Daily Meter'!S11 -> 4032 | G18: =(F18-E18)*480 -> 1536 | H18: =(F18-D18)*480 -> 2880
A19: 6 | B19: Meter 7 - 06065283 | C19: kW x 480 | D19: ='5'!F19 -> 10641.2 | E19: ='Daily Meter'!T11 -> 10647.9 | F19: ='Daily Meter'!U11 -> 10655.6 | G19: =(F19-E19)*480 -> 3696 | H19: =(F19-D19)*480 -> 6912
B20: TOTAL ELECTRICAL CONS.(kWh) | G20: =SUM(G14:G19) -> 11328 | H20: =SUM(H14:H19) -> 21216 | I20: =H20*0.43 -> 9122.88
A22: V | B22: GAS CONSUMPTION
A23: 1 | B23: MAIN LPG METER | C23: mᶟ | D23: ='5'!F23 -> 52473.5 | E23: ='Daily Meter'!V11 -> 52547.4 | F23: ='Daily Meter'!W11 -> 52635.8 | G23: =F23-E23 -> 88.4 | H23: =F23-D23 -> 162.3
C24: L | H24: =H23*3.7 -> 600.51 | I24: =H24*2.18 -> 1309.1118
D27: Summary of Daily Hotel consumption
D28: Item measured | E28: Units | F28: Consumption | G28: AED
D29: Chilled water | E29: TR | F29: =H9 -> 6994.764 | G29: =F29*0.63 -> 4406.7013
D30: DEWA Water | E30: imp. Gallon | F30: =H12 -> 65770.731 | G30: =F30*0.06 -> 3946.2439
D31: Electricity | E31: kwh | F31: =H20 -> 21216 | G31: =F31*0.43 -> 9122.88
D32: Gas | E32: m3 | F32: =H23 -> 162.3 | G32: =I24 -> 1309.1118
F33: Total cost | G33: =SUM(G29:G32) -> 18784.937

Sheet 7
A1: ENGINEERING DEPARTMENT | J1: daily reading
A3: UTILITY CONSUMPTION SHEET
B4: ='1'!B4 -> FEBRUARY 2023 | C4: 7
A5: SR.NO | B5: ITEM MEASURED | D5: Previous Reading | E5: 1st Reading (5am) | F5: 2nd Reading (5pm) | G5: 12hrs CONSUMPTION | H5: 24hrs CONSUMPTION | I5: Cost
A7: 1 | B7: DISTRICT COOLING PLANT
B8: Chilled Water | C8: MWH | D8: ='6'!F8 -> 36701.7 | E8: ='Daily Meter'!B12 -> 36705.1 | F8: ='Daily Meter'!C12 -> 36716.9 | G8: =F8-E8 -> 11.8 | H8: =F8-D8 -> 15.2
C9: TR | G9: =G8*284.34 -> 3355.212 | H9: =H8*284.34 -> 4321.968 | I9: =H9*0.63 -> 2722.8398
A10: III | B10: WATER METERS
B11: Main DEWA Meter | C11: mᶟ | D11: ='6'!F11 -> 124542 | E11: ='Daily Meter'!D12 -> 124738 | F11: ='Daily Meter'!E12 -> 124798 | G11: =F11-E11 -> 60 | H11: =F11-D11 -> 256
B12: Imperial Gallon = m³ x 219.969 | C12: IG | G12: =G11*219.969 -> 13198.14 | H12: =H11*219.969 -> 56312.064 | I12: =H12*0.06 -> 3378.7238
A13: IV | B13: ELECTRICAL METERS
A14: 1 | B14: Meter 1 - 06065253 | C14: kW x 480 | D14: ='6'!F14 -> 4276.2 | E14: ='Daily Meter'!J12 -> 4277.2 | F14: ='Daily Meter'!K12 -> 4281 | G14: =(F14-E14)*480 -> 1824 | H14: =(F14-D14)*480 -> 2304
A15: 2 | B15: Meter 2 - 06065255 | C15: kW x 480 | D15: ='6'!F15 -> 2568 | E15: ='Daily Meter'!L12 -> 2568.5 | F15: ='Daily Meter'!M12 -> 2570.8 | G15: =(F15-E15)*480 -> 1104 | H15: =(F15-D15)*480 -> 1344
A16: 3 | B16: Meter 3 - 06065259 | C16: kW x 480 | D16: ='6'!F16 -> 2756.8 | E16: ='Daily Meter'!N12 -> 2757.8 | F16: ='Daily Meter'!O12 -> 2760.3 | G16: =(F16-E16)*480 -> 1200 | H16: =(F16-D16)*480 -> 1680
A17: 4 | B17: Meter 4 - 06065262 | C17: kW x 480 | D17: ='6'!F17 -> 1384.2 | E17: ='Daily Meter'!P12 -> 1384.7 | F17: ='Daily Meter'!Q12 -> 1386.2 | G17: =(F17-E17)*480 -> 720 | H17: =(F17-D17)*480 -> 960
A18: 5 | B18: Meter 6 - 06065269 | C18: kW x 480 | D18: ='6'!F18 -> 4032 | E18: ='Daily Meter'!R12 -> 4032.8 | F18: ='Daily Meter'!S12 -> 4035.5 | G18: =(F18-E18)*480 -> 1296 | H18: =(F18-D18)*480 -> 1680
A19: 6 | B19: Meter 7 - 06065283 | C19: kW x 480 | D19: ='6'!F19 -> 10655.6 | E19: ='Daily Meter'!T12 -> 10657.6 | F19: ='Daily Meter'!U12 -> 10664.2 | G19: =(F19-E19)*480 -> 3168 | H19: =(F19-D19)*480 -> 4128
B20: TOTAL ELECTRICAL CONS.(kWh) | G20: =SUM(G14:G19) -> 9312 | H20: =SUM(H14:H19) -> 12096 | I20: =H20*0.43 -> 5201.28
A22: V | B22: GAS CONSUMPTION
A23: 1 | B23: MAIN LPG METER | C23: mᶟ | D23: ='6'!F23 -> 52635.8 | E23: ='Daily Meter'!V12 -> 52660.2 | F23: ='Daily Meter'!W12 -> 52736.5 | G23: =F23-E23 -> 76.3 | H23: =F23-D23 -> 100.7
B24: L = m³ x 2.71 | C24: L | H24: =H23*3.7 -> 372.59 | I24: =H24*2.18 -> 812.2462
D27: Summary of Daily Hotel consumption
D28: Item measured | E28: Units | F28: Consumption | G28: AED
D29: Chilled water | E29: TR | F29: =H9 -> 4321.968 | G29: =I9 -> 2722.8398
D30: DEWA Water | E30: imp. Gallon | F30: =H12 -> 56312.064 | G30: =I12 -> 3378.7238
D31: Electricity | E31: kwh | F31: =H20 -> 12096 | G31: =I20 -> 5201.28
D32: Gas | E32: m3 | F32: =H23 -> 100.7 | G32: =I24 -> 812.2462
F33: Total cost | G33: =SUM(G29:G32) -> 12115.09

Sheet 8
A1: ENGINEERING DEPARTMENT | J1: daily reading
A3: UTILITY CONSUMPTION SHEET
B4: ='1'!B4 -> FEBRUARY 2023 | C4: 8
A5: SR.NO | B5: ITEM MEASURED | D5: Previous Reading | E5: 1st Reading (5am) | F5: 2nd Reading (5pm) | G5: 12hrs CONSUMPTION | H5: 24hrs CONSUMPTION | I5: Cost
A7: 1 | B7: DISTRICT COOLING PLANT
B8: Chilled Water | C8: MWH | D8: ='7'!F8 -> 36716.9 | E8: ='Daily Meter'!B13 -> 36730.3 | F8: ='Daily Meter'!C13 -> 36739.9 | G8: =F8-E8 -> 9.6 | H8: =F8-D8 -> 23
C9: TR | G9: =G8*284.34 -> 2729.664 | H9: =H8*284.34 -> 6539.82 | I9: =H9*0.63 -> 4120.0866
A10: III | B10: WATER METERS
B11: Main DEWA Meter | C11: mᶟ | D11: ='7'!F11 -> 124798 | E11: ='Daily Meter'!D13 -> 124957 | F11: ='Daily Meter'!E13 -> 125026 | G11: =F11-E11 -> 69 | H11: =F11-D11 -> 228
B12: Imperial Gallon = m³ x 219.969 | C12: IG | G12: =G11*219.969 -> 15177.861 | H12: =H11*219.969 -> 50152.932 | I12: =H12*0.06 -> 3009.1759
A13: IV | B13: ELECTRICAL METERS
A14: 1 | B14: Meter 1 - 06065253 | C14: kW x 480 | D14: ='7'!F14 -> 4281 | E14: ='Daily Meter'!J13 -> 4285.1 | F14: ='Daily Meter'!K13 -> 4287.7 | G14: =(F14-E14)*480 -> 1248 | H14: =(F14-D14)*480 -> 3216
A15: 2 | B15: Meter 2 - 06065255 | C15: kW x 480 | D15: ='7'!F15 -> 2570.8 | E15: ='Daily Meter'!L13 -> 2573 | F15: ='Daily Meter'!M13 -> 2574.8 | G15: =(F15-E15)*480 -> 864 | H15: =(F15-D15)*480 -> 1920
A16: 3 | B16: Meter 3 - 06065259 | C16: kW x 480 | D16: ='7'!F16 -> 2760.3 | E16: ='Daily Meter'!N13 -> 2763.4 | F16: ='Daily Meter'!O13 -> 2765.1 | G16: =(F16-E16)*480 -> 816 | H16: =(F16-D16)*480 -> 2304
A17: 4 | B17: Meter 4 - 06065262 | C17: kW x 480 | D17: ='7'!F17 -> 1386.2 | E17: ='Daily Meter'!P13 -> 1387.9 | F17: ='Daily Meter'!Q13 -> 1388.9 | G17: =(F17-E17)*480 -> 480 | H17: =(F17-D17)*480 -> 1296
A18: 5 | B18: Meter 6 - 06065269 | C18: kW x 480 | D18: ='7'!F18 -> 4035.5 | E18: ='Daily Meter'!R13 -> 4038.4 | F18: ='Daily Meter'!S13 -> 4040.3 | G18: =(F18-E18)*480 -> 912 | H18: =(F18-D18)*480 -> 2304
A19: 6 | B19: Meter 7 - 06065283 | C19: kW x 480 | D19: ='7'!F19 -> 10664.2 | E19: ='Daily Meter'!T13 -> 10671.5 | F19: ='Daily Meter'!U13 -> 10676.1 | G19: =(F19-E19)*480 -> 2208 | H19: =(F19-D19)*480 -> 5712
B20: TOTAL ELECTRICAL CONS.(kWh) | G20: =SUM(G14:G19) -> 6528 | H20: =SUM(H14:H19) -> 16752 | I20: =H20*0.43 -> 7203.36
A22: V | B22: GAS CONSUMPTION
A23: 1 | B23: MAIN LPG METER | C23: mᶟ | D23: ='7'!F23 -> 52736.5 | E23: ='Daily Meter'!V13 -> 52814.8 | F23: ='Daily Meter'!W13 -> 52873.7 | G23: =F23-E23 -> 58.9 | H23: =F23-D23 -> 137.2
B24: L = m³ x 2.71 | C24: L | H24: =H23*3.7 -> 507.64 | I24: =H24*2.18 -> 1106.6552
D27: Summary of Daily Hotel consumption
D28: Item measured | E28: Units | F28: Consumption | G28: AED
D29: Chilled water | E29: TR | F29: =H9 -> 6539.82 | G29: =I9 -> 4120.0866
D30: DEWA Water | E30: imp. Gallon | F30: =H12 -> 50152.932 | G30: =I12 -> 3009.1759
D31: Electricity | E31: kwh | F31: =H20 -> 16752 | G31: =I20 -> 7203.36
D32: Gas | E32: m3 | F32: =H23 -> 137.2 | G32: =I24 -> 1106.6552
F33: Total cost | G33: =SUM(G29:G32) -> 15439.278

Sheet 9
A1: ENGINEERING DEPARTMENT | J1: daily reading
A3: UTILITY CONSUMPTION SHEET
B4: ='1'!B4 -> FEBRUARY 2023 | C4: 9
A5: SR.NO | B5: ITEM MEASURED | D5: Previous Reading | E5: 1st Reading (5am) | F5: 2nd Reading (5pm) | G5: 12hrs CONSUMPTION | H5: 24hrs CONSUMPTION | I5: Cost
A7: 1 | B7: DISTRICT COOLING PLANT
B8: Chilled Water | C8: MWH | D8: ='8'!F8 -> 36739.9 | E8: ='Daily Meter'!B14 -> 36753 | F8: ='Daily Meter'!C14 -> 36760.7 | G8: =F8-E8 -> 7.7 | H8: =F8-D8 -> 20.8
C9: TR | G9: =G8*284.34 -> 2189.418 | H9: =H8*284.34 -> 5914.272 | I9: =H9*0.63 -> 3725.9914
A10: III | B10: WATER METERS
B11: Main DEWA Meter | C11: m3 | D11: ='8'!F11 -> 125026 | E11: ='Daily Meter'!D14 -> 125304 | F11: ='Daily Meter'!E14 -> 125385 | G11: =F11-E11 -> 81 | H11: =F11-D11 -> 359
B12: Imperial Gallon = m³ x 219.969 | C12: IG | G12: =G11*219.969 -> 17817.489 | H12: =H11*219.969 -> 78968.871 | I12: =H12*0.06 -> 4738.1323
A13: IV | B13: ELECTRICAL METERS
A14: 1 | B14: Meter 1 - 06065253 | C14: kW x 480 | D14: ='8'!F14 -> 4287.7 | E14: ='Daily Meter'!J14 -> 4291.7 | F14: ='Daily Meter'!K14 -> 4294.1 | G14: =(F14-E14)*480 -> 1152 | H14: =(F14-D14)*480 -> 3072
A15: 2 | B15: Meter 2 - 06065255 | C15: kW x 480 | D15: ='8'!F15 -> 2574.8 | E15: ='Daily Meter'!L14 -> 2577 | F15: ='Daily Meter'!M14 -> 2578.7 | G15: =(F15-E15)*480 -> 816 | H15: =(F15-D15)*480 -> 1872
A16: 3 | B16: Meter 3 - 06065259 | C16: kW x 480 | D16: ='8'!F16 -> 2765.1 | E16: ='Daily Meter'!N14 -> 2768.3 | F16: ='Daily Meter'!O14 -> 2769.9 | G16: =(F16-E16)*480 -> 768 | H16: =(F16-D16)*480 -> 2304
A17: 4 | B17: Meter 4 - 06065262 | C17: kW x 480 | D17: ='8'!F17 -> 1388.9 | E17: ='Daily Meter'!P14 -> 1390.6 | F17: ='Daily Meter'!Q14 -> 1391.5 | G17: =(F17-E17)*480 -> 432 | H17: =(F17-D17)*480 -> 1248
A18: 5 | B18: Meter 6 - 06065269 | C18: kW x 480 | D18: ='8'!F18 -> 4040.3 | E18: ='Daily Meter'!R14 -> 4043.2 | F18: ='Daily Meter'!S14 -> 4044.9 | G18: =(F18-E18)*480 -> 816 | H18: =(F18-D18)*480 -> 2208
A19: 6 | B19: Meter 7 - 06065283 | C19: kW x 480 | D19: ='8'!F19 -> 10676.1 | E19: ='Daily Meter'!T14 -> 10683.2 | F19: ='Daily Meter'!U14 -> 10687.6 | G19: =(F19-E19)*480 -> 2112 | H19: =(F19-D19)*480 -> 5520
B20: TOTAL ELECTRICAL CONS.(kWh) | G20: =SUM(G14:G19) -> 6096 | H20: =SUM(H14:H19) -> 16224 | I20: =H20*0.43 -> 6976.32
A22: V | B22: GAS CONSUMPTION
A23: 1 | B23: MAIN LPG METER | C23: M3 | D23: ='8'!F23 -> 52873.7 | E23: ='Daily Meter'!V14 -> 52951.8 | F23: ='Daily Meter'!W14 -> 53009.3 | G23: =F23-E23 -> 57.5 | H23: =F23-D23 -> 135.6
B24: L = m³ x 2.71 | C24: L | H24: =H23*3.7 -> 501.72 | I24: =H24*2.18 -> 1093.7496
D27: Summary of Daily Hotel consumption
D28: Item measured | E28: Units | F28: Consumption | G28: AED
D29: Chilled water | E29: TR | F29: =H9 -> 5914.272 | G29: =I9 -> 3725.9914
D30: DEWA Water | E30: imp. Gallon | F30: =H12 -> 78968.871 | G30: =I12 -> 4738.1323
D31: Electricity | E31: kwh | F31: =H20 -> 16224 | G31: =I20 -> 6976.32
D32: Gas | E32: m3 | F32: =H23 -> 135.6 | G32: =I24 -> 1093.7496
F33: Total cost | G33: =SUM(G29:G32) -> 16534.193

Sheet 10
A1: ENGINEERING DEPARTMENT | J1: daily reading
A3: UTILITY CONSUMPTION SHEET
B4: NOVEMBER | C4: 10
A5: SR.NO | B5: ITEM MEASURED | C5: ='1'!B4 -> FEBRUARY 2023 | D5: Previous Reading | E5: 1st Reading (5am) | F5: 2nd Reading (5pm) | G5: 12hrs CONSUMPTION | H5: 24hrs CONSUMPTION | I5: Cost
A7: 1 | B7: DISTRICT COOLING PLANT
B8: Chilled Water | C8: MWH | D8: ='9'!F8 -> 36760.7 | E8: ='Daily Meter'!B15 -> 36772.2 | F8: ='Daily Meter'!C15 -> 36779.9 | G8: =F8-E8 -> 7.7 | H8: =F8-D8 -> 19.2
C9: TR | G9: =G8*284.34 -> 2189.418 | H9: =H8*284.34 -> 5459.328 | I9: =H9*0.63 -> 3439.3766
A10: III | B10: WATER METERS
B11: Main DEWA Meter | C11: m3 | D11: ='9'!F11 -> 125385 | E11: ='Daily Meter'!D15 -> 125680 | F11: ='Daily Meter'!E15 -> 125743 | G11: =F11-E11 -> 63 | H11: =F11-D11 -> 358
B12: Imperial Gallon = m³ x 219.969 | C12: IG | G12: =G11*219.969 -> 13858.047 | H12: =H11*219.969 -> 78748.902 | I12: =H12*0.06 -> 4724.9341
A13: IV | B13: ELECTRICAL METERS
A14: 1 | B14: Meter 1 - 06065253 | C14: kW x 480 | D14: ='9'!F14 -> 4294.1 | E14: ='Daily Meter'!J15 -> 4298.6 | F14: ='Daily Meter'!K15 -> 4301.4 | G14: =(F14-E14)*480 -> 1344 | H14: =(F14-D14)*480 -> 3504
A15: 2 | B15: Meter 2 - 06065255 | C15: kW x 480 | D15: ='9'!F15 -> 2578.7 | E15: ='Daily Meter'!L15 -> 2581 | F15: ='Daily Meter'!M15 -> 2582.8 | G15: =(F15-E15)*480 -> 864 | H15: =(F15-D15)*480 -> 1968
A16: 3 | B16: Meter 3 - 06065259 | C16: kW x 480 | D16: ='9'!F16 -> 2769.9 | E16: ='Daily Meter'!N15 -> 2773.6 | F16: ='Daily Meter'!O15 -> 2775.7 | G16: =(F16-E16)*480 -> 1008 | H16: =(F16-D16)*480 -> 2784
A17: 4 | B17: Meter 4 - 06065262 | C17: kW x 480 | D17: ='9'!F17 -> 1391.5 | E17: ='Daily Meter'!P15 -> 1393.3 | F17: ='Daily Meter'!Q15 -> 1394.3 | G17: =(F17-E17)*480 -> 480 | H17: =(F17-D17)*480 -> 1344
A18: 5 | B18: Meter 6 - 06065269 | C18: kW x 480 | D18: ='9'!F18 -> 4044.9 | E18: ='Daily Meter'!R15 -> 4048 | F18: ='Daily Meter'!S15 -> 4049.9 | G18: =(F18-E18)*480 -> 912 | H18: =(F18-D18)*480 -> 2400
A19: 6 | B19: Meter 7 - 06065283 | C19: kW x 480 | D19: ='9'!F19 -> 10687.6 | E19: ='Daily Meter'!T15 -> 10694.9 | F19: ='Daily Meter'!U15 -> 10699.6 | G19: =(F19-E19)*480 -> 2256 | H19: =(F19-D19)*480 -> 5760
B20: TOTAL ELECTRICAL CONS.(kWh) | G20: =SUM(G14:G19) -> 6864 | H20: =SUM(H14:H19) -> 17760 | I20: =H20*0.43 -> 7636.8
A22: V | B22: GAS CONSUMPTION
A23: 1 | B23: MAIN LPG METER | C23: M3 | D23: ='9'!F23 -> 53009.3 | E23: ='Daily Meter'!V15 -> 53090.8 | F23: ='Daily Meter'!W15 -> 53154.1 | G23: =F23-E23 -> 63.3 | H23: =F23-D23 -> 144.8
B24: L = m³ x 2.71 | C24: L | H24: =H23*3.7 -> 535.76 | I24: =H24*2.18 -> 1167.9568
D27: Summary of Daily Hotel consumption
D28: Item measured | E28: Units | F28: Consumption | G28: AED
D29: Chilled water | E29: TR | F29: =H9 -> 5459.328 | G29: =I9 -> 3439.3766
D30: DEWA Water | E30: imp. Gallon | F30: =H12 -> 78748.902 | G30: =I12 -> 4724.9341
D31: Electricity | E31: kwh | F31: =H20 -> 17760 | G31: =I20 -> 7636.8
D32: Gas | E32: m3 | F32: =H23 -> 144.8 | G32: =I24 -> 1167.9568
F33: Total cost | G33: =SUM(G29:G32) -> 16969.068

Sheet 11
A1: ENGINEERING DEPARTMENT | K1: daily reading
A3: UTILITY CONSUMPTION SHEET
B4: ='1'!B4 -> FEBRUARY 2023 | C4: 11
A5: SR.NO | B5: ITEM MEASURED | D5: Previous Reading | E5: 1st Reading (5am) | F5: 2nd Reading (5pm) | G5: 12hrs CONSUMPTION | H5: 24hrs CONSUMPTION | I5: Cost
A7: 1 | B7: DISTRICT COOLING PLANT
B8: Chilled Water | C8: MWH | D8: ='10'!F8 -> 36779.9 | E8: ='Daily Meter'!B16 -> 36790.5 | F8: ='Daily Meter'!C16 -> 36799.1 | G8: =F8-E8 -> 8.6 | H8: =F8-D8 -> 19.2
C9: TR | G9: =G8*284.34 -> 2445.324 | H9: =H8*284.34 -> 5459.328 | I9: =H9*0.63 -> 3439.3766
A10: III | B10: WATER METERS
B11: Main DEWA Meter | C11: m3 | D11: ='10'!F11 -> 125743 | E11: ='Daily Meter'!D16 -> 125890 | F11: ='Daily Meter'!E16 -> 125953 | G11: =F11-E11 -> 63 | H11: =F11-D11 -> 210
B12: Imperial Gallon = m³ x 219.969 | C12: IG | G12: =G11*219.969 -> 13858.047 | H12: =H11*219.969 -> 46193.49 | I12: =H12*0.06 -> 2771.6094
A13: IV | B13: ELECTRICAL METERS
A14: 1 | B14: Meter 1 - 06065253 | C14: kW x 480 | D14: ='10'!F14 -> 4301.4 | E14: ='Daily Meter'!J16 -> 4305.6 | F14: ='Daily Meter'!K16 -> 4308.8 | G14: =(F14-E14)*480 -> 1536 | H14: =(F14-D14)*480 -> 3552
A15: 2 | B15: Meter 2 - 06065255 | C15: kW x 480 | D15: ='10'!F15 -> 2582.8 | E15: ='Daily Meter'!L16 -> 2585.1 | F15: ='Daily Meter'!M16 -> 2587.1 | G15: =(F15-E15)*480 -> 960 | H15: =(F15-D15)*480 -> 2064
A16: 3 | B16: Meter 3 - 06065259 | C16: kW x 480 | D16: ='10'!F16 -> 2775.7 | E16: ='Daily Meter'!N16 -> 2779.2 | F16: ='Daily Meter'!O16 -> 2781.2 | G16: =(F16-E16)*480 -> 960 | H16: =(F16-D16)*480 -> 2640
A17: 4 | B17: Meter 4 - 06065262 | C17: kW x 480 | D17: ='10'!F17 -> 1394.3 | E17: ='Daily Meter'!P16 -> 1396.3 | F17: ='Daily Meter'!Q16 -> 1397.5 | G17: =(F17-E17)*480 -> 576 | H17: =(F17-D17)*480 -> 1536
A18: 5 | B18: Meter 6 - 06065269 | C18: kW x 480 | D18: ='10'!F18 -> 4049.9 | E18: ='Daily Meter'!R16 -> 4052.8 | F18: ='Daily Meter'!S16 -> 4055.1 | G18: =(F18-E18)*480 -> 1104 | H18: =(F18-D18)*480 -> 2496
A19: 6 | B19: Meter 7 - 06065283 | C19: kW x 480 | D19: ='10'!F19 -> 10699.6 | E19: ='Daily Meter'!T16 -> 10706.6 | F19: ='Daily Meter'!U16 -> 10711.7 | G19: =(F19-E19)*480 -> 2448 | H19: =(F19-D19)*480 -> 5808
B20: TOTAL ELECTRICAL CONS.(kWh) | G20: =SUM(G14:G19) -> 7584 | H20: =SUM(H14:H19) -> 18096 | I20: =H20*0.43 -> 7781.28
A22: V | B22: GAS CONSUMPTION
A23: 1 | B23: MAIN LPG METER | C23: M3 | D23: ='10'!F23 -> 53154.1 | E23: ='Daily Meter'!V16 -> 53234.7 | F23: ='Daily Meter'!W16 -> 53298.2 | G23: =F23-E23 -> 63.5 | H23: =F23-D23 -> 144.1
B24: L = m³ x 2.71 | C24: L | H24: =H23*3.7 -> 533.17 | I24: =H24*2.18 -> 1162.3106
D27: Summary of Daily Hotel consumption
D28: Item measured | E28: Units | F28: Consumption | G28: AED
D29: Chilled water | E29: TR | F29: =H9 -> 5459.328 | G29: =I9 -> 3439.3766
D30: DEWA Water | E30: imp. Gallon | F30: =H12 -> 46193.49 | G30: =I12 -> 2771.6094
D31: Electricity | E31: kwh | F31: =H20 -> 18096 | G31: =I20 -> 7781.28
D32: Gas | E32: m3 | F32: =H23 -> 144.1 | G32: =I24 -> 1162.3106
F33: Total cost | G33: =SUM(G29:G32) -> 15154.577

Sheet 12
A1: ENGINEERING DEPARTMENT | K1: daily reading
A3: UTILITY CONSUMPTION SHEET
B4: ='1'!B4 -> FEBRUARY 2023 | C4: 12
A5: SR.NO | B5: ITEM MEASURED | D5: Previous Reading | E5: 1st Reading (5am) | F5: 2nd Reading (5pm) | G5: 12hrs CONSUMPTION | H5: 24hrs CONSUMPTION | I5: Cost
A7: 1 | B7: DISTRICT COOLING PLANT
B8: Chilled Water | C8: MWH | D8: ='11'!F8 -> 36799.1 | E8: ='Daily Meter'!B17 -> 36808.7 | F8: ='Daily Meter'!C17 -> 36816.8 | G8: =F8-E8 -> 8.1 | H8: =F8-D8 -> 17.7
C9: TR | G9: =G8*284.34 -> 2303.154 | H9: =H8*284.34 -> 5032.818 | I9: =H9*0.63 -> 3170.6753
A10: III | B10: WATER METERS
B11: Main DEWA Meter | C11: m3 | D11: ='11'!F11 -> 125953 | E11: ='Daily Meter'!D17 -> 126261 | F11: ='Daily Meter'!E17 -> 126269 | G11: =F11-E11 -> 8 | H11: =F11-D11 -> 316
B12: Imperial Gallon = m³ x 219.969 | C12: IG | G12: =G11*219.969 -> 1759.752 | H12: =H11*219.969 -> 69510.204 | I12: =H12*0.06 -> 4170.6122
A13: IV | B13: ELECTRICAL METERS
A14: 1 | B14: Meter 1 - 06065253 | C14: kW x 480 | D14: ='11'!F14 -> 4308.8 | E14: ='Daily Meter'!J17 -> 4312.3 | F14: ='Daily Meter'!K17 -> 4315.2 | G14: =(F14-E14)*480 -> 1392 | H14: =(F14-D14)*480 -> 3072
A15: 2 | B15: Meter 2 - 06065255 | C15: kW x 480 | D15: ='11'!F15 -> 2587.1 | E15: ='Daily Meter'!L17 -> 2589 | F15: ='Daily Meter'!M17 -> 2590.8 | G15: =(F15-E15)*480 -> 864 | H15: =(F15-D15)*480 -> 1776
A16: 3 | B16: Meter 3 - 06065259 | C16: kW x 480 | D16: ='11'!F16 -> 2781.2 | E16: ='Daily Meter'!N17 -> 2784.1 | F16: ='Daily Meter'!O17 -> 2785.9 | G16: =(F16-E16)*480 -> 864 | H16: =(F16-D16)*480 -> 2256
A17: 4 | B17: Meter 4 - 06065262 | C17: kW x 480 | D17: ='11'!F17 -> 1397.5 | E17: ='Daily Meter'!P17 -> 1399.2 | F17: ='Daily Meter'!Q17 -> 1400.2 | G17: =(F17-E17)*480 -> 480 | H17: =(F17-D17)*480 -> 1296
A18: 5 | B18: Meter 6 - 06065269 | C18: kW x 480 | D18: ='11'!F18 -> 4055.1 | E18: ='Daily Meter'!R17 -> 4057.7 | F18: ='Daily Meter'!S17 -> 4059.8 | G18: =(F18-E18)*480 -> 1008 | H18: =(F18-D18)*480 -> 2256
A19: 6 | B19: Meter 7 - 06065283 | C19: kW x 480 | D19: ='11'!F19 -> 10711.7 | E19: ='Daily Meter'!T17 -> 10717.9 | F19: ='Daily Meter'!U17 -> 10723 | G19: =(F19-E19)*480 -> 2448 | H19: =(F19-D19)*480 -> 5424
B20: TOTAL ELECTRICAL CONS.(kWh) | G20: =SUM(G14:G19) -> 7056 | H20: =SUM(H14:H19) -> 16080 | I20: =H20*0.43 -> 6914.4
A22: V | B22: GAS CONSUMPTION
A23: 1 | B23: MAIN LPG METER | C23: M3 | D23: ='11'!F23 -> 53298.2 | E23: ='Daily Meter'!V17 -> 53365.7 | F23: ='Daily Meter'!W17 -> 53418.5 | G23: =F23-E23 -> 52.8 | H23: =F23-D23 -> 120.3
B24: L = m³ x 2.71 | C24: L | H24: =H23*3.7 -> 445.11 | I24: =H24*2.18 -> 970.3398
D27: Summary of Daily Hotel consumption
D28: Item measured | E28: Units | F28: Consumption | G28: AED
D29: Chilled water | E29: TR | F29: =H9 -> 5032.818 | G29: =I9 -> 3170.6753
D30: DEWA Water | E30: imp. Gallon | F30: =H12 -> 69510.204 | G30: =I12 -> 4170.6122
D31: Electricity | E31: kwh | F31: =H20 -> 16080 | G31: =I20 -> 6914.4
D32: Gas | E32: m3 | F32: =H23 -> 120.3 | G32: =I24 -> 970.3398
F33: Total cost | G33: =SUM(G29:G32) -> 15226.027

Sheet 13
A1: ENGINEERING DEPARTMENT | K1: daily reading
A3: UTILITY CONSUMPTION SHEET
B4: ='1'!B4 -> FEBRUARY 2023 | C4: 13
A5: SR.NO | B5: ITEM MEASURED | D5: Previous Reading | E5: 1st Reading (5am) | F5: 2nd Reading (5pm) | G5: 12hrs CONSUMPTION | H5: 24hrs CONSUMPTION | I5: Cost
A7: 1 | B7: DISTRICT COOLING PLANT
B8: Chilled Water | C8: MWH | D8: ='12'!F8 -> 36816.8 | E8: ='Daily Meter'!B18 -> 36828.3 | F8: ='Daily Meter'!C18 -> 36840.6 | G8: =F8-E8 -> 12.3 | H8: =F8-D8 -> 23.8
C9: TR | G9: =G8*284.34 -> 3497.382 | H9: =H8*284.34 -> 6767.292 | I9: =H9*0.63 -> 4263.394
A10: III | B10: WATER METERS
B11: Main DEWA Meter | C11: m3 | D11: ='12'!F11 -> 126269 | E11: ='Daily Meter'!D18 -> 126469 | F11: ='Daily Meter'!E18 -> 126501 | G11: =F11-E11 -> 32 | H11: =F11-D11 -> 232
B12: Imperial Gallon = m³ x 219.969 | C12: IG | G12: =G11*219.969 -> 7039.008 | H12: =H11*219.969 -> 51032.808 | I12: =H12*0.06 -> 3061.9685
A13: IV | B13: ELECTRICAL METERS
A14: 1 | B14: Meter 1 - 06065253 | C14: kW x 480 | D14: ='12'!F14 -> 4315.2 | E14: ='Daily Meter'!J18 -> 4318.9 | F14: ='Daily Meter'!K18 -> 4323.4 | G14: =(F14-E14)*480 -> 2160 | H14: =(F14-D14)*480 -> 3936
A15: 2 | B15: Meter 2 - 06065255 | C15: kW x 480 | D15: ='12'!F15 -> 2590.8 | E15: ='Daily Meter'!L18 -> 2592.7 | F15: ='Daily Meter'!M18 -> 2595.4 | G15: =(F15-E15)*480 -> 1296 | H15: =(F15-D15)*480 -> 2208
A16: 3 | B16: Meter 3 - 06065259 | C16: kW x 480 | D16: ='12'!F16 -> 2785.9 | E16: ='Daily Meter'!N18 -> 2788.9 | F16: ='Daily Meter'!O18 -> 2791.6 | G16: =(F16-E16)*480 -> 1296 | H16: =(F16-D16)*480 -> 2736
A17: 4 | B17: Meter 4 - 06065262 | C17: kW x 480 | D17: ='12'!F17 -> 1400.2 | E17: ='Daily Meter'!P18 -> 1401.8 | F17: ='Daily Meter'!Q18 -> 1403.6 | G17: =(F17-E17)*480 -> 864 | H17: =(F17-D17)*480 -> 1632
A18: 5 | B18: Meter 6 - 06065269 | C18: kW x 480 | D18: ='12'!F18 -> 4059.8 | E18: ='Daily Meter'!R18 -> 4062.4 | F18: ='Daily Meter'!S18 -> 4065.5 | G18: =(F18-E18)*480 -> 1488 | H18: =(F18-D18)*480 -> 2736
A19: 6 | B19: Meter 7 - 06065283 | C19: kW x 480 | D19: ='12'!F19 -> 10723 | E19: ='Daily Meter'!T18 -> 10729.6 | F19: ='Daily Meter'!U18 -> 10737.3 | G19: =(F19-E19)*480 -> 3696 | H19: =(F19-D19)*480 -> 6864
B20: TOTAL ELECTRICAL CONS.(kWh) | G20: =SUM(G14:G19) -> 10800 | H20: =SUM(H14:H19) -> 20112 | I20: =H20*0.43 -> 8648.16
A22: V | B22: GAS CONSUMPTION
A23: 1 | B23: MAIN LPG METER | C23: M3 | D23: ='12'!F23 -> 53418.5 | E23: ='Daily Meter'!V18 -> 53488.4 | F23: ='Daily Meter'!W18 -> 53549.2 | G23: =F23-E23 -> 60.8 | H23: =F23-D23 -> 130.7
B24: L = m³ x 2.71 | C24: L | H24: =H23*3.7 -> 483.59 | I24: =H24*2.18 -> 1054.2262
D27: Summary of Daily Hotel consumption
D28: Item measured | E28: Units | F28: Consumption | G28: AED
D29: Chilled water | E29: TR | F29: =H9 -> 6767.292 | G29: =I9 -> 4263.394
D30: DEWA Water | E30: imp. Gallon | F30: =H12 -> 51032.808 | G30: =I12 -> 3061.9685
D31: Electricity | E31: kwh | F31: =H20 -> 20112 | G31: =I20 -> 8648.16
D32: Gas | E32: m3 | F32: =H23 -> 130.7 | G32: =I24 -> 1054.2262
F33: Total cost | G33: =SUM(G29:G32) -> 17027.749

Sheet 14
A1: ENGINEERING DEPARTMENT | J1: daily reading
A3: UTILITY CONSUMPTION SHEET
B4: ='1'!B4 -> FEBRUARY 2023 | C4: 14
A5: SR.NO | B5: ITEM MEASURED | D5: Previous Reading | E5: 1st Reading (5am) | F5: 2nd Reading (5pm) | G5: 12hrs CONSUMPTION | H5: 24hrs CONSUMPTION | I5: Cost
A7: 1 | B7: DISTRICT COOLING PLANT
B8: Chilled Water | C8: MWH | D8: ='13'!F8 -> 36840.6 | E8: ='Daily Meter'!B19 -> 36848.6 | F8: ='Daily Meter'!C19 -> 36863.7 | G8: =F8-E8 -> 15.1 | H8: =F8-D8 -> 23.1
C9: TR | G9: =G8*284.34 -> 4293.534 | H9: =H8*284.34 -> 6568.254 | I9: =H9*0.63 -> 4138
A10: III | B10: WATER METERS
B11: Main DEWA Meter | C11: m3 | D11: ='13'!F11 -> 126501 | E11: ='Daily Meter'!D19 -> 126810 | F11: ='Daily Meter'!E19 -> 126813 | G11: =F11-E11 -> 3 | H11: =F11-D11 -> 312
B12: Imperial Gallon = m³ x 219.969 | C12: IG | G12: =G11*219.969 -> 659.907 | H12: =H11*219.969 -> 68630.328 | I12: =H12*0.06 -> 4117.8197
A13: IV | B13: ELECTRICAL METERS
A14: 1 | B14: Meter 1 - 06065253 | C14: kW x 480 | D14: ='13'!F14 -> 4323.4 | E14: ='Daily Meter'!J19 -> 4325.5 | F14: ='Daily Meter'!K19 -> 4328.3 | G14: =(F14-E14)*480 -> 1344 | H14: =(F14-D14)*480 -> 2352
A15: 2 | B15: Meter 2 - 06065255 | C15: kW x 480 | D15: ='13'!F15 -> 2595.4 | E15: ='Daily Meter'!L19 -> 2596.4 | F15: ='Daily Meter'!M19 -> 2598.2 | G15: =(F15-E15)*480 -> 864 | H15: =(F15-D15)*480 -> 1344
A16: 3 | B16: Meter 3 - 06065259 | C16: kW x 480 | D16: ='13'!F16 -> 2791.6 | E16: ='Daily Meter'!N19 -> 2793.5 | F16: ='Daily Meter'!O19 -> 2795.3 | G16: =(F16-E16)*480 -> 864 | H16: =(F16-D16)*480 -> 1776
A17: 4 | B17: Meter 4 - 06065262 | C17: kW x 480 | D17: ='13'!F17 -> 1403.6 | E17: ='Daily Meter'!P19 -> 1404.6 | F17: ='Daily Meter'!Q19 -> 1405.7 | G17: =(F17-E17)*480 -> 528 | H17: =(F17-D17)*480 -> 1008
A18: 5 | B18: Meter 6 - 06065269 | C18: kW x 480 | D18: ='13'!F18 -> 4065.5 | E18: ='Daily Meter'!R19 -> 4067.2 | F18: ='Daily Meter'!S19 -> 4069.2 | G18: =(F18-E18)*480 -> 960 | H18: =(F18-D18)*480 -> 1776
A19: 6 | B19: Meter 7 - 06065283 | C19: kW x 480 | D19: ='13'!F19 -> 10737.3 | E19: ='Daily Meter'!T19 -> 10741.9 | F19: ='Daily Meter'!U19 -> 10747.2 | G19: =(F19-E19)*480 -> 2544 | H19: =(F19-D19)*480 -> 4752
