Workbook

Sheet Total
A1: Site Name | B1: Day | C1: Month | D1: Year | E1: Total Electricity Kwh | F1: Electricity Tariff ($/Kwh) | G1: LPG (Liters) | H1: LPG $/Liters | I1: Water Utility Supply (IG) IG | J1: Water Utility Supply (IG) $/IG | K1: District Energy Cooling RTH | L1: District Energy Cooling $/RTH | M1: Room Nights | N1: Total Guests
A2: 25hours Dubai One Central | B2: 1 | C2: 3 | D2: 2024 | E2: =Submetering!E2+Submetering!F2+Submetering!G2+Submetering!H2+Submetering!I2+Submetering!J2 -> 17232 | F2: 0.44 | G2: =Submetering!M2 -> 596.07 | H2: 2.5 | I2: =Submetering!L2 -> 49712.994 | J2: 0.06 | K2: =Submetering!K2 -> 5971.14 | L2: 1.14 | M2: =INT('Daily Meter'!O6*434/100) -> 369
A3: 25hours Dubai One Central | B3: =B2+1 -> 2 | C3: 3 | D3: 2024 | E3: =Submetering!E3+Submetering!F3+Submetering!G3+Submetering!H3+Submetering!I3+Submetering!J3 -> 17184 | F3: 0.44 | G3: =Submetering!M3 -> 586.82 | H3: 2.5 | I3: =Submetering!L3 -> 48173.211 | J3: 0.06 | K3: =Submetering!K3 -> 5402.46 | L3: 1.14 | M3: =INT('Daily Meter'!O7*434/100) -> 334
A4: 25hours Dubai One Central | B4: =B3+1 -> 3 | C4: 3 | D4: 2024 | E4: =Submetering!E4+Submetering!F4+Submetering!G4+Submetering!H4+Submetering!I4+Submetering!J4 -> 17664 | F4: 0.44 | G4: =Submetering!M4 -> 430.68 | H4: 2.5 | I4: =Submetering!L4 -> 46633.428 | J4: 0.06 | K4: =Submetering!K4 -> 5345.592 | L4: 1.14 | M4: =INT('Daily Meter'!O8*434/100) -> 355
A5: 25hours Dubai One Central | B5: =B4+1 -> 4 | C5: 3 | D5: 2024 | E5: =Submetering!E5+Submetering!F5+Submetering!G5+Submetering!H5+Submetering!I5+Submetering!J5 -> 17040 | F5: 0.44 | G5: =Submetering!M5 -> 580.9 | H5: 2.5 | I5: =Submetering!L5 -> 39374.451 | J5: 0.06 | K5: =Submetering!K5 -> 5402.46 | L5: 1.14 | M5: =INT('Daily Meter'!O9*434/100) -> 385
A6: 25hours Dubai One Central | B6: =B5+1 -> 5 | C6: 3 | D6: 2024 | E6: =Submetering!E6+Submetering!F6+Submetering!G6+Submetering!H6+Submetering!I6+Submetering!J6 -> 17059.2 | F6: 0.44 | G6: =Submetering!M6 -> 549.08 | H6: 2.5 | I6: =Submetering!L6 -> 45093.645 | J6: 0.06 | K6: =Submetering!K6 -> 5828.97 | L6: 1.14 | M6: =INT('Daily Meter'!O10*434/100) -> 411
A7: 25hours Dubai One Central | B7: =B6+1 -> 6 | C7: 3 | D7: 2024 | E7: =Submetering!E7+Submetering!F7+Submetering!G7+Submetering!H7+Submetering!I7+Submetering!J7 -> 17020.8 | F7: 0.44 | G7: =Submetering!M7 -> 523.55 | H7: 2.5 | I7: =Submetering!L7 -> 40474.296 | J7: 0.06 | K7: =Submetering!K7 -> 6369.216 | L7: 1.14 | M7: =INT('Daily Meter'!O11*434/100) -> 396
A8: 25hours Dubai One Central | B8: =B7+1 -> 7 | C8: 3 | D8: 2024 | E8: =Submetering!E8+Submetering!F8+Submetering!G8+Submetering!H8+Submetering!I8+Submetering!J8 -> 16656 | F8: 0.44 | G8: =Submetering!M8 -> 504.31 | H8: 2.5 | I8: =Submetering!L8 -> 35854.947 | J8: 0.06 | K8: =Submetering!K8 -> 6227.046 | L8: 1.14 | M8: =INT('Daily Meter'!O12*434/100) -> 401
A9: 25hours Dubai One Central | B9: =B8+1 -> 8 | C9: 3 | D9: 2024 | E9: =Submetering!E9+Submetering!F9+Submetering!G9+Submetering!H9+Submetering!I9+Submetering!J9 -> 17088 | F9: 0.44 | G9: =Submetering!M9 -> 489.88 | H9: 2.5 | I9: =Submetering!L9 -> 41574.141 | J9: 0.06 | K9: =Submetering!K9 -> 6113.31 | L9: 1.14 | M9: =INT('Daily Meter'!O13*434/100) -> 318
A10: 25hours Dubai One Central | B10: =B9+1 -> 9 | C10: 3 | D10: 2024 | E10: =Submetering!E10+Submetering!F10+Submetering!G10+Submetering!H10+Submetering!I10+Submetering!J10 -> 17328 | F10: 0.44 | G10: =Submetering!M10 -> 577.57 | H10: 2.5 | I10: =Submetering!L10 -> 50372.901 | J10: 0.06 | K10: =Submetering!K10 -> 8046.822 | L10: 1.14 | M10: =INT('Daily Meter'!O14*434/100) -> 251
A11: 25hours Dubai One Central | B11: =B10+1 -> 10 | C11: 3 | D11: 2024 | E11: =Submetering!E11+Submetering!F11+Submetering!G11+Submetering!H11+Submetering!I11+Submetering!J11 -> 17136 | F11: 0.44 | G11: =Submetering!M11 -> 481 | H11: 2.5 | I11: =Submetering!L11 -> 43773.831 | J11: 0.06 | K11: =Submetering!K11 -> 5800.536 | L11: 1.14 | M11: =INT('Daily Meter'!O15*434/100) -> 171
A12: 25hours Dubai One Central | B12: =B11+1 -> 11 | C12: 3 | D12: 2024 | E12: =Submetering!E12+Submetering!F12+Submetering!G12+Submetering!H12+Submetering!I12+Submetering!J12 -> 16368 | F12: 0.44 | G12: =Submetering!M12 -> 431.42 | H12: 2.5 | I12: =Submetering!L12 -> 35634.978 | J12: 0.06 | K12: =Submetering!K12 -> 6141.744 | L12: 1.14 | M12: =INT('Daily Meter'!O16*434/100) -> 177
A13: 25hours Dubai One Central | B13: =B12+1 -> 12 | C13: 3 | D13: 2024 | E13: =Submetering!E13+Submetering!F13+Submetering!G13+Submetering!H13+Submetering!I13+Submetering!J13 -> 16512 | F13: 0.44 | G13: =Submetering!M13 -> 394.05 | H13: 2.5 | I13: =Submetering!L13 -> 30135.753 | J13: 0.06 | K13: =Submetering!K13 -> 6084.876 | L13: 1.14 | M13: =INT('Daily Meter'!O17*434/100) -> 178
A14: 25hours Dubai One Central | B14: =B13+1 -> 13 | C14: 3 | D14: 2024 | E14: =Submetering!E14+Submetering!F14+Submetering!G14+Submetering!H14+Submetering!I14+Submetering!J14 -> 16512 | F14: 0.44 | G14: =Submetering!M14 -> 430.68 | H14: 2.5 | I14: =Submetering!L14 -> 35854.947 | J14: 0.06 | K14: =Submetering!K14 -> 6056.442 | L14: 1.14 | M14: =INT('Daily Meter'!O18*434/100) -> 155
... A30: 25hours Dubai One Central | B30: =B29+1 -> 29 | C30: 3 | D30: 2024 | E30: =Submetering!E30+Submetering!F30+Submetering!G30+Submetering!H30+Submetering!I30+Submetering!J30 -> 0 | F30: 0.44 | G30: =Submetering!M30 -> 0 | H30: 2.5 | I30: =Submetering!L30 -> 0 | J30: 0.06 | K30: =Submetering!K30 -> 0 | L30: 1.14 | M30: =INT('Daily Meter'!O34*434/100) -> 0

Sheet Submetering
A1: Site Name | B1: Day | C1: Month | D1: Year | E1: Meter 1 - 06065253 | F1: Meter 2 - 06065255 | G1: Meter 3 - 06065259 | H1: Meter 4 - 06065262 | I1: Meter 6 - 06065269 | J1: Meter 7 - 06065283 | K1: District Cooling | L1: Water | M1: Gas | N1: Room Nights | O1: Total Guests
A2: 25hours Dubai One Central | B2: 1 | C2: 3 | D2: 2024 | E2: =IF(('Daily Meter'!H6-'1'!D13)<0,"0",'Daily Meter'!H6-'1'!D13)*480 -> 3360 | F2: =IF(('Daily Meter'!I6-'1'!D14)<0,"0",'Daily Meter'!I6-'1'!D14)*480 -> 2352 | G2: =IF(('Daily Meter'!J6-'1'!D15)<0,"0",'Daily Meter'!J6-'1'!D15)*480 -> 2304 | H2: =IF(('Daily Meter'!K6-'1'!D16)<0,"0",'Daily Meter'!K6-'1'!D16)*480 -> 1392 | I2: =IF(('Daily Meter'!L6-'1'!D17)<0,"0",'Daily Meter'!L6-'1'!D17)*480 -> 2208 | J2: =IF(('Daily Meter'!M6-'1'!D18)<0,"0",'Daily Meter'!M6-'1'!D18)*480 -> 5616 | K2: =IF(('Daily Meter'!B6-'1'!D7)<0,"0",'Daily Meter'!B6-'1'!D7)*284.34 -> 5971.14 | L2: =IF(('Daily Meter'!C6-'1'!D10)<0,"0",'Daily Meter'!C6-'1'!D10)*219.969 -> 49712.994 | M2: =IF(('Daily Meter'!N6-'1'!D22)<0,"0",'Daily Meter'!N6-'1'!D22)*3.7 -> 596.07 | N2: =Total!M2 -> 369
A3: 25hours Dubai One Central | B3: =B2+1 -> 2 | C3: 3 | D3: 2024 | E3: =IF(('Daily Meter'!H7-'Daily Meter'!H6)<0,"0",'Daily Meter'!H7-'Daily Meter'!H6)*480 -> 3456 | F3: =IF(('Daily Meter'!I7-'Daily Meter'!I6)<0,"0",'Daily Meter'!I7-'Daily Meter'!I6)*480 -> 2400 | G3: =IF(('Daily Meter'!J7-'Daily Meter'!J6)<0,"0",'Daily Meter'!J7-'Daily Meter'!J6)*480 -> 2304 | H3: =IF(('Daily Meter'!K7-'Daily Meter'!K6)<0,"0",'Daily Meter'!K7-'Daily Meter'!K6)*480 -> 1440 | I3: =IF(('Daily Meter'!L7-'Daily Meter'!L6)<0,"0",'Daily Meter'!L7-'Daily Meter'!L6)*480 -> 2160 | J3: =IF(('Daily Meter'!M7-'Daily Meter'!M6)<0,"0",'Daily Meter'!M7-'Daily Meter'!M6)*480 -> 5424 | K3: =IF(('Daily Meter'!B7-'Daily Meter'!B6)<0,"0",'Daily Meter'!B7-'Daily Meter'!B6)*284.34 -> 5402.46 | L3: =IF(('Daily Meter'!C7-'Daily Meter'!C6)<0,"0",'Daily Meter'!C7-'Daily Meter'!C6)*219.969 -> 48173.211 | M3: =IF(('Daily Meter'!N7-'Daily Meter'!N6)<0,"0",'Daily Meter'!N7-'Daily Meter'!N6)*3.7 -> 586.82 | N3: =Total!M3 -> 334
A4: 25hours Dubai One Central | B4: =B3+1 -> 3 | C4: 3 | D4: 2024 | E4: =IF(('Daily Meter'!H8-'Daily Meter'!H7)<0,"0",'Daily Meter'!H8-'Daily Meter'!H7)*480 -> 3456 | F4: =IF(('Daily Meter'!I8-'Daily Meter'!I7)<0,"0",'Daily Meter'!I8-'Daily Meter'!I7)*480 -> 2304 | G4: =IF(('Daily Meter'!J8-'Daily Meter'!J7)<0,"0",'Daily Meter'!J8-'Daily Meter'!J7)*480 -> 2448 | H4: =IF(('Daily Meter'!K8-'Daily Meter'!K7)<0,"0",'Daily Meter'!K8-'Daily Meter'!K7)*480 -> 1392 | I4: =IF(('Daily Meter'!L8-'Daily Meter'!L7)<0,"0",'Daily Meter'!L8-'Daily Meter'!L7)*480 -> 2256 | J4: =IF(('Daily Meter'!M8-'Daily Meter'!M7)<0,"0",'Daily Meter'!M8-'Daily Meter'!M7)*480 -> 5808 | K4: =IF(('Daily Meter'!B8-'Daily Meter'!B7)<0,"0",'Daily Meter'!B8-'Daily Meter'!B7)*284.34 -> 5345.592 | L4: =IF(('Daily Meter'!C8-'Daily Meter'!C7)<0,"0",'Daily Meter'!C8-'Daily Meter'!C7)*219.969 -> 46633.428 | M4: =IF(('Daily Meter'!N8-'Daily Meter'!N7)<0,"0",'Daily Meter'!N8-'Daily Meter'!N7)*3.7 -> 430.68 | N4: =Total!M4 -> 355
A5: 25hours Dubai One Central | B5: =B4+1 -> 4 | C5: 3 | D5: 2024 | E5: =IF(('Daily Meter'!H9-'Daily Meter'!H8)<0,"0",'Daily Meter'!H9-'Daily Meter'!H8)*480 -> 3312 | F5: =IF(('Daily Meter'!I9-'Daily Meter'!I8)<0,"0",'Daily Meter'!I9-'Daily Meter'!I8)*480 -> 2304 | G5: =IF(('Daily Meter'!J9-'Daily Meter'!J8)<0,"0",'Daily Meter'!J9-'Daily Meter'!J8)*480 -> 2208 | H5: =IF(('Daily Meter'!K9-'Daily Meter'!K8)<0,"0",'Daily Meter'!K9-'Daily Meter'!K8)*480 -> 1392 | I5: =IF(('Daily Meter'!L9-'Daily Meter'!L8)<0,"0",'Daily Meter'!L9-'Daily Meter'!L8)*480 -> 2160 | J5: =IF(('Daily Meter'!M9-'Daily Meter'!M8)<0,"0",'Daily Meter'!M9-'Daily Meter'!M8)*480 -> 5664 | K5: =IF(('Daily Meter'!B9-'Daily Meter'!B8)<0,"0",'Daily Meter'!B9-'Daily Meter'!B8)*284.34 -> 5402.46 | L5: =IF(('Daily Meter'!C9-'Daily Meter'!C8)<0,"0",'Daily Meter'!C9-'Daily Meter'!C8)*219.969 -> 39374.451 | M5: =IF(('Daily Meter'!N9-'Daily Meter'!N8)<0,"0",'Daily Meter'!N9-'Daily Meter'!N8)*3.7 -> 580.9 | N5: =Total!M5 -> 385
A6: 25hours Dubai One Central | B6: =B5+1 -> 5 | C6: 3 | D6: 2024 | E6: =IF(('Daily Meter'!H10-'Daily Meter'!H9)<0,"0",'Daily Meter'!H10-'Daily Meter'!H9)*480 -> 3264 | F6: =IF(('Daily Meter'!I10-'Daily Meter'!I9)<0,"0",'Daily Meter'!I10-'Daily Meter'!I9)*480 -> 2256 | G6: =IF(('Daily Meter'!J10-'Daily Meter'!J9)<0,"0",'Daily Meter'!J10-'Daily Meter'!J9)*480 -> 2208 | H6: =IF(('Daily Meter'!K10-'Daily Meter'!K9)<0,"0",'Daily Meter'!K10-'Daily Meter'!K9)*480 -> 1392 | I6: =IF(('Daily Meter'!L10-'Daily Meter'!L9)<0,"0",'Daily Meter'!L10-'Daily Meter'!L9)*480 -> 2227.2 | J6: =IF(('Daily Meter'!M10-'Daily Meter'!M9)<0,"0",'Daily Meter'!M10-'Daily Meter'!M9)*480 -> 5712 | K6: =IF(('Daily Meter'!B10-'Daily Meter'!B9)<0,"0",'Daily Meter'!B10-'Daily Meter'!B9)*284.34 -> 5828.97 | L6: =IF(('Daily Meter'!C10-'Daily Meter'!C9)<0,"0",'Daily Meter'!C10-'Daily Meter'!C9)*219.969 -> 45093.645 | M6: =IF(('Daily Meter'!N10-'Daily Meter'!N9)<0,"0",'Daily Meter'!N10-'Daily Meter'!N9)*3.7 -> 549.08 | N6: =Total!M6 -> 411
A7: 25hours Dubai One Central | B7: =B6+1 -> 6 | C7: 3 | D7: 2024 | E7: =IF(('Daily Meter'!H11-'Daily Meter'!H10)<0,"0",'Daily Meter'!H11-'Daily Meter'!H10)*480 -> 3456 | F7: =IF(('Daily Meter'!I11-'Daily Meter'!I10)<0,"0",'Daily Meter'!I11-'Daily Meter'!I10)*480 -> 2256 | G7: =IF(('Daily Meter'!J11-'Daily Meter'!J10)<0,"0",'Daily Meter'!J11-'Daily Meter'!J10)*480 -> 2160 | H7: =IF(('Daily Meter'!K11-'Daily Meter'!K10)<0,"0",'Daily Meter'!K11-'Daily Meter'!K10)*480 -> 1440 | I7: =IF(('Daily Meter'!L11-'Daily Meter'!L10)<0,"0",'Daily Meter'!L11-'Daily Meter'!L10)*480 -> 2188.8 | J7: =IF(('Daily Meter'!M11-'Daily Meter'!M10)<0,"0",'Daily Meter'!M11-'Daily Meter'!M10)*480 -> 5520 | K7: =IF(('Daily Meter'!B11-'Daily Meter'!B10)<0,"0",'Daily Meter'!B11-'Daily Meter'!B10)*284.34 -> 6369.216 | L7: =IF(('Daily Meter'!C11-'Daily Meter'!C10)<0,"0",'Daily Meter'!C11-'Daily Meter'!C10)*219.969 -> 40474.296 | M7: =IF(('Daily Meter'!N11-'Daily Meter'!N10)<0,"0",'Daily Meter'!N11-'Daily Meter'!N10)*3.7 -> 523.55 | N7: =Total!M7 -> 396
A8: 25hours Dubai One Central | B8: =B7+1 -> 7 | C8: 3 | D8: 2024 | E8: =IF(('Daily Meter'!H12-'Daily Meter'!H11)<0,"0",'Daily Meter'!H12-'Daily Meter'!H11)*480 -> 3456 | F8: =IF(('Daily Meter'!I12-'Daily Meter'!I11)<0,"0",'Daily Meter'!I12-'Daily Meter'!I11)*480 -> 2208 | G8: =IF(('Daily Meter'!J12-'Daily Meter'!J11)<0,"0",'Daily Meter'!J12-'Daily Meter'!J11)*480 -> 2064 | H8: =IF(('Daily Meter'!K12-'Daily Meter'!K11)<0,"0",'Daily Meter'!K12-'Daily Meter'!K11)*480 -> 1344 | I8: =IF(('Daily Meter'!L12-'Daily Meter'!L11)<0,"0",'Daily Meter'!L12-'Daily Meter'!L11)*480 -> 2160 | J8: =IF(('Daily Meter'!M12-'Daily Meter'!M11)<0,"0",'Daily Meter'!M12-'Daily Meter'!M11)*480 -> 5424 | K8: =IF(('Daily Meter'!B12-'Daily Meter'!B11)<0,"0",'Daily Meter'!B12-'Daily Meter'!B11)*284.34 -> 6227.046 | L8: =IF(('Daily Meter'!C12-'Daily Meter'!C11)<0,"0",'Daily Meter'!C12-'Daily Meter'!C11)*219.969 -> 35854.947 | M8: =IF(('Daily Meter'!N12-'Daily Meter'!N11)<0,"0",'Daily Meter'!N12-'Daily Meter'!N11)*3.7 -> 504.31 | N8: =Total!M8 -> 401
A9: 25hours Dubai One Central | B9: =B8+1 -> 8 | C9: 3 | D9: 2024 | E9: =IF(('Daily Meter'!H13-'Daily Meter'!H12)<0,"0",'Daily Meter'!H13-'Daily Meter'!H12)*480 -> 3408 | F9: =IF(('Daily Meter'!I13-'Daily Meter'!I12)<0,"0",'Daily Meter'!I13-'Daily Meter'!I12)*480 -> 2160 | G9: =IF(('Daily Meter'!J13-'Daily Meter'!J12)<0,"0",'Daily Meter'!J13-'Daily Meter'!J12)*480 -> 2256 | H9: =IF(('Daily Meter'!K13-'Daily Meter'!K12)<0,"0",'Daily Meter'!K13-'Daily Meter'!K12)*480 -> 1440 | I9: =IF(('Daily Meter'!L13-'Daily Meter'!L12)<0,"0",'Daily Meter'!L13-'Daily Meter'!L12)*480 -> 2208 | J9: =IF(('Daily Meter'!M13-'Daily Meter'!M12)<0,"0",'Daily Meter'!M13-'Daily Meter'!M12)*480 -> 5616 | K9: =IF(('Daily Meter'!B13-'Daily Meter'!B12)<0,"0",'Daily Meter'!B13-'Daily Meter'!B12)*284.34 -> 6113.31 | L9: =IF(('Daily Meter'!C13-'Daily Meter'!C12)<0,"0",'Daily Meter'!C13-'Daily Meter'!C12)*219.969 -> 41574.141 | M9: =IF(('Daily Meter'!N13-'Daily Meter'!N12)<0,"0",'Daily Meter'!N13-'Daily Meter'!N12)*3.7 -> 489.88 | N9: =Total!M9 -> 318
A10: 25hours Dubai One Central | B10: =B9+1 -> 9 | C10: 3 | D10: 2024 | E10: =IF(('Daily Meter'!H14-'Daily Meter'!H13)<0,"0",'Daily Meter'!H14-'Daily Meter'!H13)*480 -> 3552 | F10: =IF(('Daily Meter'!I14-'Daily Meter'!I13)<0,"0",'Daily Meter'!I14-'Daily Meter'!I13)*480 -> 2208 | G10: =IF(('Daily Meter'!J14-'Daily Meter'!J13)<0,"0",'Daily Meter'!J14-'Daily Meter'!J13)*480 -> 2208 | H10: =IF(('Daily Meter'!K14-'Daily Meter'!K13)<0,"0",'Daily Meter'!K14-'Daily Meter'!K13)*480 -> 1344 | I10: =IF(('Daily Meter'!L14-'Daily Meter'!L13)<0,"0",'Daily Meter'!L14-'Daily Meter'!L13)*480 -> 2208 | J10: =IF(('Daily Meter'!M14-'Daily Meter'!M13)<0,"0",'Daily Meter'!M14-'Daily Meter'!M13)*480 -> 5808 | K10: =IF(('Daily Meter'!B14-'Daily Meter'!B13)<0,"0",'Daily Meter'!B14-'Daily Meter'!B13)*284.34 -> 8046.822 | L10: =IF(('Daily Meter'!C14-'Daily Meter'!C13)<0,"0",'Daily Meter'!C14-'Daily Meter'!C13)*219.969 -> 50372.901 | M10: =IF(('Daily Meter'!N14-'Daily Meter'!N13)<0,"0",'Daily Meter'!N14-'Daily Meter'!N13)*3.7 -> 577.57 | N10: =Total!M10 -> 251
A11: 25hours Dubai One Central | B11: =B10+1 -> 10 | C11: 3 | D11: 2024 | E11: =IF(('Daily Meter'!H15-'Daily Meter'!H14)<0,"0",'Daily Meter'!H15-'Daily Meter'!H14)*480 -> 3504 | F11: =IF(('Daily Meter'!I15-'Daily Meter'!I14)<0,"0",'Daily Meter'!I15-'Daily Meter'!I14)*480 -> 2064 | G11: =IF(('Daily Meter'!J15-'Daily Meter'!J14)<0,"0",'Daily Meter'!J15-'Daily Meter'!J14)*480 -> 2160 | H11: =IF(('Daily Meter'!K15-'Daily Meter'!K14)<0,"0",'Daily Meter'!K15-'Daily Meter'!K14)*480 -> 1488 | I11: =IF(('Daily Meter'!L15-'Daily Meter'!L14)<0,"0",'Daily Meter'!L15-'Daily Meter'!L14)*480 -> 2304 | J11: =IF(('Daily Meter'!M15-'Daily Meter'!M14)<0,"0",'Daily Meter'!M15-'Daily Meter'!M14)*480 -> 5616 | K11: =IF(('Daily Meter'!B15-'Daily Meter'!B14)<0,"0",'Daily Meter'!B15-'Daily Meter'!B14)*284.34 -> 5800.536 | L11: =IF(('Daily Meter'!C15-'Daily Meter'!C14)<0,"0",'Daily Meter'!C15-'Daily Meter'!C14)*219.969 -> 43773.831 | M11: =IF(('Daily Meter'!N15-'Daily Meter'!N14)<0,"0",'Daily Meter'!N15-'Daily Meter'!N14)*3.7 -> 481 | N11: =Total!M11 -> 171
A12: 25hours Dubai One Central | B12: =B11+1 -> 11 | C12: 3 | D12: 2024 | E12: =IF(('Daily Meter'!H16-'Daily Meter'!H15)<0,"0",'Daily Meter'!H16-'Daily Meter'!H15)*480 -> 3456 | F12: =IF(('Daily Meter'!I16-'Daily Meter'!I15)<0,"0",'Daily Meter'!I16-'Daily Meter'!I15)*480 -> 1920 | G12: =IF(('Daily Meter'!J16-'Daily Meter'!J15)<0,"0",'Daily Meter'!J16-'Daily Meter'!J15)*480 -> 2016 | H12: =IF(('Daily Meter'!K16-'Daily Meter'!K15)<0,"0",'Daily Meter'!K16-'Daily Meter'!K15)*480 -> 1248 | I12: =IF(('Daily Meter'!L16-'Daily Meter'!L15)<0,"0",'Daily Meter'!L16-'Daily Meter'!L15)*480 -> 2160 | J12: =IF(('Daily Meter'!M16-'Daily Meter'!M15)<0,"0",'Daily Meter'!M16-'Daily Meter'!M15)*480 -> 5568 | K12: =IF(('Daily Meter'!B16-'Daily Meter'!B15)<0,"0",'Daily Meter'!B16-'Daily Meter'!B15)*284.34 -> 6141.744 | L12: =IF(('Daily Meter'!C16-'Daily Meter'!C15)<0,"0",'Daily Meter'!C16-'Daily Meter'!C15)*219.969 -> 35634.978 | M12: =IF(('Daily Meter'!N16-'Daily Meter'!N15)<0,"0",'Daily Meter'!N16-'Daily Meter'!N15)*3.7 -> 431.42 | N12: =Total!M12 -> 177
A13: 25hours Dubai One Central | B13: =B12+1 -> 12 | C13: 3 | D13: 2024 | E13: =IF(('Daily Meter'!H17-'Daily Meter'!H16)<0,"0",'Daily Meter'!H17-'Daily Meter'!H16)*480 -> 3312 | F13: =IF(('Daily Meter'!I17-'Daily Meter'!I16)<0,"0",'Daily Meter'!I17-'Daily Meter'!I16)*480 -> 1968 | G13: =IF(('Daily Meter'!J17-'Daily Meter'!J16)<0,"0",'Daily Meter'!J17-'Daily Meter'!J16)*480 -> 2016 | H13: =IF(('Daily Meter'!K17-'Daily Meter'!K16)<0,"0",'Daily Meter'!K17-'Daily Meter'!K16)*480 -> 1296 | I13: =IF(('Daily Meter'!L17-'Daily Meter'!L16)<0,"0",'Daily Meter'!L17-'Daily Meter'!L16)*480 -> 2208 | J13: =IF(('Daily Meter'!M17-'Daily Meter'!M16)<0,"0",'Daily Meter'!M17-'Daily Meter'!M16)*480 -> 5712 | K13: =IF(('Daily Meter'!B17-'Daily Meter'!B16)<0,"0",'Daily Meter'!B17-'Daily Meter'!B16)*284.34 -> 6084.876 | L13: =IF(('Daily Meter'!C17-'Daily Meter'!C16)<0,"0",'Daily Meter'!C17-'Daily Meter'!C16)*219.969 -> 30135.753 | M13: =IF(('Daily Meter'!N17-'Daily Meter'!N16)<0,"0",'Daily Meter'!N17-'Daily Meter'!N16)*3.7 -> 394.05 | N13: =Total!M13 -> 178
A14: 25hours Dubai One Central | B14: =B13+1 -> 13 | C14: 3 | D14: 2024 | E14: =IF(('Daily Meter'!H18-'Daily Meter'!H17)<0,"0",'Daily Meter'!H18-'Daily Meter'!H17)*480 -> 3312 | F14: =IF(('Daily Meter'!I18-'Daily Meter'!I17)<0,"0",'Daily Meter'!I18-'Daily Meter'!I17)*480 -> 2016 | G14: =IF(('Daily Meter'!J18-'Daily Meter'!J17)<0,"0",'Daily Meter'!J18-'Daily Meter'!J17)*480 -> 2064 | H14: =IF(('Daily Meter'!K18-'Daily Meter'!K17)<0,"0",'Daily Meter'!K18-'Daily Meter'!K17)*480 -> 1248 | I14: =IF(('Daily Meter'!L18-'Daily Meter'!L17)<0,"0",'Daily Meter'!L18-'Daily Meter'!L17)*480 -> 2208 | J14: =IF(('Daily Meter'!M18-'Daily Meter'!M17)<0,"0",'Daily Meter'!M18-'Daily Meter'!M17)*480 -> 5664 | K14: =IF(('Daily Meter'!B18-'Daily Meter'!B17)<0,"0",'Daily Meter'!B18-'Daily Meter'!B17)*284.34 -> 6056.442 | L14: =IF(('Daily Meter'!C18-'Daily Meter'!C17)<0,"0",'Daily Meter'!C18-'Daily Meter'!C17)*219.969 -> 35854.947 | M14: =IF(('Daily Meter'!N18-'Daily Meter'!N17)<0,"0",'Daily Meter'!N18-'Daily Meter'!N17)*3.7 -> 430.68 | N14: =Total!M14 -> 155
... A30: 25hours Dubai One Central | B30: =B29+1 -> 29 | C30: 3 | D30: 2024 | E30: =IF(('Daily Meter'!H34-'Daily Meter'!H33)<0,"0",'Daily Meter'!H34-'Daily Meter'!H33)*480 -> 0 | F30: =IF(('Daily Meter'!I34-'Daily Meter'!I33)<0,"0",'Daily Meter'!I34-'Daily Meter'!I33)*480 -> 0 | G30: =IF(('Daily Meter'!J34-'Daily Meter'!J33)<0,"0",'Daily Meter'!J34-'Daily Meter'!J33)*480 -> 0 | H30: =IF(('Daily Meter'!K34-'Daily Meter'!K33)<0,"0",'Daily Meter'!K34-'Daily Meter'!K33)*480 -> 0 | I30: =IF(('Daily Meter'!L34-'Daily Meter'!L33)<0,"0",'Daily Meter'!L34-'Daily Meter'!L33)*480 -> 0 | J30: =IF(('Daily Meter'!M34-'Daily Meter'!M33)<0,"0",'Daily Meter'!M34-'Daily Meter'!M33)*480 -> 0 | K30: =IF(('Daily Meter'!B34-'Daily Meter'!B33)<0,"0",'Daily Meter'!B34-'Daily Meter'!B33)*284.34 -> 0 | L30: =IF(('Daily Meter'!C34-'Daily Meter'!C33)<0,"0",'Daily Meter'!C34-'Daily Meter'!C33)*219.969 -> 0 | M30: =IF(('Daily Meter'!N34-'Daily Meter'!N33)<0,"0",'Daily Meter'!N34-'Daily Meter'!N33)*3.7 -> 0 | N30: =Total!M30 -> 0
B31: 30 | C31: 3 | D31: 2024 | E31: =IF(('Daily Meter'!H35-'1'!D42)<0,"0",'Daily Meter'!H35-'1'!D42)*480 -> 0 | F31: =IF(('Daily Meter'!I35-'1'!D43)<0,"0",'Daily Meter'!I35-'1'!D43)*480 -> 0 | G31: =IF(('Daily Meter'!J35-'1'!D44)<0,"0",'Daily Meter'!J35-'1'!D44)*480 -> 0 | H31: =IF(('Daily Meter'!K35-'1'!D45)<0,"0",'Daily Meter'!K35-'1'!D45)*480 -> 0 | I31: =IF(('Daily Meter'!L35-'1'!D46)<0,"0",'Daily Meter'!L35-'1'!D46)*480 -> 0 | J31: =IF(('Daily Meter'!M35-'1'!D47)<0,"0",'Daily Meter'!M35-'1'!D47)*480 -> 0 | K31: =IF(('Daily Meter'!B35-'1'!D36)<0,"0",'Daily Meter'!B35-'1'!D36)*284.34 -> 0 | L31: =IF(('Daily Meter'!C35-'1'!D39)<0,"0",'Daily Meter'!C35-'1'!D39)*219.969 -> 0 | M31: =IF(('Daily Meter'!N35-'1'!D51)<0,"0",'Daily Meter'!N35-'1'!D51)*3.7 -> 0 | N31: =Total!M31 -> 0
B32: 31 | C32: 3 | D32: 2024 | E32: =IF(('Daily Meter'!H36-'Daily Meter'!H35)<0,"0",'Daily Meter'!H36-'Daily Meter'!H35)*480 -> 0 | F32: =IF(('Daily Meter'!I36-'Daily Meter'!I35)<0,"0",'Daily Meter'!I36-'Daily Meter'!I35)*480 -> 0 | G32: =IF(('Daily Meter'!J36-'Daily Meter'!J35)<0,"0",'Daily Meter'!J36-'Daily Meter'!J35)*480 -> 0 | H32: =IF(('Daily Meter'!K36-'Daily Meter'!K35)<0,"0",'Daily Meter'!K36-'Daily Meter'!K35)*480 -> 0 | I32: =IF(('Daily Meter'!L36-'Daily Meter'!L35)<0,"0",'Daily Meter'!L36-'Daily Meter'!L35)*480 -> 0 | J32: =IF(('Daily Meter'!M36-'Daily Meter'!M35)<0,"0",'Daily Meter'!M36-'Daily Meter'!M35)*480 -> 0 | K32: =IF(('Daily Meter'!B36-'Daily Meter'!B35)<0,"0",'Daily Meter'!B36-'Daily Meter'!B35)*284.34 -> 0 | L32: =IF(('Daily Meter'!C36-'Daily Meter'!C35)<0,"0",'Daily Meter'!C36-'Daily Meter'!C35)*219.969 -> 0 | M32: =IF(('Daily Meter'!N36-'Daily Meter'!N35)<0,"0",'Daily Meter'!N36-'Daily Meter'!N35)*3.7 -> 0 | N32: =Total!M32 -> 0

Sheet Daily Meter
A1: March 2024 UTILITY READING | Q1: 1st
B2: CHILLED WATER | C2: WATER | H2: ELECTRICITY | N2: GAS | O2: OCC.
A3: Date | B3: BTU Meter | C3: Meter 1 | D3: Meter 2 | F3: Meter 3 | H3: Meter 1 | I3: Meter 2 | J3: Meter 3 | K3: Meter 4 | L3: Meter 6 | M3: Meter 7
B4: P103FF043BC | C4: 18E0300032 | D4: 18E0300060 | F4: 18E0300057 | H4: 6065253 | I4: 6065255 | J4: 6065259 | K4: 6065262 | L4: 6065269 | M4: 6065283 | N4: 77092321/2019 | O4: %
B5: 4am | C5: 4am | D5: 4am | E5: 4am | F5: 4am | G5: 4am | H5: 4am | I5: 4am | J5: 4am | K5: 4am | L5: 4am | M5: 4am | N5: 4am | O5: DAILY
A6: 1 | B6: 54738.5 | C6: 215317 | H6: 6984.9 | I6: 4219.3 | J6: 4506.4 | K6: 2532 | L6: 5845.2 | M6: 15710.7 | N6: 98432.8 | O6: 85.25
A7: 2 | B7: 54757.5 | C7: 215536 | H7: 6992.1 | I7: 4224.3 | J7: 4511.2 | K7: 2535 | L7: 5849.7 | M7: 15722 | N7: 98591.4 | O7: 76.96
A8: 3 | B8: 54776.3 | C8: 215748 | H8: 6999.3 | I8: 4229.1 | J8: 4516.3 | K8: 2537.9 | L8: 5854.4 | M8: 15734.1 | N8: 98707.8 | O8: 81.8
A9: 4 | B9: 54795.3 | C9: 215927 | H9: 7006.2 | I9: 4233.9 | J9: 4520.9 | K9: 2540.8 | L9: 5858.9 | M9: 15745.9 | N9: 98864.8 | O9: 88.94
A10: 5 | B10: 54815.8 | C10: 216132 | H10: 7013 | I10: 4238.6 | J10: 4525.5 | K10: 2543.7 | L10: 5863.54 | M10: 15757.8 | N10: 99013.2 | O10: 94.93
A11: 6 | B11: 54838.2 | C11: 216316 | H11: 7020.2 | I11: 4243.3 | J11: 4530 | K11: 2546.7 | L11: 5868.1 | M11: 15769.3 | N11: 99154.7 | O11: 91.47
A12: 7 | B12: 54860.1 | C12: 216479 | H12: 7027.4 | I12: 4247.9 | J12: 4534.3 | K12: 2549.5 | L12: 5872.6 | M12: 15780.6 | N12: 99291 | O12: 92.4
A13: 8 | B13: 54881.6 | C13: 216668 | H13: 7034.5 | I13: 4252.4 | J13: 4539 | K13: 2552.5 | L13: 5877.2 | M13: 15792.3 | N13: 99423.4 | O13: 73.5
A14: 9 | B14: 54909.9 | C14: 216897 | H14: 7041.9 | I14: 4257 | J14: 4543.6 | K14: 2555.3 | L14: 5881.8 | M14: 15804.4 | N14: 99579.5 | O14: 58.06
A15: 10 | B15: 54930.3 | C15: 217096 | H15: 7049.2 | I15: 4261.3 | J15: 4548.1 | K15: 2558.4 | L15: 5886.6 | M15: 15816.1 | N15: 99709.5 | O15: 39.63
A16: 11 | B16: 54951.9 | C16: 217258 | H16: 7056.4 | I16: 4265.3 | J16: 4552.3 | K16: 2561 | L16: 5891.1 | M16: 15827.7 | N16: 99826.1 | O16: 41.01
A17: 12 | B17: 54973.3 | C17: 217395 | H17: 7063.3 | I17: 4269.4 | J17: 4556.5 | K17: 2563.7 | L17: 5895.7 | M17: 15839.6 | N17: 99932.6 | O17: 41.24
... A32: 27 | B32: 55428.8 | C32: 220050 | H32: 7169.2 | I32: 4331.6 | J32: 4620.3 | K32: 2605.5 | L32: 5964.5 | M32: 16023.6 | N32: 101887.5 | O32: 56.45
A33: 28 | B33: 55454 | C33: 220230 | H33: 7176.6 | I33: 4335.8 | J33: 4625.1 | K33: 2608.3 | L33: 5969.2 | M33: 16035.9 | N33: 102023.4
A34: 29
A35: 30
A36: 31
O37: =AVERAGE(O6:O34) -> 61.05
Q38: engr123.

Sheet Sheet1

Sheet 1
A1: ENGINEERING DEPARTMENT | H1: daily reading
A2: UTILITY CONSUMPTION SHEET
B3: MARCH 2024 | C3: 1 | D3: % OCCUPANCY: | E3: ='Daily Meter'!O6 -> 85.25
A4: SR.NO | B4: ITEM MEASURED | D4: Previous Reading | E4: 4 AM Reading | F4: 24hrs CONSUMPTION | G4: Cost
D5: FEBRUARY 29
A6: 1 | B6: DISTRICT COOLING PLANT
B7: Chilled Water | C7: MWH | D7: 54717.5 | E7: ='Daily Meter'!B6 -> 54738.5 | F7: =E7-D7 -> 21
C8: TR | F8: =F7*284.34 -> 5971.14 | G8: =F8*0.63 -> 3761.8182
A9: III | B9: WATER METERS
B10: Main DEWA Meter | C10: m3 | D10: 215091 | E10: ='Daily Meter'!C6 -> 215317 | F10: =E10-D10 -> 226
B11: Imperial Gallon = m³ x 219.969 | C11: IG | F11: =F10*219.969 -> 49712.994 | G11: =F11*0.06 -> 2982.7796
A12: IV | B12: ELECTRICAL METERS
A13: 1 | B13: Meter 1 - 06065253 | C13: kW x 480 | D13: 6977.9 | E13: ='Daily Meter'!H6 -> 6984.9 | F13: =(E13-D13)*480 -> 3360
A14: 2 | B14: Meter 2 - 06065255 | C14: kW x 480 | D14: 4214.4 | E14: ='Daily Meter'!I6 -> 4219.3 | F14: =(E14-D14)*480 -> 2352
A15: 3 | B15: Meter 3 - 06065259 | C15: kW x 480 | D15: 4501.6 | E15: ='Daily Meter'!J6 -> 4506.4 | F15: =(E15-D15)*480 -> 2304
A16: 4 | B16: Meter 4 - 06065262 | C16: kW x 480 | D16: 2529.1 | E16: ='Daily Meter'!K6 -> 2532 | F16: =(E16-D16)*480 -> 1392
A17: 5 | B17: Meter 6 - 06065269 | C17: kW x 480 | D17: 5840.6 | E17: ='Daily Meter'!L6 -> 5845.2 | F17: =(E17-D17)*480 -> 2208
A18: 6 | B18: Meter 7 - 06065283 | C18: kW x 480 | D18: 15699 | E18: ='Daily Meter'!M6 -> 15710.7 | F18: =(E18-D18)*480 -> 5616
B19: TOTAL ELECTRICAL CONS.(kWh) | F19: =SUM(F13:F18) -> 17232 | G19: =F19*0.43 -> 7409.76
A21: V | B21: GAS CONSUMPTION
A22: 1 | B22: MAIN LPG METER | C22: M3 | D22: 98271.7 | E22: ='Daily Meter'!N6 -> 98432.8 | F22: =E22-D22 -> 161.1
B23: L = m³ x 3.70 | C23: L | F23: =F22*3.7 -> 596.07 | G23: =F23*2.5 -> 1490.175
D26: Summary of Daily Hotel consumption
D27: Item measured | E27: Units | F27: Consumption | G27: AED
D28: Chilled water | E28: TR | F28: =F8 -> 5971.14 | G28: =G8 -> 3761.8182
D29: DEWA Water | E29: imp. Gallon | F29: =F11 -> 49712.994 | G29: =G11 -> 2982.7796
D30: Electricity | E30: kwh | F30: =F19 -> 17232 | G30: =G19 -> 7409.76
D31: Gas | E31: m3 | F31: =F22 -> 161.1 | G31: =G23 -> 1490.175
F32: Total cost | G32: =SUM(G28:G31) -> 15644.533

Sheet 2
A1: ENGINEERING DEPARTMENT | H1: daily reading
A2: UTILITY CONSUMPTION SHEET
B3: ='1'!B3 -> MARCH 2024 | C3: 2 | D3: % OCCUPANCY: | E3: ='Daily Meter'!O6 -> 85.25
A4: SR.NO | B4: ITEM MEASURED | D4: Previous Reading | E4: 4 AM Reading | F4: 24hrs CONSUMPTION | G4: Cost
A6: 1 | B6: DISTRICT COOLING PLANT
B7: Chilled Water | C7: MWH | D7: ='1'!E7 -> 54738.5 | E7: ='Daily Meter'!B7 -> 54757.5 | F7: =E7-D7 -> 19
C8: TR | F8: =F7*284.34 -> 5402.46 | G8: =F8*0.63 -> 3403.5498
A9: III | B9: WATER METERS
B10: Main DEWA Meter | C10: m3 | D10: ='1'!E10 -> 215317 | E10: ='Daily Meter'!C7 -> 215536 | F10: =E10-D10 -> 219
B11: Imperial Gallon = m³ x 219.969 | C11: IG | F11: =F10*219.969 -> 48173.211 | G11: =F11*0.06 -> 2890.3927
A12: IV | B12: ELECTRICAL METERS
A13: 1 | B13: Meter 1 - 06065253 | C13: kW x 480 | D13: ='1'!E13 -> 6984.9 | E13: ='Daily Meter'!H7 -> 6992.1 | F13: =(E13-D13)*480 -> 3456
A14: 2 | B14: Meter 2 - 06065255 | C14: kW x 480 | D14: ='1'!E14 -> 4219.3 | E14: ='Daily Meter'!I7 -> 4224.3 | F14: =(E14-D14)*480 -> 2400
A15: 3 | B15: Meter 3 - 06065259 | C15: kW x 480 | D15: ='1'!E15 -> 4506.4 | E15: ='Daily Meter'!J7 -> 4511.2 | F15: =(E15-D15)*480 -> 2304
A16: 4 | B16: Meter 4 - 06065262 | C16: kW x 480 | D16: ='1'!E16 -> 2532 | E16: ='Daily Meter'!K7 -> 2535 | F16: =(E16-D16)*480 -> 1440
A17: 5 | B17: Meter 6 - 06065269 | C17: kW x 480 | D17: ='1'!E17 -> 5845.2 | E17: ='Daily Meter'!L7 -> 5849.7 | F17: =(E17-D17)*480 -> 2160
A18: 6 | B18: Meter 7 - 06065283 | C18: kW x 480 | D18: ='1'!E18 -> 15710.7 | E18: ='Daily Meter'!M7 -> 15722 | F18: =(E18-D18)*480 -> 5424
B19: TOTAL ELECTRICAL CONS.(kWh) | F19: =SUM(F13:F18) -> 17184 | G19: =F19*0.43 -> 7389.12
A21: V | B21: GAS CONSUMPTION
A22: 1 | B22: MAIN LPG METER | C22: M3 | D22: ='1'!E22 -> 98432.8 | E22: ='Daily Meter'!N7 -> 98591.4 | F22: =E22-D22 -> 158.6
B23: L = m³ x 3.70 | C23: L | F23: =F22*3.7 -> 586.82 | G23: =F23*2.5 -> 1467.05
D26: Summary of Daily Hotel consumption
D27: Item measured | E27: Units | F27: Consumption | G27: AED
D28: Chilled water | E28: TR | F28: =F8 -> 5402.46 | G28: =G8 -> 3403.5498
D29: DEWA Water | E29: imp. Gallon | F29: =F11 -> 48173.211 | G29: =G11 -> 2890.3927
D30: Electricity | E30: kwh | F30: =F19 -> 17184 | G30: =G19 -> 7389.12
D31: Gas | E31: m3 | F31: =F22 -> 158.6 | G31: =G23 -> 1467.05
F32: Total cost | G32: =SUM(G28:G31) -> 15150.112

Sheet 3
A1: ENGINEERING DEPARTMENT | H1: daily reading
A2: UTILITY CONSUMPTION SHEET
B3: ='1'!B3 -> MARCH 2024 | C3: 3 | D3: % OCCUPANCY: | E3: ='Daily Meter'!O8 -> 81.8
A4: SR.NO | B4: ITEM MEASURED | D4: Previous Reading | E4: 4 AM Reading | F4: 24hrs CONSUMPTION | G4: Cost
A6: 1 | B6: DISTRICT COOLING PLANT
B7: Chilled Water | C7: MWH | D7: ='2'!E7 -> 54757.5 | E7: ='Daily Meter'!B8 -> 54776.3 | F7: =E7-D7 -> 18.8
C8: TR | F8: =F7*284.34 -> 5345.592 | G8: =F8*0.63 -> 3367.723
A9: III | B9: WATER METERS
B10: Main DEWA Meter | C10: m3 | D10: ='2'!E10 -> 215536 | E10: ='Daily Meter'!C8 -> 215748 | F10: =E10-D10 -> 212
B11: Imperial Gallon = m³ x 219.969 | C11: IG | F11: =F10*219.969 -> 46633.428 | G11: =F11*0.06 -> 2798.0057
A12: IV | B12: ELECTRICAL METERS
A13: 1 | B13: Meter 1 - 06065253 | C13: kW x 480 | D13: ='2'!E13 -> 6992.1 | E13: ='Daily Meter'!H8 -> 6999.3 | F13: =(E13-D13)*480 -> 3456
A14: 2 | B14: Meter 2 - 06065255 | C14: kW x 480 | D14: ='2'!E14 -> 4224.3 | E14: ='Daily Meter'!I8 -> 4229.1 | F14: =(E14-D14)*480 -> 2304
A15: 3 | B15: Meter 3 - 06065259 | C15: kW x 480 | D15: ='2'!E15 -> 4511.2 | E15: ='Daily Meter'!J8 -> 4516.3 | F15: =(E15-D15)*480 -> 2448
A16: 4 | B16: Meter 4 - 06065262 | C16: kW x 480 | D16: ='2'!E16 -> 2535 | E16: ='Daily Meter'!K8 -> 2537.9 | F16: =(E16-D16)*480 -> 1392
A17: 5 | B17: Meter 6 - 06065269 | C17: kW x 480 | D17: ='2'!E17 -> 5849.7 | E17: ='Daily Meter'!L8 -> 5854.4 | F17: =(E17-D17)*480 -> 2256
A18: 6 | B18: Meter 7 - 06065283 | C18: kW x 480 | D18: ='2'!E18 -> 15722 | E18: ='Daily Meter'!M8 -> 15734.1 | F18: =(E18-D18)*480 -> 5808
B19: TOTAL ELECTRICAL CONS.(kWh) | F19: =SUM(F13:F18) -> 17664 | G19: =F19*0.43 -> 7595.52
A21: V | B21: GAS CONSUMPTION
A22: 1 | B22: MAIN LPG METER | C22: M3 | D22: ='2'!E22 -> 98591.4 | E22: ='Daily Meter'!N8 -> 98707.8 | F22: =E22-D22 -> 116.4
B23: L = m³ x 3.70 | C23: L | F23: =F22*3.7 -> 430.68 | G23: =F23*2.5 -> 1076.7
D26: Summary of Daily Hotel consumption
D27: Item measured | E27: Units | F27: Consumption | G27: AED
D28: Chilled water | E28: TR | F28: =F8 -> 5345.592 | G28: =G8 -> 3367.723
D29: DEWA Water | E29: imp. Gallon | F29: =F11 -> 46633.428 | G29: =G11 -> 2798.0057
D30: Electricity | E30: kwh | F30: =F19 -> 17664 | G30: =G19 -> 7595.52
D31: Gas | E31: m3 | F31: =F22 -> 116.4 | G31: =G23 -> 1076.7
F32: Total cost | G32: =SUM(G28:G31) -> 14837.949

Sheet 4
A1: ENGINEERING DEPARTMENT | H1: daily reading
A2: UTILITY CONSUMPTION SHEET
B3: ='1'!B3 -> MARCH 2024 | C3: 4 | D3: % OCCUPANCY: | E3: ='Daily Meter'!O9 -> 88.94
A4: SR.NO | B4: ITEM MEASURED | D4: Previous Reading | E4: 4 AM Reading | F4: 24hrs CONSUMPTION | G4: Cost
A6: 1 | B6: DISTRICT COOLING PLANT
B7: Chilled Water | C7: MWH | D7: ='3'!E7 -> 54776.3 | E7: ='Daily Meter'!B9 -> 54795.3 | F7: =E7-D7 -> 19
C8: TR | F8: =F7*284.34 -> 5402.46 | G8: =F8*0.63 -> 3403.5498
A9: III | B9: WATER METERS
B10: Main DEWA Meter | C10: m3 | D10: ='3'!E10 -> 215748 | E10: ='Daily Meter'!C9 -> 215927 | F10: =E10-D10 -> 179
B11: Imperial Gallon = m³ x 219.969 | C11: IG | F11: =F10*219.969 -> 39374.451 | G11: =F11*0.06 -> 2362.4671
A12: IV | B12: ELECTRICAL METERS
A13: 1 | B13: Meter 1 - 06065253 | C13: kW x 480 | D13: ='3'!E13 -> 6999.3 | E13: ='Daily Meter'!H9 -> 7006.2 | F13: =(E13-D13)*480 -> 3312
A14: 2 | B14: Meter 2 - 06065255 | C14: kW x 480 | D14: ='3'!E14 -> 4229.1 | E14: ='Daily Meter'!I9 -> 4233.9 | F14: =(E14-D14)*480 -> 2304
A15: 3 | B15: Meter 3 - 06065259 | C15: kW x 480 | D15: ='3'!E15 -> 4516.3 | E15: ='Daily Meter'!J9 -> 4520.9 | F15: =(E15-D15)*480 -> 2208
A16: 4 | B16: Meter 4 - 06065262 | C16: kW x 480 | D16: ='3'!E16 -> 2537.9 | E16: ='Daily Meter'!K9 -> 2540.8 | F16: =(E16-D16)*480 -> 1392
A17: 5 | B17: Meter 6 - 06065269 | C17: kW x 480 | D17: ='3'!E17 -> 5854.4 | E17: ='Daily Meter'!L9 -> 5858.9 | F17: =(E17-D17)*480 -> 2160
A18: 6 | B18: Meter 7 - 06065283 | C18: kW x 480 | D18: ='3'!E18 -> 15734.1 | E18: ='Daily Meter'!M9 -> 15745.9 | F18: =(E18-D18)*480 -> 5664
B19: TOTAL ELECTRICAL CONS.(kWh) | F19: =SUM(F13:F18) -> 17040 | G19: =F19*0.43 -> 7327.2
A21: V | B21: GAS CONSUMPTION
A22: 1 | B22: MAIN LPG METER | C22: M3 | D22: ='3'!E22 -> 98707.8 | E22: ='Daily Meter'!N9 -> 98864.8 | F22: =E22-D22 -> 157
B23: L = m³ x 3.70 | C23: L | F23: =F22*3.7 -> 580.9 | G23: =F23*2.5 -> 1452.25
D26: Summary of Daily Hotel consumption
D27: Item measured | E27: Units | F27: Consumption | G27: AED
D28: Chilled water | E28: TR | F28: =F8 -> 5402.46 | G28: =G8 -> 3403.5498
D29: DEWA Water | E29: imp. Gallon | F29: =F11 -> 39374.451 | G29: =G11 -> 2362.4671
D30: Electricity | E30: kwh | F30: =F19 -> 17040 | G30: =G19 -> 7327.2
D31: Gas | E31: m3 | F31: =F22 -> 157 | G31: =G23 -> 1452.25
F32: Total cost | G32: =SUM(G28:G31) -> 14545.467

Sheet 5
A1: ENGINEERING DEPARTMENT | H1: daily reading
A2: UTILITY CONSUMPTION SHEET
B3: ='1'!B3 -> MARCH 2024 | C3: 5 | D3: % OCCUPANCY: | E3: ='Daily Meter'!O10 -> 94.93
A4: SR.NO | B4: ITEM MEASURED | D4: Previous Reading | E4: 4 AM Reading | F4: 24hrs CONSUMPTION | G4: Cost
A6: 1 | B6: DISTRICT COOLING PLANT
B7: Chilled Water | C7: MWH | D7: ='4'!E7 -> 54795.3 | E7: ='Daily Meter'!B10 -> 54815.8 | F7: =E7-D7 -> 20.5
C8: TR | F8: =F7*284.34 -> 5828.97 | G8: =F8*0.63 -> 3672.2511
A9: III | B9: WATER METERS
B10: Main DEWA Meter | C10: m3 | D10: ='4'!E10 -> 215927 | E10: ='Daily Meter'!C10 -> 216132 | F10: =E10-D10 -> 205
B11: Imperial Gallon = m³ x 219.969 | C11: IG | F11: =F10*219.969 -> 45093.645 | G11: =F11*0.06 -> 2705.6187
A12: IV | B12: ELECTRICAL METERS
A13: 1 | B13: Meter 1 - 06065253 | C13: kW x 480 | D13: ='4'!E13 -> 7006.2 | E13: ='Daily Meter'!H10 -> 7013 | F13: =(E13-D13)*480 -> 3264
A14: 2 | B14: Meter 2 - 06065255 | C14: kW x 480 | D14: ='4'!E14 -> 4233.9 | E14: ='Daily Meter'!I10 -> 4238.6 | F14: =(E14-D14)*480 -> 2256
A15: 3 | B15: Meter 3 - 06065259 | C15: kW x 480 | D15: ='4'!E15 -> 4520.9 | E15: ='Daily Meter'!J10 -> 4525.5 | F15: =(E15-D15)*480 -> 2208
A16: 4 | B16: Meter 4 - 06065262 | C16: kW x 480 | D16: ='4'!E16 -> 2540.8 | E16: ='Daily Meter'!K10 -> 2543.7 | F16: =(E16-D16)*480 -> 1392
A17: 5 | B17: Meter 6 - 06065269 | C17: kW x 480 | D17: ='4'!E17 -> 5858.9 | E17: ='Daily Meter'!L10 -> 5863.54 | F17: =(E17-D17)*480 -> 2227.2
A18: 6 | B18: Meter 7 - 06065283 | C18: kW x 480 | D18: ='4'!E18 -> 15745.9 | E18: ='Daily Meter'!M10 -> 15757.8 | F18: =(E18-D18)*480 -> 5712
B19: TOTAL ELECTRICAL CONS.(kWh) | F19: =SUM(F13:F18) -> 17059.2 | G19: =F19*0.43 -> 7335.456
A21: V | B21: GAS CONSUMPTION
A22: 1 | B22: MAIN LPG METER | C22: M3 | D22: ='4'!E22 -> 98864.8 | E22: ='Daily Meter'!N10 -> 99013.2 | F22: =E22-D22 -> 148.4
B23: L = m³ x 3.70 | C23: L | F23: =F22*3.7 -> 549.08 | G23: =F23*2.5 -> 1372.7
D26: Summary of Daily Hotel consumption
D27: Item measured | E27: Units | F27: Consumption | G27: AED
D28: Chilled water | E28: TR | F28: =F8 -> 5828.97 | G28: =G8 -> 3672.2511
D29: DEWA Water | E29: imp. Gallon | F29: =F11 -> 45093.645 | G29: =G11 -> 2705.6187
D30: Electricity | E30: kwh | F30: =F19 -> 17059.2 | G30: =G19 -> 7335.456
D31: Gas | E31: m3 | F31: =F22 -> 148.4 | G31: =G23 -> 1372.7
F32: Total cost | G32: =SUM(G28:G31) -> 15086.026

Sheet 6
A1: ENGINEERING DEPARTMENT | H1: daily reading
A2: UTILITY CONSUMPTION SHEET
B3: ='1'!B3 -> MARCH 2024 | C3: 6 | D3: % OCCUPANCY: | E3: ='Daily Meter'!O11 -> 91.47
A4: SR.NO | B4: ITEM MEASURED | D4: Previous Reading | E4: 4 AM Reading | F4: 24hrs CONSUMPTION | G4: Cost
A6: 1 | B6: DISTRICT COOLING PLANT
B7: Chilled Water | C7: MWH | D7: ='5'!E7 -> 54815.8 | E7: ='Daily Meter'!B11 -> 54838.2 | F7: =E7-D7 -> 22.4
C8: TR | F8: =F7*284.34 -> 6369.216 | G8: =F8*0.63 -> 4012.6061
A9: III | B9: WATER METERS
B10: Main DEWA Meter | C10: m3 | D10: ='5'!E10 -> 216132 | E10: ='Daily Meter'!C11 -> 216316 | F10: =E10-D10 -> 184
B11: Imperial Gallon = m³ x 219.969 | C11: IG | F11: =F10*219.969 -> 40474.296 | G11: =F11*0.06 -> 2428.4578
A12: IV | B12: ELECTRICAL METERS
A13: 1 | B13: Meter 1 - 06065253 | C13: kW x 480 | D13: ='5'!E13 -> 7013 | E13: ='Daily Meter'!H11 -> 7020.2 | F13: =(E13-D13)*480 -> 3456
A14: 2 | B14: Meter 2 - 06065255 | C14: kW x 480 | D14: ='5'!E14 -> 4238.6 | E14: ='Daily Meter'!I11 -> 4243.3 | F14: =(E14-D14)*480 -> 2256
A15: 3 | B15: Meter 3 - 06065259 | C15: kW x 480 | D15: ='5'!E15 -> 4525.5 | E15: ='Daily Meter'!J11 -> 4530 | F15: =(E15-D15)*480 -> 2160
A16: 4 | B16: Meter 4 - 06065262 | C16: kW x 480 | D16: ='5'!E16 -> 2543.7 | E16: ='Daily Meter'!K11 -> 2546.7 | F16: =(E16-D16)*480 -> 1440
A17: 5 | B17: Meter 6 - 06065269 | C17: kW x 480 | D17: ='5'!E17 -> 5863.54 | E17: ='Daily Meter'!L11 -> 5868.1 | F17: =(E17-D17)*480 -> 2188.8
A18: 6 | B18: Meter 7 - 06065283 | C18: kW x 480 | D18: ='5'!E18 -> 15757.8 | E18: ='Daily Meter'!M11 -> 15769.3 | F18: =(E18-D18)*480 -> 5520
B19: TOTAL ELECTRICAL CONS.(kWh) | F19: =SUM(F13:F18) -> 17020.8 | G19: =F19*0.43 -> 7318.944
A21: V | B21: GAS CONSUMPTION
A22: 1 | B22: MAIN LPG METER | C22: M3 | D22: ='5'!E22 -> 99013.2 | E22: ='Daily Meter'!N11 -> 99154.7 | F22: =E22-D22 -> 141.5
B23: L = m³ x 3.70 | C23: L | F23: =F22*3.7 -> 523.55 | G23: =F23*2.5 -> 1308.875
D26: Summary of Daily Hotel consumption
D27: Item measured | E27: Units | F27: Consumption | G27: AED
D28: Chilled water | E28: TR | F28: =F8 -> 6369.216 | G28: =G8 -> 4012.6061
D29: DEWA Water | E29: imp. Gallon | F29: =F11 -> 40474.296 | G29: =G11 -> 2428.4578
D30: Electricity | E30: kwh | F30: =F19 -> 17020.8 | G30: =G19 -> 7318.944
D31: Gas | E31: m3 | F31: =F22 -> 141.5 | G31: =G23 -> 1308.875
F32: Total cost | G32: =SUM(G28:G31) -> 15068.883

Sheet 7
A1: ENGINEERING DEPARTMENT | H1: daily reading
A2: UTILITY CONSUMPTION SHEET
B3: ='1'!B3 -> MARCH 2024 | C3: 7 | D3: % OCCUPANCY: | E3: ='Daily Meter'!O12 -> 92.4
A4: SR.NO | B4: ITEM MEASURED | D4: Previous Reading | E4: 4 AM Reading | F4: 24hrs CONSUMPTION | G4: Cost
A6: 1 | B6: DISTRICT COOLING PLANT
B7: Chilled Water | C7: MWH | D7: ='6'!E7 -> 54838.2 | E7: ='Daily Meter'!B12 -> 54860.1 | F7: =E7-D7 -> 21.9
C8: TR | F8: =F7*284.34 -> 6227.046 | G8: =F8*0.63 -> 3923.039
A9: III | B9: WATER METERS
B10: Main DEWA Meter | C10: m3 | D10: ='6'!E10 -> 216316 | E10: ='Daily Meter'!C12 -> 216479 | F10: =E10-D10 -> 163
B11: Imperial Gallon = m³ x 219.969 | C11: IG | F11: =F10*219.969 -> 35854.947 | G11: =F11*0.06 -> 2151.2968
A12: IV | B12: ELECTRICAL METERS
A13: 1 | B13: Meter 1 - 06065253 | C13: kW x 480 | D13: ='6'!E13 -> 7020.2 | E13: ='Daily Meter'!H12 -> 7027.4 | F13: =(E13-D13)*480 -> 3456
A14: 2 | B14: Meter 2 - 06065255 | C14: kW x 480 | D14: ='6'!E14 -> 4243.3 | E14: ='Daily Meter'!I12 -> 4247.9 | F14: =(E14-D14)*480 -> 2208
A15: 3 | B15: Meter 3 - 06065259 | C15: kW x 480 | D15: ='6'!E15 -> 4530 | E15: ='Daily Meter'!J12 -> 4534.3 | F15: =(E15-D15)*480 -> 2064
A16: 4 | B16: Meter 4 - 06065262 | C16: kW x 480 | D16: ='6'!E16 -> 2546.7 | E16: ='Daily Meter'!K12 -> 2549.5 | F16: =(E16-D16)*480 -> 1344
A17: 5 | B17: Meter 6 - 06065269 | C17: kW x 480 | D17: ='6'!E17 -> 5868.1 | E17: ='Daily Meter'!L12 -> 5872.6 | F17: =(E17-D17)*480 -> 2160
A18: 6 | B18: Meter 7 - 06065283 | C18: kW x 480 | D18: ='6'!E18 -> 15769.3 | E18: ='Daily Meter'!M12 -> 15780.6 | F18: =(E18-D18)*480 -> 5424
B19: TOTAL ELECTRICAL CONS.(kWh) | F19: =SUM(F13:F18) -> 16656 | G19: =F19*0.43 -> 7162.08
A21: V | B21: GAS CONSUMPTION
A22: 1 | B22: MAIN LPG METER | C22: M3 | D22: ='6'!E22 -> 99154.7 | E22: ='Daily Meter'!N12 -> 99291 | F22: =E22-D22 -> 136.3
B23: L = m³ x 3.70 | C23: L | F23: =F22*3.7 -> 504.31 | G23: =F23*2.5 -> 1260.775
D26: Summary of Daily Hotel consumption
D27: Item measured | E27: Units | F27: Consumption | G27: AED
D28: Chilled water | E28: TR | F28: =F8 -> 6227.046 | G28: =G8 -> 3923.039
D29: DEWA Water | E29: imp. Gallon | F29: =F11 -> 35854.947 | G29: =G11 -> 2151.2968
D30: Electricity | E30: kwh | F30: =F19 -> 16656 | G30: =G19 -> 7162.08
D31: Gas | E31: m3 | F31: =F22 -> 136.3 | G31: =G23 -> 1260.775
F32: Total cost | G32: =SUM(G28:G31) -> 14497.191

Sheet 8
A1: ENGINEERING DEPARTMENT | H1: daily reading
A2: UTILITY CONSUMPTION SHEET
B3: ='1'!B3 -> MARCH 2024 | C3: 8 | D3: % OCCUPANCY: | E3: ='Daily Meter'!O13 -> 73.5
A4: SR.NO | B4: ITEM MEASURED | D4: Previous Reading | E4: 4 AM Reading | F4: 24hrs CONSUMPTION | G4: Cost
A6: 1 | B6: DISTRICT COOLING PLANT
B7: Chilled Water | C7: MWH | D7: ='7'!E7 -> 54860.1 | E7: ='Daily Meter'!B13 -> 54881.6 | F7: =E7-D7 -> 21.5
C8: TR | F8: =F7*284.34 -> 6113.31 | G8: =F8*0.63 -> 3851.3853
A9: III | B9: WATER METERS
B10: Main DEWA Meter | C10: m3 | D10: ='7'!E10 -> 216479 | E10: ='Daily Meter'!C13 -> 216668 | F10: =E10-D10 -> 189
B11: Imperial Gallon = m³ x 219.969 | C11: IG | F11: =F10*219.969 -> 41574.141 | G11: =F11*0.06 -> 2494.4485
A12: IV | B12: ELECTRICAL METERS
A13: 1 | B13: Meter 1 - 06065253 | C13: kW x 480 | D13: ='7'!E13 -> 7027.4 | E13: ='Daily Meter'!H13 -> 7034.5 | F13: =(E13-D13)*480 -> 3408
A14: 2 | B14: Meter 2 - 06065255 | C14: kW x 480 | D14: ='7'!E14 -> 4247.9 | E14: ='Daily Meter'!I13 -> 4252.4 | F14: =(E14-D14)*480 -> 2160
A15: 3 | B15: Meter 3 - 06065259 | C15: kW x 480 | D15: ='7'!E15 -> 4534.3 | E15: ='Daily Meter'!J13 -> 4539 | F15: =(E15-D15)*480 -> 2256
A16: 4 | B16: Meter 4 - 06065262 | C16: kW x 480 | D16: ='7'!E16 -> 2549.5 | E16: ='Daily Meter'!K13 -> 2552.5 | F16: =(E16-D16)*480 -> 1440
A17: 5 | B17: Meter 6 - 06065269 | C17: kW x 480 | D17: ='7'!E17 -> 5872.6 | E17: ='Daily Meter'!L13 -> 5877.2 | F17: =(E17-D17)*480 -> 2208
A18: 6 | B18: Meter 7 - 06065283 | C18: kW x 480 | D18: ='7'!E18 -> 15780.6 | E18: ='Daily Meter'!M13 -> 15792.3 | F18: =(E18-D18)*480 -> 5616
B19: TOTAL ELECTRICAL CONS.(kWh) | F19: =SUM(F13:F18) -> 17088 | G19: =F19*0.43 -> 7347.84
A21: V | B21: GAS CONSUMPTION
A22: 1 | B22: MAIN LPG METER | C22: M3 | D22: ='7'!E22 -> 99291 | E22: ='Daily Meter'!N13 -> 99423.4 | F22: =E22-D22 -> 132.4
B23: L = m³ x 3.70 | C23: L | F23: =F22*3.7 -> 489.88 | G23: =F23*2.5 -> 1224.7
D26: Summary of Daily Hotel consumption
D27: Item measured | E27: Units | F27: Consumption | G27: AED
D28: Chilled water | E28: TR | F28: =F8 -> 6113.31 | G28: =G8 -> 3851.3853
D29: DEWA Water | E29: imp. Gallon | F29: =F11 -> 41574.141 | G29: =G11 -> 2494.4485
D30: Electricity | E30: kwh | F30: =F19 -> 17088 | G30: =G19 -> 7347.84
D31: Gas | E31: m3 | F31: =F22 -> 132.4 | G31: =G23 -> 1224.7
F32: Total cost | G32: =SUM(G28:G31) -> 14918.374

Sheet 9
A1: ENGINEERING DEPARTMENT | H1: daily reading
A2: UTILITY CONSUMPTION SHEET
B3: ='1'!B3 -> MARCH 2024 | C3: 9 | D3: % OCCUPANCY: | E3: ='Daily Meter'!O14 -> 58.06
A4: SR.NO | B4: ITEM MEASURED | D4: Previous Reading | E4: 4 AM Reading | F4: 24hrs CONSUMPTION | G4: Cost
A6: 1 | B6: DISTRICT COOLING PLANT
B7: Chilled Water | C7: MWH | D7: ='8'!E7 -> 54881.6 | E7: ='Daily Meter'!B14 -> 54909.9 | F7: =E7-D7 -> 28.3
C8: TR | F8: =F7*284.34 -> 8046.822 | G8: =F8*0.63 -> 5069.4979
A9: III | B9: WATER METERS
B10: Main DEWA Meter | C10: m3 | D10: ='8'!E10 -> 216668 | E10: ='Daily Meter'!C14 -> 216897 | F10: =E10-D10 -> 229
B11: Imperial Gallon = m³ x 219.969 | C11: IG | F11: =F10*219.969 -> 50372.901 | G11: =F11*0.06 -> 3022.3741
A12: IV | B12: ELECTRICAL METERS
A13: 1 | B13: Meter 1 - 06065253 | C13: kW x 480 | D13: ='8'!E13 -> 7034.5 | E13: ='Daily Meter'!H14 -> 7041.9 | F13: =(E13-D13)*480 -> 3552
A14: 2 | B14: Meter 2 - 06065255 | C14: kW x 480 | D14: ='8'!E14 -> 4252.4 | E14: ='Daily Meter'!I14 -> 4257 | F14: =(E14-D14)*480 -> 2208
A15: 3 | B15: Meter 3 - 06065259 | C15: kW x 480 | D15: ='8'!E15 -> 4539 | E15: ='Daily Meter'!J14 -> 4543.6 | F15: =(E15-D15)*480 -> 2208
A16: 4 | B16: Meter 4 - 06065262 | C16: kW x 480 | D16: ='8'!E16 -> 2552.5 | E16: ='Daily Meter'!K14 -> 2555.3 | F16: =(E16-D16)*480 -> 1344
A17: 5 | B17: Meter 6 - 06065269 | C17: kW x 480 | D17: ='8'!E17 -> 5877.2 | E17: ='Daily Meter'!L14 -> 5881.8 | F17: =(E17-D17)*480 -> 2208
A18: 6 | B18: Meter 7 - 06065283 | C18: kW x 480 | D18: ='8'!E18 -> 15792.3 | E18: ='Daily Meter'!M14 -> 15804.4 | F18: =(E18-D18)*480 -> 5808
B19: TOTAL ELECTRICAL CONS.(kWh) | F19: =SUM(F13:F18) -> 17328 | G19: =F19*0.43 -> 7451.04
A21: V | B21: GAS CONSUMPTION
A22: 1 | B22: MAIN LPG METER | C22: M3 | D22: ='8'!E22 -> 99423.4 | E22: ='Daily Meter'!N14 -> 99579.5 | F22: =E22-D22 -> 156.1
B23: L = m³ x 3.70 | C23: L | F23: =F22*3.7 -> 577.57 | G23: =F23*2.5 -> 1443.925
D26: Summary of Daily Hotel consumption
D27: Item measured | E27: Units | F27: Consumption | G27: AED
D28: Chilled water | E28: TR | F28: =F8 -> 8046.822 | G28: =G8 -> 5069.4979
D29: DEWA Water | E29: imp. Gallon | F29: =F11 -> 50372.901 | G29: =G11 -> 3022.3741
D30: Electricity | E30: kwh | F30: =F19 -> 17328 | G30: =G19 -> 7451.04
D31: Gas | E31: m3 | F31: =F22 -> 156.1 | G31: =G23 -> 1443.925
F32: Total cost | G32: =SUM(G28:G31) -> 16986.837

Sheet 10
A1: ENGINEERING DEPARTMENT | H1: daily reading
A2: UTILITY CONSUMPTION SHEET
B3: ='1'!B3 -> MARCH 2024 | C3: 10 | D3: % OCCUPANCY: | E3: ='Daily Meter'!O15 -> 39.63
A4: SR.NO | B4: ITEM MEASURED | D4: Previous Reading | E4: 4 AM Reading | F4: 24hrs CONSUMPTION | G4: Cost
A6: 1 | B6: DISTRICT COOLING PLANT
B7: Chilled Water | C7: MWH | D7: ='9'!E7 -> 54909.9 | E7: ='Daily Meter'!B15 -> 54930.3 | F7: =E7-D7 -> 20.4
C8: TR | F8: =F7*284.34 -> 5800.536 | G8: =F8*0.63 -> 3654.3377
A9: III | B9: WATER METERS
B10: Main DEWA Meter | C10: m3 | D10: ='9'!E10 -> 216897 | E10: ='Daily Meter'!C15 -> 217096 | F10: =E10-D10 -> 199
B11: Imperial Gallon = m³ x 219.969 | C11: IG | F11: =F10*219.969 -> 43773.831 | G11: =F11*0.06 -> 2626.4299
A12: IV | B12: ELECTRICAL METERS
A13: 1 | B13: Meter 1 - 06065253 | C13: kW x 480 | D13: ='9'!E13 -> 7041.9 | E13: ='Daily Meter'!H15 -> 7049.2 | F13: =(E13-D13)*480 -> 3504
A14: 2 | B14: Meter 2 - 06065255 | C14: kW x 480 | D14: ='9'!E14 -> 4257 | E14: ='Daily Meter'!I15 -> 4261.3 | F14: =(E14-D14)*480 -> 2064
A15: 3 | B15: Meter 3 - 06065259 | C15: kW x 480 | D15: ='9'!E15 -> 4543.6 | E15: ='Daily Meter'!J15 -> 4548.1 | F15: =(E15-D15)*480 -> 2160
A16: 4 | B16: Meter 4 - 06065262 | C16: kW x 480 | D16: ='9'!E16 -> 2555.3 | E16: ='Daily Meter'!K15 -> 2558.4 | F16: =(E16-D16)*480 -> 1488
A17: 5 | B17: Meter 6 - 06065269 | C17: kW x 480 | D17: ='9'!E17 -> 5881.8 | E17: ='Daily Meter'!L15 -> 5886.6 | F17: =(E17-D17)*480 -> 2304
A18: 6 | B18: Meter 7 - 06065283 | C18: kW x 480 | D18: ='9'!E18 -> 15804.4 | E18: ='Daily Meter'!M15 -> 15816.1 | F18: =(E18-D18)*480 -> 5616
B19: TOTAL ELECTRICAL CONS.(kWh) | F19: =SUM(F13:F18) -> 17136 | G19: =F19*0.43 -> 7368.48
A21: V | B21: GAS CONSUMPTION
A22: 1 | B22: MAIN LPG METER | C22: M3 | D22: ='9'!E22 -> 99579.5 | E22: ='Daily Meter'!N15 -> 99709.5 | F22: =E22-D22 -> 130
B23: L = m³ x 3.70 | C23: L | F23: =F22*3.7 -> 481 | G23: =F23*2.5 -> 1202.5
D26: Summary of Daily Hotel consumption
D27: Item measured | E27: Units | F27: Consumption | G27: AED
D28: Chilled water | E28: TR | F28: =F8 -> 5800.536 | G28: =G8 -> 3654.3377
D29: DEWA Water | E29: imp. Gallon | F29: =F11 -> 43773.831 | G29: =G11 -> 2626.4299
D30: Electricity | E30: kwh | F30: =F19 -> 17136 | G30: =G19 -> 7368.48
D31: Gas | E31: m3 | F31: =F22 -> 130 | G31: =G23 -> 1202.5
F32: Total cost | G32: =SUM(G28:G31) -> 14851.748

Sheet 11
A1: ENGINEERING DEPARTMENT | H1: daily reading
A2: UTILITY CONSUMPTION SHEET
B3: ='1'!B3 -> MARCH 2024 | C3: 11 | D3: % OCCUPANCY: | E3: ='Daily Meter'!O16 -> 41.01
A4: SR.NO | B4: ITEM MEASURED | D4: Previous Reading | E4: 4 AM Reading | F4: 24hrs CONSUMPTION | G4: Cost
A6: 1 | B6: DISTRICT COOLING PLANT
B7: Chilled Water | C7: MWH | D7: ='10'!E7 -> 54930.3 | E7: ='Daily Meter'!B16 -> 54951.9 | F7: =E7-D7 -> 21.6
C8: TR | F8: =F7*284.34 -> 6141.744 | G8: =F8*0.63 -> 3869.2987
A9: III | B9: WATER METERS
B10: Main DEWA Meter | C10: m3 | D10: ='10'!E10 -> 217096 | E10: ='Daily Meter'!C16 -> 217258 | F10: =E10-D10 -> 162
B11: Imperial Gallon = m³ x 219.969 | C11: IG | F11: =F10*219.969 -> 35634.978 | G11: =F11*0.06 -> 2138.0987
A12: IV | B12: ELECTRICAL METERS
A13: 1 | B13: Meter 1 - 06065253 | C13: kW x 480 | D13: ='10'!E13 -> 7049.2 | E13: ='Daily Meter'!H16 -> 7056.4 | F13: =(E13-D13)*480 -> 3456
A14: 2 | B14: Meter 2 - 06065255 | C14: kW x 480 | D14: ='10'!E14 -> 4261.3 | E14: ='Daily Meter'!I16 -> 4265.3 | F14: =(E14-D14)*480 -> 1920
A15: 3 | B15: Meter 3 - 06065259 | C15: kW x 480 | D15: ='10'!E15 -> 4548.1 | E15: ='Daily Meter'!J16 -> 4552.3 | F15: =(E15-D15)*480 -> 2016
A16: 4 | B16: Meter 4 - 06065262 | C16: kW x 480 | D16: ='10'!E16 -> 2558.4 | E16: ='Daily Meter'!K16 -> 2561 | F16: =(E16-D16)*480 -> 1248
A17: 5 | B17: Meter 6 - 06065269 | C17: kW x 480 | D17: ='10'!E17 -> 5886.6 | E17: ='Daily Meter'!L16 -> 5891.1 | F17: =(E17-D17)*480 -> 2160
A18: 6 | B18: Meter 7 - 06065283 | C18: kW x 480 | D18: ='10'!E18 -> 15816.1 | E18: ='Daily Meter'!M16 -> 15827.7 | F18: =(E18-D18)*480 -> 5568
B19: TOTAL ELECTRICAL CONS.(kWh) | F19: =SUM(F13:F18) -> 16368 | G19: =F19*0.43 -> 7038.24
A21: V | B21: GAS CONSUMPTION
A22: 1 | B22: MAIN LPG METER | C22: M3 | D22: ='10'!E22 -> 99709.5 | E22: ='Daily Meter'!N16 -> 99826.1 | F22: =E22-D22 -> 116.6
B23: L = m³ x 3.70 | C23: L | F23: =F22*3.7 -> 431.42 | G23: =F23*2.5 -> 1078.55
D26: Summary of Daily Hotel consumption
D27: Item measured | E27: Units | F27: Consumption | G27: AED
D28: Chilled water | E28: TR | F28: =F8 -> 6141.744 | G28: =G8 -> 3869.2987
D29: DEWA Water | E29: imp. Gallon | F29: =F11 -> 35634.978 | G29: =G11 -> 2138.0987
D30: Electricity | E30: kwh | F30: =F19 -> 16368 | G30: =G19 -> 7038.24
D31: Gas | E31: m3 | F31: =F22 -> 116.6 | G31: =G23 -> 1078.55
F32: Total cost | G32: =SUM(G28:G31) -> 14124.187

Sheet 12
A1: ENGINEERING DEPARTMENT | H1: daily reading
A2: UTILITY CONSUMPTION SHEET
B3: ='1'!B3 -> MARCH 2024 | C3: 12 | D3: % OCCUPANCY: | E3: ='Daily Meter'!O17 -> 41.24
A4: SR.NO | B4: ITEM MEASURED | D4: Previous Reading | E4: 4 AM Reading | F4: 24hrs CONSUMPTION | G4: Cost
A6: 1 | B6: DISTRICT COOLING PLANT
B7: Chilled Water | C7: MWH | D7: ='11'!E7 -> 54951.9 | E7: ='Daily Meter'!B17 -> 54973.3 | F7: =E7-D7 -> 21.4
C8: TR | F8: =F7*284.34 -> 6084.876 | G8: =F8*0.63 -> 3833.4719
A9: III | B9: WATER METERS
B10: Main DEWA Meter | C10: m3 | D10: ='11'!E10 -> 217258 | E10: ='Daily Meter'!C17 -> 217395 | F10: =E10-D10 -> 137
B11: Imperial Gallon = m³ x 219.969 | C11: IG | F11: =F10*219.969 -> 30135.753 | G11: =F11*0.06 -> 1808.1452
A12: IV | B12: ELECTRICAL METERS
A13: 1 | B13: Meter 1 - 06065253 | C13: kW x 480 | D13: ='11'!E13 -> 7056.4 | E13: ='Daily Meter'!H17 -> 7063.3 | F13: =(E13-D13)*480 -> 3312
A14: 2 | B14: Meter 2 - 06065255 | C14: kW x 480 | D14: ='11'!E14 -> 4265.3 | E14: ='Daily Meter'!I17 -> 4269.4 | F14: =(E14-D14)*480 -> 1968
A15: 3 | B15: Meter 3 - 06065259 | C15: kW x 480 | D15: ='11'!E15 -> 4552.3 | E15: ='Daily Meter'!J17 -> 4556.5 | F15: =(E15-D15)*480 -> 2016
A16: 4 | B16: Meter 4 - 06065262 | C16: kW x 480 | D16: ='11'!E16 -> 2561 | E16: ='Daily Meter'!K17 -> 2563.7 | F16: =(E16-D16)*480 -> 1296
A17: 5 | B17: Meter 6 - 06065269 | C17: kW x 480 | D17: ='11'!E17 -> 5891.1 | E17: ='Daily Meter'!L17 -> 5895.7 | F17: =(E17-D17)*480 -> 2208
A18: 6 | B18: Meter 7 - 06065283 | C18: kW x 480 | D18: ='11'!E18 -> 15827.7 | E18: ='Daily Meter'!M17 -> 15839.6 | F18: =(E18-D18)*480 -> 5712
B19: TOTAL ELECTRICAL CONS.(kWh) | F19: =SUM(F13:F18) -> 16512 | G19: =F19*0.43 -> 7100.16
A21: V | B21: GAS CONSUMPTION
A22: 1 | B22: MAIN LPG METER | C22: M3 | D22: ='11'!E22 -> 99826.1 | E22: ='Daily Meter'!N17 -> 99932.6 | F22: =E22-D22 -> 106.5
B23: L = m³ x 3.70 | C23: L | F23: =F22*3.7 -> 394.05 | G23: =F23*2.5 -> 985.125
D26: Summary of Daily Hotel consumption
D27: Item measured | E27: Units | F27: Consumption | G27: AED
D28: Chilled water | E28: TR | F28: =F8 -> 6084.876 | G28: =G8 -> 3833.4719
D29: DEWA Water | E29: imp. Gallon | F29: =F11 -> 30135.753 | G29: =G11 -> 1808.1452
D30: Electricity | E30: kwh | F30: =F19 -> 16512 | G30: =G19 -> 7100.16
D31: Gas | E31: m3 | F31: =F22 -> 106.5 | G31: =G23 -> 985.125
F32: Total cost | G32: =SUM(G28:G31) -> 13726.902

Sheet 13
A1: ENGINEERING DEPARTMENT | H1: daily reading
A2: UTILITY CONSUMPTION SHEET
B3: ='1'!B3 -> MARCH 2024 | C3: 13 | D3: % OCCUPANCY: | E3: ='Daily Meter'!O18 -> 35.94
A4: SR.NO | B4: ITEM MEASURED | D4: Previous Reading | E4: 4 AM Reading | F4: 24hrs CONSUMPTION | G4: Cost
A6: 1 | B6: DISTRICT COOLING PLANT
B7: Chilled Water | C7: MWH | D7: ='12'!E7 -> 54973.3 | E7: ='Daily Meter'!B18 -> 54994.6 | F7: =E7-D7 -> 21.3
C8: TR | F8: =F7*284.34 -> 6056.442 | G8: =F8*0.63 -> 3815.5585
A9: III | B9: WATER METERS
B10: Main DEWA Meter | C10: m3 | D10: ='12'!E10 -> 217395 | E10: ='Daily Meter'!C18 -> 217558 | F10: =E10-D10 -> 163
B11: Imperial Gallon = m³ x 219.969 | C11: IG | F11: =F10*219.969 -> 35854.947 | G11: =F11*0.06 -> 2151.2968
A12: IV | B12: ELECTRICAL METERS
A13: 1 | B13: Meter 1 - 06065253 | C13: kW x 480 | D13: ='12'!E13 -> 7063.3 | E13: ='Daily Meter'!H18 -> 7070.2 | F13: =(E13-D13)*480 -> 3312
A14: 2 | B14: Meter 2 - 06065255 | C14: kW x 480 | D14: ='12'!E14 -> 4269.4 | E14: ='Daily Meter'!I18 -> 4273.6 | F14: =(E14-D14)*480 -> 2016
A15: 3 | B15: Meter 3 - 06065259 | C15: kW x 480 | D15: ='12'!E15 -> 4556.5 | E15: ='Daily Meter'!J18 -> 4560.8 | F15: =(E15-D15)*480 -> 2064
A16: 4 | B16: Meter 4 - 06065262 | C16: kW x 480 | D16: ='12'!E16 -> 2563.7 | E16: ='Daily Meter'!K18 -> 2566.3 | F16: =(E16-D16)*480 -> 1248
A17: 5 | B17: Meter 6 - 06065269 | C17: kW x 480 | D17: ='12'!E17 -> 5895.7 | E17: ='Daily Meter'!L18 -> 5900.3 | F17: =(E17-D17)*480 -> 2208
A18: 6 | B18: Meter 7 - 06065283 | C18: kW x 480 | D18: ='12'!E18 -> 15839.6 | E18: ='Daily Meter'!M18 -> 15851.4 | F18: =(E18-D18)*480 -> 5664
B19: TOTAL ELECTRICAL CONS.(kWh) | F19: =SUM(F13:F18) -> 16512 | G19: =F19*0.43 -> 7100.16
A21: V | B21: GAS CONSUMPTION
A22: 1 | B22: MAIN LPG METER | C22: M3 | D22: ='12'!E22 -> 99932.6 | E22: ='Daily Meter'!N18 -> 100049 | F22: =E22-D22 -> 116.4
B23: L = m³ x 3.70 | C23: L | F23: =F22*3.7 -> 430.68 | G23: =F23*2.5 -> 1076.7
D26: Summary of Daily Hotel consumption
D27: Item measured | E27: Units | F27: Consumption | G27: AED
D28: Chilled water | E28: TR | F28: =F8 -> 6056.442 | G28: =G8 -> 3815.5585
D29: DEWA Water | E29: imp. Gallon | F29: =F11 -> 35854.947 | G29: =G11 -> 2151.2968
D30: Electricity | E30: kwh | F30: =F19 -> 16512 | G30: =G19 -> 7100.16
D31: Gas | E31: m3 | F31: =F22 -> 116.4 | G31: =G23 -> 1076.7
F32: Total cost | G32: =SUM(G28:G31) -> 14143.715

Sheet 14
A1: ENGINEERING DEPARTMENT | H1: daily reading
A2: UTILITY CONSUMPTION SHEET
B3: ='1'!B3 -> MARCH 2024 | C3: 14 | D3: % OCCUPANCY: | E3: ='Daily Meter'!O19 -> 38.48
A4: SR.NO | B4: ITEM MEASURED | D4: Previous Reading | E4: 4 AM Reading | F4: 24hrs CONSUMPTION | G4: Cost
A6: 1 | B6: DISTRICT COOLING PLANT
B7: Chilled Water | C7: MWH | D7: ='13'!E7 -> 54994.6 | E7: ='Daily Meter'!B19 -> 55017.4 | F7: =E7-D7 -> 22.8
C8: TR | F8: =F7*284.34 -> 6482.952 | G8: =F8*0.63 -> 4084.2598
A9: III | B9: WATER METERS
B10: Main DEWA Meter | C10: m3 | D10: ='13'!E10 -> 217558 | E10: ='Daily Meter'!C19 -> 217743 | F10: =E10-D10 -> 185
B11: Imperial Gallon = m³ x 219.969 | C11: IG | F11: =F10*219.969 -> 40694.265 | G11: =F11*0.06 -> 2441.6559
A12: IV | B12: ELECTRICAL METERS
A13: 1 | B13: Meter 1 - 06065253 | C13: kW x 480 | D13: ='13'!E13 -> 7070.2 | E13: ='Daily Meter'!H19 -> 7077.2 | F13: =(E13-D13)*480 -> 3360
A14: 2 | B14: Meter 2 - 06065255 | C14: kW x 480 | D14: ='13'!E14 -> 4273.6 | E14: ='Daily Meter'!I19 -> 4277.7 | F14: =(E14-D14)*480 -> 1968
A15: 3 | B15: Meter 3 - 06065259 | C15: kW x 480 | D15: ='13'!E15 -> 4560.8 | E15: ='Daily Meter'!J19 -> 4565 | F15: =(E15-D15)*480 -> 2016
A16: 4 | B16: Meter 4 - 06065262 | C16: kW x 480 | D16: ='13'!E16 -> 2566.3 | E16: ='Daily Meter'!K19 -> 2569.1 | F16: =(E16-D16)*480 -> 1344
A17: 5 | B17: Meter 6 - 06065269 | C17: kW x 480 | D17: ='13'!E17 -> 5900.3 | E17: ='Daily Meter'!L19 -> 5904.9 | F17: =(E17-D17)*480 -> 2208
A18: 6 | B18: Meter 7 - 06065283 | C18: kW x 480 | D18: ='13'!E18 -> 15851.4 | E18: ='Daily Meter'!M19 -> 15863.4 | F18: =(E18-D18)*480 -> 5760
B19: TOTAL ELECTRICAL CONS.(kWh) | F19: =SUM(F13:F18) -> 16656 | G19: =F19*0.43 -> 7162.08
A21: V | B21: GAS CONSUMPTION
A22: 1 | B22: MAIN LPG METER | C22: M3 | D22: ='13'!E22 -> 100049 | E22: ='Daily Meter'!N19 -> 100170 | F22: =E22-D22 -> 121
B23: L = m³ x 3.70 | C23: L | F23: =F22*3.7 -> 447.7 | G23: =F23*2.5 -> 1119.25
D26: Summary of Daily Hotel consumption
D27: Item measured | E27: Units | F27: Consumption | G27: AED
D28: Chilled water | E28: TR | F28: =F8 -> 6482.952 | G28: =G8 -> 4084.2598
D29: DEWA Water | E29: imp. Gallon | F29: =F11 -> 40694.265 | G29: =G11 -> 2441.6559
D30: Electricity | E30: kwh | F30: =F19 -> 16656 | G30: =G19 -> 7162.08
D31: Gas | E31: m3 | F31: =F22 -> 121 | G31: =G23 -> 1119.25
F32: Total cost | G32: =SUM(G28:G31) -> 14807.246

Sheet 15
A1: ENGINEERING DEPARTMENT | H1: daily reading
A2: UTILITY CONSUMPTION SHEET
B3: ='1'!B3 -> MARCH 2024 | C3: 15 | D3: % OCCUPANCY: | E3: ='Daily Meter'!O20 -> 33.41
A4: SR.NO | B4: ITEM MEASURED | D4: Previous Reading | E4: 4 AM Reading | F4: 24hrs CONSUMPTION | G4: Cost
A6: 1 | B6: DISTRICT COOLING PLANT
B7: Chilled Water | C7: MWH | D7: ='14'!E7 -> 55017.4 | E7: ='Daily Meter'!B20 -> 55044 | F7: =E7-D7 -> 26.6
C8: TR | F8: =F7*284.34 -> 7563.444 | G8: =F8*0.63 -> 4764.9697
A9: III | B9: WATER METERS
B10: Main DEWA Meter | C10: m3 | D10: ='14'!E10 -> 217743 | E10: ='Daily Meter'!C20 -> 217868 | F10: =E10-D10 -> 125
B11: Imperial Gallon = m³ x 219.969 | C11: IG | F11: =F10*219.969 -> 27496.125 | G11: =F11*0.06 -> 1649.7675
A12: IV | B12: ELECTRICAL METERS
A13: 1 | B13: Meter 1 - 06065253 | C13: kW x 480 | D13: ='14'!E13 -> 7077.2 | E13: ='Daily Meter'!H20 -> 7084.4 | F13: =(E13-D13)*480 -> 3456
A14: 2 | B14: Meter 2 - 06065255 | C14: kW x 480 | D14: ='14'!E14 -> 4277.7 | E14: ='Daily Meter'!I20 -> 4281.7 | F14: =(E14-D14)*480 -> 1920
A15: 3 | B15: Meter 3 - 06065259 | C15: kW x 480 | D15: ='14'!E15 -> 4565 | E15: ='Daily Meter'!J20 -> 4569.2 | F15: =(E15-D15)*480 -> 2016
A16: 4 | B16: Meter 4 - 06065262 | C16: kW x 480 | D16: ='14'!E16 -> 2569.1 | E16: ='Daily Meter'!K20 -> 2571.8 | F16: =(E16-D16)*480 -> 1296
A17: 5 | B17: Meter 6 - 06065269 | C17: kW x 480 | D17: ='14'!E17 -> 5904.9 | E17: ='Daily Meter'!L20 -> 5909.5 | F17: =(E17-D17)*480 -> 2208
A18: 6 | B18: Meter 7 - 06065283 | C18: kW x 480 | D18: ='14'!E18 -> 15863.4 | E18: ='Daily Meter'!M20 -> 15875.5 | F18: =(E18-D18)*480 -> 5808
B19: TOTAL ELECTRICAL CONS.(kWh) | F19: =SUM(F13:F18) -> 16704 | G19: =F19*0.43 -> 7182.72
A21: V | B21: GAS CONSUMPTION
A22: 1 | B22: MAIN LPG METER | C22: M3 | D22: ='14'!E22 -> 100170 | E22: ='Daily Meter'!N20 -> 100295.7 | F22: =E22-D22 -> 125.7
B23: L = m³ x 3.70 | C23: L | F23: =F22*3.7 -> 465.09 | G23: =F23*2.5 -> 1162.725
D26: Summary of Daily Hotel consumption
D27: Item measured | E27: Units | F27: Consumption | G27: AED
